Workbook
Name _401k_Pre_Tax: 'Earnings Projection'!$B$22:$C$22
Name _401k_Roth: 'Earnings Projection'!$B$23:$C$23
Name Assumptions: 'Earnings Projection'!$B$5:$C$23
Name Bonus_Level: 'Earnings Projection'!$B$9:$C$9
Name ColumnTitle2: Amortization[[#Headers],['#]]
Name Company_401K_Match: 'Earnings Projection'!$B$12:$C$12
Name Dental: 'Earnings Projection'!$B$14:$C$14
Name DurationOfLoan: 'Mortgage Calculator'!$C$6
Name Federal_Tax_Rate: 'Earnings Projection'!$B$17:$C$17
Name HeaderRow: ROW('Amortization Table'!$B$3:$J$3)
Name HSA: 'Earnings Projection'!$B$21:$C$21
Name interest: 'Amortization Table'!$E$4:$E$363
Name InterestRate: 'Mortgage Calculator'!$C$5
Name LastRow: COUNTIF('Amortization Table'!$C$4:$C$363,">1")+HeaderRow
Name LastRow: COUNTIF('Amortization Table'!$C$4:$C$363,">1")+HeaderRow
Name LoanAmount: 'Mortgage Calculator'!$C$7
Name LoanIsGood: ('Mortgage Calculator'!$C$5*'Mortgage Calculator'!$C$6*'Mortgage Calculator'!$C$7)>0
Name LoanStart: 'Mortgage Calculator'!$C$8
Name Medical: 'Earnings Projection'!$B$13:$C$13
Name Medicare: 'Earnings Projection'!$B$20:$C$20
Name MonthlyLoanPayment: 'Mortgage Calculator'!$E$4
Name NoPaymentsRemaining: 'Amortization Table'!$J$4:$J$363
Name nper: '401k - Sean'!$E$18
Name nper: '401k - Vincent'!$E$18
Name OASDI: 'Earnings Projection'!$B$19:$C$19
Name Pay_Schedule: 'Earnings Projection'!$B$10:$C$10
Name PaymentDurationIncreaseDecrease: INT(NPER(InterestRate/12,-MonthlyLoanPayment*VLOOKUP(PaymentPercentage,PaymentScenarios,2,FALSE),LoanAmount))
Name PaymentDurationIncreaseDecrease: INT(NPER(InterestRate/12,-MonthlyLoanPayment*VLOOKUP(PaymentPercentage,PaymentScenarios,2,FALSE),LoanAmount))
Name PercentageIncreaseDecrease: 1-'Amortization Table'!PaymentDurationIncreaseDecrease/DurationOfLoan
Name PercentageIncreaseDecrease: 1-PaymentDurationIncreaseDecrease/DurationOfLoan
Name PropertyTaxAmount: 'Mortgage Calculator'!$E$8
Name randrate: '401k - Sean'!$H$21
Name randrate: '401k - Vincent'!$H$21
Name Sean: 'Earnings Projection'!$B$5:$B$23
Name Starting_401K_Contribution_Base: 'Earnings Projection'!$B$16:$C$16
Name Starting_Equity: 'Earnings Projection'!$B$8:$C$8
Name Starting_Level: 'Earnings Projection'!$B$5:$C$5
Name Starting_Salary: 'Earnings Projection'!$B$7:$C$7
Name State: 'Earnings Projection'!$B$11:$C$11
Name State_Tax_Rate: 'Earnings Projection'!$B$18:$C$18
Name TitleRegion1..C8: 'Mortgage Calculator'!$B$3
Name TitleRegion2..E8: 'Mortgage Calculator'!$D$3
Name total_interest_paid: 'Mortgage Calculator'!$E$7
Name total_loan_payment: 'Amortization Table'!$E$4:$F$363
Name total_payments: 'Amortization Table'!$H$4:$H$363
Name ValueOfHome: 'Mortgage Calculator'!$C$4
Name ValuesEntered: IF(LoanAmount*(LEN(InterestRate)>0)*DurationOfLoan*LoanStart*(LEN(PropertyTaxAmount)>0)>0,1,0)
Name ValuesEntered: IF(LoanAmount*(LEN(InterestRate)>0)*DurationOfLoan*LoanStart*(LEN(PropertyTaxAmount)>0)>0,1,0)
Name valuevx: 42.314159
Name Vincent: 'Earnings Projection'!$C$5:$C$23
Name Vision: 'Earnings Projection'!$B$15:$C$15

Sheet Compare Periods
C1: =YEAR(C2) -> 2021 | D1: =YEAR(D2) -> 2021 | E1: =YEAR(E2) -> 2021 | F1: =YEAR(F2) -> 2021 | G1: =YEAR(G2) -> 2021 | H1: =YEAR(H2) -> 2021 | I1: =YEAR(I2) -> 2021 | J1: =YEAR(J2) -> 2021 | ... Q1: =YEAR(Q2) -> 2021
B2: =COUNTA(C2:ZZ2) & "/" & "26" & " Total" -> 17/26 Total | C2: 44360 | D2: =C2+14 -> 44374 | E2: =D2+14 -> 44388 | F2: =E2+14 -> 44402 | G2: =F2+14 -> 44416 | H2: =G2+14 -> 44430 | I2: =H2+14 -> 44444 | J2: =I2+14 -> 44458 | K2: =J2+14 -> 44472 | ... S2: =R2+14 -> 44584
A3: Earnings
A4: Grossed Up Earnings | B4: =SUM(C4:XFD4) -> 4098.37 | C4: 4098.37 | D4: 0
A5: LTD Benefit Credit | B5: =SUM(C5:XFD5) -> 38.88 | C5: 0 | D5: 4.86 | E5: 4.86 | F5: 4.86 | G5: 4.86 | H5: 4.86 | I5: 4.86 | J5: 4.86 | K5: 4.86
A6: My Health Completion Credit | B6: =SUM(C6:XFD6) -> 160 | C6: 0 | D6: 20 | E6: 20 | F6: 20 | G6: 20 | H6: 20 | I6: 20 | J6: 20 | K6: 20
A7: Regular | B7: =SUM(C7:XFD7) -> 47700 | C7: 2700 | D7: 3000 | E7: 3000 | F7: 3000 | G7: 3000 | H7: 3000 | I7: 3000 | J7: 3000 | K7: 3000 | L7: 3000 | M7: 3000 | N7: 3000 | O7: 3000 | P7: 3000 | Q7: 3000 | R7: 3000
A8: Deductions
A9: Federal | B9: =SUM(C9:XFD9) -> 4135.13 | C9: 1225.93 | D9: 363.68 | E9: 363.68 | F9: 363.64 | G9: 363.64 | H9: 363.64 | I9: 363.64 | J9: 363.64 | K9: 363.64
A10: Health Savings Account | B10: =SUM(C10:XFD10) -> 438.16 | C10: 0 | D10: 54.77 | E10: 54.77 | F10: 54.77 | G10: 54.77 | H10: 54.77 | I10: 54.77 | J10: 54.77 | K10: 54.77
A11: Life Insurance Coverage | B11: =SUM(C11:XFD11) -> 9.04 | C11: 0 | D11: 1.13 | E11: 1.13 | F11: 1.13 | G11: 1.13 | H11: 1.13 | I11: 1.13 | J11: 1.13 | K11: 1.13
A12: Long Term Disability Coverage | B12: =SUM(C12:XFD12) -> 77.52 | C12: 0 | D12: 9.69 | E12: 9.69 | F12: 9.69 | G12: 9.69 | H12: 9.69 | I12: 9.69 | J12: 9.69 | K12: 9.69
A13: Medical Coverage | B13: =SUM(C13:XFD13) -> 696 | C13: 0 | D13: 87 | E13: 87 | F13: 87 | G13: 87 | H13: 87 | I13: 87 | J13: 87 | K13: 87
A14: Medicare | B14: =SUM(C14:XFD14) -> 432.53 | C14: 98.58 | D14: 41.74 | E14: 41.75 | F14: 41.74 | G14: 41.75 | H14: 41.75 | I14: 41.74 | J14: 41.74 | K14: 41.74
A15: NSP AfterTax Deduction NonRoth | B15: =SUM(C15:XFD15) -> 3480 | C15: 0 | D15: 450 | E15: 450 | F15: 300 | G15: 0 | H15: 0 | I15: 0 | J15: 0 | K15: =0.2*K7 -> 600 | L15: =8%*L7 -> 240 | M15: =8%*M7 -> 240 | N15: =8%*N7 -> 240 | O15: =8%*O7 -> 240 | P15: =8%*P7 -> 240 | Q15: =8%*Q7 -> 240 | R15: =8%*R7 -> 240
A16: OASDI | B16: =SUM(C16:XFD16) -> 1849.5 | C16: 421.5 | D16: 178.5 | E16: 178.5 | F16: 178.5 | G16: 178.5 | H16: 178.5 | I16: 178.5 | J16: 178.5 | K16: 178.5
A17: VA State Tax | B17: =SUM(C17:XFD17) -> 1245.19 | C17: 371.05 | D17: 145.69 | E17: 145.69 | F17: 145.69 | G17: 145.69 | H17: 145.69 | I17: 145.69 | J17: 0 | K17: 0
A18: AZ State Tax | B18: =SUM(C18:XFD18) -> 1073.94 | C18: 244.74 | D18: 103.65 | E18: 103.65 | F18: 103.65 | G18: 103.65 | H18: 103.65 | I18: 103.65 | J18: 103.65 | K18: 103.65
A19: Supplemental Accident Coverage | B19: =SUM(C19:XFD19) -> 12.8 | C19: 0 | D19: 1.6 | E19: 1.6 | F19: 1.6 | G19: 1.6 | H19: 1.6 | I19: 1.6 | J19: 1.6 | K19: 1.6
A20: Vision Coverage | B20: =SUM(C20:XFD20) -> 30.32 | C20: 0 | D20: 3.79 | E20: 3.79 | F20: 3.79 | G20: 3.79 | H20: 3.79 | I20: 3.79 | J20: 3.79 | K20: 3.79
A22: Gross | B22: =SUM(C22:XFD22) -> 30997.25 | C22: =SUM(C4:C7) -> 6798.37 | D22: =SUM(D4:D7) -> 3024.86 | E22: =SUM(E4:E7) -> 3024.86 | F22: =SUM(F4:F7) -> 3024.86 | G22: =SUM(G4:G7) -> 3024.86 | H22: =SUM(H4:H7) -> 3024.86 | I22: =SUM(I4:I7) -> 3024.86 | J22: =SUM(J4:J7) -> 3024.86 | K22: =SUM(K4:K7) -> 3024.86
A23: Deductions | B23: =SUM(C23:XFD23) -> 11800.13 | C23: =SUM(C9:C20) -> 2361.8 | D23: =SUM(D9:D20) -> 1441.24 | E23: =SUM(E9:E20) -> 1441.25 | F23: =SUM(F9:F20) -> 1291.2 | G23: =SUM(G9:G20) -> 991.21 | H23: =SUM(H9:H20) -> 991.21 | I23: =SUM(I9:I20) -> 991.2 | J23: =SUM(J9:J20) -> 845.51 | K23: =SUM(K9:K20) -> 1445.51
A25: Net | B25: =SUM(C25:XFD25) -> 19197.12 | C25: =C22-C23 -> 4436.57 | D25: =D22-D23 -> 1583.62 | E25: =E22-E23 -> 1583.61 | F25: =F22-F23 -> 1733.66 | G25: =G22-G23 -> 2033.65 | H25: =H22-H23 -> 2033.65 | I25: =I22-I23 -> 2033.66 | J25: =J22-J23 -> 2179.35 | K25: =K22-K23 -> 1579.35
A27: Federal | B27: =B9/B$22 -> 0.13340312 | C27: =C9/C$22 -> 0.18032705 | D27: =D9/D$22 -> 0.12023036 | E27: =E9/E$22 -> 0.12023036 | F27: =F9/F$22 -> 0.12021713 | G27: =G9/G$22 -> 0.12021713 | H27: =H9/H$22 -> 0.12021713 | I27: =I9/I$22 -> 0.12021713 | ... K27: =K9/K$22 -> 0.12021713
A28: Health Savings Account | B28: =B10/B$22 -> 0.014135447 | D28: =D10/D$22 -> 0.018106623 | E28: =E10/E$22 -> 0.018106623 | F28: =F10/F$22 -> 0.018106623 | G28: =G10/G$22 -> 0.018106623 | H28: =H10/H$22 -> 0.018106623 | I28: =I10/I$22 -> 0.018106623 | J28: =J10/J$22 -> 0.018106623 | K28: =K10/K$22 -> 0.018106623
A29: Life Insurance Coverage | B29: =B11/B$22 -> 0.00029163877 | D29: =D11/D$22 -> 0.00037357101 | E29: =E11/E$22 -> 0.00037357101 | F29: =F11/F$22 -> 0.00037357101 | G29: =G11/G$22 -> 0.00037357101 | H29: =H11/H$22 -> 0.00037357101 | I29: =I11/I$22 -> 0.00037357101 | J29: =J11/J$22 -> 0.00037357101 | K29: =K11/K$22 -> 0.00037357101
A30: Long Term Disability Coverage | B30: =B12/B$22 -> 0.002500867 | D30: =D12/D$22 -> 0.003203454 | E30: =E12/E$22 -> 0.003203454 | F30: =F12/F$22 -> 0.003203454 | G30: =G12/G$22 -> 0.003203454 | H30: =H12/H$22 -> 0.003203454 | I30: =I12/I$22 -> 0.003203454 | J30: =J12/J$22 -> 0.003203454 | K30: =K12/K$22 -> 0.003203454
A31: Medical Coverage | B31: =B13/B$7 -> 0.014591195 | D31: =D13/D$7 -> 0.029 | E31: =E13/E$22 -> 0.028761662 | F31: =F13/F$22 -> 0.028761662 | G31: =G13/G$22 -> 0.028761662 | H31: =H13/H$22 -> 0.028761662 | I31: =I13/I$22 -> 0.028761662 | J31: =J13/J$22 -> 0.028761662 | K31: =K13/K$22 -> 0.028761662
A32: Medicare | B32: =B14/B$22 -> 0.013953818 | C32: =C14/C$22 -> 0.014500535 | D32: =D14/D$22 -> 0.013798986 | E32: =E14/E$22 -> 0.013802292 | F32: =F14/F$22 -> 0.013798986 | G32: =G14/G$22 -> 0.013802292 | H32: =H14/H$22 -> 0.013802292 | I32: =I14/I$22 -> 0.013798986 | ... K32: =K14/K$22 -> 0.013798986
A33: NSP AfterTax Deduction NonRoth | B33: =B15/(B$22 - SUM(B4:B6)) -> 0.13033708 | D33: =D15/(D$22 - SUM(D4:D6)) -> 0.15 | E33: =E15/(E$22 - SUM(E4:E6)) -> 0.15 | F33: =F15/(F$22 - SUM(F4:F6)) -> 0.1 | G33: =G15/(G$22 - SUM(G4:G6)) -> 0 | H33: =H15/(H$22 - SUM(H4:H6)) -> 0 | I33: =I15/(I$22 - SUM(I4:I6)) -> 0 | J33: =J15/(J$22 - SUM(J4:J6)) -> 0 | K33: =K15/(K$22 - SUM(K4:K6)) -> 0.2
A34: OASDI | B34: =B16/(B$22-SUM(B4:B6)) -> 0.069269663 | C34: =C16/(C$22-SUM(C5:C6)) -> 0.062000156 | D34: =D16/(D$22-SUM(D4:D6)) -> 0.0595 | E34: =E16/(E$22-SUM(E4:E6)) -> 0.0595 | F34: =F16/(F$22-SUM(F4:F6)) -> 0.0595 | G34: =G16/(G$22-SUM(G4:G6)) -> 0.0595 | H34: =H16/(H$22-SUM(H4:H6)) -> 0.0595 | I34: =I16/(I$22-SUM(I4:I6)) -> 0.0595 | J34: =J16/(J$22-SUM(J4:J6)) -> 0.0595 | K34: =K16/(K$22-SUM(K4:K6)) -> 0.0595
A35: VA State Tax | B35: =B17/B$22 -> 0.040170983 | C35: =C17/C$22 -> 0.054579259 | D35: =D17/D$22 -> 0.048164213 | E35: =E17/E$22 -> 0.048164213 | F35: =F17/F$22 -> 0.048164213 | G35: =G17/G$22 -> 0.048164213 | H35: =H17/H$22 -> 0.048164213 | I35: =I17/I$22 -> 0.048164213 | ... K35: =K17/K$22 -> 0
A36: AZ State Tax | B36: =B18/B$22 -> 0.034646299 | C36: =C18/C$22 -> 0.035999806 | D36: =D18/D$22 -> 0.034266049 | E36: =E18/E$22 -> 0.034266049 | F36: =F18/F$22 -> 0.034266049 | G36: =G18/G$22 -> 0.034266049 | H36: =H18/H$22 -> 0.034266049 | I36: =I18/I$22 -> 0.034266049 | ... K36: =K18/K$22 -> 0.034266049
A37: Supplemental Accident Coverage | B37: =B19/B$22 -> 0.00041293986 | D37: =D19/D$22 -> 0.0005289501 | E37: =E19/E$22 -> 0.0005289501 | F37: =F19/F$22 -> 0.0005289501 | G37: =G19/G$22 -> 0.0005289501 | H37: =H19/H$22 -> 0.0005289501 | I37: =I19/I$22 -> 0.0005289501 | J37: =J19/J$22 -> 0.0005289501 | K37: =K19/K$22 -> 0.0005289501
A38: Vision Coverage | B38: =B20/B$22 -> 0.00097815129 | D38: =D20/D$22 -> 0.0012529505 | E38: =E20/E$22 -> 0.0012529505 | F38: =F20/F$22 -> 0.0012529505 | G38: =G20/G$22 -> 0.0012529505 | H38: =H20/H$22 -> 0.0012529505 | I38: =I20/I$22 -> 0.0012529505 | J38: =J20/J$22 -> 0.0012529505 | K38: =K20/K$22 -> 0.0012529505
B40: =0.04*D7 -> 120
B41: =B40*26 -> 3120
B42: =B15/B41 -> 1.1153846
B45: =B25/B22 -> 0.61931687

Sheet Earnings Projection
F1: Sean Age | G1: 30 | H1: =31 -> 31 | I1: =H1+1 -> 32 | J1: =I1+1 -> 33 | K1: =J1+1 -> 34 | L1: =K1+1 -> 35 | M1: =L1+1 -> 36 | N1: =M1+1 -> 37 | O1: =N1+1 -> 38 | P1: =O1+1 -> 39 | ... AU1: =AT1+1 -> 70
F2: Vincent Age | G2: 27 | H2: =28 -> 28 | I2: =H2+1 -> 29 | J2: =I2+1 -> 30 | K2: =J2+1 -> 31 | L2: =K2+1 -> 32 | M2: =L2+1 -> 33 | N2: =M2+1 -> 34 | O2: =N2+1 -> 35 | P2: =O2+1 -> 36 | ... AU2: =AT2+1 -> 67
A4: Assumptions | B4: Sean | C4: Vincent | G4: 2020 | H4: =2021 -> 2021 | I4: =H4+1 -> 2022 | J4: =I4+1 -> 2023 | K4: =J4+1 -> 2024 | L4: =K4+1 -> 2025 | M4: =L4+1 -> 2026 | N4: =M4+1 -> 2027 | O4: =N4+1 -> 2028 | P4: =O4+1 -> 2029 | ... AC4: =AB4+1 -> 2042
A5: Starting Level | F5: Earnings
A6: Bi Weekly Salary | B6: 3024.86 | F6: Sean | G6: 61641.86 | H6: 78000 | I6: =H6*1.02+H7 -> 81560 | J6: =I6*1.02+I7 -> 90191.2 | K6: =J6*1.02+J7 -> 95495.024 | L6: =K6*1.02+K7 -> 100904.92 | M6: =L6*1.02+L7 -> 102923.02 | N6: =M6*1.02+M7 -> 104981.48 | O6: =N6*1.02+N7 -> 107081.11 | P6: =O6*1.02+O7 -> 109222.74 | Q6: =P6*1.02+P7 -> 111407.19
A7: Starting Salary | B7: 78000 | C7: 165000 | F7: Exam Bonus | H7: 2000 | I7: =3500*2 -> 7000 | J7: 3500 | K7: 3500
A8: Starting Equity | F8: First Attempt Bonus | H8: 1200
A9: Bonus Level
A10: Pay Schedule | B10: Bi-weekly | C10: Bi-weekly | F10: Gross Total | G10: =SUM(G6:G8) -> 61641.86 | H10: =SUM(H6:H8) -> 81200 | I10: =SUM(I6:I8) -> 88560 | J10: =SUM(J6:J8) -> 93691.2 | K10: =SUM(K6:K8) -> 98995.024 | L10: =SUM(L6:L8) -> 100904.92 | M10: =SUM(M6:M8) -> 102923.02 | N10: =SUM(N6:N8) -> 104981.48 | ... Q10: =SUM(Q6:Q8) -> 111407.19
A11: State | B11: AZ | C11: CA
A12: Company 401K Match | B12: =50%*MIN(SUM(B22:B23),8%) -> 0.04 | F12: Vincent | G12: 159830.34 | H12: =144678.82*12/10.5 -> 165347.22 | I12: =H12*1.02 -> 168654.17 | J12: =I12*1.02 -> 172027.25 | K12: =J12*1.02 -> 175467.8 | L12: =K12*1.02 -> 178977.15 | M12: =L12*1.02 -> 182556.69 | N12: =M12*1.02 -> 186207.83 | O12: =N12*1.02 -> 189931.99 | P12: =O12*1.02 -> 193730.62 | Q12: =P12*1.02 -> 197605.24
A13: Medical | B13: 0.015 | C13: 0.015 | F13: Bonus | G13: 18293 | H13: 16463 | I13: =H13 -> 16463 | J13: =I13 -> 16463 | K13: =J13 -> 16463 | L13: =K13 -> 16463 | M13: =L13 -> 16463 | N13: =M13 -> 16463 | O13: =N13 -> 16463 | P13: =O13 -> 16463 | Q13: =P13 -> 16463
A14: Dental | B14: 0 | C14: Company | F14: Stock Vest | G14: 70160.4 | H14: 80954.24 | I14: =H14 -> 80954.24 | J14: 0 | K14: 0 | L14: 0 | M14: 1 | N14: 2 | O14: 3 | P14: 4 | Q14: 5
A15: Vision | B15: 0.001 | C15: Company
A16: Starting 401K Contribution Base | F16: Gross Total | G16: =SUM(G12:G13) -> 178123.34 | H16: =SUM(H12:H13) -> 181810.22 | I16: =SUM(I12:I13) -> 185117.17 | J16: =SUM(J12:J13) -> 188490.25 | K16: =SUM(K12:K13) -> 191930.8 | L16: =SUM(L12:L13) -> 195440.15 | M16: =SUM(M12:M13) -> 199019.69 | N16: =SUM(N12:N13) -> 202670.83 | ... Q16: =SUM(Q12:Q13) -> 214068.24
A17: Federal Tax Rate | B17: 0.133 | C17: 0.32
A18: State Tax Rate | B18: 0.035 | C18: 0.17 | F18: Combined Total | G18: =G16+G10 -> 239765.2 | H18: =H16+H10 -> 263010.22 | I18: =I16+I10 -> 273677.17 | J18: =J16+J10 -> 282181.45 | K18: =K16+K10 -> 290925.82 | L18: =L16+L10 -> 296345.08 | M18: =M16+M10 -> 301942.72 | N18: =N16+N10 -> 307652.31 | ... Q18: =Q16+Q10 -> 325475.43
A19: OASDI | B19: =6.9% -> 0.069 | C19: =6.9% -> 0.069
A20: Medicare | B20: 0.014 | C20: 0.014
A21: HSA | B21: 0.014 | F21: Pre Tax Deductions
A22: 401k Pre Tax | B22: 0.08 | F22: HSA | G22: 2066.1 | H22: 2890 | I22: 2890 | J22: 2890 | K22: 2890 | L22: 2890 | M22: 2890 | N22: 2890 | O22: 2890 | P22: 2890 | Q22: 2890
A23: 401k Roth | B23: 0.08 | F23: Medical | G23: 2028 | H23: =87*26 -> 2262 | I23: =87*26 -> 2262 | J23: =87*26 -> 2262 | K23: =87*26 -> 2262 | L23: =87*26 -> 2262 | M23: =87*26 -> 2262 | N23: =87*26 -> 2262 | O23: =87*26 -> 2262 | ... Q23: =87*26 -> 2262
A24: Charity | B24: =38.47/B6 -> 0.012717944 | F24: Vision | G24: 72.54 | H24: =3.79*26 -> 98.54 | I24: =3.79*26 -> 98.54 | J24: =3.79*26 -> 98.54 | K24: =3.79*26 -> 98.54 | L24: =3.79*26 -> 98.54 | M24: =3.79*26 -> 98.54 | N24: =3.79*26 -> 98.54 | O24: =3.79*26 -> 98.54 | ... Q24: =3.79*26 -> 98.54
A25: return net inflation | B25: 0.05 | C25: 0.05 | F25: Dental | G25: 158.97
F26: 401K | G26: 1069.66
F27: Legal | G27: 216.06
F28: Group Life | G28: 58.27
F30: Total - Sean | G30: =SUM(G22:G28) -> 5669.6 | H30: =SUM(H22:H26) -> 5250.54 | I30: =SUM(I22:I26) -> 5250.54 | J30: =SUM(J22:J26) -> 5250.54 | K30: =SUM(K22:K26) -> 5250.54 | L30: =SUM(L22:L26) -> 5250.54 | M30: =SUM(M22:M26) -> 5250.54 | N30: =SUM(N22:N26) -> 5250.54 | O30: =SUM(O22:O26) -> 5250.54 | ... Q30: =SUM(Q22:Q26) -> 5250.54
A32: Hard Coded | F32: HDHP | G32: 0 | H32: 0 | I32: =7500 -> 7500 | J32: =7500 -> 7500 | K32: =7500 -> 7500 | L32: =7500 -> 7500 | M32: =7500 -> 7500 | N32: =7500 -> 7500 | O32: =7500 -> 7500 | P32: =7500 -> 7500 | Q32: =7500 -> 7500
A33: Actual | F33: Medical | G33: =650+20+149.76+126.88 -> 946.64 | H33: =132.48*12/10.5 -> 151.40571 | I33: 0 | J33: 0 | K33: 0 | L33: 0 | M33: 0 | N33: 0 | O33: 0 | P33: 0 | Q33: 0
A34: Prediction | D34: =G34/G12 -> 0.12200437 | F34: 401K | G34: 19500 | H34: 19500 | I34: 20500 | J34: 20500 | K34: 20500 | L34: 20500 | M34: 20500 | N34: 20500 | O34: 20500 | P34: 20500 | Q34: 20500
F36: Total - Vincent | G36: =SUM(G32:G34) -> 20446.64 | H36: =SUM(H32:H34) -> 19651.406 | I36: =SUM(I32:I34) -> 28000 | J36: =SUM(J32:J34) -> 28000 | K36: =SUM(K32:K34) -> 28000 | L36: =SUM(L32:L34) -> 28000 | M36: =SUM(M32:M34) -> 28000 | N36: =SUM(N32:N34) -> 28000 | ... Q36: =SUM(Q32:Q34) -> 28000
A37: Summary
F38: Taxable Income
A39: Sean | F39: Sean | G39: =G10-G30 -> 55972.26 | H39: =H10-H30 -> 75949.46 | I39: =I10-I30 -> 83309.46 | J39: =J10-J30 -> 88440.66 | K39: =K10-K30 -> 93744.484 | L39: =L10-L30 -> 95654.384 | M39: =M10-M30 -> 97672.483 | N39: =N10-N30 -> 99730.943 | ... Q39: =Q10-Q30 -> 106156.65
A40: Vincent | F40: Vincent | G40: =G16-G36 -> 157676.7 | H40: =H16-H36 -> 162158.82 | I40: =I16-I36 -> 157117.17 | J40: =J16-J36 -> 160490.25 | K40: =K16-K36 -> 163930.8 | L40: =L16-L36 -> 167440.15 | M40: =M16-M36 -> 171019.69 | N40: =N16-N36 -> 174670.83 | ... Q40: =Q16-Q36 -> 186068.24
A41: Combined
F42: Taxes
D43: =H43/H39 -> 0.133 | F43: Federal Taxes | H43: =INDEX(Federal_Tax_Rate,1)*H39 -> 10101.278 | I43: =INDEX(Federal_Tax_Rate,1)*I39 -> 11080.158 | J43: =INDEX(Federal_Tax_Rate,1)*J39 -> 11762.608 | K43: =INDEX(Federal_Tax_Rate,1)*K39 -> 12468.016 | L43: =INDEX(Federal_Tax_Rate,1)*L39 -> 12722.033 | M43: =INDEX(Federal_Tax_Rate,1)*M39 -> 12990.44 | N43: =INDEX(Federal_Tax_Rate,1)*N39 -> 13264.215 | O43: =INDEX(Federal_Tax_Rate,1)*O39 -> 13543.466 | ... Q43: =INDEX(Federal_Tax_Rate,1)*Q39 -> 14118.834
D44: =H44/H39 -> 0.035 | F44: State Taxes | H44: =INDEX(State_Tax_Rate,1)*H39 -> 2658.2311 | I44: =INDEX(State_Tax_Rate,1)*I39 -> 2915.8311 | J44: =INDEX(State_Tax_Rate,1)*J39 -> 3095.4231 | K44: =INDEX(State_Tax_Rate,1)*K39 -> 3281.0569 | L44: =INDEX(State_Tax_Rate,1)*L39 -> 3347.9035 | M44: =INDEX(State_Tax_Rate,1)*M39 -> 3418.5369 | N44: =INDEX(State_Tax_Rate,1)*N39 -> 3490.583 | O44: =INDEX(State_Tax_Rate,1)*O39 -> 3564.0701 | ... Q44: =INDEX(State_Tax_Rate,1)*Q39 -> 3715.4828
...

Sheet Retirement
V1: return | W1: 0.05
D2: =O2*13 -> 78000 | H2: =19500/(H6+H6*0.04) -> 3.125 | O2: =O6*2 -> 6000 | P2: 0.12 | Q2: =Q7*2 -> 756 | S2: =O2-Q2 -> 5244 | V2: inflation | W2: 0
D3: =O3*13 -> 49140 | O3: =O2*(0.63) -> 3780 | Q3: =Q2 -> 756 | S3: =O3-Q3 -> 3024 | V3: return net inflation | W3: =W1-W2 -> 0.05
A4: =COUNTA(A6:A42) -> 37 | D4: Annual Salary | J4: Monthly Contributions
A5: Age | B5: Year | C5: Bonus/Exams | D5: (Assume 2% growth in salary) | G5: Net Annual Salary | H5: Monthly Salary | I5: Monthly Net Salary | J5: of Net Salary | K5: Leftover | L5: Monthly Leftover | M5: Projected rent (.33 Net salary) | N5: Net Leftover | O5: Bi Weekly Salary | P5: Contribution % | Q5: Bi Weekly Contributions | R5: Yearly Contributions | S5: Weekly Employer Match | T5: Yearly Employer Match | V5: Total + Match | W5: Cumulative | X5: Multiplier
A6: =31 -> 31 | B6: 2021 | D6: =O6*26 -> 78000 | G6: =D6*0.63 -> 49140 | H6: =O6*2 -> 6000 | I6: =G6/13 -> 3780 | O6: 3000 | P6: 0.08 | R6: 3120 | T6: 960 | V6: =T6+R6 -> 4080 | W6: =FV(W3/12,12,-1*V6/12) -> 4174.8109 | Y6: =$Y$43/(1+0.04)^(67-A6) -> 548254.62
A7: =A6+1 -> 32 | B7: =B6+1 -> 2022 | D7: =D6*1.05+C7 -> 81900 | G7: =D7*0.63 -> 51597 | H7: =O7*2 -> 6300 | I7: =G7/13 -> 3969 | J7: =Q7*2 -> 756 | K7: =I7-J7 -> 3213 | L7: =K7*12 -> 38556 | M7: =G7*0.33 -> 17027.01 | N7: =L7-M7 -> 21528.99 | O7: =D7/26 -> 3150 | P7: =$P$2 -> 0.12 | Q7: =P7*O7 -> 378 | R7: =Q7*26 -> 9828 | S7: =MIN(Q7*0.5, O7*0.08*0.5) -> 126 | T7: =S7*26 -> 3276 | V7: =MIN(T7+R7,19500) -> 13104 | W7: =FV($W$3/12,12,-1*V7/12,-1*W6) -> 17796.912 | Y7: =$Y$43/(1+0.04)^(67-A7) -> 570184.81
A8: =A7+1 -> 33 | B8: =B7+1 -> 2023 | D8: =D7*1.02+C8 -> 83538 | G8: =D8*0.63 -> 52628.94 | H8: =O8*2 -> 6426 | I8: =G8/13 -> 4048.38 | J8: =Q8*2 -> 771.12 | K8: =I8-J8 -> 3277.26 | L8: =K8*12 -> 39327.12 | M8: =G8*0.33 -> 17367.55 | N8: =L8-M8 -> 21959.57 | O8: =D8/26 -> 3213 | P8: =$P$2 -> 0.12 | Q8: =P8*O8 -> 385.56 | R8: =Q8*26 -> 10024.56 | S8: =MIN(Q8*0.5, O8*0.08*0.5) -> 128.52 | T8: =S8*26 -> 3341.52 | V8: =MIN(T8+R8,19500) -> 13366.08 | W8: =FV($W$3/12,12,-1*V8/12,-1*W7) -> 32384.117 | Y8: =$Y$43/(1+0.04)^(67-A8) -> 592992.2
A9: =A8+1 -> 34 | B9: =B8+1 -> 2024 | D9: =D8*1.02+C9 -> 85208.76 | G9: =D9*0.63 -> 53681.519 | H9: =O9*2 -> 6554.52 | I9: =G9/13 -> 4129.3476 | J9: =Q9*2 -> 786.5424 | K9: =I9-J9 -> 3342.8052 | L9: =K9*12 -> 40113.662 | M9: =G9*0.33 -> 17714.901 | N9: =L9-M9 -> 22398.761 | O9: =D9/26 -> 3277.26 | P9: =$P$2 -> 0.12 | Q9: =P9*O9 -> 393.2712 | R9: =Q9*26 -> 10225.051 | S9: =MIN(Q9*0.5, O9*0.08*0.5) -> 131.0904 | T9: =S9*26 -> 3408.3504 | V9: =MIN(T9+R9,19500) -> 13633.402 | W9: =FV($W$3/12,12,-1*V9/12,-1*W8) -> 47991.163 | Y9: =$Y$43/(1+0.04)^(67-A9) -> 616711.89
A10: =A9+1 -> 35 | B10: =B9+1 -> 2025 | D10: =D9*1.02+C10 -> 86912.935 | E10: 2.1 | F10: =D10*2.1 -> 182517.16 | G10: =D10*0.63 -> 54755.149 | H10: =O10*2 -> 6685.6104 | I10: =G10/13 -> 4211.9346 | J10: =Q10*2 -> 802.27325 | K10: =I10-J10 -> 3409.6613 | L10: =K10*12 -> 40915.936 | M10: =G10*0.33 -> 18069.199 | N10: =L10-M10 -> 22846.736 | O10: =D10/26 -> 3342.8052 | P10: =$P$2 -> 0.12 | Q10: =P10*O10 -> 401.13662 | R10: =Q10*26 -> 10429.552 | S10: =MIN(Q10*0.5, O10*0.08*0.5) -> 133.71221 | T10: =S10*26 -> 3476.5174 | V10: =MIN(T10+R10,19500) -> 13906.07 | W10: =FV($W$3/12,12,-1*V10/12,-1*W9) -> 64675.701 | X10: =W10/F10-1 -> -0.64564593 | Y10: =$Y$43/(1+0.04)^(67-A10) -> 641380.37
A11: =A10+1 -> 36 | B11: =B10+1 -> 2026 | D11: =D10*1.02+C11 -> 88651.194 | G11: =D11*0.63 -> 55850.252 | H11: =O11*2 -> 6819.3226 | I11: =G11/13 -> 4296.1732 | J11: =Q11*2 -> 818.31871 | K11: =I11-J11 -> 3477.8545 | L11: =K11*12 -> 41734.254 | M11: =G11*0.33 -> 18430.583 | N11: =L11-M11 -> 23303.671 | O11: =D11/26 -> 3409.6613 | P11: =$P$2 -> 0.12 | Q11: =P11*O11 -> 409.15936 | R11: =Q11*26 -> 10638.143 | S11: =MIN(Q11*0.5, O11*0.08*0.5) -> 136.38645 | T11: =S11*26 -> 3546.0478 | V11: =MIN(T11+R11,19500) -> 14184.191 | W11: =FV($W$3/12,12,-1*V11/12,-1*W10) -> 82498.435 | Y11: =$Y$43/(1+0.04)^(67-A11) -> 667035.58
A12: =A11+1 -> 37 | B12: =B11+1 -> 2027 | D12: =D11*1.02+C12 -> 90424.218 | G12: =D12*0.63 -> 56967.257 | H12: =O12*2 -> 6955.7091 | I12: =G12/13 -> 4382.0967 | J12: =Q12*2 -> 834.68509 | K12: =I12-J12 -> 3547.4116 | L12: =K12*12 -> 42568.939 | M12: =G12*0.33 -> 18799.195 | N12: =L12-M12 -> 23769.745 | O12: =D12/26 -> 3477.8545 | P12: =$P$2 -> 0.12 | Q12: =P12*O12 -> 417.34254 | R12: =Q12*26 -> 10850.906 | S12: =MIN(Q12*0.5, O12*0.08*0.5) -> 139.11418 | T12: =S12*26 -> 3616.9687 | V12: =MIN(T12+R12,19500) -> 14467.875 | W12: =FV($W$3/12,12,-1*V12/12,-1*W11) -> 101523.29 | Y12: =$Y$43/(1+0.04)^(67-A12) -> 693717
A13: =A12+1 -> 38 | B13: =B12+1 -> 2028 | D13: =D12*1.02+C13 -> 92232.702 | G13: =D13*0.63 -> 58106.602 | H13: =O13*2 -> 7094.8232 | I13: =G13/13 -> 4469.7386 | J13: =Q13*2 -> 851.37879 | K13: =I13-J13 -> 3618.3599 | L13: =K13*12 -> 43420.318 | M13: =G13*0.33 -> 19175.179 | N13: =L13-M13 -> 24245.139 | O13: =D13/26 -> 3547.4116 | P13: =$P$2 -> 0.12 | Q13: =P13*O13 -> 425.68939 | R13: =Q13*26 -> 11067.924 | S13: =MIN(Q13*0.5, O13*0.08*0.5) -> 141.89646 | T13: =S13*26 -> 3689.3081 | V13: =MIN(T13+R13,19500) -> 14757.232 | W13: =FV($W$3/12,12,-1*V13/12,-1*W12) -> 121817.57 | Y13: =$Y$43/(1+0.04)^(67-A13) -> 721465.68
A14: =A13+1 -> 39 | B14: =B13+1 -> 2029 | D14: =D13*1.02+C14 -> 94077.356 | G14: =D14*0.63 -> 59268.734 | H14: =O14*2 -> 7236.7197 | I14: =G14/13 -> 4559.1334 | J14: =Q14*2 -> 868.40636 | K14: =I14-J14 -> 3690.7271 | L14: =K14*12 -> 44288.725 | M14: =G14*0.33 -> 19558.682 | N14: =L14-M14 -> 24730.042 | O14: =D14/26 -> 3618.3599 | P14: =$P$2 -> 0.12 | Q14: =P14*O14 -> 434.20318 | R14: =Q14*26 -> 11289.283 | S14: =MIN(Q14*0.5, O14*0.08*0.5) -> 144.73439 | T14: =S14*26 -> 3763.0942 | V14: =MIN(T14+R14,19500) -> 15052.377 | W14: =FV($W$3/12,12,-1*V14/12,-1*W13) -> 143452.16 | Y14: =$Y$43/(1+0.04)^(67-A14) -> 750324.31
A15: =A14+1 -> 40 | B15: =B14+1 -> 2030 | D15: =D14*1.02+C15 -> 95958.903 | E15: 3 | F15: =E15*D15 -> 287876.71 | G15: =D15*0.63 -> 60454.109 | H15: =O15*2 -> 7381.4541 | I15: =G15/13 -> 4650.3161 | J15: =Q15*2 -> 885.77449 | K15: =I15-J15 -> 3764.5416 | L15: =K15*12 -> 45174.499 | M15: =G15*0.33 -> 19949.856 | N15: =L15-M15 -> 25224.643 | O15: =D15/26 -> 3690.7271 | P15: =$P$2 -> 0.12 | Q15: =P15*O15 -> 442.88725 | R15: =Q15*26 -> 11515.068 | S15: =MIN(Q15*0.5, O15*0.08*0.5) -> 147.62908 | T15: =S15*26 -> 3838.3561 | V15: =MIN(T15+R15,19500) -> 15353.425 | W15: =FV($W$3/12,12,-1*V15/12,-1*W14) -> 166501.65 | X15: =W15/F15-1 -> -0.42162168 | Y15: =$Y$43/(1+0.04)^(67-A15) -> 780337.28
A16: =A15+1 -> 41 | B16: =B15+1 -> 2031 | D16: =D15*1.02+C16 -> 97878.081 | G16: =D16*0.63 -> 61663.191 | H16: =O16*2 -> 7529.0832 | I16: =G16/13 -> 4743.3224 | J16: =Q16*2 -> 903.48998 | K16: =I16-J16 -> 3839.8324 | L16: =K16*12 -> 46077.989 | M16: =G16*0.33 -> 20348.853 | N16: =L16-M16 -> 25729.136 | O16: =D16/26 -> 3764.5416 | P16: =$P$2 -> 0.12 | Q16: =P16*O16 -> 451.74499 | R16: =Q16*26 -> 11745.37 | S16: =MIN(Q16*0.5, O16*0.08*0.5) -> 150.58166 | T16: =S16*26 -> 3915.1233 | V16: =MIN(T16+R16,19500) -> 15660.493 | W16: =FV($W$3/12,12,-1*V16/12,-1*W15) -> 191044.6 | Y16: =$Y$43/(1+0.04)^(67-A16) -> 811550.77
A17: =A16+1 -> 42 | B17: =B16+1 -> 2032 | D17: =D16*1.02+C17 -> 99835.643 | G17: =D17*0.63 -> 62896.455 | H17: =O17*2 -> 7679.6648 | I17: =G17/13 -> 4838.1889 | J17: =Q17*2 -> 921.55978 | K17: =I17-J17 -> 3916.6291 | L17: =K17*12 -> 46999.549 | M17: =G17*0.33 -> 20755.83 | N17: =L17-M17 -> 26243.719 | O17: =D17/26 -> 3839.8324 | P17: =$P$2 -> 0.12 | Q17: =P17*O17 -> 460.77989 | R17: =Q17*26 -> 11980.277 | S17: =MIN(Q17*0.5, O17*0.08*0.5) -> 153.5933 | T17: =S17*26 -> 3993.4257 | V17: =MIN(T17+R17,19500) -> 15973.703 | W17: =FV($W$3/12,12,-1*V17/12,-1*W16) -> 217163.7 | Y17: =$Y$43/(1+0.04)^(67-A17) -> 844012.81
A18: =A17+1 -> 43 | B18: =B17+1 -> 2033 | D18: =D17*1.02+C18 -> 101832.36 | G18: =D18*0.63 -> 64154.384 | H18: =O18*2 -> 7833.2581 | I18: =G18/13 -> 4934.9526 | J18: =Q18*2 -> 939.99098 | K18: =I18-J18 -> 3994.9617 | L18: =K18*12 -> 47939.54 | M18: =G18*0.33 -> 21170.947 | N18: =L18-M18 -> 26768.593 | O18: =D18/26 -> 3916.6291 | P18: =$P$2 -> 0.12 | Q18: =P18*O18 -> 469.99549 | R18: =Q18*26 -> 12219.883 | S18: =MIN(Q18*0.5, O18*0.08*0.5) -> 156.66516 | T18: =S18*26 -> 4073.2942 | V18: =MIN(T18+R18,19500) -> 16293.177 | W18: =FV($W$3/12,12,-1*V18/12,-1*W17) -> 244946.01 | Y18: =$Y$43/(1+0.04)^(67-A18) -> 877773.32
A19: =A18+1 -> 44 | B19: =B18+1 -> 2034 | D19: =D18*1.02+C19 -> 103869 | G19: =D19*0.63 -> 65437.472 | H19: =O19*2 -> 7989.9233 | I19: =G19/13 -> 5033.6517 | J19: =Q19*2 -> 958.7908 | K19: =I19-J19 -> 4074.8609 | L19: =K19*12 -> 48898.331 | M19: =G19*0.33 -> 21594.366 | N19: =L19-M19 -> 27303.965 | O19: =D19/26 -> 3994.9617 | P19: =$P$2 -> 0.12 | Q19: =P19*O19 -> 479.3954 | R19: =Q19*26 -> 12464.28 | S19: =MIN(Q19*0.5, O19*0.08*0.5) -> 159.79847 | T19: =S19*26 -> 4154.7601 | V19: =MIN(T19+R19,19500) -> 16619.04 | W19: =FV($W$3/12,12,-1*V19/12,-1*W18) -> 274483.14 | Y19: =$Y$43/(1+0.04)^(67-A19) -> 912884.25
A20: =A19+1 -> 45 | B20: =B19+1 -> 2035 | D20: =D19*1.02+C20 -> 105946.38 | E20: 3.8 | F20: =E20*D20 -> 402596.26 | G20: =D20*0.63 -> 66746.221 | H20: =O20*2 -> 8149.7218 | I20: =G20/13 -> 5134.3247 | J20: =Q20*2 -> 977.96661 | K20: =I20-J20 -> 4156.3581 | L20: =K20*12 -> 49876.297 | M20: =G20*0.33 -> 22026.253 | N20: =L20-M20 -> 27850.044 | O20: =D20/26 -> 4074.8609 | P20: =$P$2 -> 0.12 | Q20: =P20*O20 -> 488.98331 | R20: =Q20*26 -> 12713.566 | S20: =MIN(Q20*0.5, O20*0.08*0.5) -> 162.99444 | T20: =S20*26 -> 4237.8553 | V20: =MIN(T20+R20,19500) -> 16951.421 | W20: =FV($W$3/12,12,-1*V20/12,-1*W19) -> 305871.56 | X20: =W20/F20-1 -> -0.24025235 | Y20: =$Y$43/(1+0.04)^(67-A20) -> 949399.62
A21: =A20+1 -> 46 | B21: =B20+1 -> 2036 | D21: =D20*1.02+C21 -> 108065.31 | G21: =D21*0.63 -> 68081.146 | H21: =O21*2 -> 8312.7162 | I21: =G21/13 -> 5237.0112 | J21: =Q21*2 -> 997.52594 | K21: =I21-J21 -> 4239.4853 | L21: =K21*12 -> 50873.823 | M21: =G21*0.33 -> 22466.778 | N21: =L21-M21 -> 28407.045 | O21: =D21/26 -> 4156.3581 | P21: =$P$2 -> 0.12 | Q21: =P21*O21 -> 498.76297 | R21: =Q21*26 -> 12967.837 | S21: =MIN(Q21*0.5, O21*0.08*0.5) -> 166.25432 | T21: =S21*26 -> 4322.6124 | V21: =MIN(T21+R21,19500) -> 17290.45 | W21: =FV($W$3/12,12,-1*V21/12,-1*W20) -> 339212.77 | Y21: =$Y$43/(1+0.04)^(67-A21) -> 987375.6
A22: =A21+1 -> 47 | B22: =B21+1 -> 2037 | D22: =D21*1.02+C22 -> 110226.62 | G22: =D22*0.63 -> 69442.769 | H22: =O22*2 -> 8478.9705 | I22: =G22/13 -> 5341.7514 | J22: =Q22*2 -> 1017.4765 | K22: =I22-J22 -> 4324.275 | L22: =K22*12 -> 51891.3 | M22: =G22*0.33 -> 22916.114 | N22: =L22-M22 -> 28975.186 | O22: =D22/26 -> 4239.4853 | P22: =$P$2 -> 0.12 | Q22: =P22*O22 -> 508.73823 | R22: =Q22*26 -> 13227.194 | S22: =MIN(Q22*0.5, O22*0.08*0.5) -> 169.57941 | T22: =S22*26 -> 4409.0647 | V22: =MIN(T22+R22,19500) -> 17636.259 | W22: =FV($W$3/12,12,-1*V22/12,-1*W21) -> 374613.63 | Y22: =$Y$43/(1+0.04)^(67-A22) -> 1026870.6
A23: =A22+1 -> 48 | B23: =B22+1 -> 2038 | D23: =D22*1.02+C23 -> 112431.15 | G23: =D23*0.63 -> 70831.624 | H23: =O23*2 -> 8648.5499 | I23: =G23/13 -> 5448.5865 | J23: =Q23*2 -> 1037.826 | K23: =I23-J23 -> 4410.7605 | L23: =K23*12 -> 52929.126 | M23: =G23*0.33 -> 23374.436 | N23: =L23-M23 -> 29554.69 | O23: =D23/26 -> 4324.275 | P23: =$P$2 -> 0.12 | Q23: =P23*O23 -> 518.913 | R23: =Q23*26 -> 13491.738 | S23: =MIN(Q23*0.5, O23*0.08*0.5) -> 172.971 | T23: =S23*26 -> 4497.246 | V23: =MIN(T23+R23,19500) -> 17988.984 | W23: =FV($W$3/12,12,-1*V23/12,-1*W22) -> 412186.59 | Y23: =$Y$43/(1+0.04)^(67-A23) -> 1067945.5
A24: =A23+1 -> 49 | B24: =B23+1 -> 2039 | D24: =D23*1.02+C24 -> 114679.77 | G24: =D24*0.63 -> 72248.257 | H24: =O24*2 -> 8821.5209 | I24: =G24/13 -> 5557.5582 | J24: =Q24*2 -> 1058.5825 | K24: =I24-J24 -> 4498.9757 | L24: =K24*12 -> 53987.708 | M24: =G24*0.33 -> 23841.925 | N24: =L24-M24 -> 30145.784 | O24: =D24/26 -> 4410.7605 | P24: =$P$2 -> 0.12 | Q24: =P24*O24 -> 529.29126 | R24: =Q24*26 -> 13761.573 | S24: =MIN(Q24*0.5, O24*0.08*0.5) -> 176.43042 | T24: =S24*26 -> 4587.1909 | V24: =MIN(T24+R24,19500) -> 18348.764 | W24: =FV($W$3/12,12,-1*V24/12,-1*W23) -> 452049.99 | Y24: =$Y$43/(1+0.04)^(67-A24) -> 1110663.3
A25: =A24+1 -> 50 | B25: =B24+1 -> 2040 | D25: =D24*1.02+C25 -> 116973.37 | E25: 4.8 | F25: =E25*D25 -> 561472.16 | G25: =D25*0.63 -> 73693.222 | H25: =O25*2 -> 8997.9514 | I25: =G25/13 -> 5668.7094 | J25: =Q25*2 -> 1079.7542 | K25: =I25-J25 -> 4588.9552 | L25: =K25*12 -> 55067.462 | M25: =G25*0.33 -> 24318.763 | N25: =L25-M25 -> 30748.699 | O25: =D25/26 -> 4498.9757 | P25: =$P$2 -> 0.12 | Q25: =P25*O25 -> 539.87708 | R25: =Q25*26 -> 14036.804 | S25: =MIN(Q25*0.5, O25*0.08*0.5) -> 179.95903 | T25: =S25*26 -> 4678.9347 | V25: =MIN(T25+R25,26000) -> 18715.739 | W25: =FV($W$3/12,12,-1*V25/12,-1*W24) -> 494328.38 | X25: =W25/F25-1 -> -0.11958525 | Y25: =$Y$43/(1+0.04)^(67-A25) -> 1155089.8
A26: =A25+1 -> 51 | B26: =B25+1 -> 2041 | D26: =D25*1.02+C26 -> 119312.84 | G26: =D26*0.63 -> 75167.086 | H26: =O26*2 -> 9177.9104 | I26: =G26/13 -> 5782.0835 | J26: =Q26*2 -> 1101.3492 | K26: =I26-J26 -> 4680.7343 | L26: =K26*12 -> 56168.812 | M26: =G26*0.33 -> 24805.138 | N26: =L26-M26 -> 31363.673 | O26: =D26/26 -> 4588.9552 | P26: =$P$2 -> 0.12 | Q26: =P26*O26 -> 550.67462 | R26: =Q26*26 -> 14317.54 | S26: =MIN(Q26*0.5, O26*0.08*0.5) -> 183.55821 | T26: =S26*26 -> 4772.5134 | V26: =MIN(T26+R26,26000) -> 19090.054 | W26: =FV($W$3/12,12,-1*V26/12,-1*W25) -> 539152.82 | Y26: =$Y$43/(1+0.04)^(67-A26) -> 1201293.4
A27: =A26+1 -> 52 | B27: =B26+1 -> 2042 | D27: =D26*1.02+C27 -> 121699.09 | G27: =D27*0.63 -> 76670.428 | H27: =O27*2 -> 9361.4686 | I27: =G27/13 -> 5897.7252 | J27: =Q27*2 -> 1123.3762 | K27: =I27-J27 -> 4774.349 | L27: =K27*12 -> 57292.188 | M27: =G27*0.33 -> 25301.241 | N27: =L27-M27 -> 31990.947 | O27: =D27/26 -> 4680.7343 | P27: =$P$2 -> 0.12 | Q27: =P27*O27 -> 561.68812 | R27: =Q27*26 -> 14603.891 | S27: =MIN(Q27*0.5, O27*0.08*0.5) -> 187.22937 | T27: =S27*26 -> 4867.9637 | V27: =MIN(T27+R27,26000) -> 19471.855 | W27: =FV($W$3/12,12,-1*V27/12,-1*W26) -> 586661.24 | Y27: =$Y$43/(1+0.04)^(67-A27) -> 1249345.1
A28: =A27+1 -> 53 | B28: =B27+1 -> 2043 | D28: =D27*1.02+C28 -> 124133.07 | G28: =D28*0.63 -> 78203.836 | H28: =O28*2 -> 9548.698 | I28: =G28/13 -> 6015.6797 | J28: =Q28*2 -> 1145.8438 | K28: =I28-J28 -> 4869.836 | L28: =K28*12 -> 58438.032 | M28: =G28*0.33 -> 25807.266 | N28: =L28-M28 -> 32630.766 | O28: =D28/26 -> 4774.349 | P28: =$P$2 -> 0.12 | Q28: =P28*O28 -> 572.92188 | R28: =Q28*26 -> 14895.969 | S28: =MIN(Q28*0.5, O28*0.08*0.5) -> 190.97396 | T28: =S28*26 -> 4965.3229 | V28: =MIN(T28+R28,26000) -> 19861.292 | W28: =FV($W$3/12,12,-1*V28/12,-1*W27) -> 636998.77 | Y28: =$Y$43/(1+0.04)^(67-A28) -> 1299318.9
A29: =A28+1 -> 54 | B29: =B28+1 -> 2044 | D29: =D28*1.02+C29 -> 126615.74 | G29: =D29*0.63 -> 79767.913 | H29: =O29*2 -> 9739.6719 | I29: =G29/13 -> 6135.9933 | J29: =Q29*2 -> 1168.7606 | K29: =I29-J29 -> 4967.2327 | L29: =K29*12 -> 59606.792 | M29: =G29*0.33 -> 26323.411 | N29: =L29-M29 -> 33283.381 | O29: =D29/26 -> 4869.836 | P29: =$P$2 -> 0.12 | Q29: =P29*O29 -> 584.38032 | R29: =Q29*26 -> 15193.888 | S29: =MIN(Q29*0.5, O29*0.08*0.5) -> 194.79344 | T29: =S29*26 -> 5064.6294 | V29: =MIN(T29+R29,26000) -> 20258.518 | W29: =FV($W$3/12,12,-1*V29/12,-1*W28) -> 690318.12 | Y29: =$Y$43/(1+0.04)^(67-A29) -> 1351291.7
A30: =A29+1 -> 55 | B30: =B29+1 -> 2045 | D30: =D29*1.02+C30 -> 129148.05 | E30: 6.1 | F30: =E30*D30 -> 787803.1 | G30: =D30*0.63 -> 81363.271 | H30: =O30*2 -> 9934.4654 | I30: =G30/13 -> 6258.7132 | J30: =Q30*2 -> 1192.1358 | K30: =I30-J30 -> 5066.5773 | L30: =K30*12 -> 60798.928 | M30: =G30*0.33 -> 26849.88 | N30: =L30-M30 -> 33949.048 | O30: =D30/26 -> 4967.2327 | P30: =$P$2 -> 0.12 | Q30: =P30*O30 -> 596.06792 | R30: =Q30*26 -> 15497.766 | S30: =MIN(Q30*0.5, O30*0.08*0.5) -> 198.68931 | T30: =S30*26 -> 5165.922 | V30: =MIN(T30+R30,26000) -> 20663.688 | W30: =FV($W$3/12,12,-1*V30/12,-1*W29) -> 746779.98 | X30: =W30/F30-1 -> -0.052072814 | Y30: =$Y$43/(1+0.04)^(67-A30) -> 1405343.4
A31: =A30+1 -> 56 | B31: =B30+1 -> 2046 | D31: =D30*1.02+C31 -> 131731.01 | G31: =D31*0.63 -> 82990.537 | H31: =O31*2 -> 10133.155 | I31: =G31/13 -> 6383.8874 | J31: =Q31*2 -> 1215.9786 | K31: =I31-J31 -> 5167.9089 | L31: =K31*12 -> 62014.907 | M31: =G31*0.33 -> 27386.877 | N31: =L31-M31 -> 34628.029 | O31: =D31/26 -> 5066.5773 | P31: =$P$2 -> 0.12 | Q31: =P31*O31 -> 607.98928 | R31: =Q31*26 -> 15807.721 | S31: =MIN(Q31*0.5, O31*0.08*0.5) -> 202.66309 | T31: =S31*26 -> 5269.2404 | V31: =MIN(T31+R31,26000) -> 21076.962 | W31: =FV($W$3/12,12,-1*V31/12,-1*W30) -> 806553.41 | Y31: =$Y$43/(1+0.04)^(67-A31) -> 1461557.1
A32: =A31+1 -> 57 | B32: =B31+1 -> 2047 | D32: =D31*1.02+C32 -> 134365.63 | G32: =D32*0.63 -> 84650.347 | H32: =O32*2 -> 10335.818 | I32: =G32/13 -> 6511.5652 | J32: =Q32*2 -> 1240.2981 | K32: =I32-J32 -> 5271.2671 | L32: =K32*12 -> 63255.205 | M32: =G32*0.33 -> 27934.615 | N32: =L32-M32 -> 35320.59 | O32: =D32/26 -> 5167.9089 | P32: =$P$2 -> 0.12 | Q32: =P32*O32 -> 620.14907 | R32: =Q32*26 -> 16123.876 | S32: =MIN(Q32*0.5, O32*0.08*0.5) -> 206.71636 | T32: =S32*26 -> 5374.6252 | V32: =MIN(T32+R32,26000) -> 21498.501 | W32: =FV($W$3/12,12,-1*V32/12,-1*W31) -> 869816.29 | Y32: =$Y$43/(1+0.04)^(67-A32) -> 1520019.4
A33: =A32+1 -> 58 | B33: =B32+1 -> 2048 | D33: =D32*1.02+C33 -> 137052.94 | G33: =D33*0.63 -> 86343.354 | H33: =O33*2 -> 10542.534 | I33: =G33/13 -> 6641.7965 | J33: =Q33*2 -> 1265.1041 | K33: =I33-J33 -> 5376.6924 | L33: =K33*12 -> 64520.309 | M33: =G33*0.33 -> 28493.307 | N33: =L33-M33 -> 36027.002 | O33: =D33/26 -> 5271.2671 | P33: =$P$2 -> 0.12 | Q33: =P33*O33 -> 632.55205 | R33: =Q33*26 -> 16446.353 | S33: =MIN(Q33*0.5, O33*0.08*0.5) -> 210.85068 | T33: =S33*26 -> 5482.1177 | V33: =MIN(T33+R33,26000) -> 21928.471 | W33: =FV($W$3/12,12,-1*V33/12,-1*W32) -> 936755.79 | Y33: =$Y$43/(1+0.04)^(67-A33) -> 1580820.2
A34: =A33+1 -> 59 | B34: =B33+1 -> 2049 | D34: =D33*1.02+C34 -> 139794 | G34: =D34*0.63 -> 88070.222 | H34: =O34*2 -> 10753.385 | I34: =G34/13 -> 6774.6324 | J34: =Q34*2 -> 1290.4062 | K34: =I34-J34 -> 5484.2262 | L34: =K34*12 -> 65810.715 | M34: =G34*0.33 -> 29063.173 | N34: =L34-M34 -> 36747.542 | O34: =D34/26 -> 5376.6924 | P34: =$P$2 -> 0.12 | Q34: =P34*O34 -> 645.20309 | R34: =Q34*26 -> 16775.28 | S34: =MIN(Q34*0.5, O34*0.08*0.5) -> 215.0677 | T34: =S34*26 -> 5591.7601 | V34: =MIN(T34+R34,26000) -> 22367.04 | W34: =FV($W$3/12,12,-1*V34/12,-1*W33) -> 1007568.8 | Y34: =$Y$43/(1+0.04)^(67-A34) -> 1644053
A35: =A34+1 -> 60 | B35: =B34+1 -> 2050 | D35: =D34*1.02+C35 -> 142589.88 | E35: 8 | F35: =E35*D35 -> 1140719.1 | G35: =D35*0.63 -> 89831.626 | H35: =O35*2 -> 10968.452 | I35: =G35/13 -> 6910.1251 | J35: =Q35*2 -> 1316.2143 | K35: =I35-J35 -> 5593.9108 | L35: =K35*12 -> 67126.929 | M35: =G35*0.33 -> 29644.437 | N35: =L35-M35 -> 37482.493 | O35: =D35/26 -> 5484.2262 | P35: =$P$2 -> 0.12 | Q35: =P35*O35 -> 658.10715 | R35: =Q35*26 -> 17110.786 | S35: =MIN(Q35*0.5, O35*0.08*0.5) -> 219.36905 | T35: =S35*26 -> 5703.5953 | V35: =MIN(T35+R35,26000) -> 22814.381 | W35: =FV($W$3/12,12,-1*V35/12,-1*W34) -> 1082462.5 | X35: =W35/F35-1 -> -0.051070059 | Y35: =$Y$43/(1+0.04)^(67-A35) -> 1709815.1
A36: =A35+1 -> 61 | B36: =B35+1 -> 2051 | D36: =D35*1.02+C36 -> 145441.68 | G36: =D36*0.63 -> 91628.258 | H36: =O36*2 -> 11187.822 | I36: =G36/13 -> 7048.3276 | J36: =Q36*2 -> 1342.5386 | K36: =I36-J36 -> 5705.789 | L36: =K36*12 -> 68469.468 | M36: =G36*0.33 -> 30237.325 | N36: =L36-M36 -> 38232.143 | O36: =D36/26 -> 5593.9108 | P36: =$P$2 -> 0.12 | Q36: =P36*O36 -> 671.26929 | R36: =Q36*26 -> 17453.002 | S36: =MIN(Q36*0.5, O36*0.08*0.5) -> 223.75643 | T36: =S36*26 -> 5817.6672 | V36: =MIN(T36+R36,26000) -> 23270.669 | W36: =FV($W$3/12,12,-1*V36/12,-1*W35) -> 1161654.7 | Y36: =$Y$43/(1+0.04)^(67-A36) -> 1778207.7
A37: =A36+1 -> 62 | B37: =B36+1 -> 2052 | D37: =D36*1.02+C37 -> 148350.51 | G37: =D37*0.63 -> 93460.824 | H37: =O37*2 -> 11411.578 | I37: =G37/13 -> 7189.2941 | J37: =Q37*2 -> 1369.3894 | K37: =I37-J37 -> 5819.9048 | L37: =K37*12 -> 69838.857 | M37: =G37*0.33 -> 30842.072 | N37: =L37-M37 -> 38996.785 | O37: =D37/26 -> 5705.789 | P37: =$P$2 -> 0.12 | Q37: =P37*O37 -> 684.69468 | R37: =Q37*26 -> 17802.062 | S37: =MIN(Q37*0.5, O37*0.08*0.5) -> 228.23156 | T37: =S37*26 -> 5934.0205 | V37: =MIN(T37+R37,26000) -> 23736.082 | W37: =FV($W$3/12,12,-1*V37/12,-1*W36) -> 1245374.9 | Y37: =$Y$43/(1+0.04)^(67-A37) -> 1849336
A38: =A37+1 -> 63 | B38: =B37+1 -> 2053 | D38: =D37*1.02+C38 -> 151317.52 | G38: =D38*0.63 -> 95330.04 | H38: =O38*2 -> 11639.81 | I38: =G38/13 -> 7333.08 | J38: =Q38*2 -> 1396.7771 | K38: =I38-J38 -> 5936.3029 | L38: =K38*12 -> 71235.634 | M38: =G38*0.33 -> 31458.913 | N38: =L38-M38 -> 39776.721 | O38: =D38/26 -> 5819.9048 | P38: =$P$2 -> 0.12 | Q38: =P38*O38 -> 698.38857 | R38: =Q38*26 -> 18158.103 | S38: =MIN(Q38*0.5, O38*0.08*0.5) -> 232.79619 | T38: =S38*26 -> 6052.701 | V38: =MIN(T38+R38,26000) -> 24210.804 | W38: =FV($W$3/12,12,-1*V38/12,-1*W37) -> 1333864 | Y38: =$Y$43/(1+0.04)^(67-A38) -> 1923309.4
A39: =A38+1 -> 64 | B39: =B38+1 -> 2054 | D39: =D38*1.02+C39 -> 154343.87 | G39: =D39*0.63 -> 97236.641 | H39: =O39*2 -> 11872.606 | I39: =G39/13 -> 7479.7416 | J39: =Q39*2 -> 1424.7127 | K39: =I39-J39 -> 6055.0289 | L39: =K39*12 -> 72660.347 | M39: =G39*0.33 -> 32088.092 | N39: =L39-M39 -> 40572.256 | O39: =D39/26 -> 5936.3029 | P39: =$P$2 -> 0.12 | Q39: =P39*O39 -> 712.35634 | R39: =Q39*26 -> 18521.265 | S39: =MIN(Q39*0.5, O39*0.08*0.5) -> 237.45211 | T39: =S39*26 -> 6173.755 | V39: =MIN(T39+R39,26000) -> 24695.02 | W39: =FV($W$3/12,12,-1*V39/12,-1*W38) -> 1427375.9 | Y39: =$Y$43/(1+0.04)^(67-A39) -> 2000241.8
A40: =A39+1 -> 65 | B40: =B39+1 -> 2055 | D40: =D39*1.02+C40 -> 157430.75 | E40: 10.4 | F40: =E40*D40 -> 1637279.8 | G40: =D40*0.63 -> 99181.374 | H40: =O40*2 -> 12110.058 | I40: =G40/13 -> 7629.3364 | J40: =Q40*2 -> 1453.2069 | K40: =I40-J40 -> 6176.1295 | L40: =K40*12 -> 74113.554 | M40: =G40*0.33 -> 32729.853 | N40: =L40-M40 -> 41383.701 | O40: =D40/26 -> 6055.0289 | P40: =$P$2 -> 0.12 | Q40: =P40*O40 -> 726.60347 | R40: =Q40*26 -> 18891.69 | S40: =MIN(Q40*0.5, O40*0.08*0.5) -> 242.20116 | T40: =S40*26 -> 6297.2301 | V40: =MIN(T40+R40,26000) -> 25188.92 | W40: =FV($W$3/12,12,-1*V40/12,-1*W39) -> 1526177.4 | X40: =W40/F40-1 -> -0.067857914 | Y40: =$Y$43/(1+0.04)^(67-A40) -> 2080251.5
...

Sheet 401k - Vincent
A1: 401(k) Savings Calculator
H2: ="© 2008-" & YEAR(TODAY()) & " Vertex42 LLC" -> © 2008-2021 Vertex42 LLC
J3: Using This Worksheet
A4: 401(k) Plan Assumptions | F4: Summary of Results | J4: Taxes and IRS Contribution Limits are
D5: Current Age | E5: 29 | G5: Years to Invest | H5: =IF(E6-E5<=0,0,E6-E5) -> 38 | J5: NOT factored into the calculations. You must
D6: Age at Retirement | E6: 67 | J6: check to ensure that you are not contributing
E7: Balance and Salary | H7: Future Value | J7: more than the 401(k) Limit.
D8: Current 401(k) Balance | E8: 53297 | G8: ="Estimated Value After "&H5&" Years" -> Estimated Value After 38 Years | H8: =OFFSET(H32,H5+1,0,1,1) -> 5524027.4
D9: Current Annual Salary | E9: 165347 | G9: Ending Salary | H9: =OFFSET(D32,H5+1,0,1,1) -> 344035.04
D10: Annual Increase in Salary | E10: 0.02 | J10: Set Chart Y-Axis to a Fixed Value
E11: Contributions | H11: Total Contributions | J11: When making comparisons using the graph,
D12: % of Salary to Contribute | E12: =20000/E9 -> 0.12095774 | G12: Your Contributions | H12: =IF(H5>0,SUM(OFFSET(E32,2,0,H5,1)),0) -> 1122298.8 | J12: it helps to set the y-axis on the chart to some
D13: Employer Match | E13: 0.5 | G13: Employer Contributions | H13: =IF(H5>0,SUM(OFFSET(F32,2,0,H5,1)),0) -> 371137.48 | J13: maximum $ amount. Right-click on the $ axis, select
D14: Max Employee % Contribution | E14: 0.08 | G14: Total Contributions | H14: =H13+H12 -> 1493436.3 | J14: Format Axis, go to the Scale tab, uncheck the box
E15: =IF(H5>0,IF(E34>16500,"Warning: Annual Contribution Over $16,500 Limit"," . ")," . ") -> Warning: Annual Contribution Over $16,500 Limit | J15: next to Maximum, and set the max value.
E16: Return
D17: Annual Rate of Return | E17: 0.06
D18: Payments Per Year | E18: 26
H21: =(H22="On") -> FALSE
C22: [42] | G22: Random Rates | H22: Off | J22: =IF(H22="On","Press F9 to recalculate.",".") -> .
G23: Min | H23: -0.04
G24: Max | H24: 0.1
G25: Average | H25: =IF(H5>0,AVERAGE(OFFSET(C32,2,0,H5,1)),0) -> 0.06
H26: (Press F9 to Recalculate)
H31: [42]
A32: Year | B32: Age | C32: Rate | D32: Salary | E32: Annual Contribution | F32: Employer Contribution | G32: Interest | H32: Balance | J32: My Contribution | K32: Total Contribution
E33: 19651 | H33: =$E$8 -> 53297
A34: =IF(A33<$H$5,A33+1,NA()) -> 1 | B34: =IF(ISERROR(A34),NA(),$E$5+A34-1) -> 29 | C34: =IF(ISERROR(A34),NA(),IF(randrate,$H$23+RAND()*($H$24-$H$23),$E$17)) -> 0.06 | D34: =E9 -> 165347 | E34: =IF(ISERROR(A34),NA(),IF(A34<=$H$5,$E$12*D34,0)) -> 20000 | F34: =IF(ISERROR(A34),NA(),IF(A34<=$H$5,MIN($E$13*E34,$E$14*$E$13*D34),0)) -> 6613.88 | G34: =IF(ISERROR(A34),NA(),FV(C34/nper,nper,-(E34+F34)/nper,-H33)-(H33+E34+F34)) -> 4073.8618 | H34: =IF(ISERROR(A34),NA(),H33+E34+F34+G34) -> 83984.742 | J34: =IF(ISERROR(A34),NA(),SUM(E$33:E34)) -> 39651 | K34: =IF(ISERROR(A34),NA(),SUM(E$33:F34)) -> 46264.88
A35: =IF(A34<$H$5,A34+1,NA()) -> 2 | B35: =IF(ISERROR(A35),NA(),$E$5+A35-1) -> 30 | C35: =IF(ISERROR(A35),NA(),IF(randrate,$H$23+RAND()*($H$24-$H$23),$E$17)) -> 0.06 | D35: =IF(ISERROR(A35),NA(),IF(A35<=$H$5,(1+$E$10)*D34,0)) -> 168653.94 | E35: =IF(ISERROR(A35),NA(),IF(A35<=$H$5,$E$12*D35,0)) -> 20400 | F35: =IF(ISERROR(A35),NA(),IF(A35<=$H$5,MIN($E$13*E35,$E$14*$E$13*D35),0)) -> 6746.1576 | G35: =IF(ISERROR(A35),NA(),FV(C35/nper,nper,-(E35+F35)/nper,-H34)-(H34+E35+F35)) -> 5984.8748 | H35: =IF(ISERROR(A35),NA(),H34+E35+F35+G35) -> 117115.77 | J35: =IF(ISERROR(A35),NA(),SUM(E$33:E35)) -> 60051 | K35: =IF(ISERROR(A35),NA(),SUM(E$33:F35)) -> 73411.038
A36: =IF(A35<$H$5,A35+1,NA()) -> 3 | B36: =IF(ISERROR(A36),NA(),$E$5+A36-1) -> 31 | C36: =IF(ISERROR(A36),NA(),IF(randrate,$H$23+RAND()*($H$24-$H$23),$E$17)) -> 0.06 | D36: =IF(ISERROR(A36),NA(),IF(A36<=$H$5,(1+$E$10)*D35,0)) -> 172027.02 | E36: =IF(ISERROR(A36),NA(),IF(A36<=$H$5,$E$12*D36,0)) -> 20808 | F36: =IF(ISERROR(A36),NA(),IF(A36<=$H$5,MIN($E$13*E36,$E$14*$E$13*D36),0)) -> 6881.0808 | G36: =IF(ISERROR(A36),NA(),FV(C36/nper,nper,-(E36+F36)/nper,-H35)-(H35+E36+F36)) -> 8047.106 | H36: =IF(ISERROR(A36),NA(),H35+E36+F36+G36) -> 152851.96 | J36: =IF(ISERROR(A36),NA(),SUM(E$33:E36)) -> 80859 | K36: =IF(ISERROR(A36),NA(),SUM(E$33:F36)) -> 101100.12
A37: =IF(A36<$H$5,A36+1,NA()) -> 4 | B37: =IF(ISERROR(A37),NA(),$E$5+A37-1) -> 32 | C37: =IF(ISERROR(A37),NA(),IF(randrate,$H$23+RAND()*($H$24-$H$23),$E$17)) -> 0.06 | D37: =IF(ISERROR(A37),NA(),IF(A37<=$H$5,(1+$E$10)*D36,0)) -> 175467.56 | E37: =IF(ISERROR(A37),NA(),IF(A37<=$H$5,$E$12*D37,0)) -> 21224.16 | F37: =IF(ISERROR(A37),NA(),IF(A37<=$H$5,MIN($E$13*E37,$E$14*$E$13*D37),0)) -> 7018.7024 | G37: =IF(ISERROR(A37),NA(),FV(C37/nper,nper,-(E37+F37)/nper,-H36)-(H36+E37+F37)) -> 10270.559 | H37: =IF(ISERROR(A37),NA(),H36+E37+F37+G37) -> 191365.38 | J37: =IF(ISERROR(A37),NA(),SUM(E$33:E37)) -> 102083.16 | K37: =IF(ISERROR(A37),NA(),SUM(E$33:F37)) -> 129342.98
A38: =IF(A37<$H$5,A37+1,NA()) -> 5 | B38: =IF(ISERROR(A38),NA(),$E$5+A38-1) -> 33 | C38: =IF(ISERROR(A38),NA(),IF(randrate,$H$23+RAND()*($H$24-$H$23),$E$17)) -> 0.06 | D38: =IF(ISERROR(A38),NA(),IF(A38<=$H$5,(1+$E$10)*D37,0)) -> 178976.91 | E38: =IF(ISERROR(A38),NA(),IF(A38<=$H$5,$E$12*D38,0)) -> 21648.643 | F38: =IF(ISERROR(A38),NA(),IF(A38<=$H$5,MIN($E$13*E38,$E$14*$E$13*D38),0)) -> 7159.0764 | G38: =IF(ISERROR(A38),NA(),FV(C38/nper,nper,-(E38+F38)/nper,-H37)-(H37+E38+F38)) -> 12665.868 | H38: =IF(ISERROR(A38),NA(),H37+E38+F38+G38) -> 232838.97 | J38: =IF(ISERROR(A38),NA(),SUM(E$33:E38)) -> 123731.8 | K38: =IF(ISERROR(A38),NA(),SUM(E$33:F38)) -> 158150.7
A39: =IF(A38<$H$5,A38+1,NA()) -> 6 | B39: =IF(ISERROR(A39),NA(),$E$5+A39-1) -> 34 | C39: =IF(ISERROR(A39),NA(),IF(randrate,$H$23+RAND()*($H$24-$H$23),$E$17)) -> 0.06 | D39: =IF(ISERROR(A39),NA(),IF(A39<=$H$5,(1+$E$10)*D38,0)) -> 182556.45 | E39: =IF(ISERROR(A39),NA(),IF(A39<=$H$5,$E$12*D39,0)) -> 22081.616 | F39: =IF(ISERROR(A39),NA(),IF(A39<=$H$5,MIN($E$13*E39,$E$14*$E$13*D39),0)) -> 7302.2579 | G39: =IF(ISERROR(A39),NA(),FV(C39/nper,nper,-(E39+F39)/nper,-H38)-(H38+E39+F39)) -> 15244.338 | H39: =IF(ISERROR(A39),NA(),H38+E39+F39+G39) -> 277467.18 | J39: =IF(ISERROR(A39),NA(),SUM(E$33:E39)) -> 145813.42 | K39: =IF(ISERROR(A39),NA(),SUM(E$33:F39)) -> 187534.57
A40: =IF(A39<$H$5,A39+1,NA()) -> 7 | B40: =IF(ISERROR(A40),NA(),$E$5+A40-1) -> 35 | C40: =IF(ISERROR(A40),NA(),IF(randrate,$H$23+RAND()*($H$24-$H$23),$E$17)) -> 0.06 | D40: =IF(ISERROR(A40),NA(),IF(A40<=$H$5,(1+$E$10)*D39,0)) -> 186207.58 | E40: =IF(ISERROR(A40),NA(),IF(A40<=$H$5,$E$12*D40,0)) -> 22523.248 | F40: =IF(ISERROR(A40),NA(),IF(A40<=$H$5,MIN($E$13*E40,$E$14*$E$13*D40),0)) -> 7448.3031 | G40: =IF(ISERROR(A40),NA(),FV(C40/nper,nper,-(E40+F40)/nper,-H39)-(H39+E40+F40)) -> 18017.986 | H40: =IF(ISERROR(A40),NA(),H39+E40+F40+G40) -> 325456.72 | J40: =IF(ISERROR(A40),NA(),SUM(E$33:E40)) -> 168336.67 | K40: =IF(ISERROR(A40),NA(),SUM(E$33:F40)) -> 217506.13
A41: =IF(A40<$H$5,A40+1,NA()) -> 8 | B41: =IF(ISERROR(A41),NA(),$E$5+A41-1) -> 36 | C41: =IF(ISERROR(A41),NA(),IF(randrate,$H$23+RAND()*($H$24-$H$23),$E$17)) -> 0.06 | D41: =IF(ISERROR(A41),NA(),IF(A41<=$H$5,(1+$E$10)*D40,0)) -> 189931.73 | E41: =IF(ISERROR(A41),NA(),IF(A41<=$H$5,$E$12*D41,0)) -> 22973.713 | F41: =IF(ISERROR(A41),NA(),IF(A41<=$H$5,MIN($E$13*E41,$E$14*$E$13*D41),0)) -> 7597.2692 | G41: =IF(ISERROR(A41),NA(),FV(C41/nper,nper,-(E41+F41)/nper,-H40)-(H40+E41+F41)) -> 20999.586 | H41: =IF(ISERROR(A41),NA(),H40+E41+F41+G41) -> 377027.29 | J41: =IF(ISERROR(A41),NA(),SUM(E$33:E41)) -> 191310.38 | K41: =IF(ISERROR(A41),NA(),SUM(E$33:F41)) -> 248077.11
A42: =IF(A41<$H$5,A41+1,NA()) -> 9 | B42: =IF(ISERROR(A42),NA(),$E$5+A42-1) -> 37 | C42: =IF(ISERROR(A42),NA(),IF(randrate,$H$23+RAND()*($H$24-$H$23),$E$17)) -> 0.06 | D42: =IF(ISERROR(A42),NA(),IF(A42<=$H$5,(1+$E$10)*D41,0)) -> 193730.36 | E42: =IF(ISERROR(A42),NA(),IF(A42<=$H$5,$E$12*D42,0)) -> 23433.188 | F42: =IF(ISERROR(A42),NA(),IF(A42<=$H$5,MIN($E$13*E42,$E$14*$E$13*D42),0)) -> 7749.2145 | G42: =IF(ISERROR(A42),NA(),FV(C42/nper,nper,-(E42+F42)/nper,-H41)-(H41+E42+F42)) -> 24202.714 | H42: =IF(ISERROR(A42),NA(),H41+E42+F42+G42) -> 432412.4 | J42: =IF(ISERROR(A42),NA(),SUM(E$33:E42)) -> 214743.57 | K42: =IF(ISERROR(A42),NA(),SUM(E$33:F42)) -> 279259.51
A43: =IF(A42<$H$5,A42+1,NA()) -> 10 | B43: =IF(ISERROR(A43),NA(),$E$5+A43-1) -> 38 | C43: =IF(ISERROR(A43),NA(),IF(randrate,$H$23+RAND()*($H$24-$H$23),$E$17)) -> 0.06 | D43: =IF(ISERROR(A43),NA(),IF(A43<=$H$5,(1+$E$10)*D42,0)) -> 197604.97 | E43: =IF(ISERROR(A43),NA(),IF(A43<=$H$5,$E$12*D43,0)) -> 23901.851 | F43: =IF(ISERROR(A43),NA(),IF(A43<=$H$5,MIN($E$13*E43,$E$14*$E$13*D43),0)) -> 7904.1988 | G43: =IF(ISERROR(A43),NA(),FV(C43/nper,nper,-(E43+F43)/nper,-H42)-(H42+E43+F43)) -> 27641.8 | H43: =IF(ISERROR(A43),NA(),H42+E43+F43+G43) -> 491860.25 | J43: =IF(ISERROR(A43),NA(),SUM(E$33:E43)) -> 238645.42 | K43: =IF(ISERROR(A43),NA(),SUM(E$33:F43)) -> 311065.56
A44: =IF(A43<$H$5,A43+1,NA()) -> 11 | B44: =IF(ISERROR(A44),NA(),$E$5+A44-1) -> 39 | C44: =IF(ISERROR(A44),NA(),IF(randrate,$H$23+RAND()*($H$24-$H$23),$E$17)) -> 0.06 | D44: =IF(ISERROR(A44),NA(),IF(A44<=$H$5,(1+$E$10)*D43,0)) -> 201557.07 | E44: =IF(ISERROR(A44),NA(),IF(A44<=$H$5,$E$12*D44,0)) -> 24379.888 | F44: =IF(ISERROR(A44),NA(),IF(A44<=$H$5,MIN($E$13*E44,$E$14*$E$13*D44),0)) -> 8062.2828 | G44: =IF(ISERROR(A44),NA(),FV(C44/nper,nper,-(E44+F44)/nper,-H43)-(H43+E44+F44)) -> 31332.179 | H44: =IF(ISERROR(A44),NA(),H43+E44+F44+G44) -> 555634.6 | J44: =IF(ISERROR(A44),NA(),SUM(E$33:E44)) -> 263025.31 | K44: =IF(ISERROR(A44),NA(),SUM(E$33:F44)) -> 343507.73
A45: =IF(A44<$H$5,A44+1,NA()) -> 12 | B45: =IF(ISERROR(A45),NA(),$E$5+A45-1) -> 40 | C45: =IF(ISERROR(A45),NA(),IF(randrate,$H$23+RAND()*($H$24-$H$23),$E$17)) -> 0.06 | D45: =IF(ISERROR(A45),NA(),IF(A45<=$H$5,(1+$E$10)*D44,0)) -> 205588.21 | E45: =IF(ISERROR(A45),NA(),IF(A45<=$H$5,$E$12*D45,0)) -> 24867.486 | F45: =IF(ISERROR(A45),NA(),IF(A45<=$H$5,MIN($E$13*E45,$E$14*$E$13*D45),0)) -> 8223.5285 | G45: =IF(ISERROR(A45),NA(),FV(C45/nper,nper,-(E45+F45)/nper,-H44)-(H44+E45+F45)) -> 35290.151 | H45: =IF(ISERROR(A45),NA(),H44+E45+F45+G45) -> 624015.77 | J45: =IF(ISERROR(A45),NA(),SUM(E$33:E45)) -> 287892.79 | K45: =IF(ISERROR(A45),NA(),SUM(E$33:F45)) -> 376598.75
A46: =IF(A45<$H$5,A45+1,NA()) -> 13 | B46: =IF(ISERROR(A46),NA(),$E$5+A46-1) -> 41 | C46: =IF(ISERROR(A46),NA(),IF(randrate,$H$23+RAND()*($H$24-$H$23),$E$17)) -> 0.06 | D46: =IF(ISERROR(A46),NA(),IF(A46<=$H$5,(1+$E$10)*D45,0)) -> 209699.98 | E46: =IF(ISERROR(A46),NA(),IF(A46<=$H$5,$E$12*D46,0)) -> 25364.836 | F46: =IF(ISERROR(A46),NA(),IF(A46<=$H$5,MIN($E$13*E46,$E$14*$E$13*D46),0)) -> 8387.999 | G46: =IF(ISERROR(A46),NA(),FV(C46/nper,nper,-(E46+F46)/nper,-H45)-(H45+E46+F46)) -> 39533.035 | H46: =IF(ISERROR(A46),NA(),H45+E46+F46+G46) -> 697301.64 | J46: =IF(ISERROR(A46),NA(),SUM(E$33:E46)) -> 313257.63 | K46: =IF(ISERROR(A46),NA(),SUM(E$33:F46)) -> 410351.58
...

Sheet 401k - Sean
A1: 401(k) Savings Calculator
H2: ="© 2008-" & YEAR(TODAY()) & " Vertex42 LLC" -> © 2008-2021 Vertex42 LLC
J3: Using This Worksheet
A4: 401(k) Plan Assumptions | F4: Summary of Results | J4: Taxes and IRS Contribution Limits are
D5: Current Age | E5: 31 | G5: Years to Invest | H5: =IF(E6-E5<=0,0,E6-E5) -> 36 | J5: NOT factored into the calculations. You must
D6: Age at Retirement | E6: 67 | J6: check to ensure that you are not contributing
E7: Balance and Salary | H7: Future Value | J7: more than the 401(k) Limit.
D8: Current 401(k) Balance | E8: 954.6 | G8: ="Estimated Value After "&H5&" Years" -> Estimated Value After 36 Years | H8: =OFFSET(H32,H5+1,0,1,1) -> 2124875.7
D9: Current Annual Salary | E9: ='Earnings Projection'!H10 -> 81200 | G9: Ending Salary | H9: =OFFSET(D32,H5+1,0,1,1) -> 162391.03
D10: Annual Increase in Salary | E10: 0.02 | J10: Set Chart Y-Axis to a Fixed Value
E11: Contributions | H11: Total Contributions | J11: When making comparisons using the graph,
D12: % of Salary to Contribute | E12: 0.12 | G12: Your Contributions | H12: =IF(H5>0,SUM(OFFSET(E32,2,0,H5,1)),0) -> 506633.11 | J12: it helps to set the y-axis on the chart to some
D13: Employer Match | E13: 0.5 | G13: Employer Contributions | H13: =IF(H5>0,SUM(OFFSET(F32,2,0,H5,1)),0) -> 168877.7 | J13: maximum $ amount. Right-click on the $ axis, select
D14: Max Employee % Contribution | E14: 0.08 | G14: Total Contributions | H14: =H13+H12 -> 675510.82 | J14: Format Axis, go to the Scale tab, uncheck the box
E15: =IF(H5>0,IF(E34>16500,"Warning: Annual Contribution Over $16,500 Limit"," . ")," . ") -> . | J15: next to Maximum, and set the max value.
E16: Return
D17: Annual Rate of Return | E17: 0.06
D18: Payments Per Year | E18: 26
H21: =(H22="On") -> FALSE
C22: [42] | G22: Random Rates | H22: Off | J22: =IF(H22="On","Press F9 to recalculate.",".") -> .
G23: Min | H23: -0.04
G24: Max | H24: 0.1
G25: Average | H25: =IF(H5>0,AVERAGE(OFFSET(C32,2,0,H5,1)),0) -> 0.06
H26: (Press F9 to Recalculate)
H31: [42]
A32: Year | B32: Age | C32: Rate | D32: Salary | E32: Annual Contribution | F32: Employer Contribution | G32: Interest | H32: Balance | J32: My Contribution | K32: Total Contribution
E33: 0 | H33: =$E$8 -> 954.6
A34: =IF(A33<$H$5,A33+1,NA()) -> 1 | B34: =IF(ISERROR(A34),NA(),$E$5+A34-1) -> 31 | C34: =IF(ISERROR(A34),NA(),IF(randrate,$H$23+RAND()*($H$24-$H$23),$E$17)) -> 0.06 | D34: =E9 -> 81200 | E34: =IF(ISERROR(A34),NA(),IF(A34<=$H$5,$E$12*D34,0)) -> 9744 | F34: =IF(ISERROR(A34),NA(),IF(A34<=$H$5,MIN($E$13*E34,$E$14*$E$13*D34),0)) -> 3248 | G34: =IF(ISERROR(A34),NA(),FV(C34/nper,nper,-(E34+F34)/nper,-H33)-(H33+E34+F34)) -> 440.7399 | H34: =IF(ISERROR(A34),NA(),H33+E34+F34+G34) -> 14387.34 | J34: =IF(ISERROR(A34),NA(),SUM(E$33:E34)) -> 9744 | K34: =IF(ISERROR(A34),NA(),SUM(E$33:F34)) -> 12992
A35: =IF(A34<$H$5,A34+1,NA()) -> 2 | B35: =IF(ISERROR(A35),NA(),$E$5+A35-1) -> 32 | C35: =IF(ISERROR(A35),NA(),IF(randrate,$H$23+RAND()*($H$24-$H$23),$E$17)) -> 0.06 | D35: =IF(ISERROR(A35),NA(),IF(A35<=$H$5,(1+$E$10)*D34,0)) -> 82824 | E35: =IF(ISERROR(A35),NA(),IF(A35<=$H$5,$E$12*D35,0)) -> 9938.88 | F35: =IF(ISERROR(A35),NA(),IF(A35<=$H$5,MIN($E$13*E35,$E$14*$E$13*D35),0)) -> 3312.96 | G35: =IF(ISERROR(A35),NA(),FV(C35/nper,nper,-(E35+F35)/nper,-H34)-(H34+E35+F35)) -> 1278.0238 | H35: =IF(ISERROR(A35),NA(),H34+E35+F35+G35) -> 28917.204 | J35: =IF(ISERROR(A35),NA(),SUM(E$33:E35)) -> 19682.88 | K35: =IF(ISERROR(A35),NA(),SUM(E$33:F35)) -> 26243.84
A36: =IF(A35<$H$5,A35+1,NA()) -> 3 | B36: =IF(ISERROR(A36),NA(),$E$5+A36-1) -> 33 | C36: =IF(ISERROR(A36),NA(),IF(randrate,$H$23+RAND()*($H$24-$H$23),$E$17)) -> 0.06 | D36: =IF(ISERROR(A36),NA(),IF(A36<=$H$5,(1+$E$10)*D35,0)) -> 84480.48 | E36: =IF(ISERROR(A36),NA(),IF(A36<=$H$5,$E$12*D36,0)) -> 10137.658 | F36: =IF(ISERROR(A36),NA(),IF(A36<=$H$5,MIN($E$13*E36,$E$14*$E$13*D36),0)) -> 3379.2192 | G36: =IF(ISERROR(A36),NA(),FV(C36/nper,nper,-(E36+F36)/nper,-H35)-(H35+E36+F36)) -> 2183.2223 | H36: =IF(ISERROR(A36),NA(),H35+E36+F36+G36) -> 44617.303 | J36: =IF(ISERROR(A36),NA(),SUM(E$33:E36)) -> 29820.538 | K36: =IF(ISERROR(A36),NA(),SUM(E$33:F36)) -> 39760.717
A37: =IF(A36<$H$5,A36+1,NA()) -> 4 | B37: =IF(ISERROR(A37),NA(),$E$5+A37-1) -> 34 | C37: =IF(ISERROR(A37),NA(),IF(randrate,$H$23+RAND()*($H$24-$H$23),$E$17)) -> 0.06 | D37: =IF(ISERROR(A37),NA(),IF(A37<=$H$5,(1+$E$10)*D36,0)) -> 86170.09 | E37: =IF(ISERROR(A37),NA(),IF(A37<=$H$5,$E$12*D37,0)) -> 10340.411 | F37: =IF(ISERROR(A37),NA(),IF(A37<=$H$5,MIN($E$13*E37,$E$14*$E$13*D37),0)) -> 3446.8036 | G37: =IF(ISERROR(A37),NA(),FV(C37/nper,nper,-(E37+F37)/nper,-H36)-(H36+E37+F37)) -> 3160.854 | H37: =IF(ISERROR(A37),NA(),H36+E37+F37+G37) -> 61565.371 | J37: =IF(ISERROR(A37),NA(),SUM(E$33:E37)) -> 40160.948 | K37: =IF(ISERROR(A37),NA(),SUM(E$33:F37)) -> 53547.931
A38: =IF(A37<$H$5,A37+1,NA()) -> 5 | B38: =IF(ISERROR(A38),NA(),$E$5+A38-1) -> 35 | C38: =IF(ISERROR(A38),NA(),IF(randrate,$H$23+RAND()*($H$24-$H$23),$E$17)) -> 0.06 | D38: =IF(ISERROR(A38),NA(),IF(A38<=$H$5,(1+$E$10)*D37,0)) -> 87893.491 | E38: =IF(ISERROR(A38),NA(),IF(A38<=$H$5,$E$12*D38,0)) -> 10547.219 | F38: =IF(ISERROR(A38),NA(),IF(A38<=$H$5,MIN($E$13*E38,$E$14*$E$13*D38),0)) -> 3515.7397 | G38: =IF(ISERROR(A38),NA(),FV(C38/nper,nper,-(E38+F38)/nper,-H37)-(H37+E38+F38)) -> 4215.7231 | H38: =IF(ISERROR(A38),NA(),H37+E38+F38+G38) -> 79844.053 | J38: =IF(ISERROR(A38),NA(),SUM(E$33:E38)) -> 50708.167 | K38: =IF(ISERROR(A38),NA(),SUM(E$33:F38)) -> 67610.89
A39: =IF(A38<$H$5,A38+1,NA()) -> 6 | B39: =IF(ISERROR(A39),NA(),$E$5+A39-1) -> 36 | C39: =IF(ISERROR(A39),NA(),IF(randrate,$H$23+RAND()*($H$24-$H$23),$E$17)) -> 0.06 | D39: =IF(ISERROR(A39),NA(),IF(A39<=$H$5,(1+$E$10)*D38,0)) -> 89651.361 | E39: =IF(ISERROR(A39),NA(),IF(A39<=$H$5,$E$12*D39,0)) -> 10758.163 | F39: =IF(ISERROR(A39),NA(),IF(A39<=$H$5,MIN($E$13*E39,$E$14*$E$13*D39),0)) -> 3586.0544 | G39: =IF(ISERROR(A39),NA(),FV(C39/nper,nper,-(E39+F39)/nper,-H38)-(H38+E39+F39)) -> 5352.9371 | H39: =IF(ISERROR(A39),NA(),H38+E39+F39+G39) -> 99541.208 | J39: =IF(ISERROR(A39),NA(),SUM(E$33:E39)) -> 61466.331 | K39: =IF(ISERROR(A39),NA(),SUM(E$33:F39)) -> 81955.108
A40: =IF(A39<$H$5,A39+1,NA()) -> 7 | B40: =IF(ISERROR(A40),NA(),$E$5+A40-1) -> 37 | C40: =IF(ISERROR(A40),NA(),IF(randrate,$H$23+RAND()*($H$24-$H$23),$E$17)) -> 0.06 | D40: =IF(ISERROR(A40),NA(),IF(A40<=$H$5,(1+$E$10)*D39,0)) -> 91444.388 | E40: =IF(ISERROR(A40),NA(),IF(A40<=$H$5,$E$12*D40,0)) -> 10973.327 | F40: =IF(ISERROR(A40),NA(),IF(A40<=$H$5,MIN($E$13*E40,$E$14*$E$13*D40),0)) -> 3657.7755 | G40: =IF(ISERROR(A40),NA(),FV(C40/nper,nper,-(E40+F40)/nper,-H39)-(H39+E40+F40)) -> 6577.9258 | H40: =IF(ISERROR(A40),NA(),H39+E40+F40+G40) -> 120750.24 | J40: =IF(ISERROR(A40),NA(),SUM(E$33:E40)) -> 72439.657 | K40: =IF(ISERROR(A40),NA(),SUM(E$33:F40)) -> 96586.21
A41: =IF(A40<$H$5,A40+1,NA()) -> 8 | B41: =IF(ISERROR(A41),NA(),$E$5+A41-1) -> 38 | C41: =IF(ISERROR(A41),NA(),IF(randrate,$H$23+RAND()*($H$24-$H$23),$E$17)) -> 0.06 | D41: =IF(ISERROR(A41),NA(),IF(A41<=$H$5,(1+$E$10)*D40,0)) -> 93273.276 | E41: =IF(ISERROR(A41),NA(),IF(A41<=$H$5,$E$12*D41,0)) -> 11192.793 | F41: =IF(ISERROR(A41),NA(),IF(A41<=$H$5,MIN($E$13*E41,$E$14*$E$13*D41),0)) -> 3730.931 | G41: =IF(ISERROR(A41),NA(),FV(C41/nper,nper,-(E41+F41)/nper,-H40)-(H40+E41+F41)) -> 7896.4611 | H41: =IF(ISERROR(A41),NA(),H40+E41+F41+G41) -> 143570.42 | J41: =IF(ISERROR(A41),NA(),SUM(E$33:E41)) -> 83632.45 | K41: =IF(ISERROR(A41),NA(),SUM(E$33:F41)) -> 111509.93
A42: =IF(A41<$H$5,A41+1,NA()) -> 9 | B42: =IF(ISERROR(A42),NA(),$E$5+A42-1) -> 39 | C42: =IF(ISERROR(A42),NA(),IF(randrate,$H$23+RAND()*($H$24-$H$23),$E$17)) -> 0.06 | D42: =IF(ISERROR(A42),NA(),IF(A42<=$H$5,(1+$E$10)*D41,0)) -> 95138.742 | E42: =IF(ISERROR(A42),NA(),IF(A42<=$H$5,$E$12*D42,0)) -> 11416.649 | F42: =IF(ISERROR(A42),NA(),IF(A42<=$H$5,MIN($E$13*E42,$E$14*$E$13*D42),0)) -> 3805.5497 | G42: =IF(ISERROR(A42),NA(),FV(C42/nper,nper,-(E42+F42)/nper,-H41)-(H41+E42+F42)) -> 9314.6785 | H42: =IF(ISERROR(A42),NA(),H41+E42+F42+G42) -> 168107.3 | J42: =IF(ISERROR(A42),NA(),SUM(E$33:E42)) -> 95049.099 | K42: =IF(ISERROR(A42),NA(),SUM(E$33:F42)) -> 126732.13
