Workbook
Name AprSun1: DATE(CalendarYear,4,1)-WEEKDAY(DATE(CalendarYear,4,1))
Name AugSun1: DATE(CalendarYear,8,1)-WEEKDAY(DATE(CalendarYear,8,1))
Name CalendarYear: [0]!Year1
Name Categories: OFFSET(#REF!,0,0,COUNTIF(#REF!,"<>"&"--"),1)
Name CategoryIdentifiers: Categories!$B$8:$B$273
Name CategoryNames: #REF!
Name CategoryNames: Categories!$C$8:$C$273
Name DecSun1: DATE(CalendarYear,12,1)-WEEKDAY(DATE(CalendarYear,12,1))
Name Essential: #REF!
Name Expense_Lookup: [1]Discover!$S:$T
Name FebSun1: DATE(CalendarYear,2,1)-WEEKDAY(DATE(CalendarYear,2,1))
Name HiddenCategoriesCategoryNames: _xlfn.ANCHORARRAY(HiddenCategories!$B$2)
Name HiddenCategoriesSubcategoryNames: HiddenCategories!$C$2:$C$100
Name HiddenCategoriesSubcategoryNamesRows: HiddenCategories!$C$2:$CX$100
Name JanSun1: DATE(CalendarYear,1,1)-WEEKDAY(DATE(CalendarYear,1,1))
Name JulSun1: DATE(CalendarYear,7,1)-WEEKDAY(DATE(CalendarYear,7,1))
Name JunSun1: DATE(CalendarYear,6,1)-WEEKDAY(DATE(CalendarYear,6,1))
Name LastCol: COUNTA('[1]PERSONAL BUDGET - WIP'!$4:$4)+1
Name MarSun1: DATE(CalendarYear,3,1)-WEEKDAY(DATE(CalendarYear,3,1))
Name MaySun1: DATE(CalendarYear,5,1)-WEEKDAY(DATE(CalendarYear,5,1))
Name MonthlyBudgetAvailableDates: _xlfn.ANCHORARRAY(MonthlyBudgetHidden!$C$2)
Name MonthlyBudgetAvailableDateValues: MonthlyBudgetHidden!$C$2:$C$26
Name MonthlyBudgetCurrentDate: MonthlyBudgetHidden!$A$2
Name MonthlyBudgetDate: MonthlyBudget!$O$3
Name MonthlyBudgetDates: MonthlyBudgetHidden!$C$2
Name MonthlyBudgetFavoriteCategory1: MonthlyBudget!$J$25
Name MonthlyBudgetFavoriteCategory1BudgetPercentage: MonthlyBudget!$K$27
Name MonthlyBudgetFavoriteCategory1DetailsText: MonthlyBudget!$J$28
Name MonthlyBudgetFavoriteCategory1LeftText: MonthlyBudget!$L$25
Name MonthlyBudgetFavoriteCategory1Percentages: MonthlyBudget!$J$27:$L$27
Name MonthlyBudgetFavoriteCategory1RemainingPercentage: MonthlyBudget!$L$27
Name MonthlyBudgetFavoriteCategory1SpentPercentage: MonthlyBudget!$J$27
Name MonthlyBudgetFavoriteCategory2: MonthlyBudget!$O$25
Name MonthlyBudgetFavoriteCategory2BudgetPercentage: MonthlyBudget!$P$27
Name MonthlyBudgetFavoriteCategory2DetailsText: MonthlyBudget!$O$28
Name MonthlyBudgetFavoriteCategory2LeftText: MonthlyBudget!$Q$25
Name MonthlyBudgetFavoriteCategory2Percentages: MonthlyBudget!$O$27:$Q$27
Name MonthlyBudgetFavoriteCategory2RemainingPercentage: MonthlyBudget!$Q$27
Name MonthlyBudgetFavoriteCategory2SpentPercentage: MonthlyBudget!$O$27
Name MonthlyBudgetIncomeVsSpendingDescriptionText: MonthlyBudget!$C$8
Name MonthlyBudgetNearestTransactionDate: MonthlyBudgetHidden!$C$2
Name MonthlyBudgetSpendingOverTime: MonthlyBudget!$K$12:$K$17
Name MonthlyBudgetSpendingOverTimeDescriptionText: MonthlyBudget!$J$8
Name MonthlyBudgetTextDates: MonthlyBudgetHidden!$B$2:$B$2000
Name MonthlyBudgetTitle: MonthlyBudget!$B$2
Name MonthlyBudgetTotalBudget: MonthlyBudget!$J$33
Name MonthlyBudgetTotalBudgetDescriptionText: MonthlyBudget!$C$23
Name MonthlyBudgetTotalBudgetDetailsText: MonthlyBudget!$C$28
Name MonthlyBudgetTotalBudgetLeftText: MonthlyBudget!$F$25
Name MonthlyBudgetTotalBudgetPercentage: MonthlyBudget!$D$27
Name MonthlyBudgetTotalExpenses: MonthlyBudget!$F$16
Name MonthlyBudgetTotalIncome: MonthlyBudget!$F$13
Name MonthlyBudgetTotalPercentages: MonthlyBudget!$C$27:$E$27
Name MonthlyBudgetTotalRemaining: MonthlyBudget!$L$33
Name MonthlyBudgetTotalRemainingPercentage: MonthlyBudget!$E$27
Name MonthlyBudgetTotalSpent: MonthlyBudget!$F$33
Name MonthlyBudgetTotalSpentPercentage: MonthlyBudget!$C$27
Name MonthlyBudgetTransactionDates: MonthlyBudgetHidden!$A$3
Name MonthlyBudgetUnusedCategories: MonthlyBudgetHidden!$F$2:$F$2000
Name MonthlyBudgetUnusedCategoryNames: _xlfn.ANCHORARRAY(MonthlyBudgetHidden!$G$2)

Sheet Income
B1: 05/31/2021 - 06/13/2021 (Bi-Weekly (Payroll)) | C1: 06/14/2021 - 06/27/2021 (Bi-Weekly (Payroll)) | D1: 06/28/2021 - 07/11/2021 (Bi-Weekly (Payroll)) | E1: 07/12/2021 - 07/25/2021 (Bi-Weekly (Payroll)) | F1: 07/26/2021 - 08/08/2021 (Bi-Weekly (Payroll)) | G1: 08/09/2021 - 08/22/2021 (Bi-Weekly (Payroll)) | H1: 08/23/2021 - 09/05/2021 (Bi-Weekly (Payroll)) | I1: 09/06/2021 - 09/19/2021 (Bi-Weekly (Payroll)) | J1: 09/20/2021 - 10/03/2021 (Bi-Weekly (Payroll)) | K1: 10/04/2021 - 10/17/2021 (Bi-Weekly (Payroll)) | L1: 10/18/2021 - 10/31/2021 (Bi-Weekly (Payroll)) | M1: 11/01/2021 - 11/14/2021 (Bi-Weekly (Payroll)) | N1: 11/15/2021 - 11/28/2021 (Bi-Weekly (Payroll)) | O1: 11/29/2021 - 12/12/2021 (Bi-Weekly (Payroll)) | P1: 12/13/2021 - 12/26/2021 (Bi-Weekly (Payroll))
A2: Earnings
A3: Bonus - Non Discretionary | J3: 0 | K3: 0 | L3: 0 | M3: 0 | N3: 0 | O3: 0 | P3: 1200
A4: Grossed Up Earnings | B4: 4098.37 | K4: 224.74
A5: LTD Benefit Credit | B5: 0 | C5: 4.86 | D5: 4.86 | E5: 4.86 | F5: 4.86 | G5: 4.86 | H5: 4.86 | I5: 4.86 | J5: 4.86 | K5: 4.86 | L5: 4.86 | M5: 4.86 | N5: 4.86 | O5: 4.86 | P5: 4.86
A6: My Health Completion Credit | B6: 0 | C6: 20 | D6: 20 | E6: 20 | F6: 20 | G6: 20 | H6: 20 | I6: 20 | J6: 20 | K6: 20 | L6: 20 | M6: 20 | N6: 20 | O6: 20 | P6: 20
A7: Regular | B7: 2700 | C7: 3000 | D7: 3000 | E7: 3000 | F7: 3000 | G7: 3000 | H7: 3000 | I7: 3000 | J7: 3000 | K7: 3000 | L7: 3000 | M7: 3000 | N7: 3000 | O7: 3000 | P7: 3076.93
A8: Deductions
A9: Bravo Award - No Cash Net | K9: 150
A10: Charitable Giving | K10: 38.47 | L10: 38.47 | M10: 38.47 | N10: 38.47 | O10: 38.47 | P10: 38.47
A11: Federal | B11: 1225.93 | C11: 363.68 | D11: 363.68 | E11: 363.64 | F11: 363.64 | G11: 363.64 | H11: 363.64 | I11: 363.64 | J11: 363.64 | K11: 413.09 | L11: 363.64 | M11: 363.64 | N11: 310.84 | O11: 310.84 | P11: 569.29
A12: Health Savings Account | B12: 0 | C12: 54.77 | D12: 54.77 | E12: 54.77 | F12: 54.77 | G12: 54.77 | H12: 54.77 | I12: 54.77 | J12: 54.77 | K12: 54.77 | L12: 54.77 | M12: 54.77 | N12: 54.77 | O12: 54.77 | P12: 54.77
A13: Life Insurance Coverage | B13: 0 | C13: 1.13 | D13: 1.13 | E13: 1.13 | F13: 1.13 | G13: 1.13 | H13: 1.13 | I13: 1.13 | J13: 1.13 | K13: 1.13 | L13: 1.13 | M13: 1.13 | N13: 1.13 | O13: 1.13 | P13: 1.13
A14: Long Term Disability Coverage | B14: 0 | C14: 9.69 | D14: 9.69 | E14: 9.69 | F14: 9.69 | G14: 9.69 | H14: 9.69 | I14: 9.69 | J14: 9.69 | K14: 9.69 | L14: 9.69 | M14: 9.69 | N14: 9.69 | O14: 9.69 | P14: 9.69
A15: Medical Coverage | B15: 0 | C15: 87 | D15: 87 | E15: 87 | F15: 87 | G15: 87 | H15: 87 | I15: 87 | J15: 87 | K15: 87 | L15: 87 | M15: 87 | N15: 87 | O15: 87 | P15: 87
A16: Medicare | B16: 98.58 | C16: 41.74 | D16: 41.75 | E16: 41.74 | F16: 41.75 | G16: 41.75 | H16: 41.74 | I16: 41.75 | J16: 41.75 | K16: 45 | L16: 41.75 | M16: 41.74 | N16: 41.75 | O16: 41.74 | P16: 60.27
A17: Nationwide Savings Plan | B17: 0 | C17: 0 | D17: 0 | E17: 0 | F17: 0 | G17: 0 | H17: 0 | I17: 0 | J17: 0 | K17: 0 | L17: 0 | M17: 0 | N17: 240 | O17: 240 | P17: 342.15
A18: NSP AfterTax Deduction NonRoth | C18: 450 | D18: 450 | E18: 300
A19: OASDI | B19: 421.5 | C19: 178.5 | D19: 178.5 | E19: 178.5 | F19: 178.5 | G19: 178.5 | H19: 178.5 | I19: 178.5 | J19: 178.5 | K19: 192.44 | L19: 178.5 | M19: 178.5 | N19: 178.5 | O19: 178.5 | P19: 257.67
A20: Roth 401k Deduction - ROTH | J20: 150 | K20: 240 | L20: 240 | M20: 240
A21: State Tax (VA) | B21: 371.05 | C21: 145.69 | D21: 145.69 | E21: 145.69 | F21: 145.69 | G21: 145.69 | H21: 145.69
A22: State Tax (AZ) | B22: 244.74 | C22: 103.65 | D22: 103.65 | E22: 103.65 | F22: 103.65 | G22: 103.65 | H22: 103.65 | I22: 103.65 | J22: 103.65 | K22: 111.74 | L22: 103.65 | M22: 103.65 | N22: 95.01 | O22: 95.01 | P22: 137.3
A23: Supplemental Accident Coverage | B23: 0 | C23: 1.6 | D23: 1.6 | E23: 1.6 | F23: 1.6 | G23: 1.6 | H23: 1.6 | I23: 1.6 | J23: 1.6 | K23: 1.6 | L23: 1.6 | M23: 1.6 | N23: 1.6 | O23: 1.6 | P23: 1.6
A24: Vision Coverage | B24: 0 | C24: 3.79 | D24: 3.79 | E24: 3.79 | F24: 3.79 | G24: 3.79 | H24: 3.79 | I24: 3.79 | J24: 3.79 | K24: 3.79 | L24: 3.79 | M24: 3.79 | N24: 3.79 | O24: 3.79 | P24: 3.79
A26: Net Income | B26: =SUM(B3:B7)-SUM(B9:B24) -> 4436.57 | C26: =SUM(C3:C7)-SUM(C9:C24) -> 1583.62 | D26: =SUM(D3:D7)-SUM(D9:D24) -> 1583.61 | E26: =SUM(E3:E7)-SUM(E9:E24) -> 1733.66 | F26: =SUM(F3:F7)-SUM(F9:F24) -> 2033.65 | G26: =SUM(G3:G7)-SUM(G9:G24) -> 2033.65 | H26: =SUM(H3:H7)-SUM(H9:H24) -> 2033.66 | I26: =SUM(I3:I7)-SUM(I9:I24) -> 2179.34 | ... P26: =SUM(P3:P7)-SUM(P9:P24) -> 2738.66

Sheet Snapshot
C2: Snapshot | Q2: Choose month below
C4: See your spending trends month over month with easy to read graphs. To switch months, click on the blue date box to the right. | Q4: January 2022 | W4: =_xlfn.XLOOKUP(TEXT(Q4,"mmmm yyyy"),$V$7:$V$200,$W$7:$W$200) -> 44562 | Y4: Monthly Summary | AC4: Category | AD4: Count | AE4: Rank | AF4: Order | AG4: Category | AH4: $ | AJ4: Display Axis | AK4: Current Mon. | AL4: $ | AM4: =TEXT(AK6,"MMMM")&" Spending" -> January Spending | AN4: Max Date | AO4: Last Mon. | AP4: $ | AQ4: =TEXT(AO6,"MMMM")&" Spending" -> December Spending | AR4: Max Date | AT4: Merchants | AU4: $ | AV4: Trans Count | AW4: Trans Rank | AX4: $ Rank
V6: Input | W6: Month Filter | Y6: =TEXT(ABS(Z9),"$#,##0")&" "&IF(Z7>Z8,"less was spent compared to last month","more was spent compared to last month") -> $127 more was spent compared to last month | AC6: {=_xlfn.UNIQUE(INDEX(_xlfn._xlws.FILTER(CategoriesTable[],(CategoriesTable[Category type]="expense")*(NOT(CategoriesTable[ID]=0)),""),0,2),FALSE)} -> Auto/Transport | AD6: =SUMIFS(Table1[Amount $],Table1[Category],Snapshot!AC6,Table1[Month],Snapshot!$W$4)*-1 -> 0 | AE6: =RANK(AD6,$AD$6:$AD$35,0)+COUNTIF(AD6:$AD$6,AD6)-1 -> 5 | AF6: 1 | AG6: {=IF(INDEX($AD$6:$AD$35,MATCH(AF6,$AE$6:$AE$35,0),0)=0,"",INDEX($AC$6:$AC$35,MATCH(AF6,$AE$6:$AE$35,0),0))} -> Home | AH6: {=IF(INDEX($AD$6:$AD$35,MATCH(AF6,$AE$6:$AE$35,0),0)=0,0,INDEX($AD$6:$AD$35,MATCH(AF6,$AE$6:$AE$35,0),0))} -> 485 | AJ6: =DATE(2000,1,1) -> 36526 | AK6: =DATE(YEAR(W4),MONTH(W4),DAY(W4)) -> 44562 | AL6: =SUMIFS(Table1[Amount $],Table1[Category Type],"Expense",Table1[Date],Snapshot!AK6)*-1 -> 102.84 | AM6: =IF(AK6>TODAY(),NA(),SUM(AL6:$AL$6)) -> 102.84 | AN6: =IF(OR(AK6=EOMONTH($AK$6,0),AK6=TODAY()),AM6,NA()) -> #N/A | AO6: =DATE(YEAR(AK6),MONTH(AK6)-1,DAY(AK6)) -> 44531 | AP6: =SUMIFS(Table1[Amount $],Table1[Category Type],"Expense",Table1[Date],Snapshot!AO6)*-1 -> 156.42 | AQ6: =IF(AO6<=EOMONTH($AO$6,0),SUM(AP$6:$AP6),NA()) -> 156.42 | AR6: =IF(AO6=EOMONTH($AO$6,0),AQ6,NA()) -> #N/A | AT6: {=_xlfn.UNIQUE(_xlfn._xlws.FILTER(Table1[Merchant],(Table1[Merchant]<>"")*(Table1[Amount $]<0)*(Table1[Month]=Snapshot!$W$4)*(Table1[Category Type]="Expense")))} -> Best Buy | AU6: =IF(ISBLANK(AT6),"",SUMIFS(Table1[Amount $],Table1[Merchant],Snapshot!AT6,Table1[Month],Snapshot!$W$4)*-1) -> 241.99 | AV6: =IF(ISBLANK(AT6),"",COUNTIFS(Table1[Merchant],Snapshot!AT6,Table1[Month],Snapshot!$W$4)) -> 1 | AW6: =IFERROR(RANK(AV6,$AV$6:$AV$200)+COUNTIF($AV$6:AV6,AV6)-1,"") -> 1 | AX6: =IFERROR(RANK(AU6,$AU$6:$AU$200)+COUNTIF($AU$6:AU6,AU6)-1,"") -> 3
D7: Current vs. previous month spending | M7: This month's top spending categories | V7: =IF(ISBLANK(W7),"--",TEXT(W7,"mmmm")&" "&TEXT(W7,"YYYY")) -> January 2022 | W7: {=_xlfn._xlws.SORT(_xlfn.UNIQUE(_xlfn._xlws.FILTER(Table1[Month],Table1[Month]<>"",)),1,-1)} -> 44562 | Y7: =IFERROR(TEXT(AO6,"mmmm"),"--") -> December | Z7: =SUMIFS(Table1[Amount $],Table1[Category Type],"Expense",Table1[Month],DATE(YEAR(Snapshot!$W$4),MONTH(Snapshot!$W$4)-1,DAY(Snapshot!$W$4)))*-1 -> -177.55 | AC7: Bills/Utilities | AD7: =SUMIFS(Table1[Amount $],Table1[Category],Snapshot!AC7,Table1[Month],Snapshot!$W$4)*-1 -> 0 | AE7: =RANK(AD7,$AD$6:$AD$35,0)+COUNTIF(AD$6:$AD7,AD7)-1 -> 6 | AF7: 2 | AG7: {=IF(INDEX($AD$6:$AD$35,MATCH(AF7,$AE$6:$AE$35,0),0)=0,"",INDEX($AC$6:$AC$35,MATCH(AF7,$AE$6:$AE$35,0),0))} -> Restaurants/Dining | AH7: {=IF(INDEX($AD$6:$AD$35,MATCH(AF7,$AE$6:$AE$35,0),0)=0,0,INDEX($AD$6:$AD$35,MATCH(AF7,$AE$6:$AE$35,0),0))} -> 88.02 | AJ7: =DATE(YEAR(AJ6),MONTH(AJ6),DAY(AJ6)+1) -> 36527 | AK7: =IF(MONTH(AK6)=MONTH(DATE(YEAR(AK6),MONTH(AK6),DAY(AK6)+1)),DATE(YEAR(AK6),MONTH(AK6),DAY(AK6)+1),NA()) -> 44563 | AL7: =SUMIFS(Table1[Amount $],Table1[Category Type],"Expense",Table1[Date],Snapshot!AK7)*-1 -> -2031.99 | AM7: =IF(AK7>TODAY(),NA(),SUM(AL$6:$AL7)) -> -1929.15 | AN7: =IF(OR(AK7=EOMONTH($AK$6,0),AK7=TODAY()),AM7,NA()) -> #N/A | AO7: =IF(MONTH(AO6)=MONTH(DATE(YEAR(AO6),MONTH(AO6),DAY(AO6)+1)),DATE(YEAR(AO6),MONTH(AO6),DAY(AO6)+1),NA()) -> 44532 | AP7: =SUMIFS(Table1[Amount $],Table1[Category Type],"Expense",Table1[Date],Snapshot!AO7)*-1 -> -1939.09 | AQ7: =IF(AO7<=EOMONTH($AO$6,0),SUM(AP$6:$AP7),NA()) -> -1782.67 | AR7: =IF(AO7=EOMONTH($AO$6,0),AQ7,NA()) -> #N/A | AT7: Discover E Payment Lewis | AU7: =IF(ISBLANK(AT7),"",SUMIFS(Table1[Amount $],Table1[Merchant],Snapshot!AT7,Table1[Month],Snapshot!$W$4)*-1) -> 1800 | AV7: =IF(ISBLANK(AT7),"",COUNTIFS(Table1[Merchant],Snapshot!AT7,Table1[Month],Snapshot!$W$4)) -> 1 | AW7: =IFERROR(RANK(AV7,$AV$6:$AV$200)+COUNTIF($AV$6:AV7,AV7)-1,"") -> 2 | AX7: =IFERROR(RANK(AU7,$AU$6:$AU$200)+COUNTIF($AU$6:AU7,AU7)-1,"") -> 1
D8: =Y6 -> $127 more was spent compared to last month | M8: =Q10&" accounts for "&TEXT(S10/S22,"0%")&" of money spent this month" -> Home accounts for -953% of money spent this month | V8: =IF(ISBLANK(W8),"--",TEXT(W8,"mmmm")&" "&TEXT(W8,"YYYY")) -> December 2021 | W8: 44531 | Y8: =IFERROR(TEXT(AK6,"mmmm"),"--") -> January | Z8: =SUMIFS(Table1[Amount $],Table1[Category Type],"Expense",Table1[Month],Snapshot!$W$4)*-1 -> -50.9 | AC8: Entertainment | AD8: =SUMIFS(Table1[Amount $],Table1[Category],Snapshot!AC8,Table1[Month],Snapshot!$W$4)*-1 -> 0 | AE8: =RANK(AD8,$AD$6:$AD$35,0)+COUNTIF(AD$6:$AD8,AD8)-1 -> 7 | AF8: 3 | AG8: {=IF(INDEX($AD$6:$AD$35,MATCH(AF8,$AE$6:$AE$35,0),0)=0,"",INDEX($AC$6:$AC$35,MATCH(AF8,$AE$6:$AE$35,0),0))} -> Shopping | AH8: {=IF(INDEX($AD$6:$AD$35,MATCH(AF8,$AE$6:$AE$35,0),0)=0,0,INDEX($AD$6:$AD$35,MATCH(AF8,$AE$6:$AE$35,0),0))} -> 37.81 | AJ8: =DATE(YEAR(AJ7),MONTH(AJ7),DAY(AJ7)+1) -> 36528 | AK8: =IF(MONTH(AK7)=MONTH(DATE(YEAR(AK7),MONTH(AK7),DAY(AK7)+1)),DATE(YEAR(AK7),MONTH(AK7),DAY(AK7)+1),NA()) -> 44564 | AL8: =SUMIFS(Table1[Amount $],Table1[Category Type],"Expense",Table1[Date],Snapshot!AK8)*-1 -> 1878.25 | AM8: =IF(AK8>TODAY(),NA(),SUM(AL$6:$AL8)) -> -50.9 | AN8: =IF(OR(AK8=EOMONTH($AK$6,0),AK8=TODAY()),AM8,NA()) -> #N/A | AO8: =IF(MONTH(AO7)=MONTH(DATE(YEAR(AO7),MONTH(AO7),DAY(AO7)+1)),DATE(YEAR(AO7),MONTH(AO7),DAY(AO7)+1),NA()) -> 44533 | AP8: =SUMIFS(Table1[Amount $],Table1[Category Type],"Expense",Table1[Date],Snapshot!AO8)*-1 -> 250.77 | AQ8: =IF(AO8<=EOMONTH($AO$6,0),SUM(AP$6:$AP8),NA()) -> -1531.9 | AR8: =IF(AO8=EOMONTH($AO$6,0),AQ8,NA()) -> #N/A | AT8: Paypal Inst Xfer Louisck | AU8: =IF(ISBLANK(AT8),"",SUMIFS(Table1[Amount $],Table1[Merchant],Snapshot!AT8,Table1[Month],Snapshot!$W$4)*-1) -> 10 | AV8: =IF(ISBLANK(AT8),"",COUNTIFS(Table1[Merchant],Snapshot!AT8,Table1[Month],Snapshot!$W$4)) -> 1 | AW8: =IFERROR(RANK(AV8,$AV$6:$AV$200)+COUNTIF($AV$6:AV8,AV8)-1,"") -> 3 | AX8: =IFERROR(RANK(AU8,$AU$6:$AU$200)+COUNTIF($AU$6:AU8,AU8)-1,"") -> 8
V9: =IF(ISBLANK(W9),"--",TEXT(W9,"mmmm")&" "&TEXT(W9,"YYYY")) -> November 2021 | W9: 44501 | Y9: Difference | Z9: =Z8-Z7 -> 126.65 | AC9: Fees/Charges | AD9: =SUMIFS(Table1[Amount $],Table1[Category],Snapshot!AC9,Table1[Month],Snapshot!$W$4)*-1 -> 0 | AE9: =RANK(AD9,$AD$6:$AD$35,0)+COUNTIF(AD$6:$AD9,AD9)-1 -> 8 | AF9: 4 | AG9: {=IF(INDEX($AD$6:$AD$35,MATCH(AF9,$AE$6:$AE$35,0),0)=0,"",INDEX($AC$6:$AC$35,MATCH(AF9,$AE$6:$AE$35,0),0))} -> Payment | AH9: {=IF(INDEX($AD$6:$AD$35,MATCH(AF9,$AE$6:$AE$35,0),0)=0,0,INDEX($AD$6:$AD$35,MATCH(AF9,$AE$6:$AE$35,0),0))} -> 10 | AJ9: =DATE(YEAR(AJ8),MONTH(AJ8),DAY(AJ8)+1) -> 36529 | AK9: =IF(MONTH(AK8)=MONTH(DATE(YEAR(AK8),MONTH(AK8),DAY(AK8)+1)),DATE(YEAR(AK8),MONTH(AK8),DAY(AK8)+1),NA()) -> 44565 | AL9: =SUMIFS(Table1[Amount $],Table1[Category Type],"Expense",Table1[Date],Snapshot!AK9)*-1 -> 0 | AM9: =IF(AK9>TODAY(),NA(),SUM(AL$6:$AL9)) -> -50.9 | AN9: =IF(OR(AK9=EOMONTH($AK$6,0),AK9=TODAY()),AM9,NA()) -> #N/A | AO9: =IF(MONTH(AO8)=MONTH(DATE(YEAR(AO8),MONTH(AO8),DAY(AO8)+1)),DATE(YEAR(AO8),MONTH(AO8),DAY(AO8)+1),NA()) -> 44534 | AP9: =SUMIFS(Table1[Amount $],Table1[Category Type],"Expense",Table1[Date],Snapshot!AO9)*-1 -> 76.04 | AQ9: =IF(AO9<=EOMONTH($AO$6,0),SUM(AP$6:$AP9),NA()) -> -1455.86 | AR9: =IF(AO9=EOMONTH($AO$6,0),AQ9,NA()) -> #N/A | AT9: Transfer To Lewis Sharon | AU9: =IF(ISBLANK(AT9),"",SUMIFS(Table1[Amount $],Table1[Merchant],Snapshot!AT9,Table1[Month],Snapshot!$W$4)*-1) -> 485 | AV9: =IF(ISBLANK(AT9),"",COUNTIFS(Table1[Merchant],Snapshot!AT9,Table1[Month],Snapshot!$W$4)) -> 1 | AW9: =IFERROR(RANK(AV9,$AV$6:$AV$200)+COUNTIF($AV$6:AV9,AV9)-1,"") -> 4 | AX9: =IFERROR(RANK(AU9,$AU$6:$AU$200)+COUNTIF($AU$6:AU9,AU9)-1,"") -> 2
Q10: {=INDEX($AG$6:$AG$11,MATCH(1,$AF$6:$AF$11,0),0)} -> Home | S10: {=INDEX($AH$6:$AH$11,MATCH(1,$AF$6:$AF$11,0),0)} -> 485 | V10: =IF(ISBLANK(W10),"--",TEXT(W10,"mmmm")&" "&TEXT(W10,"YYYY")) -> October 2021 | W10: 44470 | AC10: Groceries | AD10: =SUMIFS(Table1[Amount $],Table1[Category],Snapshot!AC10,Table1[Month],Snapshot!$W$4)*-1 -> 0 | AE10: =RANK(AD10,$AD$6:$AD$35,0)+COUNTIF(AD$6:$AD10,AD10)-1 -> 9 | AF10: 5 | AG10: {=IF(INDEX($AD$6:$AD$35,MATCH(AF10,$AE$6:$AE$35,0),0)=0,"",INDEX($AC$6:$AC$35,MATCH(AF10,$AE$6:$AE$35,0),0))} | AH10: {=IF(INDEX($AD$6:$AD$35,MATCH(AF10,$AE$6:$AE$35,0),0)=0,0,INDEX($AD$6:$AD$35,MATCH(AF10,$AE$6:$AE$35,0),0))} -> 0 | AJ10: =DATE(YEAR(AJ9),MONTH(AJ9),DAY(AJ9)+1) -> 36530 | AK10: =IF(MONTH(AK9)=MONTH(DATE(YEAR(AK9),MONTH(AK9),DAY(AK9)+1)),DATE(YEAR(AK9),MONTH(AK9),DAY(AK9)+1),NA()) -> 44566 | AL10: =SUMIFS(Table1[Amount $],Table1[Category Type],"Expense",Table1[Date],Snapshot!AK10)*-1 -> 0 | AM10: =IF(AK10>TODAY(),NA(),SUM(AL$6:$AL10)) -> -50.9 | AN10: =IF(OR(AK10=EOMONTH($AK$6,0),AK10=TODAY()),AM10,NA()) -> #N/A | AO10: =IF(MONTH(AO9)=MONTH(DATE(YEAR(AO9),MONTH(AO9),DAY(AO9)+1)),DATE(YEAR(AO9),MONTH(AO9),DAY(AO9)+1),NA()) -> 44535 | AP10: =SUMIFS(Table1[Amount $],Table1[Category Type],"Expense",Table1[Date],Snapshot!AO10)*-1 -> 255.37 | AQ10: =IF(AO10<=EOMONTH($AO$6,0),SUM(AP$6:$AP10),NA()) -> -1200.49 | AR10: =IF(AO10=EOMONTH($AO$6,0),AQ10,NA()) -> #N/A | AT10: Hulu | AU10: =IF(ISBLANK(AT10),"",SUMIFS(Table1[Amount $],Table1[Merchant],Snapshot!AT10,Table1[Month],Snapshot!$W$4)*-1) -> 12.99 | AV10: =IF(ISBLANK(AT10),"",COUNTIFS(Table1[Merchant],Snapshot!AT10,Table1[Month],Snapshot!$W$4)) -> 1 | AW10: =IFERROR(RANK(AV10,$AV$6:$AV$200)+COUNTIF($AV$6:AV10,AV10)-1,"") -> 5 | AX10: =IFERROR(RANK(AU10,$AU$6:$AU$200)+COUNTIF($AU$6:AU10,AU10)-1,"") -> 7
V11: =IF(ISBLANK(W11),"--",TEXT(W11,"mmmm")&" "&TEXT(W11,"YYYY")) -> September 2021 | W11: 44440 | AC11: Health/Fitness | AD11: =SUMIFS(Table1[Amount $],Table1[Category],Snapshot!AC11,Table1[Month],Snapshot!$W$4)*-1 -> 0 | AE11: =RANK(AD11,$AD$6:$AD$35,0)+COUNTIF(AD$6:$AD11,AD11)-1 -> 10 | AF11: 6 | AG11: =IF(SUM(AH6:AH10)=SUM(AD6:AD35),"","All Other Categories") -> All Other Categories | AH11: =SUM(AD6:AD35)-SUM(AH6:AH10) -> -671.73 | AJ11: =DATE(YEAR(AJ10),MONTH(AJ10),DAY(AJ10)+1) -> 36531 | AK11: =IF(MONTH(AK10)=MONTH(DATE(YEAR(AK10),MONTH(AK10),DAY(AK10)+1)),DATE(YEAR(AK10),MONTH(AK10),DAY(AK10)+1),NA()) -> 44567 | AL11: =SUMIFS(Table1[Amount $],Table1[Category Type],"Expense",Table1[Date],Snapshot!AK11)*-1 -> 0 | AM11: =IF(AK11>TODAY(),NA(),SUM(AL$6:$AL11)) -> -50.9 | AN11: =IF(OR(AK11=EOMONTH($AK$6,0),AK11=TODAY()),AM11,NA()) -> -50.9 | AO11: =IF(MONTH(AO10)=MONTH(DATE(YEAR(AO10),MONTH(AO10),DAY(AO10)+1)),DATE(YEAR(AO10),MONTH(AO10),DAY(AO10)+1),NA()) -> 44536 | AP11: =SUMIFS(Table1[Amount $],Table1[Category Type],"Expense",Table1[Date],Snapshot!AO11)*-1 -> 1012.43 | AQ11: =IF(AO11<=EOMONTH($AO$6,0),SUM(AP$6:$AP11),NA()) -> -188.06 | AR11: =IF(AO11=EOMONTH($AO$6,0),AQ11,NA()) -> #N/A | AT11: Krystal And Saagar Dc | AU11: =IF(ISBLANK(AT11),"",SUMIFS(Table1[Amount $],Table1[Merchant],Snapshot!AT11,Table1[Month],Snapshot!$W$4)*-1) -> 10 | AV11: =IF(ISBLANK(AT11),"",COUNTIFS(Table1[Merchant],Snapshot!AT11,Table1[Month],Snapshot!$W$4)) -> 1 | AW11: =IFERROR(RANK(AV11,$AV$6:$AV$200)+COUNTIF($AV$6:AV11,AV11)-1,"") -> 6 | AX11: =IFERROR(RANK(AU11,$AU$6:$AU$200)+COUNTIF($AU$6:AU11,AU11)-1,"") -> 9
Q12: {=INDEX($AG$6:$AG$11,MATCH(2,$AF$6:$AF$11,0),0)} -> Restaurants/Dining | S12: {=INDEX($AH$6:$AH$11,MATCH(2,$AF$6:$AF$11,0),0)} -> 88.02 | V12: =IF(ISBLANK(W12),"--",TEXT(W12,"mmmm")&" "&TEXT(W12,"YYYY")) -> August 2021 | W12: 44409 | AC12: Home | AD12: =SUMIFS(Table1[Amount $],Table1[Category],Snapshot!AC12,Table1[Month],Snapshot!$W$4)*-1 -> 485 | AE12: =RANK(AD12,$AD$6:$AD$35,0)+COUNTIF(AD$6:$AD12,AD12)-1 -> 1 | AG12: Total | AH12: =SUM(AH6:AH11) -> -50.9 | AJ12: =DATE(YEAR(AJ11),MONTH(AJ11),DAY(AJ11)+1) -> 36532 | AK12: =IF(MONTH(AK11)=MONTH(DATE(YEAR(AK11),MONTH(AK11),DAY(AK11)+1)),DATE(YEAR(AK11),MONTH(AK11),DAY(AK11)+1),NA()) -> 44568 | AL12: =SUMIFS(Table1[Amount $],Table1[Category Type],"Expense",Table1[Date],Snapshot!AK12)*-1 -> 0 | AM12: =IF(AK12>TODAY(),NA(),SUM(AL$6:$AL12)) -> #N/A | AN12: =IF(OR(AK12=EOMONTH($AK$6,0),AK12=TODAY()),AM12,NA()) -> #N/A | AO12: =IF(MONTH(AO11)=MONTH(DATE(YEAR(AO11),MONTH(AO11),DAY(AO11)+1)),DATE(YEAR(AO11),MONTH(AO11),DAY(AO11)+1),NA()) -> 44537 | AP12: =SUMIFS(Table1[Amount $],Table1[Category Type],"Expense",Table1[Date],Snapshot!AO12)*-1 -> -5.99 | AQ12: =IF(AO12<=EOMONTH($AO$6,0),SUM(AP$6:$AP12),NA()) -> -194.05 | AR12: =IF(AO12=EOMONTH($AO$6,0),AQ12,NA()) -> #N/A | AT12: Jimmy Johns | AU12: =IF(ISBLANK(AT12),"",SUMIFS(Table1[Amount $],Table1[Merchant],Snapshot!AT12,Table1[Month],Snapshot!$W$4)*-1) -> 18.02 | AV12: =IF(ISBLANK(AT12),"",COUNTIFS(Table1[Merchant],Snapshot!AT12,Table1[Month],Snapshot!$W$4)) -> 1 | AW12: =IFERROR(RANK(AV12,$AV$6:$AV$200)+COUNTIF($AV$6:AV12,AV12)-1,"") -> 7 | AX12: =IFERROR(RANK(AU12,$AU$6:$AU$200)+COUNTIF($AU$6:AU12,AU12)-1,"") -> 5
V13: =IF(ISBLANK(W13),"--",TEXT(W13,"mmmm")&" "&TEXT(W13,"YYYY")) -> July 2021 | W13: 44378 | AC13: Income | AD13: =SUMIFS(Table1[Amount $],Table1[Category],Snapshot!AC13,Table1[Month],Snapshot!$W$4)*-1 -> -671.73 | AE13: =RANK(AD13,$AD$6:$AD$35,0)+COUNTIF(AD$6:$AD13,AD13)-1 -> 30 | AJ13: =DATE(YEAR(AJ12),MONTH(AJ12),DAY(AJ12)+1) -> 36533 | AK13: =IF(MONTH(AK12)=MONTH(DATE(YEAR(AK12),MONTH(AK12),DAY(AK12)+1)),DATE(YEAR(AK12),MONTH(AK12),DAY(AK12)+1),NA()) -> 44569 | AL13: =SUMIFS(Table1[Amount $],Table1[Category Type],"Expense",Table1[Date],Snapshot!AK13)*-1 -> 0 | AM13: =IF(AK13>TODAY(),NA(),SUM(AL$6:$AL13)) -> #N/A | AN13: =IF(OR(AK13=EOMONTH($AK$6,0),AK13=TODAY()),AM13,NA()) -> #N/A | AO13: =IF(MONTH(AO12)=MONTH(DATE(YEAR(AO12),MONTH(AO12),DAY(AO12)+1)),DATE(YEAR(AO12),MONTH(AO12),DAY(AO12)+1),NA()) -> 44538 | AP13: =SUMIFS(Table1[Amount $],Table1[Category Type],"Expense",Table1[Date],Snapshot!AO13)*-1 -> 37.3 | AQ13: =IF(AO13<=EOMONTH($AO$6,0),SUM(AP$6:$AP13),NA()) -> -156.75 | AR13: =IF(AO13=EOMONTH($AO$6,0),AQ13,NA()) -> #N/A | AT13: Olive Garden | AU13: =IF(ISBLANK(AT13),"",SUMIFS(Table1[Amount $],Table1[Merchant],Snapshot!AT13,Table1[Month],Snapshot!$W$4)*-1) -> 60 | AV13: =IF(ISBLANK(AT13),"",COUNTIFS(Table1[Merchant],Snapshot!AT13,Table1[Month],Snapshot!$W$4)) -> 1 | AW13: =IFERROR(RANK(AV13,$AV$6:$AV$200)+COUNTIF($AV$6:AV13,AV13)-1,"") -> 8 | AX13: =IFERROR(RANK(AU13,$AU$6:$AU$200)+COUNTIF($AU$6:AU13,AU13)-1,"") -> 4
Q14: {=INDEX($AG$6:$AG$11,MATCH(3,$AF$6:$AF$11,0),0)} -> Shopping | S14: {=INDEX($AH$6:$AH$11,MATCH(3,$AF$6:$AF$11,0),0)} -> 37.81 | V14: =IF(ISBLANK(W14),"--",TEXT(W14,"mmmm")&" "&TEXT(W14,"YYYY")) -> June 2021 | W14: 44348 | AC14: Misc | AD14: =SUMIFS(Table1[Amount $],Table1[Category],Snapshot!AC14,Table1[Month],Snapshot!$W$4)*-1 -> 0 | AE14: =RANK(AD14,$AD$6:$AD$35,0)+COUNTIF(AD$6:$AD14,AD14)-1 -> 11 | AJ14: =DATE(YEAR(AJ13),MONTH(AJ13),DAY(AJ13)+1) -> 36534 | AK14: =IF(MONTH(AK13)=MONTH(DATE(YEAR(AK13),MONTH(AK13),DAY(AK13)+1)),DATE(YEAR(AK13),MONTH(AK13),DAY(AK13)+1),NA()) -> 44570 | AL14: =SUMIFS(Table1[Amount $],Table1[Category Type],"Expense",Table1[Date],Snapshot!AK14)*-1 -> 0 | AM14: =IF(AK14>TODAY(),NA(),SUM(AL$6:$AL14)) -> #N/A | AN14: =IF(OR(AK14=EOMONTH($AK$6,0),AK14=TODAY()),AM14,NA()) -> #N/A | AO14: =IF(MONTH(AO13)=MONTH(DATE(YEAR(AO13),MONTH(AO13),DAY(AO13)+1)),DATE(YEAR(AO13),MONTH(AO13),DAY(AO13)+1),NA()) -> 44539 | AP14: =SUMIFS(Table1[Amount $],Table1[Category Type],"Expense",Table1[Date],Snapshot!AO14)*-1 -> 579.36 | AQ14: =IF(AO14<=EOMONTH($AO$6,0),SUM(AP$6:$AP14),NA()) -> 422.61 | AR14: =IF(AO14=EOMONTH($AO$6,0),AQ14,NA()) -> #N/A | AT14: Netflix | AU14: =IF(ISBLANK(AT14),"",SUMIFS(Table1[Amount $],Table1[Merchant],Snapshot!AT14,Table1[Month],Snapshot!$W$4)*-1) -> 14.83 | AV14: =IF(ISBLANK(AT14),"",COUNTIFS(Table1[Merchant],Snapshot!AT14,Table1[Month],Snapshot!$W$4)) -> 1 | AW14: =IFERROR(RANK(AV14,$AV$6:$AV$200)+COUNTIF($AV$6:AV14,AV14)-1,"") -> 9 | AX14: =IFERROR(RANK(AU14,$AU$6:$AU$200)+COUNTIF($AU$6:AU14,AU14)-1,"") -> 6
V15: =IF(ISBLANK(W15),"--",TEXT(W15,"mmmm")&" "&TEXT(W15,"YYYY")) -> May 2021 | W15: 44317 | AC15: Mortgage/Rent | AD15: =SUMIFS(Table1[Amount $],Table1[Category],Snapshot!AC15,Table1[Month],Snapshot!$W$4)*-1 -> 0 | AE15: =RANK(AD15,$AD$6:$AD$35,0)+COUNTIF(AD$6:$AD15,AD15)-1 -> 12 | AJ15: =DATE(YEAR(AJ14),MONTH(AJ14),DAY(AJ14)+1) -> 36535 | AK15: =IF(MONTH(AK14)=MONTH(DATE(YEAR(AK14),MONTH(AK14),DAY(AK14)+1)),DATE(YEAR(AK14),MONTH(AK14),DAY(AK14)+1),NA()) -> 44571 | AL15: =SUMIFS(Table1[Amount $],Table1[Category Type],"Expense",Table1[Date],Snapshot!AK15)*-1 -> 0 | AM15: =IF(AK15>TODAY(),NA(),SUM(AL$6:$AL15)) -> #N/A | AN15: =IF(OR(AK15=EOMONTH($AK$6,0),AK15=TODAY()),AM15,NA()) -> #N/A | AO15: =IF(MONTH(AO14)=MONTH(DATE(YEAR(AO14),MONTH(AO14),DAY(AO14)+1)),DATE(YEAR(AO14),MONTH(AO14),DAY(AO14)+1),NA()) -> 44540 | AP15: =SUMIFS(Table1[Amount $],Table1[Category Type],"Expense",Table1[Date],Snapshot!AO15)*-1 -> -26.79 | AQ15: =IF(AO15<=EOMONTH($AO$6,0),SUM(AP$6:$AP15),NA()) -> 395.82 | AR15: =IF(AO15=EOMONTH($AO$6,0),AQ15,NA()) -> #N/A | AT15: Spotify | AU15: =IF(ISBLANK(AT15),"",SUMIFS(Table1[Amount $],Table1[Merchant],Snapshot!AT15,Table1[Month],Snapshot!$W$4)*-1) -> 9.99 | AV15: =IF(ISBLANK(AT15),"",COUNTIFS(Table1[Merchant],Snapshot!AT15,Table1[Month],Snapshot!$W$4)) -> 1 | AW15: =IFERROR(RANK(AV15,$AV$6:$AV$200)+COUNTIF($AV$6:AV15,AV15)-1,"") -> 10 | AX15: =IFERROR(RANK(AU15,$AU$6:$AU$200)+COUNTIF($AU$6:AU15,AU15)-1,"") -> 10
Q16: {=INDEX($AG$6:$AG$11,MATCH(4,$AF$6:$AF$11,0),0)} -> Payment | S16: {=INDEX($AH$6:$AH$11,MATCH(4,$AF$6:$AF$11,0),0)} -> 10 | V16: =IF(ISBLANK(W16),"--",TEXT(W16,"mmmm")&" "&TEXT(W16,"YYYY")) -> April 2021 | W16: 44287 | AC16: Payment | AD16: =SUMIFS(Table1[Amount $],Table1[Category],Snapshot!AC16,Table1[Month],Snapshot!$W$4)*-1 -> 10 | AE16: =RANK(AD16,$AD$6:$AD$35,0)+COUNTIF(AD$6:$AD16,AD16)-1 -> 4 | AJ16: =DATE(YEAR(AJ15),MONTH(AJ15),DAY(AJ15)+1) -> 36536 | AK16: =IF(MONTH(AK15)=MONTH(DATE(YEAR(AK15),MONTH(AK15),DAY(AK15)+1)),DATE(YEAR(AK15),MONTH(AK15),DAY(AK15)+1),NA()) -> 44572 | AL16: =SUMIFS(Table1[Amount $],Table1[Category Type],"Expense",Table1[Date],Snapshot!AK16)*-1 -> 0 | AM16: =IF(AK16>TODAY(),NA(),SUM(AL$6:$AL16)) -> #N/A | AN16: =IF(OR(AK16=EOMONTH($AK$6,0),AK16=TODAY()),AM16,NA()) -> #N/A | AO16: =IF(MONTH(AO15)=MONTH(DATE(YEAR(AO15),MONTH(AO15),DAY(AO15)+1)),DATE(YEAR(AO15),MONTH(AO15),DAY(AO15)+1),NA()) -> 44541 | AP16: =SUMIFS(Table1[Amount $],Table1[Category Type],"Expense",Table1[Date],Snapshot!AO16)*-1 -> 30.39 | AQ16: =IF(AO16<=EOMONTH($AO$6,0),SUM(AP$6:$AP16),NA()) -> 426.21 | AR16: =IF(AO16=EOMONTH($AO$6,0),AQ16,NA()) -> #N/A | AU16: =IF(ISBLANK(AT16),"",SUMIFS(Table1[Amount $],Table1[Merchant],Snapshot!AT16,Table1[Month],Snapshot!$W$4)*-1) | AV16: =IF(ISBLANK(AT16),"",COUNTIFS(Table1[Merchant],Snapshot!AT16,Table1[Month],Snapshot!$W$4)) | AW16: =IFERROR(RANK(AV16,$AV$6:$AV$200)+COUNTIF($AV$6:AV16,AV16)-1,"") | AX16: =IFERROR(RANK(AU16,$AU$6:$AU$200)+COUNTIF($AU$6:AU16,AU16)-1,"")
V17: =IF(ISBLANK(W17),"--",TEXT(W17,"mmmm")&" "&TEXT(W17,"YYYY")) -> March 2021 | W17: 44256 | AC17: Professional Services | AD17: =SUMIFS(Table1[Amount $],Table1[Category],Snapshot!AC17,Table1[Month],Snapshot!$W$4)*-1 -> 0 | AE17: =RANK(AD17,$AD$6:$AD$35,0)+COUNTIF(AD$6:$AD17,AD17)-1 -> 13 | AJ17: =DATE(YEAR(AJ16),MONTH(AJ16),DAY(AJ16)+1) -> 36537 | AK17: =IF(MONTH(AK16)=MONTH(DATE(YEAR(AK16),MONTH(AK16),DAY(AK16)+1)),DATE(YEAR(AK16),MONTH(AK16),DAY(AK16)+1),NA()) -> 44573 | AL17: =SUMIFS(Table1[Amount $],Table1[Category Type],"Expense",Table1[Date],Snapshot!AK17)*-1 -> 0 | AM17: =IF(AK17>TODAY(),NA(),SUM(AL$6:$AL17)) -> #N/A | AN17: =IF(OR(AK17=EOMONTH($AK$6,0),AK17=TODAY()),AM17,NA()) -> #N/A | AO17: =IF(MONTH(AO16)=MONTH(DATE(YEAR(AO16),MONTH(AO16),DAY(AO16)+1)),DATE(YEAR(AO16),MONTH(AO16),DAY(AO16)+1),NA()) -> 44542 | AP17: =SUMIFS(Table1[Amount $],Table1[Category Type],"Expense",Table1[Date],Snapshot!AO17)*-1 -> 179.52 | AQ17: =IF(AO17<=EOMONTH($AO$6,0),SUM(AP$6:$AP17),NA()) -> 605.73 | AR17: =IF(AO17=EOMONTH($AO$6,0),AQ17,NA()) -> #N/A | AU17: =IF(ISBLANK(AT17),"",SUMIFS(Table1[Amount $],Table1[Merchant],Snapshot!AT17,Table1[Month],Snapshot!$W$4)*-1) | AV17: =IF(ISBLANK(AT17),"",COUNTIFS(Table1[Merchant],Snapshot!AT17,Table1[Month],Snapshot!$W$4)) | AW17: =IFERROR(RANK(AV17,$AV$6:$AV$200)+COUNTIF($AV$6:AV17,AV17)-1,"") | AX17: =IFERROR(RANK(AU17,$AU$6:$AU$200)+COUNTIF($AU$6:AU17,AU17)-1,"")
Q18: {=INDEX($AG$6:$AG$11,MATCH(5,$AF$6:$AF$11,0),0)} | S18: {=INDEX($AH$6:$AH$11,MATCH(5,$AF$6:$AF$11,0),0)} -> 0 | V18: =IF(ISBLANK(W18),"--",TEXT(W18,"mmmm")&" "&TEXT(W18,"YYYY")) -> February 2021 | W18: 44228 | AC18: Refund | AD18: =SUMIFS(Table1[Amount $],Table1[Category],Snapshot!AC18,Table1[Month],Snapshot!$W$4)*-1 -> 0 | AE18: =RANK(AD18,$AD$6:$AD$35,0)+COUNTIF(AD$6:$AD18,AD18)-1 -> 14 | AJ18: =DATE(YEAR(AJ17),MONTH(AJ17),DAY(AJ17)+1) -> 36538 | AK18: =IF(MONTH(AK17)=MONTH(DATE(YEAR(AK17),MONTH(AK17),DAY(AK17)+1)),DATE(YEAR(AK17),MONTH(AK17),DAY(AK17)+1),NA()) -> 44574 | AL18: =SUMIFS(Table1[Amount $],Table1[Category Type],"Expense",Table1[Date],Snapshot!AK18)*-1 -> 0 | AM18: =IF(AK18>TODAY(),NA(),SUM(AL$6:$AL18)) -> #N/A | AN18: =IF(OR(AK18=EOMONTH($AK$6,0),AK18=TODAY()),AM18,NA()) -> #N/A | AO18: =IF(MONTH(AO17)=MONTH(DATE(YEAR(AO17),MONTH(AO17),DAY(AO17)+1)),DATE(YEAR(AO17),MONTH(AO17),DAY(AO17)+1),NA()) -> 44543 | AP18: =SUMIFS(Table1[Amount $],Table1[Category Type],"Expense",Table1[Date],Snapshot!AO18)*-1 -> 129.04 | AQ18: =IF(AO18<=EOMONTH($AO$6,0),SUM(AP$6:$AP18),NA()) -> 734.77 | AR18: =IF(AO18=EOMONTH($AO$6,0),AQ18,NA()) -> #N/A | AU18: =IF(ISBLANK(AT18),"",SUMIFS(Table1[Amount $],Table1[Merchant],Snapshot!AT18,Table1[Month],Snapshot!$W$4)*-1) | AV18: =IF(ISBLANK(AT18),"",COUNTIFS(Table1[Merchant],Snapshot!AT18,Table1[Month],Snapshot!$W$4)) | AW18: =IFERROR(RANK(AV18,$AV$6:$AV$200)+COUNTIF($AV$6:AV18,AV18)-1,"") | AX18: =IFERROR(RANK(AU18,$AU$6:$AU$200)+COUNTIF($AU$6:AU18,AU18)-1,"")
V19: =IF(ISBLANK(W19),"--",TEXT(W19,"mmmm")&" "&TEXT(W19,"YYYY")) -> January 2021 | W19: 44197 | AC19: Restaurants/Dining | AD19: =SUMIFS(Table1[Amount $],Table1[Category],Snapshot!AC19,Table1[Month],Snapshot!$W$4)*-1 -> 88.02 | AE19: =RANK(AD19,$AD$6:$AD$35,0)+COUNTIF(AD$6:$AD19,AD19)-1 -> 2 | AJ19: =DATE(YEAR(AJ18),MONTH(AJ18),DAY(AJ18)+1) -> 36539 | AK19: =IF(MONTH(AK18)=MONTH(DATE(YEAR(AK18),MONTH(AK18),DAY(AK18)+1)),DATE(YEAR(AK18),MONTH(AK18),DAY(AK18)+1),NA()) -> 44575 | AL19: =SUMIFS(Table1[Amount $],Table1[Category Type],"Expense",Table1[Date],Snapshot!AK19)*-1 -> 0 | AM19: =IF(AK19>TODAY(),NA(),SUM(AL$6:$AL19)) -> #N/A | AN19: =IF(OR(AK19=EOMONTH($AK$6,0),AK19=TODAY()),AM19,NA()) -> #N/A | AO19: =IF(MONTH(AO18)=MONTH(DATE(YEAR(AO18),MONTH(AO18),DAY(AO18)+1)),DATE(YEAR(AO18),MONTH(AO18),DAY(AO18)+1),NA()) -> 44544 | AP19: =SUMIFS(Table1[Amount $],Table1[Category Type],"Expense",Table1[Date],Snapshot!AO19)*-1 -> 134.03 | AQ19: =IF(AO19<=EOMONTH($AO$6,0),SUM(AP$6:$AP19),NA()) -> 868.8 | AR19: =IF(AO19=EOMONTH($AO$6,0),AQ19,NA()) -> #N/A | AU19: =IF(ISBLANK(AT19),"",SUMIFS(Table1[Amount $],Table1[Merchant],Snapshot!AT19,Table1[Month],Snapshot!$W$4)*-1) | AV19: =IF(ISBLANK(AT19),"",COUNTIFS(Table1[Merchant],Snapshot!AT19,Table1[Month],Snapshot!$W$4)) | AW19: =IFERROR(RANK(AV19,$AV$6:$AV$200)+COUNTIF($AV$6:AV19,AV19)-1,"") | AX19: =IFERROR(RANK(AU19,$AU$6:$AU$200)+COUNTIF($AU$6:AU19,AU19)-1,"")
Q20: {=INDEX($AG$6:$AG$11,MATCH(6,$AF$6:$AF$11,0),0)} -> All Other Categories | S20: {=INDEX($AH$6:$AH$11,MATCH(6,$AF$6:$AF$11,0),0)} -> -671.73 | V20: =IF(ISBLANK(W20),"--",TEXT(W20,"mmmm")&" "&TEXT(W20,"YYYY")) -> December 2020 | W20: 44166 | AC20: Shopping | AD20: =SUMIFS(Table1[Amount $],Table1[Category],Snapshot!AC20,Table1[Month],Snapshot!$W$4)*-1 -> 37.81 | AE20: =RANK(AD20,$AD$6:$AD$35,0)+COUNTIF(AD$6:$AD20,AD20)-1 -> 3 | AJ20: =DATE(YEAR(AJ19),MONTH(AJ19),DAY(AJ19)+1) -> 36540 | AK20: =IF(MONTH(AK19)=MONTH(DATE(YEAR(AK19),MONTH(AK19),DAY(AK19)+1)),DATE(YEAR(AK19),MONTH(AK19),DAY(AK19)+1),NA()) -> 44576 | AL20: =SUMIFS(Table1[Amount $],Table1[Category Type],"Expense",Table1[Date],Snapshot!AK20)*-1 -> 0 | AM20: =IF(AK20>TODAY(),NA(),SUM(AL$6:$AL20)) -> #N/A | AN20: =IF(OR(AK20=EOMONTH($AK$6,0),AK20=TODAY()),AM20,NA()) -> #N/A | AO20: =IF(MONTH(AO19)=MONTH(DATE(YEAR(AO19),MONTH(AO19),DAY(AO19)+1)),DATE(YEAR(AO19),MONTH(AO19),DAY(AO19)+1),NA()) -> 44545 | AP20: =SUMIFS(Table1[Amount $],Table1[Category Type],"Expense",Table1[Date],Snapshot!AO20)*-1 -> -100 | AQ20: =IF(AO20<=EOMONTH($AO$6,0),SUM(AP$6:$AP20),NA()) -> 768.8 | AR20: =IF(AO20=EOMONTH($AO$6,0),AQ20,NA()) -> #N/A | AU20: =IF(ISBLANK(AT20),"",SUMIFS(Table1[Amount $],Table1[Merchant],Snapshot!AT20,Table1[Month],Snapshot!$W$4)*-1) | AV20: =IF(ISBLANK(AT20),"",COUNTIFS(Table1[Merchant],Snapshot!AT20,Table1[Month],Snapshot!$W$4)) | AW20: =IFERROR(RANK(AV20,$AV$6:$AV$200)+COUNTIF($AV$6:AV20,AV20)-1,"") | AX20: =IFERROR(RANK(AU20,$AU$6:$AU$200)+COUNTIF($AU$6:AU20,AU20)-1,"")
V21: =IF(ISBLANK(W21),"--",TEXT(W21,"mmmm")&" "&TEXT(W21,"YYYY")) -> November 2020 | W21: 44136 | AC21: Transfer | AD21: =SUMIFS(Table1[Amount $],Table1[Category],Snapshot!AC21,Table1[Month],Snapshot!$W$4)*-1 -> 0 | AE21: =RANK(AD21,$AD$6:$AD$35,0)+COUNTIF(AD$6:$AD21,AD21)-1 -> 15 | AJ21: =DATE(YEAR(AJ20),MONTH(AJ20),DAY(AJ20)+1) -> 36541 | AK21: =IF(MONTH(AK20)=MONTH(DATE(YEAR(AK20),MONTH(AK20),DAY(AK20)+1)),DATE(YEAR(AK20),MONTH(AK20),DAY(AK20)+1),NA()) -> 44577 | AL21: =SUMIFS(Table1[Amount $],Table1[Category Type],"Expense",Table1[Date],Snapshot!AK21)*-1 -> 0 | AM21: =IF(AK21>TODAY(),NA(),SUM(AL$6:$AL21)) -> #N/A | AN21: =IF(OR(AK21=EOMONTH($AK$6,0),AK21=TODAY()),AM21,NA()) -> #N/A | AO21: =IF(MONTH(AO20)=MONTH(DATE(YEAR(AO20),MONTH(AO20),DAY(AO20)+1)),DATE(YEAR(AO20),MONTH(AO20),DAY(AO20)+1),NA()) -> 44546 | AP21: =SUMIFS(Table1[Amount $],Table1[Category Type],"Expense",Table1[Date],Snapshot!AO21)*-1 -> -2327.26 | AQ21: =IF(AO21<=EOMONTH($AO$6,0),SUM(AP$6:$AP21),NA()) -> -1558.46 | AR21: =IF(AO21=EOMONTH($AO$6,0),AQ21,NA()) -> #N/A | AU21: =IF(ISBLANK(AT21),"",SUMIFS(Table1[Amount $],Table1[Merchant],Snapshot!AT21,Table1[Month],Snapshot!$W$4)*-1) | AV21: =IF(ISBLANK(AT21),"",COUNTIFS(Table1[Merchant],Snapshot!AT21,Table1[Month],Snapshot!$W$4)) | AW21: =IFERROR(RANK(AV21,$AV$6:$AV$200)+COUNTIF($AV$6:AV21,AV21)-1,"") | AX21: =IFERROR(RANK(AU21,$AU$6:$AU$200)+COUNTIF($AU$6:AU21,AU21)-1,"")
P22: Total spending | S22: =S10+S12+S14+S16+S18+S20 -> -50.9 | V22: =IF(ISBLANK(W22),"--",TEXT(W22,"mmmm")&" "&TEXT(W22,"YYYY")) -> October 2020 | W22: 44105 | AC22: Travel | AD22: =SUMIFS(Table1[Amount $],Table1[Category],Snapshot!AC22,Table1[Month],Snapshot!$W$4)*-1 -> 0 | AE22: =RANK(AD22,$AD$6:$AD$35,0)+COUNTIF(AD$6:$AD22,AD22)-1 -> 16 | AJ22: =DATE(YEAR(AJ21),MONTH(AJ21),DAY(AJ21)+1) -> 36542 | AK22: =IF(MONTH(AK21)=MONTH(DATE(YEAR(AK21),MONTH(AK21),DAY(AK21)+1)),DATE(YEAR(AK21),MONTH(AK21),DAY(AK21)+1),NA()) -> 44578 | AL22: =SUMIFS(Table1[Amount $],Table1[Category Type],"Expense",Table1[Date],Snapshot!AK22)*-1 -> 0 | AM22: =IF(AK22>TODAY(),NA(),SUM(AL$6:$AL22)) -> #N/A | AN22: =IF(OR(AK22=EOMONTH($AK$6,0),AK22=TODAY()),AM22,NA()) -> #N/A | AO22: =IF(MONTH(AO21)=MONTH(DATE(YEAR(AO21),MONTH(AO21),DAY(AO21)+1)),DATE(YEAR(AO21),MONTH(AO21),DAY(AO21)+1),NA()) -> 44547 | AP22: =SUMIFS(Table1[Amount $],Table1[Category Type],"Expense",Table1[Date],Snapshot!AO22)*-1 -> 462.84 | AQ22: =IF(AO22<=EOMONTH($AO$6,0),SUM(AP$6:$AP22),NA()) -> -1095.62 | AR22: =IF(AO22=EOMONTH($AO$6,0),AQ22,NA()) -> #N/A | AU22: =IF(ISBLANK(AT22),"",SUMIFS(Table1[Amount $],Table1[Merchant],Snapshot!AT22,Table1[Month],Snapshot!$W$4)*-1) | AV22: =IF(ISBLANK(AT22),"",COUNTIFS(Table1[Merchant],Snapshot!AT22,Table1[Month],Snapshot!$W$4)) | AW22: =IFERROR(RANK(AV22,$AV$6:$AV$200)+COUNTIF($AV$6:AV22,AV22)-1,"") | AX22: =IFERROR(RANK(AU22,$AU$6:$AU$200)+COUNTIF($AU$6:AU22,AU22)-1,"")
V23: =IF(ISBLANK(W23),"--",TEXT(W23,"mmmm")&" "&TEXT(W23,"YYYY")) -> September 2020 | W23: 44075 | AC23: Uncategorized | AD23: =SUMIFS(Table1[Amount $],Table1[Category],Snapshot!AC23,Table1[Month],Snapshot!$W$4)*-1 -> 0 | AE23: =RANK(AD23,$AD$6:$AD$35,0)+COUNTIF(AD$6:$AD23,AD23)-1 -> 17 | AJ23: =DATE(YEAR(AJ22),MONTH(AJ22),DAY(AJ22)+1) -> 36543 | AK23: =IF(MONTH(AK22)=MONTH(DATE(YEAR(AK22),MONTH(AK22),DAY(AK22)+1)),DATE(YEAR(AK22),MONTH(AK22),DAY(AK22)+1),NA()) -> 44579 | AL23: =SUMIFS(Table1[Amount $],Table1[Category Type],"Expense",Table1[Date],Snapshot!AK23)*-1 -> 0 | AM23: =IF(AK23>TODAY(),NA(),SUM(AL$6:$AL23)) -> #N/A | AN23: =IF(OR(AK23=EOMONTH($AK$6,0),AK23=TODAY()),AM23,NA()) -> #N/A | AO23: =IF(MONTH(AO22)=MONTH(DATE(YEAR(AO22),MONTH(AO22),DAY(AO22)+1)),DATE(YEAR(AO22),MONTH(AO22),DAY(AO22)+1),NA()) -> 44548 | AP23: =SUMIFS(Table1[Amount $],Table1[Category Type],"Expense",Table1[Date],Snapshot!AO23)*-1 -> 271.33 | AQ23: =IF(AO23<=EOMONTH($AO$6,0),SUM(AP$6:$AP23),NA()) -> -824.29 | AR23: =IF(AO23=EOMONTH($AO$6,0),AQ23,NA()) -> #N/A | AU23: =IF(ISBLANK(AT23),"",SUMIFS(Table1[Amount $],Table1[Merchant],Snapshot!AT23,Table1[Month],Snapshot!$W$4)*-1) | AV23: =IF(ISBLANK(AT23),"",COUNTIFS(Table1[Merchant],Snapshot!AT23,Table1[Month],Snapshot!$W$4)) | AW23: =IFERROR(RANK(AV23,$AV$6:$AV$200)+COUNTIF($AV$6:AV23,AV23)-1,"") | AX23: =IFERROR(RANK(AU23,$AU$6:$AU$200)+COUNTIF($AU$6:AU23,AU23)-1,"")
V24: =IF(ISBLANK(W24),"--",TEXT(W24,"mmmm")&" "&TEXT(W24,"YYYY")) -> August 2020 | W24: 44044 | AC24: Food | AD24: =SUMIFS(Table1[Amount $],Table1[Category],Snapshot!AC24,Table1[Month],Snapshot!$W$4)*-1 -> 0 | AE24: =RANK(AD24,$AD$6:$AD$35,0)+COUNTIF(AD$6:$AD24,AD24)-1 -> 18 | AJ24: =DATE(YEAR(AJ23),MONTH(AJ23),DAY(AJ23)+1) -> 36544 | AK24: =IF(MONTH(AK23)=MONTH(DATE(YEAR(AK23),MONTH(AK23),DAY(AK23)+1)),DATE(YEAR(AK23),MONTH(AK23),DAY(AK23)+1),NA()) -> 44580 | AL24: =SUMIFS(Table1[Amount $],Table1[Category Type],"Expense",Table1[Date],Snapshot!AK24)*-1 -> 0 | AM24: =IF(AK24>TODAY(),NA(),SUM(AL$6:$AL24)) -> #N/A | AN24: =IF(OR(AK24=EOMONTH($AK$6,0),AK24=TODAY()),AM24,NA()) -> #N/A | AO24: =IF(MONTH(AO23)=MONTH(DATE(YEAR(AO23),MONTH(AO23),DAY(AO23)+1)),DATE(YEAR(AO23),MONTH(AO23),DAY(AO23)+1),NA()) -> 44549 | AP24: =SUMIFS(Table1[Amount $],Table1[Category Type],"Expense",Table1[Date],Snapshot!AO24)*-1 -> 340.97 | AQ24: =IF(AO24<=EOMONTH($AO$6,0),SUM(AP$6:$AP24),NA()) -> -483.32 | AR24: =IF(AO24=EOMONTH($AO$6,0),AQ24,NA()) -> #N/A | AU24: =IF(ISBLANK(AT24),"",SUMIFS(Table1[Amount $],Table1[Merchant],Snapshot!AT24,Table1[Month],Snapshot!$W$4)*-1) | AV24: =IF(ISBLANK(AT24),"",COUNTIFS(Table1[Merchant],Snapshot!AT24,Table1[Month],Snapshot!$W$4)) | AW24: =IFERROR(RANK(AV24,$AV$6:$AV$200)+COUNTIF($AV$6:AV24,AV24)-1,"") | AX24: =IFERROR(RANK(AU24,$AU$6:$AU$200)+COUNTIF($AU$6:AU24,AU24)-1,"")
V25: =IF(ISBLANK(W25),"--",TEXT(W25,"mmmm")&" "&TEXT(W25,"YYYY")) -> July 2020 | W25: 44013 | AC25: Insurance | AD25: =SUMIFS(Table1[Amount $],Table1[Category],Snapshot!AC25,Table1[Month],Snapshot!$W$4)*-1 -> 0 | AE25: =RANK(AD25,$AD$6:$AD$35,0)+COUNTIF(AD$6:$AD25,AD25)-1 -> 19 | AJ25: =DATE(YEAR(AJ24),MONTH(AJ24),DAY(AJ24)+1) -> 36545 | AK25: =IF(MONTH(AK24)=MONTH(DATE(YEAR(AK24),MONTH(AK24),DAY(AK24)+1)),DATE(YEAR(AK24),MONTH(AK24),DAY(AK24)+1),NA()) -> 44581 | AL25: =SUMIFS(Table1[Amount $],Table1[Category Type],"Expense",Table1[Date],Snapshot!AK25)*-1 -> 0 | AM25: =IF(AK25>TODAY(),NA(),SUM(AL$6:$AL25)) -> #N/A | AN25: =IF(OR(AK25=EOMONTH($AK$6,0),AK25=TODAY()),AM25,NA()) -> #N/A | AO25: =IF(MONTH(AO24)=MONTH(DATE(YEAR(AO24),MONTH(AO24),DAY(AO24)+1)),DATE(YEAR(AO24),MONTH(AO24),DAY(AO24)+1),NA()) -> 44550 | AP25: =SUMIFS(Table1[Amount $],Table1[Category Type],"Expense",Table1[Date],Snapshot!AO25)*-1 -> 556.71 | AQ25: =IF(AO25<=EOMONTH($AO$6,0),SUM(AP$6:$AP25),NA()) -> 73.39 | AR25: =IF(AO25=EOMONTH($AO$6,0),AQ25,NA()) -> #N/A | AU25: =IF(ISBLANK(AT25),"",SUMIFS(Table1[Amount $],Table1[Merchant],Snapshot!AT25,Table1[Month],Snapshot!$W$4)*-1) | AV25: =IF(ISBLANK(AT25),"",COUNTIFS(Table1[Merchant],Snapshot!AT25,Table1[Month],Snapshot!$W$4)) | AW25: =IFERROR(RANK(AV25,$AV$6:$AV$200)+COUNTIF($AV$6:AV25,AV25)-1,"") | AX25: =IFERROR(RANK(AU25,$AU$6:$AU$200)+COUNTIF($AU$6:AU25,AU25)-1,"")
V26: =IF(ISBLANK(W26),"--",TEXT(W26,"mmmm")&" "&TEXT(W26,"YYYY")) -> June 2020 | W26: 43983 | AC26: Medical & Healthcare | AD26: =SUMIFS(Table1[Amount $],Table1[Category],Snapshot!AC26,Table1[Month],Snapshot!$W$4)*-1 -> 0 | AE26: =RANK(AD26,$AD$6:$AD$35,0)+COUNTIF(AD$6:$AD26,AD26)-1 -> 20 | AJ26: =DATE(YEAR(AJ25),MONTH(AJ25),DAY(AJ25)+1) -> 36546 | AK26: =IF(MONTH(AK25)=MONTH(DATE(YEAR(AK25),MONTH(AK25),DAY(AK25)+1)),DATE(YEAR(AK25),MONTH(AK25),DAY(AK25)+1),NA()) -> 44582 | AL26: =SUMIFS(Table1[Amount $],Table1[Category Type],"Expense",Table1[Date],Snapshot!AK26)*-1 -> 0 | AM26: =IF(AK26>TODAY(),NA(),SUM(AL$6:$AL26)) -> #N/A | AN26: =IF(OR(AK26=EOMONTH($AK$6,0),AK26=TODAY()),AM26,NA()) -> #N/A | AO26: =IF(MONTH(AO25)=MONTH(DATE(YEAR(AO25),MONTH(AO25),DAY(AO25)+1)),DATE(YEAR(AO25),MONTH(AO25),DAY(AO25)+1),NA()) -> 44551 | AP26: =SUMIFS(Table1[Amount $],Table1[Category Type],"Expense",Table1[Date],Snapshot!AO26)*-1 -> 42.73 | AQ26: =IF(AO26<=EOMONTH($AO$6,0),SUM(AP$6:$AP26),NA()) -> 116.12 | AR26: =IF(AO26=EOMONTH($AO$6,0),AQ26,NA()) -> #N/A | AU26: =IF(ISBLANK(AT26),"",SUMIFS(Table1[Amount $],Table1[Merchant],Snapshot!AT26,Table1[Month],Snapshot!$W$4)*-1) | AV26: =IF(ISBLANK(AT26),"",COUNTIFS(Table1[Merchant],Snapshot!AT26,Table1[Month],Snapshot!$W$4)) | AW26: =IFERROR(RANK(AV26,$AV$6:$AV$200)+COUNTIF($AV$6:AV26,AV26)-1,"") | AX26: =IFERROR(RANK(AU26,$AU$6:$AU$200)+COUNTIF($AU$6:AU26,AU26)-1,"")
D27: Cumulative spending throughout month | V27: =IF(ISBLANK(W27),"--",TEXT(W27,"mmmm")&" "&TEXT(W27,"YYYY")) -> May 2020 | W27: 43952 | AC27: Personal Spending | AD27: =SUMIFS(Table1[Amount $],Table1[Category],Snapshot!AC27,Table1[Month],Snapshot!$W$4)*-1 -> 0 | AE27: =RANK(AD27,$AD$6:$AD$35,0)+COUNTIF(AD$6:$AD27,AD27)-1 -> 21 | AJ27: =DATE(YEAR(AJ26),MONTH(AJ26),DAY(AJ26)+1) -> 36547 | AK27: =IF(MONTH(AK26)=MONTH(DATE(YEAR(AK26),MONTH(AK26),DAY(AK26)+1)),DATE(YEAR(AK26),MONTH(AK26),DAY(AK26)+1),NA()) -> 44583 | AL27: =SUMIFS(Table1[Amount $],Table1[Category Type],"Expense",Table1[Date],Snapshot!AK27)*-1 -> 0 | AM27: =IF(AK27>TODAY(),NA(),SUM(AL$6:$AL27)) -> #N/A | AN27: =IF(OR(AK27=EOMONTH($AK$6,0),AK27=TODAY()),AM27,NA()) -> #N/A | AO27: =IF(MONTH(AO26)=MONTH(DATE(YEAR(AO26),MONTH(AO26),DAY(AO26)+1)),DATE(YEAR(AO26),MONTH(AO26),DAY(AO26)+1),NA()) -> 44552 | AP27: =SUMIFS(Table1[Amount $],Table1[Category Type],"Expense",Table1[Date],Snapshot!AO27)*-1 -> -32.19 | AQ27: =IF(AO27<=EOMONTH($AO$6,0),SUM(AP$6:$AP27),NA()) -> 83.93 | AR27: =IF(AO27=EOMONTH($AO$6,0),AQ27,NA()) -> #N/A | AU27: =IF(ISBLANK(AT27),"",SUMIFS(Table1[Amount $],Table1[Merchant],Snapshot!AT27,Table1[Month],Snapshot!$W$4)*-1) | AV27: =IF(ISBLANK(AT27),"",COUNTIFS(Table1[Merchant],Snapshot!AT27,Table1[Month],Snapshot!$W$4)) | AW27: =IFERROR(RANK(AV27,$AV$6:$AV$200)+COUNTIF($AV$6:AV27,AV27)-1,"") | AX27: =IFERROR(RANK(AU27,$AU$6:$AU$200)+COUNTIF($AU$6:AU27,AU27)-1,"")
D28: =IFERROR(IF(AND(MONTH(W4)=MONTH(TODAY()),YEAR(W4)=YEAR(TODAY())),AK39,AK42),"") -> Spent $137 more than this time last month | V28: =IF(ISBLANK(W28),"--",TEXT(W28,"mmmm")&" "&TEXT(W28,"YYYY")) -> April 2020 | W28: 43922 | AC28: Recreational & Entertainment | AD28: =SUMIFS(Table1[Amount $],Table1[Category],Snapshot!AC28,Table1[Month],Snapshot!$W$4)*-1 -> 0 | AE28: =RANK(AD28,$AD$6:$AD$35,0)+COUNTIF(AD$6:$AD28,AD28)-1 -> 22 | AJ28: =DATE(YEAR(AJ27),MONTH(AJ27),DAY(AJ27)+1) -> 36548 | AK28: =IF(MONTH(AK27)=MONTH(DATE(YEAR(AK27),MONTH(AK27),DAY(AK27)+1)),DATE(YEAR(AK27),MONTH(AK27),DAY(AK27)+1),NA()) -> 44584 | AL28: =SUMIFS(Table1[Amount $],Table1[Category Type],"Expense",Table1[Date],Snapshot!AK28)*-1 -> 0 | AM28: =IF(AK28>TODAY(),NA(),SUM(AL$6:$AL28)) -> #N/A | AN28: =IF(OR(AK28=EOMONTH($AK$6,0),AK28=TODAY()),AM28,NA()) -> #N/A | AO28: =IF(MONTH(AO27)=MONTH(DATE(YEAR(AO27),MONTH(AO27),DAY(AO27)+1)),DATE(YEAR(AO27),MONTH(AO27),DAY(AO27)+1),NA()) -> 44553 | AP28: =SUMIFS(Table1[Amount $],Table1[Category Type],"Expense",Table1[Date],Snapshot!AO28)*-1 -> 97.82 | AQ28: =IF(AO28<=EOMONTH($AO$6,0),SUM(AP$6:$AP28),NA()) -> 181.75 | AR28: =IF(AO28=EOMONTH($AO$6,0),AQ28,NA()) -> #N/A | AU28: =IF(ISBLANK(AT28),"",SUMIFS(Table1[Amount $],Table1[Merchant],Snapshot!AT28,Table1[Month],Snapshot!$W$4)*-1) | AV28: =IF(ISBLANK(AT28),"",COUNTIFS(Table1[Merchant],Snapshot!AT28,Table1[Month],Snapshot!$W$4)) | AW28: =IFERROR(RANK(AV28,$AV$6:$AV$200)+COUNTIF($AV$6:AV28,AV28)-1,"") | AX28: =IFERROR(RANK(AU28,$AU$6:$AU$200)+COUNTIF($AU$6:AU28,AU28)-1,"")
V29: =IF(ISBLANK(W29),"--",TEXT(W29,"mmmm")&" "&TEXT(W29,"YYYY")) -> March 2020 | W29: 43891 | AC29: Savings, Investing, &Debt | AD29: =SUMIFS(Table1[Amount $],Table1[Category],Snapshot!AC29,Table1[Month],Snapshot!$W$4)*-1 -> 0 | AE29: =RANK(AD29,$AD$6:$AD$35,0)+COUNTIF(AD$6:$AD29,AD29)-1 -> 23 | AJ29: =DATE(YEAR(AJ28),MONTH(AJ28),DAY(AJ28)+1) -> 36549 | AK29: =IF(MONTH(AK28)=MONTH(DATE(YEAR(AK28),MONTH(AK28),DAY(AK28)+1)),DATE(YEAR(AK28),MONTH(AK28),DAY(AK28)+1),NA()) -> 44585 | AL29: =SUMIFS(Table1[Amount $],Table1[Category Type],"Expense",Table1[Date],Snapshot!AK29)*-1 -> 0 | AM29: =IF(AK29>TODAY(),NA(),SUM(AL$6:$AL29)) -> #N/A | AN29: =IF(OR(AK29=EOMONTH($AK$6,0),AK29=TODAY()),AM29,NA()) -> #N/A | AO29: =IF(MONTH(AO28)=MONTH(DATE(YEAR(AO28),MONTH(AO28),DAY(AO28)+1)),DATE(YEAR(AO28),MONTH(AO28),DAY(AO28)+1),NA()) -> 44554 | AP29: =SUMIFS(Table1[Amount $],Table1[Category Type],"Expense",Table1[Date],Snapshot!AO29)*-1 -> 60 | AQ29: =IF(AO29<=EOMONTH($AO$6,0),SUM(AP$6:$AP29),NA()) -> 241.75 | AR29: =IF(AO29=EOMONTH($AO$6,0),AQ29,NA()) -> #N/A | AU29: =IF(ISBLANK(AT29),"",SUMIFS(Table1[Amount $],Table1[Merchant],Snapshot!AT29,Table1[Month],Snapshot!$W$4)*-1) | AV29: =IF(ISBLANK(AT29),"",COUNTIFS(Table1[Merchant],Snapshot!AT29,Table1[Month],Snapshot!$W$4)) | AW29: =IFERROR(RANK(AV29,$AV$6:$AV$200)+COUNTIF($AV$6:AV29,AV29)-1,"") | AX29: =IFERROR(RANK(AU29,$AU$6:$AU$200)+COUNTIF($AU$6:AU29,AU29)-1,"")
V30: =IF(ISBLANK(W30),"--",TEXT(W30,"mmmm")&" "&TEXT(W30,"YYYY")) -> February 2020 | W30: 43862 | AC30: Transportation | AD30: =SUMIFS(Table1[Amount $],Table1[Category],Snapshot!AC30,Table1[Month],Snapshot!$W$4)*-1 -> 0 | AE30: =RANK(AD30,$AD$6:$AD$35,0)+COUNTIF(AD$6:$AD30,AD30)-1 -> 24 | AJ30: =DATE(YEAR(AJ29),MONTH(AJ29),DAY(AJ29)+1) -> 36550 | AK30: =IF(MONTH(AK29)=MONTH(DATE(YEAR(AK29),MONTH(AK29),DAY(AK29)+1)),DATE(YEAR(AK29),MONTH(AK29),DAY(AK29)+1),NA()) -> 44586 | AL30: =SUMIFS(Table1[Amount $],Table1[Category Type],"Expense",Table1[Date],Snapshot!AK30)*-1 -> 0 | AM30: =IF(AK30>TODAY(),NA(),SUM(AL$6:$AL30)) -> #N/A | AN30: =IF(OR(AK30=EOMONTH($AK$6,0),AK30=TODAY()),AM30,NA()) -> #N/A | AO30: =IF(MONTH(AO29)=MONTH(DATE(YEAR(AO29),MONTH(AO29),DAY(AO29)+1)),DATE(YEAR(AO29),MONTH(AO29),DAY(AO29)+1),NA()) -> 44555 | AP30: =SUMIFS(Table1[Amount $],Table1[Category Type],"Expense",Table1[Date],Snapshot!AO30)*-1 -> 216.78 | AQ30: =IF(AO30<=EOMONTH($AO$6,0),SUM(AP$6:$AP30),NA()) -> 458.53 | AR30: =IF(AO30=EOMONTH($AO$6,0),AQ30,NA()) -> #N/A | AU30: =IF(ISBLANK(AT30),"",SUMIFS(Table1[Amount $],Table1[Merchant],Snapshot!AT30,Table1[Month],Snapshot!$W$4)*-1) | AV30: =IF(ISBLANK(AT30),"",COUNTIFS(Table1[Merchant],Snapshot!AT30,Table1[Month],Snapshot!$W$4)) | AW30: =IFERROR(RANK(AV30,$AV$6:$AV$200)+COUNTIF($AV$6:AV30,AV30)-1,"") | AX30: =IFERROR(RANK(AU30,$AU$6:$AU$200)+COUNTIF($AU$6:AU30,AU30)-1,"")
V31: =IF(ISBLANK(W31),"--",TEXT(W31,"mmmm")&" "&TEXT(W31,"YYYY")) -> January 2020 | W31: 43831 | AC31: Utilities | AD31: =SUMIFS(Table1[Amount $],Table1[Category],Snapshot!AC31,Table1[Month],Snapshot!$W$4)*-1 -> 0 | AE31: =RANK(AD31,$AD$6:$AD$35,0)+COUNTIF(AD$6:$AD31,AD31)-1 -> 25 | AJ31: =DATE(YEAR(AJ30),MONTH(AJ30),DAY(AJ30)+1) -> 36551 | AK31: =IF(MONTH(AK30)=MONTH(DATE(YEAR(AK30),MONTH(AK30),DAY(AK30)+1)),DATE(YEAR(AK30),MONTH(AK30),DAY(AK30)+1),NA()) -> 44587 | AL31: =SUMIFS(Table1[Amount $],Table1[Category Type],"Expense",Table1[Date],Snapshot!AK31)*-1 -> 0 | AM31: =IF(AK31>TODAY(),NA(),SUM(AL$6:$AL31)) -> #N/A | AN31: =IF(OR(AK31=EOMONTH($AK$6,0),AK31=TODAY()),AM31,NA()) -> #N/A | AO31: =IF(MONTH(AO30)=MONTH(DATE(YEAR(AO30),MONTH(AO30),DAY(AO30)+1)),DATE(YEAR(AO30),MONTH(AO30),DAY(AO30)+1),NA()) -> 44556 | AP31: =SUMIFS(Table1[Amount $],Table1[Category Type],"Expense",Table1[Date],Snapshot!AO31)*-1 -> 112.26 | AQ31: =IF(AO31<=EOMONTH($AO$6,0),SUM(AP$6:$AP31),NA()) -> 570.79 | AR31: =IF(AO31=EOMONTH($AO$6,0),AQ31,NA()) -> #N/A | AU31: =IF(ISBLANK(AT31),"",SUMIFS(Table1[Amount $],Table1[Merchant],Snapshot!AT31,Table1[Month],Snapshot!$W$4)*-1) | AV31: =IF(ISBLANK(AT31),"",COUNTIFS(Table1[Merchant],Snapshot!AT31,Table1[Month],Snapshot!$W$4)) | AW31: =IFERROR(RANK(AV31,$AV$6:$AV$200)+COUNTIF($AV$6:AV31,AV31)-1,"") | AX31: =IFERROR(RANK(AU31,$AU$6:$AU$200)+COUNTIF($AU$6:AU31,AU31)-1,"")
V32: =IF(ISBLANK(W32),"--",TEXT(W32,"mmmm")&" "&TEXT(W32,"YYYY")) -> -- | AD32: =SUMIFS(Table1[Amount $],Table1[Category],Snapshot!AC32,Table1[Month],Snapshot!$W$4)*-1 -> 0 | AE32: =RANK(AD32,$AD$6:$AD$35,0)+COUNTIF(AD$6:$AD32,AD32)-1 -> 26 | AJ32: =DATE(YEAR(AJ31),MONTH(AJ31),DAY(AJ31)+1) -> 36552 | AK32: =IF(MONTH(AK31)=MONTH(DATE(YEAR(AK31),MONTH(AK31),DAY(AK31)+1)),DATE(YEAR(AK31),MONTH(AK31),DAY(AK31)+1),NA()) -> 44588 | AL32: =SUMIFS(Table1[Amount $],Table1[Category Type],"Expense",Table1[Date],Snapshot!AK32)*-1 -> 0 | AM32: =IF(AK32>TODAY(),NA(),SUM(AL$6:$AL32)) -> #N/A | AN32: =IF(OR(AK32=EOMONTH($AK$6,0),AK32=TODAY()),AM32,NA()) -> #N/A | AO32: =IF(MONTH(AO31)=MONTH(DATE(YEAR(AO31),MONTH(AO31),DAY(AO31)+1)),DATE(YEAR(AO31),MONTH(AO31),DAY(AO31)+1),NA()) -> 44557 | AP32: =SUMIFS(Table1[Amount $],Table1[Category Type],"Expense",Table1[Date],Snapshot!AO32)*-1 -> 426.95 | AQ32: =IF(AO32<=EOMONTH($AO$6,0),SUM(AP$6:$AP32),NA()) -> 997.74 | AR32: =IF(AO32=EOMONTH($AO$6,0),AQ32,NA()) -> #N/A | AU32: =IF(ISBLANK(AT32),"",SUMIFS(Table1[Amount $],Table1[Merchant],Snapshot!AT32,Table1[Month],Snapshot!$W$4)*-1) | AV32: =IF(ISBLANK(AT32),"",COUNTIFS(Table1[Merchant],Snapshot!AT32,Table1[Month],Snapshot!$W$4)) | AW32: =IFERROR(RANK(AV32,$AV$6:$AV$200)+COUNTIF($AV$6:AV32,AV32)-1,"") | AX32: =IFERROR(RANK(AU32,$AU$6:$AU$200)+COUNTIF($AU$6:AU32,AU32)-1,"")
V33: =IF(ISBLANK(W33),"--",TEXT(W33,"mmmm")&" "&TEXT(W33,"YYYY")) -> -- | AD33: =SUMIFS(Table1[Amount $],Table1[Category],Snapshot!AC33,Table1[Month],Snapshot!$W$4)*-1 -> 0 | AE33: =RANK(AD33,$AD$6:$AD$35,0)+COUNTIF(AD$6:$AD33,AD33)-1 -> 27 | AJ33: =DATE(YEAR(AJ32),MONTH(AJ32),DAY(AJ32)+1) -> 36553 | AK33: =IF(MONTH(AK32)=MONTH(DATE(YEAR(AK32),MONTH(AK32),DAY(AK32)+1)),DATE(YEAR(AK32),MONTH(AK32),DAY(AK32)+1),NA()) -> 44589 | AL33: =SUMIFS(Table1[Amount $],Table1[Category Type],"Expense",Table1[Date],Snapshot!AK33)*-1 -> 0 | AM33: =IF(AK33>TODAY(),NA(),SUM(AL$6:$AL33)) -> #N/A | AN33: =IF(OR(AK33=EOMONTH($AK$6,0),AK33=TODAY()),AM33,NA()) -> #N/A | AO33: =IF(MONTH(AO32)=MONTH(DATE(YEAR(AO32),MONTH(AO32),DAY(AO32)+1)),DATE(YEAR(AO32),MONTH(AO32),DAY(AO32)+1),NA()) -> 44558 | AP33: =SUMIFS(Table1[Amount $],Table1[Category Type],"Expense",Table1[Date],Snapshot!AO33)*-1 -> 11 | AQ33: =IF(AO33<=EOMONTH($AO$6,0),SUM(AP$6:$AP33),NA()) -> 1008.74 | AR33: =IF(AO33=EOMONTH($AO$6,0),AQ33,NA()) -> #N/A | AU33: =IF(ISBLANK(AT33),"",SUMIFS(Table1[Amount $],Table1[Merchant],Snapshot!AT33,Table1[Month],Snapshot!$W$4)*-1) | AV33: =IF(ISBLANK(AT33),"",COUNTIFS(Table1[Merchant],Snapshot!AT33,Table1[Month],Snapshot!$W$4)) | AW33: =IFERROR(RANK(AV33,$AV$6:$AV$200)+COUNTIF($AV$6:AV33,AV33)-1,"") | AX33: =IFERROR(RANK(AU33,$AU$6:$AU$200)+COUNTIF($AU$6:AU33,AU33)-1,"")
V34: =IF(ISBLANK(W34),"--",TEXT(W34,"mmmm")&" "&TEXT(W34,"YYYY")) -> -- | AD34: =SUMIFS(Table1[Amount $],Table1[Category],Snapshot!AC34,Table1[Month],Snapshot!$W$4)*-1 -> 0 | AE34: =RANK(AD34,$AD$6:$AD$35,0)+COUNTIF(AD$6:$AD34,AD34)-1 -> 28 | AJ34: =DATE(YEAR(AJ33),MONTH(AJ33),DAY(AJ33)+1) -> 36554 | AK34: =IF(MONTH(AK33)=MONTH(DATE(YEAR(AK33),MONTH(AK33),DAY(AK33)+1)),DATE(YEAR(AK33),MONTH(AK33),DAY(AK33)+1),NA()) -> 44590 | AL34: =SUMIFS(Table1[Amount $],Table1[Category Type],"Expense",Table1[Date],Snapshot!AK34)*-1 -> 0 | AM34: =IF(AK34>TODAY(),NA(),SUM(AL$6:$AL34)) -> #N/A | AN34: =IF(OR(AK34=EOMONTH($AK$6,0),AK34=TODAY()),AM34,NA()) -> #N/A | AO34: =IF(MONTH(AO33)=MONTH(DATE(YEAR(AO33),MONTH(AO33),DAY(AO33)+1)),DATE(YEAR(AO33),MONTH(AO33),DAY(AO33)+1),NA()) -> 44559 | AP34: =SUMIFS(Table1[Amount $],Table1[Category Type],"Expense",Table1[Date],Snapshot!AO34)*-1 -> -918.57 | AQ34: =IF(AO34<=EOMONTH($AO$6,0),SUM(AP$6:$AP34),NA()) -> 90.17 | AR34: =IF(AO34=EOMONTH($AO$6,0),AQ34,NA()) -> #N/A | AU34: =IF(ISBLANK(AT34),"",SUMIFS(Table1[Amount $],Table1[Merchant],Snapshot!AT34,Table1[Month],Snapshot!$W$4)*-1) | AV34: =IF(ISBLANK(AT34),"",COUNTIFS(Table1[Merchant],Snapshot!AT34,Table1[Month],Snapshot!$W$4)) | AW34: =IFERROR(RANK(AV34,$AV$6:$AV$200)+COUNTIF($AV$6:AV34,AV34)-1,"") | AX34: =IFERROR(RANK(AU34,$AU$6:$AU$200)+COUNTIF($AU$6:AU34,AU34)-1,"")
V35: =IF(ISBLANK(W35),"--",TEXT(W35,"mmmm")&" "&TEXT(W35,"YYYY")) -> -- | AD35: =SUMIFS(Table1[Amount $],Table1[Category],Snapshot!AC35,Table1[Month],Snapshot!$W$4)*-1 -> 0 | AE35: =RANK(AD35,$AD$6:$AD$35,0)+COUNTIF(AD$6:$AD35,AD35)-1 -> 29 | AJ35: =DATE(YEAR(AJ34),MONTH(AJ34),DAY(AJ34)+1) -> 36555 | AK35: =IF(MONTH(AK34)=MONTH(DATE(YEAR(AK34),MONTH(AK34),DAY(AK34)+1)),DATE(YEAR(AK34),MONTH(AK34),DAY(AK34)+1),NA()) -> 44591 | AL35: =SUMIFS(Table1[Amount $],Table1[Category Type],"Expense",Table1[Date],Snapshot!AK35)*-1 -> 0 | AM35: =IF(AK35>TODAY(),NA(),SUM(AL$6:$AL35)) -> #N/A | AN35: =IF(OR(AK35=EOMONTH($AK$6,0),AK35=TODAY()),AM35,NA()) -> #N/A | AO35: =IF(MONTH(AO34)=MONTH(DATE(YEAR(AO34),MONTH(AO34),DAY(AO34)+1)),DATE(YEAR(AO34),MONTH(AO34),DAY(AO34)+1),NA()) -> 44560 | AP35: =SUMIFS(Table1[Amount $],Table1[Category Type],"Expense",Table1[Date],Snapshot!AO35)*-1 -> -352.09 | AQ35: =IF(AO35<=EOMONTH($AO$6,0),SUM(AP$6:$AP35),NA()) -> -261.92 | AR35: =IF(AO35=EOMONTH($AO$6,0),AQ35,NA()) -> #N/A | AU35: =IF(ISBLANK(AT35),"",SUMIFS(Table1[Amount $],Table1[Merchant],Snapshot!AT35,Table1[Month],Snapshot!$W$4)*-1) | AV35: =IF(ISBLANK(AT35),"",COUNTIFS(Table1[Merchant],Snapshot!AT35,Table1[Month],Snapshot!$W$4)) | AW35: =IFERROR(RANK(AV35,$AV$6:$AV$200)+COUNTIF($AV$6:AV35,AV35)-1,"") | AX35: =IFERROR(RANK(AU35,$AU$6:$AU$200)+COUNTIF($AU$6:AU35,AU35)-1,"")
V36: =IF(ISBLANK(W36),"--",TEXT(W36,"mmmm")&" "&TEXT(W36,"YYYY")) -> -- | AD36: =SUMIFS(Table1[Amount $],Table1[Category],Snapshot!AC36,Table1[Month],Snapshot!$W$4)*-1 -> 0 | AE36: =RANK(AD36,$AD$6:$AD$35,0)+COUNTIF(AD$6:$AD36,AD36)-1 -> 30 | AJ36: =DATE(YEAR(AJ35),MONTH(AJ35),DAY(AJ35)+1) -> 36556 | AK36: =IF(MONTH(AK35)=MONTH(DATE(YEAR(AK35),MONTH(AK35),DAY(AK35)+1)),DATE(YEAR(AK35),MONTH(AK35),DAY(AK35)+1),NA()) -> 44592 | AL36: =SUMIFS(Table1[Amount $],Table1[Category Type],"Expense",Table1[Date],Snapshot!AK36)*-1 -> 0 | AM36: =IF(AK36>TODAY(),NA(),SUM(AL$6:$AL36)) -> #N/A | AN36: =IF(OR(AK36=EOMONTH($AK$6,0),AK36=TODAY()),AM36,NA()) -> #N/A | AO36: =IF(MONTH(AO35)=MONTH(DATE(YEAR(AO35),MONTH(AO35),DAY(AO35)+1)),DATE(YEAR(AO35),MONTH(AO35),DAY(AO35)+1),NA()) -> 44561 | AP36: =SUMIFS(Table1[Amount $],Table1[Category Type],"Expense",Table1[Date],Snapshot!AO36)*-1 -> 84.37 | AQ36: =IF(AO36<=EOMONTH($AO$6,0),SUM(AP$6:$AP36),NA()) -> -177.55 | AR36: =IF(AO36=EOMONTH($AO$6,0),AQ36,NA()) -> -177.55 | AU36: =IF(ISBLANK(AT36),"",SUMIFS(Table1[Amount $],Table1[Merchant],Snapshot!AT36,Table1[Month],Snapshot!$W$4)*-1) | AV36: =IF(ISBLANK(AT36),"",COUNTIFS(Table1[Merchant],Snapshot!AT36,Table1[Month],Snapshot!$W$4)) | AW36: =IFERROR(RANK(AV36,$AV$6:$AV$200)+COUNTIF($AV$6:AV36,AV36)-1,"") | AX36: =IFERROR(RANK(AU36,$AU$6:$AU$200)+COUNTIF($AU$6:AU36,AU36)-1,"")
V37: =IF(ISBLANK(W37),"--",TEXT(W37,"mmmm")&" "&TEXT(W37,"YYYY")) -> -- | AD37: =SUMIFS(Table1[Amount $],Table1[Category],Snapshot!AC37,Table1[Month],Snapshot!$W$4)*-1 -> 0 | AE37: =RANK(AD37,$AD$6:$AD$35,0)+COUNTIF(AD$6:$AD37,AD37)-1 -> 31 | AU37: =IF(ISBLANK(AT37),"",SUMIFS(Table1[Amount $],Table1[Merchant],Snapshot!AT37,Table1[Month],Snapshot!$W$4)*-1) | AV37: =IF(ISBLANK(AT37),"",COUNTIFS(Table1[Merchant],Snapshot!AT37,Table1[Month],Snapshot!$W$4)) | AW37: =IFERROR(RANK(AV37,$AV$6:$AV$200)+COUNTIF($AV$6:AV37,AV37)-1,"") | AX37: =IFERROR(RANK(AU37,$AU$6:$AU$200)+COUNTIF($AU$6:AU37,AU37)-1,"")
V38: =IF(ISBLANK(W38),"--",TEXT(W38,"mmmm")&" "&TEXT(W38,"YYYY")) -> -- | AD38: =SUMIFS(Table1[Amount $],Table1[Category],Snapshot!AC38,Table1[Month],Snapshot!$W$4)*-1 -> 0 | AE38: =RANK(AD38,$AD$6:$AD$35,0)+COUNTIF(AD$6:$AD38,AD38)-1 -> 32 | AK38: =TODAY() -> 44567 | AM38: {=INDEX(AM6:AM36,MATCH(AK38,AK6:AK36,0),0)} -> -50.9 | AO38: =DATE(YEAR(AK38),MONTH(AK38)-1,DAY(AK38)) -> 44536 | AQ38: {=INDEX(AQ6:AQ36,MATCH(AO38,AO6:AO36,0),0)} -> -188.06 | AU38: =IF(ISBLANK(AT38),"",SUMIFS(Table1[Amount $],Table1[Merchant],Snapshot!AT38,Table1[Month],Snapshot!$W$4)*-1) | AV38: =IF(ISBLANK(AT38),"",COUNTIFS(Table1[Merchant],Snapshot!AT38,Table1[Month],Snapshot!$W$4)) | AW38: =IFERROR(RANK(AV38,$AV$6:$AV$200)+COUNTIF($AV$6:AV38,AV38)-1,"") | AX38: =IFERROR(RANK(AU38,$AU$6:$AU$200)+COUNTIF($AU$6:AU38,AU38)-1,"")
V39: =IF(ISBLANK(W39),"--",TEXT(W39,"mmmm")&" "&TEXT(W39,"YYYY")) -> -- | AD39: =SUMIFS(Table1[Amount $],Table1[Category],Snapshot!AC39,Table1[Month],Snapshot!$W$4)*-1 -> 0 | AE39: =RANK(AD39,$AD$6:$AD$35,0)+COUNTIF(AD$6:$AD39,AD39)-1 -> 33 | AK39: =IF(AM38>AQ38,"Spent "&TEXT(AM38-AQ38,"$#,##0")&" more","Spent "&TEXT((AM38-AQ38)*-1,"$#,##0")&" less")&" than this time last month" -> Spent $137 more than this time last month | AU39: =IF(ISBLANK(AT39),"",SUMIFS(Table1[Amount $],Table1[Merchant],Snapshot!AT39,Table1[Month],Snapshot!$W$4)*-1) | AV39: =IF(ISBLANK(AT39),"",COUNTIFS(Table1[Merchant],Snapshot!AT39,Table1[Month],Snapshot!$W$4)) | AW39: =IFERROR(RANK(AV39,$AV$6:$AV$200)+COUNTIF($AV$6:AV39,AV39)-1,"") | AX39: =IFERROR(RANK(AU39,$AU$6:$AU$200)+COUNTIF($AU$6:AU39,AU39)-1,"")
V40: =IF(ISBLANK(W40),"--",TEXT(W40,"mmmm")&" "&TEXT(W40,"YYYY")) -> -- | AD40: =SUMIFS(Table1[Amount $],Table1[Category],Snapshot!AC40,Table1[Month],Snapshot!$W$4)*-1 -> 0 | AE40: =RANK(AD40,$AD$6:$AD$35,0)+COUNTIF(AD$6:$AD40,AD40)-1 -> 34 | AU40: =IF(ISBLANK(AT40),"",SUMIFS(Table1[Amount $],Table1[Merchant],Snapshot!AT40,Table1[Month],Snapshot!$W$4)*-1) | AV40: =IF(ISBLANK(AT40),"",COUNTIFS(Table1[Merchant],Snapshot!AT40,Table1[Month],Snapshot!$W$4)) | AW40: =IFERROR(RANK(AV40,$AV$6:$AV$200)+COUNTIF($AV$6:AV40,AV40)-1,"") | AX40: =IFERROR(RANK(AU40,$AU$6:$AU$200)+COUNTIF($AU$6:AU40,AU40)-1,"")
V41: =IF(ISBLANK(W41),"--",TEXT(W41,"mmmm")&" "&TEXT(W41,"YYYY")) -> -- | AD41: =SUMIFS(Table1[Amount $],Table1[Category],Snapshot!AC41,Table1[Month],Snapshot!$W$4)*-1 -> 0 | AE41: =RANK(AD41,$AD$6:$AD$35,0)+COUNTIF(AD$6:$AD41,AD41)-1 -> 35 | AK41: =IFERROR(MAX(AK6:AK36),IFERROR(AK35,IF(AK34,AK33))) -> 44592 | AM41: {=INDEX(AM6:AM36,MATCH(AK41,AK6:AK36,0),0)} -> #N/A | AO41: =IFERROR(MAX(AO6:AO36),IFERROR(AO35,IF(AO34,AO33))) -> 44561 | AQ41: {=INDEX(AQ6:AQ36,MATCH(AO41,AO6:AO36,0),0)} -> -177.55 | AU41: =IF(ISBLANK(AT41),"",SUMIFS(Table1[Amount $],Table1[Merchant],Snapshot!AT41,Table1[Month],Snapshot!$W$4)*-1) | AV41: =IF(ISBLANK(AT41),"",COUNTIFS(Table1[Merchant],Snapshot!AT41,Table1[Month],Snapshot!$W$4)) | AW41: =IFERROR(RANK(AV41,$AV$6:$AV$200)+COUNTIF($AV$6:AV41,AV41)-1,"") | AX41: =IFERROR(RANK(AU41,$AU$6:$AU$200)+COUNTIF($AU$6:AU41,AU41)-1,"")
