Workbook
Name allowance: Summary!$J$16
Name AprSun1: DATE('Income Calendar'!CalendarYear,4,1)-WEEKDAY(DATE('Income Calendar'!CalendarYear,4,1))
Name AprSun1: DATE(CalendarYear,4,1)-WEEKDAY(DATE(CalendarYear,4,1))
Name AugSun1: DATE('Income Calendar'!CalendarYear,8,1)-WEEKDAY(DATE('Income Calendar'!CalendarYear,8,1))
Name AugSun1: DATE(CalendarYear,8,1)-WEEKDAY(DATE(CalendarYear,8,1))
Name Budget: Summary!$J$11
Name CalendarYear: 'Income Calendar'!Year1
Name CalendarYear: 'Expense Calendar'!Year1
Name DecSun1: DATE('Income Calendar'!CalendarYear,12,1)-WEEKDAY(DATE('Income Calendar'!CalendarYear,12,1))
Name DecSun1: DATE(CalendarYear,12,1)-WEEKDAY(DATE(CalendarYear,12,1))
Name FebSun1: DATE('Income Calendar'!CalendarYear,2,1)-WEEKDAY(DATE('Income Calendar'!CalendarYear,2,1))
Name FebSun1: DATE(CalendarYear,2,1)-WEEKDAY(DATE(CalendarYear,2,1))
Name fixed: fixed_expenses4[#All]
Name fixed: fixed_expenses[#All]
Name income: 'Income Calendar'!$N$3
Name JanSun1: DATE('Income Calendar'!CalendarYear,1,1)-WEEKDAY(DATE('Income Calendar'!CalendarYear,1,1))
Name JanSun1: DATE(CalendarYear,1,1)-WEEKDAY(DATE(CalendarYear,1,1))
Name JulSun1: DATE('Income Calendar'!CalendarYear,7,1)-WEEKDAY(DATE('Income Calendar'!CalendarYear,7,1))
Name JulSun1: DATE(CalendarYear,7,1)-WEEKDAY(DATE(CalendarYear,7,1))
Name JunSun1: DATE('Income Calendar'!CalendarYear,6,1)-WEEKDAY(DATE('Income Calendar'!CalendarYear,6,1))
Name JunSun1: DATE(CalendarYear,6,1)-WEEKDAY(DATE(CalendarYear,6,1))
Name MarSun1: DATE('Income Calendar'!CalendarYear,3,1)-WEEKDAY(DATE('Income Calendar'!CalendarYear,3,1))
Name MarSun1: DATE(CalendarYear,3,1)-WEEKDAY(DATE(CalendarYear,3,1))
Name MaySun1: DATE('Income Calendar'!CalendarYear,5,1)-WEEKDAY(DATE('Income Calendar'!CalendarYear,5,1))
Name MaySun1: DATE(CalendarYear,5,1)-WEEKDAY(DATE(CalendarYear,5,1))
Name Month1: 'Expense Calendar'!$B$3
Name Month1: 'Income Calendar'!$B$3
Name NovSun1: DATE('Income Calendar'!CalendarYear,11,1)-WEEKDAY(DATE('Income Calendar'!CalendarYear,11,1))
Name NovSun1: DATE(CalendarYear,11,1)-WEEKDAY(DATE(CalendarYear,11,1))
Name OctSun1: DATE('Income Calendar'!CalendarYear,10,1)-WEEKDAY(DATE('Income Calendar'!CalendarYear,10,1))
Name OctSun1: DATE(CalendarYear,10,1)-WEEKDAY(DATE(CalendarYear,10,1))
Name SepSun1: DATE('Income Calendar'!CalendarYear,9,1)-WEEKDAY(DATE('Income Calendar'!CalendarYear,9,1))
Name SepSun1: DATE(CalendarYear,9,1)-WEEKDAY(DATE(CalendarYear,9,1))
Name StartMonth: 'Income Calendar'!$B$4
Name StartMonth: 'Expense Calendar'!$B$4
Name Year1: VALUE(LEFT('Expense Calendar'!$B$1,4))
Name Year1: VALUE(LEFT('Income Calendar'!$B$1,4))

Sheet Summary
A1: lynnangelcontracting@gmail.com | AJ1: *No bills can be due after the 28th due to February
B2: Jan | I2: 1 | J2: =I2+1 -> 2 | K2: =J2+1 -> 3 | L2: =K2+1 -> 4 | M2: =L2+1 -> 5 | N2: =M2+1 -> 6 | O2: =N2+1 -> 7 | P2: =O2+1 -> 8 | Q2: =P2+1 -> 9 | ... AM2: =AL2+1 -> 31
B3: Begin Cash Flow | C3: Income | D3: Fixed Expenses | E3: End Cash Flow | K3: Rent | W3: Paul Phone Bill | AB3: Lynn Phone Bill
A4: ='Expense Calendar'!B6 -> 27 | C4: ='Income Calendar'!P13 -> 800 | D4: ='Expense Calendar'!P13 -> 0 | E4: =C4-D4 -> 800 | W4: Electric
A5: ='Expense Calendar'!B15 -> 3 | B5: =E4 -> 800 | C5: ='Income Calendar'!P22 -> 800 | D5: ='Expense Calendar'!P22 -> 1200 | E5: =C5-D5+B5 -> 400
A6: ='Expense Calendar'!B24 -> 10 | B6: =E5 -> 400 | C6: ='Income Calendar'!P31 -> 800 | D6: ='Expense Calendar'!P31 -> 110 | E6: =C6-D6+B6 -> 1090
A7: ='Expense Calendar'!B33 -> 17 | B7: =E6 -> 1090 | C7: ='Income Calendar'!P40 -> 1570 | D7: ='Expense Calendar'!P40 -> 0 | E7: =C7-D7+B7 -> 2660
A8: ='Expense Calendar'!B42 -> 24 | B8: =E7 -> 2660 | C8: ='Income Calendar'!P49 -> 800 | D8: ='Expense Calendar'!P49 -> 0 | E8: =C8-D8+B8 -> 3460
A9: ='Expense Calendar'!B51 -> 31 | B9: =E8 -> 3460 | C9: ='Income Calendar'!P58 -> 0 | D9: ='Expense Calendar'!P58 -> 0 | E9: =C9-D9+B9 -> 3460
B10: FEB | E10: =E9 -> 3460 | F10: *What cash do we have in our bank right now? (Feb ) | J10: Budget | K10: Leftover (Cash) | L10: Income | M10: % Income
B11: Begin Cash Flow | C11: Income | D11: Fixed Expenses | E11: End Cash Flow | F11: Varibale Expense | G11: Savings | I11: Projected Weekly | J11: 200 | K11: =E97 -> 28882 | L11: =income -> 62420 | M11: =K11/L11 -> 0.46270426
A12: ='Expense Calendar'!B64 -> 31 | B12: =E10 -> 3460 | C12: ='Income Calendar'!P71 -> 1570 | D12: ='Expense Calendar'!P71 -> 1432 | E12: =C12-D12+B12 -> 3598 | F12: =-1*Budget -> -200 | G12: =allowance*-1 -> -50 | I12: Standard | J12: 524.2449 | K12: =L11*0.2 -> 12484 | M12: =K12/L11 -> 0.2
A13: ='Expense Calendar'!B73 -> 7 | B13: =E12+F12+G12 -> 3348 | C13: ='Income Calendar'!P80 -> 800 | D13: ='Expense Calendar'!P80 -> 0 | E13: =C13-D13+B13 -> 4148 | F13: =-1*Budget -> -200 | G13: =allowance*-1 -> -50 | I13: Monthly | J13: =Budget*4 -> 800
A14: ='Expense Calendar'!B82 -> 14 | B14: =E13+F13+G13 -> 3898 | C14: ='Income Calendar'!P89 -> 1570 | D14: ='Expense Calendar'!P89 -> 342 | E14: =C14-D14+B14 -> 5126 | F14: =-1*Budget -> -200 | G14: =allowance*-1 -> -50
A15: ='Expense Calendar'!B91 -> 21 | B15: =E14+F14+G14 -> 4876 | C15: ='Income Calendar'!P98 -> 800 | D15: ='Expense Calendar'!P98 -> 0 | E15: =C15-D15+B15 -> 5676 | F15: =-1*Budget -> -200 | G15: =allowance*-1 -> -50 | J15: Savings | K15: Total
A16: ='Expense Calendar'!B100 -> 28 | B16: =E15+F15+G15 -> 5426 | C16: ='Income Calendar'!P107 -> 0 | D16: ='Expense Calendar'!P107 -> 0 | E16: =C16-D16+B16 -> 5426 | I16: Weekly | J16: 50 | K16: =SUM(G12:G17,G20:G25,G28:G33,G36:G41,G44:G49,G52:G57,G60:G65,G68:G73,G76:G81,G84:G89,G92:G97)*-1 -> 2450 | L16: *without interest
A17: ='Expense Calendar'!B109 -> 7 | B17: =E16+F16+G16 -> 5426 | C17: ='Income Calendar'!P116 -> 0 | D17: ='Expense Calendar'!P116 -> 0 | E17: =C17-D17+B17 -> 5426 | K17: current interest rate | L17: 0.0005 | M17: Bank of America
B18: MAR
B19: Begin Cash Flow | C19: Income | D19: Fixed Expenses | E19: End Cash Flow | F19: Varibale Expense | G19: Savings
A20: ='Expense Calendar'!B122 -> 28 | C20: ='Income Calendar'!P129 -> 1570 | D20: ='Expense Calendar'!P129 -> 1432 | E20: =C20-D20+E17 -> 5564 | F20: =-1*Budget -> -200 | G20: =allowance*-1 -> -50
A21: ='Expense Calendar'!B131 -> 7 | B21: =E20+F20+G20 -> 5314 | C21: ='Income Calendar'!P138 -> 800 | D21: ='Expense Calendar'!P138 -> 0 | E21: =C21-D21+B21 -> 6114 | F21: =-1*Budget -> -200 | G21: =allowance*-1 -> -50
A22: ='Expense Calendar'!B140 -> 14 | B22: =E21+F21+G21 -> 5864 | C22: ='Income Calendar'!P147 -> 1570 | D22: ='Expense Calendar'!P147 -> 342 | E22: =C22-D22+B22 -> 7092 | F22: =-1*Budget -> -200 | G22: =allowance*-1 -> -50
A23: ='Expense Calendar'!B149 -> 21 | B23: =E22+F22+G22 -> 6842 | C23: ='Income Calendar'!P156 -> 800 | D23: ='Expense Calendar'!P156 -> 0 | E23: =C23-D23+B23 -> 7642 | F23: =-1*Budget -> -200 | G23: =allowance*-1 -> -50
A24: ='Expense Calendar'!B158 -> 28 | B24: =E23+F23+G23 -> 7392 | C24: ='Income Calendar'!P165 -> 0 | D24: ='Expense Calendar'!P165 -> 0 | E24: =C24-D24+B24 -> 7392
A25: ='Expense Calendar'!B167 -> 4 | B25: =E24+F24+G24 -> 7392 | C25: ='Income Calendar'!P174 -> 0 | D25: ='Expense Calendar'!P174 -> 0 | E25: =C25-D25+B25 -> 7392
B26: APR
B27: Begin Cash Flow | C27: Income | D27: Fixed Expenses | E27: End Cash Flow | F27: Varibale Expense | G27: Savings
A28: ='Expense Calendar'!B180 -> 28 | C28: ='Income Calendar'!P187 -> 1570 | D28: ='Expense Calendar'!P187 -> 1432 | E28: =C28-D28+E25 -> 7530 | F28: =-1*Budget -> -200 | G28: =allowance*-1 -> -50
A29: ='Expense Calendar'!B189 -> 4 | B29: =E28+F28+G28 -> 7280 | C29: ='Income Calendar'!P196 -> 800 | D29: ='Expense Calendar'!P196 -> 0 | E29: =C29-D29+B29 -> 8080 | F29: =-1*Budget -> -200 | G29: =allowance*-1 -> -50
A30: ='Expense Calendar'!B198 -> 11 | B30: =E29+F29+G29 -> 7830 | C30: ='Income Calendar'!P205 -> 1570 | D30: ='Expense Calendar'!P205 -> 342 | E30: =C30-D30+B30 -> 9058 | F30: =-1*Budget -> -200 | G30: =allowance*-1 -> -50
A31: ='Expense Calendar'!B207 -> 18 | B31: =E30+F30+G30 -> 8808 | C31: ='Income Calendar'!P214 -> 800 | D31: ='Expense Calendar'!P214 -> 0 | E31: =C31-D31+B31 -> 9608 | F31: =-1*Budget -> -200 | G31: =allowance*-1 -> -50
A32: ='Expense Calendar'!B216 -> 25 | B32: =E31+F31+G31 -> 9358 | C32: ='Income Calendar'!P223 -> 1570 | D32: ='Expense Calendar'!P223 -> 232 | E32: =C32-D32+B32 -> 10696 | F32: =-1*Budget -> -200 | G32: =allowance*-1 -> -50
A33: ='Expense Calendar'!B225 -> 2 | B33: =E32+F32+G32 -> 10446 | C33: ='Income Calendar'!P232 -> 0 | D33: ='Expense Calendar'!P232 -> 0 | E33: =C33-D33+B33 -> 10446
B34: MAY
B35: Begin Cash Flow | C35: Income | D35: Fixed Expenses | E35: End Cash Flow | F35: Varibale Expense | G35: Savings
A36: ='Expense Calendar'!B238 -> 25 | C36: ='Income Calendar'!P245 -> 0 | D36: ='Expense Calendar'!P245 -> 0 | E36: =C36-D36+E33 -> 10446 | F36: =-1*Budget -> -200 | G36: =allowance*-1 -> -50
A37: ='Expense Calendar'!B247 -> 2 | B37: =E36+F36+G36 -> 10196 | C37: ='Income Calendar'!P254 -> 1570 | D37: ='Expense Calendar'!P254 -> 1200 | E37: =C37-D37+B37 -> 10566 | F37: =-1*Budget -> -200 | G37: =allowance*-1 -> -50
A38: ='Expense Calendar'!B256 -> 9 | B38: =E37+F37+G37 -> 10316 | C38: ='Income Calendar'!P263 -> 800 | D38: ='Expense Calendar'!P263 -> 342 | E38: =C38-D38+B38 -> 10774 | F38: =-1*Budget -> -200 | G38: =allowance*-1 -> -50
A39: ='Expense Calendar'!B265 -> 16 | B39: =E38+F38+G38 -> 10524 | C39: ='Income Calendar'!P272 -> 1570 | D39: ='Expense Calendar'!P272 -> 0 | E39: =C39-D39+B39 -> 12094 | F39: =-1*Budget -> -200 | G39: =allowance*-1 -> -50
A40: ='Expense Calendar'!B274 -> 23 | B40: =E39+F39+G39 -> 11844 | C40: ='Income Calendar'!P281 -> 800 | D40: ='Expense Calendar'!P281 -> 232 | E40: =C40-D40+B40 -> 12412 | F40: =-1*Budget -> -200 | G40: =allowance*-1 -> -50
...

Sheet Expense Calendar
B1: =YEAR(TODAY()) -> 2021 | C1: EXPENSE CALENDAR
A2: January label is in cell at right, Monthly Total label in cell L2, Grand Total label in N2, and Tip in G2. | B2: JANUARY | G2: TIP: Change the year in cell B1 to update the calendar year. | L2: MONTHLY TOTAL | N2: GRAND TOTAL
A3: Monthly Total is auto calculated in cell L3 and Grand Total in N3. | F3: =IFERROR(WEEKDAY(DATEVALUE(B2&" 1, "&Year1)),"") -> 6 | L3: =SUM(P13,P22,P31,P40,P49,P58) -> 1310 | N3: =SUM(P:P) -> 21288
A4: January calendar is in cells B5 through O58. | B4: 1 | D4: 2 | F4: 3 | H4: 4 | J4: 5 | L4: 6 | N4: 7
A5: Weekdays are in cells at right, cells B5 through N5, and Weekly Total label in cell P5. | B5: SUNDAY | D5: MONDAY | E5: =IF(WEEKDAY(DATEVALUE(Month1&" 1, "&Year1))=COLUMN(#REF!),1,IF(LEN(C5)>0,C5+1,"")) -> #VALUE! | F5: TUESDAY | G5: =IF(WEEKDAY(DATEVALUE(Month1&" 1, "&Year1))=COLUMN(#REF!),1,IF(LEN(E5)>0,E5+1,"")) -> #VALUE! | H5: WEDNESDAY | I5: =IF(WEEKDAY(DATEVALUE(Month1&" 1, "&Year1))=COLUMN(#REF!),1,IF(LEN(G5)>0,G5+1,"")) -> #VALUE! | J5: THURSDAY | K5: =IF(WEEKDAY(DATEVALUE(Month1&" 1, "&Year1))=COLUMN(#REF!),1,IF(LEN(I5)>0,I5+1,"")) -> #VALUE! | L5: FRIDAY | M5: =IF(WEEKDAY(DATEVALUE(Month1&" 1, "&Year1))=COLUMN(#REF!),1,IF(LEN(K5)>0,K5+1,"")) -> #VALUE! | N5: SATURDAY | O5: =IF(WEEKDAY(DATEVALUE(Month1&" 1, "&Year1))=COLUMN(#REF!),1,IF(LEN(M5)>0,M5+1,"")) -> #VALUE! | P5: WEEKLY TOTAL | T5: Description | U5: Amount | V5: Included
A6: Calendar dates are in cells at right, cells B6 through O6. If it doesn’t start with number 1, then it is date of previous month. | B6: =DAY(IF(DAY(JanSun1)=1,JanSun1-6,JanSun1+1)) -> 27 | D6: =DAY(IF(DAY(JanSun1)=1,JanSun1-5,JanSun1+2)) -> 28 | F6: =DAY(IF(DAY(JanSun1)=1,JanSun1-4,JanSun1+3)) -> 29 | H6: =DAY(IF(DAY(JanSun1)=1,JanSun1-3,JanSun1+4)) -> 30 | J6: =DAY(IF(DAY(JanSun1)=1,JanSun1-2,JanSun1+5)) -> 31 | L6: =DAY(IF(DAY(JanSun1)=1,JanSun1-1,JanSun1+6)) -> 1 | N6: =DAY(IF(DAY(JanSun1)=1,JanSun1,JanSun1+7)) -> 2 | T6: Paul Phone Bill | U6: 60
A7: Description and Amount labels are in cells at right, cells B7 through O7. | B7: DESCRIPTION | C7: AMOUNT | D7: DESCRIPTION | E7: AMOUNT | F7: DESCRIPTION | G7: AMOUNT | H7: DESCRIPTION | I7: AMOUNT | J7: DESCRIPTION | K7: AMOUNT | L7: DESCRIPTION | M7: AMOUNT | N7: DESCRIPTION | O7: AMOUNT | T7: Cairo Phone Bill | U7: 115 | V7: *Disney Plus, Hulu, Espn, Kids Phone
A8: Enter Description and Amount of each expense in cells at right, cells B8 through O12. Next instruction is in cell A13. | B8: =IF(HLOOKUP(B6,Summary!$I$2:$AM$7,2,0)=0,"",HLOOKUP(B6,Summary!$I$2:$AM$7,2,0)) | C8: =IFERROR(VLOOKUP(B8,fixed_expenses[],2,0),"") | D8: =IF(HLOOKUP(D6,Summary!$I$2:$AM$7,2,0)=0,"",HLOOKUP(D6,Summary!$I$2:$AM$7,2,0)) | E8: =IFERROR(VLOOKUP(D8,fixed_expenses[],2,0),"") | F8: =IF(HLOOKUP(F6,Summary!$I$2:$AM$7,2,0)=0,"",HLOOKUP(F6,Summary!$I$2:$AM$7,2,0)) | G8: =IFERROR(VLOOKUP(F8,fixed_expenses[],2,0),"") | H8: =IF(HLOOKUP(H6,Summary!$I$2:$AM$7,2,0)=0,"",HLOOKUP(H6,Summary!$I$2:$AM$7,2,0)) | I8: =IFERROR(VLOOKUP(H8,fixed_expenses[],2,0),"") | J8: =IF(HLOOKUP(J6,Summary!$I$2:$AM$7,2,0)=0,"",HLOOKUP(J6,Summary!$I$2:$AM$7,2,0)) | K8: =IFERROR(VLOOKUP(J8,fixed_expenses[],2,0),"") | L8: =IF(HLOOKUP(L6,Summary!$I$2:$AM$7,2,0)=0,"",HLOOKUP(L6,Summary!$I$2:$AM$7,2,0)) | M8: =IFERROR(VLOOKUP(L8,fixed_expenses[],2,0),"") | N8: =IF(HLOOKUP(N6,Summary!$I$2:$AM$7,2,0)=0,"",HLOOKUP(N6,Summary!$I$2:$AM$7,2,0)) | O8: =IFERROR(VLOOKUP(N8,fixed_expenses[],2,0),"") | T8: Electric | U8: 50
B9: =IF(HLOOKUP(B6,Summary!$I$2:$AM$7,3,0)=0,"",HLOOKUP(B6,Summary!$I$2:$AM$7,3,0)) | C9: =IFERROR(VLOOKUP(B9,fixed_expenses[],2,0),"") | D9: =IF(HLOOKUP(D6,Summary!$I$2:$AM$7,3,0)=0,"",HLOOKUP(D6,Summary!$I$2:$AM$7,3,0)) | E9: =IFERROR(VLOOKUP(D9,fixed_expenses[],2,0),"") | F9: =IF(HLOOKUP(F6,Summary!$I$2:$AM$7,3,0)=0,"",HLOOKUP(F6,Summary!$I$2:$AM$7,3,0)) | G9: =IFERROR(VLOOKUP(F9,fixed_expenses[],2,0),"") | H9: =IF(HLOOKUP(H6,Summary!$I$2:$AM$7,3,0)=0,"",HLOOKUP(H6,Summary!$I$2:$AM$7,3,0)) | I9: =IFERROR(VLOOKUP(H9,fixed_expenses[],2,0),"") | J9: =IF(HLOOKUP(J6,Summary!$I$2:$AM$7,3,0)=0,"",HLOOKUP(J6,Summary!$I$2:$AM$7,3,0)) | K9: =IFERROR(VLOOKUP(J9,fixed_expenses[],2,0),"") | L9: =IF(HLOOKUP(L6,Summary!$I$2:$AM$7,3,0)=0,"",HLOOKUP(L6,Summary!$I$2:$AM$7,3,0)) | M9: =IFERROR(VLOOKUP(L9,fixed_expenses[],2,0),"") | N9: =IF(HLOOKUP(N6,Summary!$I$2:$AM$7,3,0)=0,"",HLOOKUP(N6,Summary!$I$2:$AM$7,3,0)) | O9: =IFERROR(VLOOKUP(N9,fixed_expenses[],2,0),"") | T9: Rent | U9: 1200
B10: =IF(HLOOKUP(B6,Summary!$I$2:$AM$7,4,0)=0,"",HLOOKUP(B6,Summary!$I$2:$AM$7,4,0)) | C10: =IFERROR(VLOOKUP(B10,fixed_expenses[],2,0),"") | D10: =IF(HLOOKUP(D6,Summary!$I$2:$AM$7,4,0)=0,"",HLOOKUP(D6,Summary!$I$2:$AM$7,4,0)) | E10: =IFERROR(VLOOKUP(D10,fixed_expenses[],2,0),"") | F10: =IF(HLOOKUP(F6,Summary!$I$2:$AM$7,4,0)=0,"",HLOOKUP(F6,Summary!$I$2:$AM$7,4,0)) | G10: =IFERROR(VLOOKUP(F10,fixed_expenses[],2,0),"") | H10: =IF(HLOOKUP(H6,Summary!$I$2:$AM$7,4,0)=0,"",HLOOKUP(H6,Summary!$I$2:$AM$7,4,0)) | I10: =IFERROR(VLOOKUP(H10,fixed_expenses[],2,0),"") | J10: =IF(HLOOKUP(J6,Summary!$I$2:$AM$7,4,0)=0,"",HLOOKUP(J6,Summary!$I$2:$AM$7,4,0)) | K10: =IFERROR(VLOOKUP(J10,fixed_expenses[],2,0),"") | L10: =IF(HLOOKUP(L6,Summary!$I$2:$AM$7,4,0)=0,"",HLOOKUP(L6,Summary!$I$2:$AM$7,4,0)) | M10: =IFERROR(VLOOKUP(L10,fixed_expenses[],2,0),"") | N10: =IF(HLOOKUP(N6,Summary!$I$2:$AM$7,4,0)=0,"",HLOOKUP(N6,Summary!$I$2:$AM$7,4,0)) | O10: =IFERROR(VLOOKUP(N10,fixed_expenses[],2,0),"") | T10: Car | U10: 232
B11: =IF(HLOOKUP(B6,Summary!$I$2:$AM$7,5,0)=0,"",HLOOKUP(B6,Summary!$I$2:$AM$7,5,0)) | C11: =IFERROR(VLOOKUP(B11,fixed_expenses[],2,0),"") | D11: =IF(HLOOKUP(D6,Summary!$I$2:$AM$7,5,0)=0,"",HLOOKUP(D6,Summary!$I$2:$AM$7,5,0)) | E11: =IFERROR(VLOOKUP(D11,fixed_expenses[],2,0),"") | F11: =IF(HLOOKUP(F6,Summary!$I$2:$AM$7,5,0)=0,"",HLOOKUP(F6,Summary!$I$2:$AM$7,5,0)) | G11: =IFERROR(VLOOKUP(F11,fixed_expenses[],2,0),"") | H11: =IF(HLOOKUP(H6,Summary!$I$2:$AM$7,5,0)=0,"",HLOOKUP(H6,Summary!$I$2:$AM$7,5,0)) | I11: =IFERROR(VLOOKUP(H11,fixed_expenses[],2,0),"") | J11: =IF(HLOOKUP(J6,Summary!$I$2:$AM$7,5,0)=0,"",HLOOKUP(J6,Summary!$I$2:$AM$7,5,0)) | K11: =IFERROR(VLOOKUP(J11,fixed_expenses[],2,0),"") | L11: =IF(HLOOKUP(L6,Summary!$I$2:$AM$7,5,0)=0,"",HLOOKUP(L6,Summary!$I$2:$AM$7,5,0)) | M11: =IFERROR(VLOOKUP(L11,fixed_expenses[],2,0),"") | N11: =IF(HLOOKUP(N6,Summary!$I$2:$AM$7,5,0)=0,"",HLOOKUP(N6,Summary!$I$2:$AM$7,5,0)) | O11: =IFERROR(VLOOKUP(N11,fixed_expenses[],2,0),"")
B12: =IF(HLOOKUP(B6,Summary!$I$2:$AM$7,6,0)=0,"",HLOOKUP(B6,Summary!$I$2:$AM$7,6,0)) | C12: =IFERROR(VLOOKUP(B12,fixed_expenses[],2,0),"") | D12: =IF(HLOOKUP(D6,Summary!$I$2:$AM$7,6,0)=0,"",HLOOKUP(D6,Summary!$I$2:$AM$7,6,0)) | E12: =IFERROR(VLOOKUP(D12,fixed_expenses[],2,0),"") | F12: =IF(HLOOKUP(F6,Summary!$I$2:$AM$7,6,0)=0,"",HLOOKUP(F6,Summary!$I$2:$AM$7,6,0)) | G12: =IFERROR(VLOOKUP(F12,fixed_expenses[],2,0),"") | H12: =IF(HLOOKUP(H6,Summary!$I$2:$AM$7,6,0)=0,"",HLOOKUP(H6,Summary!$I$2:$AM$7,6,0)) | I12: =IFERROR(VLOOKUP(H12,fixed_expenses[],2,0),"") | J12: =IF(HLOOKUP(J6,Summary!$I$2:$AM$7,6,0)=0,"",HLOOKUP(J6,Summary!$I$2:$AM$7,6,0)) | K12: =IFERROR(VLOOKUP(J12,fixed_expenses[],2,0),"") | L12: =IF(HLOOKUP(L6,Summary!$I$2:$AM$7,6,0)=0,"",HLOOKUP(L6,Summary!$I$2:$AM$7,6,0)) | M12: =IFERROR(VLOOKUP(L12,fixed_expenses[],2,0),"") | N12: =IF(HLOOKUP(N6,Summary!$I$2:$AM$7,6,0)=0,"",HLOOKUP(N6,Summary!$I$2:$AM$7,6,0)) | O12: =IFERROR(VLOOKUP(N12,fixed_expenses[],2,0),"")
A13: Total is auto calculated for each day and week in cell at right, cells C13 through P13. Next instruction is in cell A15. | B13: TOTAL | C13: =SUM(C8:C12) -> 0 | E13: =SUM(E8:E12) -> 0 | G13: =SUM(G8:G12) -> 0 | I13: =SUM(I8:I12) -> 0 | K13: =SUM(K8:K12) -> 0 | M13: =SUM(M8:M12) -> 0 | O13: =SUM(O8:O12) -> 0 | P13: =SUMIF(B6:N6,"<8",C13:O13) -> 0
A15: Calendar dates are in cells at right, cells B15 through O15. | B15: =N6+1 -> 3 | D15: =B15+1 -> 4 | F15: =D15+1 -> 5 | H15: =F15+1 -> 6 | J15: =H15+1 -> 7 | L15: =J15+1 -> 8 | N15: =L15+1 -> 9
A16: Description and Amount labels are in cells at right, cells B16 through O16. | B16: DESCRIPTION | C16: AMOUNT | D16: DESCRIPTION | E16: AMOUNT | F16: DESCRIPTION | G16: AMOUNT | H16: DESCRIPTION | I16: AMOUNT | J16: DESCRIPTION | K16: AMOUNT | L16: DESCRIPTION | M16: AMOUNT | N16: DESCRIPTION | O16: AMOUNT
A17: Enter Description and Amount of each expense in cells at right, cells B17 through O21. Next instruction is in cell A22. | B17: =IF(HLOOKUP(B15,Summary!$I$2:$AM$7,2,0)=0,"",HLOOKUP(B15,Summary!$I$2:$AM$7,2,0)) -> Rent | C17: =IFERROR(VLOOKUP(B17,fixed_expenses[],2,0),"") -> 1200 | D17: =IF(HLOOKUP(D15,Summary!$I$2:$AM$7,2,0)=0,"",HLOOKUP(D15,Summary!$I$2:$AM$7,2,0)) | E17: =IFERROR(VLOOKUP(D17,fixed_expenses[],2,0),"") | F17: =IF(HLOOKUP(F15,Summary!$I$2:$AM$7,2,0)=0,"",HLOOKUP(F15,Summary!$I$2:$AM$7,2,0)) | G17: =IFERROR(VLOOKUP(F17,fixed_expenses[],2,0),"") | H17: =IF(HLOOKUP(H15,Summary!$I$2:$AM$7,2,0)=0,"",HLOOKUP(H15,Summary!$I$2:$AM$7,2,0)) | I17: =IFERROR(VLOOKUP(H17,fixed_expenses[],2,0),"") | J17: =IF(HLOOKUP(J15,Summary!$I$2:$AM$7,2,0)=0,"",HLOOKUP(J15,Summary!$I$2:$AM$7,2,0)) | K17: =IFERROR(VLOOKUP(J17,fixed_expenses[],2,0),"") | L17: =IF(HLOOKUP(L15,Summary!$I$2:$AM$7,2,0)=0,"",HLOOKUP(L15,Summary!$I$2:$AM$7,2,0)) | M17: =IFERROR(VLOOKUP(L17,fixed_expenses[],2,0),"") | N17: =IF(HLOOKUP(N15,Summary!$I$2:$AM$7,2,0)=0,"",HLOOKUP(N15,Summary!$I$2:$AM$7,2,0)) | O17: =IFERROR(VLOOKUP(N17,fixed_expenses[],2,0),"")
B18: =IF(HLOOKUP(B15,Summary!$I$2:$AM$7,3,0)=0,"",HLOOKUP(B15,Summary!$I$2:$AM$7,3,0)) | C18: =IFERROR(VLOOKUP(B18,fixed_expenses[],2,0),"") | D18: =IF(HLOOKUP(D15,Summary!$I$2:$AM$7,3,0)=0,"",HLOOKUP(D15,Summary!$I$2:$AM$7,3,0)) | E18: =IFERROR(VLOOKUP(D18,fixed_expenses[],2,0),"") | F18: =IF(HLOOKUP(F15,Summary!$I$2:$AM$7,3,0)=0,"",HLOOKUP(F15,Summary!$I$2:$AM$7,3,0)) | G18: =IFERROR(VLOOKUP(F18,fixed_expenses[],2,0),"") | H18: =IF(HLOOKUP(H15,Summary!$I$2:$AM$7,3,0)=0,"",HLOOKUP(H15,Summary!$I$2:$AM$7,3,0)) | I18: =IFERROR(VLOOKUP(H18,fixed_expenses[],2,0),"") | J18: =IF(HLOOKUP(J15,Summary!$I$2:$AM$7,3,0)=0,"",HLOOKUP(J15,Summary!$I$2:$AM$7,3,0)) | K18: =IFERROR(VLOOKUP(J18,fixed_expenses[],2,0),"") | L18: =IF(HLOOKUP(L15,Summary!$I$2:$AM$7,3,0)=0,"",HLOOKUP(L15,Summary!$I$2:$AM$7,3,0)) | M18: =IFERROR(VLOOKUP(L18,fixed_expenses[],2,0),"") | N18: =IF(HLOOKUP(N15,Summary!$I$2:$AM$7,3,0)=0,"",HLOOKUP(N15,Summary!$I$2:$AM$7,3,0)) | O18: =IFERROR(VLOOKUP(N18,fixed_expenses[],2,0),"")
B19: =IF(HLOOKUP(B15,Summary!$I$2:$AM$7,4,0)=0,"",HLOOKUP(B15,Summary!$I$2:$AM$7,4,0)) | C19: =IFERROR(VLOOKUP(B19,fixed_expenses[],2,0),"") | D19: =IF(HLOOKUP(D15,Summary!$I$2:$AM$7,4,0)=0,"",HLOOKUP(D15,Summary!$I$2:$AM$7,4,0)) | E19: =IFERROR(VLOOKUP(D19,fixed_expenses[],2,0),"") | F19: =IF(HLOOKUP(F15,Summary!$I$2:$AM$7,4,0)=0,"",HLOOKUP(F15,Summary!$I$2:$AM$7,4,0)) | G19: =IFERROR(VLOOKUP(F19,fixed_expenses[],2,0),"") | H19: =IF(HLOOKUP(H15,Summary!$I$2:$AM$7,4,0)=0,"",HLOOKUP(H15,Summary!$I$2:$AM$7,4,0)) | I19: =IFERROR(VLOOKUP(H19,fixed_expenses[],2,0),"") | J19: =IF(HLOOKUP(J15,Summary!$I$2:$AM$7,4,0)=0,"",HLOOKUP(J15,Summary!$I$2:$AM$7,4,0)) | K19: =IFERROR(VLOOKUP(J19,fixed_expenses[],2,0),"") | L19: =IF(HLOOKUP(L15,Summary!$I$2:$AM$7,4,0)=0,"",HLOOKUP(L15,Summary!$I$2:$AM$7,4,0)) | M19: =IFERROR(VLOOKUP(L19,fixed_expenses[],2,0),"") | N19: =IF(HLOOKUP(N15,Summary!$I$2:$AM$7,4,0)=0,"",HLOOKUP(N15,Summary!$I$2:$AM$7,4,0)) | O19: =IFERROR(VLOOKUP(N19,fixed_expenses[],2,0),"")
B20: =IF(HLOOKUP(B15,Summary!$I$2:$AM$7,5,0)=0,"",HLOOKUP(B15,Summary!$I$2:$AM$7,5,0)) | C20: =IFERROR(VLOOKUP(B20,fixed_expenses[],2,0),"") | D20: =IF(HLOOKUP(D15,Summary!$I$2:$AM$7,5,0)=0,"",HLOOKUP(D15,Summary!$I$2:$AM$7,5,0)) | E20: =IFERROR(VLOOKUP(D20,fixed_expenses[],2,0),"") | F20: =IF(HLOOKUP(F15,Summary!$I$2:$AM$7,5,0)=0,"",HLOOKUP(F15,Summary!$I$2:$AM$7,5,0)) | G20: =IFERROR(VLOOKUP(F20,fixed_expenses[],2,0),"") | H20: =IF(HLOOKUP(H15,Summary!$I$2:$AM$7,5,0)=0,"",HLOOKUP(H15,Summary!$I$2:$AM$7,5,0)) | I20: =IFERROR(VLOOKUP(H20,fixed_expenses[],2,0),"") | J20: =IF(HLOOKUP(J15,Summary!$I$2:$AM$7,5,0)=0,"",HLOOKUP(J15,Summary!$I$2:$AM$7,5,0)) | K20: =IFERROR(VLOOKUP(J20,fixed_expenses[],2,0),"") | L20: =IF(HLOOKUP(L15,Summary!$I$2:$AM$7,5,0)=0,"",HLOOKUP(L15,Summary!$I$2:$AM$7,5,0)) | M20: =IFERROR(VLOOKUP(L20,fixed_expenses[],2,0),"") | N20: =IF(HLOOKUP(N15,Summary!$I$2:$AM$7,5,0)=0,"",HLOOKUP(N15,Summary!$I$2:$AM$7,5,0)) | O20: =IFERROR(VLOOKUP(N20,fixed_expenses[],2,0),"")
B21: =IF(HLOOKUP(B15,Summary!$I$2:$AM$7,6,0)=0,"",HLOOKUP(B15,Summary!$I$2:$AM$7,6,0)) | C21: =IFERROR(VLOOKUP(B21,fixed_expenses[],2,0),"") | D21: =IF(HLOOKUP(D15,Summary!$I$2:$AM$7,6,0)=0,"",HLOOKUP(D15,Summary!$I$2:$AM$7,6,0)) | E21: =IFERROR(VLOOKUP(D21,fixed_expenses[],2,0),"") | F21: =IF(HLOOKUP(F15,Summary!$I$2:$AM$7,6,0)=0,"",HLOOKUP(F15,Summary!$I$2:$AM$7,6,0)) | G21: =IFERROR(VLOOKUP(F21,fixed_expenses[],2,0),"") | H21: =IF(HLOOKUP(H15,Summary!$I$2:$AM$7,6,0)=0,"",HLOOKUP(H15,Summary!$I$2:$AM$7,6,0)) | I21: =IFERROR(VLOOKUP(H21,fixed_expenses[],2,0),"") | J21: =IF(HLOOKUP(J15,Summary!$I$2:$AM$7,6,0)=0,"",HLOOKUP(J15,Summary!$I$2:$AM$7,6,0)) | K21: =IFERROR(VLOOKUP(J21,fixed_expenses[],2,0),"") | L21: =IF(HLOOKUP(L15,Summary!$I$2:$AM$7,6,0)=0,"",HLOOKUP(L15,Summary!$I$2:$AM$7,6,0)) | M21: =IFERROR(VLOOKUP(L21,fixed_expenses[],2,0),"") | N21: =IF(HLOOKUP(N15,Summary!$I$2:$AM$7,6,0)=0,"",HLOOKUP(N15,Summary!$I$2:$AM$7,6,0)) | O21: =IFERROR(VLOOKUP(N21,fixed_expenses[],2,0),"")
A22: Total is auto calculated for each day and week in cell at right, cells C22 through P22. Next instruction is in cell A24. | B22: TOTAL | C22: =SUM(C17:C21) -> 1200 | E22: =SUM(E17:E21) -> 0 | G22: =SUM(G17:G21) -> 0 | I22: =SUM(I17:I21) -> 0 | K22: =SUM(K17:K21) -> 0 | M22: =SUM(M17:M21) -> 0 | O22: =SUM(O17:O21) -> 0 | P22: =SUM(C22,E22,G22,I22,K22,M22,O22) -> 1200
A24: Calendar dates are in cells at right, cells B24 through O24. | B24: =N15+1 -> 10 | D24: =B24+1 -> 11 | F24: =D24+1 -> 12 | H24: =F24+1 -> 13 | J24: =H24+1 -> 14 | L24: =J24+1 -> 15 | N24: =L24+1 -> 16
A25: Description and Amount labels are in cells at right, cells B25 through O25. | B25: DESCRIPTION | C25: AMOUNT | D25: DESCRIPTION | E25: AMOUNT | F25: DESCRIPTION | G25: AMOUNT | H25: DESCRIPTION | I25: AMOUNT | J25: DESCRIPTION | K25: AMOUNT | L25: DESCRIPTION | M25: AMOUNT | N25: DESCRIPTION | O25: AMOUNT
A26: Enter Description and Amount of each expense in cells at right, cells B26 through O30. Next instruction is in cell A31. | B26: =IF(HLOOKUP(B24,Summary!$I$2:$AM$7,2,0)=0,"",HLOOKUP(B24,Summary!$I$2:$AM$7,2,0)) | C26: =IFERROR(VLOOKUP(B26,fixed_expenses[],2,0),"") | D26: =IF(HLOOKUP(D24,Summary!$I$2:$AM$7,2,0)=0,"",HLOOKUP(D24,Summary!$I$2:$AM$7,2,0)) | E26: =IFERROR(VLOOKUP(D26,fixed_expenses[],2,0),"") | F26: =IF(HLOOKUP(F24,Summary!$I$2:$AM$7,2,0)=0,"",HLOOKUP(F24,Summary!$I$2:$AM$7,2,0)) | G26: =IFERROR(VLOOKUP(F26,fixed_expenses[],2,0),"") | H26: =IF(HLOOKUP(H24,Summary!$I$2:$AM$7,2,0)=0,"",HLOOKUP(H24,Summary!$I$2:$AM$7,2,0)) | I26: =IFERROR(VLOOKUP(H26,fixed_expenses[],2,0),"") | J26: =IF(HLOOKUP(J24,Summary!$I$2:$AM$7,2,0)=0,"",HLOOKUP(J24,Summary!$I$2:$AM$7,2,0)) | K26: =IFERROR(VLOOKUP(J26,fixed_expenses[],2,0),"") | L26: =IF(HLOOKUP(L24,Summary!$I$2:$AM$7,2,0)=0,"",HLOOKUP(L24,Summary!$I$2:$AM$7,2,0)) -> Paul Phone Bill | M26: =IFERROR(VLOOKUP(L26,fixed_expenses[],2,0),"") -> 60 | N26: =IF(HLOOKUP(N24,Summary!$I$2:$AM$7,2,0)=0,"",HLOOKUP(N24,Summary!$I$2:$AM$7,2,0)) | O26: =IFERROR(VLOOKUP(N26,fixed_expenses[],2,0),"")
B27: =IF(HLOOKUP(B24,Summary!$I$2:$AM$7,3,0)=0,"",HLOOKUP(B24,Summary!$I$2:$AM$7,3,0)) | C27: =IFERROR(VLOOKUP(B27,fixed_expenses[],2,0),"") | D27: =IF(HLOOKUP(D24,Summary!$I$2:$AM$7,3,0)=0,"",HLOOKUP(D24,Summary!$I$2:$AM$7,3,0)) | E27: =IFERROR(VLOOKUP(D27,fixed_expenses[],2,0),"") | F27: =IF(HLOOKUP(F24,Summary!$I$2:$AM$7,3,0)=0,"",HLOOKUP(F24,Summary!$I$2:$AM$7,3,0)) | G27: =IFERROR(VLOOKUP(F27,fixed_expenses[],2,0),"") | H27: =IF(HLOOKUP(H24,Summary!$I$2:$AM$7,3,0)=0,"",HLOOKUP(H24,Summary!$I$2:$AM$7,3,0)) | I27: =IFERROR(VLOOKUP(H27,fixed_expenses[],2,0),"") | J27: =IF(HLOOKUP(J24,Summary!$I$2:$AM$7,3,0)=0,"",HLOOKUP(J24,Summary!$I$2:$AM$7,3,0)) | K27: =IFERROR(VLOOKUP(J27,fixed_expenses[],2,0),"") | L27: =IF(HLOOKUP(L24,Summary!$I$2:$AM$7,3,0)=0,"",HLOOKUP(L24,Summary!$I$2:$AM$7,3,0)) -> Electric | M27: =IFERROR(VLOOKUP(L27,fixed_expenses[],2,0),"") -> 50 | N27: =IF(HLOOKUP(N24,Summary!$I$2:$AM$7,3,0)=0,"",HLOOKUP(N24,Summary!$I$2:$AM$7,3,0)) | O27: =IFERROR(VLOOKUP(N27,fixed_expenses[],2,0),"")
B28: =IF(HLOOKUP(B24,Summary!$I$2:$AM$7,4,0)=0,"",HLOOKUP(B24,Summary!$I$2:$AM$7,4,0)) | C28: =IFERROR(VLOOKUP(B28,fixed_expenses[],2,0),"") | D28: =IF(HLOOKUP(D24,Summary!$I$2:$AM$7,4,0)=0,"",HLOOKUP(D24,Summary!$I$2:$AM$7,4,0)) | E28: =IFERROR(VLOOKUP(D28,fixed_expenses[],2,0),"") | F28: =IF(HLOOKUP(F24,Summary!$I$2:$AM$7,4,0)=0,"",HLOOKUP(F24,Summary!$I$2:$AM$7,4,0)) | G28: =IFERROR(VLOOKUP(F28,fixed_expenses[],2,0),"") | H28: =IF(HLOOKUP(H24,Summary!$I$2:$AM$7,4,0)=0,"",HLOOKUP(H24,Summary!$I$2:$AM$7,4,0)) | I28: =IFERROR(VLOOKUP(H28,fixed_expenses[],2,0),"") | J28: =IF(HLOOKUP(J24,Summary!$I$2:$AM$7,4,0)=0,"",HLOOKUP(J24,Summary!$I$2:$AM$7,4,0)) | K28: =IFERROR(VLOOKUP(J28,fixed_expenses[],2,0),"") | L28: =IF(HLOOKUP(L24,Summary!$I$2:$AM$7,4,0)=0,"",HLOOKUP(L24,Summary!$I$2:$AM$7,4,0)) | M28: =IFERROR(VLOOKUP(L28,fixed_expenses[],2,0),"") | N28: =IF(HLOOKUP(N24,Summary!$I$2:$AM$7,4,0)=0,"",HLOOKUP(N24,Summary!$I$2:$AM$7,4,0)) | O28: =IFERROR(VLOOKUP(N28,fixed_expenses[],2,0),"")
B29: =IF(HLOOKUP(B24,Summary!$I$2:$AM$7,5,0)=0,"",HLOOKUP(B24,Summary!$I$2:$AM$7,5,0)) | C29: =IFERROR(VLOOKUP(B29,fixed_expenses[],2,0),"") | D29: =IF(HLOOKUP(D24,Summary!$I$2:$AM$7,5,0)=0,"",HLOOKUP(D24,Summary!$I$2:$AM$7,5,0)) | E29: =IFERROR(VLOOKUP(D29,fixed_expenses[],2,0),"") | F29: =IF(HLOOKUP(F24,Summary!$I$2:$AM$7,5,0)=0,"",HLOOKUP(F24,Summary!$I$2:$AM$7,5,0)) | G29: =IFERROR(VLOOKUP(F29,fixed_expenses[],2,0),"") | H29: =IF(HLOOKUP(H24,Summary!$I$2:$AM$7,5,0)=0,"",HLOOKUP(H24,Summary!$I$2:$AM$7,5,0)) | I29: =IFERROR(VLOOKUP(H29,fixed_expenses[],2,0),"") | J29: =IF(HLOOKUP(J24,Summary!$I$2:$AM$7,5,0)=0,"",HLOOKUP(J24,Summary!$I$2:$AM$7,5,0)) | K29: =IFERROR(VLOOKUP(J29,fixed_expenses[],2,0),"") | L29: =IF(HLOOKUP(L24,Summary!$I$2:$AM$7,5,0)=0,"",HLOOKUP(L24,Summary!$I$2:$AM$7,5,0)) | M29: =IFERROR(VLOOKUP(L29,fixed_expenses[],2,0),"") | N29: =IF(HLOOKUP(N24,Summary!$I$2:$AM$7,5,0)=0,"",HLOOKUP(N24,Summary!$I$2:$AM$7,5,0)) | O29: =IFERROR(VLOOKUP(N29,fixed_expenses[],2,0),"")
B30: =IF(HLOOKUP(B24,Summary!$I$2:$AM$7,6,0)=0,"",HLOOKUP(B24,Summary!$I$2:$AM$7,6,0)) | C30: =IFERROR(VLOOKUP(B30,fixed_expenses[],2,0),"") | D30: =IF(HLOOKUP(D24,Summary!$I$2:$AM$7,6,0)=0,"",HLOOKUP(D24,Summary!$I$2:$AM$7,6,0)) | E30: =IFERROR(VLOOKUP(D30,fixed_expenses[],2,0),"") | F30: =IF(HLOOKUP(F24,Summary!$I$2:$AM$7,6,0)=0,"",HLOOKUP(F24,Summary!$I$2:$AM$7,6,0)) | G30: =IFERROR(VLOOKUP(F30,fixed_expenses[],2,0),"") | H30: =IF(HLOOKUP(H24,Summary!$I$2:$AM$7,6,0)=0,"",HLOOKUP(H24,Summary!$I$2:$AM$7,6,0)) | I30: =IFERROR(VLOOKUP(H30,fixed_expenses[],2,0),"") | J30: =IF(HLOOKUP(J24,Summary!$I$2:$AM$7,6,0)=0,"",HLOOKUP(J24,Summary!$I$2:$AM$7,6,0)) | K30: =IFERROR(VLOOKUP(J30,fixed_expenses[],2,0),"") | L30: =IF(HLOOKUP(L24,Summary!$I$2:$AM$7,6,0)=0,"",HLOOKUP(L24,Summary!$I$2:$AM$7,6,0)) | M30: =IFERROR(VLOOKUP(L30,fixed_expenses[],2,0),"") | N30: =IF(HLOOKUP(N24,Summary!$I$2:$AM$7,6,0)=0,"",HLOOKUP(N24,Summary!$I$2:$AM$7,6,0)) | O30: =IFERROR(VLOOKUP(N30,fixed_expenses[],2,0),"")
A31: Total is auto calculated for each day and week in cell at right, cells C31 through P31. Next instruction is in cell A33. | B31: TOTAL | C31: =SUM(C26:C30) -> 0 | E31: =SUM(E26:E30) -> 0 | G31: =SUM(G26:G30) -> 0 | I31: =SUM(I26:I30) -> 0 | K31: =SUM(K26:K30) -> 0 | M31: =SUM(M26:M30) -> 110 | O31: =SUM(O26:O30) -> 0 | P31: =SUM(C31,E31,G31,I31,K31,M31,O31) -> 110
A33: Calendar dates are in cells at right, cells B33 through O33. | B33: =N24+1 -> 17 | D33: =B33+1 -> 18 | F33: =D33+1 -> 19 | H33: =F33+1 -> 20 | J33: =H33+1 -> 21 | L33: =J33+1 -> 22 | N33: =L33+1 -> 23
A34: Description and Amount labels are in cells at right, cells B34 through O34. | B34: DESCRIPTION | C34: AMOUNT | D34: DESCRIPTION | E34: AMOUNT | F34: DESCRIPTION | G34: AMOUNT | H34: DESCRIPTION | I34: AMOUNT | J34: DESCRIPTION | K34: AMOUNT | L34: DESCRIPTION | M34: AMOUNT | N34: DESCRIPTION | O34: AMOUNT
A35: Enter Description and Amount of each expense in cells at right, cells B35 through O39. Next instruction is in cell A40. | B35: =IF(HLOOKUP(B33,Summary!$I$2:$AM$7,2,0)=0,"",HLOOKUP(B33,Summary!$I$2:$AM$7,2,0)) | C35: =IFERROR(VLOOKUP(B35,fixed_expenses[],2,0),"") | D35: =IF(HLOOKUP(D33,Summary!$I$2:$AM$7,2,0)=0,"",HLOOKUP(D33,Summary!$I$2:$AM$7,2,0)) | E35: =IFERROR(VLOOKUP(D35,fixed_expenses[],2,0),"") | F35: =IF(HLOOKUP(F33,Summary!$I$2:$AM$7,2,0)=0,"",HLOOKUP(F33,Summary!$I$2:$AM$7,2,0)) | G35: =IFERROR(VLOOKUP(F35,fixed_expenses[],2,0),"") | H35: =IF(HLOOKUP(H33,Summary!$I$2:$AM$7,2,0)=0,"",HLOOKUP(H33,Summary!$I$2:$AM$7,2,0)) -> Lynn Phone Bill | I35: =IFERROR(VLOOKUP(H35,fixed_expenses[],2,0),"") | J35: =IF(HLOOKUP(J33,Summary!$I$2:$AM$7,2,0)=0,"",HLOOKUP(J33,Summary!$I$2:$AM$7,2,0)) | K35: =IFERROR(VLOOKUP(J35,fixed_expenses[],2,0),"") | L35: =IF(HLOOKUP(L33,Summary!$I$2:$AM$7,2,0)=0,"",HLOOKUP(L33,Summary!$I$2:$AM$7,2,0)) | M35: =IFERROR(VLOOKUP(L35,fixed_expenses[],2,0),"") | N35: =IF(HLOOKUP(N33,Summary!$I$2:$AM$7,2,0)=0,"",HLOOKUP(N33,Summary!$I$2:$AM$7,2,0)) | O35: =IFERROR(VLOOKUP(N35,fixed_expenses[],2,0),"")
B36: =IF(HLOOKUP(B33,Summary!$I$2:$AM$7,3,0)=0,"",HLOOKUP(B33,Summary!$I$2:$AM$7,3,0)) | C36: =IFERROR(VLOOKUP(B36,fixed_expenses[],2,0),"") | D36: =IF(HLOOKUP(D33,Summary!$I$2:$AM$7,3,0)=0,"",HLOOKUP(D33,Summary!$I$2:$AM$7,3,0)) | E36: =IFERROR(VLOOKUP(D36,fixed_expenses[],2,0),"") | F36: =IF(HLOOKUP(F33,Summary!$I$2:$AM$7,3,0)=0,"",HLOOKUP(F33,Summary!$I$2:$AM$7,3,0)) | G36: =IFERROR(VLOOKUP(F36,fixed_expenses[],2,0),"") | H36: =IF(HLOOKUP(H33,Summary!$I$2:$AM$7,3,0)=0,"",HLOOKUP(H33,Summary!$I$2:$AM$7,3,0)) | I36: =IFERROR(VLOOKUP(H36,fixed_expenses[],2,0),"") | J36: =IF(HLOOKUP(J33,Summary!$I$2:$AM$7,3,0)=0,"",HLOOKUP(J33,Summary!$I$2:$AM$7,3,0)) | K36: =IFERROR(VLOOKUP(J36,fixed_expenses[],2,0),"") | L36: =IF(HLOOKUP(L33,Summary!$I$2:$AM$7,3,0)=0,"",HLOOKUP(L33,Summary!$I$2:$AM$7,3,0)) | M36: =IFERROR(VLOOKUP(L36,fixed_expenses[],2,0),"") | N36: =IF(HLOOKUP(N33,Summary!$I$2:$AM$7,3,0)=0,"",HLOOKUP(N33,Summary!$I$2:$AM$7,3,0)) | O36: =IFERROR(VLOOKUP(N36,fixed_expenses[],2,0),"")
B37: =IF(HLOOKUP(B33,Summary!$I$2:$AM$7,4,0)=0,"",HLOOKUP(B33,Summary!$I$2:$AM$7,4,0)) | C37: =IFERROR(VLOOKUP(B37,fixed_expenses[],2,0),"") | D37: =IF(HLOOKUP(D33,Summary!$I$2:$AM$7,4,0)=0,"",HLOOKUP(D33,Summary!$I$2:$AM$7,4,0)) | E37: =IFERROR(VLOOKUP(D37,fixed_expenses[],2,0),"") | F37: =IF(HLOOKUP(F33,Summary!$I$2:$AM$7,4,0)=0,"",HLOOKUP(F33,Summary!$I$2:$AM$7,4,0)) | G37: =IFERROR(VLOOKUP(F37,fixed_expenses[],2,0),"") | H37: =IF(HLOOKUP(H33,Summary!$I$2:$AM$7,4,0)=0,"",HLOOKUP(H33,Summary!$I$2:$AM$7,4,0)) | I37: =IFERROR(VLOOKUP(H37,fixed_expenses[],2,0),"") | J37: =IF(HLOOKUP(J33,Summary!$I$2:$AM$7,4,0)=0,"",HLOOKUP(J33,Summary!$I$2:$AM$7,4,0)) | K37: =IFERROR(VLOOKUP(J37,fixed_expenses[],2,0),"") | L37: =IF(HLOOKUP(L33,Summary!$I$2:$AM$7,4,0)=0,"",HLOOKUP(L33,Summary!$I$2:$AM$7,4,0)) | M37: =IFERROR(VLOOKUP(L37,fixed_expenses[],2,0),"") | N37: =IF(HLOOKUP(N33,Summary!$I$2:$AM$7,4,0)=0,"",HLOOKUP(N33,Summary!$I$2:$AM$7,4,0)) | O37: =IFERROR(VLOOKUP(N37,fixed_expenses[],2,0),"")
B38: =IF(HLOOKUP(B33,Summary!$I$2:$AM$7,5,0)=0,"",HLOOKUP(B33,Summary!$I$2:$AM$7,5,0)) | C38: =IFERROR(VLOOKUP(B38,fixed_expenses[],2,0),"") | D38: =IF(HLOOKUP(D33,Summary!$I$2:$AM$7,5,0)=0,"",HLOOKUP(D33,Summary!$I$2:$AM$7,5,0)) | E38: =IFERROR(VLOOKUP(D38,fixed_expenses[],2,0),"") | F38: =IF(HLOOKUP(F33,Summary!$I$2:$AM$7,5,0)=0,"",HLOOKUP(F33,Summary!$I$2:$AM$7,5,0)) | G38: =IFERROR(VLOOKUP(F38,fixed_expenses[],2,0),"") | H38: =IF(HLOOKUP(H33,Summary!$I$2:$AM$7,5,0)=0,"",HLOOKUP(H33,Summary!$I$2:$AM$7,5,0)) | I38: =IFERROR(VLOOKUP(H38,fixed_expenses[],2,0),"") | J38: =IF(HLOOKUP(J33,Summary!$I$2:$AM$7,5,0)=0,"",HLOOKUP(J33,Summary!$I$2:$AM$7,5,0)) | K38: =IFERROR(VLOOKUP(J38,fixed_expenses[],2,0),"") | L38: =IF(HLOOKUP(L33,Summary!$I$2:$AM$7,5,0)=0,"",HLOOKUP(L33,Summary!$I$2:$AM$7,5,0)) | M38: =IFERROR(VLOOKUP(L38,fixed_expenses[],2,0),"") | N38: =IF(HLOOKUP(N33,Summary!$I$2:$AM$7,5,0)=0,"",HLOOKUP(N33,Summary!$I$2:$AM$7,5,0)) | O38: =IFERROR(VLOOKUP(N38,fixed_expenses[],2,0),"")
B39: =IF(HLOOKUP(B33,Summary!$I$2:$AM$7,6,0)=0,"",HLOOKUP(B33,Summary!$I$2:$AM$7,6,0)) | C39: =IFERROR(VLOOKUP(B39,fixed_expenses[],2,0),"") | D39: =IF(HLOOKUP(D33,Summary!$I$2:$AM$7,6,0)=0,"",HLOOKUP(D33,Summary!$I$2:$AM$7,6,0)) | E39: =IFERROR(VLOOKUP(D39,fixed_expenses[],2,0),"") | F39: =IF(HLOOKUP(F33,Summary!$I$2:$AM$7,6,0)=0,"",HLOOKUP(F33,Summary!$I$2:$AM$7,6,0)) | G39: =IFERROR(VLOOKUP(F39,fixed_expenses[],2,0),"") | H39: =IF(HLOOKUP(H33,Summary!$I$2:$AM$7,6,0)=0,"",HLOOKUP(H33,Summary!$I$2:$AM$7,6,0)) | I39: =IFERROR(VLOOKUP(H39,fixed_expenses[],2,0),"") | J39: =IF(HLOOKUP(J33,Summary!$I$2:$AM$7,6,0)=0,"",HLOOKUP(J33,Summary!$I$2:$AM$7,6,0)) | K39: =IFERROR(VLOOKUP(J39,fixed_expenses[],2,0),"") | L39: =IF(HLOOKUP(L33,Summary!$I$2:$AM$7,6,0)=0,"",HLOOKUP(L33,Summary!$I$2:$AM$7,6,0)) | M39: =IFERROR(VLOOKUP(L39,fixed_expenses[],2,0),"") | N39: =IF(HLOOKUP(N33,Summary!$I$2:$AM$7,6,0)=0,"",HLOOKUP(N33,Summary!$I$2:$AM$7,6,0)) | O39: =IFERROR(VLOOKUP(N39,fixed_expenses[],2,0),"")
A40: Total is auto calculated for each day and week in cell at right, cells C40 through P40. Next instruction is in cell A42. | B40: TOTAL | C40: =SUM(C35:C39) -> 0 | E40: =SUM(E35:E39) -> 0 | G40: =SUM(G35:G39) -> 0 | I40: =SUM(I35:I39) -> 0 | K40: =SUM(K35:K39) -> 0 | M40: =SUM(M35:M39) -> 0 | O40: =SUM(O35:O39) -> 0 | P40: =SUM(C40,E40,G40,I40,K40,M40,O40) -> 0
A42: Calendar dates are in cells at right, cells B42 through O42. | B42: =DAY(IF(DAY(JanSun1)=1,JanSun1+22,JanSun1+29)) -> 24 | D42: =DAY(IF(DAY(JanSun1)=1,JanSun1+23,JanSun1+30)) -> 25 | F42: =DAY(IF(DAY(JanSun1)=1,JanSun1+24,JanSun1+31)) -> 26 | H42: =DAY(IF(DAY(JanSun1)=1,JanSun1+25,JanSun1+32)) -> 27 | J42: =DAY(IF(DAY(JanSun1)=1,JanSun1+26,JanSun1+33)) -> 28 | L42: =DAY(IF(DAY(JanSun1)=1,JanSun1+27,JanSun1+34)) -> 29 | N42: =DAY(IF(DAY(JanSun1)=1,JanSun1+28,JanSun1+35)) -> 30
A43: Description and Amount labels are in cells at right, cells B43 through O43. | B43: DESCRIPTION | C43: AMOUNT | D43: DESCRIPTION | E43: AMOUNT | F43: DESCRIPTION | G43: AMOUNT | H43: DESCRIPTION | I43: AMOUNT | J43: DESCRIPTION | K43: AMOUNT | L43: DESCRIPTION | M43: AMOUNT | N43: DESCRIPTION | O43: AMOUNT
A44: Enter Description and Amount of each expense in cells at right, cells B44 through O48. Next instruction is in cell A49. | B44: =IF(HLOOKUP(B42,Summary!$I$2:$AM$7,2,0)=0,"",HLOOKUP(B42,Summary!$I$2:$AM$7,2,0)) | C44: =IFERROR(VLOOKUP(B44,fixed_expenses[],2,0),"") | D44: =IF(HLOOKUP(D42,Summary!$I$2:$AM$7,2,0)=0,"",HLOOKUP(D42,Summary!$I$2:$AM$7,2,0)) | E44: =IFERROR(VLOOKUP(D44,fixed_expenses[],2,0),"") | F44: =IF(HLOOKUP(F42,Summary!$I$2:$AM$7,2,0)=0,"",HLOOKUP(F42,Summary!$I$2:$AM$7,2,0)) | G44: =IFERROR(VLOOKUP(F44,fixed_expenses[],2,0),"") | H44: =IF(HLOOKUP(H42,Summary!$I$2:$AM$7,2,0)=0,"",HLOOKUP(H42,Summary!$I$2:$AM$7,2,0)) | I44: =IFERROR(VLOOKUP(H44,fixed_expenses[],2,0),"") | J44: =IF(HLOOKUP(J42,Summary!$I$2:$AM$7,2,0)=0,"",HLOOKUP(J42,Summary!$I$2:$AM$7,2,0)) | K44: =IFERROR(VLOOKUP(J44,fixed_expenses[],2,0),"") | L44: =IF(HLOOKUP(L42,Summary!$I$2:$AM$7,2,0)=0,"",HLOOKUP(L42,Summary!$I$2:$AM$7,2,0)) | M44: =IFERROR(VLOOKUP(L44,fixed_expenses[],2,0),"") | N44: =IF(HLOOKUP(N42,Summary!$I$2:$AM$7,2,0)=0,"",HLOOKUP(N42,Summary!$I$2:$AM$7,2,0)) | O44: =IFERROR(VLOOKUP(N44,fixed_expenses[],2,0),"")
...

Sheet Income Calendar
B1: =YEAR(TODAY()) -> 2021 | C1: EXPENSE CALENDAR
A2: January label is in cell at right, Monthly Total label in cell L2, Grand Total label in N2, and Tip in G2. | B2: JANUARY | G2: TIP: Change the year in cell B1 to update the calendar year. | L2: MONTHLY TOTAL | N2: GRAND TOTAL
A3: Monthly Total is auto calculated in cell L3 and Grand Total in N3. | F3: =IFERROR(WEEKDAY(DATEVALUE(B2&" 1, "&Year1)),"") -> 6 | L3: =SUM(P13,P22,P31,P40,P49,P58) -> 4770 | N3: =SUM(P:P) -> 62420
A4: January calendar is in cells B5 through O58. | B4: 1 | D4: 2 | F4: 3 | H4: 4 | J4: 5 | L4: 6 | N4: 7
A5: Weekdays are in cells at right, cells B5 through N5, and Weekly Total label in cell P5. | B5: SUNDAY | D5: MONDAY | E5: =IF(WEEKDAY(DATEVALUE(Month1&" 1, "&Year1))=COLUMN(#REF!),1,IF(LEN(C5)>0,C5+1,"")) -> #VALUE! | F5: TUESDAY | G5: =IF(WEEKDAY(DATEVALUE(Month1&" 1, "&Year1))=COLUMN(#REF!),1,IF(LEN(E5)>0,E5+1,"")) -> #VALUE! | H5: WEDNESDAY | I5: =IF(WEEKDAY(DATEVALUE(Month1&" 1, "&Year1))=COLUMN(#REF!),1,IF(LEN(G5)>0,G5+1,"")) -> #VALUE! | J5: THURSDAY | K5: =IF(WEEKDAY(DATEVALUE(Month1&" 1, "&Year1))=COLUMN(#REF!),1,IF(LEN(I5)>0,I5+1,"")) -> #VALUE! | L5: FRIDAY | M5: =IF(WEEKDAY(DATEVALUE(Month1&" 1, "&Year1))=COLUMN(#REF!),1,IF(LEN(K5)>0,K5+1,"")) -> #VALUE! | N5: SATURDAY | O5: =IF(WEEKDAY(DATEVALUE(Month1&" 1, "&Year1))=COLUMN(#REF!),1,IF(LEN(M5)>0,M5+1,"")) -> #VALUE! | P5: WEEKLY TOTAL | T5: Description | U5: Amount
A6: Calendar dates are in cells at right, cells B6 through O6. If it doesn’t start with number 1, then it is date of previous month. | B6: =DAY(IF(DAY(JanSun1)=1,JanSun1-6,JanSun1+1)) -> 27 | D6: =DAY(IF(DAY(JanSun1)=1,JanSun1-5,JanSun1+2)) -> 28 | F6: =DAY(IF(DAY(JanSun1)=1,JanSun1-4,JanSun1+3)) -> 29 | H6: =DAY(IF(DAY(JanSun1)=1,JanSun1-3,JanSun1+4)) -> 30 | J6: =DAY(IF(DAY(JanSun1)=1,JanSun1-2,JanSun1+5)) -> 31 | L6: =DAY(IF(DAY(JanSun1)=1,JanSun1-1,JanSun1+6)) -> 1 | N6: =DAY(IF(DAY(JanSun1)=1,JanSun1,JanSun1+7)) -> 2 | T6: Paul Income | U6: 800
A7: Description and Amount labels are in cells at right, cells B7 through O7. | B7: DESCRIPTION | C7: AMOUNT | D7: DESCRIPTION | E7: AMOUNT | F7: DESCRIPTION | G7: AMOUNT | H7: DESCRIPTION | I7: AMOUNT | J7: DESCRIPTION | K7: AMOUNT | L7: DESCRIPTION | M7: AMOUNT | N7: DESCRIPTION | O7: AMOUNT | T7: Lynn Income | U7: 770
A8: Enter Description and Amount of each expense in cells at right, cells B8 through O12. Next instruction is in cell A13. | C8: =IFERROR(VLOOKUP(B8,fixed_expenses4[],2,0),"") | E8: =IFERROR(VLOOKUP(D8,fixed_expenses4[],2,0),"") | G8: =IFERROR(VLOOKUP(F8,fixed_expenses4[],2,0),"") | I8: =IFERROR(VLOOKUP(H8,fixed_expenses4[],2,0),"") | K8: =IFERROR(VLOOKUP(J8,fixed_expenses4[],2,0),"") | L8: Paul Income | M8: =IFERROR(VLOOKUP(L8,fixed_expenses4[],2,0),"") -> 800 | O8: =IFERROR(VLOOKUP(N8,fixed_expenses4[],2,0),"")
C9: =IFERROR(VLOOKUP(B9,fixed_expenses4[],2,0),"") | E9: =IFERROR(VLOOKUP(D9,fixed_expenses4[],2,0),"") | G9: =IFERROR(VLOOKUP(F9,fixed_expenses4[],2,0),"") | I9: =IFERROR(VLOOKUP(H9,fixed_expenses4[],2,0),"") | K9: =IFERROR(VLOOKUP(J9,fixed_expenses4[],2,0),"") | M9: =IFERROR(VLOOKUP(L9,fixed_expenses4[],2,0),"") | O9: =IFERROR(VLOOKUP(N9,fixed_expenses4[],2,0),"")
C10: =IFERROR(VLOOKUP(B10,fixed_expenses4[],2,0),"") | E10: =IFERROR(VLOOKUP(D10,fixed_expenses4[],2,0),"") | G10: =IFERROR(VLOOKUP(F10,fixed_expenses4[],2,0),"") | I10: =IFERROR(VLOOKUP(H10,fixed_expenses4[],2,0),"") | K10: =IFERROR(VLOOKUP(J10,fixed_expenses4[],2,0),"") | M10: =IFERROR(VLOOKUP(L10,fixed_expenses4[],2,0),"") | O10: =IFERROR(VLOOKUP(N10,fixed_expenses4[],2,0),"")
C11: =IFERROR(VLOOKUP(B11,fixed_expenses4[],2,0),"") | E11: =IFERROR(VLOOKUP(D11,fixed_expenses4[],2,0),"") | G11: =IFERROR(VLOOKUP(F11,fixed_expenses4[],2,0),"") | I11: =IFERROR(VLOOKUP(H11,fixed_expenses4[],2,0),"") | K11: =IFERROR(VLOOKUP(J11,fixed_expenses4[],2,0),"") | M11: =IFERROR(VLOOKUP(L11,fixed_expenses4[],2,0),"") | O11: =IFERROR(VLOOKUP(N11,fixed_expenses4[],2,0),"")
C12: =IFERROR(VLOOKUP(B12,fixed_expenses4[],2,0),"") | E12: =IFERROR(VLOOKUP(D12,fixed_expenses4[],2,0),"") | G12: =IFERROR(VLOOKUP(F12,fixed_expenses4[],2,0),"") | I12: =IFERROR(VLOOKUP(H12,fixed_expenses4[],2,0),"") | K12: =IFERROR(VLOOKUP(J12,fixed_expenses4[],2,0),"") | M12: =IFERROR(VLOOKUP(L12,fixed_expenses4[],2,0),"") | O12: =IFERROR(VLOOKUP(N12,fixed_expenses4[],2,0),"")
A13: Total is auto calculated for each day and week in cell at right, cells C13 through P13. Next instruction is in cell A15. | B13: TOTAL | C13: =SUM(C8:C12) -> 0 | E13: =SUM(E8:E12) -> 0 | G13: =SUM(G8:G12) -> 0 | I13: =SUM(I8:I12) -> 0 | K13: =SUM(K8:K12) -> 0 | M13: =SUM(M8:M12) -> 800 | O13: =SUM(O8:O12) -> 0 | P13: =SUMIF(B6:N6,"<8",C13:O13) -> 800
A15: Calendar dates are in cells at right, cells B15 through O15. | B15: =N6+1 -> 3 | D15: =B15+1 -> 4 | F15: =D15+1 -> 5 | H15: =F15+1 -> 6 | J15: =H15+1 -> 7 | L15: =J15+1 -> 8 | N15: =L15+1 -> 9
A16: Description and Amount labels are in cells at right, cells B16 through O16. | B16: DESCRIPTION | C16: AMOUNT | D16: DESCRIPTION | E16: AMOUNT | F16: DESCRIPTION | G16: AMOUNT | H16: DESCRIPTION | I16: AMOUNT | J16: DESCRIPTION | K16: AMOUNT | L16: DESCRIPTION | M16: AMOUNT | N16: DESCRIPTION | O16: AMOUNT
A17: Enter Description and Amount of each expense in cells at right, cells B17 through O21. Next instruction is in cell A22. | C17: =IFERROR(VLOOKUP(B17,fixed_expenses4[],2,0),"") | E17: =IFERROR(VLOOKUP(D17,fixed_expenses4[],2,0),"") | G17: =IFERROR(VLOOKUP(F17,fixed_expenses4[],2,0),"") | I17: =IFERROR(VLOOKUP(H17,fixed_expenses4[],2,0),"") | K17: =IFERROR(VLOOKUP(J17,fixed_expenses4[],2,0),"") | L17: Paul Income | M17: =IFERROR(VLOOKUP(L17,fixed_expenses4[],2,0),"") -> 800 | O17: =IFERROR(VLOOKUP(N17,fixed_expenses4[],2,0),"")
C18: =IFERROR(VLOOKUP(B18,fixed_expenses4[],2,0),"") | E18: =IFERROR(VLOOKUP(D18,fixed_expenses4[],2,0),"") | G18: =IFERROR(VLOOKUP(F18,fixed_expenses4[],2,0),"") | I18: =IFERROR(VLOOKUP(H18,fixed_expenses4[],2,0),"") | K18: =IFERROR(VLOOKUP(J18,fixed_expenses4[],2,0),"") | M18: =IFERROR(VLOOKUP(L18,fixed_expenses4[],2,0),"") | O18: =IFERROR(VLOOKUP(N18,fixed_expenses4[],2,0),"")
C19: =IFERROR(VLOOKUP(B19,fixed_expenses4[],2,0),"") | E19: =IFERROR(VLOOKUP(D19,fixed_expenses4[],2,0),"") | G19: =IFERROR(VLOOKUP(F19,fixed_expenses4[],2,0),"") | I19: =IFERROR(VLOOKUP(H19,fixed_expenses4[],2,0),"") | K19: =IFERROR(VLOOKUP(J19,fixed_expenses4[],2,0),"") | M19: =IFERROR(VLOOKUP(L19,fixed_expenses4[],2,0),"") | O19: =IFERROR(VLOOKUP(N19,fixed_expenses4[],2,0),"")
C20: =IFERROR(VLOOKUP(B20,fixed_expenses4[],2,0),"") | E20: =IFERROR(VLOOKUP(D20,fixed_expenses4[],2,0),"") | G20: =IFERROR(VLOOKUP(F20,fixed_expenses4[],2,0),"") | I20: =IFERROR(VLOOKUP(H20,fixed_expenses4[],2,0),"") | K20: =IFERROR(VLOOKUP(J20,fixed_expenses4[],2,0),"") | M20: =IFERROR(VLOOKUP(L20,fixed_expenses4[],2,0),"") | O20: =IFERROR(VLOOKUP(N20,fixed_expenses4[],2,0),"")
C21: =IFERROR(VLOOKUP(B21,fixed_expenses4[],2,0),"") | E21: =IFERROR(VLOOKUP(D21,fixed_expenses4[],2,0),"") | G21: =IFERROR(VLOOKUP(F21,fixed_expenses4[],2,0),"") | I21: =IFERROR(VLOOKUP(H21,fixed_expenses4[],2,0),"") | K21: =IFERROR(VLOOKUP(J21,fixed_expenses4[],2,0),"") | M21: =IFERROR(VLOOKUP(L21,fixed_expenses4[],2,0),"") | O21: =IFERROR(VLOOKUP(N21,fixed_expenses4[],2,0),"")
A22: Total is auto calculated for each day and week in cell at right, cells C22 through P22. Next instruction is in cell A24. | B22: TOTAL | C22: =SUM(C17:C21) -> 0 | E22: =SUM(E17:E21) -> 0 | G22: =SUM(G17:G21) -> 0 | I22: =SUM(I17:I21) -> 0 | K22: =SUM(K17:K21) -> 0 | M22: =SUM(M17:M21) -> 800 | O22: =SUM(O17:O21) -> 0 | P22: =SUM(C22,E22,G22,I22,K22,M22,O22) -> 800
A24: Calendar dates are in cells at right, cells B24 through O24. | B24: =N15+1 -> 10 | D24: =B24+1 -> 11 | F24: =D24+1 -> 12 | H24: =F24+1 -> 13 | J24: =H24+1 -> 14 | L24: =J24+1 -> 15 | N24: =L24+1 -> 16
A25: Description and Amount labels are in cells at right, cells B25 through O25. | B25: DESCRIPTION | C25: AMOUNT | D25: DESCRIPTION | E25: AMOUNT | F25: DESCRIPTION | G25: AMOUNT | H25: DESCRIPTION | I25: AMOUNT | J25: DESCRIPTION | K25: AMOUNT | L25: DESCRIPTION | M25: AMOUNT | N25: DESCRIPTION | O25: AMOUNT
A26: Enter Description and Amount of each expense in cells at right, cells B26 through O30. Next instruction is in cell A31. | C26: =IFERROR(VLOOKUP(B26,fixed_expenses4[],2,0),"") | E26: =IFERROR(VLOOKUP(D26,fixed_expenses4[],2,0),"") | G26: =IFERROR(VLOOKUP(F26,fixed_expenses4[],2,0),"") | I26: =IFERROR(VLOOKUP(H26,fixed_expenses4[],2,0),"") | K26: =IFERROR(VLOOKUP(J26,fixed_expenses4[],2,0),"") | L26: Paul Income | M26: =IFERROR(VLOOKUP(L26,fixed_expenses4[],2,0),"") -> 800 | O26: =IFERROR(VLOOKUP(N26,fixed_expenses4[],2,0),"")
C27: =IFERROR(VLOOKUP(B27,fixed_expenses4[],2,0),"") | E27: =IFERROR(VLOOKUP(D27,fixed_expenses4[],2,0),"") | G27: =IFERROR(VLOOKUP(F27,fixed_expenses4[],2,0),"") | I27: =IFERROR(VLOOKUP(H27,fixed_expenses4[],2,0),"") | K27: =IFERROR(VLOOKUP(J27,fixed_expenses4[],2,0),"") | M27: =IFERROR(VLOOKUP(L27,fixed_expenses4[],2,0),"") | O27: =IFERROR(VLOOKUP(N27,fixed_expenses4[],2,0),"")
C28: =IFERROR(VLOOKUP(B28,fixed_expenses4[],2,0),"") | E28: =IFERROR(VLOOKUP(D28,fixed_expenses4[],2,0),"") | G28: =IFERROR(VLOOKUP(F28,fixed_expenses4[],2,0),"") | I28: =IFERROR(VLOOKUP(H28,fixed_expenses4[],2,0),"") | K28: =IFERROR(VLOOKUP(J28,fixed_expenses4[],2,0),"") | M28: =IFERROR(VLOOKUP(L28,fixed_expenses4[],2,0),"") | O28: =IFERROR(VLOOKUP(N28,fixed_expenses4[],2,0),"")
C29: =IFERROR(VLOOKUP(B29,fixed_expenses4[],2,0),"") | E29: =IFERROR(VLOOKUP(D29,fixed_expenses4[],2,0),"") | G29: =IFERROR(VLOOKUP(F29,fixed_expenses4[],2,0),"") | I29: =IFERROR(VLOOKUP(H29,fixed_expenses4[],2,0),"") | K29: =IFERROR(VLOOKUP(J29,fixed_expenses4[],2,0),"") | M29: =IFERROR(VLOOKUP(L29,fixed_expenses4[],2,0),"") | O29: =IFERROR(VLOOKUP(N29,fixed_expenses4[],2,0),"")
C30: =IFERROR(VLOOKUP(B30,fixed_expenses4[],2,0),"") | E30: =IFERROR(VLOOKUP(D30,fixed_expenses4[],2,0),"") | G30: =IFERROR(VLOOKUP(F30,fixed_expenses4[],2,0),"") | I30: =IFERROR(VLOOKUP(H30,fixed_expenses4[],2,0),"") | K30: =IFERROR(VLOOKUP(J30,fixed_expenses4[],2,0),"") | M30: =IFERROR(VLOOKUP(L30,fixed_expenses4[],2,0),"") | O30: =IFERROR(VLOOKUP(N30,fixed_expenses4[],2,0),"")
A31: Total is auto calculated for each day and week in cell at right, cells C31 through P31. Next instruction is in cell A33. | B31: TOTAL | C31: =SUM(C26:C30) -> 0 | E31: =SUM(E26:E30) -> 0 | G31: =SUM(G26:G30) -> 0 | I31: =SUM(I26:I30) -> 0 | K31: =SUM(K26:K30) -> 0 | M31: =SUM(M26:M30) -> 800 | O31: =SUM(O26:O30) -> 0 | P31: =SUM(C31,E31,G31,I31,K31,M31,O31) -> 800
A33: Calendar dates are in cells at right, cells B33 through O33. | B33: =N24+1 -> 17 | D33: =B33+1 -> 18 | F33: =D33+1 -> 19 | H33: =F33+1 -> 20 | J33: =H33+1 -> 21 | L33: =J33+1 -> 22 | N33: =L33+1 -> 23
A34: Description and Amount labels are in cells at right, cells B34 through O34. | B34: DESCRIPTION | C34: AMOUNT | D34: DESCRIPTION | E34: AMOUNT | F34: DESCRIPTION | G34: AMOUNT | H34: DESCRIPTION | I34: AMOUNT | J34: DESCRIPTION | K34: AMOUNT | L34: DESCRIPTION | M34: AMOUNT | N34: DESCRIPTION | O34: AMOUNT
A35: Enter Description and Amount of each expense in cells at right, cells B35 through O39. Next instruction is in cell A40. | C35: =IFERROR(VLOOKUP(B35,fixed_expenses4[],2,0),"") | E35: =IFERROR(VLOOKUP(D35,fixed_expenses4[],2,0),"") | G35: =IFERROR(VLOOKUP(F35,fixed_expenses4[],2,0),"") | I35: =IFERROR(VLOOKUP(H35,fixed_expenses4[],2,0),"") | K35: =IFERROR(VLOOKUP(J35,fixed_expenses4[],2,0),"") | L35: Paul Income | M35: =IFERROR(VLOOKUP(L35,fixed_expenses4[],2,0),"") -> 800 | O35: =IFERROR(VLOOKUP(N35,fixed_expenses4[],2,0),"")
C36: =IFERROR(VLOOKUP(B36,fixed_expenses4[],2,0),"") | E36: =IFERROR(VLOOKUP(D36,fixed_expenses4[],2,0),"") | G36: =IFERROR(VLOOKUP(F36,fixed_expenses4[],2,0),"") | I36: =IFERROR(VLOOKUP(H36,fixed_expenses4[],2,0),"") | K36: =IFERROR(VLOOKUP(J36,fixed_expenses4[],2,0),"") | L36: Lynn Income | M36: =IFERROR(VLOOKUP(L36,fixed_expenses4[],2,0),"") -> 770 | O36: =IFERROR(VLOOKUP(N36,fixed_expenses4[],2,0),"")
C37: =IFERROR(VLOOKUP(B37,fixed_expenses4[],2,0),"") | E37: =IFERROR(VLOOKUP(D37,fixed_expenses4[],2,0),"") | G37: =IFERROR(VLOOKUP(F37,fixed_expenses4[],2,0),"") | I37: =IFERROR(VLOOKUP(H37,fixed_expenses4[],2,0),"") | K37: =IFERROR(VLOOKUP(J37,fixed_expenses4[],2,0),"") | M37: =IFERROR(VLOOKUP(L37,fixed_expenses4[],2,0),"") | O37: =IFERROR(VLOOKUP(N37,fixed_expenses4[],2,0),"")
C38: =IFERROR(VLOOKUP(B38,fixed_expenses4[],2,0),"") | E38: =IFERROR(VLOOKUP(D38,fixed_expenses4[],2,0),"") | G38: =IFERROR(VLOOKUP(F38,fixed_expenses4[],2,0),"") | I38: =IFERROR(VLOOKUP(H38,fixed_expenses4[],2,0),"") | K38: =IFERROR(VLOOKUP(J38,fixed_expenses4[],2,0),"") | M38: =IFERROR(VLOOKUP(L38,fixed_expenses4[],2,0),"") | O38: =IFERROR(VLOOKUP(N38,fixed_expenses4[],2,0),"")
C39: =IFERROR(VLOOKUP(B39,fixed_expenses4[],2,0),"") | E39: =IFERROR(VLOOKUP(D39,fixed_expenses4[],2,0),"") | G39: =IFERROR(VLOOKUP(F39,fixed_expenses4[],2,0),"") | I39: =IFERROR(VLOOKUP(H39,fixed_expenses4[],2,0),"") | K39: =IFERROR(VLOOKUP(J39,fixed_expenses4[],2,0),"") | M39: =IFERROR(VLOOKUP(L39,fixed_expenses4[],2,0),"") | O39: =IFERROR(VLOOKUP(N39,fixed_expenses4[],2,0),"")
A40: Total is auto calculated for each day and week in cell at right, cells C40 through P40. Next instruction is in cell A42. | B40: TOTAL | C40: =SUM(C35:C39) -> 0 | E40: =SUM(E35:E39) -> 0 | G40: =SUM(G35:G39) -> 0 | I40: =SUM(I35:I39) -> 0 | K40: =SUM(K35:K39) -> 0 | M40: =SUM(M35:M39) -> 1570 | O40: =SUM(O35:O39) -> 0 | P40: =SUM(C40,E40,G40,I40,K40,M40,O40) -> 1570
A42: Calendar dates are in cells at right, cells B42 through O42. | B42: =DAY(IF(DAY(JanSun1)=1,JanSun1+22,JanSun1+29)) -> 24 | D42: =DAY(IF(DAY(JanSun1)=1,JanSun1+23,JanSun1+30)) -> 25 | F42: =DAY(IF(DAY(JanSun1)=1,JanSun1+24,JanSun1+31)) -> 26 | H42: =DAY(IF(DAY(JanSun1)=1,JanSun1+25,JanSun1+32)) -> 27 | J42: =DAY(IF(DAY(JanSun1)=1,JanSun1+26,JanSun1+33)) -> 28 | L42: =DAY(IF(DAY(JanSun1)=1,JanSun1+27,JanSun1+34)) -> 29 | N42: =DAY(IF(DAY(JanSun1)=1,JanSun1+28,JanSun1+35)) -> 30
A43: Description and Amount labels are in cells at right, cells B43 through O43. | B43: DESCRIPTION | C43: AMOUNT | D43: DESCRIPTION | E43: AMOUNT | F43: DESCRIPTION | G43: AMOUNT | H43: DESCRIPTION | I43: AMOUNT | J43: DESCRIPTION | K43: AMOUNT | L43: DESCRIPTION | M43: AMOUNT | N43: DESCRIPTION | O43: AMOUNT
A44: Enter Description and Amount of each expense in cells at right, cells B44 through O48. Next instruction is in cell A49. | C44: =IFERROR(VLOOKUP(B44,fixed_expenses4[],2,0),"") | E44: =IFERROR(VLOOKUP(D44,fixed_expenses4[],2,0),"") | G44: =IFERROR(VLOOKUP(F44,fixed_expenses4[],2,0),"") | I44: =IFERROR(VLOOKUP(H44,fixed_expenses4[],2,0),"") | K44: =IFERROR(VLOOKUP(J44,fixed_expenses4[],2,0),"") | L44: Paul Income | M44: =IFERROR(VLOOKUP(L44,fixed_expenses4[],2,0),"") -> 800 | O44: =IFERROR(VLOOKUP(N44,fixed_expenses4[],2,0),"")
...
