Workbook
Name allowance: #REF!
Name AprSun1: DATE(CalendarYear,4,1)-WEEKDAY(DATE(CalendarYear,4,1))
Name AugSun1: DATE(CalendarYear,8,1)-WEEKDAY(DATE(CalendarYear,8,1))
Name budget: '[1]Pivot (2021)'!$A$2
Name Budget: #REF!
Name CalendarYear: [0]!Year1
Name Categories: [2]!TableAssetAllocation[Category]
Name DecSun1: DATE(CalendarYear,12,1)-WEEKDAY(DATE(CalendarYear,12,1))
Name Expense_Categories: 'Categories - WIP'!$A$2:$A$12
Name Expense_Lookup: Discover!$Q:$R
Name FebSun1: DATE(CalendarYear,2,1)-WEEKDAY(DATE(CalendarYear,2,1))
Name fixed: #REF!
Name income: #REF!
Name JanSun1: DATE(CalendarYear,1,1)-WEEKDAY(DATE(CalendarYear,1,1))
Name JulSun1: DATE(CalendarYear,7,1)-WEEKDAY(DATE(CalendarYear,7,1))
Name JunSun1: DATE(CalendarYear,6,1)-WEEKDAY(DATE(CalendarYear,6,1))
Name LastCol: COUNTA('PERSONAL BUDGET - WIP'!$4:$4)+1
Name MarSun1: DATE(CalendarYear,3,1)-WEEKDAY(DATE(CalendarYear,3,1))
Name MaySun1: DATE(CalendarYear,5,1)-WEEKDAY(DATE(CalendarYear,5,1))
Name NovSun1: DATE(CalendarYear,11,1)-WEEKDAY(DATE(CalendarYear,11,1))
Name OctSun1: DATE(CalendarYear,10,1)-WEEKDAY(DATE(CalendarYear,10,1))
Name PrintArea_SET: OFFSET('PERSONAL BUDGET - WIP'!$C$2,,,MATCH(REPT("z",255),'PERSONAL BUDGET - WIP'!$C:$C),LastCol)
Name Robinhood: #REF!
Name SepSun1: DATE(CalendarYear,9,1)-WEEKDAY(DATE(CalendarYear,9,1))
Name StartMonth: #REF!
Name Tail_Rent: '[1]2021 Income'!#REF!
Name Title2: #REF!
Name valdate: #REF!
Name Year1: VALUE(LEFT(#REF!,4))

Sheet Wells Fargo
A1: Month | B1: Day | C1: Date | D1: Description2 | E1: Description | F1: Amount | G1: Primary
A2: =MONTH(C2) -> 1 | B2: =DAY(C2) -> 4 | C2: 44200 | D2: DISCOVER | E2: DISCOVER E-PAYMENT 210101 4732 LEWIS SEAN | F2: -700 | G2: Credit
A3: =MONTH(C3) -> 1 | B3: =DAY(C3) -> 4 | C3: 44200 | D3: IRS | E3: IRS TREAS 310 XXTAXEIP2 010421 XXXXXXXXXX00908 LEWIS, SEAN | F3: 600 | G3: Stimulus 1
A4: =MONTH(C4) -> 1 | B4: =DAY(C4) -> 15 | C4: 44211 | D4: DISCOVER | E4: DISCOVER E-PAYMENT 210115 4732 LEWIS SEAN | F4: -729.23 | G4: Credit
A5: =MONTH(C5) -> 1 | B5: =DAY(C5) -> 15 | C5: 44211 | D5: Elephant | E5: Elephant Ins PAYROLL 210113 2087 Lewis Sean | F5: 1459.65 | G5: Elephant
A6: =MONTH(C6) -> 1 | B6: =DAY(C6) -> 19 | C6: 44215 | D6: VENMO | E6: VENMO PAYMENT 5101219782 SEAN LEWIS | F6: -569.12 | G6: Vincent
A7: =MONTH(C7) -> 1 | B7: =DAY(C7) -> 19 | C7: 44215 | D7: VENMO | E7: VENMO PAYMENT 5101208453 SEAN LEWIS | F7: -78.86 | G7: Amar - Electric
A8: =MONTH(C8) -> 1 | B8: =DAY(C8) -> 19 | C8: 44215 | D8: VENMO | E8: VENMO CASHOUT 5117912825 SEAN LEWIS | F8: 150 | G8: Venmo Cash Out
A9: =MONTH(C9) -> 1 | B9: =DAY(C9) -> 21 | C9: 44217 | D9: PURCHASE | E9: PURCHASE AUTHORIZED ON 01/20 CASH APP* 8774174551 CA S461020486646597 CARD 6634 | F9: -155 | G9: Cairo
A10: =MONTH(C10) -> 1 | B10: =DAY(C10) -> 22 | C10: 44218 | D10: PURCHASE | E10: PURCHASE AUTHORIZED ON 01/21 SOCIETY OF ACTUARI 847-706-3620 IL S581021446560343 CARD 6634 | F10: -75 | G10: SOA
A11: =MONTH(C11) -> 1 | B11: =DAY(C11) -> 26 | C11: 44222 | D11: MONEY | E11: MONEY TRANSFER AUTHORIZED ON 01/26 FROM Sean Lewis VA S00581026542833832 CARD 6634 | F11: 155 | G11: Cairo
A12: =MONTH(C12) -> 1 | B12: =DAY(C12) -> 28 | C12: 44224 | D12: ROBINHOOD | E12: ROBINHOOD Funds 210127 XXXXX4480 Sean Lewis | F12: -100 | G12: Investment
A13: =MONTH(C13) -> 1 | B13: =DAY(C13) -> 28 | C13: 44224 | D13: ROBINHOOD | E13: ROBINHOOD Funds 210127 XXXXX4480 Sean Lewis | F13: -50 | G13: Investment
... A127: =MONTH(C127) -> 6 | B127: =DAY(C127) -> 17 | C127: 44364 | D127: Nationwide | E127: Nationwide PAYROLL 01 HRP0007397914 Sean Lewis | F127: 4436.57 | G127: Nationwide
A128: =MONTH(C128) -> 6 | B128: =DAY(C128) -> 18 | C128: 44365 | D128: =LEFT(E128, FIND(" ",E128)-1) -> PRINCIPAL | E128: PRINCIPAL TRUST DR CR 210617 PACT#179541394 SEAN LEWIS | F128: 3967.1 | G128: Principal retirement
A129: =MONTH(C129) -> 6 | B129: =DAY(C129) -> 18 | C129: 44365 | D129: =LEFT(E129, FIND(" ",E129)-1) -> Elephant | E129: Elephant Ins PAYROLL 210616 2087 Lewis Sean | F129: 680.02 | G129: Elephant
A130: =MONTH(C130) -> 6 | B130: =DAY(C130) -> 21 | C130: 44368 | D130: =LEFT(E130, FIND(" ",E130)-1) -> VENMO | E130: VENMO PAYMENT 210620 1014291472980 SEAN LEWIS | F130: -2738.5 | G130: Matt Bozz
A131: =MONTH(C131) -> 6 | B131: =DAY(C131) -> 21 | C131: 44368 | D131: =LEFT(E131, FIND(" ",E131)-1) -> VENMO | E131: VENMO PAYMENT 210620 1014291497592 SEAN LEWIS | F131: -615 | G131: Anush Rohani Shukla
A132: =MONTH(C132) -> 6 | B132: =DAY(C132) -> 23 | C132: 44370 | D132: =LEFT(E132, FIND(" ",E132)-1) -> DISCOVER | E132: DISCOVER E-PAYMENT 210623 7328 LEWIS SEAN | F132: -1869 | G132: Credit
A133: =MONTH(C133) -> 6 | B133: =DAY(C133) -> 23 | C133: 44370 | D133: =LEFT(E133, FIND(" ",E133)-1) -> PURCHASE | E133: PURCHASE AUTHORIZED ON 06/22 STITCH FIX STYLIN 844-386-3850 CA S581173332274659 CARD 6634 | F133: -20 | G133: Headshot
A134: =MONTH(C134) -> 6 | B134: =DAY(C134) -> 23 | C134: 44370 | D134: =LEFT(E134, FIND(" ",E134)-1) -> PRINCIPAL | E134: PRINCIPAL TRUST DR CR 210622 PACT#180033360 Sean Lewis | F134: 198.46 | G134: Principal retirement
A135: =MONTH(C135) -> 6 | B135: =DAY(C135) -> 25 | C135: 44372 | D135: =LEFT(E135, FIND(" ",E135)-1) -> PURCHASE | E135: PURCHASE AUTHORIZED ON 06/23 TST* TIO PABLO TAQ RICHMOND VA S461175013934521 CARD 6634 | F135: -58.57 | G135: Resteraunt
A136: =MONTH(C136) -> 6 | B136: =DAY(C136) -> 30 | C136: 44377 | D136: =LEFT(E136, FIND(" ",E136)-1) -> New | E136: New Manchester F WEB PMTS 063021 M7CVM7 Sean Lewis | F136: -1804.34 | G136: New Manchester - Rent
A137: =MONTH(C137) -> 7 | B137: =DAY(C137) -> 1 | C137: 44378 | D137: =LEFT(E137, FIND(" ",E137)-1) -> DISCOVER | E137: DISCOVER E-PAYMENT 210701 7328 LEWIS SEAN | F137: -871.96 | G137: Credit
A138: =MONTH(C138) -> 7 | B138: =DAY(C138) -> 1 | C138: 44378 | D138: =LEFT(E138, FIND(" ",E138)-1) -> Nationwide | E138: Nationwide PAYROLL 01 HRP0007447918 Sean Lewis | F138: 1583.62 | G138: Nationwide
A139: =MONTH(C139) -> 7 | B139: =DAY(C139) -> 6 | C139: 44383 | D139: =LEFT(E139, FIND(" ",E139)-1) -> DISCOVER | E139: DISCOVER E-PAYMENT 210705 7328 LEWIS SEAN | F139: -367.73 | G139: Credit
... A215: =MONTH(C215) -> 10 | B215: =DAY(C215) -> 1 | C215: 44470 | D215: =LEFT(E215, FIND(" ",E215)-1) -> VENMO | E215: VENMO PAYMENT 211001 1016029881790 SEAN LEWIS | F215: -1866.67 | G215: Rent - Artisan Village
A216: =MONTH(C216) -> 10 | B216: =DAY(C216) -> 4 | C216: 44473 | D216: =LEFT(E216, FIND(" ",E216)-1) -> VENMO | E216: VENMO PAYMENT 211003 1016066822276 SEAN LEWIS | F216: -155
A217: =MONTH(C217) -> 10 | B217: =DAY(C217) -> 5 | C217: 44474 | D217: =LEFT(E217, FIND(" ",E217)-1) -> MONEY | E217: MONEY TRANSFER AUTHORIZED ON 10/05 FROM Sean Lewis VA S00301278504520063 CARD 6634 | F217: 170
A218: =MONTH(C218) -> 10 | B218: =DAY(C218) -> 5 | C218: 44474 | D218: =LEFT(E218, FIND(" ",E218)-1) -> MONEY | E218: MONEY TRANSFER AUTHORIZED ON 10/05 FROM Sean Lewis VA S00461278489165227 CARD 6634 | F218: 100
A219: =MONTH(C219) -> 10 | B219: =DAY(C219) -> 7 | C219: 44476 | D219: =LEFT(E219, FIND(" ",E219)-1) -> Nationwide | E219: Nationwide PAYROLL 01 HRP0007713476 Sean Lewis | F219: 2029.34 | G219: Nationwide
A220: =MONTH(C220) -> 10 | B220: =DAY(C220) -> 8 | C220: 44477 | D220: =LEFT(E220, FIND(" ",E220)-1) -> BEST | E220: BEST BUY PAYMENT 211007 610557584343627 SEAN LEWIS | F220: -2378.52
A221: =MONTH(C221) -> 10 | B221: =DAY(C221) -> 12 | C221: 44481 | D221: =LEFT(E221, FIND(" ",E221)-1) -> APS | E221: APS electric pmt PAYMENT 211008 5175354092 Lewis,Sean | F221: -14.71 | G221: APS
A222: =MONTH(C222) -> 10 | B222: =DAY(C222) -> 12 | C222: 44481 | D222: =LEFT(E222, FIND(" ",E222)-1) -> PURCHASE | E222: PURCHASE AUTHORIZED ON 10/11 WAL-MART #2515 PHOENIX AZ P00000000177097893 CARD 6634 | F222: -34.43
A223: =MONTH(C223) -> 10 | B223: =DAY(C223) -> 12 | C223: 44481 | D223: =LEFT(E223, FIND(" ",E223)-1) -> PURCHASE | E223: PURCHASE AUTHORIZED ON 10/08 CASH APP*SHEVON LE 8774174551 CA S381281823108419 CARD 6634 | F223: -350 | G223: Shevon
A224: =MONTH(C224) -> 10 | B224: =DAY(C224) -> 12 | C224: 44481 | D224: =LEFT(E224, FIND(" ",E224)-1) -> FIDELITY | E224: FIDELITY 10077 P FIDELITY 10077 XXXXX0268 SEAN LEWIS | F224: 1201.6 | G224: Fidelity Retirement
A225: =MONTH(C225) -> 10 | B225: =DAY(C225) -> 18 | C225: 44487 | D225: =LEFT(E225, FIND(" ",E225)-1) -> VENMO | E225: VENMO PAYMENT 211018 1016334480094 SEAN LEWIS | F225: -50 | G225: ZZZ
A226: =MONTH(C226) -> 10 | B226: =DAY(C226) -> 20 | C226: 44489 | D226: =LEFT(E226, FIND(" ",E226)-1) -> TRANSFER | E226: TRANSFER FROM LEWIS SHARON ON 10/20 REF # PP0CNS6J5C PURCHASE OF HOME OFFICE AND PROTECTION | F226: 377.98 | G226: Mom
A227: =MONTH(C227) -> 10 | B227: =DAY(C227) -> 20 | C227: 44489 | D227: =LEFT(E227, FIND(" ",E227)-1) -> TRANSFER | E227: TRANSFER FROM LEWIS SHARON ON 10/20 REF # PP0CNS6836 FOR LENOVO COMPUTER PURCHASE | F227: 812.12 | G227: Mom
A228: =MONTH(C228) -> 10 | B228: =DAY(C228) -> 21 | C228: 44490 | D228: =LEFT(E228, FIND(" ",E228)-1) -> VENMO | E228: VENMO PAYMENT 211021 1016376963889 SEAN LEWIS | F228: -1682.31 | G228: ZZZ
...

Sheet Discover
A1: Year | B1: Month | C1: Trans. date | D1: Post date | E1: Description | F1: Amount | G1: Category | H1: Expense Type | I1: Cumulative | J1: Association | K1: Budget Main CAT
A2: =YEAR(C2) -> 2021 | B2: =MONTH(C2) -> 1 | C2: 44197 | D2: 44197 | E2: INTERNET PAYMENT - THANK YOU | F2: -700 | G2: Payments and Credits | H2: =VLOOKUP(G2,Expense_Lookup,2,0) -> Payment | I2: 728.15
A3: =YEAR(C3) -> 2021 | B3: =MONTH(C3) -> 1 | C3: 44197 | D3: 44199 | E3: NETFLIX.COM NETFLIX.COM CA44115296471 | F3: 13.99 | G3: APP | H3: =VLOOKUP(G3,Expense_Lookup,2,0) -> Fixed | I3: =I2+F3 -> 742.14 | J3: Netflix | K3: SUBSCRIPTION
A4: =YEAR(C4) -> 2021 | B4: =MONTH(C4) -> 1 | C4: 44197 | D4: 44199 | E4: SPOTIFY P12D96D434 8777781161 NY | F4: 9.99 | G4: APP | H4: =VLOOKUP(G4,Expense_Lookup,2,0) -> Fixed | I4: =I3+F4 -> 752.13 | J4: Spotify | K4: SUBSCRIPTION | N4: Variable | O4: =SUMIFS(F:F,H:H,N4) -> 25417.25 | S4: Jan | T4: Feb | U4: Mar | V4: Apr | W4: May | X4: June | Y4: July | Z4: Aug | AA4: Sep | AB4: Oct | AC4: Nov | AD4: Dec | AE4: Yearly
A5: =YEAR(C5) -> 2021 | B5: =MONTH(C5) -> 1 | C5: 44197 | D5: 44199 | E5: WAWA 697 STAFFORD VA | F5: 18.87 | G5: Gasoline | H5: =VLOOKUP(G5,Expense_Lookup,2,0) -> Variable | I5: =I4+F5 -> 771 | K5: TRANSPORTATION | N5: Fixed | O5: =SUMIFS(F:F,H:H,N5) -> 6083.78 | Q5: {=_xlfn.UNIQUE(_xlfn._xlws.FILTER(G:G,(G:G<>0) ))} -> Category
A6: =YEAR(C6) -> 2021 | B6: =MONTH(C6) -> 1 | C6: 44201 | D6: 44201 | E6: MYFICO COM 8003194433 GA | F6: 39.95 | G6: APP | H6: =VLOOKUP(G6,Expense_Lookup,2,0) -> Fixed | I6: =I5+F6 -> 810.95 | J6: Credit Score | K6: SUBSCRIPTION | O6: =SUM(O4:O5) -> 31501.03 | Q6: Payments and Credits | R6: Payment | S6: =SUMIFS(F:F,G:G,Q6,$B:$B,1) -> -2157.38 | T6: =SUMIFS(F:F,G:G,Q6,$B:$B,2) -> -2256.47 | U6: =SUMIFS(F:F,G:G,Q6,$B:$B,3) -> -2413.62 | V6: =SUMIFS($F:$F,$G:$G,$Q6,$B:$B,4) -> -471.07 | W6: =SUMIFS($F:$F,$G:$G,$Q6,$B:$B,5) -> -2855.16 | X6: =SUMIFS($F:$F,$G:$G,$Q6,$B:$B,6) -> -3297.83 | Y6: =SUMIFS($F:$F,$G:$G,$Q6,$B:$B,7) -> -6127.09 | Z6: =SUMIFS($F:$F,$G:$G,$Q6,$B:$B,8) -> -3272.24 | AA6: =SUMIFS($F:$F,$G:$G,$Q6,$B:$B,9) -> -4605.13 | AB6: =SUMIFS($F:$F,$G:$G,$Q6,$B:$B,10) -> -1714.73 | AC6: =SUMIFS($F:$F,$G:$G,$Q6,$B:$B,11) -> -3675.51
A7: =YEAR(C7) -> 2021 | B7: =MONTH(C7) -> 1 | C7: 44201 | D7: 44201 | E7: STATE FARM INSURANCE 800-956-6310 IL | F7: 91.78 | G7: APP | H7: =VLOOKUP(G7,Expense_Lookup,2,0) -> Fixed | I7: =I6+F7 -> 902.73 | J7: State Farm | K7: TRANSPORTATION | N7: Family | Q7: APP | R7: Fixed | S7: =SUMIFS(F:F,G:G,Q7,$B:$B,1) -> 190.63 | T7: =SUMIFS(F:F,G:G,Q7,$B:$B,2) -> 250.9 | U7: =SUMIFS(F:F,G:G,Q7,$B:$B,3) -> 559.85 | V7: =SUMIFS(F:F,G:G,Q7,$B:$B,4) -> 308.43 | W7: =SUMIFS($F:$F,$G:$G,$Q7,$B:$B,5) -> 592.35 | X7: =SUMIFS($F:$F,$G:$G,$Q7,$B:$B,6) -> 579.09 | Y7: =SUMIFS($F:$F,$G:$G,$Q7,$B:$B,7) -> 395.95 | Z7: =SUMIFS($F:$F,$G:$G,$Q7,$B:$B,8) -> 655.42 | AA7: =SUMIFS($F:$F,$G:$G,$Q7,$B:$B,9) -> 616.67 | AB7: =SUMIFS($F:$F,$G:$G,$Q7,$B:$B,10) -> 790.91 | AC7: =SUMIFS($F:$F,$G:$G,$Q7,$B:$B,11) -> 152.59 | AE7: =SUM(S7:AD7) -> 5092.79
A8: =YEAR(C8) -> 2021 | B8: =MONTH(C8) -> 1 | C8: 44201 | D8: 44201 | E8: STEAMPOWERED.COM 425-952-2985 WA | F8: 19.99 | G8: Merchandise | H8: =VLOOKUP(G8,Expense_Lookup,2,0) -> Variable | I8: =I7+F8 -> 922.72 | J8: Neir Automata | K8: ENTERTAINMENT | N8: Jayelin | O8: =SUMIFS(F:F,J:J,N8)+SUMIFS('Cash Flow'!$B:$B,'Cash Flow'!$A:$A,Discover!N8)*-1 -> 910.36 | Q8: Gasoline | R8: Variable | S8: =SUMIFS(F:F,G:G,Q8,$B:$B,1) -> 67.87 | T8: =SUMIFS(F:F,G:G,Q8,$B:$B,2) -> 67.47 | U8: =SUMIFS(F:F,G:G,Q8,$B:$B,3) -> 80.06 | V8: =SUMIFS(F:F,G:G,Q8,$B:$B,4) -> 125.95 | W8: =SUMIFS($F:$F,$G:$G,$Q8,$B:$B,5) -> 115.16 | X8: =SUMIFS($F:$F,$G:$G,$Q8,$B:$B,6) -> 104.56 | Y8: =SUMIFS($F:$F,$G:$G,$Q8,$B:$B,7) -> 71.41 | Z8: =SUMIFS($F:$F,$G:$G,$Q8,$B:$B,8) -> 199.88 | AA8: =SUMIFS($F:$F,$G:$G,$Q8,$B:$B,9) -> 353.18 | AB8: =SUMIFS($F:$F,$G:$G,$Q8,$B:$B,10) -> 103 | AC8: =SUMIFS($F:$F,$G:$G,$Q8,$B:$B,11) -> 0 | AE8: =SUM(S8:AD8) -> 1288.54
A9: =YEAR(C9) -> 2021 | B9: =MONTH(C9) -> 1 | C9: 44202 | D9: 44202 | E9: LIVECAREER.COM 800652843 866-933-7587 PR | F9: 24.95 | G9: Family | H9: =VLOOKUP(G9,Expense_Lookup,2,0) -> Variable | I9: =I8+F9 -> 947.67 | J9: Jayelin | K9: MISC PAYMENTS | N9: Shevon | O9: =SUMIFS(F:F,J:J,N9)+SUMIFS('Cash Flow'!$B:$B,'Cash Flow'!$A:$A,Discover!N9)*-1 -> 1624.95 | Q9: Merchandise | R9: Variable | S9: =SUMIFS(F:F,G:G,Q9,$B:$B,1) -> 434.08 | T9: =SUMIFS(F:F,G:G,Q9,$B:$B,2) -> 262.63 | U9: =SUMIFS(F:F,G:G,Q9,$B:$B,3) -> 427.64 | V9: =SUMIFS(F:F,G:G,Q9,$B:$B,4) -> 360.76 | W9: =SUMIFS($F:$F,$G:$G,$Q9,$B:$B,5) -> 645.99 | X9: =SUMIFS($F:$F,$G:$G,$Q9,$B:$B,6) -> 1136.89 | Y9: =SUMIFS($F:$F,$G:$G,$Q9,$B:$B,7) -> 1104.67 | Z9: =SUMIFS($F:$F,$G:$G,$Q9,$B:$B,8) -> 662.17 | AA9: =SUMIFS($F:$F,$G:$G,$Q9,$B:$B,9) -> 2140.89 | AB9: =SUMIFS($F:$F,$G:$G,$Q9,$B:$B,10) -> 1531.79 | AC9: =SUMIFS($F:$F,$G:$G,$Q9,$B:$B,11) -> 266.43 | AE9: =SUM(S9:AD9) -> 8973.94
A10: =YEAR(C10) -> 2021 | B10: =MONTH(C10) -> 1 | C10: 44202 | D10: 44202 | E10: RIVER RUN SHORT PUMP HENRICO VA | F10: 30 | G10: Medical Services | H10: =VLOOKUP(G10,Expense_Lookup,2,0) -> Variable | I10: =I9+F10 -> 977.67 | K10: HEALTH | N10: Don | O10: =SUMIFS(F:F,J:J,N10)+SUMIFS('Cash Flow'!$B:$B,'Cash Flow'!$A:$A,Discover!N10)*-1 -> 297.5 | Q10: Family | R10: Variable | S10: =SUMIFS(F:F,G:G,Q10,$B:$B,1) -> 172.84 | T10: =SUMIFS(F:F,G:G,Q10,$B:$B,2) -> 71.26 | U10: =SUMIFS(F:F,G:G,Q10,$B:$B,3) -> 84.95 | V10: =SUMIFS(F:F,G:G,Q10,$B:$B,4) -> 9.95 | W10: =SUMIFS($F:$F,$G:$G,$Q10,$B:$B,5) -> 91.85 | X10: =SUMIFS($F:$F,$G:$G,$Q10,$B:$B,6) -> 0 | Y10: =SUMIFS($F:$F,$G:$G,$Q10,$B:$B,7) -> 0 | Z10: =SUMIFS($F:$F,$G:$G,$Q10,$B:$B,8) -> 0 | AA10: =SUMIFS($F:$F,$G:$G,$Q10,$B:$B,9) -> 0 | AB10: =SUMIFS($F:$F,$G:$G,$Q10,$B:$B,10) -> 0 | AC10: =SUMIFS($F:$F,$G:$G,$Q10,$B:$B,11) -> 0 | AE10: =SUM(S10:AD10) -> 430.85
A11: =YEAR(C11) -> 2021 | B11: =MONTH(C11) -> 1 | C11: 44202 | D11: 44202 | E11: THE MARKET @ 25TH RICHMOND VA | F11: 24.24 | G11: Supermarkets | H11: =VLOOKUP(G11,Expense_Lookup,2,0) -> Variable | I11: =I10+F11 -> 1001.91 | K11: DAILY LIVING | N11: Dorry | O11: =SUMIFS(F:F,J:J,N11)+SUMIFS('Cash Flow'!$B:$B,'Cash Flow'!$A:$A,Discover!N11)*-1 -> 595 | Q11: Medical Services | R11: Variable | S11: =SUMIFS(F:F,G:G,Q11,$B:$B,1) -> 70.51 | T11: =SUMIFS(F:F,G:G,Q11,$B:$B,2) -> 0 | U11: =SUMIFS(F:F,G:G,Q11,$B:$B,3) -> 0 | V11: =SUMIFS(F:F,G:G,Q11,$B:$B,4) -> 0 | W11: =SUMIFS($F:$F,$G:$G,$Q11,$B:$B,5) -> 0 | X11: =SUMIFS($F:$F,$G:$G,$Q11,$B:$B,6) -> 0 | Y11: =SUMIFS($F:$F,$G:$G,$Q11,$B:$B,7) -> 0 | Z11: =SUMIFS($F:$F,$G:$G,$Q11,$B:$B,8) -> 0 | AA11: =SUMIFS($F:$F,$G:$G,$Q11,$B:$B,9) -> 0 | AB11: =SUMIFS($F:$F,$G:$G,$Q11,$B:$B,10) -> 0 | AC11: =SUMIFS($F:$F,$G:$G,$Q11,$B:$B,11) -> 0 | AE11: =SUM(S11:AD11) -> 70.51
A12: =YEAR(C12) -> 2021 | B12: =MONTH(C12) -> 1 | C12: 44203 | D12: 44203 | E12: AMERICA'S BEST WINGS HENRICO VA | F12: 12.09 | G12: Restaurants | H12: =VLOOKUP(G12,Expense_Lookup,2,0) -> Variable | I12: =I11+F12 -> 1014 | K12: DAILY LIVING | N12: Cairo | O12: =SUMIFS(F:F,J:J,N12)+SUMIFS('Cash Flow'!$B:$B,'Cash Flow'!$A:$A,Discover!N12)*-1 -> 0 | Q12: Supermarkets | R12: Variable | S12: =SUMIFS(F:F,G:G,Q12,$B:$B,1) -> 138.14 | T12: =SUMIFS(F:F,G:G,Q12,$B:$B,2) -> 247.65 | U12: =SUMIFS(F:F,G:G,Q12,$B:$B,3) -> 132.85 | V12: =SUMIFS(F:F,G:G,Q12,$B:$B,4) -> 25.32 | W12: =SUMIFS($F:$F,$G:$G,$Q12,$B:$B,5) -> 321.42 | X12: =SUMIFS($F:$F,$G:$G,$Q12,$B:$B,6) -> 100.64 | Y12: =SUMIFS($F:$F,$G:$G,$Q12,$B:$B,7) -> 328.94 | Z12: =SUMIFS($F:$F,$G:$G,$Q12,$B:$B,8) -> 114.91 | AA12: =SUMIFS($F:$F,$G:$G,$Q12,$B:$B,9) -> 192.66 | AB12: =SUMIFS($F:$F,$G:$G,$Q12,$B:$B,10) -> 218.82 | AC12: =SUMIFS($F:$F,$G:$G,$Q12,$B:$B,11) -> 103.39 | AE12: =SUM(S12:AD12) -> 1924.74
A13: =YEAR(C13) -> 2021 | B13: =MONTH(C13) -> 1 | C13: 44203 | D13: 44203 | E13: GO DRAGON ASIAN GRILL RICHMOND VA | F13: 44 | G13: Restaurants | H13: =VLOOKUP(G13,Expense_Lookup,2,0) -> Variable | I13: =I12+F13 -> 1058 | K13: DAILY LIVING | O13: =SUM(O8:O12) -> 3427.81 | Q13: Restaurants | R13: Variable | S13: =SUMIFS(F:F,G:G,Q13,$B:$B,1) -> 117.23 | T13: =SUMIFS(F:F,G:G,Q13,$B:$B,2) -> 51.96 | U13: =SUMIFS(F:F,G:G,Q13,$B:$B,3) -> 259.85 | V13: =SUMIFS(F:F,G:G,Q13,$B:$B,4) -> 487.13 | W13: =SUMIFS($F:$F,$G:$G,$Q13,$B:$B,5) -> 247.11 | X13: =SUMIFS($F:$F,$G:$G,$Q13,$B:$B,6) -> 472.59 | Y13: =SUMIFS($F:$F,$G:$G,$Q13,$B:$B,7) -> 689.58 | Z13: =SUMIFS($F:$F,$G:$G,$Q13,$B:$B,8) -> 1021.47 | AA13: =SUMIFS($F:$F,$G:$G,$Q13,$B:$B,9) -> 1134.5 | AB13: =SUMIFS($F:$F,$G:$G,$Q13,$B:$B,10) -> 465.78 | AC13: =SUMIFS($F:$F,$G:$G,$Q13,$B:$B,11) -> 252.96 | AE13: =SUM(S13:AD13) -> 5200.16
A14: =YEAR(C14) -> 2021 | B14: =MONTH(C14) -> 1 | C14: 44203 | D14: 44203 | E14: THE MARKET @ 25TH RICHMOND VA | F14: 14.52 | G14: Supermarkets | H14: =VLOOKUP(G14,Expense_Lookup,2,0) -> Variable | I14: =I13+F14 -> 1072.52 | K14: DAILY LIVING | Q14: Services | R14: Variable | S14: =SUMIFS(F:F,G:G,Q14,$B:$B,1) -> 29.27 | T14: =SUMIFS(F:F,G:G,Q14,$B:$B,2) -> 0 | U14: =SUMIFS(F:F,G:G,Q14,$B:$B,3) -> 470 | V14: =SUMIFS(F:F,G:G,Q14,$B:$B,4) -> 98 | W14: =SUMIFS($F:$F,$G:$G,$Q14,$B:$B,5) -> 1.5 | X14: =SUMIFS($F:$F,$G:$G,$Q14,$B:$B,6) -> 213.84 | Y14: =SUMIFS($F:$F,$G:$G,$Q14,$B:$B,7) -> 1904.58 | Z14: =SUMIFS($F:$F,$G:$G,$Q14,$B:$B,8) -> 283.03 | AA14: =SUMIFS($F:$F,$G:$G,$Q14,$B:$B,9) -> 375.1 | AB14: =SUMIFS($F:$F,$G:$G,$Q14,$B:$B,10) -> 352.52 | AC14: =SUMIFS($F:$F,$G:$G,$Q14,$B:$B,11) -> 5 | AE14: =SUM(S14:AD14) -> 3732.84
A15: =YEAR(C15) -> 2021 | B15: =MONTH(C15) -> 1 | C15: 44204 | D15: 44204 | E15: CVS/PHARMACY #01988 RICHMOND VA | F15: 3.37 | G15: Family | H15: =VLOOKUP(G15,Expense_Lookup,2,0) -> Variable | I15: =I14+F15 -> 1075.89 | J15: Jayelin | K15: MISC PAYMENTS | N15: Trips | Q15: Education | R15: Variable | S15: =SUMIFS(F:F,G:G,Q15,$B:$B,1) -> 49 | T15: =SUMIFS(F:F,G:G,Q15,$B:$B,2) -> 215 | U15: =SUMIFS(F:F,G:G,Q15,$B:$B,3) -> 0 | V15: =SUMIFS(F:F,G:G,Q15,$B:$B,4) -> 0 | W15: =SUMIFS($F:$F,$G:$G,$Q15,$B:$B,5) -> 0 | X15: =SUMIFS($F:$F,$G:$G,$Q15,$B:$B,6) -> 199 | Y15: =SUMIFS($F:$F,$G:$G,$Q15,$B:$B,7) -> 0 | Z15: =SUMIFS($F:$F,$G:$G,$Q15,$B:$B,8) -> 4.8 | AA15: =SUMIFS($F:$F,$G:$G,$Q15,$B:$B,9) -> 0 | AB15: =SUMIFS($F:$F,$G:$G,$Q15,$B:$B,10) -> 0 | AC15: =SUMIFS($F:$F,$G:$G,$Q15,$B:$B,11) -> 0 | AE15: =SUM(S15:AD15) -> 467.8
A16: =YEAR(C16) -> 2021 | B16: =MONTH(C16) -> 1 | C16: 44204 | D16: 44204 | E16: LABCORP PSCC 2 800-845-6167 NC202101072171244 | F16: 40.51 | G16: Medical Services | H16: =VLOOKUP(G16,Expense_Lookup,2,0) -> Variable | I16: =I15+F16 -> 1116.4 | J16: Doctor | K16: HEALTH | N16: New York | O16: =SUMIFS(F:F,J:J,N16)+SUMIFS('Cash Flow'!$B:$B,'Cash Flow'!$A:$A,Discover!N16)*-1 -> 373.46 | Q16: Awards and Rebate Credits | R16: Payment | S16: =SUMIFS(F:F,G:G,Q16,$B:$B,1) -> -22.18 | T16: =SUMIFS(F:F,G:G,Q16,$B:$B,2) -> -14 | U16: =SUMIFS(F:F,G:G,Q16,$B:$B,3) -> -14.05 | V16: =SUMIFS(F:F,G:G,Q16,$B:$B,4) -> 0 | W16: =SUMIFS($F:$F,$G:$G,$Q16,$B:$B,5) -> 0 | X16: =SUMIFS($F:$F,$G:$G,$Q16,$B:$B,6) -> 0 | Y16: =SUMIFS($F:$F,$G:$G,$Q16,$B:$B,7) -> 0 | Z16: =SUMIFS($F:$F,$G:$G,$Q16,$B:$B,8) -> -38.86 | AA16: =SUMIFS($F:$F,$G:$G,$Q16,$B:$B,9) -> 0 | AB16: =SUMIFS($F:$F,$G:$G,$Q16,$B:$B,10) -> 0 | AC16: =SUMIFS($F:$F,$G:$G,$Q16,$B:$B,11) -> -43.38 | AE16: =SUM(S16:AD16) -> -132.47
A17: =YEAR(C17) -> 2021 | B17: =MONTH(C17) -> 1 | C17: 44205 | D17: 44205 | E17: BINGO BEER CO - GAMES PE RICHMOND VA | F17: 30 | G17: Restaurants | H17: =VLOOKUP(G17,Expense_Lookup,2,0) -> Variable | I17: =I16+F17 -> 1146.4 | J17: Akhil | K17: DAILY LIVING | N17: Brooklyn | O17: =SUMIFS(F:F,J:J,N17)+SUMIFS('Cash Flow'!$B:$B,'Cash Flow'!$A:$A,Discover!N17)*-1 -> 1983.8 | Q17: Government Services | R17: Variable | S17: =SUMIFS(F:F,G:G,Q17,$B:$B,1) -> 0 | T17: =SUMIFS(F:F,G:G,Q17,$B:$B,2) -> 40.15 | U17: =SUMIFS(F:F,G:G,Q17,$B:$B,3) -> 0 | V17: =SUMIFS(F:F,G:G,Q17,$B:$B,4) -> 0 | W17: =SUMIFS($F:$F,$G:$G,$Q17,$B:$B,5) -> 26.35 | X17: =SUMIFS($F:$F,$G:$G,$Q17,$B:$B,6) -> 195.05 | Y17: =SUMIFS($F:$F,$G:$G,$Q17,$B:$B,7) -> 194 | Z17: =SUMIFS($F:$F,$G:$G,$Q17,$B:$B,8) -> 21.51 | AA17: =SUMIFS($F:$F,$G:$G,$Q17,$B:$B,9) -> 140.91 | AB17: =SUMIFS($F:$F,$G:$G,$Q17,$B:$B,10) -> 0 | AC17: =SUMIFS($F:$F,$G:$G,$Q17,$B:$B,11) -> 138.14 | AE17: =SUM(S17:AD17) -> 756.11
A18: =YEAR(C18) -> 2021 | B18: =MONTH(C18) -> 1 | C18: 44205 | D18: 44205 | E18: WALMART SC 07032 HENRICO VA | F18: 37.5 | G18: Merchandise | H18: =VLOOKUP(G18,Expense_Lookup,2,0) -> Variable | I18: =I17+F18 -> 1183.9 | K18: PERSONAL | O18: =SUM(O16:O17) -> 2357.26 | Q18: Automotive | R18: Fixed | S18: =SUMIFS(F:F,G:G,Q18,$B:$B,1) -> 0 | T18: =SUMIFS(F:F,G:G,Q18,$B:$B,2) -> 0 | U18: =SUMIFS(F:F,G:G,Q18,$B:$B,3) -> 86.17 | V18: =SUMIFS(F:F,G:G,Q18,$B:$B,4) -> 5.65 | W18: =SUMIFS($F:$F,$G:$G,$Q18,$B:$B,5) -> 401.19 | X18: =SUMIFS($F:$F,$G:$G,$Q18,$B:$B,6) -> 0 | Y18: =SUMIFS($F:$F,$G:$G,$Q18,$B:$B,7) -> 394.26 | Z18: =SUMIFS($F:$F,$G:$G,$Q18,$B:$B,8) -> 0 | AA18: =SUMIFS($F:$F,$G:$G,$Q18,$B:$B,9) -> 110.71 | AB18: =SUMIFS($F:$F,$G:$G,$Q18,$B:$B,10) -> 0 | AC18: =SUMIFS($F:$F,$G:$G,$Q18,$B:$B,11) -> 0 | AE18: =SUM(S18:AD18) -> 997.98
A19: =YEAR(C19) -> 2021 | B19: =MONTH(C19) -> 1 | C19: 44206 | D19: 44206 | E19: APPLE.COM/BILL 866-712-7753 CAAPPLE PAY ENDING IN 4775MMW3T9K9KMA0 | F19: 14.99 | G19: APP | H19: =VLOOKUP(G19,Expense_Lookup,2,0) -> Fixed | I19: =I18+F19 -> 1198.89 | J19: HBO | K19: SUBSCRIPTION | Q19: Travel/ Entertainment | R19: Variable | S19: =SUMIFS(F:F,G:G,Q19,$B:$B,1) -> 0 | T19: =SUMIFS(F:F,G:G,Q19,$B:$B,2) -> 0 | U19: =SUMIFS(F:F,G:G,Q19,$B:$B,3) -> 101.04 | V19: =SUMIFS(F:F,G:G,Q19,$B:$B,4) -> 4.24 | W19: =SUMIFS($F:$F,$G:$G,$Q19,$B:$B,5) -> 360.05 | X19: =SUMIFS($F:$F,$G:$G,$Q19,$B:$B,6) -> 179.77 | Y19: =SUMIFS($F:$F,$G:$G,$Q19,$B:$B,7) -> 864.12 | Z19: =SUMIFS($F:$F,$G:$G,$Q19,$B:$B,8) -> 241.29 | AA19: =SUMIFS($F:$F,$G:$G,$Q19,$B:$B,9) -> 360.22 | AB19: =SUMIFS($F:$F,$G:$G,$Q19,$B:$B,10) -> 61.14 | AC19: =SUMIFS($F:$F,$G:$G,$Q19,$B:$B,11) -> 69.2 | AE19: =SUM(S19:AD19) -> 2241.07
A20: =YEAR(C20) -> 2021 | B20: =MONTH(C20) -> 1 | C20: 44206 | D20: 44206 | E20: FEDEX 782422707980 800-4633339 TN | F20: 14.47 | G20: Services | H20: =VLOOKUP(G20,Expense_Lookup,2,0) -> Variable | I20: =I19+F20 -> 1213.36 | J20: Darron | K20: MISC PAYMENTS | N20: Moving | Q20: Home Improvement | R20: Variable | S20: =SUMIFS(F:F,G:G,Q20,$B:$B,1) -> 0 | T20: =SUMIFS(F:F,G:G,Q20,$B:$B,2) -> 0 | U20: =SUMIFS(F:F,G:G,Q20,$B:$B,3) -> 0 | V20: =SUMIFS(F:F,G:G,Q20,$B:$B,4) -> 92.58 | W20: =SUMIFS($F:$F,$G:$G,$Q20,$B:$B,5) -> 54.37 | X20: =SUMIFS($F:$F,$G:$G,$Q20,$B:$B,6) -> 23.13 | Y20: =SUMIFS($F:$F,$G:$G,$Q20,$B:$B,7) -> 0 | Z20: =SUMIFS($F:$F,$G:$G,$Q20,$B:$B,8) -> 89.51 | AA20: =SUMIFS($F:$F,$G:$G,$Q20,$B:$B,9) -> 0 | AB20: =SUMIFS($F:$F,$G:$G,$Q20,$B:$B,10) -> 167.01 | AC20: =SUMIFS($F:$F,$G:$G,$Q20,$B:$B,11) -> 0 | AE20: =SUM(S20:AD20) -> 426.6
A21: =YEAR(C21) -> 2021 | B21: =MONTH(C21) -> 1 | C21: 44206 | D21: 44206 | E21: FEDEX 782422725203 800-4633339 TN | F21: 11.45 | G21: Services | H21: =VLOOKUP(G21,Expense_Lookup,2,0) -> Variable | I21: =I20+F21 -> 1224.81 | J21: Darron | K21: MISC PAYMENTS | N21: Storage | O21: =SUMIFS(F:F,J:J,N21)+SUMIFS('Cash Flow'!$B:$B,'Cash Flow'!$A:$A,Discover!N21)*-1 -> 396.27 | Q21: Car Wash | R21: Variable | S21: =SUMIFS(F:F,G:G,Q21,$B:$B,1) -> 0 | T21: =SUMIFS(F:F,G:G,Q21,$B:$B,2) -> 0 | U21: =SUMIFS(F:F,G:G,Q21,$B:$B,3) -> 0 | V21: =SUMIFS(F:F,G:G,Q21,$B:$B,4) -> 0 | W21: =SUMIFS($F:$F,$G:$G,$Q21,$B:$B,5) -> 0 | X21: =SUMIFS($F:$F,$G:$G,$Q21,$B:$B,6) -> 0 | Y21: =SUMIFS($F:$F,$G:$G,$Q21,$B:$B,7) -> 0 | Z21: =SUMIFS($F:$F,$G:$G,$Q21,$B:$B,8) -> 63.08 | AA21: =SUMIFS($F:$F,$G:$G,$Q21,$B:$B,9) -> 0 | AB21: =SUMIFS($F:$F,$G:$G,$Q21,$B:$B,10) -> 0 | AC21: =SUMIFS($F:$F,$G:$G,$Q21,$B:$B,11) -> 0 | AE21: =SUM(S21:AD21) -> 63.08
A22: =YEAR(C22) -> 2021 | B22: =MONTH(C22) -> 1 | C22: 44206 | D22: 44206 | E22: WALMART SC 07032 HENRICO VA | F22: 74.16 | G22: Merchandise | H22: =VLOOKUP(G22,Expense_Lookup,2,0) -> Variable | I22: =I21+F22 -> 1298.97 | K22: PERSONAL | N22: Arizona | O22: =SUMIFS(F:F,J:J,N22)+SUMIFS('Cash Flow'!$B:$B,'Cash Flow'!$A:$A,Discover!N22)*-1 -> 1380.63 | S22: =SUM(S6:S21) -> -909.99 | T22: =SUM(T6:T21) -> -1063.45 | U22: =SUM(U6:U21) -> -225.26 | V22: =SUM(V6:V21) -> 1046.94 | W22: =SUM(W6:W21) -> 2.18 | X22: =SUM(X6:X21) -> -93.27 | Y22: =SUM(Y6:Y21) -> -179.58 | Z22: =SUM(Z6:Z21) -> 45.97 | ... AC22: =SUM(AC6:AC21) -> -2731.18
A23: =YEAR(C23) -> 2021 | B23: =MONTH(C23) -> 1 | C23: 44207 | D23: 44207 | E23: CASH APP*SHEVON LEW 415-375-3176 CA | F23: 103 | G23: Family | H23: =VLOOKUP(G23,Expense_Lookup,2,0) -> Variable | I23: =I22+F23 -> 1401.97 | J23: Shevon | K23: MISC PAYMENTS | N23: road trip | O23: =SUMIFS(F:F,J:J,N23)+SUMIFS('Cash Flow'!$B:$B,'Cash Flow'!$A:$A,Discover!N23)*-1 -> 1213.29 | R23: Monthly Spending -> | S23: =SUM(S7:S15,S17:S21) -> 1269.57 | T23: =SUM(T7:T15,T17:T21) -> 1207.02 | U23: =SUM(U7:U15,U17:U21) -> 2202.41 | V23: =SUM(V7:V15,V17:V21) -> 1518.01 | W23: =SUM(W7:W15,W17:W21) -> 2857.34 | X23: =SUM(X7:X15,X17:X21) -> 3204.56 | Y23: =SUM(Y7:Y15,Y17:Y21) -> 5947.51 | Z23: =SUM(Z7:Z15,Z17:Z21) -> 3357.07 | ... AD23: =SUM(AD7:AD15,AD17:AD21) -> 0
A24: =YEAR(C24) -> 2021 | B24: =MONTH(C24) -> 1 | C24: 44207 | D24: 44207 | E24: PAYPAL *ETCHEDACTUA 402-935-7733 CA | F24: 49 | G24: Education | H24: =VLOOKUP(G24,Expense_Lookup,2,0) -> Variable | I24: =I23+F24 -> 1450.97 | K24: PERSONAL | O24: =SUM(O21:O22) -> 1776.9
A25: =YEAR(C25) -> 2021 | B25: =MONTH(C25) -> 1 | C25: 44208 | D25: 44208 | E25: EXXONMOBIL RICHMOND VA | F25: 23.27 | G25: Gasoline | H25: =VLOOKUP(G25,Expense_Lookup,2,0) -> Variable | I25: =I24+F25 -> 1474.24 | K25: TRANSPORTATION
A26: =YEAR(C26) -> 2021 | B26: =MONTH(C26) -> 1 | C26: 44208 | D26: 44208 | E26: FAMILY DOLLAR #5701 RICHMOND VA | F26: 3.33 | G26: Family | H26: =VLOOKUP(G26,Expense_Lookup,2,0) -> Variable | I26: =I25+F26 -> 1477.57 | J26: Jayelin | K26: MISC PAYMENTS
A27: =YEAR(C27) -> 2021 | B27: =MONTH(C27) -> 1 | C27: 44208 | D27: 44208 | E27: PAYPAL *VIZMEDIALLC 888-221-1161 CA | F27: 1.99 | G27: APP | H27: =VLOOKUP(G27,Expense_Lookup,2,0) -> Fixed | I27: =I26+F27 -> 1479.56 | J27: Manga | K27: SUBSCRIPTION
A28: =YEAR(C28) -> 2021 | B28: =MONTH(C28) -> 1 | C28: 44211 | D28: 44211 | E28: CASHBACK BONUS REDEMPTION PYMT/STMT CRDT | F28: -22.18 | G28: Awards and Rebate Credits | H28: =VLOOKUP(G28,Expense_Lookup,2,0) -> Payment | I28: =I27+F28 -> 1457.38
A29: =YEAR(C29) -> 2021 | B29: =MONTH(C29) -> 1 | C29: 44211 | D29: 44211 | E29: DIRECTPAY FULL BALANCESEE DETAILS OF YOUR NEXT DIRECTPAY BELOW | F29: -728.15 | G29: Payments and Credits | H29: =VLOOKUP(G29,Expense_Lookup,2,0) -> Payment | I29: =I28+F29 -> 729.23
A30: =YEAR(C30) -> 2021 | B30: =MONTH(C30) -> 1 | C30: 44211 | D30: 44211 | E30: INTERNET PAYMENT - THANK YOU | F30: -729.23 | G30: Payments and Credits | H30: =VLOOKUP(G30,Expense_Lookup,2,0) -> Payment | I30: =I29+F30 -> 0
A31: =YEAR(C31) -> 2021 | B31: =MONTH(C31) -> 1 | C31: 44211 | D31: 44211 | E31: MCDONALD'S F17579 RICHMOND VA | F31: 4.32 | G31: Family | H31: =VLOOKUP(G31,Expense_Lookup,2,0) -> Variable | I31: =I30+F31 -> 4.32 | J31: Jayelin | K31: MISC PAYMENTS
A32: =YEAR(C32) -> 2021 | B32: =MONTH(C32) -> 1 | C32: 44211 | D32: 44211 | E32: WALGREENS #3860 RICHMOND VA | F32: 21.19 | G32: Merchandise | H32: =VLOOKUP(G32,Expense_Lookup,2,0) -> Variable | I32: =I31+F32 -> 25.51 | J32: Draino | K32: MISC PAYMENTS
A33: =YEAR(C33) -> 2021 | B33: =MONTH(C33) -> 1 | C33: 44211 | D33: 44211 | E33: WALMART SC 07032 HENRICO VA | F33: 19.4 | G33: Merchandise | H33: =VLOOKUP(G33,Expense_Lookup,2,0) -> Variable | I33: =I32+F33 -> 44.91 | J33: Study | K33: PERSONAL
A34: =YEAR(C34) -> 2021 | B34: =MONTH(C34) -> 1 | C34: 44212 | D34: 44212 | E34: AMZN MKTP US*0H4DK7EL3 AMZN.COM/BILLWA72J9EGRQCDU | F34: 58.29 | G34: Merchandise | H34: =VLOOKUP(G34,Expense_Lookup,2,0) -> Variable | I34: =I33+F34 -> 103.2 | J34: Webcam | K34: PERSONAL
A35: =YEAR(C35) -> 2021 | B35: =MONTH(C35) -> 1 | C35: 44215 | D35: 44215 | E35: CHIPOTLE 1975 RICHMOND VA | F35: 8.23 | G35: Restaurants | H35: =VLOOKUP(G35,Expense_Lookup,2,0) -> Variable | I35: =I34+F35 -> 111.43 | K35: DAILY LIVING
A36: =YEAR(C36) -> 2021 | B36: =MONTH(C36) -> 1 | C36: 44215 | D36: 44215 | E36: CVS/PHARMACY #01988 RICHMOND VA | F36: 2.86 | G36: Family | H36: =VLOOKUP(G36,Expense_Lookup,2,0) -> Variable | I36: =I35+F36 -> 114.29 | J36: Jayelin | K36: MISC PAYMENTS
A37: =YEAR(C37) -> 2021 | B37: =MONTH(C37) -> 1 | C37: 44215 | D37: 44215 | E37: SP * ILF, LLC 8888044453 TX | F37: 99.9 | G37: Merchandise | H37: =VLOOKUP(G37,Expense_Lookup,2,0) -> Variable | I37: =I36+F37 -> 214.19 | K37: PERSONAL
A38: =YEAR(C38) -> 2021 | B38: =MONTH(C38) -> 1 | C38: 44216 | D38: 44216 | E38: THE MARKET @ 25TH RICHMOND VA | F38: 15.15 | G38: Supermarkets | H38: =VLOOKUP(G38,Expense_Lookup,2,0) -> Variable | I38: =I37+F38 -> 229.34 | K38: DAILY LIVING
A39: =YEAR(C39) -> 2021 | B39: =MONTH(C39) -> 1 | C39: 44217 | D39: 44217 | E39: KINGSISLE *PIRATE101 512-623-5983 TX00099RS900000000000000 | F39: 9.95 | G39: Family | H39: =VLOOKUP(G39,Expense_Lookup,2,0) -> Variable | I39: =I38+F39 -> 239.29 | J39: Jayelin | K39: MISC PAYMENTS
A40: =YEAR(C40) -> 2021 | B40: =MONTH(C40) -> 1 | C40: 44217 | D40: 44217 | E40: PP*PP ROKU FOR CRUNCHYR 402-935-7733 CA | F40: 7.99 | G40: APP | H40: =VLOOKUP(G40,Expense_Lookup,2,0) -> Fixed | I40: =I39+F40 -> 247.28 | J40: Crunchyroll | K40: SUBSCRIPTION
...

Sheet Sheet1
M1: 44533 | N1: 1962.31
J2: Vincent | K2: 742.18 | M2: 44547 | N2: 1962.31
J3: Best Buy | K3: 54.01 | M3: 44561 | N3: 1962.31
G4: Wells Fargo | H4: Discover | J4: Kim | K4: 140
G5: 1422.84 | H5: 2011.06
F6: Pay Best Buy | G6: =G5-K3 -> 1368.83
F7: Pay Vincent | G7: =G6-K2 -> 626.65
F8: Pay 15% of Discover | G8: =G7-I8 -> 324.991 | H8: =H5*0.85 -> 1709.401 | I8: =H5*0.15 -> 301.659
F9: Cashback Bonus | G9: =G8+44.4 -> 369.391
F14: -Fiscal Impact Analysis
F18: 725
F19: 1149
F20: =F19+F18 -> 1874

Sheet Subscriptions
A1: Name | B1: Sub Type | C1: Cancelled? | D1: Day | E1: Total Paid | F1: # | G1: Avg. Paid | H1: Jan | I1: Feb | J1: Mar | K1: Apr | L1: May | M1: June | N1: July | O1: Aug | P1: Sep | Q1: Oct | R1: Nov | S1: Dec
A2: {=_xlfn._xlws.SORT(_xlfn.UNIQUE(_xlfn.UNIQUE(_xlfn._xlws.FILTER(Discover!J:J, (Discover!G:G = "APP")*(Discover!J:J <>0)),1)))} -> Apple Music | B2: Monthly | C2: Yes | D2: {=AVERAGE(DAY(_xlfn.UNIQUE(_xlfn._xlws.FILTER(Discover!C:C, Discover!J:J = A2,0),1)))} -> 29 | E2: =SUMIFS(Discover!F:F,Discover!J:J,Subscriptions!A2) -> 21.18 | F2: =COUNTIFS(Discover!J:J,Subscriptions!A2,Discover!G:G,"APP") -> 2 | G2: =E2/F2 -> 10.59 | H2: =SUMIFS(Discover!$F:$F,Discover!$J:$J,Subscriptions!$A2,Discover!$B:$B,1) -> 0 | I2: =SUMIFS(Discover!$F:$F,Discover!$J:$J,Subscriptions!$A2,Discover!$B:$B,2) -> 0 | J2: =SUMIFS(Discover!$F:$F,Discover!$J:$J,Subscriptions!$A2,Discover!$B:$B,3) -> 0 | K2: =SUMIFS(Discover!$F:$F,Discover!$J:$J,Subscriptions!$A2,Discover!$B:$B,4) -> 0 | L2: =SUMIFS(Discover!$F:$F,Discover!$J:$J,Subscriptions!$A2,Discover!$B:$B,5) -> 0 | M2: =SUMIFS(Discover!$F:$F,Discover!$J:$J,Subscriptions!$A2,Discover!$B:$B,6) -> 0 | N2: =SUMIFS(Discover!$F:$F,Discover!$J:$J,Subscriptions!$A2,Discover!$B:$B,7) -> 0 | O2: =SUMIFS(Discover!$F:$F,Discover!$J:$J,Subscriptions!$A2,Discover!$B:$B,8) -> 10.59 | P2: =SUMIFS(Discover!$F:$F,Discover!$J:$J,Subscriptions!$A2,Discover!$B:$B,9) -> 10.59 | Q2: =SUMIFS(Discover!$F:$F,Discover!$J:$J,Subscriptions!$A2,Discover!$B:$B,10) -> 0 | R2: =SUMIFS(Discover!$F:$F,Discover!$J:$J,Subscriptions!$A2,Discover!$B:$B,11) -> 0 | S2: =SUMIFS(Discover!$F:$F,Discover!$J:$J,Subscriptions!$A2,Discover!$B:$B,12) -> 0
A3: Apple TV+ | B3: One time | C3: No | D3: {=AVERAGE(DAY(_xlfn.UNIQUE(_xlfn._xlws.FILTER(Discover!C:C, Discover!J:J = A3,0),1)))} -> 17 | E3: =SUMIFS(Discover!F:F,Discover!J:J,Subscriptions!A3) -> 10.58 | F3: =COUNTIFS(Discover!J:J,Subscriptions!A3,Discover!G:G,"APP") -> 2 | G3: =E3/F3 -> 5.29 | H3: =SUMIFS(Discover!$F:$F,Discover!$J:$J,Subscriptions!$A3,Discover!$B:$B,1) -> 0 | I3: =SUMIFS(Discover!$F:$F,Discover!$J:$J,Subscriptions!$A3,Discover!$B:$B,2) -> 0 | J3: =SUMIFS(Discover!$F:$F,Discover!$J:$J,Subscriptions!$A3,Discover!$B:$B,3) -> 0 | K3: =SUMIFS(Discover!$F:$F,Discover!$J:$J,Subscriptions!$A3,Discover!$B:$B,4) -> 0 | L3: =SUMIFS(Discover!$F:$F,Discover!$J:$J,Subscriptions!$A3,Discover!$B:$B,5) -> 0 | M3: =SUMIFS(Discover!$F:$F,Discover!$J:$J,Subscriptions!$A3,Discover!$B:$B,6) -> 0 | N3: =SUMIFS(Discover!$F:$F,Discover!$J:$J,Subscriptions!$A3,Discover!$B:$B,7) -> 0 | O3: =SUMIFS(Discover!$F:$F,Discover!$J:$J,Subscriptions!$A3,Discover!$B:$B,8) -> 0 | P3: =SUMIFS(Discover!$F:$F,Discover!$J:$J,Subscriptions!$A3,Discover!$B:$B,9) -> 5.29 | Q3: =SUMIFS(Discover!$F:$F,Discover!$J:$J,Subscriptions!$A3,Discover!$B:$B,10) -> 5.29 | R3: =SUMIFS(Discover!$F:$F,Discover!$J:$J,Subscriptions!$A3,Discover!$B:$B,11) -> 0 | S3: =SUMIFS(Discover!$F:$F,Discover!$J:$J,Subscriptions!$A3,Discover!$B:$B,12) -> 0
A4: Audible | B4: Monthly | C4: No | D4: {=AVERAGE(DAY(_xlfn.UNIQUE(_xlfn._xlws.FILTER(Discover!C:C, Discover!J:J = A4,0),1)))} -> 18.5 | E4: =SUMIFS(Discover!F:F,Discover!J:J,Subscriptions!A4) -> 65.2 | F4: =COUNTIFS(Discover!J:J,Subscriptions!A4,Discover!G:G,"APP") -> 4 | G4: =E4/F4 -> 16.3 | H4: =SUMIFS(Discover!$F:$F,Discover!$J:$J,Subscriptions!$A4,Discover!$B:$B,1) -> 0 | I4: =SUMIFS(Discover!$F:$F,Discover!$J:$J,Subscriptions!$A4,Discover!$B:$B,2) -> 0 | J4: =SUMIFS(Discover!$F:$F,Discover!$J:$J,Subscriptions!$A4,Discover!$B:$B,3) -> 0 | K4: =SUMIFS(Discover!$F:$F,Discover!$J:$J,Subscriptions!$A4,Discover!$B:$B,4) -> 0 | L4: =SUMIFS(Discover!$F:$F,Discover!$J:$J,Subscriptions!$A4,Discover!$B:$B,5) -> 0 | M4: =SUMIFS(Discover!$F:$F,Discover!$J:$J,Subscriptions!$A4,Discover!$B:$B,6) -> 0 | N4: =SUMIFS(Discover!$F:$F,Discover!$J:$J,Subscriptions!$A4,Discover!$B:$B,7) -> 0 | O4: =SUMIFS(Discover!$F:$F,Discover!$J:$J,Subscriptions!$A4,Discover!$B:$B,8) -> 56.52 | P4: =SUMIFS(Discover!$F:$F,Discover!$J:$J,Subscriptions!$A4,Discover!$B:$B,9) -> 8.68 | Q4: =SUMIFS(Discover!$F:$F,Discover!$J:$J,Subscriptions!$A4,Discover!$B:$B,10) -> 0 | R4: =SUMIFS(Discover!$F:$F,Discover!$J:$J,Subscriptions!$A4,Discover!$B:$B,11) -> 0 | S4: =SUMIFS(Discover!$F:$F,Discover!$J:$J,Subscriptions!$A4,Discover!$B:$B,12) -> 0
A5: Bloomberg | B5: Monthly | C5: Yes | D5: {=AVERAGE(DAY(_xlfn.UNIQUE(_xlfn._xlws.FILTER(Discover!C:C, Discover!J:J = A5,0),1)))} -> 31 | E5: =SUMIFS(Discover!F:F,Discover!J:J,Subscriptions!A5) -> 37.09 | F5: =COUNTIFS(Discover!J:J,Subscriptions!A5,Discover!G:G,"APP") -> 1 | G5: =E5/F5 -> 37.09 | H5: =SUMIFS(Discover!$F:$F,Discover!$J:$J,Subscriptions!$A5,Discover!$B:$B,1) -> 0 | I5: =SUMIFS(Discover!$F:$F,Discover!$J:$J,Subscriptions!$A5,Discover!$B:$B,2) -> 0 | J5: =SUMIFS(Discover!$F:$F,Discover!$J:$J,Subscriptions!$A5,Discover!$B:$B,3) -> 0 | K5: =SUMIFS(Discover!$F:$F,Discover!$J:$J,Subscriptions!$A5,Discover!$B:$B,4) -> 0 | L5: =SUMIFS(Discover!$F:$F,Discover!$J:$J,Subscriptions!$A5,Discover!$B:$B,5) -> 37.09 | M5: =SUMIFS(Discover!$F:$F,Discover!$J:$J,Subscriptions!$A5,Discover!$B:$B,6) -> 0 | N5: =SUMIFS(Discover!$F:$F,Discover!$J:$J,Subscriptions!$A5,Discover!$B:$B,7) -> 0 | O5: =SUMIFS(Discover!$F:$F,Discover!$J:$J,Subscriptions!$A5,Discover!$B:$B,8) -> 0 | P5: =SUMIFS(Discover!$F:$F,Discover!$J:$J,Subscriptions!$A5,Discover!$B:$B,9) -> 0 | Q5: =SUMIFS(Discover!$F:$F,Discover!$J:$J,Subscriptions!$A5,Discover!$B:$B,10) -> 0 | R5: =SUMIFS(Discover!$F:$F,Discover!$J:$J,Subscriptions!$A5,Discover!$B:$B,11) -> 0 | S5: =SUMIFS(Discover!$F:$F,Discover!$J:$J,Subscriptions!$A5,Discover!$B:$B,12) -> 0
A6: Bumble | B6: Monthly | C6: Yes | D6: {=AVERAGE(DAY(_xlfn.UNIQUE(_xlfn._xlws.FILTER(Discover!C:C, Discover!J:J = A6,0),1)))} -> 10 | E6: =SUMIFS(Discover!F:F,Discover!J:J,Subscriptions!A6) -> 84.59 | F6: =COUNTIFS(Discover!J:J,Subscriptions!A6,Discover!G:G,"APP") -> 3 | G6: =E6/F6 -> 28.196667 | H6: =SUMIFS(Discover!$F:$F,Discover!$J:$J,Subscriptions!$A6,Discover!$B:$B,1) -> 0 | I6: =SUMIFS(Discover!$F:$F,Discover!$J:$J,Subscriptions!$A6,Discover!$B:$B,2) -> 0 | J6: =SUMIFS(Discover!$F:$F,Discover!$J:$J,Subscriptions!$A6,Discover!$B:$B,3) -> 0 | K6: =SUMIFS(Discover!$F:$F,Discover!$J:$J,Subscriptions!$A6,Discover!$B:$B,4) -> 0 | L6: =SUMIFS(Discover!$F:$F,Discover!$J:$J,Subscriptions!$A6,Discover!$B:$B,5) -> 0 | M6: =SUMIFS(Discover!$F:$F,Discover!$J:$J,Subscriptions!$A6,Discover!$B:$B,6) -> 0 | N6: =SUMIFS(Discover!$F:$F,Discover!$J:$J,Subscriptions!$A6,Discover!$B:$B,7) -> 0 | O6: =SUMIFS(Discover!$F:$F,Discover!$J:$J,Subscriptions!$A6,Discover!$B:$B,8) -> 84.59 | P6: =SUMIFS(Discover!$F:$F,Discover!$J:$J,Subscriptions!$A6,Discover!$B:$B,9) -> 0 | Q6: =SUMIFS(Discover!$F:$F,Discover!$J:$J,Subscriptions!$A6,Discover!$B:$B,10) -> 0 | R6: =SUMIFS(Discover!$F:$F,Discover!$J:$J,Subscriptions!$A6,Discover!$B:$B,11) -> 0 | S6: =SUMIFS(Discover!$F:$F,Discover!$J:$J,Subscriptions!$A6,Discover!$B:$B,12) -> 0
A7: Catan Gold | B7: Monthly | C7: No | D7: {=AVERAGE(DAY(_xlfn.UNIQUE(_xlfn._xlws.FILTER(Discover!C:C, Discover!J:J = A7,0),1)))} -> 26 | E7: =SUMIFS(Discover!F:F,Discover!J:J,Subscriptions!A7) -> 14.99 | F7: =COUNTIFS(Discover!J:J,Subscriptions!A7,Discover!G:G,"APP") -> 1 | G7: =E7/F7 -> 14.99 | H7: =SUMIFS(Discover!$F:$F,Discover!$J:$J,Subscriptions!$A7,Discover!$B:$B,1) -> 0 | I7: =SUMIFS(Discover!$F:$F,Discover!$J:$J,Subscriptions!$A7,Discover!$B:$B,2) -> 0 | J7: =SUMIFS(Discover!$F:$F,Discover!$J:$J,Subscriptions!$A7,Discover!$B:$B,3) -> 14.99 | K7: =SUMIFS(Discover!$F:$F,Discover!$J:$J,Subscriptions!$A7,Discover!$B:$B,4) -> 0 | L7: =SUMIFS(Discover!$F:$F,Discover!$J:$J,Subscriptions!$A7,Discover!$B:$B,5) -> 0 | M7: =SUMIFS(Discover!$F:$F,Discover!$J:$J,Subscriptions!$A7,Discover!$B:$B,6) -> 0 | N7: =SUMIFS(Discover!$F:$F,Discover!$J:$J,Subscriptions!$A7,Discover!$B:$B,7) -> 0 | O7: =SUMIFS(Discover!$F:$F,Discover!$J:$J,Subscriptions!$A7,Discover!$B:$B,8) -> 0 | P7: =SUMIFS(Discover!$F:$F,Discover!$J:$J,Subscriptions!$A7,Discover!$B:$B,9) -> 0 | Q7: =SUMIFS(Discover!$F:$F,Discover!$J:$J,Subscriptions!$A7,Discover!$B:$B,10) -> 0 | R7: =SUMIFS(Discover!$F:$F,Discover!$J:$J,Subscriptions!$A7,Discover!$B:$B,11) -> 0 | S7: =SUMIFS(Discover!$F:$F,Discover!$J:$J,Subscriptions!$A7,Discover!$B:$B,12) -> 0
A8: Couple Cents | B8: Annual | C8: No | D8: {=AVERAGE(DAY(_xlfn.UNIQUE(_xlfn._xlws.FILTER(Discover!C:C, Discover!J:J = A8,0),1)))} -> 27 | E8: =SUMIFS(Discover!F:F,Discover!J:J,Subscriptions!A8) -> 79.92 | F8: =COUNTIFS(Discover!J:J,Subscriptions!A8,Discover!G:G,"APP") -> 7 | G8: =E8/F8 -> 11.417143 | H8: =SUMIFS(Discover!$F:$F,Discover!$J:$J,Subscriptions!$A8,Discover!$B:$B,1) -> 0 | I8: =SUMIFS(Discover!$F:$F,Discover!$J:$J,Subscriptions!$A8,Discover!$B:$B,2) -> 9.99 | J8: =SUMIFS(Discover!$F:$F,Discover!$J:$J,Subscriptions!$A8,Discover!$B:$B,3) -> 9.99 | K8: =SUMIFS(Discover!$F:$F,Discover!$J:$J,Subscriptions!$A8,Discover!$B:$B,4) -> 9.99 | L8: =SUMIFS(Discover!$F:$F,Discover!$J:$J,Subscriptions!$A8,Discover!$B:$B,5) -> 9.99 | M8: =SUMIFS(Discover!$F:$F,Discover!$J:$J,Subscriptions!$A8,Discover!$B:$B,6) -> 9.99 | N8: =SUMIFS(Discover!$F:$F,Discover!$J:$J,Subscriptions!$A8,Discover!$B:$B,7) -> 9.99 | O8: =SUMIFS(Discover!$F:$F,Discover!$J:$J,Subscriptions!$A8,Discover!$B:$B,8) -> 9.99 | P8: =SUMIFS(Discover!$F:$F,Discover!$J:$J,Subscriptions!$A8,Discover!$B:$B,9) -> 9.99 | Q8: =SUMIFS(Discover!$F:$F,Discover!$J:$J,Subscriptions!$A8,Discover!$B:$B,10) -> 0 | R8: =SUMIFS(Discover!$F:$F,Discover!$J:$J,Subscriptions!$A8,Discover!$B:$B,11) -> 0 | S8: =SUMIFS(Discover!$F:$F,Discover!$J:$J,Subscriptions!$A8,Discover!$B:$B,12) -> 0
A9: Credit Score | B9: Monthly | C9: Yes | D9: {=AVERAGE(DAY(_xlfn.UNIQUE(_xlfn._xlws.FILTER(Discover!C:C, Discover!J:J = A9,0),1)))} -> 5 | E9: =SUMIFS(Discover!F:F,Discover!J:J,Subscriptions!A9) -> 39.95 | F9: =COUNTIFS(Discover!J:J,Subscriptions!A9,Discover!G:G,"APP") -> 1 | G9: =E9/F9 -> 39.95 | H9: =SUMIFS(Discover!$F:$F,Discover!$J:$J,Subscriptions!$A9,Discover!$B:$B,1) -> 39.95 | I9: =SUMIFS(Discover!$F:$F,Discover!$J:$J,Subscriptions!$A9,Discover!$B:$B,2) -> 0 | J9: =SUMIFS(Discover!$F:$F,Discover!$J:$J,Subscriptions!$A9,Discover!$B:$B,3) -> 0 | K9: =SUMIFS(Discover!$F:$F,Discover!$J:$J,Subscriptions!$A9,Discover!$B:$B,4) -> 0 | L9: =SUMIFS(Discover!$F:$F,Discover!$J:$J,Subscriptions!$A9,Discover!$B:$B,5) -> 0 | M9: =SUMIFS(Discover!$F:$F,Discover!$J:$J,Subscriptions!$A9,Discover!$B:$B,6) -> 0 | N9: =SUMIFS(Discover!$F:$F,Discover!$J:$J,Subscriptions!$A9,Discover!$B:$B,7) -> 0 | O9: =SUMIFS(Discover!$F:$F,Discover!$J:$J,Subscriptions!$A9,Discover!$B:$B,8) -> 0 | P9: =SUMIFS(Discover!$F:$F,Discover!$J:$J,Subscriptions!$A9,Discover!$B:$B,9) -> 0 | Q9: =SUMIFS(Discover!$F:$F,Discover!$J:$J,Subscriptions!$A9,Discover!$B:$B,10) -> 0 | R9: =SUMIFS(Discover!$F:$F,Discover!$J:$J,Subscriptions!$A9,Discover!$B:$B,11) -> 0 | S9: =SUMIFS(Discover!$F:$F,Discover!$J:$J,Subscriptions!$A9,Discover!$B:$B,12) -> 0
A10: Crunch Fitness | B10: 6-Months | C10: No | D10: {=AVERAGE(DAY(_xlfn.UNIQUE(_xlfn._xlws.FILTER(Discover!C:C, Discover!J:J = A10,0),1)))} -> 28 | E10: =SUMIFS(Discover!F:F,Discover!J:J,Subscriptions!A10) -> 29.85 | F10: =COUNTIFS(Discover!J:J,Subscriptions!A10,Discover!G:G,"APP") -> 3 | G10: =E10/F10 -> 9.95 | H10: =SUMIFS(Discover!$F:$F,Discover!$J:$J,Subscriptions!$A10,Discover!$B:$B,1) -> 9.95 | I10: =SUMIFS(Discover!$F:$F,Discover!$J:$J,Subscriptions!$A10,Discover!$B:$B,2) -> 9.95 | J10: =SUMIFS(Discover!$F:$F,Discover!$J:$J,Subscriptions!$A10,Discover!$B:$B,3) -> 9.95 | K10: =SUMIFS(Discover!$F:$F,Discover!$J:$J,Subscriptions!$A10,Discover!$B:$B,4) -> 0 | L10: =SUMIFS(Discover!$F:$F,Discover!$J:$J,Subscriptions!$A10,Discover!$B:$B,5) -> 0 | M10: =SUMIFS(Discover!$F:$F,Discover!$J:$J,Subscriptions!$A10,Discover!$B:$B,6) -> 0 | N10: =SUMIFS(Discover!$F:$F,Discover!$J:$J,Subscriptions!$A10,Discover!$B:$B,7) -> 0 | O10: =SUMIFS(Discover!$F:$F,Discover!$J:$J,Subscriptions!$A10,Discover!$B:$B,8) -> 0 | P10: =SUMIFS(Discover!$F:$F,Discover!$J:$J,Subscriptions!$A10,Discover!$B:$B,9) -> 0 | Q10: =SUMIFS(Discover!$F:$F,Discover!$J:$J,Subscriptions!$A10,Discover!$B:$B,10) -> 0 | R10: =SUMIFS(Discover!$F:$F,Discover!$J:$J,Subscriptions!$A10,Discover!$B:$B,11) -> 0 | S10: =SUMIFS(Discover!$F:$F,Discover!$J:$J,Subscriptions!$A10,Discover!$B:$B,12) -> 0
A11: Crunchyroll | B11: 1 Year | C11: Yes | D11: {=AVERAGE(DAY(_xlfn.UNIQUE(_xlfn._xlws.FILTER(Discover!C:C, Discover!J:J = A11,0),1)))} -> 21.111111 | E11: =SUMIFS(Discover!F:F,Discover!J:J,Subscriptions!A11) -> 71.91 | F11: =COUNTIFS(Discover!J:J,Subscriptions!A11,Discover!G:G,"APP") -> 9 | G11: =E11/F11 -> 7.99 | H11: =SUMIFS(Discover!$F:$F,Discover!$J:$J,Subscriptions!$A11,Discover!$B:$B,1) -> 7.99 | I11: =SUMIFS(Discover!$F:$F,Discover!$J:$J,Subscriptions!$A11,Discover!$B:$B,2) -> 7.99 | J11: =SUMIFS(Discover!$F:$F,Discover!$J:$J,Subscriptions!$A11,Discover!$B:$B,3) -> 7.99 | K11: =SUMIFS(Discover!$F:$F,Discover!$J:$J,Subscriptions!$A11,Discover!$B:$B,4) -> 7.99 | L11: =SUMIFS(Discover!$F:$F,Discover!$J:$J,Subscriptions!$A11,Discover!$B:$B,5) -> 7.99 | M11: =SUMIFS(Discover!$F:$F,Discover!$J:$J,Subscriptions!$A11,Discover!$B:$B,6) -> 7.99 | N11: =SUMIFS(Discover!$F:$F,Discover!$J:$J,Subscriptions!$A11,Discover!$B:$B,7) -> 7.99 | O11: =SUMIFS(Discover!$F:$F,Discover!$J:$J,Subscriptions!$A11,Discover!$B:$B,8) -> 7.99 | P11: =SUMIFS(Discover!$F:$F,Discover!$J:$J,Subscriptions!$A11,Discover!$B:$B,9) -> 7.99 | Q11: =SUMIFS(Discover!$F:$F,Discover!$J:$J,Subscriptions!$A11,Discover!$B:$B,10) -> 0 | R11: =SUMIFS(Discover!$F:$F,Discover!$J:$J,Subscriptions!$A11,Discover!$B:$B,11) -> 0 | S11: =SUMIFS(Discover!$F:$F,Discover!$J:$J,Subscriptions!$A11,Discover!$B:$B,12) -> 0
A12: Disney | B12: 1 Month | C12: Yes | D12: {=AVERAGE(DAY(_xlfn.UNIQUE(_xlfn._xlws.FILTER(Discover!C:C, Discover!J:J = A12,0),1)))} -> 1 | E12: =SUMIFS(Discover!F:F,Discover!J:J,Subscriptions!A12) -> 69.99 | F12: =COUNTIFS(Discover!J:J,Subscriptions!A12,Discover!G:G,"APP") -> 1 | G12: =E12/F12 -> 69.99 | H12: =SUMIFS(Discover!$F:$F,Discover!$J:$J,Subscriptions!$A12,Discover!$B:$B,1) -> 0 | I12: =SUMIFS(Discover!$F:$F,Discover!$J:$J,Subscriptions!$A12,Discover!$B:$B,2) -> 0 | J12: =SUMIFS(Discover!$F:$F,Discover!$J:$J,Subscriptions!$A12,Discover!$B:$B,3) -> 69.99 | K12: =SUMIFS(Discover!$F:$F,Discover!$J:$J,Subscriptions!$A12,Discover!$B:$B,4) -> 0 | L12: =SUMIFS(Discover!$F:$F,Discover!$J:$J,Subscriptions!$A12,Discover!$B:$B,5) -> 0 | M12: =SUMIFS(Discover!$F:$F,Discover!$J:$J,Subscriptions!$A12,Discover!$B:$B,6) -> 0 | N12: =SUMIFS(Discover!$F:$F,Discover!$J:$J,Subscriptions!$A12,Discover!$B:$B,7) -> 0 | O12: =SUMIFS(Discover!$F:$F,Discover!$J:$J,Subscriptions!$A12,Discover!$B:$B,8) -> 0 | P12: =SUMIFS(Discover!$F:$F,Discover!$J:$J,Subscriptions!$A12,Discover!$B:$B,9) -> 0 | Q12: =SUMIFS(Discover!$F:$F,Discover!$J:$J,Subscriptions!$A12,Discover!$B:$B,10) -> 0 | R12: =SUMIFS(Discover!$F:$F,Discover!$J:$J,Subscriptions!$A12,Discover!$B:$B,11) -> 0 | S12: =SUMIFS(Discover!$F:$F,Discover!$J:$J,Subscriptions!$A12,Discover!$B:$B,12) -> 0
A13: Family Fitness | B13: Monthly | C13: No | D13: {=AVERAGE(DAY(_xlfn.UNIQUE(_xlfn._xlws.FILTER(Discover!C:C, Discover!J:J = A13,0),1)))} -> 6.2 | E13: =SUMIFS(Discover!F:F,Discover!J:J,Subscriptions!A13) -> 418.8 | F13: =COUNTIFS(Discover!J:J,Subscriptions!A13,Discover!G:G,"APP") -> 5 | G13: =E13/F13 -> 83.76 | H13: =SUMIFS(Discover!$F:$F,Discover!$J:$J,Subscriptions!$A13,Discover!$B:$B,1) -> 0 | I13: =SUMIFS(Discover!$F:$F,Discover!$J:$J,Subscriptions!$A13,Discover!$B:$B,2) -> 0 | J13: =SUMIFS(Discover!$F:$F,Discover!$J:$J,Subscriptions!$A13,Discover!$B:$B,3) -> 0 | K13: =SUMIFS(Discover!$F:$F,Discover!$J:$J,Subscriptions!$A13,Discover!$B:$B,4) -> 84.95 | L13: =SUMIFS(Discover!$F:$F,Discover!$J:$J,Subscriptions!$A13,Discover!$B:$B,5) -> 94.95 | M13: =SUMIFS(Discover!$F:$F,Discover!$J:$J,Subscriptions!$A13,Discover!$B:$B,6) -> 143.95 | N13: =SUMIFS(Discover!$F:$F,Discover!$J:$J,Subscriptions!$A13,Discover!$B:$B,7) -> 0 | O13: =SUMIFS(Discover!$F:$F,Discover!$J:$J,Subscriptions!$A13,Discover!$B:$B,8) -> 94.95 | P13: =SUMIFS(Discover!$F:$F,Discover!$J:$J,Subscriptions!$A13,Discover!$B:$B,9) -> 0 | Q13: =SUMIFS(Discover!$F:$F,Discover!$J:$J,Subscriptions!$A13,Discover!$B:$B,10) -> 0 | R13: =SUMIFS(Discover!$F:$F,Discover!$J:$J,Subscriptions!$A13,Discover!$B:$B,11) -> 0 | S13: =SUMIFS(Discover!$F:$F,Discover!$J:$J,Subscriptions!$A13,Discover!$B:$B,12) -> 0
A14: Final Fantasy | B14: Monthly | C14: No | D14: {=AVERAGE(DAY(_xlfn.UNIQUE(_xlfn._xlws.FILTER(Discover!C:C, Discover!J:J = A14,0),1)))} -> 9.5 | E14: =SUMIFS(Discover!F:F,Discover!J:J,Subscriptions!A14) -> 155.88 | F14: =COUNTIFS(Discover!J:J,Subscriptions!A14,Discover!G:G,"APP") -> 2 | G14: =E14/F14 -> 77.94 | H14: =SUMIFS(Discover!$F:$F,Discover!$J:$J,Subscriptions!$A14,Discover!$B:$B,1) -> 0 | I14: =SUMIFS(Discover!$F:$F,Discover!$J:$J,Subscriptions!$A14,Discover!$B:$B,2) -> 0 | J14: =SUMIFS(Discover!$F:$F,Discover!$J:$J,Subscriptions!$A14,Discover!$B:$B,3) -> 0 | K14: =SUMIFS(Discover!$F:$F,Discover!$J:$J,Subscriptions!$A14,Discover!$B:$B,4) -> 0 | L14: =SUMIFS(Discover!$F:$F,Discover!$J:$J,Subscriptions!$A14,Discover!$B:$B,5) -> 77.94 | M14: =SUMIFS(Discover!$F:$F,Discover!$J:$J,Subscriptions!$A14,Discover!$B:$B,6) -> 77.94 | N14: =SUMIFS(Discover!$F:$F,Discover!$J:$J,Subscriptions!$A14,Discover!$B:$B,7) -> 0 | O14: =SUMIFS(Discover!$F:$F,Discover!$J:$J,Subscriptions!$A14,Discover!$B:$B,8) -> 0 | P14: =SUMIFS(Discover!$F:$F,Discover!$J:$J,Subscriptions!$A14,Discover!$B:$B,9) -> 0 | Q14: =SUMIFS(Discover!$F:$F,Discover!$J:$J,Subscriptions!$A14,Discover!$B:$B,10) -> 0 | R14: =SUMIFS(Discover!$F:$F,Discover!$J:$J,Subscriptions!$A14,Discover!$B:$B,11) -> 0 | S14: =SUMIFS(Discover!$F:$F,Discover!$J:$J,Subscriptions!$A14,Discover!$B:$B,12) -> 0
A15: Finimize | E15: =SUMIFS(Discover!F:F,Discover!J:J,Subscriptions!A15) -> 79.99 | F15: =COUNTIFS(Discover!J:J,Subscriptions!A15,Discover!G:G,"APP") -> 1 | G15: =E15/F15 -> 79.99 | H15: =SUMIFS(Discover!$F:$F,Discover!$J:$J,Subscriptions!$A15,Discover!$B:$B,1) -> 0 | I15: =SUMIFS(Discover!$F:$F,Discover!$J:$J,Subscriptions!$A15,Discover!$B:$B,2) -> 0 | J15: =SUMIFS(Discover!$F:$F,Discover!$J:$J,Subscriptions!$A15,Discover!$B:$B,3) -> 79.99 | K15: =SUMIFS(Discover!$F:$F,Discover!$J:$J,Subscriptions!$A15,Discover!$B:$B,4) -> 0 | L15: =SUMIFS(Discover!$F:$F,Discover!$J:$J,Subscriptions!$A15,Discover!$B:$B,5) -> 0 | M15: =SUMIFS(Discover!$F:$F,Discover!$J:$J,Subscriptions!$A15,Discover!$B:$B,6) -> 0 | N15: =SUMIFS(Discover!$F:$F,Discover!$J:$J,Subscriptions!$A15,Discover!$B:$B,7) -> 0 | O15: =SUMIFS(Discover!$F:$F,Discover!$J:$J,Subscriptions!$A15,Discover!$B:$B,8) -> 0 | P15: =SUMIFS(Discover!$F:$F,Discover!$J:$J,Subscriptions!$A15,Discover!$B:$B,9) -> 0 | Q15: =SUMIFS(Discover!$F:$F,Discover!$J:$J,Subscriptions!$A15,Discover!$B:$B,10) -> 0 | R15: =SUMIFS(Discover!$F:$F,Discover!$J:$J,Subscriptions!$A15,Discover!$B:$B,11) -> 0 | S15: =SUMIFS(Discover!$F:$F,Discover!$J:$J,Subscriptions!$A15,Discover!$B:$B,12) -> 0
A16: fraud | B16: Monthly | C16: No | D16: {=AVERAGE(DAY(_xlfn.UNIQUE(_xlfn._xlws.FILTER(Discover!C:C, Discover!J:J = A16,0),1)))} -> 14 | E16: =SUMIFS(Discover!F:F,Discover!J:J,Subscriptions!A16) -> 3.99 | F16: =COUNTIFS(Discover!J:J,Subscriptions!A16,Discover!G:G,"APP") -> 1 | G16: =E16/F16 -> 3.99 | H16: =SUMIFS(Discover!$F:$F,Discover!$J:$J,Subscriptions!$A16,Discover!$B:$B,1) -> 0 | I16: =SUMIFS(Discover!$F:$F,Discover!$J:$J,Subscriptions!$A16,Discover!$B:$B,2) -> 0 | J16: =SUMIFS(Discover!$F:$F,Discover!$J:$J,Subscriptions!$A16,Discover!$B:$B,3) -> 0 | K16: =SUMIFS(Discover!$F:$F,Discover!$J:$J,Subscriptions!$A16,Discover!$B:$B,4) -> 0 | L16: =SUMIFS(Discover!$F:$F,Discover!$J:$J,Subscriptions!$A16,Discover!$B:$B,5) -> 0 | M16: =SUMIFS(Discover!$F:$F,Discover!$J:$J,Subscriptions!$A16,Discover!$B:$B,6) -> 0 | N16: =SUMIFS(Discover!$F:$F,Discover!$J:$J,Subscriptions!$A16,Discover!$B:$B,7) -> 0 | O16: =SUMIFS(Discover!$F:$F,Discover!$J:$J,Subscriptions!$A16,Discover!$B:$B,8) -> 3.99 | P16: =SUMIFS(Discover!$F:$F,Discover!$J:$J,Subscriptions!$A16,Discover!$B:$B,9) -> 0 | Q16: =SUMIFS(Discover!$F:$F,Discover!$J:$J,Subscriptions!$A16,Discover!$B:$B,10) -> 0 | R16: =SUMIFS(Discover!$F:$F,Discover!$J:$J,Subscriptions!$A16,Discover!$B:$B,11) -> 0 | S16: =SUMIFS(Discover!$F:$F,Discover!$J:$J,Subscriptions!$A16,Discover!$B:$B,12) -> 0
A17: Funimation | B17: Monthly | C17: No | D17: {=AVERAGE(DAY(_xlfn.UNIQUE(_xlfn._xlws.FILTER(Discover!C:C, Discover!J:J = A17,0),1)))} -> 18 | E17: =SUMIFS(Discover!F:F,Discover!J:J,Subscriptions!A17) -> 8.47 | F17: =COUNTIFS(Discover!J:J,Subscriptions!A17,Discover!G:G,"APP") -> 1 | G17: =E17/F17 -> 8.47 | H17: =SUMIFS(Discover!$F:$F,Discover!$J:$J,Subscriptions!$A17,Discover!$B:$B,1) -> 0 | I17: =SUMIFS(Discover!$F:$F,Discover!$J:$J,Subscriptions!$A17,Discover!$B:$B,2) -> 0 | J17: =SUMIFS(Discover!$F:$F,Discover!$J:$J,Subscriptions!$A17,Discover!$B:$B,3) -> 0 | K17: =SUMIFS(Discover!$F:$F,Discover!$J:$J,Subscriptions!$A17,Discover!$B:$B,4) -> 0 | L17: =SUMIFS(Discover!$F:$F,Discover!$J:$J,Subscriptions!$A17,Discover!$B:$B,5) -> 0 | M17: =SUMIFS(Discover!$F:$F,Discover!$J:$J,Subscriptions!$A17,Discover!$B:$B,6) -> 0 | N17: =SUMIFS(Discover!$F:$F,Discover!$J:$J,Subscriptions!$A17,Discover!$B:$B,7) -> 0 | O17: =SUMIFS(Discover!$F:$F,Discover!$J:$J,Subscriptions!$A17,Discover!$B:$B,8) -> 8.47 | P17: =SUMIFS(Discover!$F:$F,Discover!$J:$J,Subscriptions!$A17,Discover!$B:$B,9) -> 0 | Q17: =SUMIFS(Discover!$F:$F,Discover!$J:$J,Subscriptions!$A17,Discover!$B:$B,10) -> 0 | R17: =SUMIFS(Discover!$F:$F,Discover!$J:$J,Subscriptions!$A17,Discover!$B:$B,11) -> 0 | S17: =SUMIFS(Discover!$F:$F,Discover!$J:$J,Subscriptions!$A17,Discover!$B:$B,12) -> 0
A18: GuitarTuna | B18: Monthly | C18: No | D18: {=AVERAGE(DAY(_xlfn.UNIQUE(_xlfn._xlws.FILTER(Discover!C:C, Discover!J:J = A18,0),1)))} -> 25 | E18: =SUMIFS(Discover!F:F,Discover!J:J,Subscriptions!A18) -> 5.29 | F18: =COUNTIFS(Discover!J:J,Subscriptions!A18,Discover!G:G,"APP") -> 1 | G18: =E18/F18 -> 5.29 | H18: =SUMIFS(Discover!$F:$F,Discover!$J:$J,Subscriptions!$A18,Discover!$B:$B,1) -> 0 | I18: =SUMIFS(Discover!$F:$F,Discover!$J:$J,Subscriptions!$A18,Discover!$B:$B,2) -> 0 | J18: =SUMIFS(Discover!$F:$F,Discover!$J:$J,Subscriptions!$A18,Discover!$B:$B,3) -> 0 | K18: =SUMIFS(Discover!$F:$F,Discover!$J:$J,Subscriptions!$A18,Discover!$B:$B,4) -> 0 | L18: =SUMIFS(Discover!$F:$F,Discover!$J:$J,Subscriptions!$A18,Discover!$B:$B,5) -> 5.29 | M18: =SUMIFS(Discover!$F:$F,Discover!$J:$J,Subscriptions!$A18,Discover!$B:$B,6) -> 0 | N18: =SUMIFS(Discover!$F:$F,Discover!$J:$J,Subscriptions!$A18,Discover!$B:$B,7) -> 0 | O18: =SUMIFS(Discover!$F:$F,Discover!$J:$J,Subscriptions!$A18,Discover!$B:$B,8) -> 0 | P18: =SUMIFS(Discover!$F:$F,Discover!$J:$J,Subscriptions!$A18,Discover!$B:$B,9) -> 0 | Q18: =SUMIFS(Discover!$F:$F,Discover!$J:$J,Subscriptions!$A18,Discover!$B:$B,10) -> 0 | R18: =SUMIFS(Discover!$F:$F,Discover!$J:$J,Subscriptions!$A18,Discover!$B:$B,11) -> 0 | S18: =SUMIFS(Discover!$F:$F,Discover!$J:$J,Subscriptions!$A18,Discover!$B:$B,12) -> 0
A19: HBO | B19: Annual | C19: Yes | D19: {=AVERAGE(DAY(_xlfn.UNIQUE(_xlfn._xlws.FILTER(Discover!C:C, Discover!J:J = A19,0),1)))} -> 11.7 | E19: =SUMIFS(Discover!F:F,Discover!J:J,Subscriptions!A19) -> 156.11 | F19: =COUNTIFS(Discover!J:J,Subscriptions!A19,Discover!G:G,"APP") -> 10 | G19: =E19/F19 -> 15.611 | H19: =SUMIFS(Discover!$F:$F,Discover!$J:$J,Subscriptions!$A19,Discover!$B:$B,1) -> 14.99 | I19: =SUMIFS(Discover!$F:$F,Discover!$J:$J,Subscriptions!$A19,Discover!$B:$B,2) -> 14.99 | J19: =SUMIFS(Discover!$F:$F,Discover!$J:$J,Subscriptions!$A19,Discover!$B:$B,3) -> 14.99 | K19: =SUMIFS(Discover!$F:$F,Discover!$J:$J,Subscriptions!$A19,Discover!$B:$B,4) -> 15.89 | L19: =SUMIFS(Discover!$F:$F,Discover!$J:$J,Subscriptions!$A19,Discover!$B:$B,5) -> 15.89 | M19: =SUMIFS(Discover!$F:$F,Discover!$J:$J,Subscriptions!$A19,Discover!$B:$B,6) -> 15.89 | N19: =SUMIFS(Discover!$F:$F,Discover!$J:$J,Subscriptions!$A19,Discover!$B:$B,7) -> 15.89 | O19: =SUMIFS(Discover!$F:$F,Discover!$J:$J,Subscriptions!$A19,Discover!$B:$B,8) -> 16.01 | P19: =SUMIFS(Discover!$F:$F,Discover!$J:$J,Subscriptions!$A19,Discover!$B:$B,9) -> 15.68 | Q19: =SUMIFS(Discover!$F:$F,Discover!$J:$J,Subscriptions!$A19,Discover!$B:$B,10) -> 15.89 | R19: =SUMIFS(Discover!$F:$F,Discover!$J:$J,Subscriptions!$A19,Discover!$B:$B,11) -> 0 | S19: =SUMIFS(Discover!$F:$F,Discover!$J:$J,Subscriptions!$A19,Discover!$B:$B,12) -> 0
A20: Hulu | B20: Monthly | C20: No | D20: {=AVERAGE(DAY(_xlfn.UNIQUE(_xlfn._xlws.FILTER(Discover!C:C, Discover!J:J = A20,0),1)))} -> 3 | E20: =SUMIFS(Discover!F:F,Discover!J:J,Subscriptions!A20) -> 68.33 | F20: =COUNTIFS(Discover!J:J,Subscriptions!A20,Discover!G:G,"APP") -> 8 | G20: =E20/F20 -> 8.54125 | H20: =SUMIFS(Discover!$F:$F,Discover!$J:$J,Subscriptions!$A20,Discover!$B:$B,1) -> 0 | I20: =SUMIFS(Discover!$F:$F,Discover!$J:$J,Subscriptions!$A20,Discover!$B:$B,2) -> 0 | J20: =SUMIFS(Discover!$F:$F,Discover!$J:$J,Subscriptions!$A20,Discover!$B:$B,3) -> 0 | K20: =SUMIFS(Discover!$F:$F,Discover!$J:$J,Subscriptions!$A20,Discover!$B:$B,4) -> 0.99 | L20: =SUMIFS(Discover!$F:$F,Discover!$J:$J,Subscriptions!$A20,Discover!$B:$B,5) -> 5.99 | M20: =SUMIFS(Discover!$F:$F,Discover!$J:$J,Subscriptions!$A20,Discover!$B:$B,6) -> 0.4 | N20: =SUMIFS(Discover!$F:$F,Discover!$J:$J,Subscriptions!$A20,Discover!$B:$B,7) -> 11.99 | O20: =SUMIFS(Discover!$F:$F,Discover!$J:$J,Subscriptions!$A20,Discover!$B:$B,8) -> 11.99 | P20: =SUMIFS(Discover!$F:$F,Discover!$J:$J,Subscriptions!$A20,Discover!$B:$B,9) -> 11.99 | Q20: =SUMIFS(Discover!$F:$F,Discover!$J:$J,Subscriptions!$A20,Discover!$B:$B,10) -> 11.99 | R20: =SUMIFS(Discover!$F:$F,Discover!$J:$J,Subscriptions!$A20,Discover!$B:$B,11) -> 12.99 | S20: =SUMIFS(Discover!$F:$F,Discover!$J:$J,Subscriptions!$A20,Discover!$B:$B,12) -> 0
A21: Internet | B21: Monthly | C21: No | D21: {=AVERAGE(DAY(_xlfn.UNIQUE(_xlfn._xlws.FILTER(Discover!C:C, Discover!J:J = A21,0),1)))} -> 16 | E21: =SUMIFS(Discover!F:F,Discover!J:J,Subscriptions!A21) -> 50 | F21: =COUNTIFS(Discover!J:J,Subscriptions!A21,Discover!G:G,"APP") -> 1 | G21: =E21/F21 -> 50 | H21: =SUMIFS(Discover!$F:$F,Discover!$J:$J,Subscriptions!$A21,Discover!$B:$B,1) -> 0 | I21: =SUMIFS(Discover!$F:$F,Discover!$J:$J,Subscriptions!$A21,Discover!$B:$B,2) -> 0 | J21: =SUMIFS(Discover!$F:$F,Discover!$J:$J,Subscriptions!$A21,Discover!$B:$B,3) -> 0 | K21: =SUMIFS(Discover!$F:$F,Discover!$J:$J,Subscriptions!$A21,Discover!$B:$B,4) -> 0 | L21: =SUMIFS(Discover!$F:$F,Discover!$J:$J,Subscriptions!$A21,Discover!$B:$B,5) -> 0 | M21: =SUMIFS(Discover!$F:$F,Discover!$J:$J,Subscriptions!$A21,Discover!$B:$B,6) -> 0 | N21: =SUMIFS(Discover!$F:$F,Discover!$J:$J,Subscriptions!$A21,Discover!$B:$B,7) -> 50 | O21: =SUMIFS(Discover!$F:$F,Discover!$J:$J,Subscriptions!$A21,Discover!$B:$B,8) -> 0 | P21: =SUMIFS(Discover!$F:$F,Discover!$J:$J,Subscriptions!$A21,Discover!$B:$B,9) -> 0 | Q21: =SUMIFS(Discover!$F:$F,Discover!$J:$J,Subscriptions!$A21,Discover!$B:$B,10) -> 0 | R21: =SUMIFS(Discover!$F:$F,Discover!$J:$J,Subscriptions!$A21,Discover!$B:$B,11) -> 0 | S21: =SUMIFS(Discover!$F:$F,Discover!$J:$J,Subscriptions!$A21,Discover!$B:$B,12) -> 0
A22: Lifetime Gym | B22: Monthly | C22: Yes | D22: {=AVERAGE(DAY(_xlfn.UNIQUE(_xlfn._xlws.FILTER(Discover!C:C, Discover!J:J = A22,0),1)))} -> 25 | E22: =SUMIFS(Discover!F:F,Discover!J:J,Subscriptions!A22) -> 16.15 | F22: =COUNTIFS(Discover!J:J,Subscriptions!A22,Discover!G:G,"APP") -> 1 | G22: =E22/F22 -> 16.15 | H22: =SUMIFS(Discover!$F:$F,Discover!$J:$J,Subscriptions!$A22,Discover!$B:$B,1) -> 0 | I22: =SUMIFS(Discover!$F:$F,Discover!$J:$J,Subscriptions!$A22,Discover!$B:$B,2) -> 0 | J22: =SUMIFS(Discover!$F:$F,Discover!$J:$J,Subscriptions!$A22,Discover!$B:$B,3) -> 0 | K22: =SUMIFS(Discover!$F:$F,Discover!$J:$J,Subscriptions!$A22,Discover!$B:$B,4) -> 0 | L22: =SUMIFS(Discover!$F:$F,Discover!$J:$J,Subscriptions!$A22,Discover!$B:$B,5) -> 0 | M22: =SUMIFS(Discover!$F:$F,Discover!$J:$J,Subscriptions!$A22,Discover!$B:$B,6) -> 0 | N22: =SUMIFS(Discover!$F:$F,Discover!$J:$J,Subscriptions!$A22,Discover!$B:$B,7) -> 0 | O22: =SUMIFS(Discover!$F:$F,Discover!$J:$J,Subscriptions!$A22,Discover!$B:$B,8) -> 0 | P22: =SUMIFS(Discover!$F:$F,Discover!$J:$J,Subscriptions!$A22,Discover!$B:$B,9) -> 0 | Q22: =SUMIFS(Discover!$F:$F,Discover!$J:$J,Subscriptions!$A22,Discover!$B:$B,10) -> 16.15 | R22: =SUMIFS(Discover!$F:$F,Discover!$J:$J,Subscriptions!$A22,Discover!$B:$B,11) -> 0 | S22: =SUMIFS(Discover!$F:$F,Discover!$J:$J,Subscriptions!$A22,Discover!$B:$B,12) -> 0
