Workbook
Name allowance: #REF!
Name AprSun1: DATE(CalendarYear,4,1)-WEEKDAY(DATE(CalendarYear,4,1))
Name AugSun1: DATE(CalendarYear,8,1)-WEEKDAY(DATE(CalendarYear,8,1))
Name budget: '[1]Pivot (2021)'!$A$2
Name Budget: #REF!
Name CalendarYear: [0]!Year1
Name Categories: [2]!TableAssetAllocation[Category]
Name DecSun1: DATE(CalendarYear,12,1)-WEEKDAY(DATE(CalendarYear,12,1))
Name Expense_Lookup: Discover!$P:$Q
Name FebSun1: DATE(CalendarYear,2,1)-WEEKDAY(DATE(CalendarYear,2,1))
Name fixed: #REF!
Name income: #REF!
Name JanSun1: DATE(CalendarYear,1,1)-WEEKDAY(DATE(CalendarYear,1,1))
Name JulSun1: DATE(CalendarYear,7,1)-WEEKDAY(DATE(CalendarYear,7,1))
Name JunSun1: DATE(CalendarYear,6,1)-WEEKDAY(DATE(CalendarYear,6,1))
Name MarSun1: DATE(CalendarYear,3,1)-WEEKDAY(DATE(CalendarYear,3,1))
Name MaySun1: DATE(CalendarYear,5,1)-WEEKDAY(DATE(CalendarYear,5,1))
Name NovSun1: DATE(CalendarYear,11,1)-WEEKDAY(DATE(CalendarYear,11,1))
Name OctSun1: DATE(CalendarYear,10,1)-WEEKDAY(DATE(CalendarYear,10,1))
Name Robinhood: #REF!
Name SepSun1: DATE(CalendarYear,9,1)-WEEKDAY(DATE(CalendarYear,9,1))
Name StartMonth: #REF!
Name Tail_Rent: '[1]2021 Income'!#REF!
Name Title2: #REF!
Name valdate: #REF!
Name Year1: VALUE(LEFT(#REF!,4))

Sheet Wells Fargo
A1: Month | B1: Day | C1: Date | D1: Description2 | E1: Description | F1: Amount | G1: Primary
A2: =MONTH(C2) -> 1 | B2: =DAY(C2) -> 4 | C2: 44200 | D2: DISCOVER | E2: DISCOVER E-PAYMENT 210101 4732 LEWIS SEAN | F2: -700 | G2: Credit
A3: =MONTH(C3) -> 1 | B3: =DAY(C3) -> 4 | C3: 44200 | D3: IRS | E3: IRS TREAS 310 XXTAXEIP2 010421 XXXXXXXXXX00908 LEWIS, SEAN | F3: 600 | G3: Stimulus 1
A4: =MONTH(C4) -> 1 | B4: =DAY(C4) -> 15 | C4: 44211 | D4: DISCOVER | E4: DISCOVER E-PAYMENT 210115 4732 LEWIS SEAN | F4: -729.23 | G4: Credit
A5: =MONTH(C5) -> 1 | B5: =DAY(C5) -> 15 | C5: 44211 | D5: Elephant | E5: Elephant Ins PAYROLL 210113 2087 Lewis Sean | F5: 1459.65 | G5: Elephant
A6: =MONTH(C6) -> 1 | B6: =DAY(C6) -> 19 | C6: 44215 | D6: VENMO | E6: VENMO PAYMENT 5101219782 SEAN LEWIS | F6: -569.12 | G6: Vincent
A7: =MONTH(C7) -> 1 | B7: =DAY(C7) -> 19 | C7: 44215 | D7: VENMO | E7: VENMO PAYMENT 5101208453 SEAN LEWIS | F7: -78.86 | G7: Amar - Electric
A8: =MONTH(C8) -> 1 | B8: =DAY(C8) -> 19 | C8: 44215 | D8: VENMO | E8: VENMO CASHOUT 5117912825 SEAN LEWIS | F8: 150 | G8: Venmo Cash Out
A9: =MONTH(C9) -> 1 | B9: =DAY(C9) -> 21 | C9: 44217 | D9: PURCHASE | E9: PURCHASE AUTHORIZED ON 01/20 CASH APP* 8774174551 CA S461020486646597 CARD 6634 | F9: -155 | G9: Cairo
A10: =MONTH(C10) -> 1 | B10: =DAY(C10) -> 22 | C10: 44218 | D10: PURCHASE | E10: PURCHASE AUTHORIZED ON 01/21 SOCIETY OF ACTUARI 847-706-3620 IL S581021446560343 CARD 6634 | F10: -75 | G10: SOA
A11: =MONTH(C11) -> 1 | B11: =DAY(C11) -> 26 | C11: 44222 | D11: MONEY | E11: MONEY TRANSFER AUTHORIZED ON 01/26 FROM Sean Lewis VA S00581026542833832 CARD 6634 | F11: 155 | G11: Cairo
A12: =MONTH(C12) -> 1 | B12: =DAY(C12) -> 28 | C12: 44224 | D12: ROBINHOOD | E12: ROBINHOOD Funds 210127 XXXXX4480 Sean Lewis | F12: -100 | G12: Investment
A13: =MONTH(C13) -> 1 | B13: =DAY(C13) -> 28 | C13: 44224 | D13: ROBINHOOD | E13: ROBINHOOD Funds 210127 XXXXX4480 Sean Lewis | F13: -50 | G13: Investment
... A127: =MONTH(C127) -> 6 | B127: =DAY(C127) -> 17 | C127: 44364 | D127: Nationwide | E127: Nationwide PAYROLL 01 HRP0007397914 Sean Lewis | F127: 4436.57 | G127: Nationwide
A128: =MONTH(C128) -> 6 | B128: =DAY(C128) -> 18 | C128: 44365 | D128: =LEFT(E128, FIND(" ",E128)-1) -> PRINCIPAL | E128: PRINCIPAL TRUST DR CR 210617 PACT#179541394 SEAN LEWIS | F128: 3967.1 | G128: Principal retirement
A129: =MONTH(C129) -> 6 | B129: =DAY(C129) -> 18 | C129: 44365 | D129: =LEFT(E129, FIND(" ",E129)-1) -> Elephant | E129: Elephant Ins PAYROLL 210616 2087 Lewis Sean | F129: 680.02 | G129: Elephant
A130: =MONTH(C130) -> 6 | B130: =DAY(C130) -> 21 | C130: 44368 | D130: =LEFT(E130, FIND(" ",E130)-1) -> VENMO | E130: VENMO PAYMENT 210620 1014291472980 SEAN LEWIS | F130: -2738.5 | G130: Matt Bozz
A131: =MONTH(C131) -> 6 | B131: =DAY(C131) -> 21 | C131: 44368 | D131: =LEFT(E131, FIND(" ",E131)-1) -> VENMO | E131: VENMO PAYMENT 210620 1014291497592 SEAN LEWIS | F131: -615 | G131: Anush Rohani Shukla
A132: =MONTH(C132) -> 6 | B132: =DAY(C132) -> 23 | C132: 44370 | D132: =LEFT(E132, FIND(" ",E132)-1) -> DISCOVER | E132: DISCOVER E-PAYMENT 210623 7328 LEWIS SEAN | F132: -1869 | G132: Credit
A133: =MONTH(C133) -> 6 | B133: =DAY(C133) -> 23 | C133: 44370 | D133: =LEFT(E133, FIND(" ",E133)-1) -> PURCHASE | E133: PURCHASE AUTHORIZED ON 06/22 STITCH FIX STYLIN 844-386-3850 CA S581173332274659 CARD 6634 | F133: -20 | G133: Headshot
A134: =MONTH(C134) -> 6 | B134: =DAY(C134) -> 23 | C134: 44370 | D134: =LEFT(E134, FIND(" ",E134)-1) -> PRINCIPAL | E134: PRINCIPAL TRUST DR CR 210622 PACT#180033360 Sean Lewis | F134: 198.46 | G134: Principal retirement
A135: =MONTH(C135) -> 6 | B135: =DAY(C135) -> 25 | C135: 44372 | D135: =LEFT(E135, FIND(" ",E135)-1) -> PURCHASE | E135: PURCHASE AUTHORIZED ON 06/23 TST* TIO PABLO TAQ RICHMOND VA S461175013934521 CARD 6634 | F135: -58.57 | G135: Resteraunt
A136: =MONTH(C136) -> 6 | B136: =DAY(C136) -> 30 | C136: 44377 | D136: =LEFT(E136, FIND(" ",E136)-1) -> New | E136: New Manchester F WEB PMTS 063021 M7CVM7 Sean Lewis | F136: -1804.34 | G136: New Manchester - Rent
A137: =MONTH(C137) -> 7 | B137: =DAY(C137) -> 1 | C137: 44378 | D137: =LEFT(E137, FIND(" ",E137)-1) -> DISCOVER | E137: DISCOVER E-PAYMENT 210701 7328 LEWIS SEAN | F137: -871.96 | G137: Credit
A138: =MONTH(C138) -> 7 | B138: =DAY(C138) -> 1 | C138: 44378 | D138: =LEFT(E138, FIND(" ",E138)-1) -> Nationwide | E138: Nationwide PAYROLL 01 HRP0007447918 Sean Lewis | F138: 1583.62 | G138: Nationwide
A139: =MONTH(C139) -> 7 | B139: =DAY(C139) -> 6 | C139: 44383 | D139: =LEFT(E139, FIND(" ",E139)-1) -> DISCOVER | E139: DISCOVER E-PAYMENT 210705 7328 LEWIS SEAN | F139: -367.73 | G139: Credit
... A147: =MONTH(C147) -> 7 | B147: =DAY(C147) -> 7 | C147: 44384 | D147: =LEFT(E147, FIND(" ",E147)-1) -> PURCHASE | E147: PURCHASE AUTHORIZED ON 07/06 PHO QUE HUONG NUMB GLEN ALLEN VA S381187824546148 CARD 6634 | F147: -30 | G147: Resteraunt

Sheet Discover
A1: Year | B1: Month | C1: Trans. date | D1: Post date | F1: Description | G1: Amount | H1: Category | I1: Expense Type | J1: Cumulative | K1: Association
A2: =YEAR(C2) -> 2021 | B2: =MONTH(C2) -> 1 | C2: 44197 | D2: 44197 | E2: =LEFT(F2,5) -> INTER | F2: INTERNET PAYMENT - THANK YOU | G2: -700 | H2: Payments and Credits | I2: =VLOOKUP(H2,Expense_Lookup,2,0) -> Payment | J2: 728.15
A3: =YEAR(C3) -> 2021 | B3: =MONTH(C3) -> 1 | C3: 44197 | D3: 44199 | E3: =LEFT(F3,5) -> NETFL | F3: NETFLIX.COM NETFLIX.COM CA44115296471 | G3: 13.99 | H3: APP | I3: =VLOOKUP(H3,Expense_Lookup,2,0) -> Fixed | J3: =J2+G3 -> 742.14 | K3: Netflix
A4: =YEAR(C4) -> 2021 | B4: =MONTH(C4) -> 1 | C4: 44197 | D4: 44199 | E4: =LEFT(F4,5) -> SPOTI | F4: SPOTIFY P12D96D434 8777781161 NY | G4: 9.99 | H4: APP | I4: =VLOOKUP(H4,Expense_Lookup,2,0) -> Fixed | J4: =J3+G4 -> 752.13 | K4: Spotify | M4: Variable | N4: =SUMIFS(G:G,I:I,M4) -> 12045.17 | R4: Jan | S4: Feb | T4: Mar | U4: Apr | V4: May | W4: June | X4: July | Y4: Aug | Z4: Sep | AA4: Oct | AB4: Nov | AC4: Dec
A5: =YEAR(C5) -> 2021 | B5: =MONTH(C5) -> 1 | C5: 44197 | D5: 44199 | E5: =LEFT(F5,5) -> WAWA | F5: WAWA 697 STAFFORD VA | G5: 18.87 | H5: Gasoline | I5: =VLOOKUP(H5,Expense_Lookup,2,0) -> Variable | J5: =J4+G5 -> 771 | M5: Fixed | N5: =SUMIFS(G:G,I:I,M5) -> 3270.22 | P5: {=_xlfn.UNIQUE(_xlfn._xlws.FILTER(H:H,(H:H<>0) ))} -> Category
A6: =YEAR(C6) -> 2021 | B6: =MONTH(C6) -> 1 | C6: 44201 | D6: 44201 | E6: =LEFT(F6,5) -> MYFIC | F6: MYFICO COM 8003194433 GA | G6: 39.95 | H6: APP | I6: =VLOOKUP(H6,Expense_Lookup,2,0) -> Fixed | J6: =J5+G6 -> 810.95 | K6: Credit Score | N6: =SUM(N4:N5) -> 15315.39 | P6: Payments and Credits | Q6: Payment | R6: =SUMIFS(G:G,H:H,P6,$B:$B,1) -> -2157.38 | S6: =SUMIFS(G:G,H:H,P6,$B:$B,2) -> -2256.47 | T6: =SUMIFS(G:G,H:H,P6,$B:$B,3) -> -2413.62 | U6: =SUMIFS($G:$G,$H:$H,$P6,$B:$B,4) -> -471.07 | V6: =SUMIFS($G:$G,$H:$H,$P6,$B:$B,5) -> -2855.16 | W6: =SUMIFS($G:$G,$H:$H,$P6,$B:$B,6) -> -3297.83 | X6: =SUMIFS($G:$G,$H:$H,$P6,$B:$B,7) -> -3414.44
A7: =YEAR(C7) -> 2021 | B7: =MONTH(C7) -> 1 | C7: 44201 | D7: 44201 | E7: =LEFT(F7,5) -> STATE | F7: STATE FARM INSURANCE 800-956-6310 IL | G7: 91.78 | H7: APP | I7: =VLOOKUP(H7,Expense_Lookup,2,0) -> Fixed | J7: =J6+G7 -> 902.73 | K7: State Farm | M7: Family | P7: APP | Q7: Fixed | R7: =SUMIFS(G:G,H:H,P7,$B:$B,1) -> 225.53 | S7: =SUMIFS(G:G,H:H,P7,$B:$B,2) -> 260.85 | T7: =SUMIFS(G:G,H:H,P7,$B:$B,3) -> 493.82 | U7: =SUMIFS(G:G,H:H,P7,$B:$B,4) -> 318.38 | V7: =SUMIFS($G:$G,$H:$H,$P7,$B:$B,5) -> 506.1 | W7: =SUMIFS($G:$G,$H:$H,$P7,$B:$B,6) -> 579.09 | X7: =SUMIFS($G:$G,$H:$H,$P7,$B:$B,7) -> 138.88
A8: =YEAR(C8) -> 2021 | B8: =MONTH(C8) -> 1 | C8: 44201 | D8: 44201 | E8: =LEFT(F8,5) -> STEAM | F8: STEAMPOWERED.COM 425-952-2985 WA | G8: 19.99 | H8: Merchandise | I8: =VLOOKUP(H8,Expense_Lookup,2,0) -> Variable | J8: =J7+G8 -> 922.72 | K8: Neir Automata | M8: Jayelin | N8: =SUMIFS(G:G,K:K,M8)+SUMIFS('Cash Flow'!$B:$B,'Cash Flow'!$A:$A,Discover!M8)*-1 -> 700.36 | P8: Gasoline | Q8: Variable | R8: =SUMIFS(G:G,H:H,P8,$B:$B,1) -> 67.87 | S8: =SUMIFS(G:G,H:H,P8,$B:$B,2) -> 67.47 | T8: =SUMIFS(G:G,H:H,P8,$B:$B,3) -> 80.06 | U8: =SUMIFS(G:G,H:H,P8,$B:$B,4) -> 125.95 | V8: =SUMIFS($G:$G,$H:$H,$P8,$B:$B,5) -> 115.16 | W8: =SUMIFS($G:$G,$H:$H,$P8,$B:$B,6) -> 104.56 | X8: =SUMIFS($G:$G,$H:$H,$P8,$B:$B,7) -> 32.33
A9: =YEAR(C9) -> 2021 | B9: =MONTH(C9) -> 1 | C9: 44202 | D9: 44202 | E9: =LEFT(F9,5) -> LIVEC | F9: LIVECAREER.COM 800652843 866-933-7587 PR | G9: 24.95 | H9: APP | I9: =VLOOKUP(H9,Expense_Lookup,2,0) -> Fixed | J9: =J8+G9 -> 947.67 | K9: Jayelin | M9: Shevon | N9: =SUMIFS(G:G,K:K,M9)+SUMIFS('Cash Flow'!$B:$B,'Cash Flow'!$A:$A,Discover!M9)*-1 -> 514.95 | P9: Merchandise | Q9: Variable | R9: =SUMIFS(G:G,H:H,P9,$B:$B,1) -> 447.39 | S9: =SUMIFS(G:G,H:H,P9,$B:$B,2) -> 291.35 | T9: =SUMIFS(G:G,H:H,P9,$B:$B,3) -> 427.64 | U9: =SUMIFS(G:G,H:H,P9,$B:$B,4) -> 360.76 | V9: =SUMIFS($G:$G,$H:$H,$P9,$B:$B,5) -> 645.99 | W9: =SUMIFS($G:$G,$H:$H,$P9,$B:$B,6) -> 1136.89 | X9: =SUMIFS($G:$G,$H:$H,$P9,$B:$B,7) -> 742.08
A10: =YEAR(C10) -> 2021 | B10: =MONTH(C10) -> 1 | C10: 44202 | D10: 44202 | E10: =LEFT(F10,5) -> RIVER | F10: RIVER RUN SHORT PUMP HENRICO VA | G10: 30 | H10: Medical Services | I10: =VLOOKUP(H10,Expense_Lookup,2,0) -> Variable | J10: =J9+G10 -> 977.67 | M10: Don | N10: =SUMIFS(G:G,K:K,M10)+SUMIFS('Cash Flow'!$B:$B,'Cash Flow'!$A:$A,Discover!M10)*-1 -> 227.5 | P10: Medical Services | Q10: Variable | R10: =SUMIFS(G:G,H:H,P10,$B:$B,1) -> 70.51 | S10: =SUMIFS(G:G,H:H,P10,$B:$B,2) -> 0 | T10: =SUMIFS(G:G,H:H,P10,$B:$B,3) -> 0 | U10: =SUMIFS(G:G,H:H,P10,$B:$B,4) -> 0 | V10: =SUMIFS($G:$G,$H:$H,$P10,$B:$B,5) -> 0 | W10: =SUMIFS($G:$G,$H:$H,$P10,$B:$B,6) -> 0 | X10: =SUMIFS($G:$G,$H:$H,$P10,$B:$B,7) -> 0
A11: =YEAR(C11) -> 2021 | B11: =MONTH(C11) -> 1 | C11: 44202 | D11: 44202 | E11: =LEFT(F11,5) -> THE M | F11: THE MARKET @ 25TH RICHMOND VA | G11: 24.24 | H11: Supermarkets | I11: =VLOOKUP(H11,Expense_Lookup,2,0) -> Variable | J11: =J10+G11 -> 1001.91 | M11: Dorry | N11: =SUMIFS(G:G,K:K,M11)+SUMIFS('Cash Flow'!$B:$B,'Cash Flow'!$A:$A,Discover!M11)*-1 -> 355 | P11: Supermarkets | Q11: Variable | R11: =SUMIFS(G:G,H:H,P11,$B:$B,1) -> 145.56 | S11: =SUMIFS(G:G,H:H,P11,$B:$B,2) -> 247.65 | T11: =SUMIFS(G:G,H:H,P11,$B:$B,3) -> 132.85 | U11: =SUMIFS(G:G,H:H,P11,$B:$B,4) -> 25.32 | V11: =SUMIFS($G:$G,$H:$H,$P11,$B:$B,5) -> 321.42 | W11: =SUMIFS($G:$G,$H:$H,$P11,$B:$B,6) -> 100.64 | X11: =SUMIFS($G:$G,$H:$H,$P11,$B:$B,7) -> 15.6
A12: =YEAR(C12) -> 2021 | B12: =MONTH(C12) -> 1 | C12: 44203 | D12: 44203 | E12: =LEFT(F12,5) -> AMERI | F12: AMERICA'S BEST WINGS HENRICO VA | G12: 12.09 | H12: Restaurants | I12: =VLOOKUP(H12,Expense_Lookup,2,0) -> Variable | J12: =J11+G12 -> 1014 | M12: Cairo | N12: =SUMIFS(G:G,K:K,M12)+SUMIFS('Cash Flow'!$B:$B,'Cash Flow'!$A:$A,Discover!M12)*-1 -> 0 | P12: Restaurants | Q12: Variable | R12: =SUMIFS(G:G,H:H,P12,$B:$B,1) -> 131.44 | S12: =SUMIFS(G:G,H:H,P12,$B:$B,2) -> 69.55 | T12: =SUMIFS(G:G,H:H,P12,$B:$B,3) -> 314.85 | U12: =SUMIFS(G:G,H:H,P12,$B:$B,4) -> 487.13 | V12: =SUMIFS($G:$G,$H:$H,$P12,$B:$B,5) -> 247.11 | W12: =SUMIFS($G:$G,$H:$H,$P12,$B:$B,6) -> 472.59 | X12: =SUMIFS($G:$G,$H:$H,$P12,$B:$B,7) -> 354.18
A13: =YEAR(C13) -> 2021 | B13: =MONTH(C13) -> 1 | C13: 44203 | D13: 44203 | E13: =LEFT(F13,5) -> GO DR | F13: GO DRAGON ASIAN GRILL RICHMOND VA | G13: 44 | H13: Restaurants | I13: =VLOOKUP(H13,Expense_Lookup,2,0) -> Variable | J13: =J12+G13 -> 1058 | N13: =SUM(N8:N12) -> 1797.81 | P13: Services | Q13: Variable | R13: =SUMIFS(G:G,H:H,P13,$B:$B,1) -> 29.27 | S13: =SUMIFS(G:G,H:H,P13,$B:$B,2) -> 0 | T13: =SUMIFS(G:G,H:H,P13,$B:$B,3) -> 565.98 | U13: =SUMIFS(G:G,H:H,P13,$B:$B,4) -> 98 | V13: =SUMIFS($G:$G,$H:$H,$P13,$B:$B,5) -> 87.75 | W13: =SUMIFS($G:$G,$H:$H,$P13,$B:$B,6) -> 213.84 | X13: =SUMIFS($G:$G,$H:$H,$P13,$B:$B,7) -> 1380.63
A14: =YEAR(C14) -> 2021 | B14: =MONTH(C14) -> 1 | C14: 44203 | D14: 44203 | E14: =LEFT(F14,5) -> THE M | F14: THE MARKET @ 25TH RICHMOND VA | G14: 14.52 | H14: Supermarkets | I14: =VLOOKUP(H14,Expense_Lookup,2,0) -> Variable | J14: =J13+G14 -> 1072.52 | P14: Family | Q14: Variable | R14: =SUMIFS(G:G,H:H,P14,$B:$B,1) -> 103 | S14: =SUMIFS(G:G,H:H,P14,$B:$B,2) -> 0 | T14: =SUMIFS(G:G,H:H,P14,$B:$B,3) -> 0 | U14: =SUMIFS(G:G,H:H,P14,$B:$B,4) -> 0 | V14: =SUMIFS($G:$G,$H:$H,$P14,$B:$B,5) -> 0 | W14: =SUMIFS($G:$G,$H:$H,$P14,$B:$B,6) -> 0 | X14: =SUMIFS($G:$G,$H:$H,$P14,$B:$B,7) -> 0
A15: =YEAR(C15) -> 2021 | B15: =MONTH(C15) -> 1 | C15: 44204 | D15: 44204 | E15: =LEFT(F15,5) -> CVS/P | F15: CVS/PHARMACY #01988 RICHMOND VA | G15: 3.37 | H15: Merchandise | I15: =VLOOKUP(H15,Expense_Lookup,2,0) -> Variable | J15: =J14+G15 -> 1075.89 | K15: Jayelin | M15: Trips | P15: Education | Q15: Variable | R15: =SUMIFS(G:G,H:H,P15,$B:$B,1) -> 49 | S15: =SUMIFS(G:G,H:H,P15,$B:$B,2) -> 215 | T15: =SUMIFS(G:G,H:H,P15,$B:$B,3) -> 0 | U15: =SUMIFS(G:G,H:H,P15,$B:$B,4) -> 0 | V15: =SUMIFS($G:$G,$H:$H,$P15,$B:$B,5) -> 0 | W15: =SUMIFS($G:$G,$H:$H,$P15,$B:$B,6) -> 199 | X15: =SUMIFS($G:$G,$H:$H,$P15,$B:$B,7) -> 0
A16: =YEAR(C16) -> 2021 | B16: =MONTH(C16) -> 1 | C16: 44204 | D16: 44204 | E16: =LEFT(F16,5) -> LABCO | F16: LABCORP PSCC 2 800-845-6167 NC202101072171244 | G16: 40.51 | H16: Medical Services | I16: =VLOOKUP(H16,Expense_Lookup,2,0) -> Variable | J16: =J15+G16 -> 1116.4 | K16: Doctor | M16: New York | N16: =SUMIFS(G:G,K:K,M16)+SUMIFS('Cash Flow'!$B:$B,'Cash Flow'!$A:$A,Discover!M16)*-1 -> 373.46 | P16: Awards and Rebate Credits | Q16: Payment | R16: =SUMIFS(G:G,H:H,P16,$B:$B,1) -> -22.18 | S16: =SUMIFS(G:G,H:H,P16,$B:$B,2) -> -14 | T16: =SUMIFS(G:G,H:H,P16,$B:$B,3) -> -14.05 | U16: =SUMIFS(G:G,H:H,P16,$B:$B,4) -> 0 | V16: =SUMIFS($G:$G,$H:$H,$P16,$B:$B,5) -> 0 | W16: =SUMIFS($G:$G,$H:$H,$P16,$B:$B,6) -> 0 | X16: =SUMIFS($G:$G,$H:$H,$P16,$B:$B,7) -> 0
A17: =YEAR(C17) -> 2021 | B17: =MONTH(C17) -> 1 | C17: 44205 | D17: 44205 | E17: =LEFT(F17,5) -> BINGO | F17: BINGO BEER CO - GAMES PE RICHMOND VA | G17: 30 | H17: Restaurants | I17: =VLOOKUP(H17,Expense_Lookup,2,0) -> Variable | J17: =J16+G17 -> 1146.4 | K17: Akhil | M17: Brooklyn | N17: =SUMIFS(G:G,K:K,M17)+SUMIFS('Cash Flow'!$B:$B,'Cash Flow'!$A:$A,Discover!M17)*-1 -> 1983.8 | P17: Travel/ Entertainment | Q17: Variable | R17: =SUMIFS(G:G,H:H,P17,$B:$B,1) -> 0 | S17: =SUMIFS(G:G,H:H,P17,$B:$B,2) -> 15 | T17: =SUMIFS(G:G,H:H,P17,$B:$B,3) -> 101.04 | U17: =SUMIFS(G:G,H:H,P17,$B:$B,4) -> 4.24 | V17: =SUMIFS($G:$G,$H:$H,$P17,$B:$B,5) -> 360.05 | W17: =SUMIFS($G:$G,$H:$H,$P17,$B:$B,6) -> 179.77 | X17: =SUMIFS($G:$G,$H:$H,$P17,$B:$B,7) -> 399.77
A18: =YEAR(C18) -> 2021 | B18: =MONTH(C18) -> 1 | C18: 44205 | D18: 44205 | E18: =LEFT(F18,5) -> WALMA | F18: WALMART SC 07032 HENRICO VA | G18: 37.5 | H18: Merchandise | I18: =VLOOKUP(H18,Expense_Lookup,2,0) -> Variable | J18: =J17+G18 -> 1183.9 | N18: =SUM(N16:N17) -> 2357.26 | P18: Government Services | Q18: Fixed | R18: =SUMIFS(G:G,H:H,P18,$B:$B,1) -> 0 | S18: =SUMIFS(G:G,H:H,P18,$B:$B,2) -> 40.15 | T18: =SUMIFS(G:G,H:H,P18,$B:$B,3) -> 0 | U18: =SUMIFS(G:G,H:H,P18,$B:$B,4) -> 0 | V18: =SUMIFS($G:$G,$H:$H,$P18,$B:$B,5) -> 26.35 | W18: =SUMIFS($G:$G,$H:$H,$P18,$B:$B,6) -> 195.05 | X18: =SUMIFS($G:$G,$H:$H,$P18,$B:$B,7) -> 0
A19: =YEAR(C19) -> 2021 | B19: =MONTH(C19) -> 1 | C19: 44206 | D19: 44206 | E19: =LEFT(F19,5) -> APPLE | F19: APPLE.COM/BILL 866-712-7753 CAAPPLE PAY ENDING IN 4775MMW3T9K9KMA0 | G19: 14.99 | H19: APP | I19: =VLOOKUP(H19,Expense_Lookup,2,0) -> Fixed | J19: =J18+G19 -> 1198.89 | K19: HBO | P19: Automotive | Q19: Fixed | R19: =SUMIFS(G:G,H:H,P19,$B:$B,1) -> 0 | S19: =SUMIFS(G:G,H:H,P19,$B:$B,2) -> 0 | T19: =SUMIFS(G:G,H:H,P19,$B:$B,3) -> 86.17 | U19: =SUMIFS(G:G,H:H,P19,$B:$B,4) -> 5.65 | V19: =SUMIFS($G:$G,$H:$H,$P19,$B:$B,5) -> 401.19 | W19: =SUMIFS($G:$G,$H:$H,$P19,$B:$B,6) -> 0 | X19: =SUMIFS($G:$G,$H:$H,$P19,$B:$B,7) -> 0
A20: =YEAR(C20) -> 2021 | B20: =MONTH(C20) -> 1 | C20: 44206 | D20: 44206 | E20: =LEFT(F20,5) -> FEDEX | F20: FEDEX 782422707980 800-4633339 TN | G20: 14.47 | H20: Services | I20: =VLOOKUP(H20,Expense_Lookup,2,0) -> Variable | J20: =J19+G20 -> 1213.36 | K20: Darron | M20: Moving | P20: Home Improvement | Q20: Variable | R20: =SUMIFS(G:G,H:H,P20,$B:$B,1) -> 0 | S20: =SUMIFS(G:G,H:H,P20,$B:$B,2) -> 0 | T20: =SUMIFS(G:G,H:H,P20,$B:$B,3) -> 0 | U20: =SUMIFS(G:G,H:H,P20,$B:$B,4) -> 92.58 | V20: =SUMIFS($G:$G,$H:$H,$P20,$B:$B,5) -> 54.37 | W20: =SUMIFS($G:$G,$H:$H,$P20,$B:$B,6) -> 23.13 | X20: =SUMIFS($G:$G,$H:$H,$P20,$B:$B,7) -> 0
A21: =YEAR(C21) -> 2021 | B21: =MONTH(C21) -> 1 | C21: 44206 | D21: 44206 | E21: =LEFT(F21,5) -> FEDEX | F21: FEDEX 782422725203 800-4633339 TN | G21: 11.45 | H21: Services | I21: =VLOOKUP(H21,Expense_Lookup,2,0) -> Variable | J21: =J20+G21 -> 1224.81 | K21: Darron | M21: Storage | N21: =SUMIFS(G:G,K:K,M21)+SUMIFS('Cash Flow'!$B:$B,'Cash Flow'!$A:$A,Discover!M21)*-1 -> 396.27 | P21: Department Stores | Q21: Variable | R21: =SUMIFS(G:G,H:H,P21,$B:$B,1) -> 0 | S21: =SUMIFS(G:G,H:H,P21,$B:$B,2) -> 0 | T21: =SUMIFS(G:G,H:H,P21,$B:$B,3) -> 0 | U21: =SUMIFS(G:G,H:H,P21,$B:$B,4) -> 0 | V21: =SUMIFS($G:$G,$H:$H,$P21,$B:$B,5) -> 91.85 | W21: =SUMIFS($G:$G,$H:$H,$P21,$B:$B,6) -> 0 | X21: =SUMIFS($G:$G,$H:$H,$P21,$B:$B,7) -> 0
A22: =YEAR(C22) -> 2021 | B22: =MONTH(C22) -> 1 | C22: 44206 | D22: 44206 | E22: =LEFT(F22,5) -> WALMA | F22: WALMART SC 07032 HENRICO VA | G22: 74.16 | H22: Merchandise | I22: =VLOOKUP(H22,Expense_Lookup,2,0) -> Variable | J22: =J21+G22 -> 1298.97 | M22: Arizona | N22: =SUMIFS(G:G,K:K,M22)+SUMIFS('Cash Flow'!$B:$B,'Cash Flow'!$A:$A,Discover!M22)*-1 -> 1380.63 | R22: =SUM(R6:R21) -> -909.99 | S22: =SUM(S6:S21) -> -1063.45 | T22: =SUM(T6:T21) -> -225.26 | U22: =SUM(U6:U21) -> 1046.94 | V22: =SUM(V6:V21) -> 2.18 | W22: =SUM(W6:W21) -> -93.27 | X22: =SUM(X6:X21) -> -350.97
A23: =YEAR(C23) -> 2021 | B23: =MONTH(C23) -> 1 | C23: 44207 | D23: 44207 | E23: =LEFT(F23,5) -> CASH | F23: CASH APP*SHEVON LEW 415-375-3176 CA | G23: 103 | H23: Family | I23: =VLOOKUP(H23,Expense_Lookup,2,0) -> Variable | J23: =J22+G23 -> 1401.97 | K23: Shevon | N23: =SUM(N21:N22) -> 1776.9 | Q23: Monthly Spending -> | R23: =SUM(R7:R15,R17:R21) -> 1269.57 | S23: =SUM(S7:S15,S17:S21) -> 1207.02 | T23: =SUM(T7:T15,T17:T21) -> 2202.41 | U23: =SUM(U7:U15,U17:U21) -> 1518.01 | V23: =SUM(V7:V15,V17:V21) -> 2857.34 | W23: =SUM(W7:W15,W17:W21) -> 3204.56 | X23: =SUM(X7:X15,X17:X21) -> 3063.47
A24: =YEAR(C24) -> 2021 | B24: =MONTH(C24) -> 1 | C24: 44207 | D24: 44207 | E24: =LEFT(F24,5) -> PAYPA | F24: PAYPAL *ETCHEDACTUA 402-935-7733 CA | G24: 49 | H24: Education | I24: =VLOOKUP(H24,Expense_Lookup,2,0) -> Variable | J24: =J23+G24 -> 1450.97
A25: =YEAR(C25) -> 2021 | B25: =MONTH(C25) -> 1 | C25: 44208 | D25: 44208 | E25: =LEFT(F25,5) -> EXXON | F25: EXXONMOBIL RICHMOND VA | G25: 23.27 | H25: Gasoline | I25: =VLOOKUP(H25,Expense_Lookup,2,0) -> Variable | J25: =J24+G25 -> 1474.24
A26: =YEAR(C26) -> 2021 | B26: =MONTH(C26) -> 1 | C26: 44208 | D26: 44208 | E26: =LEFT(F26,5) -> FAMIL | F26: FAMILY DOLLAR #5701 RICHMOND VA | G26: 3.33 | H26: Merchandise | I26: =VLOOKUP(H26,Expense_Lookup,2,0) -> Variable | J26: =J25+G26 -> 1477.57 | K26: Jayelin
A27: =YEAR(C27) -> 2021 | B27: =MONTH(C27) -> 1 | C27: 44208 | D27: 44208 | E27: =LEFT(F27,5) -> PAYPA | F27: PAYPAL *VIZMEDIALLC 888-221-1161 CA | G27: 1.99 | H27: APP | I27: =VLOOKUP(H27,Expense_Lookup,2,0) -> Fixed | J27: =J26+G27 -> 1479.56 | K27: Manga
A28: =YEAR(C28) -> 2021 | B28: =MONTH(C28) -> 1 | C28: 44211 | D28: 44211 | E28: =LEFT(F28,5) -> CASHB | F28: CASHBACK BONUS REDEMPTION PYMT/STMT CRDT | G28: -22.18 | H28: Awards and Rebate Credits | I28: =VLOOKUP(H28,Expense_Lookup,2,0) -> Payment | J28: =J27+G28 -> 1457.38
A29: =YEAR(C29) -> 2021 | B29: =MONTH(C29) -> 1 | C29: 44211 | D29: 44211 | E29: =LEFT(F29,5) -> DIREC | F29: DIRECTPAY FULL BALANCESEE DETAILS OF YOUR NEXT DIRECTPAY BELOW | G29: -728.15 | H29: Payments and Credits | I29: =VLOOKUP(H29,Expense_Lookup,2,0) -> Payment | J29: =J28+G29 -> 729.23
A30: =YEAR(C30) -> 2021 | B30: =MONTH(C30) -> 1 | C30: 44211 | D30: 44211 | E30: =LEFT(F30,5) -> INTER | F30: INTERNET PAYMENT - THANK YOU | G30: -729.23 | H30: Payments and Credits | I30: =VLOOKUP(H30,Expense_Lookup,2,0) -> Payment | J30: =J29+G30 -> 0
A31: =YEAR(C31) -> 2021 | B31: =MONTH(C31) -> 1 | C31: 44211 | D31: 44211 | E31: =LEFT(F31,5) -> MCDON | F31: MCDONALD'S F17579 RICHMOND VA | G31: 4.32 | H31: Restaurants | I31: =VLOOKUP(H31,Expense_Lookup,2,0) -> Variable | J31: =J30+G31 -> 4.32 | K31: Jayelin
A32: =YEAR(C32) -> 2021 | B32: =MONTH(C32) -> 1 | C32: 44211 | D32: 44211 | E32: =LEFT(F32,5) -> WALGR | F32: WALGREENS #3860 RICHMOND VA | G32: 21.19 | H32: Merchandise | I32: =VLOOKUP(H32,Expense_Lookup,2,0) -> Variable | J32: =J31+G32 -> 25.51 | K32: Draino
A33: =YEAR(C33) -> 2021 | B33: =MONTH(C33) -> 1 | C33: 44211 | D33: 44211 | E33: =LEFT(F33,5) -> WALMA | F33: WALMART SC 07032 HENRICO VA | G33: 19.4 | H33: Merchandise | I33: =VLOOKUP(H33,Expense_Lookup,2,0) -> Variable | J33: =J32+G33 -> 44.91 | K33: Study
A34: =YEAR(C34) -> 2021 | B34: =MONTH(C34) -> 1 | C34: 44212 | D34: 44212 | E34: =LEFT(F34,5) -> AMZN | F34: AMZN MKTP US*0H4DK7EL3 AMZN.COM/BILLWA72J9EGRQCDU | G34: 58.29 | H34: Merchandise | I34: =VLOOKUP(H34,Expense_Lookup,2,0) -> Variable | J34: =J33+G34 -> 103.2 | K34: Webcam
A35: =YEAR(C35) -> 2021 | B35: =MONTH(C35) -> 1 | C35: 44215 | D35: 44215 | E35: =LEFT(F35,5) -> CHIPO | F35: CHIPOTLE 1975 RICHMOND VA | G35: 8.23 | H35: Restaurants | I35: =VLOOKUP(H35,Expense_Lookup,2,0) -> Variable | J35: =J34+G35 -> 111.43
A36: =YEAR(C36) -> 2021 | B36: =MONTH(C36) -> 1 | C36: 44215 | D36: 44215 | E36: =LEFT(F36,5) -> CVS/P | F36: CVS/PHARMACY #01988 RICHMOND VA | G36: 2.86 | H36: Merchandise | I36: =VLOOKUP(H36,Expense_Lookup,2,0) -> Variable | J36: =J35+G36 -> 114.29 | K36: Jayelin
A37: =YEAR(C37) -> 2021 | B37: =MONTH(C37) -> 1 | C37: 44215 | D37: 44215 | E37: =LEFT(F37,5) -> SP * | F37: SP * ILF, LLC 8888044453 TX | G37: 99.9 | H37: Merchandise | I37: =VLOOKUP(H37,Expense_Lookup,2,0) -> Variable | J37: =J36+G37 -> 214.19
A38: =YEAR(C38) -> 2021 | B38: =MONTH(C38) -> 1 | C38: 44216 | D38: 44216 | E38: =LEFT(F38,5) -> THE M | F38: THE MARKET @ 25TH RICHMOND VA | G38: 15.15 | H38: Supermarkets | I38: =VLOOKUP(H38,Expense_Lookup,2,0) -> Variable | J38: =J37+G38 -> 229.34
A39: =YEAR(C39) -> 2021 | B39: =MONTH(C39) -> 1 | C39: 44217 | D39: 44217 | E39: =LEFT(F39,5) -> KINGS | F39: KINGSISLE *PIRATE101 512-623-5983 TX00099RS900000000000000 | G39: 9.95 | H39: APP | I39: =VLOOKUP(H39,Expense_Lookup,2,0) -> Fixed | J39: =J38+G39 -> 239.29 | K39: Jayelin
A40: =YEAR(C40) -> 2021 | B40: =MONTH(C40) -> 1 | C40: 44217 | D40: 44217 | E40: =LEFT(F40,5) -> PP*PP | F40: PP*PP ROKU FOR CRUNCHYR 402-935-7733 CA | G40: 7.99 | H40: APP | I40: =VLOOKUP(H40,Expense_Lookup,2,0) -> Fixed | J40: =J39+G40 -> 247.28 | K40: Crunchyroll
...

Sheet Cash Flow
C1: 1 | D1: 1 | E1: 1 | F1: 1 | G1: 1 | H1: 2 | I1: 2 | J1: 2 | K1: 2 | L1: 3 | M1: 3 | N1: 3 | O1: 3 | P1: 3 | Q1: 4 | R1: 4 | S1: 4 | T1: 4 | U1: 4 | V1: 5 | W1: 5 | X1: 5 | Y1: 5 | Z1: 5 | AA1: 6 | AB1: 6 | AC1: 6 | AD1: 6 | AE1: 6 | AF1: 7 | AG1: 7 | AH1: 7 | AI1: 7 | AJ1: 7 | AK1: 8 | AL1: 8 | AM1: 8 | AN1: 8 | AO1: 8 | AP1: 9 | AQ1: 9 | AR1: 9 | AS1: 9 | AT1: 9 | AU1: 10 | AV1: 10 | AW1: 10 | AX1: 10 | AY1: 10 | AZ1: 11 | BA1: 11 | BB1: 11 | BC1: 11 | BD1: 11 | BE1: 12 | BF1: 12 | BG1: 12 | BH1: 12 | BI1: 12
A2: Begin Balance | B2: 167.58 | C2: Jan | H2: Feb | L2: Mar | Q2: Apr | V2: May | AA2: Jun | AF2: Jul | AK2: Aug | AP2: Sep | AU2: Oct | AZ2: Nov | BE2: Dec
C3: 1 | D3: 8 | E3: 15 | F3: 22 | G3: 31 | H3: 5 | I3: 12 | J3: 19 | K3: 28 | L3: 5 | M3: 12 | N3: 19 | O3: 26 | P3: 31 | Q3: 2 | R3: 9 | S3: 16 | T3: 23 | U3: 30 | V3: 7 | W3: 14 | X3: 21 | Y3: 28 | Z3: 31 | AA3: 4 | AB3: 11 | AC3: 18 | AD3: 25 | AE3: 30 | AF3: 2 | AG3: 9 | AH3: 16 | AI3: 23 | AJ3: 30 | AK3: 6 | AL3: 13 | AM3: 20 | AN3: 27 | AO3: 31 | AP3: 3 | AQ3: 10 | AR3: 17 | AS3: 24 | AT3: 30 | AU3: 1 | AV3: 8 | AW3: 15 | AX3: 22 | AY3: 29 | AZ3: 5 | BA3: 12 | BB3: 19 | BC3: 26 | BD3: 30 | BE3: 3 | BF3: 10 | BG3: 17 | BH3: 24 | BI3: 31
A4: {=_xlfn._xlws.SORT(_xlfn.UNIQUE(_xlfn._xlws.FILTER('Wells Fargo'!G:G,('Wells Fargo'!G:G<>0)*('Wells Fargo'!G:G<>"Primary"))))} -> Amar - Electric | B4: =SUM(C4:BI4) -> -592.54 | C4: =SUMIFS('Wells Fargo'!$F:$F,'Wells Fargo'!$G:$G,'Cash Flow'!$A4,'Wells Fargo'!$A:$A,C$1,'Wells Fargo'!$B:$B,"<="&'Cash Flow'!C$3) -> 0 | D4: =SUMIFS('Wells Fargo'!$F:$F,'Wells Fargo'!$G:$G,'Cash Flow'!$A4,'Wells Fargo'!$A:$A,D$1,'Wells Fargo'!$B:$B,"<="&'Cash Flow'!D$3,'Wells Fargo'!$B:$B,">"&'Cash Flow'!C$3) -> 0 | E4: =SUMIFS('Wells Fargo'!$F:$F,'Wells Fargo'!$G:$G,'Cash Flow'!$A4,'Wells Fargo'!$A:$A,E$1,'Wells Fargo'!$B:$B,"<="&'Cash Flow'!E$3,'Wells Fargo'!$B:$B,">"&'Cash Flow'!D$3) -> 0 | F4: =SUMIFS('Wells Fargo'!$F:$F,'Wells Fargo'!$G:$G,'Cash Flow'!$A4,'Wells Fargo'!$A:$A,F$1,'Wells Fargo'!$B:$B,"<="&'Cash Flow'!F$3,'Wells Fargo'!$B:$B,">"&'Cash Flow'!E$3) -> -78.86 | G4: =SUMIFS('Wells Fargo'!$F:$F,'Wells Fargo'!$G:$G,'Cash Flow'!$A4,'Wells Fargo'!$A:$A,G$1,'Wells Fargo'!$B:$B,"<="&'Cash Flow'!G$3,'Wells Fargo'!$B:$B,">"&'Cash Flow'!F$3) -> 0 | H4: =SUMIFS('Wells Fargo'!$F:$F,'Wells Fargo'!$G:$G,'Cash Flow'!$A4,'Wells Fargo'!$A:$A,H$1,'Wells Fargo'!$B:$B,"<="&'Cash Flow'!H$3) -> 0 | I4: =SUMIFS('Wells Fargo'!$F:$F,'Wells Fargo'!$G:$G,'Cash Flow'!$A4,'Wells Fargo'!$A:$A,I$1,'Wells Fargo'!$B:$B,"<="&'Cash Flow'!I$3,'Wells Fargo'!$B:$B,">"&'Cash Flow'!H$3) -> 0 | J4: =SUMIFS('Wells Fargo'!$F:$F,'Wells Fargo'!$G:$G,'Cash Flow'!$A4,'Wells Fargo'!$A:$A,J$1,'Wells Fargo'!$B:$B,"<="&'Cash Flow'!J$3,'Wells Fargo'!$B:$B,">"&'Cash Flow'!I$3) -> 0 | K4: =SUMIFS('Wells Fargo'!$F:$F,'Wells Fargo'!$G:$G,'Cash Flow'!$A4,'Wells Fargo'!$A:$A,K$1,'Wells Fargo'!$B:$B,"<="&'Cash Flow'!K$3,'Wells Fargo'!$B:$B,">"&'Cash Flow'!J$3) -> -81.32 | L4: =SUMIFS('Wells Fargo'!$F:$F,'Wells Fargo'!$G:$G,'Cash Flow'!$A4,'Wells Fargo'!$A:$A,L$1,'Wells Fargo'!$B:$B,"<="&'Cash Flow'!L$3) -> 0 | M4: =SUMIFS('Wells Fargo'!$F:$F,'Wells Fargo'!$G:$G,'Cash Flow'!$A4,'Wells Fargo'!$A:$A,M$1,'Wells Fargo'!$B:$B,"<="&'Cash Flow'!M$3,'Wells Fargo'!$B:$B,">"&'Cash Flow'!L$3) -> 0 | N4: =SUMIFS('Wells Fargo'!$F:$F,'Wells Fargo'!$G:$G,'Cash Flow'!$A4,'Wells Fargo'!$A:$A,N$1,'Wells Fargo'!$B:$B,"<="&'Cash Flow'!N$3,'Wells Fargo'!$B:$B,">"&'Cash Flow'!M$3) -> -39.7 | O4: =SUMIFS('Wells Fargo'!$F:$F,'Wells Fargo'!$G:$G,'Cash Flow'!$A4,'Wells Fargo'!$A:$A,O$1,'Wells Fargo'!$B:$B,"<="&'Cash Flow'!O$3,'Wells Fargo'!$B:$B,">"&'Cash Flow'!N$3) -> 0 | P4: =SUMIFS('Wells Fargo'!$F:$F,'Wells Fargo'!$G:$G,'Cash Flow'!$A4,'Wells Fargo'!$A:$A,P$1,'Wells Fargo'!$B:$B,"<="&'Cash Flow'!P$3,'Wells Fargo'!$B:$B,">"&'Cash Flow'!O$3) -> 0 | Q4: =SUMIFS('Wells Fargo'!$F:$F,'Wells Fargo'!$G:$G,'Cash Flow'!$A4,'Wells Fargo'!$A:$A,Q$1,'Wells Fargo'!$B:$B,"<="&'Cash Flow'!Q$3) -> 0 | R4: =SUMIFS('Wells Fargo'!$F:$F,'Wells Fargo'!$G:$G,'Cash Flow'!$A4,'Wells Fargo'!$A:$A,R$1,'Wells Fargo'!$B:$B,"<="&'Cash Flow'!R$3,'Wells Fargo'!$B:$B,">"&'Cash Flow'!Q$3) -> 0 | S4: =SUMIFS('Wells Fargo'!$F:$F,'Wells Fargo'!$G:$G,'Cash Flow'!$A4,'Wells Fargo'!$A:$A,S$1,'Wells Fargo'!$B:$B,"<="&'Cash Flow'!S$3,'Wells Fargo'!$B:$B,">"&'Cash Flow'!R$3) -> -138.52 | T4: =SUMIFS('Wells Fargo'!$F:$F,'Wells Fargo'!$G:$G,'Cash Flow'!$A4,'Wells Fargo'!$A:$A,T$1,'Wells Fargo'!$B:$B,"<="&'Cash Flow'!T$3,'Wells Fargo'!$B:$B,">"&'Cash Flow'!S$3) -> 0 | U4: =SUMIFS('Wells Fargo'!$F:$F,'Wells Fargo'!$G:$G,'Cash Flow'!$A4,'Wells Fargo'!$A:$A,U$1,'Wells Fargo'!$B:$B,"<="&'Cash Flow'!U$3,'Wells Fargo'!$B:$B,">"&'Cash Flow'!T$3) -> 0 | V4: =SUMIFS('Wells Fargo'!$F:$F,'Wells Fargo'!$G:$G,'Cash Flow'!$A4,'Wells Fargo'!$A:$A,V$1,'Wells Fargo'!$B:$B,"<="&'Cash Flow'!V$3) -> 0 | W4: =SUMIFS('Wells Fargo'!$F:$F,'Wells Fargo'!$G:$G,'Cash Flow'!$A4,'Wells Fargo'!$A:$A,W$1,'Wells Fargo'!$B:$B,"<="&'Cash Flow'!W$3,'Wells Fargo'!$B:$B,">"&'Cash Flow'!V$3) -> -136.14 | X4: =SUMIFS('Wells Fargo'!$F:$F,'Wells Fargo'!$G:$G,'Cash Flow'!$A4,'Wells Fargo'!$A:$A,X$1,'Wells Fargo'!$B:$B,"<="&'Cash Flow'!X$3,'Wells Fargo'!$B:$B,">"&'Cash Flow'!W$3) -> 0 | Y4: =SUMIFS('Wells Fargo'!$F:$F,'Wells Fargo'!$G:$G,'Cash Flow'!$A4,'Wells Fargo'!$A:$A,Y$1,'Wells Fargo'!$B:$B,"<="&'Cash Flow'!Y$3,'Wells Fargo'!$B:$B,">"&'Cash Flow'!X$3) -> 0 | Z4: =SUMIFS('Wells Fargo'!$F:$F,'Wells Fargo'!$G:$G,'Cash Flow'!$A4,'Wells Fargo'!$A:$A,Z$1,'Wells Fargo'!$B:$B,"<="&'Cash Flow'!Z$3,'Wells Fargo'!$B:$B,">"&'Cash Flow'!Y$3) -> 0 | AA4: =SUMIFS('Wells Fargo'!$F:$F,'Wells Fargo'!$G:$G,'Cash Flow'!$A4,'Wells Fargo'!$A:$A,AA$1,'Wells Fargo'!$B:$B,"<="&'Cash Flow'!AA$3) -> -118 | AB4: =SUMIFS('Wells Fargo'!$F:$F,'Wells Fargo'!$G:$G,'Cash Flow'!$A4,'Wells Fargo'!$A:$A,AB$1,'Wells Fargo'!$B:$B,"<="&'Cash Flow'!AB$3,'Wells Fargo'!$B:$B,">"&'Cash Flow'!AA$3) -> 0 | AC4: =SUMIFS('Wells Fargo'!$F:$F,'Wells Fargo'!$G:$G,'Cash Flow'!$A4,'Wells Fargo'!$A:$A,AC$1,'Wells Fargo'!$B:$B,"<="&'Cash Flow'!AC$3,'Wells Fargo'!$B:$B,">"&'Cash Flow'!AB$3) -> 0 | AD4: =SUMIFS('Wells Fargo'!$F:$F,'Wells Fargo'!$G:$G,'Cash Flow'!$A4,'Wells Fargo'!$A:$A,AD$1,'Wells Fargo'!$B:$B,"<="&'Cash Flow'!AD$3,'Wells Fargo'!$B:$B,">"&'Cash Flow'!AC$3) -> 0 | AE4: =SUMIFS('Wells Fargo'!$F:$F,'Wells Fargo'!$G:$G,'Cash Flow'!$A4,'Wells Fargo'!$A:$A,AE$1,'Wells Fargo'!$B:$B,"<="&'Cash Flow'!AE$3,'Wells Fargo'!$B:$B,">"&'Cash Flow'!AD$3) -> 0 | AF4: =SUMIFS('Wells Fargo'!$F:$F,'Wells Fargo'!$G:$G,'Cash Flow'!$A4,'Wells Fargo'!$A:$A,AF$1,'Wells Fargo'!$B:$B,"<="&'Cash Flow'!AF$3) -> 0 | AG4: =SUMIFS('Wells Fargo'!$F:$F,'Wells Fargo'!$G:$G,'Cash Flow'!$A4,'Wells Fargo'!$A:$A,AG$1,'Wells Fargo'!$B:$B,"<="&'Cash Flow'!AG$3,'Wells Fargo'!$B:$B,">"&'Cash Flow'!AF$3) -> 0 | AH4: =SUMIFS('Wells Fargo'!$F:$F,'Wells Fargo'!$G:$G,'Cash Flow'!$A4,'Wells Fargo'!$A:$A,AH$1,'Wells Fargo'!$B:$B,"<="&'Cash Flow'!AH$3,'Wells Fargo'!$B:$B,">"&'Cash Flow'!AG$3) -> 0 | AI4: =SUMIFS('Wells Fargo'!$F:$F,'Wells Fargo'!$G:$G,'Cash Flow'!$A4,'Wells Fargo'!$A:$A,AI$1,'Wells Fargo'!$B:$B,"<="&'Cash Flow'!AI$3,'Wells Fargo'!$B:$B,">"&'Cash Flow'!AH$3) -> 0 | AJ4: =SUMIFS('Wells Fargo'!$F:$F,'Wells Fargo'!$G:$G,'Cash Flow'!$A4,'Wells Fargo'!$A:$A,AJ$1,'Wells Fargo'!$B:$B,"<="&'Cash Flow'!AJ$3,'Wells Fargo'!$B:$B,">"&'Cash Flow'!AI$3) -> 0 | AK4: =SUMIFS('Wells Fargo'!$F:$F,'Wells Fargo'!$G:$G,'Cash Flow'!$A4,'Wells Fargo'!$A:$A,AK$1,'Wells Fargo'!$B:$B,"<="&'Cash Flow'!AK$3) -> 0 | AL4: =SUMIFS('Wells Fargo'!$F:$F,'Wells Fargo'!$G:$G,'Cash Flow'!$A4,'Wells Fargo'!$A:$A,AL$1,'Wells Fargo'!$B:$B,"<="&'Cash Flow'!AL$3,'Wells Fargo'!$B:$B,">"&'Cash Flow'!AK$3) -> 0 | AM4: =SUMIFS('Wells Fargo'!$F:$F,'Wells Fargo'!$G:$G,'Cash Flow'!$A4,'Wells Fargo'!$A:$A,AM$1,'Wells Fargo'!$B:$B,"<="&'Cash Flow'!AM$3,'Wells Fargo'!$B:$B,">"&'Cash Flow'!AL$3) -> 0 | AN4: =SUMIFS('Wells Fargo'!$F:$F,'Wells Fargo'!$G:$G,'Cash Flow'!$A4,'Wells Fargo'!$A:$A,AN$1,'Wells Fargo'!$B:$B,"<="&'Cash Flow'!AN$3,'Wells Fargo'!$B:$B,">"&'Cash Flow'!AM$3) -> 0 | AO4: =SUMIFS('Wells Fargo'!$F:$F,'Wells Fargo'!$G:$G,'Cash Flow'!$A4,'Wells Fargo'!$A:$A,AO$1,'Wells Fargo'!$B:$B,"<="&'Cash Flow'!AO$3,'Wells Fargo'!$B:$B,">"&'Cash Flow'!AN$3) -> 0 | AP4: =SUMIFS('Wells Fargo'!$F:$F,'Wells Fargo'!$G:$G,'Cash Flow'!$A4,'Wells Fargo'!$A:$A,AP$1,'Wells Fargo'!$B:$B,"<="&'Cash Flow'!AP$3) -> 0 | AQ4: =SUMIFS('Wells Fargo'!$F:$F,'Wells Fargo'!$G:$G,'Cash Flow'!$A4,'Wells Fargo'!$A:$A,AQ$1,'Wells Fargo'!$B:$B,"<="&'Cash Flow'!AQ$3,'Wells Fargo'!$B:$B,">"&'Cash Flow'!AP$3) -> 0 | AR4: =SUMIFS('Wells Fargo'!$F:$F,'Wells Fargo'!$G:$G,'Cash Flow'!$A4,'Wells Fargo'!$A:$A,AR$1,'Wells Fargo'!$B:$B,"<="&'Cash Flow'!AR$3,'Wells Fargo'!$B:$B,">"&'Cash Flow'!AQ$3) -> 0 | AS4: =SUMIFS('Wells Fargo'!$F:$F,'Wells Fargo'!$G:$G,'Cash Flow'!$A4,'Wells Fargo'!$A:$A,AS$1,'Wells Fargo'!$B:$B,"<="&'Cash Flow'!AS$3,'Wells Fargo'!$B:$B,">"&'Cash Flow'!AR$3) -> 0 | AT4: =SUMIFS('Wells Fargo'!$F:$F,'Wells Fargo'!$G:$G,'Cash Flow'!$A4,'Wells Fargo'!$A:$A,AT$1,'Wells Fargo'!$B:$B,"<="&'Cash Flow'!AT$3,'Wells Fargo'!$B:$B,">"&'Cash Flow'!AS$3) -> 0 | AU4: =SUMIFS('Wells Fargo'!$F:$F,'Wells Fargo'!$G:$G,'Cash Flow'!$A4,'Wells Fargo'!$A:$A,AU$1,'Wells Fargo'!$B:$B,"<="&'Cash Flow'!AU$3) -> 0 | AV4: =SUMIFS('Wells Fargo'!$F:$F,'Wells Fargo'!$G:$G,'Cash Flow'!$A4,'Wells Fargo'!$A:$A,AV$1,'Wells Fargo'!$B:$B,"<="&'Cash Flow'!AV$3,'Wells Fargo'!$B:$B,">"&'Cash Flow'!AU$3) -> 0 | AW4: =SUMIFS('Wells Fargo'!$F:$F,'Wells Fargo'!$G:$G,'Cash Flow'!$A4,'Wells Fargo'!$A:$A,AW$1,'Wells Fargo'!$B:$B,"<="&'Cash Flow'!AW$3,'Wells Fargo'!$B:$B,">"&'Cash Flow'!AV$3) -> 0 | AX4: =SUMIFS('Wells Fargo'!$F:$F,'Wells Fargo'!$G:$G,'Cash Flow'!$A4,'Wells Fargo'!$A:$A,AX$1,'Wells Fargo'!$B:$B,"<="&'Cash Flow'!AX$3,'Wells Fargo'!$B:$B,">"&'Cash Flow'!AW$3) -> 0 | AY4: =SUMIFS('Wells Fargo'!$F:$F,'Wells Fargo'!$G:$G,'Cash Flow'!$A4,'Wells Fargo'!$A:$A,AY$1,'Wells Fargo'!$B:$B,"<="&'Cash Flow'!AY$3,'Wells Fargo'!$B:$B,">"&'Cash Flow'!AX$3) -> 0 | AZ4: =SUMIFS('Wells Fargo'!$F:$F,'Wells Fargo'!$G:$G,'Cash Flow'!$A4,'Wells Fargo'!$A:$A,AZ$1,'Wells Fargo'!$B:$B,"<="&'Cash Flow'!AZ$3) -> 0 | BA4: =SUMIFS('Wells Fargo'!$F:$F,'Wells Fargo'!$G:$G,'Cash Flow'!$A4,'Wells Fargo'!$A:$A,BA$1,'Wells Fargo'!$B:$B,"<="&'Cash Flow'!BA$3,'Wells Fargo'!$B:$B,">"&'Cash Flow'!AZ$3) -> 0 | BB4: =SUMIFS('Wells Fargo'!$F:$F,'Wells Fargo'!$G:$G,'Cash Flow'!$A4,'Wells Fargo'!$A:$A,BB$1,'Wells Fargo'!$B:$B,"<="&'Cash Flow'!BB$3,'Wells Fargo'!$B:$B,">"&'Cash Flow'!BA$3) -> 0 | BC4: =SUMIFS('Wells Fargo'!$F:$F,'Wells Fargo'!$G:$G,'Cash Flow'!$A4,'Wells Fargo'!$A:$A,BC$1,'Wells Fargo'!$B:$B,"<="&'Cash Flow'!BC$3,'Wells Fargo'!$B:$B,">"&'Cash Flow'!BB$3) -> 0 | BD4: =SUMIFS('Wells Fargo'!$F:$F,'Wells Fargo'!$G:$G,'Cash Flow'!$A4,'Wells Fargo'!$A:$A,BD$1,'Wells Fargo'!$B:$B,"<="&'Cash Flow'!BD$3,'Wells Fargo'!$B:$B,">"&'Cash Flow'!BC$3) -> 0 | BE4: =SUMIFS('Wells Fargo'!$F:$F,'Wells Fargo'!$G:$G,'Cash Flow'!$A4,'Wells Fargo'!$A:$A,BE$1,'Wells Fargo'!$B:$B,"<="&'Cash Flow'!BE$3) -> 0 | BF4: =SUMIFS('Wells Fargo'!$F:$F,'Wells Fargo'!$G:$G,'Cash Flow'!$A4,'Wells Fargo'!$A:$A,BF$1,'Wells Fargo'!$B:$B,"<="&'Cash Flow'!BF$3,'Wells Fargo'!$B:$B,">"&'Cash Flow'!BE$3) -> 0 | BG4: =SUMIFS('Wells Fargo'!$F:$F,'Wells Fargo'!$G:$G,'Cash Flow'!$A4,'Wells Fargo'!$A:$A,BG$1,'Wells Fargo'!$B:$B,"<="&'Cash Flow'!BG$3,'Wells Fargo'!$B:$B,">"&'Cash Flow'!BF$3) -> 0 | BH4: =SUMIFS('Wells Fargo'!$F:$F,'Wells Fargo'!$G:$G,'Cash Flow'!$A4,'Wells Fargo'!$A:$A,BH$1,'Wells Fargo'!$B:$B,"<="&'Cash Flow'!BH$3,'Wells Fargo'!$B:$B,">"&'Cash Flow'!BG$3) -> 0 | BI4: =SUMIFS('Wells Fargo'!$F:$F,'Wells Fargo'!$G:$G,'Cash Flow'!$A4,'Wells Fargo'!$A:$A,BI$1,'Wells Fargo'!$B:$B,"<="&'Cash Flow'!BI$3,'Wells Fargo'!$B:$B,">"&'Cash Flow'!BH$3) -> 0
A5: Amar - Rent | B5: =SUM(C5:BI5) -> -2800 | C5: =SUMIFS('Wells Fargo'!$F:$F,'Wells Fargo'!$G:$G,'Cash Flow'!$A5,'Wells Fargo'!$A:$A,C$1,'Wells Fargo'!$B:$B,"<="&'Cash Flow'!C$3) -> 0 | D5: =SUMIFS('Wells Fargo'!$F:$F,'Wells Fargo'!$G:$G,'Cash Flow'!$A5,'Wells Fargo'!$A:$A,D$1,'Wells Fargo'!$B:$B,"<="&'Cash Flow'!D$3,'Wells Fargo'!$B:$B,">"&'Cash Flow'!C$3) -> 0 | E5: =SUMIFS('Wells Fargo'!$F:$F,'Wells Fargo'!$G:$G,'Cash Flow'!$A5,'Wells Fargo'!$A:$A,E$1,'Wells Fargo'!$B:$B,"<="&'Cash Flow'!E$3,'Wells Fargo'!$B:$B,">"&'Cash Flow'!D$3) -> 0 | F5: =SUMIFS('Wells Fargo'!$F:$F,'Wells Fargo'!$G:$G,'Cash Flow'!$A5,'Wells Fargo'!$A:$A,F$1,'Wells Fargo'!$B:$B,"<="&'Cash Flow'!F$3,'Wells Fargo'!$B:$B,">"&'Cash Flow'!E$3) -> 0 | G5: =SUMIFS('Wells Fargo'!$F:$F,'Wells Fargo'!$G:$G,'Cash Flow'!$A5,'Wells Fargo'!$A:$A,G$1,'Wells Fargo'!$B:$B,"<="&'Cash Flow'!G$3,'Wells Fargo'!$B:$B,">"&'Cash Flow'!F$3) -> -700 | H5: =SUMIFS('Wells Fargo'!$F:$F,'Wells Fargo'!$G:$G,'Cash Flow'!$A5,'Wells Fargo'!$A:$A,H$1,'Wells Fargo'!$B:$B,"<="&'Cash Flow'!H$3) -> 0 | I5: =SUMIFS('Wells Fargo'!$F:$F,'Wells Fargo'!$G:$G,'Cash Flow'!$A5,'Wells Fargo'!$A:$A,I$1,'Wells Fargo'!$B:$B,"<="&'Cash Flow'!I$3,'Wells Fargo'!$B:$B,">"&'Cash Flow'!H$3) -> 0 | J5: =SUMIFS('Wells Fargo'!$F:$F,'Wells Fargo'!$G:$G,'Cash Flow'!$A5,'Wells Fargo'!$A:$A,J$1,'Wells Fargo'!$B:$B,"<="&'Cash Flow'!J$3,'Wells Fargo'!$B:$B,">"&'Cash Flow'!I$3) -> 0 | K5: =SUMIFS('Wells Fargo'!$F:$F,'Wells Fargo'!$G:$G,'Cash Flow'!$A5,'Wells Fargo'!$A:$A,K$1,'Wells Fargo'!$B:$B,"<="&'Cash Flow'!K$3,'Wells Fargo'!$B:$B,">"&'Cash Flow'!J$3) -> -700 | L5: =SUMIFS('Wells Fargo'!$F:$F,'Wells Fargo'!$G:$G,'Cash Flow'!$A5,'Wells Fargo'!$A:$A,L$1,'Wells Fargo'!$B:$B,"<="&'Cash Flow'!L$3) -> 0 | M5: =SUMIFS('Wells Fargo'!$F:$F,'Wells Fargo'!$G:$G,'Cash Flow'!$A5,'Wells Fargo'!$A:$A,M$1,'Wells Fargo'!$B:$B,"<="&'Cash Flow'!M$3,'Wells Fargo'!$B:$B,">"&'Cash Flow'!L$3) -> 0 | N5: =SUMIFS('Wells Fargo'!$F:$F,'Wells Fargo'!$G:$G,'Cash Flow'!$A5,'Wells Fargo'!$A:$A,N$1,'Wells Fargo'!$B:$B,"<="&'Cash Flow'!N$3,'Wells Fargo'!$B:$B,">"&'Cash Flow'!M$3) -> -700 | O5: =SUMIFS('Wells Fargo'!$F:$F,'Wells Fargo'!$G:$G,'Cash Flow'!$A5,'Wells Fargo'!$A:$A,O$1,'Wells Fargo'!$B:$B,"<="&'Cash Flow'!O$3,'Wells Fargo'!$B:$B,">"&'Cash Flow'!N$3) -> 0 | P5: =SUMIFS('Wells Fargo'!$F:$F,'Wells Fargo'!$G:$G,'Cash Flow'!$A5,'Wells Fargo'!$A:$A,P$1,'Wells Fargo'!$B:$B,"<="&'Cash Flow'!P$3,'Wells Fargo'!$B:$B,">"&'Cash Flow'!O$3) -> 0 | Q5: =SUMIFS('Wells Fargo'!$F:$F,'Wells Fargo'!$G:$G,'Cash Flow'!$A5,'Wells Fargo'!$A:$A,Q$1,'Wells Fargo'!$B:$B,"<="&'Cash Flow'!Q$3) -> 0 | R5: =SUMIFS('Wells Fargo'!$F:$F,'Wells Fargo'!$G:$G,'Cash Flow'!$A5,'Wells Fargo'!$A:$A,R$1,'Wells Fargo'!$B:$B,"<="&'Cash Flow'!R$3,'Wells Fargo'!$B:$B,">"&'Cash Flow'!Q$3) -> 0 | S5: =SUMIFS('Wells Fargo'!$F:$F,'Wells Fargo'!$G:$G,'Cash Flow'!$A5,'Wells Fargo'!$A:$A,S$1,'Wells Fargo'!$B:$B,"<="&'Cash Flow'!S$3,'Wells Fargo'!$B:$B,">"&'Cash Flow'!R$3) -> 0 | T5: =SUMIFS('Wells Fargo'!$F:$F,'Wells Fargo'!$G:$G,'Cash Flow'!$A5,'Wells Fargo'!$A:$A,T$1,'Wells Fargo'!$B:$B,"<="&'Cash Flow'!T$3,'Wells Fargo'!$B:$B,">"&'Cash Flow'!S$3) -> -700 | U5: =SUMIFS('Wells Fargo'!$F:$F,'Wells Fargo'!$G:$G,'Cash Flow'!$A5,'Wells Fargo'!$A:$A,U$1,'Wells Fargo'!$B:$B,"<="&'Cash Flow'!U$3,'Wells Fargo'!$B:$B,">"&'Cash Flow'!T$3) -> 0 | V5: =SUMIFS('Wells Fargo'!$F:$F,'Wells Fargo'!$G:$G,'Cash Flow'!$A5,'Wells Fargo'!$A:$A,V$1,'Wells Fargo'!$B:$B,"<="&'Cash Flow'!V$3) -> 0 | W5: =SUMIFS('Wells Fargo'!$F:$F,'Wells Fargo'!$G:$G,'Cash Flow'!$A5,'Wells Fargo'!$A:$A,W$1,'Wells Fargo'!$B:$B,"<="&'Cash Flow'!W$3,'Wells Fargo'!$B:$B,">"&'Cash Flow'!V$3) -> 0 | X5: =SUMIFS('Wells Fargo'!$F:$F,'Wells Fargo'!$G:$G,'Cash Flow'!$A5,'Wells Fargo'!$A:$A,X$1,'Wells Fargo'!$B:$B,"<="&'Cash Flow'!X$3,'Wells Fargo'!$B:$B,">"&'Cash Flow'!W$3) -> 0 | Y5: =SUMIFS('Wells Fargo'!$F:$F,'Wells Fargo'!$G:$G,'Cash Flow'!$A5,'Wells Fargo'!$A:$A,Y$1,'Wells Fargo'!$B:$B,"<="&'Cash Flow'!Y$3,'Wells Fargo'!$B:$B,">"&'Cash Flow'!X$3) -> 0 | Z5: =SUMIFS('Wells Fargo'!$F:$F,'Wells Fargo'!$G:$G,'Cash Flow'!$A5,'Wells Fargo'!$A:$A,Z$1,'Wells Fargo'!$B:$B,"<="&'Cash Flow'!Z$3,'Wells Fargo'!$B:$B,">"&'Cash Flow'!Y$3) -> 0 | AA5: =SUMIFS('Wells Fargo'!$F:$F,'Wells Fargo'!$G:$G,'Cash Flow'!$A5,'Wells Fargo'!$A:$A,AA$1,'Wells Fargo'!$B:$B,"<="&'Cash Flow'!AA$3) -> 0 | AB5: =SUMIFS('Wells Fargo'!$F:$F,'Wells Fargo'!$G:$G,'Cash Flow'!$A5,'Wells Fargo'!$A:$A,AB$1,'Wells Fargo'!$B:$B,"<="&'Cash Flow'!AB$3,'Wells Fargo'!$B:$B,">"&'Cash Flow'!AA$3) -> 0 | AC5: =SUMIFS('Wells Fargo'!$F:$F,'Wells Fargo'!$G:$G,'Cash Flow'!$A5,'Wells Fargo'!$A:$A,AC$1,'Wells Fargo'!$B:$B,"<="&'Cash Flow'!AC$3,'Wells Fargo'!$B:$B,">"&'Cash Flow'!AB$3) -> 0 | AD5: =SUMIFS('Wells Fargo'!$F:$F,'Wells Fargo'!$G:$G,'Cash Flow'!$A5,'Wells Fargo'!$A:$A,AD$1,'Wells Fargo'!$B:$B,"<="&'Cash Flow'!AD$3,'Wells Fargo'!$B:$B,">"&'Cash Flow'!AC$3) -> 0 | AE5: =SUMIFS('Wells Fargo'!$F:$F,'Wells Fargo'!$G:$G,'Cash Flow'!$A5,'Wells Fargo'!$A:$A,AE$1,'Wells Fargo'!$B:$B,"<="&'Cash Flow'!AE$3,'Wells Fargo'!$B:$B,">"&'Cash Flow'!AD$3) -> 0 | AF5: =SUMIFS('Wells Fargo'!$F:$F,'Wells Fargo'!$G:$G,'Cash Flow'!$A5,'Wells Fargo'!$A:$A,AF$1,'Wells Fargo'!$B:$B,"<="&'Cash Flow'!AF$3) -> 0 | AG5: =SUMIFS('Wells Fargo'!$F:$F,'Wells Fargo'!$G:$G,'Cash Flow'!$A5,'Wells Fargo'!$A:$A,AG$1,'Wells Fargo'!$B:$B,"<="&'Cash Flow'!AG$3,'Wells Fargo'!$B:$B,">"&'Cash Flow'!AF$3) -> 0 | AH5: =SUMIFS('Wells Fargo'!$F:$F,'Wells Fargo'!$G:$G,'Cash Flow'!$A5,'Wells Fargo'!$A:$A,AH$1,'Wells Fargo'!$B:$B,"<="&'Cash Flow'!AH$3,'Wells Fargo'!$B:$B,">"&'Cash Flow'!AG$3) -> 0 | AI5: =SUMIFS('Wells Fargo'!$F:$F,'Wells Fargo'!$G:$G,'Cash Flow'!$A5,'Wells Fargo'!$A:$A,AI$1,'Wells Fargo'!$B:$B,"<="&'Cash Flow'!AI$3,'Wells Fargo'!$B:$B,">"&'Cash Flow'!AH$3) -> 0 | AJ5: =SUMIFS('Wells Fargo'!$F:$F,'Wells Fargo'!$G:$G,'Cash Flow'!$A5,'Wells Fargo'!$A:$A,AJ$1,'Wells Fargo'!$B:$B,"<="&'Cash Flow'!AJ$3,'Wells Fargo'!$B:$B,">"&'Cash Flow'!AI$3) -> 0 | AK5: =SUMIFS('Wells Fargo'!$F:$F,'Wells Fargo'!$G:$G,'Cash Flow'!$A5,'Wells Fargo'!$A:$A,AK$1,'Wells Fargo'!$B:$B,"<="&'Cash Flow'!AK$3) -> 0 | AL5: =SUMIFS('Wells Fargo'!$F:$F,'Wells Fargo'!$G:$G,'Cash Flow'!$A5,'Wells Fargo'!$A:$A,AL$1,'Wells Fargo'!$B:$B,"<="&'Cash Flow'!AL$3,'Wells Fargo'!$B:$B,">"&'Cash Flow'!AK$3) -> 0 | AM5: =SUMIFS('Wells Fargo'!$F:$F,'Wells Fargo'!$G:$G,'Cash Flow'!$A5,'Wells Fargo'!$A:$A,AM$1,'Wells Fargo'!$B:$B,"<="&'Cash Flow'!AM$3,'Wells Fargo'!$B:$B,">"&'Cash Flow'!AL$3) -> 0 | AN5: =SUMIFS('Wells Fargo'!$F:$F,'Wells Fargo'!$G:$G,'Cash Flow'!$A5,'Wells Fargo'!$A:$A,AN$1,'Wells Fargo'!$B:$B,"<="&'Cash Flow'!AN$3,'Wells Fargo'!$B:$B,">"&'Cash Flow'!AM$3) -> 0 | AO5: =SUMIFS('Wells Fargo'!$F:$F,'Wells Fargo'!$G:$G,'Cash Flow'!$A5,'Wells Fargo'!$A:$A,AO$1,'Wells Fargo'!$B:$B,"<="&'Cash Flow'!AO$3,'Wells Fargo'!$B:$B,">"&'Cash Flow'!AN$3) -> 0 | AP5: =SUMIFS('Wells Fargo'!$F:$F,'Wells Fargo'!$G:$G,'Cash Flow'!$A5,'Wells Fargo'!$A:$A,AP$1,'Wells Fargo'!$B:$B,"<="&'Cash Flow'!AP$3) -> 0 | AQ5: =SUMIFS('Wells Fargo'!$F:$F,'Wells Fargo'!$G:$G,'Cash Flow'!$A5,'Wells Fargo'!$A:$A,AQ$1,'Wells Fargo'!$B:$B,"<="&'Cash Flow'!AQ$3,'Wells Fargo'!$B:$B,">"&'Cash Flow'!AP$3) -> 0 | AR5: =SUMIFS('Wells Fargo'!$F:$F,'Wells Fargo'!$G:$G,'Cash Flow'!$A5,'Wells Fargo'!$A:$A,AR$1,'Wells Fargo'!$B:$B,"<="&'Cash Flow'!AR$3,'Wells Fargo'!$B:$B,">"&'Cash Flow'!AQ$3) -> 0 | AS5: =SUMIFS('Wells Fargo'!$F:$F,'Wells Fargo'!$G:$G,'Cash Flow'!$A5,'Wells Fargo'!$A:$A,AS$1,'Wells Fargo'!$B:$B,"<="&'Cash Flow'!AS$3,'Wells Fargo'!$B:$B,">"&'Cash Flow'!AR$3) -> 0 | AT5: =SUMIFS('Wells Fargo'!$F:$F,'Wells Fargo'!$G:$G,'Cash Flow'!$A5,'Wells Fargo'!$A:$A,AT$1,'Wells Fargo'!$B:$B,"<="&'Cash Flow'!AT$3,'Wells Fargo'!$B:$B,">"&'Cash Flow'!AS$3) -> 0 | AU5: =SUMIFS('Wells Fargo'!$F:$F,'Wells Fargo'!$G:$G,'Cash Flow'!$A5,'Wells Fargo'!$A:$A,AU$1,'Wells Fargo'!$B:$B,"<="&'Cash Flow'!AU$3) -> 0 | AV5: =SUMIFS('Wells Fargo'!$F:$F,'Wells Fargo'!$G:$G,'Cash Flow'!$A5,'Wells Fargo'!$A:$A,AV$1,'Wells Fargo'!$B:$B,"<="&'Cash Flow'!AV$3,'Wells Fargo'!$B:$B,">"&'Cash Flow'!AU$3) -> 0 | AW5: =SUMIFS('Wells Fargo'!$F:$F,'Wells Fargo'!$G:$G,'Cash Flow'!$A5,'Wells Fargo'!$A:$A,AW$1,'Wells Fargo'!$B:$B,"<="&'Cash Flow'!AW$3,'Wells Fargo'!$B:$B,">"&'Cash Flow'!AV$3) -> 0 | AX5: =SUMIFS('Wells Fargo'!$F:$F,'Wells Fargo'!$G:$G,'Cash Flow'!$A5,'Wells Fargo'!$A:$A,AX$1,'Wells Fargo'!$B:$B,"<="&'Cash Flow'!AX$3,'Wells Fargo'!$B:$B,">"&'Cash Flow'!AW$3) -> 0 | AY5: =SUMIFS('Wells Fargo'!$F:$F,'Wells Fargo'!$G:$G,'Cash Flow'!$A5,'Wells Fargo'!$A:$A,AY$1,'Wells Fargo'!$B:$B,"<="&'Cash Flow'!AY$3,'Wells Fargo'!$B:$B,">"&'Cash Flow'!AX$3) -> 0 | AZ5: =SUMIFS('Wells Fargo'!$F:$F,'Wells Fargo'!$G:$G,'Cash Flow'!$A5,'Wells Fargo'!$A:$A,AZ$1,'Wells Fargo'!$B:$B,"<="&'Cash Flow'!AZ$3) -> 0 | BA5: =SUMIFS('Wells Fargo'!$F:$F,'Wells Fargo'!$G:$G,'Cash Flow'!$A5,'Wells Fargo'!$A:$A,BA$1,'Wells Fargo'!$B:$B,"<="&'Cash Flow'!BA$3,'Wells Fargo'!$B:$B,">"&'Cash Flow'!AZ$3) -> 0 | BB5: =SUMIFS('Wells Fargo'!$F:$F,'Wells Fargo'!$G:$G,'Cash Flow'!$A5,'Wells Fargo'!$A:$A,BB$1,'Wells Fargo'!$B:$B,"<="&'Cash Flow'!BB$3,'Wells Fargo'!$B:$B,">"&'Cash Flow'!BA$3) -> 0 | BC5: =SUMIFS('Wells Fargo'!$F:$F,'Wells Fargo'!$G:$G,'Cash Flow'!$A5,'Wells Fargo'!$A:$A,BC$1,'Wells Fargo'!$B:$B,"<="&'Cash Flow'!BC$3,'Wells Fargo'!$B:$B,">"&'Cash Flow'!BB$3) -> 0 | BD5: =SUMIFS('Wells Fargo'!$F:$F,'Wells Fargo'!$G:$G,'Cash Flow'!$A5,'Wells Fargo'!$A:$A,BD$1,'Wells Fargo'!$B:$B,"<="&'Cash Flow'!BD$3,'Wells Fargo'!$B:$B,">"&'Cash Flow'!BC$3) -> 0 | BE5: =SUMIFS('Wells Fargo'!$F:$F,'Wells Fargo'!$G:$G,'Cash Flow'!$A5,'Wells Fargo'!$A:$A,BE$1,'Wells Fargo'!$B:$B,"<="&'Cash Flow'!BE$3) -> 0 | BF5: =SUMIFS('Wells Fargo'!$F:$F,'Wells Fargo'!$G:$G,'Cash Flow'!$A5,'Wells Fargo'!$A:$A,BF$1,'Wells Fargo'!$B:$B,"<="&'Cash Flow'!BF$3,'Wells Fargo'!$B:$B,">"&'Cash Flow'!BE$3) -> 0 | BG5: =SUMIFS('Wells Fargo'!$F:$F,'Wells Fargo'!$G:$G,'Cash Flow'!$A5,'Wells Fargo'!$A:$A,BG$1,'Wells Fargo'!$B:$B,"<="&'Cash Flow'!BG$3,'Wells Fargo'!$B:$B,">"&'Cash Flow'!BF$3) -> 0 | BH5: =SUMIFS('Wells Fargo'!$F:$F,'Wells Fargo'!$G:$G,'Cash Flow'!$A5,'Wells Fargo'!$A:$A,BH$1,'Wells Fargo'!$B:$B,"<="&'Cash Flow'!BH$3,'Wells Fargo'!$B:$B,">"&'Cash Flow'!BG$3) -> 0 | BI5: =SUMIFS('Wells Fargo'!$F:$F,'Wells Fargo'!$G:$G,'Cash Flow'!$A5,'Wells Fargo'!$A:$A,BI$1,'Wells Fargo'!$B:$B,"<="&'Cash Flow'!BI$3,'Wells Fargo'!$B:$B,">"&'Cash Flow'!BH$3) -> 0
A6: Amar - Water | B6: =SUM(C6:BI6) -> -400 | C6: =SUMIFS('Wells Fargo'!$F:$F,'Wells Fargo'!$G:$G,'Cash Flow'!$A6,'Wells Fargo'!$A:$A,C$1,'Wells Fargo'!$B:$B,"<="&'Cash Flow'!C$3) -> 0 | D6: =SUMIFS('Wells Fargo'!$F:$F,'Wells Fargo'!$G:$G,'Cash Flow'!$A6,'Wells Fargo'!$A:$A,D$1,'Wells Fargo'!$B:$B,"<="&'Cash Flow'!D$3,'Wells Fargo'!$B:$B,">"&'Cash Flow'!C$3) -> 0 | E6: =SUMIFS('Wells Fargo'!$F:$F,'Wells Fargo'!$G:$G,'Cash Flow'!$A6,'Wells Fargo'!$A:$A,E$1,'Wells Fargo'!$B:$B,"<="&'Cash Flow'!E$3,'Wells Fargo'!$B:$B,">"&'Cash Flow'!D$3) -> 0 | F6: =SUMIFS('Wells Fargo'!$F:$F,'Wells Fargo'!$G:$G,'Cash Flow'!$A6,'Wells Fargo'!$A:$A,F$1,'Wells Fargo'!$B:$B,"<="&'Cash Flow'!F$3,'Wells Fargo'!$B:$B,">"&'Cash Flow'!E$3) -> 0 | G6: =SUMIFS('Wells Fargo'!$F:$F,'Wells Fargo'!$G:$G,'Cash Flow'!$A6,'Wells Fargo'!$A:$A,G$1,'Wells Fargo'!$B:$B,"<="&'Cash Flow'!G$3,'Wells Fargo'!$B:$B,">"&'Cash Flow'!F$3) -> 0 | H6: =SUMIFS('Wells Fargo'!$F:$F,'Wells Fargo'!$G:$G,'Cash Flow'!$A6,'Wells Fargo'!$A:$A,H$1,'Wells Fargo'!$B:$B,"<="&'Cash Flow'!H$3) -> 0 | I6: =SUMIFS('Wells Fargo'!$F:$F,'Wells Fargo'!$G:$G,'Cash Flow'!$A6,'Wells Fargo'!$A:$A,I$1,'Wells Fargo'!$B:$B,"<="&'Cash Flow'!I$3,'Wells Fargo'!$B:$B,">"&'Cash Flow'!H$3) -> 0 | J6: =SUMIFS('Wells Fargo'!$F:$F,'Wells Fargo'!$G:$G,'Cash Flow'!$A6,'Wells Fargo'!$A:$A,J$1,'Wells Fargo'!$B:$B,"<="&'Cash Flow'!J$3,'Wells Fargo'!$B:$B,">"&'Cash Flow'!I$3) -> 0 | K6: =SUMIFS('Wells Fargo'!$F:$F,'Wells Fargo'!$G:$G,'Cash Flow'!$A6,'Wells Fargo'!$A:$A,K$1,'Wells Fargo'!$B:$B,"<="&'Cash Flow'!K$3,'Wells Fargo'!$B:$B,">"&'Cash Flow'!J$3) -> 0 | L6: =SUMIFS('Wells Fargo'!$F:$F,'Wells Fargo'!$G:$G,'Cash Flow'!$A6,'Wells Fargo'!$A:$A,L$1,'Wells Fargo'!$B:$B,"<="&'Cash Flow'!L$3) -> 0 | M6: =SUMIFS('Wells Fargo'!$F:$F,'Wells Fargo'!$G:$G,'Cash Flow'!$A6,'Wells Fargo'!$A:$A,M$1,'Wells Fargo'!$B:$B,"<="&'Cash Flow'!M$3,'Wells Fargo'!$B:$B,">"&'Cash Flow'!L$3) -> -150 | N6: =SUMIFS('Wells Fargo'!$F:$F,'Wells Fargo'!$G:$G,'Cash Flow'!$A6,'Wells Fargo'!$A:$A,N$1,'Wells Fargo'!$B:$B,"<="&'Cash Flow'!N$3,'Wells Fargo'!$B:$B,">"&'Cash Flow'!M$3) -> 0 | O6: =SUMIFS('Wells Fargo'!$F:$F,'Wells Fargo'!$G:$G,'Cash Flow'!$A6,'Wells Fargo'!$A:$A,O$1,'Wells Fargo'!$B:$B,"<="&'Cash Flow'!O$3,'Wells Fargo'!$B:$B,">"&'Cash Flow'!N$3) -> 0 | P6: =SUMIFS('Wells Fargo'!$F:$F,'Wells Fargo'!$G:$G,'Cash Flow'!$A6,'Wells Fargo'!$A:$A,P$1,'Wells Fargo'!$B:$B,"<="&'Cash Flow'!P$3,'Wells Fargo'!$B:$B,">"&'Cash Flow'!O$3) -> 0 | Q6: =SUMIFS('Wells Fargo'!$F:$F,'Wells Fargo'!$G:$G,'Cash Flow'!$A6,'Wells Fargo'!$A:$A,Q$1,'Wells Fargo'!$B:$B,"<="&'Cash Flow'!Q$3) -> 0 | R6: =SUMIFS('Wells Fargo'!$F:$F,'Wells Fargo'!$G:$G,'Cash Flow'!$A6,'Wells Fargo'!$A:$A,R$1,'Wells Fargo'!$B:$B,"<="&'Cash Flow'!R$3,'Wells Fargo'!$B:$B,">"&'Cash Flow'!Q$3) -> 0 | S6: =SUMIFS('Wells Fargo'!$F:$F,'Wells Fargo'!$G:$G,'Cash Flow'!$A6,'Wells Fargo'!$A:$A,S$1,'Wells Fargo'!$B:$B,"<="&'Cash Flow'!S$3,'Wells Fargo'!$B:$B,">"&'Cash Flow'!R$3) -> -100 | T6: =SUMIFS('Wells Fargo'!$F:$F,'Wells Fargo'!$G:$G,'Cash Flow'!$A6,'Wells Fargo'!$A:$A,T$1,'Wells Fargo'!$B:$B,"<="&'Cash Flow'!T$3,'Wells Fargo'!$B:$B,">"&'Cash Flow'!S$3) -> 0 | U6: =SUMIFS('Wells Fargo'!$F:$F,'Wells Fargo'!$G:$G,'Cash Flow'!$A6,'Wells Fargo'!$A:$A,U$1,'Wells Fargo'!$B:$B,"<="&'Cash Flow'!U$3,'Wells Fargo'!$B:$B,">"&'Cash Flow'!T$3) -> 0 | V6: =SUMIFS('Wells Fargo'!$F:$F,'Wells Fargo'!$G:$G,'Cash Flow'!$A6,'Wells Fargo'!$A:$A,V$1,'Wells Fargo'!$B:$B,"<="&'Cash Flow'!V$3) -> 0 | W6: =SUMIFS('Wells Fargo'!$F:$F,'Wells Fargo'!$G:$G,'Cash Flow'!$A6,'Wells Fargo'!$A:$A,W$1,'Wells Fargo'!$B:$B,"<="&'Cash Flow'!W$3,'Wells Fargo'!$B:$B,">"&'Cash Flow'!V$3) -> -150 | X6: =SUMIFS('Wells Fargo'!$F:$F,'Wells Fargo'!$G:$G,'Cash Flow'!$A6,'Wells Fargo'!$A:$A,X$1,'Wells Fargo'!$B:$B,"<="&'Cash Flow'!X$3,'Wells Fargo'!$B:$B,">"&'Cash Flow'!W$3) -> 0 | Y6: =SUMIFS('Wells Fargo'!$F:$F,'Wells Fargo'!$G:$G,'Cash Flow'!$A6,'Wells Fargo'!$A:$A,Y$1,'Wells Fargo'!$B:$B,"<="&'Cash Flow'!Y$3,'Wells Fargo'!$B:$B,">"&'Cash Flow'!X$3) -> 0 | Z6: =SUMIFS('Wells Fargo'!$F:$F,'Wells Fargo'!$G:$G,'Cash Flow'!$A6,'Wells Fargo'!$A:$A,Z$1,'Wells Fargo'!$B:$B,"<="&'Cash Flow'!Z$3,'Wells Fargo'!$B:$B,">"&'Cash Flow'!Y$3) -> 0 | AA6: =SUMIFS('Wells Fargo'!$F:$F,'Wells Fargo'!$G:$G,'Cash Flow'!$A6,'Wells Fargo'!$A:$A,AA$1,'Wells Fargo'!$B:$B,"<="&'Cash Flow'!AA$3) -> 0 | AB6: =SUMIFS('Wells Fargo'!$F:$F,'Wells Fargo'!$G:$G,'Cash Flow'!$A6,'Wells Fargo'!$A:$A,AB$1,'Wells Fargo'!$B:$B,"<="&'Cash Flow'!AB$3,'Wells Fargo'!$B:$B,">"&'Cash Flow'!AA$3) -> 0 | AC6: =SUMIFS('Wells Fargo'!$F:$F,'Wells Fargo'!$G:$G,'Cash Flow'!$A6,'Wells Fargo'!$A:$A,AC$1,'Wells Fargo'!$B:$B,"<="&'Cash Flow'!AC$3,'Wells Fargo'!$B:$B,">"&'Cash Flow'!AB$3) -> 0 | AD6: =SUMIFS('Wells Fargo'!$F:$F,'Wells Fargo'!$G:$G,'Cash Flow'!$A6,'Wells Fargo'!$A:$A,AD$1,'Wells Fargo'!$B:$B,"<="&'Cash Flow'!AD$3,'Wells Fargo'!$B:$B,">"&'Cash Flow'!AC$3) -> 0 | AE6: =SUMIFS('Wells Fargo'!$F:$F,'Wells Fargo'!$G:$G,'Cash Flow'!$A6,'Wells Fargo'!$A:$A,AE$1,'Wells Fargo'!$B:$B,"<="&'Cash Flow'!AE$3,'Wells Fargo'!$B:$B,">"&'Cash Flow'!AD$3) -> 0 | AF6: =SUMIFS('Wells Fargo'!$F:$F,'Wells Fargo'!$G:$G,'Cash Flow'!$A6,'Wells Fargo'!$A:$A,AF$1,'Wells Fargo'!$B:$B,"<="&'Cash Flow'!AF$3) -> 0 | AG6: =SUMIFS('Wells Fargo'!$F:$F,'Wells Fargo'!$G:$G,'Cash Flow'!$A6,'Wells Fargo'!$A:$A,AG$1,'Wells Fargo'!$B:$B,"<="&'Cash Flow'!AG$3,'Wells Fargo'!$B:$B,">"&'Cash Flow'!AF$3) -> 0 | AH6: =SUMIFS('Wells Fargo'!$F:$F,'Wells Fargo'!$G:$G,'Cash Flow'!$A6,'Wells Fargo'!$A:$A,AH$1,'Wells Fargo'!$B:$B,"<="&'Cash Flow'!AH$3,'Wells Fargo'!$B:$B,">"&'Cash Flow'!AG$3) -> 0 | AI6: =SUMIFS('Wells Fargo'!$F:$F,'Wells Fargo'!$G:$G,'Cash Flow'!$A6,'Wells Fargo'!$A:$A,AI$1,'Wells Fargo'!$B:$B,"<="&'Cash Flow'!AI$3,'Wells Fargo'!$B:$B,">"&'Cash Flow'!AH$3) -> 0 | AJ6: =SUMIFS('Wells Fargo'!$F:$F,'Wells Fargo'!$G:$G,'Cash Flow'!$A6,'Wells Fargo'!$A:$A,AJ$1,'Wells Fargo'!$B:$B,"<="&'Cash Flow'!AJ$3,'Wells Fargo'!$B:$B,">"&'Cash Flow'!AI$3) -> 0 | AK6: =SUMIFS('Wells Fargo'!$F:$F,'Wells Fargo'!$G:$G,'Cash Flow'!$A6,'Wells Fargo'!$A:$A,AK$1,'Wells Fargo'!$B:$B,"<="&'Cash Flow'!AK$3) -> 0 | AL6: =SUMIFS('Wells Fargo'!$F:$F,'Wells Fargo'!$G:$G,'Cash Flow'!$A6,'Wells Fargo'!$A:$A,AL$1,'Wells Fargo'!$B:$B,"<="&'Cash Flow'!AL$3,'Wells Fargo'!$B:$B,">"&'Cash Flow'!AK$3) -> 0 | AM6: =SUMIFS('Wells Fargo'!$F:$F,'Wells Fargo'!$G:$G,'Cash Flow'!$A6,'Wells Fargo'!$A:$A,AM$1,'Wells Fargo'!$B:$B,"<="&'Cash Flow'!AM$3,'Wells Fargo'!$B:$B,">"&'Cash Flow'!AL$3) -> 0 | AN6: =SUMIFS('Wells Fargo'!$F:$F,'Wells Fargo'!$G:$G,'Cash Flow'!$A6,'Wells Fargo'!$A:$A,AN$1,'Wells Fargo'!$B:$B,"<="&'Cash Flow'!AN$3,'Wells Fargo'!$B:$B,">"&'Cash Flow'!AM$3) -> 0 | AO6: =SUMIFS('Wells Fargo'!$F:$F,'Wells Fargo'!$G:$G,'Cash Flow'!$A6,'Wells Fargo'!$A:$A,AO$1,'Wells Fargo'!$B:$B,"<="&'Cash Flow'!AO$3,'Wells Fargo'!$B:$B,">"&'Cash Flow'!AN$3) -> 0 | AP6: =SUMIFS('Wells Fargo'!$F:$F,'Wells Fargo'!$G:$G,'Cash Flow'!$A6,'Wells Fargo'!$A:$A,AP$1,'Wells Fargo'!$B:$B,"<="&'Cash Flow'!AP$3) -> 0 | AQ6: =SUMIFS('Wells Fargo'!$F:$F,'Wells Fargo'!$G:$G,'Cash Flow'!$A6,'Wells Fargo'!$A:$A,AQ$1,'Wells Fargo'!$B:$B,"<="&'Cash Flow'!AQ$3,'Wells Fargo'!$B:$B,">"&'Cash Flow'!AP$3) -> 0 | AR6: =SUMIFS('Wells Fargo'!$F:$F,'Wells Fargo'!$G:$G,'Cash Flow'!$A6,'Wells Fargo'!$A:$A,AR$1,'Wells Fargo'!$B:$B,"<="&'Cash Flow'!AR$3,'Wells Fargo'!$B:$B,">"&'Cash Flow'!AQ$3) -> 0 | AS6: =SUMIFS('Wells Fargo'!$F:$F,'Wells Fargo'!$G:$G,'Cash Flow'!$A6,'Wells Fargo'!$A:$A,AS$1,'Wells Fargo'!$B:$B,"<="&'Cash Flow'!AS$3,'Wells Fargo'!$B:$B,">"&'Cash Flow'!AR$3) -> 0 | AT6: =SUMIFS('Wells Fargo'!$F:$F,'Wells Fargo'!$G:$G,'Cash Flow'!$A6,'Wells Fargo'!$A:$A,AT$1,'Wells Fargo'!$B:$B,"<="&'Cash Flow'!AT$3,'Wells Fargo'!$B:$B,">"&'Cash Flow'!AS$3) -> 0 | AU6: =SUMIFS('Wells Fargo'!$F:$F,'Wells Fargo'!$G:$G,'Cash Flow'!$A6,'Wells Fargo'!$A:$A,AU$1,'Wells Fargo'!$B:$B,"<="&'Cash Flow'!AU$3) -> 0 | AV6: =SUMIFS('Wells Fargo'!$F:$F,'Wells Fargo'!$G:$G,'Cash Flow'!$A6,'Wells Fargo'!$A:$A,AV$1,'Wells Fargo'!$B:$B,"<="&'Cash Flow'!AV$3,'Wells Fargo'!$B:$B,">"&'Cash Flow'!AU$3) -> 0 | AW6: =SUMIFS('Wells Fargo'!$F:$F,'Wells Fargo'!$G:$G,'Cash Flow'!$A6,'Wells Fargo'!$A:$A,AW$1,'Wells Fargo'!$B:$B,"<="&'Cash Flow'!AW$3,'Wells Fargo'!$B:$B,">"&'Cash Flow'!AV$3) -> 0 | AX6: =SUMIFS('Wells Fargo'!$F:$F,'Wells Fargo'!$G:$G,'Cash Flow'!$A6,'Wells Fargo'!$A:$A,AX$1,'Wells Fargo'!$B:$B,"<="&'Cash Flow'!AX$3,'Wells Fargo'!$B:$B,">"&'Cash Flow'!AW$3) -> 0 | AY6: =SUMIFS('Wells Fargo'!$F:$F,'Wells Fargo'!$G:$G,'Cash Flow'!$A6,'Wells Fargo'!$A:$A,AY$1,'Wells Fargo'!$B:$B,"<="&'Cash Flow'!AY$3,'Wells Fargo'!$B:$B,">"&'Cash Flow'!AX$3) -> 0 | AZ6: =SUMIFS('Wells Fargo'!$F:$F,'Wells Fargo'!$G:$G,'Cash Flow'!$A6,'Wells Fargo'!$A:$A,AZ$1,'Wells Fargo'!$B:$B,"<="&'Cash Flow'!AZ$3) -> 0 | BA6: =SUMIFS('Wells Fargo'!$F:$F,'Wells Fargo'!$G:$G,'Cash Flow'!$A6,'Wells Fargo'!$A:$A,BA$1,'Wells Fargo'!$B:$B,"<="&'Cash Flow'!BA$3,'Wells Fargo'!$B:$B,">"&'Cash Flow'!AZ$3) -> 0 | BB6: =SUMIFS('Wells Fargo'!$F:$F,'Wells Fargo'!$G:$G,'Cash Flow'!$A6,'Wells Fargo'!$A:$A,BB$1,'Wells Fargo'!$B:$B,"<="&'Cash Flow'!BB$3,'Wells Fargo'!$B:$B,">"&'Cash Flow'!BA$3) -> 0 | BC6: =SUMIFS('Wells Fargo'!$F:$F,'Wells Fargo'!$G:$G,'Cash Flow'!$A6,'Wells Fargo'!$A:$A,BC$1,'Wells Fargo'!$B:$B,"<="&'Cash Flow'!BC$3,'Wells Fargo'!$B:$B,">"&'Cash Flow'!BB$3) -> 0 | BD6: =SUMIFS('Wells Fargo'!$F:$F,'Wells Fargo'!$G:$G,'Cash Flow'!$A6,'Wells Fargo'!$A:$A,BD$1,'Wells Fargo'!$B:$B,"<="&'Cash Flow'!BD$3,'Wells Fargo'!$B:$B,">"&'Cash Flow'!BC$3) -> 0 | BE6: =SUMIFS('Wells Fargo'!$F:$F,'Wells Fargo'!$G:$G,'Cash Flow'!$A6,'Wells Fargo'!$A:$A,BE$1,'Wells Fargo'!$B:$B,"<="&'Cash Flow'!BE$3) -> 0 | BF6: =SUMIFS('Wells Fargo'!$F:$F,'Wells Fargo'!$G:$G,'Cash Flow'!$A6,'Wells Fargo'!$A:$A,BF$1,'Wells Fargo'!$B:$B,"<="&'Cash Flow'!BF$3,'Wells Fargo'!$B:$B,">"&'Cash Flow'!BE$3) -> 0 | BG6: =SUMIFS('Wells Fargo'!$F:$F,'Wells Fargo'!$G:$G,'Cash Flow'!$A6,'Wells Fargo'!$A:$A,BG$1,'Wells Fargo'!$B:$B,"<="&'Cash Flow'!BG$3,'Wells Fargo'!$B:$B,">"&'Cash Flow'!BF$3) -> 0 | BH6: =SUMIFS('Wells Fargo'!$F:$F,'Wells Fargo'!$G:$G,'Cash Flow'!$A6,'Wells Fargo'!$A:$A,BH$1,'Wells Fargo'!$B:$B,"<="&'Cash Flow'!BH$3,'Wells Fargo'!$B:$B,">"&'Cash Flow'!BG$3) -> 0 | BI6: =SUMIFS('Wells Fargo'!$F:$F,'Wells Fargo'!$G:$G,'Cash Flow'!$A6,'Wells Fargo'!$A:$A,BI$1,'Wells Fargo'!$B:$B,"<="&'Cash Flow'!BI$3,'Wells Fargo'!$B:$B,">"&'Cash Flow'!BH$3) -> 0
