Workbook
Name Categories: OFFSET(Categories_deprecated_2jdI!$J$7,0,0,COUNTIF(Categories_deprecated_2jdI!$J$7:$J$44,"<>"&"--"),1)
Name CategoryIdentifiers: Categories!$B$8:$B$100
Name CategoryNames: Categories!$C$8:$C$100
Name FrequencyKey: RecurringExpenses!$X$8:$X$11
Name FrequencyValue: RecurringExpenses!$Y$8:$Y$11
Name HiddenCategoriesCategoryNames: _xlfn.ANCHORARRAY(HiddenCategories!$B$2)
Name HiddenCategoriesSubcategoryNames: HiddenCategories!$C$2:$C$100
Name HiddenCategoriesSubcategoryNamesRows: HiddenCategories!$C$2:$CX$100
Name Months: OFFSET(Snapshot!$V$7,0,0,COUNTIF(Snapshot!$V$7:$V$200,"<>"&"--"),1)
Name snapshot_month: Snapshot!$Q$4
Name SubcategoryNames: Categories!$I$8:$I$100
Name user_custom_categories: Categories_deprecated_2jdI!$C$25:$E$44

Sheet Transactions
B2: Transactions
B3: Transactions from your added accounts are automatically imported here. Click Update in the task pane to import more transactions. Edit the Merchant and Category columns to better reflect where and how you spend your money.
B6: Date | C6: Merchant | D6: Category | E6: Subcategory | F6: Amount $ | G6: Account | H6: Account Number | I6: Institution | J6: Transaction_ID | K6: Account_ID | L6: Institution_ID | M6: Category Type | N6: Date_Day | O6: Date_Month | P6: Date_Year | Q6: Beginning of Week | R6: Month
B7: 44302 | C7: Atm Cash Withdrawal Aspen | D7: Transfer | F7: -200 | J7: 985572e216794b238fa7213245412ee0 | K7: 0ced1dbbb4a747578f3268aacbdce68e | L7: 0223204f73754797a10ae9c56a61ed0d | M7: {=IFERROR(INDEX(CategoriesTable[Category type],MATCH(Table1[[#This Row],[Category]],CategoriesTable[Category name],0),0),"")} -> Transfer | N7: 16 | O7: =MONTH(Table1[[#This Row],[Date]]) -> 4 | P7: 2021 | Q7: =IF(ISBLANK(Table1[[#This Row],[Date]]),"",Table1[[#This Row],[Date]]-WEEKDAY(Table1[[#This Row],[Date]],2)+1) -> 44298 | R7: =IF(ISBLANK(Table1[[#This Row],[Date]]),"",DATE(Table1[[#This Row],[Date_Year]],Table1[[#This Row],[Date_Month]],1)) -> 44287
B8: 44301 | C8: Electronic Debit Transamerica Ins | D8: Bills/Utilities | F8: -10.9 | J8: 8f8a985455a44a4ea7676fcc75a84c51 | K8: 0ced1dbbb4a747578f3268aacbdce68e | L8: 0223204f73754797a10ae9c56a61ed0d | M8: {=IFERROR(INDEX(CategoriesTable[Category type],MATCH(Table1[[#This Row],[Category]],CategoriesTable[Category name],0),0),"")} -> Expense | N8: 15 | O8: =MONTH(Table1[[#This Row],[Date]]) -> 4 | P8: 2021 | Q8: =IF(ISBLANK(Table1[[#This Row],[Date]]),"",Table1[[#This Row],[Date]]-WEEKDAY(Table1[[#This Row],[Date]],2)+1) -> 44298 | R8: =IF(ISBLANK(Table1[[#This Row],[Date]]),"",DATE(Table1[[#This Row],[Date_Year]],Table1[[#This Row],[Date_Month]],1)) -> 44287
B9: 44294 | C9: XBOX Live | D9: Entertainment | F9: -10.59 | J9: 5eba4e9093fe4a9f99d838f562920cbd | K9: 0ced1dbbb4a747578f3268aacbdce68e | L9: 0223204f73754797a10ae9c56a61ed0d | M9: {=IFERROR(INDEX(CategoriesTable[Category type],MATCH(Table1[[#This Row],[Category]],CategoriesTable[Category name],0),0),"")} -> Expense | N9: 8 | O9: =MONTH(Table1[[#This Row],[Date]]) -> 4 | P9: 2021 | Q9: =IF(ISBLANK(Table1[[#This Row],[Date]]),"",Table1[[#This Row],[Date]]-WEEKDAY(Table1[[#This Row],[Date]],2)+1) -> 44291 | R9: =IF(ISBLANK(Table1[[#This Row],[Date]]),"",DATE(Table1[[#This Row],[Date_Year]],Table1[[#This Row],[Date_Month]],1)) -> 44287
B10: 44292 | C10: Verizon | D10: Bills/Utilities | F10: -326.03 | J10: ee49fc1d1a9243b58afc9b778fb8afac | K10: 0ced1dbbb4a747578f3268aacbdce68e | L10: 0223204f73754797a10ae9c56a61ed0d | M10: {=IFERROR(INDEX(CategoriesTable[Category type],MATCH(Table1[[#This Row],[Category]],CategoriesTable[Category name],0),0),"")} -> Expense | N10: 6 | O10: =MONTH(Table1[[#This Row],[Date]]) -> 4 | P10: 2021 | Q10: =IF(ISBLANK(Table1[[#This Row],[Date]]),"",Table1[[#This Row],[Date]]-WEEKDAY(Table1[[#This Row],[Date]],2)+1) -> 44291 | R10: =IF(ISBLANK(Table1[[#This Row],[Date]]),"",DATE(Table1[[#This Row],[Date_Year]],Table1[[#This Row],[Date_Month]],1)) -> 44287
B11: 44291 | C11: Atm Cash Withdrawal Aspen | D11: Transfer | F11: -160 | J11: 539dad513aac4b72a195f704cd2d6ca4 | K11: 0ced1dbbb4a747578f3268aacbdce68e | L11: 0223204f73754797a10ae9c56a61ed0d | M11: {=IFERROR(INDEX(CategoriesTable[Category type],MATCH(Table1[[#This Row],[Category]],CategoriesTable[Category name],0),0),"")} -> Transfer | N11: 5 | O11: =MONTH(Table1[[#This Row],[Date]]) -> 4 | P11: 2021 | Q11: =IF(ISBLANK(Table1[[#This Row],[Date]]),"",Table1[[#This Row],[Date]]-WEEKDAY(Table1[[#This Row],[Date]],2)+1) -> 44291 | R11: =IF(ISBLANK(Table1[[#This Row],[Date]]),"",DATE(Table1[[#This Row],[Date_Year]],Table1[[#This Row],[Date_Month]],1)) -> 44287
B12: 44291 | C12: Netflix | D12: Bills/Utilities | F12: -19.07 | J12: ede53e3ac5064dc1a5c3dad531e6647b | K12: 0ced1dbbb4a747578f3268aacbdce68e | L12: 0223204f73754797a10ae9c56a61ed0d | M12: {=IFERROR(INDEX(CategoriesTable[Category type],MATCH(Table1[[#This Row],[Category]],CategoriesTable[Category name],0),0),"")} -> Expense | N12: 5 | O12: =MONTH(Table1[[#This Row],[Date]]) -> 4 | P12: 2021 | Q12: =IF(ISBLANK(Table1[[#This Row],[Date]]),"",Table1[[#This Row],[Date]]-WEEKDAY(Table1[[#This Row],[Date]],2)+1) -> 44291 | R12: =IF(ISBLANK(Table1[[#This Row],[Date]]),"",DATE(Table1[[#This Row],[Date_Year]],Table1[[#This Row],[Date_Month]],1)) -> 44287
B13: 44289 | C13: Cinnabon | D13: Restaurants/Dining | F13: -25.97 | J13: 4dd1e4b6530548948e5422244c00fed8 | K13: 0ced1dbbb4a747578f3268aacbdce68e | L13: 0223204f73754797a10ae9c56a61ed0d | M13: {=IFERROR(INDEX(CategoriesTable[Category type],MATCH(Table1[[#This Row],[Category]],CategoriesTable[Category name],0),0),"")} -> Expense | N13: 3 | O13: =MONTH(Table1[[#This Row],[Date]]) -> 4 | P13: 2021 | Q13: =IF(ISBLANK(Table1[[#This Row],[Date]]),"",Table1[[#This Row],[Date]]-WEEKDAY(Table1[[#This Row],[Date]],2)+1) -> 44284 | R13: =IF(ISBLANK(Table1[[#This Row],[Date]]),"",DATE(Table1[[#This Row],[Date_Year]],Table1[[#This Row],[Date_Month]],1)) -> 44287
B14: 44288 | C14: CVS Care Pass | D14: Shopping | F14: -5.3 | J14: 6a91c9cd36f142ed96634e1f701a58f6 | K14: 0ced1dbbb4a747578f3268aacbdce68e | L14: 0223204f73754797a10ae9c56a61ed0d | M14: {=IFERROR(INDEX(CategoriesTable[Category type],MATCH(Table1[[#This Row],[Category]],CategoriesTable[Category name],0),0),"")} -> Expense | N14: 2 | O14: =MONTH(Table1[[#This Row],[Date]]) -> 4 | P14: 2021 | Q14: =IF(ISBLANK(Table1[[#This Row],[Date]]),"",Table1[[#This Row],[Date]]-WEEKDAY(Table1[[#This Row],[Date]],2)+1) -> 44284 | R14: =IF(ISBLANK(Table1[[#This Row],[Date]]),"",DATE(Table1[[#This Row],[Date_Year]],Table1[[#This Row],[Date_Month]],1)) -> 44287
B15: 44288 | C15: 7 Eleven | D15: Restaurants/Dining | F15: -16.76 | J15: fd7d2fd0c9ca4bd9ab4782bc4771e628 | K15: 0ced1dbbb4a747578f3268aacbdce68e | L15: 0223204f73754797a10ae9c56a61ed0d | M15: {=IFERROR(INDEX(CategoriesTable[Category type],MATCH(Table1[[#This Row],[Category]],CategoriesTable[Category name],0),0),"")} -> Expense | N15: 2 | O15: =MONTH(Table1[[#This Row],[Date]]) -> 4 | P15: 2021 | Q15: =IF(ISBLANK(Table1[[#This Row],[Date]]),"",Table1[[#This Row],[Date]]-WEEKDAY(Table1[[#This Row],[Date]],2)+1) -> 44284 | R15: =IF(ISBLANK(Table1[[#This Row],[Date]]),"",DATE(Table1[[#This Row],[Date_Year]],Table1[[#This Row],[Date_Month]],1)) -> 44287
B16: 44288 | C16: Point Of Sale Debit | D16: Auto/Transport | F16: -2500 | J16: 3821a77aaba34a279fe744b4121cce26 | K16: 0ced1dbbb4a747578f3268aacbdce68e | L16: 0223204f73754797a10ae9c56a61ed0d | M16: {=IFERROR(INDEX(CategoriesTable[Category type],MATCH(Table1[[#This Row],[Category]],CategoriesTable[Category name],0),0),"")} -> Expense | N16: 2 | O16: =MONTH(Table1[[#This Row],[Date]]) -> 4 | P16: 2021 | Q16: =IF(ISBLANK(Table1[[#This Row],[Date]]),"",Table1[[#This Row],[Date]]-WEEKDAY(Table1[[#This Row],[Date]],2)+1) -> 44284 | R16: =IF(ISBLANK(Table1[[#This Row],[Date]]),"",DATE(Table1[[#This Row],[Date_Year]],Table1[[#This Row],[Date_Month]],1)) -> 44287
B17: 44287 | C17: Amercican Home Shield | D17: Bills/Utilities | F17: -54.99 | J17: 7b73ea380fe54ba8b6cf0298c5a4e78a | K17: 0ced1dbbb4a747578f3268aacbdce68e | L17: 0223204f73754797a10ae9c56a61ed0d | M17: {=IFERROR(INDEX(CategoriesTable[Category type],MATCH(Table1[[#This Row],[Category]],CategoriesTable[Category name],0),0),"")} -> Expense | N17: 1 | O17: =MONTH(Table1[[#This Row],[Date]]) -> 4 | P17: 2021 | Q17: =IF(ISBLANK(Table1[[#This Row],[Date]]),"",Table1[[#This Row],[Date]]-WEEKDAY(Table1[[#This Row],[Date]],2)+1) -> 44284 | R17: =IF(ISBLANK(Table1[[#This Row],[Date]]),"",DATE(Table1[[#This Row],[Date_Year]],Table1[[#This Row],[Date_Month]],1)) -> 44287
B18: 44287 | C18: Electronic Credit TreasXxciv Serv | D18: Income | F18: 4433.04 | J18: 54e8ad2e0b5345eb9ae1a55dd18e6af1 | K18: 0ced1dbbb4a747578f3268aacbdce68e | L18: 0223204f73754797a10ae9c56a61ed0d | M18: {=IFERROR(INDEX(CategoriesTable[Category type],MATCH(Table1[[#This Row],[Category]],CategoriesTable[Category name],0),0),"")} -> Income | N18: 1 | O18: =MONTH(Table1[[#This Row],[Date]]) -> 4 | P18: 2021 | Q18: =IF(ISBLANK(Table1[[#This Row],[Date]]),"",Table1[[#This Row],[Date]]-WEEKDAY(Table1[[#This Row],[Date]],2)+1) -> 44284 | R18: =IF(ISBLANK(Table1[[#This Row],[Date]]),"",DATE(Table1[[#This Row],[Date_Year]],Table1[[#This Row],[Date_Month]],1)) -> 44287
... B1250: 43763 | C1250: Check Card Purchase Subway | D1250: Restaurants/Dining | F1250: -16.39 | J1250: 73ee7a71ccf94f14b5b1fcbc03c88b9a | K1250: 0ced1dbbb4a747578f3268aacbdce68e | L1250: 0223204f73754797a10ae9c56a61ed0d | M1250: {=IFERROR(INDEX(CategoriesTable[Category type],MATCH(Table1[[#This Row],[Category]],CategoriesTable[Category name],0),0),"")} -> Expense | N1250: 25 | O1250: =MONTH(Table1[[#This Row],[Date]]) -> 10 | P1250: 2019 | Q1250: =IF(ISBLANK(Table1[[#This Row],[Date]]),"",Table1[[#This Row],[Date]]-WEEKDAY(Table1[[#This Row],[Date]],2)+1) -> 43759 | R1250: =IF(ISBLANK(Table1[[#This Row],[Date]]),"",DATE(Table1[[#This Row],[Date_Year]],Table1[[#This Row],[Date_Month]],1)) -> 43739
M1251: {=IFERROR(INDEX(CategoriesTable[Category type],MATCH(Table1[[#This Row],[Category]],CategoriesTable[Category name],0),0),"")} | N1251: =DAY(Table1[[#This Row],[Date]]) -> 0 | O1251: =MONTH(Table1[[#This Row],[Date]]) -> 1 | P1251: =YEAR(Table1[[#This Row],[Date]]) -> 1900 | Q1251: =IF(ISBLANK(Table1[[#This Row],[Date]]),"",Table1[[#This Row],[Date]]-WEEKDAY(Table1[[#This Row],[Date]],2)+1) | R1251: =IF(ISBLANK(Table1[[#This Row],[Date]]),"",DATE(Table1[[#This Row],[Date_Year]],Table1[[#This Row],[Date_Month]],1))
L1252: {=IFERROR(INDEX(CategoriesTableLegacy[Category Type],MATCH(Table1[[#This Row],[Category]],CategoriesTableLegacy[Category Name],0),0),"")}

Sheet Spotify
A1: Spotify
A2: 44281 | B2: Spotify | C2: Bills/Utilities | E2: -10.59
A3: 44253 | B3: Spotify | C3: Bills/Utilities | E3: -9.99
A4: 44222 | B4: Spotify | C4: Bills/Utilities | E4: -9.99
A5: 44191 | B5: Spotify | C5: Bills/Utilities | E5: -9.99
A6: 44161 | B6: Spotify | C6: Bills/Utilities | E6: -9.99
A7: 44130 | B7: Spotify | C7: Bills/Utilities | E7: -9.99
A8: 44100 | B8: Spotify | C8: Bills/Utilities | E8: -9.99
A9: 44069 | B9: Spotify | C9: Bills/Utilities | E9: -9.99
A10: 44039 | B10: Spotify | C10: Fees/Charges | E10: -36
A11: 44008 | B11: Spotify | C11: Bills/Utilities | E11: -9.99
A12: 43977 | B12: Spotify | C12: Bills/Utilities | E12: -9.99
A13: 43947 | B13: Spotify | C13: Bills/Utilities | E13: -9.99
A14: 43916 | B14: Spotify | C14: Bills/Utilities | E14: -9.99

Sheet Verizon
A2: 44262 | B2: Verizon Wireless | C2: Bills/Utilities | E2: -123.2
A3: 44233 | B3: Verizon Wireless | C3: Bills/Utilities | E3: -123.2
A4: 44198 | B4: Verizon Wireless | C4: Bills/Utilities | E4: -123.02
A5: 44171 | B5: Verizon Wireless | C5: Bills/Utilities | E5: -123.02
A6: 44143 | B6: Verizon Wireless | C6: Bills/Utilities | E6: -123.02

Sheet Amazon Prime
A1: Amazon Prime
A2: 44255 | B2: Amazon Prime | C2: Shopping | E2: -12.99 | G2: Username:
A3: 44227 | B3: Amazon Prime | C3: Shopping | E3: -12.99 | G3: Password:
A4: 44196 | B4: Amazon Prime | C4: Shopping | E4: -12.99
A5: 44165 | B5: Amazon Prime | C5: Shopping | E5: -12.99
A6: 44135 | B6: Amazon Prime | C6: Shopping | E6: -12.99
A7: 44104 | B7: Amazon Prime | C7: Shopping | E7: -12.99
A8: 44074 | B8: Amazon Prime | C8: Shopping | E8: -12.99
A9: 44046 | B9: Amazon Prime | C9: Shopping | E9: -12.99
A10: 44012 | B10: Amazon Prime | C10: Shopping | E10: -12.99
A11: 43982 | B11: Amazon Prime | C11: Shopping | E11: -12.99
A12: 43951 | B12: Amazon Prime | C12: Shopping | E12: -12.99
A13: 43921 | B13: Amazon Prime | C13: Shopping | E13: -12.99
A14: 43890 | B14: Amazon Prime | C14: Shopping | E14: -12.99
A15: 43861 | B15: Amazon Prime | C15: Shopping | E15: -12.99
... A18: 43769 | B18: Amazon Prime | C18: Shopping | E18: -12.99

Sheet Shen Life
M1: Shen Life Insurance
M2: 44279 | N2: Electronic Debit Shen Life | O2: Bills/Utilities | Q2: -40.28
M3: 44251 | N3: Electronic Debit Shen Life | O3: Bills/Utilities | Q3: -40.28
M4: 44218 | N4: Electronic Debit Shen Life | O4: Bills/Utilities | Q4: -40.28
M5: 44188 | N5: Electronic Debit Shen Life | O5: Bills/Utilities | Q5: -40.28
M6: 44159 | N6: Electronic Debit Shen Life | O6: Bills/Utilities | Q6: -40.28
M7: 44126 | N7: Electronic Debit Shen Life | O7: Bills/Utilities | Q7: -40.28
M8: 44097 | N8: Electronic Debit Shen Life | O8: Bills/Utilities | Q8: -40.28
M9: 44067 | N9: Electronic Debit Shen Life | O9: Bills/Utilities | Q9: -40.28
M10: 44034 | N10: Electronic Debit Shen Life | O10: Bills/Utilities | Q10: -40.28
M11: 44006 | N11: Electronic Debit Shen Life | O11: Bills/Utilities | Q11: -40.28
M12: 43973 | N12: Electronic Debit Shen Life | O12: Bills/Utilities | Q12: -40.28
M13: 43943 | N13: Electronic Debit Shen Life | O13: Bills/Utilities | Q13: -40.28
... M18: 43791 | N18: Electronic Debit Shen Life | O18: Bills/Utilities | Q18: -40.28

Sheet Paymentus
K1: 44275 | L1: Check Card Purchase Paymentus | M1: Professional Services | O1: -3.95
K2: 44251 | L2: Check Card Purchase Paymentus | M2: Professional Services | O2: -3.95
K3: 44175 | L3: Check Card Purchase Paymentus | M3: Professional Services | O3: -3.95
K4: 44159 | L4: Check Card Purchase Paymentus | M4: Professional Services | O4: -3.95

Sheet TransAmerica
A1: TransAmerica Life Insurance
A2: 44301 | B2: Electronic Debit Transamerica Ins | C2: Bills/Utilities | E2: -10.9 | F2: =YEAR(A2) -> 2021 | I2: 2019 | J2: =SUMIFS(E:E,F:F,I2) -> -975.8
A3: 44284 | B3: Electronic Debit Tran Life | C3: Bills/Utilities | E3: -344.72 | F3: =YEAR(A3) -> 2021 | I3: 2020 | J3: =SUMIFS(E:E,F:F,I3) -> -3762.4
A4: 44272 | B4: Electronic Debit Transamerica Ins | C4: Bills/Utilities | E4: -10.9 | F4: =YEAR(A4) -> 2021 | I4: 2021 | J4: =SUMIFS(E:E,F:F,I4) -> -1077.76
A5: 44256 | B5: Electronic Debit Tran Life | C5: Bills/Utilities | E5: -344.72 | F5: =YEAR(A5) -> 2021
A6: 44245 | B6: Electronic Debit Transamerica Ins | C6: Bills/Utilities | E6: -10.9 | F6: =YEAR(A6) -> 2021
A7: 44223 | B7: Electronic Debit Tran Life | C7: Bills/Utilities | E7: -344.72 | F7: =YEAR(A7) -> 2021
A8: 44211 | B8: Electronic Debit Transamerica Ins | C8: Bills/Utilities | E8: -10.9 | F8: =YEAR(A8) -> 2021
A9: 44195 | B9: Electronic Debit Tran Life | C9: Bills/Utilities | E9: -344.72 | F9: =YEAR(A9) -> 2020
A10: 44181 | B10: Electronic Debit Transamerica Ins | C10: Bills/Utilities | E10: -10.9 | F10: =YEAR(A10) -> 2020
A11: 44165 | B11: Electronic Debit Tran Life | C11: Bills/Utilities | E11: -344.72 | F11: =YEAR(A11) -> 2020
A12: 44153 | B12: Electronic Debit Transamerica Ins | C12: Bills/Utilities | E12: -10.9 | F12: =YEAR(A12) -> 2020
A13: 44132 | B13: Electronic Debit Tran Life | C13: Bills/Utilities | E13: -344.72 | F13: =YEAR(A13) -> 2020
A14: 44119 | B14: Electronic Debit Transamerica Ins | C14: Bills/Utilities | E14: -10.9 | F14: =YEAR(A14) -> 2020
A15: 44103 | B15: Electronic Debit Transamerica Tpl | C15: Bills/Utilities | E15: -344.72 | F15: =YEAR(A15) -> 2020
A16: 44090 | B16: Electronic Debit Transamerica Ins | C16: Bills/Utilities | E16: -10.9 | F16: =YEAR(A16) -> 2020
... A36: 43767 | B36: Electronic Debit Transamerica Tpl | C36: Bills/Utilities | E36: -318 | F36: =YEAR(A36) -> 2019

Sheet RecurringExpenses
C2: Recurring Expenses
C3: Money in Excel automatically identifies which transactions are recurring. If any recurring expenses are missing, input them into empty rows. Our system will use 1) Merchant, 2) Amount $, 3) and Frequency to search for these transactions in the future and monitor prices.
C7: Most Costly Recurring Expenses | H7: Recurring Expenses Details | X7: FREQUENCY KEY
C8: Merchant | D8: Annual Cost | G8: Id | H8: Merchant | I8: Amount $ | J8: Frequency | K8: YTD/Annual Cost | L8: Price Change $ | M8: Last Date Paid | N8: Upcoming Pay Date | O8: Sum from Trans | P8: Upcoming Days | Q8: Rank_Days | R8: Rank_Annual | S8: User Added | T8: Column1 | X8: Weekly | Y8: 52
C9: {=IFERROR(INDEX(RecurringExp[Merchant],MATCH($B19,RecurringExp[Rank_Annual],0),0),"")} -> Verizon | D9: {=IFERROR(INDEX(RecurringExp[YTD/Annual Cost],MATCH($B19,RecurringExp[Rank_Annual],0),0),NA())} -> 1248.02 | G9: 10356f54718044df8b62308dc482e640 | H9: Electronic Debit Tran Life | I9: 344.72 | J9: Monthly | K9: =IFERROR(IF(ISBLANK(RecurringExp[[#This Row],[Amount $]]),"",IF(RecurringExp[[#This Row],[Sum from Trans]]<>"",RecurringExp[[#This Row],[Sum from Trans]],RecurringExp[[#This Row],[Amount $]]*_xlfn.XLOOKUP(RecurringExp[[#This Row],[Frequency]],FrequencyKey,FrequencyValue))),"") -> 1034.16 | L9: 0 | M9: 44284 | N9: 44309 | O9: =IF(SUMIFS(Table1[Amount $],Table1[Merchant],RecurringExp[[#This Row],[Merchant]],Table1[Date_Year],YEAR(TODAY()))*-1=0,"",SUMIFS(Table1[Amount $],Table1[Merchant],RecurringExp[[#This Row],[Merchant]],Table1[Date_Year],YEAR(TODAY()))*-1) -> 1034.16 | P9: =IF(ISBLANK(RecurringExp[[#This Row],[Upcoming Pay Date]]),"",IF(RecurringExp[[#This Row],[Upcoming Pay Date]]-TODAY()<0,"",IF(RecurringExp[[#This Row],[Upcoming Pay Date]]-TODAY()>30,"",RecurringExp[[#This Row],[Upcoming Pay Date]]-TODAY()))) -> 6 | Q9: =IFERROR(RANK(RecurringExp[[#This Row],[Upcoming Days]],RecurringExp[Upcoming Days],1)+COUNTIF(RecurringExp[[#This Row],[Upcoming Days]]:RecurringExp[[#This Row],[Upcoming Days]],RecurringExp[[#This Row],[Upcoming Days]])-1,"") -> 3 | R9: =IFERROR(RANK(RecurringExp[[#This Row],[YTD/Annual Cost]],RecurringExp[YTD/Annual Cost],0)+COUNTIF(RecurringExp[[#This Row],[YTD/Annual Cost]]:RecurringExp[[#This Row],[YTD/Annual Cost]],RecurringExp[[#This Row],[YTD/Annual Cost]])-1,"") -> 2 | S9: FALSE | X9: Monthly | Y9: 12
C10: {=IFERROR(INDEX(RecurringExp[Merchant],MATCH($B20,RecurringExp[Rank_Annual],0),0),"")} -> Electronic Debit Tran Life | D10: {=IFERROR(INDEX(RecurringExp[YTD/Annual Cost],MATCH($B20,RecurringExp[Rank_Annual],0),0),NA())} -> 1034.16 | G10: f5004c8526f74da69afb1ec3bc1654f3 | H10: Check Card Purchase Credit | I10: 226 | J10: Monthly | K10: =IFERROR(IF(ISBLANK(RecurringExp[[#This Row],[Amount $]]),"",IF(RecurringExp[[#This Row],[Sum from Trans]]<>"",RecurringExp[[#This Row],[Sum from Trans]],RecurringExp[[#This Row],[Amount $]]*_xlfn.XLOOKUP(RecurringExp[[#This Row],[Frequency]],FrequencyKey,FrequencyValue))),"") -> 452 | L10: -0.5 | M10: 44275 | N10: 44304 | O10: =IF(SUMIFS(Table1[Amount $],Table1[Merchant],RecurringExp[[#This Row],[Merchant]],Table1[Date_Year],YEAR(TODAY()))*-1=0,"",SUMIFS(Table1[Amount $],Table1[Merchant],RecurringExp[[#This Row],[Merchant]],Table1[Date_Year],YEAR(TODAY()))*-1) -> 452 | P10: =IF(ISBLANK(RecurringExp[[#This Row],[Upcoming Pay Date]]),"",IF(RecurringExp[[#This Row],[Upcoming Pay Date]]-TODAY()<0,"",IF(RecurringExp[[#This Row],[Upcoming Pay Date]]-TODAY()>30,"",RecurringExp[[#This Row],[Upcoming Pay Date]]-TODAY()))) -> 1 | Q10: =IFERROR(RANK(RecurringExp[[#This Row],[Upcoming Days]],RecurringExp[Upcoming Days],1)+COUNTIF(RecurringExp[[#This Row],[Upcoming Days]]:RecurringExp[[#This Row],[Upcoming Days]],RecurringExp[[#This Row],[Upcoming Days]])-1,"") -> 1 | R10: =IFERROR(RANK(RecurringExp[[#This Row],[YTD/Annual Cost]],RecurringExp[YTD/Annual Cost],0)+COUNTIF(RecurringExp[[#This Row],[YTD/Annual Cost]]:RecurringExp[[#This Row],[YTD/Annual Cost]],RecurringExp[[#This Row],[YTD/Annual Cost]])-1,"") -> 4 | S10: FALSE | X10: Quarterly | Y10: 4
C11: {=IFERROR(INDEX(RecurringExp[Merchant],MATCH($B21,RecurringExp[Rank_Annual],0),0),"")} -> Pepco | D11: {=IFERROR(INDEX(RecurringExp[YTD/Annual Cost],MATCH($B21,RecurringExp[Rank_Annual],0),0),NA())} -> 473.95 | G11: f95ec81a473c48febed64722b3cd4567 | H11: Electronic Debit Shen Life | I11: 40.28 | J11: Monthly | K11: =IFERROR(IF(ISBLANK(RecurringExp[[#This Row],[Amount $]]),"",IF(RecurringExp[[#This Row],[Sum from Trans]]<>"",RecurringExp[[#This Row],[Sum from Trans]],RecurringExp[[#This Row],[Amount $]]*_xlfn.XLOOKUP(RecurringExp[[#This Row],[Frequency]],FrequencyKey,FrequencyValue))),"") -> 120.84 | L11: 0 | M11: 44279 | N11: 44307 | O11: =IF(SUMIFS(Table1[Amount $],Table1[Merchant],RecurringExp[[#This Row],[Merchant]],Table1[Date_Year],YEAR(TODAY()))*-1=0,"",SUMIFS(Table1[Amount $],Table1[Merchant],RecurringExp[[#This Row],[Merchant]],Table1[Date_Year],YEAR(TODAY()))*-1) -> 120.84 | P11: =IF(ISBLANK(RecurringExp[[#This Row],[Upcoming Pay Date]]),"",IF(RecurringExp[[#This Row],[Upcoming Pay Date]]-TODAY()<0,"",IF(RecurringExp[[#This Row],[Upcoming Pay Date]]-TODAY()>30,"",RecurringExp[[#This Row],[Upcoming Pay Date]]-TODAY()))) -> 4 | Q11: =IFERROR(RANK(RecurringExp[[#This Row],[Upcoming Days]],RecurringExp[Upcoming Days],1)+COUNTIF(RecurringExp[[#This Row],[Upcoming Days]]:RecurringExp[[#This Row],[Upcoming Days]],RecurringExp[[#This Row],[Upcoming Days]])-1,"") -> 2 | R11: =IFERROR(RANK(RecurringExp[[#This Row],[YTD/Annual Cost]],RecurringExp[YTD/Annual Cost],0)+COUNTIF(RecurringExp[[#This Row],[YTD/Annual Cost]]:RecurringExp[[#This Row],[YTD/Annual Cost]],RecurringExp[[#This Row],[YTD/Annual Cost]])-1,"") -> 7 | S11: FALSE | X11: Annual | Y11: 1
C12: {=IFERROR(INDEX(RecurringExp[Merchant],MATCH($B22,RecurringExp[Rank_Annual],0),0),"")} -> Check Card Purchase Credit | D12: {=IFERROR(INDEX(RecurringExp[YTD/Annual Cost],MATCH($B22,RecurringExp[Rank_Annual],0),0),NA())} -> 452 | G12: 97ac467f47ed4d2587fe9463fa2b1d99 | H12: Amazon Prime | I12: 12.99 | J12: Monthly | K12: =IFERROR(IF(ISBLANK(RecurringExp[[#This Row],[Amount $]]),"",IF(RecurringExp[[#This Row],[Sum from Trans]]<>"",RecurringExp[[#This Row],[Sum from Trans]],RecurringExp[[#This Row],[Amount $]]*_xlfn.XLOOKUP(RecurringExp[[#This Row],[Frequency]],FrequencyKey,FrequencyValue))),"") -> 25.98 | L12: 0 | M12: 44255 | N12: 44282 | O12: =IF(SUMIFS(Table1[Amount $],Table1[Merchant],RecurringExp[[#This Row],[Merchant]],Table1[Date_Year],YEAR(TODAY()))*-1=0,"",SUMIFS(Table1[Amount $],Table1[Merchant],RecurringExp[[#This Row],[Merchant]],Table1[Date_Year],YEAR(TODAY()))*-1) -> 25.98 | P12: =IF(ISBLANK(RecurringExp[[#This Row],[Upcoming Pay Date]]),"",IF(RecurringExp[[#This Row],[Upcoming Pay Date]]-TODAY()<0,"",IF(RecurringExp[[#This Row],[Upcoming Pay Date]]-TODAY()>30,"",RecurringExp[[#This Row],[Upcoming Pay Date]]-TODAY()))) | Q12: =IFERROR(RANK(RecurringExp[[#This Row],[Upcoming Days]],RecurringExp[Upcoming Days],1)+COUNTIF(RecurringExp[[#This Row],[Upcoming Days]]:RecurringExp[[#This Row],[Upcoming Days]],RecurringExp[[#This Row],[Upcoming Days]])-1,"") | R12: =IFERROR(RANK(RecurringExp[[#This Row],[YTD/Annual Cost]],RecurringExp[YTD/Annual Cost],0)+COUNTIF(RecurringExp[[#This Row],[YTD/Annual Cost]]:RecurringExp[[#This Row],[YTD/Annual Cost]],RecurringExp[[#This Row],[YTD/Annual Cost]])-1,"") -> 14 | S12: FALSE
C13: {=IFERROR(INDEX(RecurringExp[Merchant],MATCH($B23,RecurringExp[Rank_Annual],0),0),"")} -> Verizon Wireless | D13: {=IFERROR(INDEX(RecurringExp[YTD/Annual Cost],MATCH($B23,RecurringExp[Rank_Annual],0),0),NA())} -> 369.42 | G13: 733e186ad45c41c18cdbd0db71529383 | H13: Electronic Debit Transamerica Ins | I13: 10.9 | J13: Monthly | K13: =IFERROR(IF(ISBLANK(RecurringExp[[#This Row],[Amount $]]),"",IF(RecurringExp[[#This Row],[Sum from Trans]]<>"",RecurringExp[[#This Row],[Sum from Trans]],RecurringExp[[#This Row],[Amount $]]*_xlfn.XLOOKUP(RecurringExp[[#This Row],[Frequency]],FrequencyKey,FrequencyValue))),"") -> 43.6 | L13: 0 | M13: 44301 | N13: 44328 | O13: =IF(SUMIFS(Table1[Amount $],Table1[Merchant],RecurringExp[[#This Row],[Merchant]],Table1[Date_Year],YEAR(TODAY()))*-1=0,"",SUMIFS(Table1[Amount $],Table1[Merchant],RecurringExp[[#This Row],[Merchant]],Table1[Date_Year],YEAR(TODAY()))*-1) -> 43.6 | P13: =IF(ISBLANK(RecurringExp[[#This Row],[Upcoming Pay Date]]),"",IF(RecurringExp[[#This Row],[Upcoming Pay Date]]-TODAY()<0,"",IF(RecurringExp[[#This Row],[Upcoming Pay Date]]-TODAY()>30,"",RecurringExp[[#This Row],[Upcoming Pay Date]]-TODAY()))) -> 25 | Q13: =IFERROR(RANK(RecurringExp[[#This Row],[Upcoming Days]],RecurringExp[Upcoming Days],1)+COUNTIF(RecurringExp[[#This Row],[Upcoming Days]]:RecurringExp[[#This Row],[Upcoming Days]],RecurringExp[[#This Row],[Upcoming Days]])-1,"") -> 4 | R13: =IFERROR(RANK(RecurringExp[[#This Row],[YTD/Annual Cost]],RecurringExp[YTD/Annual Cost],0)+COUNTIF(RecurringExp[[#This Row],[YTD/Annual Cost]]:RecurringExp[[#This Row],[YTD/Annual Cost]],RecurringExp[[#This Row],[YTD/Annual Cost]])-1,"") -> 10 | S13: FALSE
G14: bae3166a432246f8a5f5bfe277a884d0 | H14: Netflix | I14: 19.07 | J14: Monthly | K14: =IFERROR(IF(ISBLANK(RecurringExp[[#This Row],[Amount $]]),"",IF(RecurringExp[[#This Row],[Sum from Trans]]<>"",RecurringExp[[#This Row],[Sum from Trans]],RecurringExp[[#This Row],[Amount $]]*_xlfn.XLOOKUP(RecurringExp[[#This Row],[Frequency]],FrequencyKey,FrequencyValue))),"") -> 73.04 | L14: 15.12 | M14: 44267 | N14: 44297 | O14: =IF(SUMIFS(Table1[Amount $],Table1[Merchant],RecurringExp[[#This Row],[Merchant]],Table1[Date_Year],YEAR(TODAY()))*-1=0,"",SUMIFS(Table1[Amount $],Table1[Merchant],RecurringExp[[#This Row],[Merchant]],Table1[Date_Year],YEAR(TODAY()))*-1) -> 73.04 | P14: =IF(ISBLANK(RecurringExp[[#This Row],[Upcoming Pay Date]]),"",IF(RecurringExp[[#This Row],[Upcoming Pay Date]]-TODAY()<0,"",IF(RecurringExp[[#This Row],[Upcoming Pay Date]]-TODAY()>30,"",RecurringExp[[#This Row],[Upcoming Pay Date]]-TODAY()))) | Q14: =IFERROR(RANK(RecurringExp[[#This Row],[Upcoming Days]],RecurringExp[Upcoming Days],1)+COUNTIF(RecurringExp[[#This Row],[Upcoming Days]]:RecurringExp[[#This Row],[Upcoming Days]],RecurringExp[[#This Row],[Upcoming Days]])-1,"") | R14: =IFERROR(RANK(RecurringExp[[#This Row],[YTD/Annual Cost]],RecurringExp[YTD/Annual Cost],0)+COUNTIF(RecurringExp[[#This Row],[YTD/Annual Cost]]:RecurringExp[[#This Row],[YTD/Annual Cost]],RecurringExp[[#This Row],[YTD/Annual Cost]])-1,"") -> 9 | S14: FALSE
G15: a36684c6cc8a402e8c2cf99a8e29b8a0 | H15: Verizon | I15: 326.03 | J15: Monthly | K15: =IFERROR(IF(ISBLANK(RecurringExp[[#This Row],[Amount $]]),"",IF(RecurringExp[[#This Row],[Sum from Trans]]<>"",RecurringExp[[#This Row],[Sum from Trans]],RecurringExp[[#This Row],[Amount $]]*_xlfn.XLOOKUP(RecurringExp[[#This Row],[Frequency]],FrequencyKey,FrequencyValue))),"") -> 1248.02 | L15: 326.03 | M15: 44267 | N15: 44297 | O15: =IF(SUMIFS(Table1[Amount $],Table1[Merchant],RecurringExp[[#This Row],[Merchant]],Table1[Date_Year],YEAR(TODAY()))*-1=0,"",SUMIFS(Table1[Amount $],Table1[Merchant],RecurringExp[[#This Row],[Merchant]],Table1[Date_Year],YEAR(TODAY()))*-1) -> 1248.02 | P15: =IF(ISBLANK(RecurringExp[[#This Row],[Upcoming Pay Date]]),"",IF(RecurringExp[[#This Row],[Upcoming Pay Date]]-TODAY()<0,"",IF(RecurringExp[[#This Row],[Upcoming Pay Date]]-TODAY()>30,"",RecurringExp[[#This Row],[Upcoming Pay Date]]-TODAY()))) | Q15: =IFERROR(RANK(RecurringExp[[#This Row],[Upcoming Days]],RecurringExp[Upcoming Days],1)+COUNTIF(RecurringExp[[#This Row],[Upcoming Days]]:RecurringExp[[#This Row],[Upcoming Days]],RecurringExp[[#This Row],[Upcoming Days]])-1,"") | R15: =IFERROR(RANK(RecurringExp[[#This Row],[YTD/Annual Cost]],RecurringExp[YTD/Annual Cost],0)+COUNTIF(RecurringExp[[#This Row],[YTD/Annual Cost]]:RecurringExp[[#This Row],[YTD/Annual Cost]],RecurringExp[[#This Row],[YTD/Annual Cost]])-1,"") -> 1 | S15: TRUE
G16: 44d8b5f616c94a5abb1bba30de4f123c | H16: Verizon Wireless | I16: 123.02 | J16: Monthly | K16: =IFERROR(IF(ISBLANK(RecurringExp[[#This Row],[Amount $]]),"",IF(RecurringExp[[#This Row],[Sum from Trans]]<>"",RecurringExp[[#This Row],[Sum from Trans]],RecurringExp[[#This Row],[Amount $]]*_xlfn.XLOOKUP(RecurringExp[[#This Row],[Frequency]],FrequencyKey,FrequencyValue))),"") -> 369.42 | L16: 123.02 | M16: 44268 | N16: 44298 | O16: =IF(SUMIFS(Table1[Amount $],Table1[Merchant],RecurringExp[[#This Row],[Merchant]],Table1[Date_Year],YEAR(TODAY()))*-1=0,"",SUMIFS(Table1[Amount $],Table1[Merchant],RecurringExp[[#This Row],[Merchant]],Table1[Date_Year],YEAR(TODAY()))*-1) -> 369.42 | P16: =IF(ISBLANK(RecurringExp[[#This Row],[Upcoming Pay Date]]),"",IF(RecurringExp[[#This Row],[Upcoming Pay Date]]-TODAY()<0,"",IF(RecurringExp[[#This Row],[Upcoming Pay Date]]-TODAY()>30,"",RecurringExp[[#This Row],[Upcoming Pay Date]]-TODAY()))) | Q16: =IFERROR(RANK(RecurringExp[[#This Row],[Upcoming Days]],RecurringExp[Upcoming Days],1)+COUNTIF(RecurringExp[[#This Row],[Upcoming Days]]:RecurringExp[[#This Row],[Upcoming Days]],RecurringExp[[#This Row],[Upcoming Days]])-1,"") | R16: =IFERROR(RANK(RecurringExp[[#This Row],[YTD/Annual Cost]],RecurringExp[YTD/Annual Cost],0)+COUNTIF(RecurringExp[[#This Row],[YTD/Annual Cost]]:RecurringExp[[#This Row],[YTD/Annual Cost]],RecurringExp[[#This Row],[YTD/Annual Cost]])-1,"") -> 5 | S16: TRUE
C17: Upcoming Due Dates | G17: 3a7b9681a72246a7b6d8c44c0037c119 | H17: Spotify | I17: 9.99 | J17: Monthly | K17: =IFERROR(IF(ISBLANK(RecurringExp[[#This Row],[Amount $]]),"",IF(RecurringExp[[#This Row],[Sum from Trans]]<>"",RecurringExp[[#This Row],[Sum from Trans]],RecurringExp[[#This Row],[Amount $]]*_xlfn.XLOOKUP(RecurringExp[[#This Row],[Frequency]],FrequencyKey,FrequencyValue))),"") -> 30.57 | L17: 9.99 | O17: =IF(SUMIFS(Table1[Amount $],Table1[Merchant],RecurringExp[[#This Row],[Merchant]],Table1[Date_Year],YEAR(TODAY()))*-1=0,"",SUMIFS(Table1[Amount $],Table1[Merchant],RecurringExp[[#This Row],[Merchant]],Table1[Date_Year],YEAR(TODAY()))*-1) -> 30.57 | P17: =IF(ISBLANK(RecurringExp[[#This Row],[Upcoming Pay Date]]),"",IF(RecurringExp[[#This Row],[Upcoming Pay Date]]-TODAY()<0,"",IF(RecurringExp[[#This Row],[Upcoming Pay Date]]-TODAY()>30,"",RecurringExp[[#This Row],[Upcoming Pay Date]]-TODAY()))) | Q17: =IFERROR(RANK(RecurringExp[[#This Row],[Upcoming Days]],RecurringExp[Upcoming Days],1)+COUNTIF(RecurringExp[[#This Row],[Upcoming Days]]:RecurringExp[[#This Row],[Upcoming Days]],RecurringExp[[#This Row],[Upcoming Days]])-1,"") | R17: =IFERROR(RANK(RecurringExp[[#This Row],[YTD/Annual Cost]],RecurringExp[YTD/Annual Cost],0)+COUNTIF(RecurringExp[[#This Row],[YTD/Annual Cost]]:RecurringExp[[#This Row],[YTD/Annual Cost]],RecurringExp[[#This Row],[YTD/Annual Cost]])-1,"") -> 12 | S17: TRUE
C18: Merchant | D18: $ Amount | E18: Days to Pay | G18: 9fd9623113b14378b3151d18e87991ca | H18: Xbox Live | I18: 9.99 | J18: Monthly | K18: =IFERROR(IF(ISBLANK(RecurringExp[[#This Row],[Amount $]]),"",IF(RecurringExp[[#This Row],[Sum from Trans]]<>"",RecurringExp[[#This Row],[Sum from Trans]],RecurringExp[[#This Row],[Amount $]]*_xlfn.XLOOKUP(RecurringExp[[#This Row],[Frequency]],FrequencyKey,FrequencyValue))),"") -> 40.56 | L18: 9.99 | O18: =IF(SUMIFS(Table1[Amount $],Table1[Merchant],RecurringExp[[#This Row],[Merchant]],Table1[Date_Year],YEAR(TODAY()))*-1=0,"",SUMIFS(Table1[Amount $],Table1[Merchant],RecurringExp[[#This Row],[Merchant]],Table1[Date_Year],YEAR(TODAY()))*-1) -> 40.56 | P18: =IF(ISBLANK(RecurringExp[[#This Row],[Upcoming Pay Date]]),"",IF(RecurringExp[[#This Row],[Upcoming Pay Date]]-TODAY()<0,"",IF(RecurringExp[[#This Row],[Upcoming Pay Date]]-TODAY()>30,"",RecurringExp[[#This Row],[Upcoming Pay Date]]-TODAY()))) | Q18: =IFERROR(RANK(RecurringExp[[#This Row],[Upcoming Days]],RecurringExp[Upcoming Days],1)+COUNTIF(RecurringExp[[#This Row],[Upcoming Days]]:RecurringExp[[#This Row],[Upcoming Days]],RecurringExp[[#This Row],[Upcoming Days]])-1,"") | R18: =IFERROR(RANK(RecurringExp[[#This Row],[YTD/Annual Cost]],RecurringExp[YTD/Annual Cost],0)+COUNTIF(RecurringExp[[#This Row],[YTD/Annual Cost]]:RecurringExp[[#This Row],[YTD/Annual Cost]],RecurringExp[[#This Row],[YTD/Annual Cost]])-1,"") -> 11 | S18: TRUE
B19: 1 | C19: =IFERROR(INDEX(RecurringExp[Merchant],MATCH($B19,RecurringExp[Rank_Days],0),0),"") -> Check Card Purchase Credit | D19: {=IFERROR(INDEX(RecurringExp[Amount $],MATCH($B19,RecurringExp[Rank_Days],0),0),"")} -> 226 | E19: {=IFERROR(IF(INDEX(RecurringExp[Upcoming Days],MATCH($B19,RecurringExp[Rank_Days],0),0)=0,"Today",INDEX(RecurringExp[Upcoming Days],MATCH($B19,RecurringExp[Rank_Days],0),0)),"")} -> 1 | G19: 1fcc54d44edd46dabe6a9e1f754e9b91 | H19: Door Dash Pass | I19: 9.99 | J19: Monthly | K19: =IFERROR(IF(ISBLANK(RecurringExp[[#This Row],[Amount $]]),"",IF(RecurringExp[[#This Row],[Sum from Trans]]<>"",RecurringExp[[#This Row],[Sum from Trans]],RecurringExp[[#This Row],[Amount $]]*_xlfn.XLOOKUP(RecurringExp[[#This Row],[Frequency]],FrequencyKey,FrequencyValue))),"") -> 29.97 | L19: 9.99 | O19: =IF(SUMIFS(Table1[Amount $],Table1[Merchant],RecurringExp[[#This Row],[Merchant]],Table1[Date_Year],YEAR(TODAY()))*-1=0,"",SUMIFS(Table1[Amount $],Table1[Merchant],RecurringExp[[#This Row],[Merchant]],Table1[Date_Year],YEAR(TODAY()))*-1) -> 29.97 | P19: =IF(ISBLANK(RecurringExp[[#This Row],[Upcoming Pay Date]]),"",IF(RecurringExp[[#This Row],[Upcoming Pay Date]]-TODAY()<0,"",IF(RecurringExp[[#This Row],[Upcoming Pay Date]]-TODAY()>30,"",RecurringExp[[#This Row],[Upcoming Pay Date]]-TODAY()))) | Q19: =IFERROR(RANK(RecurringExp[[#This Row],[Upcoming Days]],RecurringExp[Upcoming Days],1)+COUNTIF(RecurringExp[[#This Row],[Upcoming Days]]:RecurringExp[[#This Row],[Upcoming Days]],RecurringExp[[#This Row],[Upcoming Days]])-1,"") | R19: =IFERROR(RANK(RecurringExp[[#This Row],[YTD/Annual Cost]],RecurringExp[YTD/Annual Cost],0)+COUNTIF(RecurringExp[[#This Row],[YTD/Annual Cost]]:RecurringExp[[#This Row],[YTD/Annual Cost]],RecurringExp[[#This Row],[YTD/Annual Cost]])-1,"") -> 13 | S19: TRUE
B20: 2 | C20: =IFERROR(INDEX(RecurringExp[Merchant],MATCH($B21,RecurringExp[Rank_Days],0),0),"") -> Electronic Debit Tran Life | D20: {=IFERROR(INDEX(RecurringExp[Amount $],MATCH($B21,RecurringExp[Rank_Days],0),0),"")} -> 344.72 | E20: {=IFERROR(IF(INDEX(RecurringExp[Upcoming Days],MATCH($B21,RecurringExp[Rank_Days],0),0)=0,"Today",INDEX(RecurringExp[Upcoming Days],MATCH($B21,RecurringExp[Rank_Days],0),0)),"")} -> 6 | G20: 78cd7f00d91d4a11b62fc27c980e85e0 | H20: Amercican Home Shield | I20: 54.99 | J20: Monthly | K20: =IFERROR(IF(ISBLANK(RecurringExp[[#This Row],[Amount $]]),"",IF(RecurringExp[[#This Row],[Sum from Trans]]<>"",RecurringExp[[#This Row],[Sum from Trans]],RecurringExp[[#This Row],[Amount $]]*_xlfn.XLOOKUP(RecurringExp[[#This Row],[Frequency]],FrequencyKey,FrequencyValue))),"") -> 109.98 | L20: 54.99 | O20: =IF(SUMIFS(Table1[Amount $],Table1[Merchant],RecurringExp[[#This Row],[Merchant]],Table1[Date_Year],YEAR(TODAY()))*-1=0,"",SUMIFS(Table1[Amount $],Table1[Merchant],RecurringExp[[#This Row],[Merchant]],Table1[Date_Year],YEAR(TODAY()))*-1) -> 109.98 | P20: =IF(ISBLANK(RecurringExp[[#This Row],[Upcoming Pay Date]]),"",IF(RecurringExp[[#This Row],[Upcoming Pay Date]]-TODAY()<0,"",IF(RecurringExp[[#This Row],[Upcoming Pay Date]]-TODAY()>30,"",RecurringExp[[#This Row],[Upcoming Pay Date]]-TODAY()))) | Q20: =IFERROR(RANK(RecurringExp[[#This Row],[Upcoming Days]],RecurringExp[Upcoming Days],1)+COUNTIF(RecurringExp[[#This Row],[Upcoming Days]]:RecurringExp[[#This Row],[Upcoming Days]],RecurringExp[[#This Row],[Upcoming Days]])-1,"") | R20: =IFERROR(RANK(RecurringExp[[#This Row],[YTD/Annual Cost]],RecurringExp[YTD/Annual Cost],0)+COUNTIF(RecurringExp[[#This Row],[YTD/Annual Cost]]:RecurringExp[[#This Row],[YTD/Annual Cost]],RecurringExp[[#This Row],[YTD/Annual Cost]])-1,"") -> 8 | S20: TRUE
B21: 3 | C21: =IFERROR(INDEX(RecurringExp[Merchant],MATCH($B22,RecurringExp[Rank_Days],0),0),"") -> Electronic Debit Transamerica Ins | D21: {=IFERROR(INDEX(RecurringExp[Amount $],MATCH($B22,RecurringExp[Rank_Days],0),0),"")} -> 10.9 | E21: {=IFERROR(IF(INDEX(RecurringExp[Upcoming Days],MATCH($B22,RecurringExp[Rank_Days],0),0)=0,"Today",INDEX(RecurringExp[Upcoming Days],MATCH($B22,RecurringExp[Rank_Days],0),0)),"")} -> 25 | G21: bba6eb3df4614aa195dc047d4eae2f58 | H21: CVS Care Pass | I21: 5.3 | J21: Monthly | K21: =IFERROR(IF(ISBLANK(RecurringExp[[#This Row],[Amount $]]),"",IF(RecurringExp[[#This Row],[Sum from Trans]]<>"",RecurringExp[[#This Row],[Sum from Trans]],RecurringExp[[#This Row],[Amount $]]*_xlfn.XLOOKUP(RecurringExp[[#This Row],[Frequency]],FrequencyKey,FrequencyValue))),"") -> 21.2 | L21: 5.3 | O21: =IF(SUMIFS(Table1[Amount $],Table1[Merchant],RecurringExp[[#This Row],[Merchant]],Table1[Date_Year],YEAR(TODAY()))*-1=0,"",SUMIFS(Table1[Amount $],Table1[Merchant],RecurringExp[[#This Row],[Merchant]],Table1[Date_Year],YEAR(TODAY()))*-1) -> 21.2 | P21: =IF(ISBLANK(RecurringExp[[#This Row],[Upcoming Pay Date]]),"",IF(RecurringExp[[#This Row],[Upcoming Pay Date]]-TODAY()<0,"",IF(RecurringExp[[#This Row],[Upcoming Pay Date]]-TODAY()>30,"",RecurringExp[[#This Row],[Upcoming Pay Date]]-TODAY()))) | Q21: =IFERROR(RANK(RecurringExp[[#This Row],[Upcoming Days]],RecurringExp[Upcoming Days],1)+COUNTIF(RecurringExp[[#This Row],[Upcoming Days]]:RecurringExp[[#This Row],[Upcoming Days]],RecurringExp[[#This Row],[Upcoming Days]])-1,"") | R21: =IFERROR(RANK(RecurringExp[[#This Row],[YTD/Annual Cost]],RecurringExp[YTD/Annual Cost],0)+COUNTIF(RecurringExp[[#This Row],[YTD/Annual Cost]]:RecurringExp[[#This Row],[YTD/Annual Cost]],RecurringExp[[#This Row],[YTD/Annual Cost]])-1,"") -> 15 | S21: TRUE
B22: 4 | C22: =IFERROR(INDEX(RecurringExp[Merchant],MATCH($B23,RecurringExp[Rank_Days],0),0),"") | D22: {=IFERROR(INDEX(RecurringExp[Amount $],MATCH($B23,RecurringExp[Rank_Days],0),0),"")} | E22: {=IFERROR(IF(INDEX(RecurringExp[Upcoming Days],MATCH($B23,RecurringExp[Rank_Days],0),0)=0,"Today",INDEX(RecurringExp[Upcoming Days],MATCH($B23,RecurringExp[Rank_Days],0),0)),"")} | H22: T Mobile | I22: 65.92 | J22: Monthly | K22: =IFERROR(IF(ISBLANK(RecurringExp[[#This Row],[Amount $]]),"",IF(RecurringExp[[#This Row],[Sum from Trans]]<>"",RecurringExp[[#This Row],[Sum from Trans]],RecurringExp[[#This Row],[Amount $]]*_xlfn.XLOOKUP(RecurringExp[[#This Row],[Frequency]],FrequencyKey,FrequencyValue))),"") -> 197.69 | O22: =IF(SUMIFS(Table1[Amount $],Table1[Merchant],RecurringExp[[#This Row],[Merchant]],Table1[Date_Year],YEAR(TODAY()))*-1=0,"",SUMIFS(Table1[Amount $],Table1[Merchant],RecurringExp[[#This Row],[Merchant]],Table1[Date_Year],YEAR(TODAY()))*-1) -> 197.69 | P22: =IF(ISBLANK(RecurringExp[[#This Row],[Upcoming Pay Date]]),"",IF(RecurringExp[[#This Row],[Upcoming Pay Date]]-TODAY()<0,"",IF(RecurringExp[[#This Row],[Upcoming Pay Date]]-TODAY()>30,"",RecurringExp[[#This Row],[Upcoming Pay Date]]-TODAY()))) | Q22: =IFERROR(RANK(RecurringExp[[#This Row],[Upcoming Days]],RecurringExp[Upcoming Days],1)+COUNTIF(RecurringExp[[#This Row],[Upcoming Days]]:RecurringExp[[#This Row],[Upcoming Days]],RecurringExp[[#This Row],[Upcoming Days]])-1,"") | R22: =IFERROR(RANK(RecurringExp[[#This Row],[YTD/Annual Cost]],RecurringExp[YTD/Annual Cost],0)+COUNTIF(RecurringExp[[#This Row],[YTD/Annual Cost]]:RecurringExp[[#This Row],[YTD/Annual Cost]],RecurringExp[[#This Row],[YTD/Annual Cost]])-1,"") -> 6
B23: 5 | H23: Pepco | I23: 473.95 | J23: Unknown | K23: =IFERROR(IF(ISBLANK(RecurringExp[[#This Row],[Amount $]]),"",IF(RecurringExp[[#This Row],[Sum from Trans]]<>"",RecurringExp[[#This Row],[Sum from Trans]],RecurringExp[[#This Row],[Amount $]]*_xlfn.XLOOKUP(RecurringExp[[#This Row],[Frequency]],FrequencyKey,FrequencyValue))),"") -> 473.95 | O23: =IF(SUMIFS(Table1[Amount $],Table1[Merchant],RecurringExp[[#This Row],[Merchant]],Table1[Date_Year],YEAR(TODAY()))*-1=0,"",SUMIFS(Table1[Amount $],Table1[Merchant],RecurringExp[[#This Row],[Merchant]],Table1[Date_Year],YEAR(TODAY()))*-1) -> 473.95 | P23: =IF(ISBLANK(RecurringExp[[#This Row],[Upcoming Pay Date]]),"",IF(RecurringExp[[#This Row],[Upcoming Pay Date]]-TODAY()<0,"",IF(RecurringExp[[#This Row],[Upcoming Pay Date]]-TODAY()>30,"",RecurringExp[[#This Row],[Upcoming Pay Date]]-TODAY()))) | Q23: =IFERROR(RANK(RecurringExp[[#This Row],[Upcoming Days]],RecurringExp[Upcoming Days],1)+COUNTIF(RecurringExp[[#This Row],[Upcoming Days]]:RecurringExp[[#This Row],[Upcoming Days]],RecurringExp[[#This Row],[Upcoming Days]])-1,"") | R23: =IFERROR(RANK(RecurringExp[[#This Row],[YTD/Annual Cost]],RecurringExp[YTD/Annual Cost],0)+COUNTIF(RecurringExp[[#This Row],[YTD/Annual Cost]]:RecurringExp[[#This Row],[YTD/Annual Cost]],RecurringExp[[#This Row],[YTD/Annual Cost]])-1,"") -> 3 | T23: 2109
H24: JC Penny | I24: 155 | J24: Unknown | K24: =IFERROR(IF(ISBLANK(RecurringExp[[#This Row],[Amount $]]),"",IF(RecurringExp[[#This Row],[Sum from Trans]]<>"",RecurringExp[[#This Row],[Sum from Trans]],RecurringExp[[#This Row],[Amount $]]*_xlfn.XLOOKUP(RecurringExp[[#This Row],[Frequency]],FrequencyKey,FrequencyValue))),"") | O24: =IF(SUMIFS(Table1[Amount $],Table1[Merchant],RecurringExp[[#This Row],[Merchant]],Table1[Date_Year],YEAR(TODAY()))*-1=0,"",SUMIFS(Table1[Amount $],Table1[Merchant],RecurringExp[[#This Row],[Merchant]],Table1[Date_Year],YEAR(TODAY()))*-1) | P24: =IF(ISBLANK(RecurringExp[[#This Row],[Upcoming Pay Date]]),"",IF(RecurringExp[[#This Row],[Upcoming Pay Date]]-TODAY()<0,"",IF(RecurringExp[[#This Row],[Upcoming Pay Date]]-TODAY()>30,"",RecurringExp[[#This Row],[Upcoming Pay Date]]-TODAY()))) | Q24: =IFERROR(RANK(RecurringExp[[#This Row],[Upcoming Days]],RecurringExp[Upcoming Days],1)+COUNTIF(RecurringExp[[#This Row],[Upcoming Days]]:RecurringExp[[#This Row],[Upcoming Days]],RecurringExp[[#This Row],[Upcoming Days]])-1,"") | R24: =IFERROR(RANK(RecurringExp[[#This Row],[YTD/Annual Cost]],RecurringExp[YTD/Annual Cost],0)+COUNTIF(RecurringExp[[#This Row],[YTD/Annual Cost]]:RecurringExp[[#This Row],[YTD/Annual Cost]],RecurringExp[[#This Row],[YTD/Annual Cost]])-1,"")
H25: Kohls | I25: 95 | J25: Unknown | K25: =IFERROR(IF(ISBLANK(RecurringExp[[#This Row],[Amount $]]),"",IF(RecurringExp[[#This Row],[Sum from Trans]]<>"",RecurringExp[[#This Row],[Sum from Trans]],RecurringExp[[#This Row],[Amount $]]*_xlfn.XLOOKUP(RecurringExp[[#This Row],[Frequency]],FrequencyKey,FrequencyValue))),"") | O25: =IF(SUMIFS(Table1[Amount $],Table1[Merchant],RecurringExp[[#This Row],[Merchant]],Table1[Date_Year],YEAR(TODAY()))*-1=0,"",SUMIFS(Table1[Amount $],Table1[Merchant],RecurringExp[[#This Row],[Merchant]],Table1[Date_Year],YEAR(TODAY()))*-1) | P25: =IF(ISBLANK(RecurringExp[[#This Row],[Upcoming Pay Date]]),"",IF(RecurringExp[[#This Row],[Upcoming Pay Date]]-TODAY()<0,"",IF(RecurringExp[[#This Row],[Upcoming Pay Date]]-TODAY()>30,"",RecurringExp[[#This Row],[Upcoming Pay Date]]-TODAY()))) | Q25: =IFERROR(RANK(RecurringExp[[#This Row],[Upcoming Days]],RecurringExp[Upcoming Days],1)+COUNTIF(RecurringExp[[#This Row],[Upcoming Days]]:RecurringExp[[#This Row],[Upcoming Days]],RecurringExp[[#This Row],[Upcoming Days]])-1,"") | R25: =IFERROR(RANK(RecurringExp[[#This Row],[YTD/Annual Cost]],RecurringExp[YTD/Annual Cost],0)+COUNTIF(RecurringExp[[#This Row],[YTD/Annual Cost]]:RecurringExp[[#This Row],[YTD/Annual Cost]],RecurringExp[[#This Row],[YTD/Annual Cost]])-1,"")
K26: =IFERROR(IF(ISBLANK(RecurringExp[[#This Row],[Amount $]]),"",IF(RecurringExp[[#This Row],[Sum from Trans]]<>"",RecurringExp[[#This Row],[Sum from Trans]],RecurringExp[[#This Row],[Amount $]]*_xlfn.XLOOKUP(RecurringExp[[#This Row],[Frequency]],FrequencyKey,FrequencyValue))),"") | O26: =IF(SUMIFS(Table1[Amount $],Table1[Merchant],RecurringExp[[#This Row],[Merchant]],Table1[Date_Year],YEAR(TODAY()))*-1=0,"",SUMIFS(Table1[Amount $],Table1[Merchant],RecurringExp[[#This Row],[Merchant]],Table1[Date_Year],YEAR(TODAY()))*-1) | P26: =IF(ISBLANK(RecurringExp[[#This Row],[Upcoming Pay Date]]),"",IF(RecurringExp[[#This Row],[Upcoming Pay Date]]-TODAY()<0,"",IF(RecurringExp[[#This Row],[Upcoming Pay Date]]-TODAY()>30,"",RecurringExp[[#This Row],[Upcoming Pay Date]]-TODAY()))) | Q26: =IFERROR(RANK(RecurringExp[[#This Row],[Upcoming Days]],RecurringExp[Upcoming Days],1)+COUNTIF(RecurringExp[[#This Row],[Upcoming Days]]:RecurringExp[[#This Row],[Upcoming Days]],RecurringExp[[#This Row],[Upcoming Days]])-1,"") | R26: =IFERROR(RANK(RecurringExp[[#This Row],[YTD/Annual Cost]],RecurringExp[YTD/Annual Cost],0)+COUNTIF(RecurringExp[[#This Row],[YTD/Annual Cost]]:RecurringExp[[#This Row],[YTD/Annual Cost]],RecurringExp[[#This Row],[YTD/Annual Cost]])-1,"")
K27: =IFERROR(IF(ISBLANK(RecurringExp[[#This Row],[Amount $]]),"",IF(RecurringExp[[#This Row],[Sum from Trans]]<>"",RecurringExp[[#This Row],[Sum from Trans]],RecurringExp[[#This Row],[Amount $]]*_xlfn.XLOOKUP(RecurringExp[[#This Row],[Frequency]],FrequencyKey,FrequencyValue))),"") | O27: =IF(SUMIFS(Table1[Amount $],Table1[Merchant],RecurringExp[[#This Row],[Merchant]],Table1[Date_Year],YEAR(TODAY()))*-1=0,"",SUMIFS(Table1[Amount $],Table1[Merchant],RecurringExp[[#This Row],[Merchant]],Table1[Date_Year],YEAR(TODAY()))*-1) | P27: =IF(ISBLANK(RecurringExp[[#This Row],[Upcoming Pay Date]]),"",IF(RecurringExp[[#This Row],[Upcoming Pay Date]]-TODAY()<0,"",IF(RecurringExp[[#This Row],[Upcoming Pay Date]]-TODAY()>30,"",RecurringExp[[#This Row],[Upcoming Pay Date]]-TODAY()))) | Q27: =IFERROR(RANK(RecurringExp[[#This Row],[Upcoming Days]],RecurringExp[Upcoming Days],1)+COUNTIF(RecurringExp[[#This Row],[Upcoming Days]]:RecurringExp[[#This Row],[Upcoming Days]],RecurringExp[[#This Row],[Upcoming Days]])-1,"") | R27: =IFERROR(RANK(RecurringExp[[#This Row],[YTD/Annual Cost]],RecurringExp[YTD/Annual Cost],0)+COUNTIF(RecurringExp[[#This Row],[YTD/Annual Cost]]:RecurringExp[[#This Row],[YTD/Annual Cost]],RecurringExp[[#This Row],[YTD/Annual Cost]])-1,"")
K28: =IFERROR(IF(ISBLANK(RecurringExp[[#This Row],[Amount $]]),"",IF(RecurringExp[[#This Row],[Sum from Trans]]<>"",RecurringExp[[#This Row],[Sum from Trans]],RecurringExp[[#This Row],[Amount $]]*_xlfn.XLOOKUP(RecurringExp[[#This Row],[Frequency]],FrequencyKey,FrequencyValue))),"") | O28: =IF(SUMIFS(Table1[Amount $],Table1[Merchant],RecurringExp[[#This Row],[Merchant]],Table1[Date_Year],YEAR(TODAY()))*-1=0,"",SUMIFS(Table1[Amount $],Table1[Merchant],RecurringExp[[#This Row],[Merchant]],Table1[Date_Year],YEAR(TODAY()))*-1) | P28: =IF(ISBLANK(RecurringExp[[#This Row],[Upcoming Pay Date]]),"",IF(RecurringExp[[#This Row],[Upcoming Pay Date]]-TODAY()<0,"",IF(RecurringExp[[#This Row],[Upcoming Pay Date]]-TODAY()>30,"",RecurringExp[[#This Row],[Upcoming Pay Date]]-TODAY()))) | Q28: =IFERROR(RANK(RecurringExp[[#This Row],[Upcoming Days]],RecurringExp[Upcoming Days],1)+COUNTIF(RecurringExp[[#This Row],[Upcoming Days]]:RecurringExp[[#This Row],[Upcoming Days]],RecurringExp[[#This Row],[Upcoming Days]])-1,"") | R28: =IFERROR(RANK(RecurringExp[[#This Row],[YTD/Annual Cost]],RecurringExp[YTD/Annual Cost],0)+COUNTIF(RecurringExp[[#This Row],[YTD/Annual Cost]]:RecurringExp[[#This Row],[YTD/Annual Cost]],RecurringExp[[#This Row],[YTD/Annual Cost]])-1,"")
K29: =IFERROR(IF(ISBLANK(RecurringExp[[#This Row],[Amount $]]),"",IF(RecurringExp[[#This Row],[Sum from Trans]]<>"",RecurringExp[[#This Row],[Sum from Trans]],RecurringExp[[#This Row],[Amount $]]*_xlfn.XLOOKUP(RecurringExp[[#This Row],[Frequency]],FrequencyKey,FrequencyValue))),"") | O29: =IF(SUMIFS(Table1[Amount $],Table1[Merchant],RecurringExp[[#This Row],[Merchant]],Table1[Date_Year],YEAR(TODAY()))*-1=0,"",SUMIFS(Table1[Amount $],Table1[Merchant],RecurringExp[[#This Row],[Merchant]],Table1[Date_Year],YEAR(TODAY()))*-1) | P29: =IF(ISBLANK(RecurringExp[[#This Row],[Upcoming Pay Date]]),"",IF(RecurringExp[[#This Row],[Upcoming Pay Date]]-TODAY()<0,"",IF(RecurringExp[[#This Row],[Upcoming Pay Date]]-TODAY()>30,"",RecurringExp[[#This Row],[Upcoming Pay Date]]-TODAY()))) | Q29: =IFERROR(RANK(RecurringExp[[#This Row],[Upcoming Days]],RecurringExp[Upcoming Days],1)+COUNTIF(RecurringExp[[#This Row],[Upcoming Days]]:RecurringExp[[#This Row],[Upcoming Days]],RecurringExp[[#This Row],[Upcoming Days]])-1,"") | R29: =IFERROR(RANK(RecurringExp[[#This Row],[YTD/Annual Cost]],RecurringExp[YTD/Annual Cost],0)+COUNTIF(RecurringExp[[#This Row],[YTD/Annual Cost]]:RecurringExp[[#This Row],[YTD/Annual Cost]],RecurringExp[[#This Row],[YTD/Annual Cost]])-1,"")
K30: =IFERROR(IF(ISBLANK(RecurringExp[[#This Row],[Amount $]]),"",IF(RecurringExp[[#This Row],[Sum from Trans]]<>"",RecurringExp[[#This Row],[Sum from Trans]],RecurringExp[[#This Row],[Amount $]]*_xlfn.XLOOKUP(RecurringExp[[#This Row],[Frequency]],FrequencyKey,FrequencyValue))),"") | O30: =IF(SUMIFS(Table1[Amount $],Table1[Merchant],RecurringExp[[#This Row],[Merchant]],Table1[Date_Year],YEAR(TODAY()))*-1=0,"",SUMIFS(Table1[Amount $],Table1[Merchant],RecurringExp[[#This Row],[Merchant]],Table1[Date_Year],YEAR(TODAY()))*-1) | P30: =IF(ISBLANK(RecurringExp[[#This Row],[Upcoming Pay Date]]),"",IF(RecurringExp[[#This Row],[Upcoming Pay Date]]-TODAY()<0,"",IF(RecurringExp[[#This Row],[Upcoming Pay Date]]-TODAY()>30,"",RecurringExp[[#This Row],[Upcoming Pay Date]]-TODAY()))) | Q30: =IFERROR(RANK(RecurringExp[[#This Row],[Upcoming Days]],RecurringExp[Upcoming Days],1)+COUNTIF(RecurringExp[[#This Row],[Upcoming Days]]:RecurringExp[[#This Row],[Upcoming Days]],RecurringExp[[#This Row],[Upcoming Days]])-1,"") | R30: =IFERROR(RANK(RecurringExp[[#This Row],[YTD/Annual Cost]],RecurringExp[YTD/Annual Cost],0)+COUNTIF(RecurringExp[[#This Row],[YTD/Annual Cost]]:RecurringExp[[#This Row],[YTD/Annual Cost]],RecurringExp[[#This Row],[YTD/Annual Cost]])-1,"")
K31: =IFERROR(IF(ISBLANK(RecurringExp[[#This Row],[Amount $]]),"",IF(RecurringExp[[#This Row],[Sum from Trans]]<>"",RecurringExp[[#This Row],[Sum from Trans]],RecurringExp[[#This Row],[Amount $]]*_xlfn.XLOOKUP(RecurringExp[[#This Row],[Frequency]],FrequencyKey,FrequencyValue))),"") | O31: =IF(SUMIFS(Table1[Amount $],Table1[Merchant],RecurringExp[[#This Row],[Merchant]],Table1[Date_Year],YEAR(TODAY()))*-1=0,"",SUMIFS(Table1[Amount $],Table1[Merchant],RecurringExp[[#This Row],[Merchant]],Table1[Date_Year],YEAR(TODAY()))*-1) | P31: =IF(ISBLANK(RecurringExp[[#This Row],[Upcoming Pay Date]]),"",IF(RecurringExp[[#This Row],[Upcoming Pay Date]]-TODAY()<0,"",IF(RecurringExp[[#This Row],[Upcoming Pay Date]]-TODAY()>30,"",RecurringExp[[#This Row],[Upcoming Pay Date]]-TODAY()))) | Q31: =IFERROR(RANK(RecurringExp[[#This Row],[Upcoming Days]],RecurringExp[Upcoming Days],1)+COUNTIF(RecurringExp[[#This Row],[Upcoming Days]]:RecurringExp[[#This Row],[Upcoming Days]],RecurringExp[[#This Row],[Upcoming Days]])-1,"") | R31: =IFERROR(RANK(RecurringExp[[#This Row],[YTD/Annual Cost]],RecurringExp[YTD/Annual Cost],0)+COUNTIF(RecurringExp[[#This Row],[YTD/Annual Cost]]:RecurringExp[[#This Row],[YTD/Annual Cost]],RecurringExp[[#This Row],[YTD/Annual Cost]])-1,"")

Sheet Snapshot
C2: Snapshot | Q2: Choose month below
C4: See your spending trends month over month with easy to read graphs. To switch months, click on the blue date box to the right. | Q4: June 2020 | W4: =_xlfn.XLOOKUP(TEXT(Q4,"mmmm yyyy"),$V$7:$V$200,$W$7:$W$200) -> 43983 | Y4: Monthly Summary | AC4: Category | AD4: Count | AE4: Rank | AF4: Order | AG4: Category | AH4: $ | AJ4: Display Axis | AK4: Current Mon. | AL4: $ | AM4: =TEXT(AK6,"MMMM")&" Spending" -> June Spending | AN4: Max Date | AO4: Last Mon. | AP4: $ | AQ4: =TEXT(AO6,"MMMM")&" Spending" -> May Spending | AR4: Max Date | AT4: Merchants | AU4: $ | AV4: Trans Count | AW4: Trans Rank | AX4: $ Rank
V6: Input | W6: Month Filter | Y6: =TEXT(ABS(Z9),"$#,##0")&" "&IF(Z7>Z8,"less was spent compared to last month","more was spent compared to last month") -> $321 less was spent compared to last month | AC6: {=_xlfn.UNIQUE(INDEX(_xlfn._xlws.FILTER(CategoriesTable[],(CategoriesTable[Category type]="expense")*(NOT(CategoriesTable[ID]=0)),""),0,2),FALSE)} -> Auto/Transport | AD6: =SUMIFS(Table1[Amount $],Table1[Category],Snapshot!AC6,Table1[Month],Snapshot!$W$4)*-1 -> 0 | AE6: =RANK(AD6,$AD$6:$AD$35,0)+COUNTIF(AD6:$AD$6,AD6)-1 -> 10 | AF6: 1 | AG6: {=IF(INDEX($AD$6:$AD$35,MATCH(AF6,$AE$6:$AE$35,0),0)=0,"",INDEX($AC$6:$AC$35,MATCH(AF6,$AE$6:$AE$35,0),0))} -> Bills/Utilities | AH6: {=IF(INDEX($AD$6:$AD$35,MATCH(AF6,$AE$6:$AE$35,0),0)=0,0,INDEX($AD$6:$AD$35,MATCH(AF6,$AE$6:$AE$35,0),0))} -> 1881.32 | AJ6: =DATE(2000,1,1) -> 36526 | AK6: =DATE(YEAR(W4),MONTH(W4),DAY(W4)) -> 43983 | AL6: =SUMIFS(Table1[Amount $],Table1[Category Type],"Expense",Table1[Date],Snapshot!AK6)*-1 -> 50.16 | AM6: =IF(AK6>TODAY(),NA(),SUM(AL6:$AL$6)) -> 50.16 | AN6: =IF(OR(AK6=EOMONTH($AK$6,0),AK6=TODAY()),AM6,NA()) -> #N/A | AO6: =DATE(YEAR(AK6),MONTH(AK6)-1,DAY(AK6)) -> 43952 | AP6: =SUMIFS(Table1[Amount $],Table1[Category Type],"Expense",Table1[Date],Snapshot!AO6)*-1 -> 500 | AQ6: =IF(AO6<=EOMONTH($AO$6,0),SUM(AP$6:$AP6),NA()) -> 500 | AR6: =IF(AO6=EOMONTH($AO$6,0),AQ6,NA()) -> #N/A | AT6: {=_xlfn.UNIQUE(_xlfn._xlws.FILTER(Table1[Merchant],(Table1[Merchant]<>"")*(Table1[Amount $]<0)*(Table1[Month]=Snapshot!$W$4)*(Table1[Category Type]="Expense")))} -> Amazon Prime | AU6: =IF(ISBLANK(AT6),"",SUMIFS(Table1[Amount $],Table1[Merchant],Snapshot!AT6,Table1[Month],Snapshot!$W$4)*-1) -> 12.99 | AV6: =IF(ISBLANK(AT6),"",COUNTIFS(Table1[Merchant],Snapshot!AT6,Table1[Month],Snapshot!$W$4)) -> 1 | AW6: =IFERROR(RANK(AV6,$AV$6:$AV$200)+COUNTIF($AV$6:AV6,AV6)-1,"") -> 8 | AX6: =IFERROR(RANK(AU6,$AU$6:$AU$200)+COUNTIF($AU$6:AU6,AU6)-1,"") -> 25
D7: Current vs. previous month spending | M7: This month's top spending categories | V7: =IF(ISBLANK(W7),"--",TEXT(W7,"mmmm")&" "&TEXT(W7,"YYYY")) -> April 2021 | W7: {=_xlfn._xlws.SORT(_xlfn.UNIQUE(_xlfn._xlws.FILTER(Table1[Month],Table1[Month]<>"",)),1,-1)} -> 44287 | Y7: =IFERROR(TEXT(AO6,"mmmm"),"--") -> May | Z7: =SUMIFS(Table1[Amount $],Table1[Category Type],"Expense",Table1[Month],DATE(YEAR(Snapshot!$W$4),MONTH(Snapshot!$W$4)-1,DAY(Snapshot!$W$4)))*-1 -> 4475.64 | AC7: Bills/Utilities | AD7: =SUMIFS(Table1[Amount $],Table1[Category],Snapshot!AC7,Table1[Month],Snapshot!$W$4)*-1 -> 1881.32 | AE7: =RANK(AD7,$AD$6:$AD$35,0)+COUNTIF(AD$6:$AD7,AD7)-1 -> 1 | AF7: 2 | AG7: {=IF(INDEX($AD$6:$AD$35,MATCH(AF7,$AE$6:$AE$35,0),0)=0,"",INDEX($AC$6:$AC$35,MATCH(AF7,$AE$6:$AE$35,0),0))} -> Shopping | AH7: {=IF(INDEX($AD$6:$AD$35,MATCH(AF7,$AE$6:$AE$35,0),0)=0,0,INDEX($AD$6:$AD$35,MATCH(AF7,$AE$6:$AE$35,0),0))} -> 573.13 | AJ7: =DATE(YEAR(AJ6),MONTH(AJ6),DAY(AJ6)+1) -> 36527 | AK7: =IF(MONTH(AK6)=MONTH(DATE(YEAR(AK6),MONTH(AK6),DAY(AK6)+1)),DATE(YEAR(AK6),MONTH(AK6),DAY(AK6)+1),NA()) -> 43984 | AL7: =SUMIFS(Table1[Amount $],Table1[Category Type],"Expense",Table1[Date],Snapshot!AK7)*-1 -> 149.93 | AM7: =IF(AK7>TODAY(),NA(),SUM(AL$6:$AL7)) -> 200.09 | AN7: =IF(OR(AK7=EOMONTH($AK$6,0),AK7=TODAY()),AM7,NA()) -> #N/A | AO7: =IF(MONTH(AO6)=MONTH(DATE(YEAR(AO6),MONTH(AO6),DAY(AO6)+1)),DATE(YEAR(AO6),MONTH(AO6),DAY(AO6)+1),NA()) -> 43953 | AP7: =SUMIFS(Table1[Amount $],Table1[Category Type],"Expense",Table1[Date],Snapshot!AO7)*-1 -> 77.58 | AQ7: =IF(AO7<=EOMONTH($AO$6,0),SUM(AP$6:$AP7),NA()) -> 577.58 | AR7: =IF(AO7=EOMONTH($AO$6,0),AQ7,NA()) -> #N/A | AT7: Electronic Debit Transamerica Tpl | AU7: =IF(ISBLANK(AT7),"",SUMIFS(Table1[Amount $],Table1[Merchant],Snapshot!AT7,Table1[Month],Snapshot!$W$4)*-1) -> 318 | AV7: =IF(ISBLANK(AT7),"",COUNTIFS(Table1[Merchant],Snapshot!AT7,Table1[Month],Snapshot!$W$4)) -> 1 | AW7: =IFERROR(RANK(AV7,$AV$6:$AV$200)+COUNTIF($AV$6:AV7,AV7)-1,"") -> 9 | AX7: =IFERROR(RANK(AU7,$AU$6:$AU$200)+COUNTIF($AU$6:AU7,AU7)-1,"") -> 5
D8: =Y6 -> $321 less was spent compared to last month | M8: =Q10&" accounts for "&TEXT(S10/S22,"0%")&" of money spent this month" -> Bills/Utilities accounts for 45% of money spent this month | V8: =IF(ISBLANK(W8),"--",TEXT(W8,"mmmm")&" "&TEXT(W8,"YYYY")) -> March 2021 | W8: 44256 | Y8: =IFERROR(TEXT(AK6,"mmmm"),"--") -> June | Z8: =SUMIFS(Table1[Amount $],Table1[Category Type],"Expense",Table1[Month],Snapshot!$W$4)*-1 -> 4154.17 | AC8: Entertainment | AD8: =SUMIFS(Table1[Amount $],Table1[Category],Snapshot!AC8,Table1[Month],Snapshot!$W$4)*-1 -> 32.38 | AE8: =RANK(AD8,$AD$6:$AD$35,0)+COUNTIF(AD$6:$AD8,AD8)-1 -> 7 | AF8: 3 | AG8: {=IF(INDEX($AD$6:$AD$35,MATCH(AF8,$AE$6:$AE$35,0),0)=0,"",INDEX($AC$6:$AC$35,MATCH(AF8,$AE$6:$AE$35,0),0))} -> Restaurants/Dining | AH8: {=IF(INDEX($AD$6:$AD$35,MATCH(AF8,$AE$6:$AE$35,0),0)=0,0,INDEX($AD$6:$AD$35,MATCH(AF8,$AE$6:$AE$35,0),0))} -> 562.29 | AJ8: =DATE(YEAR(AJ7),MONTH(AJ7),DAY(AJ7)+1) -> 36528 | AK8: =IF(MONTH(AK7)=MONTH(DATE(YEAR(AK7),MONTH(AK7),DAY(AK7)+1)),DATE(YEAR(AK7),MONTH(AK7),DAY(AK7)+1),NA()) -> 43985 | AL8: =SUMIFS(Table1[Amount $],Table1[Category Type],"Expense",Table1[Date],Snapshot!AK8)*-1 -> 109.44 | AM8: =IF(AK8>TODAY(),NA(),SUM(AL$6:$AL8)) -> 309.53 | AN8: =IF(OR(AK8=EOMONTH($AK$6,0),AK8=TODAY()),AM8,NA()) -> #N/A | AO8: =IF(MONTH(AO7)=MONTH(DATE(YEAR(AO7),MONTH(AO7),DAY(AO7)+1)),DATE(YEAR(AO7),MONTH(AO7),DAY(AO7)+1),NA()) -> 43954 | AP8: =SUMIFS(Table1[Amount $],Table1[Category Type],"Expense",Table1[Date],Snapshot!AO8)*-1 -> 0 | AQ8: =IF(AO8<=EOMONTH($AO$6,0),SUM(AP$6:$AP8),NA()) -> 577.58 | AR8: =IF(AO8=EOMONTH($AO$6,0),AQ8,NA()) -> #N/A | AT8: Overdraft Item Fee For | AU8: =IF(ISBLANK(AT8),"",SUMIFS(Table1[Amount $],Table1[Merchant],Snapshot!AT8,Table1[Month],Snapshot!$W$4)*-1) -> 180 | AV8: =IF(ISBLANK(AT8),"",COUNTIFS(Table1[Merchant],Snapshot!AT8,Table1[Month],Snapshot!$W$4)) -> 5 | AW8: =IFERROR(RANK(AV8,$AV$6:$AV$200)+COUNTIF($AV$6:AV8,AV8)-1,"") -> 2 | AX8: =IFERROR(RANK(AU8,$AU$6:$AU$200)+COUNTIF($AU$6:AU8,AU8)-1,"") -> 10
V9: =IF(ISBLANK(W9),"--",TEXT(W9,"mmmm")&" "&TEXT(W9,"YYYY")) -> February 2021 | W9: 44228 | Y9: Difference | Z9: =Z8-Z7 -> -321.47 | AC9: Fees/Charges | AD9: =SUMIFS(Table1[Amount $],Table1[Category],Snapshot!AC9,Table1[Month],Snapshot!$W$4)*-1 -> 325.95 | AE9: =RANK(AD9,$AD$6:$AD$35,0)+COUNTIF(AD$6:$AD9,AD9)-1 -> 5 | AF9: 4 | AG9: {=IF(INDEX($AD$6:$AD$35,MATCH(AF9,$AE$6:$AE$35,0),0)=0,"",INDEX($AC$6:$AC$35,MATCH(AF9,$AE$6:$AE$35,0),0))} -> Professional Services | AH9: {=IF(INDEX($AD$6:$AD$35,MATCH(AF9,$AE$6:$AE$35,0),0)=0,0,INDEX($AD$6:$AD$35,MATCH(AF9,$AE$6:$AE$35,0),0))} -> 500 | AJ9: =DATE(YEAR(AJ8),MONTH(AJ8),DAY(AJ8)+1) -> 36529 | AK9: =IF(MONTH(AK8)=MONTH(DATE(YEAR(AK8),MONTH(AK8),DAY(AK8)+1)),DATE(YEAR(AK8),MONTH(AK8),DAY(AK8)+1),NA()) -> 43986 | AL9: =SUMIFS(Table1[Amount $],Table1[Category Type],"Expense",Table1[Date],Snapshot!AK9)*-1 -> 90.9 | AM9: =IF(AK9>TODAY(),NA(),SUM(AL$6:$AL9)) -> 400.43 | AN9: =IF(OR(AK9=EOMONTH($AK$6,0),AK9=TODAY()),AM9,NA()) -> #N/A | AO9: =IF(MONTH(AO8)=MONTH(DATE(YEAR(AO8),MONTH(AO8),DAY(AO8)+1)),DATE(YEAR(AO8),MONTH(AO8),DAY(AO8)+1),NA()) -> 43955 | AP9: =SUMIFS(Table1[Amount $],Table1[Category Type],"Expense",Table1[Date],Snapshot!AO9)*-1 -> 0 | AQ9: =IF(AO9<=EOMONTH($AO$6,0),SUM(AP$6:$AP9),NA()) -> 577.58 | AR9: =IF(AO9=EOMONTH($AO$6,0),AQ9,NA()) -> #N/A | AT9: Overdraft Protection Transfer Fee | AU9: =IF(ISBLANK(AT9),"",SUMIFS(Table1[Amount $],Table1[Merchant],Snapshot!AT9,Table1[Month],Snapshot!$W$4)*-1) -> 12.5 | AV9: =IF(ISBLANK(AT9),"",COUNTIFS(Table1[Merchant],Snapshot!AT9,Table1[Month],Snapshot!$W$4)) -> 1 | AW9: =IFERROR(RANK(AV9,$AV$6:$AV$200)+COUNTIF($AV$6:AV9,AV9)-1,"") -> 10 | AX9: =IFERROR(RANK(AU9,$AU$6:$AU$200)+COUNTIF($AU$6:AU9,AU9)-1,"") -> 26
