Workbook

Sheet Discover Data
B1: Trans. Date | C1: Post Date | D1: Description | E1: Amount | F1: Category | G1: Short_Desc | H1: Date | I1: Reoccurring_Flag | J1: Category_2 | K1: CumAmount | N1: 01/2022 | O1: 02/2022 | P1: 03/2022 | Q1: 04/2022 | R1: 05/2022 | S1: 06/2022 | T1: 07/2022 | U1: 08/2022 | V1: 09/2022 | W1: 10/2022 | X1: 11/2022 | Y1: 12/2022
A2: 0 | B2: 01/01/2022 | C2: 01/01/2022 | D2: Balance | E2: 3581.67 | F2: Balance | G2: Balance | K2: 3581.67 | M2: Automotive | N2: =SUMIFS(dis_table[Amount],dis_table[Category],$M2,dis_table[Date],N$1) -> 42.34 | O2: =SUMIFS(dis_table[Amount],dis_table[Category],$M2,dis_table[Date],O$1) -> 0 | P2: =SUMIFS(dis_table[Amount],dis_table[Category],$M2,dis_table[Date],P$1) -> 0 | Q2: =SUMIFS(dis_table[Amount],dis_table[Category],$M2,dis_table[Date],Q$1) -> 0 | R2: =SUMIFS(dis_table[Amount],dis_table[Category],$M2,dis_table[Date],R$1) -> 0 | S2: =SUMIFS(dis_table[Amount],dis_table[Category],$M2,dis_table[Date],S$1) -> 0 | T2: =SUMIFS(dis_table[Amount],dis_table[Category],$M2,dis_table[Date],T$1) -> 21 | U2: =SUMIFS(dis_table[Amount],dis_table[Category],$M2,dis_table[Date],U$1) -> 130.33 | ... Y2: =SUMIFS(dis_table[Amount],dis_table[Category],$M2,dis_table[Date],Y$1) -> 0
A3: 1 | B3: 01/01/2022 | C3: 01/01/2022 | D3: JIMMY JOHNS - 2500 PHOENIX AZ | E3: 18.02 | F3: Restaurants | G3: fast_food | H3: 01/2022 | I3: No | J3: Food | K3: 3599.69 | M3: Education | N3: =SUMIFS(dis_table[Amount],dis_table[Category],$M3,dis_table[Date],N$1) -> 0 | O3: =SUMIFS(dis_table[Amount],dis_table[Category],$M3,dis_table[Date],O$1) -> 0 | P3: =SUMIFS(dis_table[Amount],dis_table[Category],$M3,dis_table[Date],P$1) -> 0 | Q3: =SUMIFS(dis_table[Amount],dis_table[Category],$M3,dis_table[Date],Q$1) -> 21.71 | R3: =SUMIFS(dis_table[Amount],dis_table[Category],$M3,dis_table[Date],R$1) -> 0 | S3: =SUMIFS(dis_table[Amount],dis_table[Category],$M3,dis_table[Date],S$1) -> 298 | T3: =SUMIFS(dis_table[Amount],dis_table[Category],$M3,dis_table[Date],T$1) -> 100.25 | U3: =SUMIFS(dis_table[Amount],dis_table[Category],$M3,dis_table[Date],U$1) -> 33 | ... Y3: =SUMIFS(dis_table[Amount],dis_table[Category],$M3,dis_table[Date],Y$1) -> 0
A4: 2 | B4: 01/01/2022 | C4: 01/01/2022 | D4: OLIVE GARDE00064212140 PHOENIX AZ | E4: 60 | F4: Restaurants | G4: restaurant | H4: 01/2022 | I4: No | J4: Food | K4: 3659.69 | M4: Gasoline | N4: =SUMIFS(dis_table[Amount],dis_table[Category],$M4,dis_table[Date],N$1) -> 92.41 | O4: =SUMIFS(dis_table[Amount],dis_table[Category],$M4,dis_table[Date],O$1) -> 0 | P4: =SUMIFS(dis_table[Amount],dis_table[Category],$M4,dis_table[Date],P$1) -> 342.53 | Q4: =SUMIFS(dis_table[Amount],dis_table[Category],$M4,dis_table[Date],Q$1) -> 3.59 | R4: =SUMIFS(dis_table[Amount],dis_table[Category],$M4,dis_table[Date],R$1) -> 73.21 | S4: =SUMIFS(dis_table[Amount],dis_table[Category],$M4,dis_table[Date],S$1) -> 11.8 | T4: =SUMIFS(dis_table[Amount],dis_table[Category],$M4,dis_table[Date],T$1) -> 229.64 | U4: =SUMIFS(dis_table[Amount],dis_table[Category],$M4,dis_table[Date],U$1) -> 0 | ... Y4: =SUMIFS(dis_table[Amount],dis_table[Category],$M4,dis_table[Date],Y$1) -> 0
A5: 3 | B5: 01/01/2022 | C5: 01/03/2022 | D5: NETFLIX.COM NETFLIX.COM CAITEM TRANSFERRED FROM PREV ACCOUNT | E5: 14.83 | F5: Merchandise | G5: netflix | H5: 01/2022 | I5: Yes | J5: Recreation_Entertainment | K5: 3674.52 | M5: Government Services | N5: =SUMIFS(dis_table[Amount],dis_table[Category],$M5,dis_table[Date],N$1) -> 0 | O5: =SUMIFS(dis_table[Amount],dis_table[Category],$M5,dis_table[Date],O$1) -> 0 | P5: =SUMIFS(dis_table[Amount],dis_table[Category],$M5,dis_table[Date],P$1) -> 35 | Q5: =SUMIFS(dis_table[Amount],dis_table[Category],$M5,dis_table[Date],Q$1) -> 0 | R5: =SUMIFS(dis_table[Amount],dis_table[Category],$M5,dis_table[Date],R$1) -> 0 | S5: =SUMIFS(dis_table[Amount],dis_table[Category],$M5,dis_table[Date],S$1) -> 0 | T5: =SUMIFS(dis_table[Amount],dis_table[Category],$M5,dis_table[Date],T$1) -> 0 | U5: =SUMIFS(dis_table[Amount],dis_table[Category],$M5,dis_table[Date],U$1) -> 0 | ... Y5: =SUMIFS(dis_table[Amount],dis_table[Category],$M5,dis_table[Date],Y$1) -> 0
A6: 4 | B6: 01/01/2022 | C6: 01/03/2022 | D6: SPOTIFY P18D298A28 8777781161 NYITEM TRANSFERRED FROM PREV ACCOUNT | E6: 9.99 | F6: Merchandise | G6: spotify | H6: 01/2022 | I6: Yes | J6: Recreation_Entertainment | K6: 3684.51 | M6: Home Improvement | N6: =SUMIFS(dis_table[Amount],dis_table[Category],$M6,dis_table[Date],N$1) -> 0 | O6: =SUMIFS(dis_table[Amount],dis_table[Category],$M6,dis_table[Date],O$1) -> 0 | P6: =SUMIFS(dis_table[Amount],dis_table[Category],$M6,dis_table[Date],P$1) -> 0 | Q6: =SUMIFS(dis_table[Amount],dis_table[Category],$M6,dis_table[Date],Q$1) -> 0 | R6: =SUMIFS(dis_table[Amount],dis_table[Category],$M6,dis_table[Date],R$1) -> 0 | S6: =SUMIFS(dis_table[Amount],dis_table[Category],$M6,dis_table[Date],S$1) -> 0 | T6: =SUMIFS(dis_table[Amount],dis_table[Category],$M6,dis_table[Date],T$1) -> 49.46 | U6: =SUMIFS(dis_table[Amount],dis_table[Category],$M6,dis_table[Date],U$1) -> 197.48 | ... Y6: =SUMIFS(dis_table[Amount],dis_table[Category],$M6,dis_table[Date],Y$1) -> 0
A7: 5 | B7: 01/02/2022 | C7: 01/02/2022 | D7: INTERNET PAYMENT - THANK YOU | E7: -1800 | F7: Payments and Credits | G7: payment | H7: 01/2022 | I7: No | J7: Payment_and_Interest | K7: 1884.51 | M7: Interest | N7: =SUMIFS(dis_table[Amount],dis_table[Category],$M7,dis_table[Date],N$1) -> 0 | O7: =SUMIFS(dis_table[Amount],dis_table[Category],$M7,dis_table[Date],O$1) -> 0 | P7: =SUMIFS(dis_table[Amount],dis_table[Category],$M7,dis_table[Date],P$1) -> 0 | Q7: =SUMIFS(dis_table[Amount],dis_table[Category],$M7,dis_table[Date],Q$1) -> 0 | R7: =SUMIFS(dis_table[Amount],dis_table[Category],$M7,dis_table[Date],R$1) -> 50.48 | S7: =SUMIFS(dis_table[Amount],dis_table[Category],$M7,dis_table[Date],S$1) -> 99.24 | T7: =SUMIFS(dis_table[Amount],dis_table[Category],$M7,dis_table[Date],T$1) -> 99.19 | U7: =SUMIFS(dis_table[Amount],dis_table[Category],$M7,dis_table[Date],U$1) -> 61.69 | ... Y7: =SUMIFS(dis_table[Amount],dis_table[Category],$M7,dis_table[Date],Y$1) -> 0
A8: 6 | B8: 01/02/2022 | C8: 01/03/2022 | D8: KRYSTAL AND SAAGAR 2025317527 DCITEM TRANSFERRED FROM PREV ACCOUNT | E8: 10 | F8: Merchandise | G8: breaking_points | H8: 01/2022 | I8: Yes | J8: Recreation_Entertainment | K8: 1894.51 | M8: Medical Services | N8: =SUMIFS(dis_table[Amount],dis_table[Category],$M8,dis_table[Date],N$1) -> 0 | O8: =SUMIFS(dis_table[Amount],dis_table[Category],$M8,dis_table[Date],O$1) -> 0 | P8: =SUMIFS(dis_table[Amount],dis_table[Category],$M8,dis_table[Date],P$1) -> 432 | Q8: =SUMIFS(dis_table[Amount],dis_table[Category],$M8,dis_table[Date],Q$1) -> 0 | R8: =SUMIFS(dis_table[Amount],dis_table[Category],$M8,dis_table[Date],R$1) -> 37.5 | S8: =SUMIFS(dis_table[Amount],dis_table[Category],$M8,dis_table[Date],S$1) -> 0 | T8: =SUMIFS(dis_table[Amount],dis_table[Category],$M8,dis_table[Date],T$1) -> 0 | U8: =SUMIFS(dis_table[Amount],dis_table[Category],$M8,dis_table[Date],U$1) -> 0 | ... Y8: =SUMIFS(dis_table[Amount],dis_table[Category],$M8,dis_table[Date],Y$1) -> 0
A9: 7 | B9: 01/03/2022 | C9: 01/03/2022 | D9: PAYPAL *HULU 402-935-7733 CA | E9: 12.99 | F9: Services | G9: hulu | H9: 01/2022 | I9: Yes | J9: Recreation_Entertainment | K9: 1907.5 | M9: Merchandise | N9: =SUMIFS(dis_table[Amount],dis_table[Category],$M9,dis_table[Date],N$1) -> 802.23 | O9: =SUMIFS(dis_table[Amount],dis_table[Category],$M9,dis_table[Date],O$1) -> 473.95 | P9: =SUMIFS(dis_table[Amount],dis_table[Category],$M9,dis_table[Date],P$1) -> 1208.91 | Q9: =SUMIFS(dis_table[Amount],dis_table[Category],$M9,dis_table[Date],Q$1) -> 1041.03 | R9: =SUMIFS(dis_table[Amount],dis_table[Category],$M9,dis_table[Date],R$1) -> 1359.53 | S9: =SUMIFS(dis_table[Amount],dis_table[Category],$M9,dis_table[Date],S$1) -> 900.1 | T9: =SUMIFS(dis_table[Amount],dis_table[Category],$M9,dis_table[Date],T$1) -> 1381.63 | U9: =SUMIFS(dis_table[Amount],dis_table[Category],$M9,dis_table[Date],U$1) -> 796.45 | ... Y9: =SUMIFS(dis_table[Amount],dis_table[Category],$M9,dis_table[Date],Y$1) -> 0
A10: 8 | B10: 01/04/2022 | C10: 01/04/2022 | D10: AUTOZONE #2768 PHOENIX AZ | E10: 42.34 | F10: Automotive | G10: car | H10: 01/2022 | I10: No | J10: Utilities | K10: 1949.84 | M10: Restaurants | N10: =SUMIFS(dis_table[Amount],dis_table[Category],$M10,dis_table[Date],N$1) -> 388.66 | O10: =SUMIFS(dis_table[Amount],dis_table[Category],$M10,dis_table[Date],O$1) -> 115.83 | P10: =SUMIFS(dis_table[Amount],dis_table[Category],$M10,dis_table[Date],P$1) -> 1073.85 | Q10: =SUMIFS(dis_table[Amount],dis_table[Category],$M10,dis_table[Date],Q$1) -> 575.54 | R10: =SUMIFS(dis_table[Amount],dis_table[Category],$M10,dis_table[Date],R$1) -> 770.3 | S10: =SUMIFS(dis_table[Amount],dis_table[Category],$M10,dis_table[Date],S$1) -> 478.24 | T10: =SUMIFS(dis_table[Amount],dis_table[Category],$M10,dis_table[Date],T$1) -> 801.09 | U10: =SUMIFS(dis_table[Amount],dis_table[Category],$M10,dis_table[Date],U$1) -> 643.66 | ... Y10: =SUMIFS(dis_table[Amount],dis_table[Category],$M10,dis_table[Date],Y$1) -> 0
A11: 9 | B11: 01/04/2022 | C11: 01/04/2022 | D11: STATE FARM INSURANCE 800-956-6310 ILITEM TRANSFERRED FROM PREV ACCOUNT | E11: 79.38 | F11: Merchandise | G11: state_farm | H11: 01/2022 | I11: Yes | J11: Insurance | K11: 2029.22 | M11: Services | N11: =SUMIFS(dis_table[Amount],dis_table[Category],$M11,dis_table[Date],N$1) -> 497.44 | O11: =SUMIFS(dis_table[Amount],dis_table[Category],$M11,dis_table[Date],O$1) -> 132.57 | P11: =SUMIFS(dis_table[Amount],dis_table[Category],$M11,dis_table[Date],P$1) -> 378.81 | Q11: =SUMIFS(dis_table[Amount],dis_table[Category],$M11,dis_table[Date],Q$1) -> 78.88 | R11: =SUMIFS(dis_table[Amount],dis_table[Category],$M11,dis_table[Date],R$1) -> 138.95 | S11: =SUMIFS(dis_table[Amount],dis_table[Category],$M11,dis_table[Date],S$1) -> 134.85 | T11: =SUMIFS(dis_table[Amount],dis_table[Category],$M11,dis_table[Date],T$1) -> 246.78 | U11: =SUMIFS(dis_table[Amount],dis_table[Category],$M11,dis_table[Date],U$1) -> 35.85 | ... Y11: =SUMIFS(dis_table[Amount],dis_table[Category],$M11,dis_table[Date],Y$1) -> 0
A12: 10 | B12: 01/05/2022 | C12: 01/05/2022 | D12: MCDONALD'S F20697 PHOENIX AZAPPLE PAY ENDING IN 4775 | E12: 8 | F12: Restaurants | G12: fast_food | H12: 01/2022 | I12: No | J12: Food | K12: 2037.22 | M12: Supermarkets | N12: =SUMIFS(dis_table[Amount],dis_table[Category],$M12,dis_table[Date],N$1) -> 151.27 | O12: =SUMIFS(dis_table[Amount],dis_table[Category],$M12,dis_table[Date],O$1) -> 132.46 | P12: =SUMIFS(dis_table[Amount],dis_table[Category],$M12,dis_table[Date],P$1) -> 12.27 | Q12: =SUMIFS(dis_table[Amount],dis_table[Category],$M12,dis_table[Date],Q$1) -> 459.72 | R12: =SUMIFS(dis_table[Amount],dis_table[Category],$M12,dis_table[Date],R$1) -> 46.36 | S12: =SUMIFS(dis_table[Amount],dis_table[Category],$M12,dis_table[Date],S$1) -> 181.77 | T12: =SUMIFS(dis_table[Amount],dis_table[Category],$M12,dis_table[Date],T$1) -> 372.82 | U12: =SUMIFS(dis_table[Amount],dis_table[Category],$M12,dis_table[Date],U$1) -> 220.27 | ... Y12: =SUMIFS(dis_table[Amount],dis_table[Category],$M12,dis_table[Date],Y$1) -> 0
A13: 11 | B13: 01/08/2022 | C13: 01/08/2022 | D13: 3856 EL POLLO LOCO PHOENIX AZ | E13: 29.93 | F13: Restaurants | G13: fast_food | H13: 01/2022 | I13: No | J13: Food | K13: 2067.15 | M13: Travel/ Entertainment | N13: =SUMIFS(dis_table[Amount],dis_table[Category],$M13,dis_table[Date],N$1) -> 217.36 | O13: =SUMIFS(dis_table[Amount],dis_table[Category],$M13,dis_table[Date],O$1) -> 608.72 | P13: =SUMIFS(dis_table[Amount],dis_table[Category],$M13,dis_table[Date],P$1) -> 422 | Q13: =SUMIFS(dis_table[Amount],dis_table[Category],$M13,dis_table[Date],Q$1) -> 409.8 | R13: =SUMIFS(dis_table[Amount],dis_table[Category],$M13,dis_table[Date],R$1) -> 1511.29 | S13: =SUMIFS(dis_table[Amount],dis_table[Category],$M13,dis_table[Date],S$1) -> 1230.06 | T13: =SUMIFS(dis_table[Amount],dis_table[Category],$M13,dis_table[Date],T$1) -> 418.69 | U13: =SUMIFS(dis_table[Amount],dis_table[Category],$M13,dis_table[Date],U$1) -> 32.04 | ... Y13: =SUMIFS(dis_table[Amount],dis_table[Category],$M13,dis_table[Date],Y$1) -> 0
A14: 12 | B14: 01/08/2022 | C14: 01/08/2022 | D14: DRI*NVIDIA STORE NVIDIA.COM MNITEM TRANSFERRED FROM PREV ACCOUNT | E14: 4.99 | F14: Merchandise | G14: nvidia | H14: 01/2022 | I14: Yes | J14: Recreation_Entertainment | K14: 2072.14 | M14: Balance | N14: =SUM(N2:N13) -> 2191.71 | O14: =SUM(O2:O13) -> 1463.53 | P14: =SUM(P2:P13) -> 3905.37 | Q14: =SUM(Q2:Q13) -> 2590.27 | R14: =SUM(R2:R13) -> 3987.62 | S14: =SUM(S2:S13) -> 3334.06 | T14: =SUM(T2:T13) -> 3720.55 | U14: =SUM(U2:U13) -> 2150.77 | ... Y14: =SUM(Y2:Y13) -> 0
A15: 13 | B15: 01/09/2022 | C15: 01/09/2022 | D15: SAFEWAY #2651 PHOENIX AZ | E15: 36.72 | F15: Supermarkets | G15: groceries | H15: 01/2022 | I15: No | J15: Food | K15: 2108.86 | M15: Payments and Credits | N15: =SUMIFS(dis_table[Amount],dis_table[Category],$M15,dis_table[Date],N$1) -> -3994.92 | O15: =SUMIFS(dis_table[Amount],dis_table[Category],$M15,dis_table[Date],O$1) -> -2509.43 | P15: =SUMIFS(dis_table[Amount],dis_table[Category],$M15,dis_table[Date],P$1) -> -1969.1 | Q15: =SUMIFS(dis_table[Amount],dis_table[Category],$M15,dis_table[Date],Q$1) -> -934.85 | R15: =SUMIFS(dis_table[Amount],dis_table[Category],$M15,dis_table[Date],R$1) -> -2000 | S15: =SUMIFS(dis_table[Amount],dis_table[Category],$M15,dis_table[Date],S$1) -> -4008 | T15: =SUMIFS(dis_table[Amount],dis_table[Category],$M15,dis_table[Date],T$1) -> -8859.68 | U15: =SUMIFS(dis_table[Amount],dis_table[Category],$M15,dis_table[Date],U$1) -> -1792.5 | ... Y15: =SUMIFS(dis_table[Amount],dis_table[Category],$M15,dis_table[Date],Y$1) -> 0
A16: 14 | B16: 01/09/2022 | C16: 01/09/2022 | D16: SAFEWAY #2651 PHOENIX AZ | E16: 32.58 | F16: Supermarkets | G16: groceries | H16: 01/2022 | I16: No | J16: Food | K16: 2141.44 | M16: Awards and Rebate Credits | N16: =SUMIFS(dis_table[Amount],dis_table[Category],$M16,dis_table[Date],N$1) -> -29.08 | O16: =SUMIFS(dis_table[Amount],dis_table[Category],$M16,dis_table[Date],O$1) -> -29.29 | P16: =SUMIFS(dis_table[Amount],dis_table[Category],$M16,dis_table[Date],P$1) -> 0 | Q16: =SUMIFS(dis_table[Amount],dis_table[Category],$M16,dis_table[Date],Q$1) -> -65.15 | R16: =SUMIFS(dis_table[Amount],dis_table[Category],$M16,dis_table[Date],R$1) -> -41.23 | S16: =SUMIFS(dis_table[Amount],dis_table[Category],$M16,dis_table[Date],S$1) -> 0 | T16: =SUMIFS(dis_table[Amount],dis_table[Category],$M16,dis_table[Date],T$1) -> -81.42 | U16: =SUMIFS(dis_table[Amount],dis_table[Category],$M16,dis_table[Date],U$1) -> -53.05 | ... Y16: =SUMIFS(dis_table[Amount],dis_table[Category],$M16,dis_table[Date],Y$1) -> 0
A17: 15 | B17: 01/09/2022 | C17: 01/09/2022 | D17: PAYPAL *HEARSTMAGAZ 402-935-7733 CA | E17: 20 | F17: Merchandise | G17: pay_wall | H17: 01/2022 | I17: Yes | J17: Recreation_Entertainment | K17: 2161.44
A18: 16 | B18: 01/09/2022 | C18: 01/09/2022 | D18: SAFEWAY #2651 PHOENIX AZ | E18: 2.49 | F18: Supermarkets | G18: groceries | H18: 01/2022 | I18: No | J18: Food | K18: 2163.93 | N18: 01/2022 | O18: 02/2022 | P18: 03/2022 | Q18: 04/2022 | R18: 05/2022 | S18: 06/2022 | T18: 07/2022 | U18: 08/2022 | V18: 09/2022 | W18: 10/2022 | X18: 11/2022 | Y18: 12/2022
A19: 17 | B19: 01/10/2022 | C19: 01/10/2022 | D19: AMZN MKTP US*BP5036MA3 AMZN.COM/BILLWAITEM TRANSFERRED FROM PREV ACCOUNT | E19: 49.98 | F19: Merchandise | G19: amazon | H19: 01/2022 | I19: No | J19: Personal_Spending | K19: 2213.91 | M19: =M14 -> Balance | N19: 3659.69 | O19: =O14 -> 1463.53 | P19: =P14 -> 3905.37 | Q19: =Q14 -> 2590.27 | R19: =R14 -> 3987.62 | S19: =S14 -> 3334.06 | T19: =T14 -> 3720.55 | U19: =U14 -> 2150.77 | V19: =V14 -> 3625.55 | ... Y19: =Y14 -> 0
A20: 18 | B20: 01/10/2022 | C20: 01/10/2022 | D20: MCDONALD'S F20697 PHOENIX AZ | E20: 10.09 | F20: Restaurants | G20: fast_food | H20: 01/2022 | I20: No | J20: Food | K20: 2224 | M20: =M15 -> Payments and Credits | N20: =N15*-1 -> 3994.92 | O20: =O15*-1 -> 2509.43 | P20: =P15*-1 -> 1969.1 | Q20: =Q15*-1 -> 934.85 | R20: =R15*-1 -> 2000 | S20: =S15*-1 -> 4008 | T20: =T15*-1 -> 8859.68 | U20: =U15*-1 -> 1792.5 | ... Y20: =Y15*-1 -> 0
A21: 19 | B21: 01/11/2022 | C21: 01/11/2022 | D21: LIFE TIME ATHLETIC 279 PHOENIX AZ01118R | E21: 210 | F21: Travel/ Entertainment | G21: gym | H21: 01/2022 | I21: No | J21: Personal_Spending | K21: 2434
A22: 20 | B22: 01/12/2022 | C22: 01/12/2022 | D22: CAFE RIO 0084 SCOTTSDALE SCOTTSDALE AZ | E22: 15.1 | F22: Restaurants | G22: fast_food | H22: 01/2022 | I22: No | J22: Food | K22: 2449.1
A23: 21 | B23: 01/12/2022 | C23: 01/12/2022 | D23: CVS/PHARMACY #09252 SCOTTSDALE AZAPPLE PAY ENDING IN 4775 | E23: 19.8 | F23: Merchandise | G23: conv_store | H23: 01/2022 | I23: No | J23: Personal_Spending | K23: 2468.9
A24: 22 | B24: 01/13/2022 | C24: 01/13/2022 | D24: INTERNET PAYMENT - THANK YOU | E24: -2194.92 | F24: Payments and Credits | G24: payment | H24: 01/2022 | I24: No | J24: Payment_and_Interest | K24: 273.98
A25: 23 | B25: 01/13/2022 | C25: 01/13/2022 | D25: CASHBACK BONUS REDEMPTION PYMT/STMT CRDT | E25: -29.08 | F25: Awards and Rebate Credits | G25: cashback_bonus | H25: 01/2022 | I25: No | J25: Payment_and_Interest | K25: 244.9
A26: 24 | B26: 01/13/2022 | C26: 01/13/2022 | D26: CIRCLE K 01930 YUMA AZ01374R | E26: 30.89 | F26: Gasoline | G26: gas_station | H26: 01/2022 | I26: No | J26: Transportation | K26: 275.79
A27: 25 | B27: 01/14/2022 | C27: 01/14/2022 | D27: MCDONALDS 20697 PHOENIX AZ | E27: 6.29 | F27: Restaurants | G27: fast_food | H27: 01/2022 | I27: No | J27: Food | K27: 282.08
A28: 26 | B28: 01/14/2022 | C28: 02/03/2022 | D28: SEVEN MILE CASINO RESTAU CHULA VISTA CA | E28: 60 | F28: Restaurants | G28: restaurant | H28: 01/2022 | I28: No | J28: Food | K28: 342.08
A29: 27 | B29: 01/14/2022 | C29: 01/14/2022 | D29: APPLE.COM/BILL 866-712-7753 CAAPPLE PAY ENDING IN 4775MMW7SF5QV8A0 | E29: 15.89 | F29: Merchandise | G29: hbo | H29: 01/2022 | I29: Yes | J29: Recreation_Entertainment | K29: 357.97
A30: 28 | B30: 01/15/2022 | C30: 01/15/2022 | D30: RALPHS # 0212 SAN DIEGO CA | E30: 35.02 | F30: Supermarkets | G30: groceries | H30: 01/2022 | I30: No | J30: Food | K30: 392.99
A31: 29 | B31: 01/15/2022 | C31: 01/15/2022 | D31: TACOS EL GORDO - CHULA V CHULA VISTA CA | E31: 21.49 | F31: Restaurants | G31: fast_food | H31: 01/2022 | I31: No | J31: Food | K31: 414.48
A32: 30 | B32: 01/15/2022 | C32: 01/15/2022 | D32: THE CRACK SHACK LITTLE I SAN DIEGO CA | E32: 52.41 | F32: Restaurants | G32: restaurant | H32: 01/2022 | I32: No | J32: Food | K32: 466.89
... A739: 737 | B739: 09/14/2022 | C739: 09/14/2022 | D739: TST* RISE PIZZERIA BURLINGAME CA00049860008560623466AA | E739: 37 | F739: Restaurants | G739: restaurant | H739: 09/2022 | I739: No | J739: Food | K739: 668.05
A740: 738 | B740: 09/15/2022 | C740: 09/15/2022 | D740: APPLE.COM/US 800-676-2775 CAW1217133334A263446652 | E740: 53.72 | F740: Merchandise | H740: 09/2022 | I740: No | K740: 721.77
A741: 739 | B741: 09/15/2022 | C741: 09/15/2022 | D741: HAN SUNG BBQ SANTA CLARA CA | E741: 42 | F741: Restaurants | G741: restaurant | H741: 09/2022 | I741: No | J741: Food | K741: 763.77
A742: 740 | B742: 09/16/2022 | C742: 09/16/2022 | D742: FLIGHTS BURLINGAME CA | E742: 102.7 | F742: Restaurants | G742: restaurant | H742: 09/2022 | I742: No | J742: Food | K742: 866.47
A743: 741 | B743: 09/17/2022 | C743: 09/17/2022 | D743: TMOBILE*AUTO PAY 800-937-8997 WAITEM TRANSFERRED FROM PREV ACCOUNT | E743: 70 | F743: Merchandise | G743: cell_phone | H743: 09/2022 | I743: No | J743: Utilities | K743: 936.47
A744: 742 | B744: 09/17/2022 | C744: 09/17/2022 | D744: TARGET 00011221091 SAN MATEO CA | E744: 27.89 | F744: Supermarkets | G744: target | H744: 09/2022 | I744: No | J744: Personal_Spending | K744: 964.36
A745: 743 | B745: 09/17/2022 | C745: 09/17/2022 | D745: CKE*SOM TUM STATION SAN SAN MATEO CA | E745: 14.83 | F745: Restaurants | G745: restaurant | H745: 09/2022 | I745: No | J745: Food | K745: 979.19
A746: 744 | B746: 09/17/2022 | C746: 09/17/2022 | D746: APPLE.COM/BILL 111-111-1111 CAAPPLE PAY ENDING IN 4775 | E746: 5.29 | F746: Merchandise | G746: apple_tv | H746: 09/2022 | I746: Yes | J746: Recreation_Entertainment | K746: 984.48
...

Sheet Discover Account
A1: Date | B1: Payment | C1: CumAmount
A2: 01/2022 | C2: 3581.67
A3: 01/2022 | C3: 3599.69
A4: 01/2022 | B4: -1800 | C4: 3659.69
A5: 01/2022 | C5: 3674.52
A6: 01/2022 | C6: 3684.51
A7: 01/2022 | C7: 3694.6
A8: 01/2022 | C8: 3744.58
A9: 01/2022 | C9: 3954.58
A10: 01/2022 | C10: 3974.38
A11: 01/2022 | C11: 3989.48
A12: 01/2022 | C12: 1794.56
A13: 01/2022 | C13: 1825.45
A14: 01/2022 | C14: 1796.37
A15: 01/2022 | C15: 1856.37
A16: 01/2022 | C16: 1862.66
... A32: 01/2022 | C32: 2573.73
A33: 01/2022 | B33: =(C32-C33)*-1 -> -1800 | C33: 773.73
A34: 01/2022 | C34: 786.72
A35: 01/2022 | C35: 797.72
A36: 01/2022 | C36: 802.71
A37: 01/2022 | C37: 835.15
A38: 01/2022 | C38: 841.98
A39: 01/2022 | C39: 849.34
A40: 01/2022 | C40: 879.33
A41: 01/2022 | C41: 902.12
A42: 01/2022 | C42: 935.1
A43: 01/2022 | C43: 965.1
A44: 01/2022 | C44: 1044.1
A45: 01/2022 | C45: 1074.1
... A74: 02/2022 | C74: 1897.34
A75: 02/2022 | B75: =(C74-C75)*-1 -> -1733.33 | C75: 164.01
A76: 02/2022 | C76: 179.9
A77: 02/2022 | B77: =(C76-C77)*-1 -> -5 | C77: 174.9
A78: 02/2022 | C78: 184.1
A79: 02/2022 | C79: 204.1
A80: 02/2022 | C80: 218.21
A81: 02/2022 | C81: 233.2
A82: 02/2022 | C82: 259.79
A83: 02/2022 | C83: 308.79
...

Sheet Care Credit
A1: Transaction Date | B1: Post Date | C1: Description | D1: Amount | E1: Short_Desc | F1: Date | G1: Category_2
A2: 44571 | B2: 44571 | C2: 8534812QVLH06N92F WESTERN DENTAL OF ARIZONAPHOENIX AZ | D2: 2286 | E2: Dental | F2: =MONTH(A2)&"/"&YEAR(A2) -> 1/2022 | G2: Medical
A3: 44574 | B3: 44574 | C3: 8534812QX019L6GDK PAYMENT - THANK YOU | D3: -1000 | E3: Payment | F3: =MONTH(A3)&"/"&YEAR(A3) -> 1/2022
A4: 44599 | B4: 44599 | C4: Card Security 1-800-815-4051 | D4: 21.35 | E4: Security | F4: =MONTH(A4)&"/"&YEAR(A4) -> 2/2022 | G4: Medical
A5: 44602 | B5: 44602 | C5: 8534812DT01Q3QH69 PAYMENT - THANK YOU | D5: -307.35 | E5: Payment | F5: =MONTH(A5)&"/"&YEAR(A5) -> 2/2022
A6: 44611 | B6: 44611 | C6: 8534812E301QZ55AX PAYMENT - THANK YOU | D6: -1000 | E6: Payment | F6: =MONTH(A6)&"/"&YEAR(A6) -> 2/2022
A7: 44645 | B7: 44645 | C7: 8534812F6LK8M1WZE BANNER SURGERY CENTER CAMPHOENIX AZ | D7: 2121.16 | E7: Surgery | F7: =MONTH(A7)&"/"&YEAR(A7) -> 3/2022 | G7: Medical
A8: 44658 | B8: 44658 | C8: 8534812FH01H6BNDY PAYMENT - THANK YOU | D8: -1000 | E8: Payment | F8: =MONTH(A8)&"/"&YEAR(A8) -> 4/2022
A9: 44659 | B9: 44659 | C9: Card Security 1-800-815-4051 | D9: 18.61 | E9: Security | F9: =MONTH(A9)&"/"&YEAR(A9) -> 4/2022
A10: 44677 | B10: 44677 | C10: 8534812G501JT48VE PAYMENT - THANK YOU | D10: -139.77 | E10: Payment | F10: =MONTH(A10)&"/"&YEAR(A10) -> 4/2022
A11: 44686 | B11: 44686 | C11: 8534812GD01KKWEH4 PAYMENT - THANK YOU | D11: -1000 | E11: Payment | F11: =MONTH(A11)&"/"&YEAR(A11) -> 5/2022
A12: 44760 | B12: 44760 | C12: 8534812JRLK8M1WZF BANNER SURGERY CENTER CAMPHOENIX AZ | D12: -504.86 | E12: refund | F12: =MONTH(A12)&"/"&YEAR(A12) -> 7/2022
A13: 44763 | B13: 44763 | C13: F907200JU000CB202 CREDIT BALANCE I KETTERING OH | D13: 504.86 | E13: Refund | F13: =MONTH(A13)&"/"&YEAR(A13) -> 7/2022 | G13: Medical

Sheet Best Buy
A1: Transaction Date | B1: Amount | C1: Description | D1: Category | E1: Short_Desc | F1: Date | G1: Category_2
A2: 44697 | B2: 582.53 | C2: COACHING ACTUARIES WWW.COACHINGAIA | D2: sale | E2: learning | F2: =MONTH(A2)&"/"&YEAR(A2) -> 5/2022 | G2: Personal_Spending
A3: 44714 | B3: -974.91 | C3: ONLINE PAYMENT DEERFIELD IL | D3: payment | E3: payment | F3: =MONTH(A3)&"/"&YEAR(A3) -> 6/2022
A4: 44702 | B4: 12 | C4: SEASCAPE GOLF CLUB APTOS CA | D4: sale | E4: golf | F4: =MONTH(A4)&"/"&YEAR(A4) -> 5/2022 | G4: Recreation_Entertainment
A5: 44702 | B5: 9.6 | C5: SEASCAPE GOLF CLUB APTOS CA | D5: sale | E5: golf | F5: =MONTH(A5)&"/"&YEAR(A5) -> 5/2022 | G5: Recreation_Entertainment
A6: 44702 | B6: 26.14 | C6: SEASCAPE GOLF CLUB APTOS CA | D6: sale | E6: golf | F6: =MONTH(A6)&"/"&YEAR(A6) -> 5/2022 | G6: Recreation_Entertainment
A7: 44702 | B7: 299.8 | C7: TST* Laili Restaurant Santa Cruz CA | D7: sale | E7: golf | F7: =MONTH(A7)&"/"&YEAR(A7) -> 5/2022 | G7: Recreation_Entertainment
A8: 44703 | B8: 32 | C8: MELOMELO KAVA BAR - SANT SANTA CRUZ CA | D8: sale | E8: resteraunt | F8: =MONTH(A8)&"/"&YEAR(A8) -> 5/2022 | G8: Food
A9: 44703 | B9: 12.84 | C9: SQ *HMB COFFEE CO Half Moon BayCA | D9: sale | E9: coffee | F9: =MONTH(A9)&"/"&YEAR(A9) -> 5/2022 | G9: Food

Sheet Wells Fargo
A1: Trans Date | B1: Debit_Amount | C1: Amount | D1: Description | E1: Short_Desc | F1: Date | G1: Category_2
A2: 44564 | B2: -1800 | C2: =IF(SIGN(B2)=-1, B2*-1, B2) -> 1800 | D2: DISCOVER E-PAYMENT 220102 4618 LEWIS SEAN | E2: discover | F2: =MONTH(A2)&"/"&YEAR(A2) -> 1/2022 | G2: credit
A3: 44564 | B3: -241.99 | C3: =IF(SIGN(B3)=-1, B3*-1, B3) -> 241.99 | D3: BEST BUY PAYMENT 220102 610633785460241 SEAN LEWIS | E3: best_buy | F3: =MONTH(A3)&"/"&YEAR(A3) -> 1/2022 | G3: credit
A4: 44564 | B4: -10 | C4: =IF(SIGN(B4)=-1, B4*-1, B4) -> 10 | D4: PAYPAL INST XFER 220101 LOUISCK SEAN LEWIS | E4: comedy | F4: =MONTH(A4)&"/"&YEAR(A4) -> 1/2022 | G4: =IFERROR(VLOOKUP('Wells Fargo'!E159,dis_table[[#All],[Short_Desc]:[CumAmount]],4,0),0) -> 0
A5: 44564 | B5: 194 | C5: =IF(SIGN(B5)=-1, B5*-1, B5) -> 194 | D5: ATM CASH DEPOSIT ON 01/02 3002 N Central Ave Phoenix AZ 0003743 ATM ID 5449B CARD 6634 | E5: atm | F5: =MONTH(A5)&"/"&YEAR(A5) -> 1/2022 | G5: 0
A6: 44564 | B6: -485 | C6: =IF(SIGN(B6)=-1, B6*-1, B6) -> 485 | D6: TRANSFER TO LEWIS SHARON ON 01/03 REF #PP0D9295LZ XXXXXXXXX5267 | E6: mom | F6: =MONTH(A6)&"/"&YEAR(A6) -> 1/2022 | G6: People
A7: 44564 | B7: 477.73 | C7: =IF(SIGN(B7)=-1, B7*-1, B7) -> 477.73 | D7: RTP from VENMO on 01/03 Ref#20220103021000021P1BRJPM00530020747 | E7: Vincent | F7: =MONTH(A7)&"/"&YEAR(A7) -> 1/2022 | G7: People
A8: 44568 | B8: 30.89 | C8: =IF(SIGN(B8)=-1, B8*-1, B8) -> 30.89 | D8: VENMO CASHOUT 220107 1017829933941 SEAN LEWIS | E8: Vincent | F8: =MONTH(A8)&"/"&YEAR(A8) -> 1/2022 | G8: Utilities
A9: 44568 | B9: 23.27 | C9: =IF(SIGN(B9)=-1, B9*-1, B9) -> 23.27 | D9: LIFETIME FITNESS DIRECT DEP 220107 558079861456SHS LEWIS,SEAN | E9: gym | F9: =MONTH(A9)&"/"&YEAR(A9) -> 1/2022 | G9: =IFERROR(VLOOKUP('Wells Fargo'!E156,dis_table[[#All],[Short_Desc]:[CumAmount]],4,0),0) -> 0
A10: 44571 | B10: 234.58 | C10: =IF(SIGN(B10)=-1, B10*-1, B10) -> 234.58 | D10: VENMO CASHOUT 220110 1017875354612 SEAN LEWIS | E10: Melanie | F10: =MONTH(A10)&"/"&YEAR(A10) -> 1/2022 | G10: Utilities
A11: 44571 | B11: 50 | C11: =IF(SIGN(B11)=-1, B11*-1, B11) -> 50 | D11: VENMO CASHOUT 220110 1017874602288 SEAN LEWIS | E11: Kabir | F11: =MONTH(A11)&"/"&YEAR(A11) -> 1/2022 | G11: Recreation_Entertainment
A12: 44572 | B12: -100 | C12: =IF(SIGN(B12)=-1, B12*-1, B12) -> 100 | D12: PURCHASE AUTHORIZED ON 01/10 CASH APP*CYANFACE 8774174551 CA S462010765413680 CARD 6634 | E12: Jayelin | F12: =MONTH(A12)&"/"&YEAR(A12) -> 1/2022 | G12: People
A13: 44574 | B13: -2194.92 | C13: =IF(SIGN(B13)=-1, B13*-1, B13) -> 2194.92 | D13: DISCOVER E-PAYMENT 220113 4618 LEWIS SEAN | E13: discover | F13: =MONTH(A13)&"/"&YEAR(A13) -> 1/2022 | G13: credit
A14: 44574 | B14: 3898.5 | C14: =IF(SIGN(B14)=-1, B14*-1, B14) -> 3898.5 | D14: Nationwide PAYROLL 01 HRP0007983168 Sean Lewis | E14: nationwide | F14: =MONTH(A14)&"/"&YEAR(A14) -> 1/2022 | G14: income
A15: 44575 | B15: -1000 | C15: =IF(SIGN(B15)=-1, B15*-1, B15) -> 1000 | D15: Synchrony Bank CC PYMT JAN 13 601918368630042 SEAN LEWIS | E15: care_credit | F15: =MONTH(A15)&"/"&YEAR(A15) -> 1/2022 | G15: credit
A16: 44575 | B16: -2.5 | C16: =IF(SIGN(B16)=-1, B16*-1, B16) -> 2.5 | D16: NON-WELLS FARGO ATM TRANSACTION FEE | E16: atm | F16: =MONTH(A16)&"/"&YEAR(A16) -> 1/2022 | G16: =IFERROR(VLOOKUP('Wells Fargo'!E148,dis_table[[#All],[Short_Desc]:[CumAmount]],4,0),0) -> 0
A17: 44575 | B17: -103.5 | C17: =IF(SIGN(B17)=-1, B17*-1, B17) -> 103.5 | D17: NON-WF ATM WITHDRAWAL AUTHORIZED ON 01/14 666 W E ST SAN DIEGO CA 382015019310845 ATM ID CA0961 CARD 6634 | E17: atm | F17: =MONTH(A17)&"/"&YEAR(A17) -> 1/2022 | G17: 0
A18: 44579 | B18: -48.5 | C18: =IF(SIGN(B18)=-1, B18*-1, B18) -> 48.5 | D18: NON-WF ATM WITHDRAWAL AUTHORIZED ON 01/16 4645 DE SOTO ST SAN DIEGO CA 582017109140029 ATM ID L631055 CARD 6634 | E18: atm | F18: =MONTH(A18)&"/"&YEAR(A18) -> 1/2022 | G18: =IFERROR(VLOOKUP('Wells Fargo'!E140,dis_table[[#All],[Short_Desc]:[CumAmount]],4,0),0) -> 0
A19: 44579 | B19: -2.5 | C19: =IF(SIGN(B19)=-1, B19*-1, B19) -> 2.5 | D19: NON-WELLS FARGO ATM TRANSACTION FEE | E19: atm | F19: =MONTH(A19)&"/"&YEAR(A19) -> 1/2022 | G19: =IFERROR(VLOOKUP('Wells Fargo'!E144,dis_table[[#All],[Short_Desc]:[CumAmount]],4,0),0) -> 0
A20: 44579 | B20: -10 | C20: =IF(SIGN(B20)=-1, B20*-1, B20) -> 10 | D20: PURCHASE AUTHORIZED ON 01/16 CASH APP*VALLEY 8774174551 CA S382017149175934 CARD 6634 | E20: fast_food | F20: =MONTH(A20)&"/"&YEAR(A20) -> 1/2022 | G20: =IFERROR(VLOOKUP('Wells Fargo'!E137,dis_table[[#All],[Short_Desc]:[CumAmount]],4,0),0) -> Misc
A21: 44579 | B21: -20 | C21: =IF(SIGN(B21)=-1, B21*-1, B21) -> 20 | D21: PURCHASE AUTHORIZED ON 01/16 CASH APP*DARIUS CA 8774174551 CA S382017148849842 CARD 6634 | E21: fast_food | F21: =MONTH(A21)&"/"&YEAR(A21) -> 1/2022 | G21: =IFERROR(VLOOKUP('Wells Fargo'!E138,dis_table[[#All],[Short_Desc]:[CumAmount]],4,0),0) -> Personal_Spending
A22: 44579 | B22: -2.5 | C22: =IF(SIGN(B22)=-1, B22*-1, B22) -> 2.5 | D22: NON-WELLS FARGO ATM TRANSACTION FEE | E22: atm | F22: =MONTH(A22)&"/"&YEAR(A22) -> 1/2022 | G22: =IFERROR(VLOOKUP('Wells Fargo'!E139,dis_table[[#All],[Short_Desc]:[CumAmount]],4,0),0) -> People
A23: 44579 | B23: -54.04 | C23: =IF(SIGN(B23)=-1, B23*-1, B23) -> 54.04 | D23: PURCHASE AUTHORIZED ON 01/16 CHEVRON 0094991 SAN DIEGO CA S382017053945491 CARD 6634 | E23: gas_station | F23: =MONTH(A23)&"/"&YEAR(A23) -> 1/2022 | G23: =IFERROR(VLOOKUP('Wells Fargo'!E141,dis_table[[#All],[Short_Desc]:[CumAmount]],4,0),0) -> 0
A24: 44579 | B24: -21.54 | C24: =IF(SIGN(B24)=-1, B24*-1, B24) -> 21.54 | D24: PURCHASE AUTHORIZED ON 01/16 SD ZOO CINNAMON TR SAN DIEGO CA S382017034170694 CARD 6634 | E24: zoo | F24: =MONTH(A24)&"/"&YEAR(A24) -> 1/2022 | G24: =IFERROR(VLOOKUP('Wells Fargo'!E142,dis_table[[#All],[Short_Desc]:[CumAmount]],4,0),0) -> 0
A25: 44579 | B25: -6.99 | C25: =IF(SIGN(B25)=-1, B25*-1, B25) -> 6.99 | D25: PURCHASE AUTHORIZED ON 01/16 SD ZOO CANYON CAFE SAN DIEGO CA S582016817636715 CARD 6634 | E25: zoo | F25: =MONTH(A25)&"/"&YEAR(A25) -> 1/2022 | G25: =IFERROR(VLOOKUP('Wells Fargo'!E143,dis_table[[#All],[Short_Desc]:[CumAmount]],4,0),0) -> People
A26: 44579 | B26: -42.75 | C26: =IF(SIGN(B26)=-1, B26*-1, B26) -> 42.75 | D26: NON-WF ATM WITHDRAWAL AUTHORIZED ON 01/16 3710 VOLTAIRE ST. STE 1 SAN DIEGO CA 582016595373620 ATM ID P459681 CARD 6634 | E26: atm | F26: =MONTH(A26)&"/"&YEAR(A26) -> 1/2022 | G26: =IFERROR(VLOOKUP('Wells Fargo'!E145,dis_table[[#All],[Short_Desc]:[CumAmount]],4,0),0) -> 0
A27: 44579 | B27: -40 | C27: =IF(SIGN(B27)=-1, B27*-1, B27) -> 40 | D27: PURCHASE AUTHORIZED ON 01/15 BALLAST POINT LITT SAN DIEGO CA S302015831911176 CARD 6634 | E27: restaurant | F27: =MONTH(A27)&"/"&YEAR(A27) -> 1/2022 | G27: Food
A28: 44579 | B28: -576.01 | C28: =IF(SIGN(B28)=-1, B28*-1, B28) -> 576.01 | D28: VENMO PAYMENT 220117 1018001608819 SEAN LEWIS | E28: Kabir | F28: =MONTH(A28)&"/"&YEAR(A28) -> 1/2022 | G28: Recreation_Entertainment
A29: 44579 | B29: -68.33 | C29: =IF(SIGN(B29)=-1, B29*-1, B29) -> 68.33 | D29: VENMO PAYMENT 220117 1018001751483 SEAN LEWIS | E29: Logan | F29: =MONTH(A29)&"/"&YEAR(A29) -> 1/2022 | G29: Recreation_Entertainment
A30: 44585 | B30: -70 | C30: =IF(SIGN(B30)=-1, B30*-1, B30) -> 70 | D30: VENMO PAYMENT 220122 1018085063025 SEAN LEWIS | E30: Jon | F30: =MONTH(A30)&"/"&YEAR(A30) -> 1/2022 | G30: Personal_Spending
A31: 44588 | B31: -1866.67 | C31: =IF(SIGN(B31)=-1, B31*-1, B31) -> 1866.67 | D31: VENMO PAYMENT 220127 1018168964129 SEAN LEWIS | E31: rent | F31: =MONTH(A31)&"/"&YEAR(A31) -> 1/2022 | G31: Housing
A32: 44588 | B32: 933.33 | C32: =IF(SIGN(B32)=-1, B32*-1, B32) -> 933.33 | D32: VENMO CASHOUT 220127 1018164349212 SEAN LEWIS | E32: Vincent | F32: =MONTH(A32)&"/"&YEAR(A32) -> 1/2022 | G32: Housing
A33: 44588 | B33: 1718.36 | C33: =IF(SIGN(B33)=-1, B33*-1, B33) -> 1718.36 | D33: Nationwide PAYROLL 01 HRP0008024211 Sean Lewis | E33: nationwide | F33: =MONTH(A33)&"/"&YEAR(A33) -> 1/2022 | G33: income
A34: 44592 | B34: -120 | C34: =IF(SIGN(B34)=-1, B34*-1, B34) -> 120 | D34: TRANSFER TO LEWIS DON ON 01/31 REF #PP0Q7YVDF7 XXXXXX7932 | E34: Don | F34: =MONTH(A34)&"/"&YEAR(A34) -> 1/2022 | G34: People
A35: 44592 | B35: -20 | C35: =IF(SIGN(B35)=-1, B35*-1, B35) -> 20 | D35: TRANSFER TO LEWIS SHARON ON 01/31 REF #PP0Q7YX7VJ XXXXXXXXX5267 | E35: mom | F35: =MONTH(A35)&"/"&YEAR(A35) -> 1/2022 | G35: People
A36: 44592 | B36: -29 | C36: =IF(SIGN(B36)=-1, B36*-1, B36) -> 29 | D36: VENMO PAYMENT 220129 1018202156945 SEAN LEWIS | E36: Nick | F36: =MONTH(A36)&"/"&YEAR(A36) -> 1/2022 | G36: Recreation_Entertainment
A37: 44599 | B37: 120 | C37: =IF(SIGN(B37)=-1, B37*-1, B37) -> 120 | D37: ZELLE FROM LEWIS JUSTINA ON 02/05 REF # PP0Q8BDL92 | E37: Don | F37: =MONTH(A37)&"/"&YEAR(A37) -> 2/2022 | G37: People
A38: 44602 | B38: -1733.33 | C38: =IF(SIGN(B38)=-1, B38*-1, B38) -> 1733.33 | D38: DISCOVER E-PAYMENT 220210 4618 LEWIS SEAN | E38: discover | F38: =MONTH(A38)&"/"&YEAR(A38) -> 2/2022 | G38: =IFERROR(VLOOKUP('Wells Fargo'!E122,dis_table[[#All],[Short_Desc]:[CumAmount]],4,0),0) -> 0
A39: 44602 | B39: -70 | C39: =IF(SIGN(B39)=-1, B39*-1, B39) -> 70 | D39: VENMO PAYMENT 220210 1018415472279 SEAN LEWIS | E39: Kim | F39: =MONTH(A39)&"/"&YEAR(A39) -> 2/2022 | G39: Personal_Spending
A40: 44602 | B40: 662.38 | C40: =IF(SIGN(B40)=-1, B40*-1, B40) -> 662.38 | D40: VENMO CASHOUT 220210 1018420729744 SEAN LEWIS | E40: Vincent | F40: =MONTH(A40)&"/"&YEAR(A40) -> 2/2022 | G40: Housing
...

Sheet AMEX
A1: Date | B1: Description | C1: Amount | D1: Category
A2: 02/03/2022 | B2: LIFE TIME CAFE 132Q3KATY AZ | C2: 17.81 | D2: Restaurant-Bar & Café
A3: 02/04/2022 | B3: HACHI RAMEN 0000 TEMPE AZ | C3: 32.41 | D3: Restaurant-Restaurant
A4: 02/04/2022 | B4: THE HOME DEPOT TEMPE AZ | C4: 26.04 | D4: Merchandise & Supplies-Hardware Supplies
A5: 02/05/2022 | B5: UNITED STATES PROFESORLANDO FL | C5: 378.17 | D5: Entertainment-Associations
A6: 02/06/2022 | B6: BOSA DONUTS AHWATUKEPHOENIX AZ | C6: 5 | D6: Restaurant-Restaurant
A7: 02/06/2022 | B7: TARGET PHOENIX SPECTPHOENIX AZ | C7: 152.8 | D7: Merchandise & Supplies-Wholesale Stores
A8: 02/06/2022 | B8: TST* WOW WOW HAWAIIAPHOENIX AZ | C8: 15.7 | D8: Restaurant-Restaurant
A9: 02/06/2022 | B9: UNION 76 09480716 PHOENIX AZ | C9: 37.4 | D9: Transportation-Fuel
A10: 02/08/2022 | B10: TACOS HUICHO #2 0000PHOENIX AZ | C10: 40.87 | D10: Restaurant-Restaurant
A11: 02/09/2022 | B11: WALGREENS PHOENIX AZ | C11: 3.19 | D11: Merchandise & Supplies-Pharmacies
A12: 02/10/2022 | B12: PHOENIX TENNIS CENTEPHOENIX AZ | C12: 4.33 | D12: Other-Miscellaneous
A13: 02/10/2022 | B13: TCKTWEB*CARIBOUWITHSSAN FRANCISCO CA | C13: 67 | D13: Entertainment-General Events
... A68: 07/17/2022 | B68: VHLV- LODGING 021770LAS VEGAS NV | C68: 112.87 | D68: Travel-Lodging

Sheet June Trips
A1: Trans Date | B1: Description | C1: Individual Amount | D1: Shared Amount | E1: Split Amount | F1: Amount | G1: Date | H1: Short_Desc | I1: Category_2
A2: 44725 | B2: Aldi | D2: 11.71 | E2: =D2/2 -> 5.855 | F2: =E2+C2 -> 5.855 | G2: =MONTH(A2)&"/"&YEAR(A2) -> 6/2022 | H2: groceries | I2: =VLOOKUP(Table5[[#This Row],[Short_Desc]],dis_table[[#All],[Short_Desc]:[CumAmount]],4,0) -> Food
A3: 44727 | B3: Uber | D3: 42.54 | E3: =D3/2 -> 21.27 | F3: =E3+C3 -> 21.27 | G3: =MONTH(A3)&"/"&YEAR(A3) -> 6/2022 | H3: ride_share | I3: =VLOOKUP(Table5[[#This Row],[Short_Desc]],dis_table[[#All],[Short_Desc]:[CumAmount]],4,0) -> Transportation
A4: 44729 | B4: Hilton Shulas Resturant | C4: 5.3 | F4: =E4+C4 -> 5.3 | G4: =MONTH(A4)&"/"&YEAR(A4) -> 6/2022 | H4: restaurant | I4: =VLOOKUP(Table5[[#This Row],[Short_Desc]],dis_table[[#All],[Short_Desc]:[CumAmount]],4,0) -> Food
A5: 44731 | B5: Amtrak Northeast Cafe | C5: 18.5 | F5: =E5+C5 -> 18.5 | G5: =MONTH(A5)&"/"&YEAR(A5) -> 6/2022 | H5: fast_food | I5: =VLOOKUP(Table5[[#This Row],[Short_Desc]],dis_table[[#All],[Short_Desc]:[CumAmount]],4,0) -> Food
A6: 44731 | B6: Macdonalds | D6: 23.62 | E6: =D6/2 -> 11.81 | F6: =E6+C6 -> 11.81 | G6: =MONTH(A6)&"/"&YEAR(A6) -> 6/2022 | H6: fast_food | I6: =VLOOKUP(Table5[[#This Row],[Short_Desc]],dis_table[[#All],[Short_Desc]:[CumAmount]],4,0) -> Food
A7: 44731 | B7: Hilton | D7: 497.04 | E7: =D7/2 -> 248.52 | F7: =E7+C7 -> 248.52 | G7: =MONTH(A7)&"/"&YEAR(A7) -> 6/2022 | H7: hotel | I7: Recreation_Entertainment
A8: 44732 | B8: Uber | D8: 56.52 | E8: =D8/2 -> 28.26 | F8: =E8+C8 -> 28.26 | G8: =MONTH(A8)&"/"&YEAR(A8) -> 6/2022 | H8: ride_share | I8: =VLOOKUP(Table5[[#This Row],[Short_Desc]],dis_table[[#All],[Short_Desc]:[CumAmount]],4,0) -> Transportation
A9: 44732 | B9: Uber | D9: 12.97 | E9: =D9/2 -> 6.485 | F9: =E9+C9 -> 6.485 | G9: =MONTH(A9)&"/"&YEAR(A9) -> 6/2022 | H9: ride_share | I9: =VLOOKUP(Table5[[#This Row],[Short_Desc]],dis_table[[#All],[Short_Desc]:[CumAmount]],4,0) -> Transportation
A10: 44732 | B10: Republic | D10: 85 | E10: =D10/2 -> 42.5 | F10: =E10+C10 -> 42.5 | G10: =MONTH(A10)&"/"&YEAR(A10) -> 6/2022 | H10: restaurant | I10: =VLOOKUP(Table5[[#This Row],[Short_Desc]],dis_table[[#All],[Short_Desc]:[CumAmount]],4,0) -> Food
A11: 44732 | B11: Trip Advisor (underground tour) | D11: 58.06 | E11: =D11/2 -> 29.03 | F11: =E11+C11 -> 29.03 | G11: =MONTH(A11)&"/"&YEAR(A11) -> 6/2022 | H11: tour | I11: Recreation_Entertainment
A12: 44734 | B12: Hurry Curry of Tokyo | D12: 33.08 | E12: =D12/2 -> 16.54 | F12: =E12+C12 -> 16.54 | G12: =MONTH(A12)&"/"&YEAR(A12) -> 6/2022 | H12: restaurant | I12: =VLOOKUP(Table5[[#This Row],[Short_Desc]],dis_table[[#All],[Short_Desc]:[CumAmount]],4,0) -> Food
A13: 44735 | B13: La Parisienne French Bakery | D13: 26.22 | E13: =D13/2 -> 13.11 | F13: =E13+C13 -> 13.11 | G13: =MONTH(A13)&"/"&YEAR(A13) -> 6/2022 | H13: restaurant | I13: =VLOOKUP(Table5[[#This Row],[Short_Desc]],dis_table[[#All],[Short_Desc]:[CumAmount]],4,0) -> Food
A14: 44736 | B14: UW food Services | C14: 14.37 | F14: =E14+C14 -> 14.37 | G14: =MONTH(A14)&"/"&YEAR(A14) -> 6/2022 | H14: fast_food | I14: =VLOOKUP(Table5[[#This Row],[Short_Desc]],dis_table[[#All],[Short_Desc]:[CumAmount]],4,0) -> Food
A15: 44736 | B15: What the Pho Xpress | D15: 32.82 | E15: =D15/2 -> 16.41 | F15: =E15+C15 -> 16.41 | G15: =MONTH(A15)&"/"&YEAR(A15) -> 6/2022 | H15: restaurant | I15: =VLOOKUP(Table5[[#This Row],[Short_Desc]],dis_table[[#All],[Short_Desc]:[CumAmount]],4,0) -> Food
A16: 44736 | B16: Macy's (Luggage) | C16: 711.25 | F16: =E16+C16 -> 711.25 | G16: =MONTH(A16)&"/"&YEAR(A16) -> 6/2022 | H16: luggage | I16: Personal_Spending
A17: 44736 | B17: Umi Sake House | D17: 145.54 | E17: =D17/2 -> 72.77 | F17: =E17+C17 -> 72.77 | G17: =MONTH(A17)&"/"&YEAR(A17) -> 6/2022 | H17: restaurant | I17: =VLOOKUP(Table5[[#This Row],[Short_Desc]],dis_table[[#All],[Short_Desc]:[CumAmount]],4,0) -> Food
A18: 44738 | B18: Pho Viet Anh | D18: 44 | E18: =D18/2 -> 22 | F18: =E18+C18 -> 22 | G18: =MONTH(A18)&"/"&YEAR(A18) -> 6/2022 | H18: restaurant | I18: =VLOOKUP(Table5[[#This Row],[Short_Desc]],dis_table[[#All],[Short_Desc]:[CumAmount]],4,0) -> Food
A19: 44738 | B19: Hyatt House Space Needle | D19: 1751.05 | E19: =D19/2 -> 875.525 | F19: =E19+C19 -> 875.525 | G19: =MONTH(A19)&"/"&YEAR(A19) -> 6/2022 | H19: hotel | I19: Recreation_Entertainment
A20: 44739 | B20: Traveluro - Hampton Inn | D20: 116 | E20: =D20/2 -> 58 | F20: =E20+C20 -> 58 | G20: =MONTH(A20)&"/"&YEAR(A20) -> 6/2022 | H20: hotel | I20: Recreation_Entertainment
A21: 44740 | B21: Pitamore | D21: 25.71 | E21: =D21/2 -> 12.855 | F21: =E21+C21 -> 12.855 | G21: =MONTH(A21)&"/"&YEAR(A21) -> 6/2022 | H21: restaurant | I21: =VLOOKUP(Table5[[#This Row],[Short_Desc]],dis_table[[#All],[Short_Desc]:[CumAmount]],4,0) -> Food
A22: 44741 | B22: Ramen Utsuke | D22: 34.7 | E22: =D22/2 -> 17.35 | F22: =E22+C22 -> 17.35 | G22: =MONTH(A22)&"/"&YEAR(A22) -> 6/2022 | H22: restaurant | I22: =VLOOKUP(Table5[[#This Row],[Short_Desc]],dis_table[[#All],[Short_Desc]:[CumAmount]],4,0) -> Food
A23: 44741 | B23: CVS Pharmacy | D23: 19.88 | E23: =D23/2 -> 9.94 | F23: =E23+C23 -> 9.94 | G23: =MONTH(A23)&"/"&YEAR(A23) -> 6/2022 | H23: conv_store | I23: =VLOOKUP(Table5[[#This Row],[Short_Desc]],dis_table[[#All],[Short_Desc]:[CumAmount]],4,0) -> Personal_Spending
A24: 44741 | B24: Uber Eats | D24: 41.7 | E24: =D24/2 -> 20.85 | F24: =E24+C24 -> 20.85 | G24: =MONTH(A24)&"/"&YEAR(A24) -> 6/2022 | H24: fast_food | I24: =VLOOKUP(Table5[[#This Row],[Short_Desc]],dis_table[[#All],[Short_Desc]:[CumAmount]],4,0) -> Food
A25: 44741 | B25: Hotel Tonight - Kimton Hotel Monaco Baltimore | D25: 478 | E25: =D25/2 -> 239 | F25: =E25+C25 -> 239 | G25: =MONTH(A25)&"/"&YEAR(A25) -> 6/2022 | H25: hotel | I25: Recreation_Entertainment
A26: 44742 | B26: CVS Pharmacy | D26: 46.45 | E26: =D26/2 -> 23.225 | F26: =E26+C26 -> 23.225 | G26: =MONTH(A26)&"/"&YEAR(A26) -> 6/2022 | H26: conv_store | I26: =VLOOKUP(Table5[[#This Row],[Short_Desc]],dis_table[[#All],[Short_Desc]:[CumAmount]],4,0) -> Personal_Spending
A27: 44742 | B27: Corner Baker Inner Harbor | D27: 21.28 | E27: =D27/2 -> 10.64 | F27: =E27+C27 -> 10.64 | G27: =MONTH(A27)&"/"&YEAR(A27) -> 6/2022 | H27: restaurant | I27: =VLOOKUP(Table5[[#This Row],[Short_Desc]],dis_table[[#All],[Short_Desc]:[CumAmount]],4,0) -> Food
A28: 44742 | B28: Dalesios Restaurant of Little Italy | D28: 50.88 | E28: =D28/2 -> 25.44 | F28: =E28+C28 -> 25.44 | G28: =MONTH(A28)&"/"&YEAR(A28) -> 6/2022 | H28: restaurant | I28: =VLOOKUP(Table5[[#This Row],[Short_Desc]],dis_table[[#All],[Short_Desc]:[CumAmount]],4,0) -> Food
A29: 44743 | B29: Uber Eats - kumari restaurant | D29: 53.5 | E29: =D29/2 -> 26.75 | F29: =E29+C29 -> 26.75 | G29: =MONTH(A29)&"/"&YEAR(A29) -> 7/2022 | H29: fast_food | I29: =VLOOKUP(Table5[[#This Row],[Short_Desc]],dis_table[[#All],[Short_Desc]:[CumAmount]],4,0) -> Food
A30: 44743 | B30: Chipotle | D30: 20.41 | E30: =D30/2 -> 10.205 | F30: =E30+C30 -> 10.205 | G30: =MONTH(A30)&"/"&YEAR(A30) -> 7/2022 | H30: fast_food | I30: =VLOOKUP(Table5[[#This Row],[Short_Desc]],dis_table[[#All],[Short_Desc]:[CumAmount]],4,0) -> Food
A31: 44744 | B31: Uber Eats | D31: 38.5 | E31: =D31/2 -> 19.25 | F31: =E31+C31 -> 19.25 | G31: =MONTH(A31)&"/"&YEAR(A31) -> 7/2022 | H31: fast_food | I31: =VLOOKUP(Table5[[#This Row],[Short_Desc]],dis_table[[#All],[Short_Desc]:[CumAmount]],4,0) -> Food
A32: 44745 | B32: Uber | D32: 95.86 | E32: =D32/2 -> 47.93 | F32: =E32+C32 -> 47.93 | G32: =MONTH(A32)&"/"&YEAR(A32) -> 7/2022 | H32: ride_share | I32: =VLOOKUP(Table5[[#This Row],[Short_Desc]],dis_table[[#All],[Short_Desc]:[CumAmount]],4,0) -> Transportation
A33: 44745 | B33: Kimpton Hotel (Mini Bar) | C33: 9.54 | F33: =E33+C33 -> 9.54 | G33: =MONTH(A33)&"/"&YEAR(A33) -> 7/2022 | H33: conv_store | I33: =VLOOKUP(Table5[[#This Row],[Short_Desc]],dis_table[[#All],[Short_Desc]:[CumAmount]],4,0) -> Personal_Spending
F34: =SUBTOTAL(109,Table5[Amount]) -> 2690.48

Sheet Accounts
B2: Balance | C2: Limit | D2: Available Credit | E2: Monthly Payment | F2: Due Date
A3: Discover | B3: 6077.24 | C3: 7900 | D3: =C3-B3 -> 1822.76 | E3: 120 | F3: 28 | G3: =B3/E3 -> 50.643667
A4: Care Credit | B4: 0 | C4: 7550 | D4: =C4-B4 -> 7550 | F4: 2
A5: Best Buy | B5: 554.09 | C5: 4997 | D5: =C5-B5 -> 4442.91 | F5: 14
A6: Amex | B6: 505.36 | F6: 2
A7: Student Loan | B7: 22430.56 | E7: 348
A8: Vincent Debt | B8: =Table5[[#Totals],[Amount]] -> 2690.48
A12: Income | B12: 44771 | C12: =B12+14 -> 44785 | D12: =C12+14 -> 44799 | E12: =D12+14 -> 44813 | F12: =E12+14 -> 44827 | G12: =F12+14 -> 44841 | H12: =G12+14 -> 44855 | I12: =H12+14 -> 44869 | J12: =I12+14 -> 44883 | ... M12: =L12+14 -> 44925
A13: Nationwide | B13: 2482.89 | C13: 2482.89 | D13: 2482.89 | E13: 2482.89 | F13: 2482.89 | G13: 2482.89 | H13: 2482.89 | I13: 2482.89 | J13: 2482.89 | K13: 2482.89 | L13: 2482.89 | M13: 2482.89 | N13: =SUM(B13:M13) -> 29794.68
A14: surgery refund | B14: 504.86
A15: deposit | G15: 550
B16: =SUM(B13:B15) -> 2987.75 | C16: =SUM(C13:C15)+B28 -> 2993.4 | D16: =SUM(D13:D15)+C28 -> 2916.84 | E16: =SUM(E13:E15)+D28 -> 2999.73 | F16: =SUM(F13:F15)+E28 -> 2944.524 | G16: =SUM(G13:G15)+F28 -> 3439.318 | H16: =SUM(H13:H15)+G28 -> 3026.112 | I16: =SUM(I13:I15)+H28 -> 2970.906 | J16: =SUM(J13:J15)+I28 -> 2857.7 | ... M16: =SUM(M13:M15)+L28 -> 5048.37
A18: Payments
A19: rent | B19: 1400 | D19: 1400 | G19: 710 | I19: 710 | K19: 710
A20: Discover | B20: 1077.24 | C20: 1500 | D20: 1000 | E20: 2000 | F20: 2000 | G20: 1300 | H20: 2000 | I20: 1000 | J20: 2000 | K20: 1200 | L20: 1000 | M20: 1000
A21: Care Credit | B21: 0 | C21: 0 | D21: 0 | E21: 0 | F21: 0 | G21: 0 | H21: 0 | I21: 0 | J21: 0 | K21: 0 | L21: 0 | M21: 0
A22: Best Buy | C22: 554.09 | D22: 0 | E22: 0 | F22: 0 | G22: 0 | H22: 0 | I22: 0 | J22: 0 | K22: 0 | L22: 0 | M22: 0
A23: Amex | C23: 505.36 | D23: 0 | E23: 0 | F23: 0 | G23: 0 | H23: 0 | I23: 0 | J23: 0 | K23: 0 | L23: 0 | M23: 0
A24: Student Loan | G24: =$E$7 -> 348 | I24: =$E$7 -> 348 | K24: =$E$7 -> 348
A25: Vincent Debt | E25: =B8/5 -> 538.096 | F25: 538.096 | G25: 538.096 | H25: 538.096 | I25: 538.096
B26: =SUM(B19:B25) -> 2477.24 | C26: =SUM(C19:C25) -> 2559.45 | D26: =SUM(D19:D25) -> 2400 | E26: =SUM(E19:E25) -> 2538.096 | F26: =SUM(F19:F25) -> 2538.096 | G26: =SUM(G19:G25) -> 2896.096 | H26: =SUM(H19:H25) -> 2538.096 | I26: =SUM(I19:I25) -> 2596.096 | ... M26: =SUM(M19:M25) -> 1000
B28: =B16-B26 -> 510.51 | C28: =C16-C26 -> 433.95 | D28: =D16-D26 -> 516.84 | E28: =E16-E26 -> 461.634 | F28: =F16-F26 -> 406.428 | G28: =G16-G26 -> 543.222 | H28: =H16-H26 -> 488.016 | I28: =I16-I26 -> 374.81 | ... M28: =M16-M26 -> 4048.37
A30: Discover Balance Watch
A31: Starting Balance | B31: =B3 -> 6077.24 | C31: =B34 -> 6000 | D31: =C34 -> 5500 | E31: =D34 -> 5500 | F31: =E34 -> 4500 | G31: =F34 -> 3500 | H31: =G34 -> 3200 | I31: =H34 -> 2200 | J31: =I34 -> 2200 | ... M31: =L34 -> 1000
A32: After Payment | B32: =B31-B20 -> 5000 | C32: =C31-C20 -> 4500 | D32: =D31-D20 -> 4500 | E32: =E31-E20 -> 3500 | F32: =F31-F20 -> 2500 | G32: =G31-G20 -> 2200 | H32: =H31-H20 -> 1200 | I32: =I31-I20 -> 1200 | ... M32: =M31-M20 -> 0
A33: Est. Spending | B33: 1000 | C33: 1000 | D33: 1000 | E33: 1000 | F33: 1000 | G33: 1000 | H33: 1000 | I33: 1000 | J33: 1000 | K33: 1000 | L33: 1000 | M33: 1000
A34: Ending Balance | B34: =B32+B33 -> 6000 | C34: =C32+C33 -> 5500 | D34: =D32+D33 -> 5500 | E34: =E32+E33 -> 4500 | F34: =F32+F33 -> 3500 | G34: =G32+G33 -> 3200 | H34: =H32+H33 -> 2200 | I34: =I32+I33 -> 2200 | ... M34: =M32+M33 -> 1000

Sheet Category Summary
B2: All Accounts | C2: 01/2022 | D2: 02/2022 | E2: 03/2022 | F2: 04/2022 | G2: 05/2022 | H2: 06/2022 | I2: 07/2022 | J2: 08/2022 | K2: 09/2022 | L2: 10/2022 | M2: 11/2022 | N2: 12/2022 | O2: Total
B3: Food | C3: =SUMIFS(dis_table[Amount],dis_table[Category_2],'Category Summary'!$B3,dis_table[Date],'Category Summary'!C$2) +SUMIFS(cc_table[Amount],cc_table[Category_2],'Category Summary'!$B3,cc_table[Date],'Category Summary'!C$2) + SUMIFS(bb_table[Amount],bb_table[Category_2],'Category Summary'!$B3,bb_table[Date],'Category Summary'!C$2) + SUMIFS(Table5[Amount],Table5[Category_2],'Category Summary'!$B3,Table5[Date],'Category Summary'!C$2)+C18*-1 -> 587.29 | D3: =SUMIFS(dis_table[Amount],dis_table[Category_2],'Category Summary'!$B3,dis_table[Date],'Category Summary'!D$2) +SUMIFS(cc_table[Amount],cc_table[Category_2],'Category Summary'!$B3,cc_table[Date],'Category Summary'!D$2) + SUMIFS(bb_table[Amount],bb_table[Category_2],'Category Summary'!$B3,bb_table[Date],'Category Summary'!D$2) + SUMIFS(Table5[Amount],Table5[Category_2],'Category Summary'!$B3,Table5[Date],'Category Summary'!D$2)+D18*-1 -> 248.29 | E3: =SUMIFS(dis_table[Amount],dis_table[Category_2],'Category Summary'!$B3,dis_table[Date],'Category Summary'!E$2) +SUMIFS(cc_table[Amount],cc_table[Category_2],'Category Summary'!$B3,cc_table[Date],'Category Summary'!E$2) + SUMIFS(bb_table[Amount],bb_table[Category_2],'Category Summary'!$B3,bb_table[Date],'Category Summary'!E$2) + SUMIFS(Table5[Amount],Table5[Category_2],'Category Summary'!$B3,Table5[Date],'Category Summary'!E$2)+E18*-1 -> 1231.25 | F3: =SUMIFS(dis_table[Amount],dis_table[Category_2],'Category Summary'!$B3,dis_table[Date],'Category Summary'!F$2) +SUMIFS(cc_table[Amount],cc_table[Category_2],'Category Summary'!$B3,cc_table[Date],'Category Summary'!F$2) + SUMIFS(bb_table[Amount],bb_table[Category_2],'Category Summary'!$B3,bb_table[Date],'Category Summary'!F$2) + SUMIFS(Table5[Amount],Table5[Category_2],'Category Summary'!$B3,Table5[Date],'Category Summary'!F$2)+F18*-1 -> 945.31 | G3: =SUMIFS(dis_table[Amount],dis_table[Category_2],'Category Summary'!$B3,dis_table[Date],'Category Summary'!G$2) +SUMIFS(cc_table[Amount],cc_table[Category_2],'Category Summary'!$B3,cc_table[Date],'Category Summary'!G$2) + SUMIFS(bb_table[Amount],bb_table[Category_2],'Category Summary'!$B3,bb_table[Date],'Category Summary'!G$2) + SUMIFS(Table5[Amount],Table5[Category_2],'Category Summary'!$B3,Table5[Date],'Category Summary'!G$2)+G18*-1 -> 766.29 | H3: =SUMIFS(dis_table[Amount],dis_table[Category_2],'Category Summary'!$B3,dis_table[Date],'Category Summary'!H$2) +SUMIFS(cc_table[Amount],cc_table[Category_2],'Category Summary'!$B3,cc_table[Date],'Category Summary'!H$2) + SUMIFS(bb_table[Amount],bb_table[Category_2],'Category Summary'!$B3,bb_table[Date],'Category Summary'!H$2) + SUMIFS(Table5[Amount],Table5[Category_2],'Category Summary'!$B3,Table5[Date],'Category Summary'!H$2)+H18*-1 -> 945.77 | I3: =SUMIFS(dis_table[Amount],dis_table[Category_2],'Category Summary'!$B3,dis_table[Date],'Category Summary'!I$2) +SUMIFS(cc_table[Amount],cc_table[Category_2],'Category Summary'!$B3,cc_table[Date],'Category Summary'!I$2) + SUMIFS(bb_table[Amount],bb_table[Category_2],'Category Summary'!$B3,bb_table[Date],'Category Summary'!I$2) + SUMIFS(Table5[Amount],Table5[Category_2],'Category Summary'!$B3,Table5[Date],'Category Summary'!I$2)+I18*-1 -> 1137.425 | J3: =SUMIFS(dis_table[Amount],dis_table[Category_2],'Category Summary'!$B3,dis_table[Date],'Category Summary'!J$2) +SUMIFS(cc_table[Amount],cc_table[Category_2],'Category Summary'!$B3,cc_table[Date],'Category Summary'!J$2) + SUMIFS(bb_table[Amount],bb_table[Category_2],'Category Summary'!$B3,bb_table[Date],'Category Summary'!J$2) + SUMIFS(Table5[Amount],Table5[Category_2],'Category Summary'!$B3,Table5[Date],'Category Summary'!J$2)+J18*-1 -> 795.71 | ... M3: =SUMIFS(dis_table[Amount],dis_table[Category_2],'Category Summary'!$B3,dis_table[Date],'Category Summary'!M$2) +SUMIFS(cc_table[Amount],cc_table[Category_2],'Category Summary'!$B3,cc_table[Date],'Category Summary'!M$2) + SUMIFS(bb_table[Amount],bb_table[Category_2],'Category Summary'!$B3,bb_table[Date],'Category Summary'!M$2) + SUMIFS(Table5[Amount],Table5[Category_2],'Category Summary'!$B3,Table5[Date],'Category Summary'!M$2)+M18*-1 -> 649.85 | N3: =SUMIFS(dis_table[Category_2],dis_table[Amount],'Category Summary'!$B3,dis_table[Post Date],'Category Summary'!N$2) +SUMIFS(cc_table[Post Date],cc_table[Short_Desc],'Category Summary'!$B3,cc_table[Amount],'Category Summary'!N$2) + SUMIFS(bb_table[Category_2],bb_table[Short_Desc],'Category Summary'!$B3,bb_table[Category],'Category Summary'!N$2) + SUMIFS(Table5[Description],Table5[Split Amount],'Category Summary'!$B3,Table5[Individual Amount],'Category Summary'!N$2)+N18*-1 -> 0 | O3: =SUM(C3:N3) -> 8880.035 | P3: =O3/$O$27 -> 0.22643417
B4: Recreation_Entertainment | C4: =SUMIFS(dis_table[Amount],dis_table[Category_2],'Category Summary'!$B4,dis_table[Date],'Category Summary'!C$2) +SUMIFS(cc_table[Amount],cc_table[Category_2],'Category Summary'!$B4,cc_table[Date],'Category Summary'!C$2) + SUMIFS(bb_table[Amount],bb_table[Category_2],'Category Summary'!$B4,bb_table[Date],'Category Summary'!C$2) + SUMIFS(Table5[Amount],Table5[Category_2],'Category Summary'!$B4,Table5[Date],'Category Summary'!C$2)+C19*-1 -> 849.09 | D4: =SUMIFS(dis_table[Amount],dis_table[Category_2],'Category Summary'!$B4,dis_table[Date],'Category Summary'!D$2) +SUMIFS(cc_table[Amount],cc_table[Category_2],'Category Summary'!$B4,cc_table[Date],'Category Summary'!D$2) + SUMIFS(bb_table[Amount],bb_table[Category_2],'Category Summary'!$B4,bb_table[Date],'Category Summary'!D$2) + SUMIFS(Table5[Amount],Table5[Category_2],'Category Summary'!$B4,Table5[Date],'Category Summary'!D$2)+D19*-1 -> 528.66 | E4: =SUMIFS(dis_table[Amount],dis_table[Category_2],'Category Summary'!$B4,dis_table[Date],'Category Summary'!E$2) +SUMIFS(cc_table[Amount],cc_table[Category_2],'Category Summary'!$B4,cc_table[Date],'Category Summary'!E$2) + SUMIFS(bb_table[Amount],bb_table[Category_2],'Category Summary'!$B4,bb_table[Date],'Category Summary'!E$2) + SUMIFS(Table5[Amount],Table5[Category_2],'Category Summary'!$B4,Table5[Date],'Category Summary'!E$2)+E19*-1 -> 887.47 | F4: =SUMIFS(dis_table[Amount],dis_table[Category_2],'Category Summary'!$B4,dis_table[Date],'Category Summary'!F$2) +SUMIFS(cc_table[Amount],cc_table[Category_2],'Category Summary'!$B4,cc_table[Date],'Category Summary'!F$2) + SUMIFS(bb_table[Amount],bb_table[Category_2],'Category Summary'!$B4,bb_table[Date],'Category Summary'!F$2) + SUMIFS(Table5[Amount],Table5[Category_2],'Category Summary'!$B4,Table5[Date],'Category Summary'!F$2)+F19*-1 -> 695.02 | G4: =SUMIFS(dis_table[Amount],dis_table[Category_2],'Category Summary'!$B4,dis_table[Date],'Category Summary'!G$2) +SUMIFS(cc_table[Amount],cc_table[Category_2],'Category Summary'!$B4,cc_table[Date],'Category Summary'!G$2) + SUMIFS(bb_table[Amount],bb_table[Category_2],'Category Summary'!$B4,bb_table[Date],'Category Summary'!G$2) + SUMIFS(Table5[Amount],Table5[Category_2],'Category Summary'!$B4,Table5[Date],'Category Summary'!G$2)+G19*-1 -> 2111.44 | H4: =SUMIFS(dis_table[Amount],dis_table[Category_2],'Category Summary'!$B4,dis_table[Date],'Category Summary'!H$2) +SUMIFS(cc_table[Amount],cc_table[Category_2],'Category Summary'!$B4,cc_table[Date],'Category Summary'!H$2) + SUMIFS(bb_table[Amount],bb_table[Category_2],'Category Summary'!$B4,bb_table[Date],'Category Summary'!H$2) + SUMIFS(Table5[Amount],Table5[Category_2],'Category Summary'!$B4,Table5[Date],'Category Summary'!H$2)+H19*-1 -> 2665.935 | I4: =SUMIFS(dis_table[Amount],dis_table[Category_2],'Category Summary'!$B4,dis_table[Date],'Category Summary'!I$2) +SUMIFS(cc_table[Amount],cc_table[Category_2],'Category Summary'!$B4,cc_table[Date],'Category Summary'!I$2) + SUMIFS(bb_table[Amount],bb_table[Category_2],'Category Summary'!$B4,bb_table[Date],'Category Summary'!I$2) + SUMIFS(Table5[Amount],Table5[Category_2],'Category Summary'!$B4,Table5[Date],'Category Summary'!I$2)+I19*-1 -> 879.96 | J4: =SUMIFS(dis_table[Amount],dis_table[Category_2],'Category Summary'!$B4,dis_table[Date],'Category Summary'!J$2) +SUMIFS(cc_table[Amount],cc_table[Category_2],'Category Summary'!$B4,cc_table[Date],'Category Summary'!J$2) + SUMIFS(bb_table[Amount],bb_table[Category_2],'Category Summary'!$B4,bb_table[Date],'Category Summary'!J$2) + SUMIFS(Table5[Amount],Table5[Category_2],'Category Summary'!$B4,Table5[Date],'Category Summary'!J$2)+J19*-1 -> 91.71 | ... M4: =SUMIFS(dis_table[Amount],dis_table[Category_2],'Category Summary'!$B4,dis_table[Date],'Category Summary'!M$2) +SUMIFS(cc_table[Amount],cc_table[Category_2],'Category Summary'!$B4,cc_table[Date],'Category Summary'!M$2) + SUMIFS(bb_table[Amount],bb_table[Category_2],'Category Summary'!$B4,bb_table[Date],'Category Summary'!M$2) + SUMIFS(Table5[Amount],Table5[Category_2],'Category Summary'!$B4,Table5[Date],'Category Summary'!M$2)+M19*-1 -> 205.88 | N4: =SUMIFS(dis_table[Category_2],dis_table[Amount],'Category Summary'!$B4,dis_table[Post Date],'Category Summary'!N$2) +SUMIFS(cc_table[Post Date],cc_table[Short_Desc],'Category Summary'!$B4,cc_table[Amount],'Category Summary'!N$2) + SUMIFS(bb_table[Category_2],bb_table[Short_Desc],'Category Summary'!$B4,bb_table[Category],'Category Summary'!N$2) + SUMIFS(Table5[Description],Table5[Split Amount],'Category Summary'!$B4,Table5[Individual Amount],'Category Summary'!N$2)+N19*-1 -> 0 | O4: =SUM(C4:N4) -> 10122.405 | P4: =O4/$O$27 -> 0.25811367
