Workbook
Name AprSun1: DATE(CalendarYear,4,1)-WEEKDAY(DATE(CalendarYear,4,1))
Name AugSun1: DATE(CalendarYear,8,1)-WEEKDAY(DATE(CalendarYear,8,1))
Name budget: '[1]Pivot (2021)'!$A$2
Name CalendarYear: [0]!Year1
Name CategoryNames: 'Categories - WIP'!$A$1:$L$1
Name DecSun1: DATE(CalendarYear,12,1)-WEEKDAY(DATE(CalendarYear,12,1))
Name Essential: 'Categories - WIP'!$A$2:$A$12
Name Expense_Lookup: Discover!$T:$U
Name FebSun1: DATE(CalendarYear,2,1)-WEEKDAY(DATE(CalendarYear,2,1))
Name JanSun1: DATE(CalendarYear,1,1)-WEEKDAY(DATE(CalendarYear,1,1))
Name JulSun1: DATE(CalendarYear,7,1)-WEEKDAY(DATE(CalendarYear,7,1))
Name JunSun1: DATE(CalendarYear,6,1)-WEEKDAY(DATE(CalendarYear,6,1))
Name LastCol: COUNTA('PERSONAL BUDGET - WIP'!$4:$4)+1
Name MarSun1: DATE(CalendarYear,3,1)-WEEKDAY(DATE(CalendarYear,3,1))
Name MaySun1: DATE(CalendarYear,5,1)-WEEKDAY(DATE(CalendarYear,5,1))
Name Non_Essential: 'Categories - WIP'!$B$2:$B$12
Name NovSun1: DATE(CalendarYear,11,1)-WEEKDAY(DATE(CalendarYear,11,1))
Name OctSun1: DATE(CalendarYear,10,1)-WEEKDAY(DATE(CalendarYear,10,1))
Name PrintArea_SET: OFFSET('PERSONAL BUDGET - WIP'!$C$2,,,MATCH(REPT("z",255),'PERSONAL BUDGET - WIP'!$C:$C),LastCol)
Name SepSun1: DATE(CalendarYear,9,1)-WEEKDAY(DATE(CalendarYear,9,1))
Name Year1: VALUE(LEFT(#REF!,4))

Sheet Wells Fargo
A1: Month | B1: Day | C1: Date | D1: Description2 | E1: Description | F1: Amount | G1: Primary | H1: Main Category | I1: Secondary Category | J1: Specific Category
A2: =MONTH(C2) -> 1 | B2: =DAY(C2) -> 4 | C2: 44200 | D2: DISCOVER | E2: DISCOVER E-PAYMENT 210101 4732 LEWIS SEAN | F2: -700 | G2: Credit | H2: Essential | I2: SAVINGS, INVESTING, & DEBT | J2: Credit
A3: =MONTH(C3) -> 1 | B3: =DAY(C3) -> 4 | C3: 44200 | D3: IRS | E3: IRS TREAS 310 XXTAXEIP2 010421 XXXXXXXXXX00908 LEWIS, SEAN | F3: 600 | G3: Stimulus 1
A4: =MONTH(C4) -> 1 | B4: =DAY(C4) -> 15 | C4: 44211 | D4: DISCOVER | E4: DISCOVER E-PAYMENT 210115 4732 LEWIS SEAN | F4: -729.23 | G4: Credit | H4: Essential | I4: SAVINGS, INVESTING, & DEBT | J4: Credit
A5: =MONTH(C5) -> 1 | B5: =DAY(C5) -> 15 | C5: 44211 | D5: Elephant | E5: Elephant Ins PAYROLL 210113 2087 Lewis Sean | F5: 1459.65 | G5: Elephant
A6: =MONTH(C6) -> 1 | B6: =DAY(C6) -> 19 | C6: 44215 | D6: VENMO | E6: VENMO PAYMENT 5101219782 SEAN LEWIS | F6: -569.12 | G6: Vincent | H6: Essential | I6: SAVINGS, INVESTING, & DEBT | J6: Personal Debt
A7: =MONTH(C7) -> 1 | B7: =DAY(C7) -> 19 | C7: 44215 | D7: VENMO | E7: VENMO PAYMENT 5101208453 SEAN LEWIS | F7: -78.86 | G7: Amar - Electric | H7: Essential | I7: UTILITIES | J7: Electricity
A8: =MONTH(C8) -> 1 | B8: =DAY(C8) -> 19 | C8: 44215 | D8: VENMO | E8: VENMO CASHOUT 5117912825 SEAN LEWIS | F8: 150 | G8: Venmo Cash Out | H8: Essential | I8: SAVINGS, INVESTING, & DEBT | J8: Personal Debt
A9: =MONTH(C9) -> 1 | B9: =DAY(C9) -> 21 | C9: 44217 | D9: PURCHASE | E9: PURCHASE AUTHORIZED ON 01/20 CASH APP* 8774174551 CA S461020486646597 CARD 6634 | F9: -155 | G9: Cairo | H9: Non-Essential | I9: MISCELLANEUS | J9: Family
A10: =MONTH(C10) -> 1 | B10: =DAY(C10) -> 22 | C10: 44218 | D10: PURCHASE | E10: PURCHASE AUTHORIZED ON 01/21 SOCIETY OF ACTUARI 847-706-3620 IL S581021446560343 CARD 6634 | F10: -75 | G10: SOA | H10: Essential | I10: HOME | J10: Study Material (Pre Nationwide)
A11: =MONTH(C11) -> 1 | B11: =DAY(C11) -> 26 | C11: 44222 | D11: MONEY | E11: MONEY TRANSFER AUTHORIZED ON 01/26 FROM Sean Lewis VA S00581026542833832 CARD 6634 | F11: 155 | G11: Cairo | H11: Non-Essential | I11: MISCELLANEUS | J11: Family
A12: =MONTH(C12) -> 1 | B12: =DAY(C12) -> 28 | C12: 44224 | D12: ROBINHOOD | E12: ROBINHOOD Funds 210127 XXXXX4480 Sean Lewis | F12: -100 | G12: Investment | H12: Essential | I12: SAVINGS, INVESTING, & DEBT | J12: Securities
A13: =MONTH(C13) -> 1 | B13: =DAY(C13) -> 28 | C13: 44224 | D13: ROBINHOOD | E13: ROBINHOOD Funds 210127 XXXXX4480 Sean Lewis | F13: -50 | G13: Investment | H13: Essential | I13: SAVINGS, INVESTING, & DEBT | J13: Securities
A14: =MONTH(C14) -> 1 | B14: =DAY(C14) -> 28 | C14: 44224 | D14: ATM | E14: ATM CHECK DEPOSIT ON 01/28 3201 WEST CARY ST RICHMOND VA 0005841 ATM ID 0255N CARD 6634 | F14: 388.47 | G14: HSA
A15: =MONTH(C15) -> 1 | B15: =DAY(C15) -> 29 | C15: 44225 | D15: VENMO | E15: VENMO PAYMENT 5176119364 SEAN LEWIS | F15: -728.15 | G15: Vincent | H15: Essential | I15: SAVINGS, INVESTING, & DEBT | J15: Personal Debt
A16: =MONTH(C16) -> 1 | B16: =DAY(C16) -> 29 | C16: 44225 | D16: VENMO | E16: VENMO PAYMENT 5176123809 SEAN LEWIS | F16: -700 | G16: Amar - Rent | H16: Essential | I16: HOME | J16: Rent
A17: =MONTH(C17) -> 1 | B17: =DAY(C17) -> 29 | C17: 44225 | D17: Elephant | E17: Elephant Ins PAYROLL 210127 2087 Lewis Sean | F17: 1459.64 | G17: Elephant
A18: =MONTH(C18) -> 2 | B18: =DAY(C18) -> 2 | C18: 44229 | D18: Credit | E18: Credit Karma Transfer 210202 1416312297 Sean Lewis | F18: -1 | G18: Credit Karma | H18: Essential | I18: SAVINGS, INVESTING, & DEBT | J18: Securities
A19: =MONTH(C19) -> 2 | B19: =DAY(C19) -> 2 | C19: 44229 | D19: PURCHASE | E19: PURCHASE AUTHORIZED ON 02/02 CVS/PHARMACY #01 01988--3 RICHMOND VA P00381033853505879 CARD 6634 | F19: -36.84 | G19: Purchase | H19: Non-Essential | I19: PERSONAL SPENDING | J19: Conveinence Store
A20: =MONTH(C20) -> 2 | B20: =DAY(C20) -> 2 | C20: 44229 | D20: RTP | E20: RTP from VENMO on 02/02 Ref#20210202021000021P1BRJPM00020016153 | F20: 495 | G20: Vincent | H20: Essential | I20: SAVINGS, INVESTING, & DEBT | J20: Personal Debt
A21: =MONTH(C21) -> 2 | B21: =DAY(C21) -> 3 | C21: 44230 | D21: BEST | E21: BEST BUY PAYMENT 210202 140344289448116 SEAN LEWIS | F21: -157.47 | G21: Credit | H21: Essential | I21: SAVINGS, INVESTING, & DEBT | J21: Credit
A22: =MONTH(C22) -> 2 | B22: =DAY(C22) -> 3 | C22: 44230 | D22: PURCHASE | E22: PURCHASE AUTHORIZED ON 02/02 CASH APP*DON 8774174551 CA S381033547779628 CARD 6634 | F22: -600 | G22: Don | H22: Non-Essential | I22: MISCELLANEUS | J22: Family
A23: =MONTH(C23) -> 2 | B23: =DAY(C23) -> 4 | C23: 44231 | D23: ROBINHOOD | E23: ROBINHOOD Funds 210203 XXXXX4480 Sean Lewis | F23: -50 | G23: Investment | H23: Essential | I23: SAVINGS, INVESTING, & DEBT | J23: Securities
A24: =MONTH(C24) -> 2 | B24: =DAY(C24) -> 8 | C24: 44235 | D24: ROBINHOOD | E24: ROBINHOOD Funds 210205 XXXXX4480 Sean Lewis | F24: -40 | G24: Investment | H24: Essential | I24: SAVINGS, INVESTING, & DEBT | J24: Securities
A25: =MONTH(C25) -> 2 | B25: =DAY(C25) -> 8 | C25: 44235 | D25: ROBINHOOD | E25: ROBINHOOD Funds 210205 XXXXX4480 Sean Lewis | F25: -10 | G25: Investment | H25: Essential | I25: SAVINGS, INVESTING, & DEBT | J25: Securities
A26: =MONTH(C26) -> 2 | B26: =DAY(C26) -> 9 | C26: 44236 | D26: AVIDIA | E26: AVIDIA BANK SETL 210208 0268 LEWIS,SEAN | F26: 138.48 | G26: HSA
A27: =MONTH(C27) -> 2 | B27: =DAY(C27) -> 12 | C27: 44239 | D27: DISCOVER | E27: DISCOVER E-PAYMENT 210212 4732 LEWIS SEAN | F27: -715.37 | G27: Credit | H27: Essential | I27: SAVINGS, INVESTING, & DEBT | J27: Credit
A28: =MONTH(C28) -> 2 | B28: =DAY(C28) -> 12 | C28: 44239 | D28: VENMO | E28: VENMO PAYMENT 5259216200 SEAN LEWIS | F28: -350 | G28: Vincent | H28: Essential | I28: SAVINGS, INVESTING, & DEBT | J28: Personal Debt
A29: =MONTH(C29) -> 2 | B29: =DAY(C29) -> 12 | C29: 44239 | D29: ROBINHOOD | E29: ROBINHOOD Funds 210211 XXXXX4480 Sean Lewis | F29: -100 | G29: Investment | H29: Essential | I29: SAVINGS, INVESTING, & DEBT | J29: Securities
A30: =MONTH(C30) -> 2 | B30: =DAY(C30) -> 12 | C30: 44239 | D30: Elephant | E30: Elephant Ins PAYROLL 210210 2087 Lewis Sean | F30: 1809.65 | G30: Elephant
A31: =MONTH(C31) -> 2 | B31: =DAY(C31) -> 16 | C31: 44243 | D31: VENMO | E31: VENMO PAYMENT 5280886625 SEAN LEWIS | F31: -500 | G31: Vincent | H31: Essential | I31: SAVINGS, INVESTING, & DEBT | J31: Personal Debt
A32: =MONTH(C32) -> 2 | B32: =DAY(C32) -> 16 | C32: 44243 | D32: TD | E32: TD AMERITRADE ACH IN a9KLOZ6PGB LEWIS SEAN | F32: -100 | G32: Investment | H32: Essential | I32: SAVINGS, INVESTING, & DEBT | J32: Securities
A33: =MONTH(C33) -> 2 | B33: =DAY(C33) -> 16 | C33: 44243 | D33: ROBINHOOD | E33: ROBINHOOD Funds 210212 XXXXX4480 Sean Lewis | F33: -100 | G33: Investment | H33: Essential | I33: SAVINGS, INVESTING, & DEBT | J33: Securities
A34: =MONTH(C34) -> 2 | B34: =DAY(C34) -> 16 | C34: 44243 | D34: MONEY | E34: MONEY TRANSFER AUTHORIZED ON 02/16 FROM Sean Lewis VA S00301047447217307 CARD 6634 | F34: 492.5 | G34: Don | H34: Non-Essential | I34: MISCELLANEUS | J34: Family
A35: =MONTH(C35) -> 2 | B35: =DAY(C35) -> 17 | C35: 44244 | D35: ROBINHOOD | E35: ROBINHOOD Funds 210216 XXXXX4480 Sean Lewis | F35: -300 | G35: Investment | H35: Essential | I35: SAVINGS, INVESTING, & DEBT | J35: Securities
A36: =MONTH(C36) -> 2 | B36: =DAY(C36) -> 17 | C36: 44244 | D36: ROBINHOOD | E36: ROBINHOOD Funds 210216 XXXXX4480 Sean Lewis | F36: -150 | G36: Investment | H36: Essential | I36: SAVINGS, INVESTING, & DEBT | J36: Securities
A37: =MONTH(C37) -> 2 | B37: =DAY(C37) -> 17 | C37: 44244 | D37: ROBINHOOD | E37: ROBINHOOD Funds 210216 XXXXX4480 Sean Lewis | F37: -50 | G37: Investment | H37: Essential | I37: SAVINGS, INVESTING, & DEBT | J37: Securities
A38: =MONTH(C38) -> 2 | B38: =DAY(C38) -> 17 | C38: 44244 | D38: WEBULL | E38: WEBULL FINANCIAL ACH Feb 17 20210213000010 SEAN LEWIS | F38: 56.74 | G38: Investment | H38: Essential | I38: SAVINGS, INVESTING, & DEBT | J38: Securities
A39: =MONTH(C39) -> 2 | B39: =DAY(C39) -> 19 | C39: 44246 | D39: ROBINHOOD | E39: ROBINHOOD Funds 210218 XXXXX4480 Sean Lewis | F39: -100 | G39: Investment | H39: Essential | I39: SAVINGS, INVESTING, & DEBT | J39: Securities
A40: =MONTH(C40) -> 2 | B40: =DAY(C40) -> 19 | C40: 44246 | D40: AVIDIA | E40: AVIDIA BANK SETL 210218 0268 LEWIS,SEAN | F40: 138.47 | G40: HSA
...

Sheet Sheet1
A6: Sum of Amount | B6: Column Labels
A7: Row Labels | B7: Restaurants | C7: Supermarkets | D7: Grand Total
A8: 1 | B8: 117.23 | C8: 138.14 | D8: 255.37
A9: 2 | B9: 51.96 | C9: 247.65 | D9: 299.61
A10: 3 | B10: 259.85 | C10: 132.85 | D10: 392.7
A11: 4 | B11: 487.13 | C11: 25.32 | D11: 512.45
A12: 5 | B12: 259.75 | C12: 321.42 | D12: 581.17
A13: 6 | B13: 472.59 | C13: 100.64 | D13: 573.23
A14: 7 | B14: 689.58 | C14: 328.94 | D14: 1018.52
A15: 8 | B15: 1021.47 | C15: 114.91 | D15: 1136.38
A16: 9 | B16: 1134.5 | C16: 192.66 | D16: 1327.16
A17: 10 | B17: 465.78 | C17: 218.82 | D17: 684.6
A18: 11 | B18: 697.63 | C18: 235.31 | D18: 932.94
A19: 12 | B19: 778.91 | C19: 263.92 | D19: 1042.83
A20: Grand Total | B20: 6436.38 | C20: 2320.58 | D20: 8756.96

Sheet Discover
A1: Year | B1: Month | C1: Trans. date | D1: Post date | E1: Description | F1: Amount | G1: Category | H1: Category_2 | I1: Expense Type | J1: Cumulative | K1: Association | L1: Main Category | M1: Secondary Category | N1: Specific Category | Q1: Essential | R1: =SUMIFS(Table1[Amount],Table1[Main Category], Q1) -> 14607.94
A2: =YEAR(C2) -> 2021 | B2: =MONTH(C2) -> 1 | C2: 44197 | D2: 44197 | E2: INTERNET PAYMENT - THANK YOU | F2: -700 | G2: Payments and Credits | I2: =VLOOKUP(G2,Expense_Lookup,2,0) -> Payment | J2: 728.15 | Q2: Non-Essential | R2: =SUMIFS(Table1[Amount],Table1[Main Category], Q2) -> 19966.37
A3: =YEAR(C3) -> 2021 | B3: =MONTH(C3) -> 1 | C3: 44197 | D3: 44199 | E3: NETFLIX.COM NETFLIX.COM CA44115296471 | F3: 13.99 | G3: APP | I3: =VLOOKUP(G3,Expense_Lookup,2,0) -> Fixed | J3: =J2+F3 -> 742.14 | K3: Netflix | L3: Non-Essential | M3: RECREATION & ENTERTAINMENT | N3: Streaming Services | R3: =SUM(R1:R2) -> 34574.31
A4: =YEAR(C4) -> 2021 | B4: =MONTH(C4) -> 1 | C4: 44197 | D4: 44199 | E4: SPOTIFY P12D96D434 8777781161 NY | F4: 9.99 | G4: APP | I4: =VLOOKUP(G4,Expense_Lookup,2,0) -> Fixed | J4: =J3+F4 -> 752.13 | K4: Spotify | L4: Non-Essential | M4: RECREATION & ENTERTAINMENT | N4: Streaming Services | V4: Jan | W4: Feb | X4: Mar | Y4: Apr | Z4: May | AA4: June | AB4: July | AC4: Aug | AD4: Sep | AE4: Oct | AF4: Nov | AG4: Dec | AH4: Yearly
A5: =YEAR(C5) -> 2021 | B5: =MONTH(C5) -> 1 | C5: 44197 | D5: 44199 | E5: WAWA 697 STAFFORD VA | F5: 18.87 | G5: Gasoline | I5: =VLOOKUP(G5,Expense_Lookup,2,0) -> Variable | J5: =J4+F5 -> 771 | L5: Essential | M5: TRANSPORTATION | N5: Gas | Q5: Variable | R5: =SUMIFS(F:F,I:I,Q5) -> 30647.22 | T5: {=_xlfn.UNIQUE(_xlfn._xlws.FILTER(G:G,(G:G<>0) ))} -> Category
A6: =YEAR(C6) -> 2021 | B6: =MONTH(C6) -> 1 | C6: 44201 | D6: 44201 | E6: MYFICO COM 8003194433 GA | F6: 39.95 | G6: APP | I6: =VLOOKUP(G6,Expense_Lookup,2,0) -> Fixed | J6: =J5+F6 -> 810.95 | K6: Credit Score | L6: Non-Essential | M6: PERSONAL SPENDING | N6: Subscription | Q6: Fixed | R6: =SUMIFS(F:F,I:I,Q6) -> 7246.32 | T6: Payments and Credits | U6: Payment | V6: =SUMIFS(F:F,G:G,T6,$B:$B,1) -> -2157.38 | W6: =SUMIFS(F:F,G:G,T6,$B:$B,2) -> -2256.47 | X6: =SUMIFS(F:F,G:G,T6,$B:$B,3) -> -2413.62 | Y6: =SUMIFS($F:$F,$G:$G,$T6,$B:$B,4) -> -471.07 | Z6: =SUMIFS($F:$F,$G:$G,$T6,$B:$B,5) -> -2855.16 | AA6: =SUMIFS($F:$F,$G:$G,$T6,$B:$B,6) -> -3297.83 | AB6: =SUMIFS($F:$F,$G:$G,$T6,$B:$B,7) -> -6127.09 | AC6: =SUMIFS($F:$F,$G:$G,$T6,$B:$B,8) -> -3272.24 | AD6: =SUMIFS($F:$F,$G:$G,$T6,$B:$B,9) -> -4605.13 | AE6: =SUMIFS($F:$F,$G:$G,$T6,$B:$B,10) -> -1714.73 | AF6: =SUMIFS($F:$F,$G:$G,$T6,$B:$B,11) -> -4175.51 | AG6: =SUMIFS($F:$F,$G:$G,$T6,$B:$B,12) -> -3272.92
A7: =YEAR(C7) -> 2021 | B7: =MONTH(C7) -> 1 | C7: 44201 | D7: 44201 | E7: STATE FARM INSURANCE 800-956-6310 IL | F7: 91.78 | G7: APP | I7: =VLOOKUP(G7,Expense_Lookup,2,0) -> Fixed | J7: =J6+F7 -> 902.73 | K7: State Farm | L7: Essential | M7: INSURANCE | N7: Auto Insurance | R7: =SUM(R5:R6) -> 37893.54 | T7: APP | U7: Fixed | V7: =SUMIFS(F:F,G:G,T7,$B:$B,1) -> 190.63 | W7: =SUMIFS(F:F,G:G,T7,$B:$B,2) -> 250.9 | X7: =SUMIFS(F:F,G:G,T7,$B:$B,3) -> 559.85 | Y7: =SUMIFS(F:F,G:G,T7,$B:$B,4) -> 334.83 | Z7: =SUMIFS($F:$F,$G:$G,$T7,$B:$B,5) -> 592.35 | AA7: =SUMIFS($F:$F,$G:$G,$T7,$B:$B,6) -> 579.09 | AB7: =SUMIFS($F:$F,$G:$G,$T7,$B:$B,7) -> 395.95 | AC7: =SUMIFS($F:$F,$G:$G,$T7,$B:$B,8) -> 655.42 | AD7: =SUMIFS($F:$F,$G:$G,$T7,$B:$B,9) -> 616.67 | AE7: =SUMIFS($F:$F,$G:$G,$T7,$B:$B,10) -> 833.3 | AF7: =SUMIFS($F:$F,$G:$G,$T7,$B:$B,11) -> 673.82 | AG7: =SUMIFS($F:$F,$G:$G,$T7,$B:$B,12) -> 479.27 | AH7: =SUM(V7:AG7) -> 6162.08
A8: =YEAR(C8) -> 2021 | B8: =MONTH(C8) -> 1 | C8: 44201 | D8: 44201 | E8: STEAMPOWERED.COM 425-952-2985 WA | F8: 19.99 | G8: Merchandise | I8: =VLOOKUP(G8,Expense_Lookup,2,0) -> Variable | J8: =J7+F8 -> 922.72 | K8: Neir Automata | L8: Non-Essential | M8: RECREATION & ENTERTAINMENT | N8: Video Games | Q8: Family | T8: Gasoline | U8: Variable | V8: =SUMIFS(F:F,G:G,T8,$B:$B,1) -> 67.87 | W8: =SUMIFS(F:F,G:G,T8,$B:$B,2) -> 67.47 | X8: =SUMIFS(F:F,G:G,T8,$B:$B,3) -> 80.06 | Y8: =SUMIFS(F:F,G:G,T8,$B:$B,4) -> 125.95 | Z8: =SUMIFS($F:$F,$G:$G,$T8,$B:$B,5) -> 115.16 | AA8: =SUMIFS($F:$F,$G:$G,$T8,$B:$B,6) -> 104.56 | AB8: =SUMIFS($F:$F,$G:$G,$T8,$B:$B,7) -> 71.41 | AC8: =SUMIFS($F:$F,$G:$G,$T8,$B:$B,8) -> 199.88 | AD8: =SUMIFS($F:$F,$G:$G,$T8,$B:$B,9) -> 353.18 | AE8: =SUMIFS($F:$F,$G:$G,$T8,$B:$B,10) -> 103 | AF8: =SUMIFS($F:$F,$G:$G,$T8,$B:$B,11) -> 0 | AG8: =SUMIFS($F:$F,$G:$G,$T8,$B:$B,12) -> 80.38 | AH8: =SUM(V8:AG8) -> 1368.92
A9: =YEAR(C9) -> 2021 | B9: =MONTH(C9) -> 1 | C9: 44202 | D9: 44202 | E9: LIVECAREER.COM 800652843 866-933-7587 PR | F9: 24.95 | G9: Family | I9: =VLOOKUP(G9,Expense_Lookup,2,0) -> Variable | J9: =J8+F9 -> 947.67 | K9: Jayelin | L9: Non-Essential | M9: MISCELLANEUS | N9: Family | Q9: Jayelin | R9: =SUMIFS(F:F,K:K,Q9)+SUMIFS('Cash Flow'!$B:$B,'Cash Flow'!$A:$A,Discover!Q9)*-1 -> 914.35 | T9: Merchandise | U9: Variable | V9: =SUMIFS(F:F,G:G,T9,$B:$B,1) -> 434.08 | W9: =SUMIFS(F:F,G:G,T9,$B:$B,2) -> 262.63 | X9: =SUMIFS(F:F,G:G,T9,$B:$B,3) -> 427.64 | Y9: =SUMIFS(F:F,G:G,T9,$B:$B,4) -> 334.36 | Z9: =SUMIFS($F:$F,$G:$G,$T9,$B:$B,5) -> 633.35 | AA9: =SUMIFS($F:$F,$G:$G,$T9,$B:$B,6) -> 1136.89 | AB9: =SUMIFS($F:$F,$G:$G,$T9,$B:$B,7) -> 1104.67 | AC9: =SUMIFS($F:$F,$G:$G,$T9,$B:$B,8) -> 662.17 | AD9: =SUMIFS($F:$F,$G:$G,$T9,$B:$B,9) -> 2140.89 | AE9: =SUMIFS($F:$F,$G:$G,$T9,$B:$B,10) -> 1489.4 | AF9: =SUMIFS($F:$F,$G:$G,$T9,$B:$B,11) -> 575.7 | AG9: =SUMIFS($F:$F,$G:$G,$T9,$B:$B,12) -> 872.75 | AH9: =SUM(V9:AG9) -> 10074.53
A10: =YEAR(C10) -> 2021 | B10: =MONTH(C10) -> 1 | C10: 44202 | D10: 44202 | E10: RIVER RUN SHORT PUMP HENRICO VA | F10: 30 | G10: Medical Services | I10: =VLOOKUP(G10,Expense_Lookup,2,0) -> Variable | J10: =J9+F10 -> 977.67 | K10: Dentist | L10: Essential | M10: MEDICAL & HEALTHCARE | N10: Dental Care | Q10: Shevon | R10: =SUMIFS(F:F,K:K,Q10)+SUMIFS('Cash Flow'!$B:$B,'Cash Flow'!$A:$A,Discover!Q10)*-1 -> 1774.95 | T10: Family | U10: Variable | V10: =SUMIFS(F:F,G:G,T10,$B:$B,1) -> 172.84 | W10: =SUMIFS(F:F,G:G,T10,$B:$B,2) -> 71.26 | X10: =SUMIFS(F:F,G:G,T10,$B:$B,3) -> 84.95 | Y10: =SUMIFS(F:F,G:G,T10,$B:$B,4) -> 9.95 | Z10: =SUMIFS($F:$F,$G:$G,$T10,$B:$B,5) -> 91.85 | AA10: =SUMIFS($F:$F,$G:$G,$T10,$B:$B,6) -> 0 | AB10: =SUMIFS($F:$F,$G:$G,$T10,$B:$B,7) -> 0 | AC10: =SUMIFS($F:$F,$G:$G,$T10,$B:$B,8) -> 0 | AD10: =SUMIFS($F:$F,$G:$G,$T10,$B:$B,9) -> 0 | AE10: =SUMIFS($F:$F,$G:$G,$T10,$B:$B,10) -> 0 | AF10: =SUMIFS($F:$F,$G:$G,$T10,$B:$B,11) -> 0 | AG10: =SUMIFS($F:$F,$G:$G,$T10,$B:$B,12) -> 0 | AH10: =SUM(V10:AG10) -> 430.85
A11: =YEAR(C11) -> 2021 | B11: =MONTH(C11) -> 1 | C11: 44202 | D11: 44202 | E11: THE MARKET @ 25TH RICHMOND VA | F11: 24.24 | G11: Supermarkets | I11: =VLOOKUP(G11,Expense_Lookup,2,0) -> Variable | J11: =J10+F11 -> 1001.91 | L11: Essential | M11: FOOD | N11: Groceries | Q11: Don | R11: =SUMIFS(F:F,K:K,Q11)+SUMIFS('Cash Flow'!$B:$B,'Cash Flow'!$A:$A,Discover!Q11)*-1 -> 127.5 | T11: Medical Services | U11: Variable | V11: =SUMIFS(F:F,G:G,T11,$B:$B,1) -> 70.51 | W11: =SUMIFS(F:F,G:G,T11,$B:$B,2) -> 0 | X11: =SUMIFS(F:F,G:G,T11,$B:$B,3) -> 0 | Y11: =SUMIFS(F:F,G:G,T11,$B:$B,4) -> 0 | Z11: =SUMIFS($F:$F,$G:$G,$T11,$B:$B,5) -> 0 | AA11: =SUMIFS($F:$F,$G:$G,$T11,$B:$B,6) -> 0 | AB11: =SUMIFS($F:$F,$G:$G,$T11,$B:$B,7) -> 0 | AC11: =SUMIFS($F:$F,$G:$G,$T11,$B:$B,8) -> 0 | AD11: =SUMIFS($F:$F,$G:$G,$T11,$B:$B,9) -> 0 | AE11: =SUMIFS($F:$F,$G:$G,$T11,$B:$B,10) -> 0 | AF11: =SUMIFS($F:$F,$G:$G,$T11,$B:$B,11) -> 0 | AG11: =SUMIFS($F:$F,$G:$G,$T11,$B:$B,12) -> 0 | AH11: =SUM(V11:AG11) -> 70.51
A12: =YEAR(C12) -> 2021 | B12: =MONTH(C12) -> 1 | C12: 44203 | D12: 44203 | E12: AMERICA'S BEST WINGS HENRICO VA | F12: 12.09 | G12: Restaurants | H12: fast_food | I12: =VLOOKUP(G12,Expense_Lookup,2,0) -> Variable | J12: =J11+F12 -> 1014 | L12: Non-Essential | M12: RECREATION & ENTERTAINMENT | N12: Resteraunts | Q12: Dorry | R12: =SUMIFS(F:F,K:K,Q12)+SUMIFS('Cash Flow'!$B:$B,'Cash Flow'!$A:$A,Discover!Q12)*-1 -> 455 | T12: Supermarkets | U12: Variable | V12: =SUMIFS(F:F,G:G,T12,$B:$B,1) -> 138.14 | W12: =SUMIFS(F:F,G:G,T12,$B:$B,2) -> 247.65 | X12: =SUMIFS(F:F,G:G,T12,$B:$B,3) -> 132.85 | Y12: =SUMIFS(F:F,G:G,T12,$B:$B,4) -> 25.32 | Z12: =SUMIFS($F:$F,$G:$G,$T12,$B:$B,5) -> 321.42 | AA12: =SUMIFS($F:$F,$G:$G,$T12,$B:$B,6) -> 100.64 | AB12: =SUMIFS($F:$F,$G:$G,$T12,$B:$B,7) -> 328.94 | AC12: =SUMIFS($F:$F,$G:$G,$T12,$B:$B,8) -> 114.91 | AD12: =SUMIFS($F:$F,$G:$G,$T12,$B:$B,9) -> 192.66 | AE12: =SUMIFS($F:$F,$G:$G,$T12,$B:$B,10) -> 218.82 | AF12: =SUMIFS($F:$F,$G:$G,$T12,$B:$B,11) -> 235.31 | AG12: =SUMIFS($F:$F,$G:$G,$T12,$B:$B,12) -> 263.92 | AH12: =SUM(V12:AG12) -> 2320.58
A13: =YEAR(C13) -> 2021 | B13: =MONTH(C13) -> 1 | C13: 44203 | D13: 44203 | E13: GO DRAGON ASIAN GRILL RICHMOND VA | F13: 44 | G13: Restaurants | I13: =VLOOKUP(G13,Expense_Lookup,2,0) -> Variable | J13: =J12+F13 -> 1058 | L13: Non-Essential | M13: RECREATION & ENTERTAINMENT | N13: Resteraunts | Q13: Cairo | R13: =SUMIFS(F:F,K:K,Q13)+SUMIFS('Cash Flow'!$B:$B,'Cash Flow'!$A:$A,Discover!Q13)*-1 -> 0 | T13: Restaurants | U13: Variable | V13: =SUMIFS(F:F,G:G,T13,$B:$B,1) -> 117.23 | W13: =SUMIFS(F:F,G:G,T13,$B:$B,2) -> 51.96 | X13: =SUMIFS(F:F,G:G,T13,$B:$B,3) -> 259.85 | Y13: =SUMIFS(F:F,G:G,T13,$B:$B,4) -> 487.13 | Z13: =SUMIFS($F:$F,$G:$G,$T13,$B:$B,5) -> 259.75 | AA13: =SUMIFS($F:$F,$G:$G,$T13,$B:$B,6) -> 472.59 | AB13: =SUMIFS($F:$F,$G:$G,$T13,$B:$B,7) -> 689.58 | AC13: =SUMIFS($F:$F,$G:$G,$T13,$B:$B,8) -> 1021.47 | AD13: =SUMIFS($F:$F,$G:$G,$T13,$B:$B,9) -> 1134.5 | AE13: =SUMIFS($F:$F,$G:$G,$T13,$B:$B,10) -> 465.78 | AF13: =SUMIFS($F:$F,$G:$G,$T13,$B:$B,11) -> 697.63 | AG13: =SUMIFS($F:$F,$G:$G,$T13,$B:$B,12) -> 778.91 | AH13: =SUM(V13:AG13) -> 6436.38
A14: =YEAR(C14) -> 2021 | B14: =MONTH(C14) -> 1 | C14: 44203 | D14: 44203 | E14: THE MARKET @ 25TH RICHMOND VA | F14: 14.52 | G14: Supermarkets | I14: =VLOOKUP(G14,Expense_Lookup,2,0) -> Variable | J14: =J13+F14 -> 1072.52 | L14: Essential | M14: FOOD | N14: Groceries | R14: =SUM(R9:R13) -> 3271.8 | T14: Services | U14: Variable | V14: =SUMIFS(F:F,G:G,T14,$B:$B,1) -> 29.27 | W14: =SUMIFS(F:F,G:G,T14,$B:$B,2) -> 0 | X14: =SUMIFS(F:F,G:G,T14,$B:$B,3) -> 470 | Y14: =SUMIFS(F:F,G:G,T14,$B:$B,4) -> 98 | Z14: =SUMIFS($F:$F,$G:$G,$T14,$B:$B,5) -> 1.5 | AA14: =SUMIFS($F:$F,$G:$G,$T14,$B:$B,6) -> 213.84 | AB14: =SUMIFS($F:$F,$G:$G,$T14,$B:$B,7) -> 1904.58 | AC14: =SUMIFS($F:$F,$G:$G,$T14,$B:$B,8) -> 283.03 | AD14: =SUMIFS($F:$F,$G:$G,$T14,$B:$B,9) -> 375.1 | AE14: =SUMIFS($F:$F,$G:$G,$T14,$B:$B,10) -> 352.52 | AF14: =SUMIFS($F:$F,$G:$G,$T14,$B:$B,11) -> 0 | AG14: =SUMIFS($F:$F,$G:$G,$T14,$B:$B,12) -> 237.18 | AH14: =SUM(V14:AG14) -> 3965.02
A15: =YEAR(C15) -> 2021 | B15: =MONTH(C15) -> 1 | C15: 44204 | D15: 44204 | E15: CVS/PHARMACY #01988 RICHMOND VA | F15: 3.37 | G15: Family | I15: =VLOOKUP(G15,Expense_Lookup,2,0) -> Variable | J15: =J14+F15 -> 1075.89 | K15: Jayelin | L15: Non-Essential | M15: MISCELLANEUS | N15: Family | T15: Education | U15: Variable | V15: =SUMIFS(F:F,G:G,T15,$B:$B,1) -> 49 | W15: =SUMIFS(F:F,G:G,T15,$B:$B,2) -> 215 | X15: =SUMIFS(F:F,G:G,T15,$B:$B,3) -> 0 | Y15: =SUMIFS(F:F,G:G,T15,$B:$B,4) -> 0 | Z15: =SUMIFS($F:$F,$G:$G,$T15,$B:$B,5) -> 0 | AA15: =SUMIFS($F:$F,$G:$G,$T15,$B:$B,6) -> 199 | AB15: =SUMIFS($F:$F,$G:$G,$T15,$B:$B,7) -> 0 | AC15: =SUMIFS($F:$F,$G:$G,$T15,$B:$B,8) -> 4.8 | AD15: =SUMIFS($F:$F,$G:$G,$T15,$B:$B,9) -> 0 | AE15: =SUMIFS($F:$F,$G:$G,$T15,$B:$B,10) -> 0 | AF15: =SUMIFS($F:$F,$G:$G,$T15,$B:$B,11) -> 0 | AG15: =SUMIFS($F:$F,$G:$G,$T15,$B:$B,12) -> 0 | AH15: =SUM(V15:AG15) -> 467.8
A16: =YEAR(C16) -> 2021 | B16: =MONTH(C16) -> 1 | C16: 44204 | D16: 44204 | E16: LABCORP PSCC 2 800-845-6167 NC202101072171244 | F16: 40.51 | G16: Medical Services | I16: =VLOOKUP(G16,Expense_Lookup,2,0) -> Variable | J16: =J15+F16 -> 1116.4 | K16: Doctor | L16: Essential | M16: MEDICAL & HEALTHCARE | N16: Out-of-Pocket Costs | Q16: Trips | T16: Awards and Rebate Credits | U16: Payment | V16: =SUMIFS(F:F,G:G,T16,$B:$B,1) -> -22.18 | W16: =SUMIFS(F:F,G:G,T16,$B:$B,2) -> -14 | X16: =SUMIFS(F:F,G:G,T16,$B:$B,3) -> -14.05 | Y16: =SUMIFS(F:F,G:G,T16,$B:$B,4) -> 0 | Z16: =SUMIFS($F:$F,$G:$G,$T16,$B:$B,5) -> 0 | AA16: =SUMIFS($F:$F,$G:$G,$T16,$B:$B,6) -> 0 | AB16: =SUMIFS($F:$F,$G:$G,$T16,$B:$B,7) -> 0 | AC16: =SUMIFS($F:$F,$G:$G,$T16,$B:$B,8) -> -38.86 | AD16: =SUMIFS($F:$F,$G:$G,$T16,$B:$B,9) -> 0 | AE16: =SUMIFS($F:$F,$G:$G,$T16,$B:$B,10) -> 0 | AF16: =SUMIFS($F:$F,$G:$G,$T16,$B:$B,11) -> -43.38 | AG16: =SUMIFS($F:$F,$G:$G,$T16,$B:$B,12) -> -44.4 | AH16: =SUM(V16:AG16) -> -176.87
A17: =YEAR(C17) -> 2021 | B17: =MONTH(C17) -> 1 | C17: 44205 | D17: 44205 | E17: BINGO BEER CO - GAMES PE RICHMOND VA | F17: 30 | G17: Restaurants | I17: =VLOOKUP(G17,Expense_Lookup,2,0) -> Variable | J17: =J16+F17 -> 1146.4 | K17: Akhil | L17: Non-Essential | M17: RECREATION & ENTERTAINMENT | N17: Resteraunts | Q17: New York | R17: =SUMIFS(F:F,K:K,Q17)+SUMIFS('Cash Flow'!$B:$B,'Cash Flow'!$A:$A,Discover!Q17)*-1 -> 373.46 | T17: Government Services | U17: Variable | V17: =SUMIFS(F:F,G:G,T17,$B:$B,1) -> 0 | W17: =SUMIFS(F:F,G:G,T17,$B:$B,2) -> 40.15 | X17: =SUMIFS(F:F,G:G,T17,$B:$B,3) -> 0 | Y17: =SUMIFS(F:F,G:G,T17,$B:$B,4) -> 0 | Z17: =SUMIFS($F:$F,$G:$G,$T17,$B:$B,5) -> 26.35 | AA17: =SUMIFS($F:$F,$G:$G,$T17,$B:$B,6) -> 195.05 | AB17: =SUMIFS($F:$F,$G:$G,$T17,$B:$B,7) -> 194 | AC17: =SUMIFS($F:$F,$G:$G,$T17,$B:$B,8) -> 21.51 | AD17: =SUMIFS($F:$F,$G:$G,$T17,$B:$B,9) -> 140.91 | AE17: =SUMIFS($F:$F,$G:$G,$T17,$B:$B,10) -> 0 | AF17: =SUMIFS($F:$F,$G:$G,$T17,$B:$B,11) -> 138.14 | AG17: =SUMIFS($F:$F,$G:$G,$T17,$B:$B,12) -> 20.06 | AH17: =SUM(V17:AG17) -> 776.17
A18: =YEAR(C18) -> 2021 | B18: =MONTH(C18) -> 1 | C18: 44205 | D18: 44205 | E18: WALMART SC 07032 HENRICO VA | F18: 37.5 | G18: Merchandise | I18: =VLOOKUP(G18,Expense_Lookup,2,0) -> Variable | J18: =J17+F18 -> 1183.9 | L18: Non-Essential | M18: PERSONAL SPENDING | N18: Walmart/Target Run | Q18: Brooklyn | R18: =SUMIFS(F:F,K:K,Q18)+SUMIFS('Cash Flow'!$B:$B,'Cash Flow'!$A:$A,Discover!Q18)*-1 -> 1983.8 | T18: Automotive | U18: Fixed | V18: =SUMIFS(F:F,G:G,T18,$B:$B,1) -> 0 | W18: =SUMIFS(F:F,G:G,T18,$B:$B,2) -> 0 | X18: =SUMIFS(F:F,G:G,T18,$B:$B,3) -> 86.17 | Y18: =SUMIFS(F:F,G:G,T18,$B:$B,4) -> 5.65 | Z18: =SUMIFS($F:$F,$G:$G,$T18,$B:$B,5) -> 401.19 | AA18: =SUMIFS($F:$F,$G:$G,$T18,$B:$B,6) -> 0 | AB18: =SUMIFS($F:$F,$G:$G,$T18,$B:$B,7) -> 394.26 | AC18: =SUMIFS($F:$F,$G:$G,$T18,$B:$B,8) -> 0 | AD18: =SUMIFS($F:$F,$G:$G,$T18,$B:$B,9) -> 110.71 | AE18: =SUMIFS($F:$F,$G:$G,$T18,$B:$B,10) -> 0 | AF18: =SUMIFS($F:$F,$G:$G,$T18,$B:$B,11) -> 0 | AG18: =SUMIFS($F:$F,$G:$G,$T18,$B:$B,12) -> 93.25 | AH18: =SUM(V18:AG18) -> 1091.23
A19: =YEAR(C19) -> 2021 | B19: =MONTH(C19) -> 1 | C19: 44206 | D19: 44206 | E19: APPLE.COM/BILL 866-712-7753 CAAPPLE PAY ENDING IN 4775MMW3T9K9KMA0 | F19: 14.99 | G19: APP | I19: =VLOOKUP(G19,Expense_Lookup,2,0) -> Fixed | J19: =J18+F19 -> 1198.89 | K19: HBO | L19: Non-Essential | M19: RECREATION & ENTERTAINMENT | N19: Streaming Services | R19: =SUM(R17:R18) -> 2357.26 | T19: Travel/ Entertainment | U19: Variable | V19: =SUMIFS(F:F,G:G,T19,$B:$B,1) -> 0 | W19: =SUMIFS(F:F,G:G,T19,$B:$B,2) -> 0 | X19: =SUMIFS(F:F,G:G,T19,$B:$B,3) -> 101.04 | Y19: =SUMIFS(F:F,G:G,T19,$B:$B,4) -> 4.24 | Z19: =SUMIFS($F:$F,$G:$G,$T19,$B:$B,5) -> 360.05 | AA19: =SUMIFS($F:$F,$G:$G,$T19,$B:$B,6) -> 179.77 | AB19: =SUMIFS($F:$F,$G:$G,$T19,$B:$B,7) -> 864.12 | AC19: =SUMIFS($F:$F,$G:$G,$T19,$B:$B,8) -> 241.29 | AD19: =SUMIFS($F:$F,$G:$G,$T19,$B:$B,9) -> 360.22 | AE19: =SUMIFS($F:$F,$G:$G,$T19,$B:$B,10) -> 61.14 | AF19: =SUMIFS($F:$F,$G:$G,$T19,$B:$B,11) -> 234.66 | AG19: =SUMIFS($F:$F,$G:$G,$T19,$B:$B,12) -> 543.58 | AH19: =SUM(V19:AG19) -> 2950.11
A20: =YEAR(C20) -> 2021 | B20: =MONTH(C20) -> 1 | C20: 44206 | D20: 44206 | E20: FEDEX 782422707980 800-4633339 TN | F20: 14.47 | G20: Services | I20: =VLOOKUP(G20,Expense_Lookup,2,0) -> Variable | J20: =J19+F20 -> 1213.36 | K20: Darron | L20: Non-Essential | M20: MISCELLANEUS | N20: Family | Q20: Moving | T20: Home Improvement | U20: Variable | V20: =SUMIFS(F:F,G:G,T20,$B:$B,1) -> 0 | W20: =SUMIFS(F:F,G:G,T20,$B:$B,2) -> 0 | X20: =SUMIFS(F:F,G:G,T20,$B:$B,3) -> 0 | Y20: =SUMIFS(F:F,G:G,T20,$B:$B,4) -> 92.58 | Z20: =SUMIFS($F:$F,$G:$G,$T20,$B:$B,5) -> 54.37 | AA20: =SUMIFS($F:$F,$G:$G,$T20,$B:$B,6) -> 23.13 | AB20: =SUMIFS($F:$F,$G:$G,$T20,$B:$B,7) -> 0 | AC20: =SUMIFS($F:$F,$G:$G,$T20,$B:$B,8) -> 89.51 | AD20: =SUMIFS($F:$F,$G:$G,$T20,$B:$B,9) -> 0 | AE20: =SUMIFS($F:$F,$G:$G,$T20,$B:$B,10) -> 167.01 | AF20: =SUMIFS($F:$F,$G:$G,$T20,$B:$B,11) -> 0 | AG20: =SUMIFS($F:$F,$G:$G,$T20,$B:$B,12) -> 0 | AH20: =SUM(V20:AG20) -> 426.6
A21: =YEAR(C21) -> 2021 | B21: =MONTH(C21) -> 1 | C21: 44206 | D21: 44206 | E21: FEDEX 782422725203 800-4633339 TN | F21: 11.45 | G21: Services | I21: =VLOOKUP(G21,Expense_Lookup,2,0) -> Variable | J21: =J20+F21 -> 1224.81 | K21: Darron | L21: Non-Essential | M21: MISCELLANEUS | N21: Family | Q21: Storage | R21: =SUMIFS(F:F,K:K,Q21)+SUMIFS('Cash Flow'!$B:$B,'Cash Flow'!$A:$A,Discover!Q21)*-1 -> 361.27 | T21: Car Wash | U21: Variable | V21: =SUMIFS(F:F,G:G,T21,$B:$B,1) -> 0 | W21: =SUMIFS(F:F,G:G,T21,$B:$B,2) -> 0 | X21: =SUMIFS(F:F,G:G,T21,$B:$B,3) -> 0 | Y21: =SUMIFS(F:F,G:G,T21,$B:$B,4) -> 0 | Z21: =SUMIFS($F:$F,$G:$G,$T21,$B:$B,5) -> 0 | AA21: =SUMIFS($F:$F,$G:$G,$T21,$B:$B,6) -> 0 | AB21: =SUMIFS($F:$F,$G:$G,$T21,$B:$B,7) -> 0 | AC21: =SUMIFS($F:$F,$G:$G,$T21,$B:$B,8) -> 63.08 | AD21: =SUMIFS($F:$F,$G:$G,$T21,$B:$B,9) -> 0 | AE21: =SUMIFS($F:$F,$G:$G,$T21,$B:$B,10) -> 0 | AF21: =SUMIFS($F:$F,$G:$G,$T21,$B:$B,11) -> 0 | AG21: =SUMIFS($F:$F,$G:$G,$T21,$B:$B,12) -> 0 | AH21: =SUM(V21:AG21) -> 63.08
A22: =YEAR(C22) -> 2021 | B22: =MONTH(C22) -> 1 | C22: 44206 | D22: 44206 | E22: WALMART SC 07032 HENRICO VA | F22: 74.16 | G22: Merchandise | I22: =VLOOKUP(G22,Expense_Lookup,2,0) -> Variable | J22: =J21+F22 -> 1298.97 | L22: Non-Essential | M22: PERSONAL SPENDING | N22: Walmart/Target Run | Q22: Arizona | R22: =SUMIFS(F:F,K:K,Q22)+SUMIFS('Cash Flow'!$B:$B,'Cash Flow'!$A:$A,Discover!Q22)*-1 -> 1380.63 | T22: Department Stores | U22: Variable | V22: =SUMIFS(F:F,G:G,T22,$B:$B,1) -> 0 | W22: =SUMIFS(F:F,G:G,T22,$B:$B,2) -> 0 | X22: =SUMIFS(F:F,G:G,T22,$B:$B,3) -> 0 | Y22: =SUMIFS(F:F,G:G,T22,$B:$B,4) -> 0 | Z22: =SUMIFS($F:$F,$G:$G,$T22,$B:$B,5) -> 0 | AA22: =SUMIFS($F:$F,$G:$G,$T22,$B:$B,6) -> 0 | AB22: =SUMIFS($F:$F,$G:$G,$T22,$B:$B,7) -> 0 | AC22: =SUMIFS($F:$F,$G:$G,$T22,$B:$B,8) -> 0 | AD22: =SUMIFS($F:$F,$G:$G,$T22,$B:$B,9) -> 0 | AE22: =SUMIFS($F:$F,$G:$G,$T22,$B:$B,10) -> 0 | AF22: =SUMIFS($F:$F,$G:$G,$T22,$B:$B,11) -> 1455.66 | AG22: =SUMIFS($F:$F,$G:$G,$T22,$B:$B,12) -> 0
A23: =YEAR(C23) -> 2021 | B23: =MONTH(C23) -> 1 | C23: 44207 | D23: 44207 | E23: CASH APP*SHEVON LEW 415-375-3176 CA | F23: 103 | G23: Family | I23: =VLOOKUP(G23,Expense_Lookup,2,0) -> Variable | J23: =J22+F23 -> 1401.97 | K23: Shevon | L23: Non-Essential | M23: MISCELLANEUS | N23: Family | Q23: road trip | R23: =SUMIFS(F:F,K:K,Q23)+SUMIFS('Cash Flow'!$B:$B,'Cash Flow'!$A:$A,Discover!Q23)*-1 -> 1213.29 | V23: =SUM(V6:V22) -> -909.99 | W23: =SUM(W6:W22) -> -1063.45 | X23: =SUM(X6:X22) -> -225.26 | Y23: =SUM(Y6:Y22) -> 1046.94 | Z23: =SUM(Z6:Z22) -> 2.18 | AA23: =SUM(AA6:AA22) -> -93.27 | AB23: =SUM(AB6:AB22) -> -179.58 | AC23: =SUM(AC6:AC22) -> 45.97 | ... AG23: =SUM(AG6:AG22) -> 51.98
A24: =YEAR(C24) -> 2021 | B24: =MONTH(C24) -> 1 | C24: 44207 | D24: 44207 | E24: PAYPAL *ETCHEDACTUA 402-935-7733 CA | F24: 49 | G24: Education | I24: =VLOOKUP(G24,Expense_Lookup,2,0) -> Variable | J24: =J23+F24 -> 1450.97 | L24: Essential | M24: HOME | N24: Study Material (Pre Nationwide) | R24: =SUM(R21:R22) -> 1741.9 | U24: Monthly Spending -> | V24: =SUM(V7:V15,V17:V22) -> 1269.57 | W24: =SUM(W7:W15,W17:W22) -> 1207.02 | X24: =SUM(X7:X15,X17:X22) -> 2202.41 | Y24: =SUM(Y7:Y15,Y17:Y22) -> 1518.01 | Z24: =SUM(Z7:Z15,Z17:Z22) -> 2857.34 | AA24: =SUM(AA7:AA15,AA17:AA22) -> 3204.56 | AB24: =SUM(AB7:AB15,AB17:AB22) -> 5947.51 | AC24: =SUM(AC7:AC15,AC17:AC22) -> 3357.07 | ... AG24: =SUM(AG7:AG15,AG17:AG22) -> 3369.3
A25: =YEAR(C25) -> 2021 | B25: =MONTH(C25) -> 1 | C25: 44208 | D25: 44208 | E25: EXXONMOBIL RICHMOND VA | F25: 23.27 | G25: Gasoline | I25: =VLOOKUP(G25,Expense_Lookup,2,0) -> Variable | J25: =J24+F25 -> 1474.24 | L25: Essential | M25: TRANSPORTATION | N25: Gas
A26: =YEAR(C26) -> 2021 | B26: =MONTH(C26) -> 1 | C26: 44208 | D26: 44208 | E26: FAMILY DOLLAR #5701 RICHMOND VA | F26: 3.33 | G26: Family | I26: =VLOOKUP(G26,Expense_Lookup,2,0) -> Variable | J26: =J25+F26 -> 1477.57 | K26: Jayelin | L26: Non-Essential | M26: MISCELLANEUS | N26: Family
A27: =YEAR(C27) -> 2021 | B27: =MONTH(C27) -> 1 | C27: 44208 | D27: 44208 | E27: PAYPAL *VIZMEDIALLC 888-221-1161 CA | F27: 1.99 | G27: APP | I27: =VLOOKUP(G27,Expense_Lookup,2,0) -> Fixed | J27: =J26+F27 -> 1479.56 | K27: Manga | L27: Non-Essential | M27: RECREATION & ENTERTAINMENT | N27: Streaming Services
A28: =YEAR(C28) -> 2021 | B28: =MONTH(C28) -> 1 | C28: 44211 | D28: 44211 | E28: CASHBACK BONUS REDEMPTION PYMT/STMT CRDT | F28: -22.18 | G28: Awards and Rebate Credits | I28: =VLOOKUP(G28,Expense_Lookup,2,0) -> Payment | J28: =J27+F28 -> 1457.38
A29: =YEAR(C29) -> 2021 | B29: =MONTH(C29) -> 1 | C29: 44211 | D29: 44211 | E29: DIRECTPAY FULL BALANCESEE DETAILS OF YOUR NEXT DIRECTPAY BELOW | F29: -728.15 | G29: Payments and Credits | I29: =VLOOKUP(G29,Expense_Lookup,2,0) -> Payment | J29: =J28+F29 -> 729.23
A30: =YEAR(C30) -> 2021 | B30: =MONTH(C30) -> 1 | C30: 44211 | D30: 44211 | E30: INTERNET PAYMENT - THANK YOU | F30: -729.23 | G30: Payments and Credits | I30: =VLOOKUP(G30,Expense_Lookup,2,0) -> Payment | J30: =J29+F30 -> 0
A31: =YEAR(C31) -> 2021 | B31: =MONTH(C31) -> 1 | C31: 44211 | D31: 44211 | E31: MCDONALD'S F17579 RICHMOND VA | F31: 4.32 | G31: Family | I31: =VLOOKUP(G31,Expense_Lookup,2,0) -> Variable | J31: =J30+F31 -> 4.32 | K31: Jayelin | L31: Non-Essential | M31: MISCELLANEUS | N31: Family
A32: =YEAR(C32) -> 2021 | B32: =MONTH(C32) -> 1 | C32: 44211 | D32: 44211 | E32: WALGREENS #3860 RICHMOND VA | F32: 21.19 | G32: Merchandise | I32: =VLOOKUP(G32,Expense_Lookup,2,0) -> Variable | J32: =J31+F32 -> 25.51 | K32: Draino | L32: Non-Essential | M32: PERSONAL SPENDING | N32: Conveinence Store
A33: =YEAR(C33) -> 2021 | B33: =MONTH(C33) -> 1 | C33: 44211 | D33: 44211 | E33: WALMART SC 07032 HENRICO VA | F33: 19.4 | G33: Merchandise | I33: =VLOOKUP(G33,Expense_Lookup,2,0) -> Variable | J33: =J32+F33 -> 44.91 | K33: Study | L33: Essential | M33: HOME | N33: Office Supplies
A34: =YEAR(C34) -> 2021 | B34: =MONTH(C34) -> 1 | C34: 44212 | D34: 44212 | E34: AMZN MKTP US*0H4DK7EL3 AMZN.COM/BILLWA72J9EGRQCDU | F34: 58.29 | G34: Merchandise | I34: =VLOOKUP(G34,Expense_Lookup,2,0) -> Variable | J34: =J33+F34 -> 103.2 | K34: Webcam | L34: Essential | M34: HOME | N34: Office Supplies
A35: =YEAR(C35) -> 2021 | B35: =MONTH(C35) -> 1 | C35: 44215 | D35: 44215 | E35: CHIPOTLE 1975 RICHMOND VA | F35: 8.23 | G35: Restaurants | H35: fast_food | I35: =VLOOKUP(G35,Expense_Lookup,2,0) -> Variable | J35: =J34+F35 -> 111.43 | L35: Non-Essential | M35: RECREATION & ENTERTAINMENT | N35: Resteraunts
A36: =YEAR(C36) -> 2021 | B36: =MONTH(C36) -> 1 | C36: 44215 | D36: 44215 | E36: CVS/PHARMACY #01988 RICHMOND VA | F36: 2.86 | G36: Family | I36: =VLOOKUP(G36,Expense_Lookup,2,0) -> Variable | J36: =J35+F36 -> 114.29 | K36: Jayelin | L36: Non-Essential | M36: MISCELLANEUS | N36: Family
A37: =YEAR(C37) -> 2021 | B37: =MONTH(C37) -> 1 | C37: 44215 | D37: 44215 | E37: SP * ILF, LLC 8888044453 TX | F37: 99.9 | G37: Merchandise | I37: =VLOOKUP(G37,Expense_Lookup,2,0) -> Variable | J37: =J36+F37 -> 214.19 | L37: Non-Essential | M37: PERSONAL SPENDING | N37: --
A38: =YEAR(C38) -> 2021 | B38: =MONTH(C38) -> 1 | C38: 44216 | D38: 44216 | E38: THE MARKET @ 25TH RICHMOND VA | F38: 15.15 | G38: Supermarkets | I38: =VLOOKUP(G38,Expense_Lookup,2,0) -> Variable | J38: =J37+F38 -> 229.34 | L38: Essential | M38: FOOD | N38: Groceries
A39: =YEAR(C39) -> 2021 | B39: =MONTH(C39) -> 1 | C39: 44217 | D39: 44217 | E39: KINGSISLE *PIRATE101 512-623-5983 TX00099RS900000000000000 | F39: 9.95 | G39: Family | I39: =VLOOKUP(G39,Expense_Lookup,2,0) -> Variable | J39: =J38+F39 -> 239.29 | K39: Jayelin | L39: Non-Essential | M39: MISCELLANEUS | N39: Family
A40: =YEAR(C40) -> 2021 | B40: =MONTH(C40) -> 1 | C40: 44217 | D40: 44217 | E40: PP*PP ROKU FOR CRUNCHYR 402-935-7733 CA | F40: 7.99 | G40: APP | I40: =VLOOKUP(G40,Expense_Lookup,2,0) -> Fixed | J40: =J39+F40 -> 247.28 | K40: Crunchyroll | L40: Non-Essential | M40: RECREATION & ENTERTAINMENT | N40: Streaming Services
...

Sheet Subscriptions
A1: Name | B1: Sub Type | C1: Cancelled? | D1: Day | E1: Total Paid | F1: # | G1: Avg. Paid | H1: Jan | I1: Feb | J1: Mar | K1: Apr | L1: May | M1: June | N1: July | O1: Aug | P1: Sep | Q1: Oct | R1: Nov | S1: Dec
A2: {=_xlfn._xlws.SORT(_xlfn.UNIQUE(_xlfn.UNIQUE(_xlfn._xlws.FILTER(Discover!K:K, (Discover!G:G = "APP")*(Discover!K:K <>0)),1)))} -> Apple Music | B2: Monthly | C2: Yes | D2: {=AVERAGE(DAY(_xlfn.UNIQUE(_xlfn._xlws.FILTER(Discover!C:C, Discover!K:K = A2,0),1)))} -> 29 | E2: =SUMIFS(Discover!F:F,Discover!K:K,Subscriptions!A2) -> 21.18 | F2: =COUNTIFS(Discover!K:K,Subscriptions!A2,Discover!G:G,"APP") -> 2 | G2: =E2/F2 -> 10.59 | H2: =SUMIFS(Discover!$F:$F,Discover!$K:$K,Subscriptions!$A2,Discover!$B:$B,1) -> 0 | I2: =SUMIFS(Discover!$F:$F,Discover!$K:$K,Subscriptions!$A2,Discover!$B:$B,2) -> 0 | J2: =SUMIFS(Discover!$F:$F,Discover!$K:$K,Subscriptions!$A2,Discover!$B:$B,3) -> 0 | K2: =SUMIFS(Discover!$F:$F,Discover!$K:$K,Subscriptions!$A2,Discover!$B:$B,4) -> 0 | L2: =SUMIFS(Discover!$F:$F,Discover!$K:$K,Subscriptions!$A2,Discover!$B:$B,5) -> 0 | M2: =SUMIFS(Discover!$F:$F,Discover!$K:$K,Subscriptions!$A2,Discover!$B:$B,6) -> 0 | N2: =SUMIFS(Discover!$F:$F,Discover!$K:$K,Subscriptions!$A2,Discover!$B:$B,7) -> 0 | O2: =SUMIFS(Discover!$F:$F,Discover!$K:$K,Subscriptions!$A2,Discover!$B:$B,8) -> 10.59 | P2: =SUMIFS(Discover!$F:$F,Discover!$K:$K,Subscriptions!$A2,Discover!$B:$B,9) -> 10.59 | Q2: =SUMIFS(Discover!$F:$F,Discover!$K:$K,Subscriptions!$A2,Discover!$B:$B,10) -> 0 | R2: =SUMIFS(Discover!$F:$F,Discover!$K:$K,Subscriptions!$A2,Discover!$B:$B,11) -> 0 | S2: =SUMIFS(Discover!$F:$F,Discover!$K:$K,Subscriptions!$A2,Discover!$B:$B,12) -> 0
A3: Apple TV+ | B3: One time | C3: No | D3: {=AVERAGE(DAY(_xlfn.UNIQUE(_xlfn._xlws.FILTER(Discover!C:C, Discover!K:K = A3,0),1)))} -> 17.75 | E3: =SUMIFS(Discover!F:F,Discover!K:K,Subscriptions!A3) -> 21.16 | F3: =COUNTIFS(Discover!K:K,Subscriptions!A3,Discover!G:G,"APP") -> 4 | G3: =E3/F3 -> 5.29 | H3: =SUMIFS(Discover!$F:$F,Discover!$K:$K,Subscriptions!$A3,Discover!$B:$B,1) -> 0 | I3: =SUMIFS(Discover!$F:$F,Discover!$K:$K,Subscriptions!$A3,Discover!$B:$B,2) -> 0 | J3: =SUMIFS(Discover!$F:$F,Discover!$K:$K,Subscriptions!$A3,Discover!$B:$B,3) -> 0 | K3: =SUMIFS(Discover!$F:$F,Discover!$K:$K,Subscriptions!$A3,Discover!$B:$B,4) -> 0 | L3: =SUMIFS(Discover!$F:$F,Discover!$K:$K,Subscriptions!$A3,Discover!$B:$B,5) -> 0 | M3: =SUMIFS(Discover!$F:$F,Discover!$K:$K,Subscriptions!$A3,Discover!$B:$B,6) -> 0 | N3: =SUMIFS(Discover!$F:$F,Discover!$K:$K,Subscriptions!$A3,Discover!$B:$B,7) -> 0 | O3: =SUMIFS(Discover!$F:$F,Discover!$K:$K,Subscriptions!$A3,Discover!$B:$B,8) -> 0 | P3: =SUMIFS(Discover!$F:$F,Discover!$K:$K,Subscriptions!$A3,Discover!$B:$B,9) -> 5.29 | Q3: =SUMIFS(Discover!$F:$F,Discover!$K:$K,Subscriptions!$A3,Discover!$B:$B,10) -> 5.29 | R3: =SUMIFS(Discover!$F:$F,Discover!$K:$K,Subscriptions!$A3,Discover!$B:$B,11) -> 5.29 | S3: =SUMIFS(Discover!$F:$F,Discover!$K:$K,Subscriptions!$A3,Discover!$B:$B,12) -> 5.29
A4: Audible | B4: Monthly | C4: No | D4: {=AVERAGE(DAY(_xlfn.UNIQUE(_xlfn._xlws.FILTER(Discover!C:C, Discover!K:K = A4,0),1)))} -> 18.5 | E4: =SUMIFS(Discover!F:F,Discover!K:K,Subscriptions!A4) -> 65.2 | F4: =COUNTIFS(Discover!K:K,Subscriptions!A4,Discover!G:G,"APP") -> 4 | G4: =E4/F4 -> 16.3 | H4: =SUMIFS(Discover!$F:$F,Discover!$K:$K,Subscriptions!$A4,Discover!$B:$B,1) -> 0 | I4: =SUMIFS(Discover!$F:$F,Discover!$K:$K,Subscriptions!$A4,Discover!$B:$B,2) -> 0 | J4: =SUMIFS(Discover!$F:$F,Discover!$K:$K,Subscriptions!$A4,Discover!$B:$B,3) -> 0 | K4: =SUMIFS(Discover!$F:$F,Discover!$K:$K,Subscriptions!$A4,Discover!$B:$B,4) -> 0 | L4: =SUMIFS(Discover!$F:$F,Discover!$K:$K,Subscriptions!$A4,Discover!$B:$B,5) -> 0 | M4: =SUMIFS(Discover!$F:$F,Discover!$K:$K,Subscriptions!$A4,Discover!$B:$B,6) -> 0 | N4: =SUMIFS(Discover!$F:$F,Discover!$K:$K,Subscriptions!$A4,Discover!$B:$B,7) -> 0 | O4: =SUMIFS(Discover!$F:$F,Discover!$K:$K,Subscriptions!$A4,Discover!$B:$B,8) -> 56.52 | P4: =SUMIFS(Discover!$F:$F,Discover!$K:$K,Subscriptions!$A4,Discover!$B:$B,9) -> 8.68 | Q4: =SUMIFS(Discover!$F:$F,Discover!$K:$K,Subscriptions!$A4,Discover!$B:$B,10) -> 0 | R4: =SUMIFS(Discover!$F:$F,Discover!$K:$K,Subscriptions!$A4,Discover!$B:$B,11) -> 0 | S4: =SUMIFS(Discover!$F:$F,Discover!$K:$K,Subscriptions!$A4,Discover!$B:$B,12) -> 0
A5: Bloomberg | B5: Monthly | C5: Yes | D5: {=AVERAGE(DAY(_xlfn.UNIQUE(_xlfn._xlws.FILTER(Discover!C:C, Discover!K:K = A5,0),1)))} -> 31 | E5: =SUMIFS(Discover!F:F,Discover!K:K,Subscriptions!A5) -> 37.09 | F5: =COUNTIFS(Discover!K:K,Subscriptions!A5,Discover!G:G,"APP") -> 1 | G5: =E5/F5 -> 37.09 | H5: =SUMIFS(Discover!$F:$F,Discover!$K:$K,Subscriptions!$A5,Discover!$B:$B,1) -> 0 | I5: =SUMIFS(Discover!$F:$F,Discover!$K:$K,Subscriptions!$A5,Discover!$B:$B,2) -> 0 | J5: =SUMIFS(Discover!$F:$F,Discover!$K:$K,Subscriptions!$A5,Discover!$B:$B,3) -> 0 | K5: =SUMIFS(Discover!$F:$F,Discover!$K:$K,Subscriptions!$A5,Discover!$B:$B,4) -> 0 | L5: =SUMIFS(Discover!$F:$F,Discover!$K:$K,Subscriptions!$A5,Discover!$B:$B,5) -> 37.09 | M5: =SUMIFS(Discover!$F:$F,Discover!$K:$K,Subscriptions!$A5,Discover!$B:$B,6) -> 0 | N5: =SUMIFS(Discover!$F:$F,Discover!$K:$K,Subscriptions!$A5,Discover!$B:$B,7) -> 0 | O5: =SUMIFS(Discover!$F:$F,Discover!$K:$K,Subscriptions!$A5,Discover!$B:$B,8) -> 0 | P5: =SUMIFS(Discover!$F:$F,Discover!$K:$K,Subscriptions!$A5,Discover!$B:$B,9) -> 0 | Q5: =SUMIFS(Discover!$F:$F,Discover!$K:$K,Subscriptions!$A5,Discover!$B:$B,10) -> 0 | R5: =SUMIFS(Discover!$F:$F,Discover!$K:$K,Subscriptions!$A5,Discover!$B:$B,11) -> 0 | S5: =SUMIFS(Discover!$F:$F,Discover!$K:$K,Subscriptions!$A5,Discover!$B:$B,12) -> 0
A6: Bumble | B6: Monthly | C6: Yes | D6: {=AVERAGE(DAY(_xlfn.UNIQUE(_xlfn._xlws.FILTER(Discover!C:C, Discover!K:K = A6,0),1)))} -> 10 | E6: =SUMIFS(Discover!F:F,Discover!K:K,Subscriptions!A6) -> 126.98 | F6: =COUNTIFS(Discover!K:K,Subscriptions!A6,Discover!G:G,"APP") -> 4 | G6: =E6/F6 -> 31.745 | H6: =SUMIFS(Discover!$F:$F,Discover!$K:$K,Subscriptions!$A6,Discover!$B:$B,1) -> 0 | I6: =SUMIFS(Discover!$F:$F,Discover!$K:$K,Subscriptions!$A6,Discover!$B:$B,2) -> 0 | J6: =SUMIFS(Discover!$F:$F,Discover!$K:$K,Subscriptions!$A6,Discover!$B:$B,3) -> 0 | K6: =SUMIFS(Discover!$F:$F,Discover!$K:$K,Subscriptions!$A6,Discover!$B:$B,4) -> 0 | L6: =SUMIFS(Discover!$F:$F,Discover!$K:$K,Subscriptions!$A6,Discover!$B:$B,5) -> 0 | M6: =SUMIFS(Discover!$F:$F,Discover!$K:$K,Subscriptions!$A6,Discover!$B:$B,6) -> 0 | N6: =SUMIFS(Discover!$F:$F,Discover!$K:$K,Subscriptions!$A6,Discover!$B:$B,7) -> 0 | O6: =SUMIFS(Discover!$F:$F,Discover!$K:$K,Subscriptions!$A6,Discover!$B:$B,8) -> 84.59 | P6: =SUMIFS(Discover!$F:$F,Discover!$K:$K,Subscriptions!$A6,Discover!$B:$B,9) -> 0 | Q6: =SUMIFS(Discover!$F:$F,Discover!$K:$K,Subscriptions!$A6,Discover!$B:$B,10) -> 42.39 | R6: =SUMIFS(Discover!$F:$F,Discover!$K:$K,Subscriptions!$A6,Discover!$B:$B,11) -> 0 | S6: =SUMIFS(Discover!$F:$F,Discover!$K:$K,Subscriptions!$A6,Discover!$B:$B,12) -> 0
A7: Catan Gold | B7: Monthly | C7: No | D7: {=AVERAGE(DAY(_xlfn.UNIQUE(_xlfn._xlws.FILTER(Discover!C:C, Discover!K:K = A7,0),1)))} -> 26 | E7: =SUMIFS(Discover!F:F,Discover!K:K,Subscriptions!A7) -> 14.99 | F7: =COUNTIFS(Discover!K:K,Subscriptions!A7,Discover!G:G,"APP") -> 1 | G7: =E7/F7 -> 14.99 | H7: =SUMIFS(Discover!$F:$F,Discover!$K:$K,Subscriptions!$A7,Discover!$B:$B,1) -> 0 | I7: =SUMIFS(Discover!$F:$F,Discover!$K:$K,Subscriptions!$A7,Discover!$B:$B,2) -> 0 | J7: =SUMIFS(Discover!$F:$F,Discover!$K:$K,Subscriptions!$A7,Discover!$B:$B,3) -> 14.99 | K7: =SUMIFS(Discover!$F:$F,Discover!$K:$K,Subscriptions!$A7,Discover!$B:$B,4) -> 0 | L7: =SUMIFS(Discover!$F:$F,Discover!$K:$K,Subscriptions!$A7,Discover!$B:$B,5) -> 0 | M7: =SUMIFS(Discover!$F:$F,Discover!$K:$K,Subscriptions!$A7,Discover!$B:$B,6) -> 0 | N7: =SUMIFS(Discover!$F:$F,Discover!$K:$K,Subscriptions!$A7,Discover!$B:$B,7) -> 0 | O7: =SUMIFS(Discover!$F:$F,Discover!$K:$K,Subscriptions!$A7,Discover!$B:$B,8) -> 0 | P7: =SUMIFS(Discover!$F:$F,Discover!$K:$K,Subscriptions!$A7,Discover!$B:$B,9) -> 0 | Q7: =SUMIFS(Discover!$F:$F,Discover!$K:$K,Subscriptions!$A7,Discover!$B:$B,10) -> 0 | R7: =SUMIFS(Discover!$F:$F,Discover!$K:$K,Subscriptions!$A7,Discover!$B:$B,11) -> 0 | S7: =SUMIFS(Discover!$F:$F,Discover!$K:$K,Subscriptions!$A7,Discover!$B:$B,12) -> 0
A8: Couple Cents | B8: Annual | C8: No | D8: {=AVERAGE(DAY(_xlfn.UNIQUE(_xlfn._xlws.FILTER(Discover!C:C, Discover!K:K = A8,0),1)))} -> 27 | E8: =SUMIFS(Discover!F:F,Discover!K:K,Subscriptions!A8) -> 79.92 | F8: =COUNTIFS(Discover!K:K,Subscriptions!A8,Discover!G:G,"APP") -> 7 | G8: =E8/F8 -> 11.417143 | H8: =SUMIFS(Discover!$F:$F,Discover!$K:$K,Subscriptions!$A8,Discover!$B:$B,1) -> 0 | I8: =SUMIFS(Discover!$F:$F,Discover!$K:$K,Subscriptions!$A8,Discover!$B:$B,2) -> 9.99 | J8: =SUMIFS(Discover!$F:$F,Discover!$K:$K,Subscriptions!$A8,Discover!$B:$B,3) -> 9.99 | K8: =SUMIFS(Discover!$F:$F,Discover!$K:$K,Subscriptions!$A8,Discover!$B:$B,4) -> 9.99 | L8: =SUMIFS(Discover!$F:$F,Discover!$K:$K,Subscriptions!$A8,Discover!$B:$B,5) -> 9.99 | M8: =SUMIFS(Discover!$F:$F,Discover!$K:$K,Subscriptions!$A8,Discover!$B:$B,6) -> 9.99 | N8: =SUMIFS(Discover!$F:$F,Discover!$K:$K,Subscriptions!$A8,Discover!$B:$B,7) -> 9.99 | O8: =SUMIFS(Discover!$F:$F,Discover!$K:$K,Subscriptions!$A8,Discover!$B:$B,8) -> 9.99 | P8: =SUMIFS(Discover!$F:$F,Discover!$K:$K,Subscriptions!$A8,Discover!$B:$B,9) -> 9.99 | Q8: =SUMIFS(Discover!$F:$F,Discover!$K:$K,Subscriptions!$A8,Discover!$B:$B,10) -> 0 | R8: =SUMIFS(Discover!$F:$F,Discover!$K:$K,Subscriptions!$A8,Discover!$B:$B,11) -> 0 | S8: =SUMIFS(Discover!$F:$F,Discover!$K:$K,Subscriptions!$A8,Discover!$B:$B,12) -> 0
A9: Credit Score | B9: Monthly | C9: Yes | D9: {=AVERAGE(DAY(_xlfn.UNIQUE(_xlfn._xlws.FILTER(Discover!C:C, Discover!K:K = A9,0),1)))} -> 5 | E9: =SUMIFS(Discover!F:F,Discover!K:K,Subscriptions!A9) -> 39.95 | F9: =COUNTIFS(Discover!K:K,Subscriptions!A9,Discover!G:G,"APP") -> 1 | G9: =E9/F9 -> 39.95 | H9: =SUMIFS(Discover!$F:$F,Discover!$K:$K,Subscriptions!$A9,Discover!$B:$B,1) -> 39.95 | I9: =SUMIFS(Discover!$F:$F,Discover!$K:$K,Subscriptions!$A9,Discover!$B:$B,2) -> 0 | J9: =SUMIFS(Discover!$F:$F,Discover!$K:$K,Subscriptions!$A9,Discover!$B:$B,3) -> 0 | K9: =SUMIFS(Discover!$F:$F,Discover!$K:$K,Subscriptions!$A9,Discover!$B:$B,4) -> 0 | L9: =SUMIFS(Discover!$F:$F,Discover!$K:$K,Subscriptions!$A9,Discover!$B:$B,5) -> 0 | M9: =SUMIFS(Discover!$F:$F,Discover!$K:$K,Subscriptions!$A9,Discover!$B:$B,6) -> 0 | N9: =SUMIFS(Discover!$F:$F,Discover!$K:$K,Subscriptions!$A9,Discover!$B:$B,7) -> 0 | O9: =SUMIFS(Discover!$F:$F,Discover!$K:$K,Subscriptions!$A9,Discover!$B:$B,8) -> 0 | P9: =SUMIFS(Discover!$F:$F,Discover!$K:$K,Subscriptions!$A9,Discover!$B:$B,9) -> 0 | Q9: =SUMIFS(Discover!$F:$F,Discover!$K:$K,Subscriptions!$A9,Discover!$B:$B,10) -> 0 | R9: =SUMIFS(Discover!$F:$F,Discover!$K:$K,Subscriptions!$A9,Discover!$B:$B,11) -> 0 | S9: =SUMIFS(Discover!$F:$F,Discover!$K:$K,Subscriptions!$A9,Discover!$B:$B,12) -> 0
A10: Crunch Fitness | B10: 6-Months | C10: No | D10: {=AVERAGE(DAY(_xlfn.UNIQUE(_xlfn._xlws.FILTER(Discover!C:C, Discover!K:K = A10,0),1)))} -> 28 | E10: =SUMIFS(Discover!F:F,Discover!K:K,Subscriptions!A10) -> 29.85 | F10: =COUNTIFS(Discover!K:K,Subscriptions!A10,Discover!G:G,"APP") -> 3 | G10: =E10/F10 -> 9.95 | H10: =SUMIFS(Discover!$F:$F,Discover!$K:$K,Subscriptions!$A10,Discover!$B:$B,1) -> 9.95 | I10: =SUMIFS(Discover!$F:$F,Discover!$K:$K,Subscriptions!$A10,Discover!$B:$B,2) -> 9.95 | J10: =SUMIFS(Discover!$F:$F,Discover!$K:$K,Subscriptions!$A10,Discover!$B:$B,3) -> 9.95 | K10: =SUMIFS(Discover!$F:$F,Discover!$K:$K,Subscriptions!$A10,Discover!$B:$B,4) -> 0 | L10: =SUMIFS(Discover!$F:$F,Discover!$K:$K,Subscriptions!$A10,Discover!$B:$B,5) -> 0 | M10: =SUMIFS(Discover!$F:$F,Discover!$K:$K,Subscriptions!$A10,Discover!$B:$B,6) -> 0 | N10: =SUMIFS(Discover!$F:$F,Discover!$K:$K,Subscriptions!$A10,Discover!$B:$B,7) -> 0 | O10: =SUMIFS(Discover!$F:$F,Discover!$K:$K,Subscriptions!$A10,Discover!$B:$B,8) -> 0 | P10: =SUMIFS(Discover!$F:$F,Discover!$K:$K,Subscriptions!$A10,Discover!$B:$B,9) -> 0 | Q10: =SUMIFS(Discover!$F:$F,Discover!$K:$K,Subscriptions!$A10,Discover!$B:$B,10) -> 0 | R10: =SUMIFS(Discover!$F:$F,Discover!$K:$K,Subscriptions!$A10,Discover!$B:$B,11) -> 0 | S10: =SUMIFS(Discover!$F:$F,Discover!$K:$K,Subscriptions!$A10,Discover!$B:$B,12) -> 0
A11: Crunchyroll | B11: 1 Year | C11: Yes | D11: {=AVERAGE(DAY(_xlfn.UNIQUE(_xlfn._xlws.FILTER(Discover!C:C, Discover!K:K = A11,0),1)))} -> 21.090909 | E11: =SUMIFS(Discover!F:F,Discover!K:K,Subscriptions!A11) -> 87.89 | F11: =COUNTIFS(Discover!K:K,Subscriptions!A11,Discover!G:G,"APP") -> 11 | G11: =E11/F11 -> 7.99 | H11: =SUMIFS(Discover!$F:$F,Discover!$K:$K,Subscriptions!$A11,Discover!$B:$B,1) -> 7.99 | I11: =SUMIFS(Discover!$F:$F,Discover!$K:$K,Subscriptions!$A11,Discover!$B:$B,2) -> 7.99 | J11: =SUMIFS(Discover!$F:$F,Discover!$K:$K,Subscriptions!$A11,Discover!$B:$B,3) -> 7.99 | K11: =SUMIFS(Discover!$F:$F,Discover!$K:$K,Subscriptions!$A11,Discover!$B:$B,4) -> 7.99 | L11: =SUMIFS(Discover!$F:$F,Discover!$K:$K,Subscriptions!$A11,Discover!$B:$B,5) -> 7.99 | M11: =SUMIFS(Discover!$F:$F,Discover!$K:$K,Subscriptions!$A11,Discover!$B:$B,6) -> 7.99 | N11: =SUMIFS(Discover!$F:$F,Discover!$K:$K,Subscriptions!$A11,Discover!$B:$B,7) -> 7.99 | O11: =SUMIFS(Discover!$F:$F,Discover!$K:$K,Subscriptions!$A11,Discover!$B:$B,8) -> 7.99 | P11: =SUMIFS(Discover!$F:$F,Discover!$K:$K,Subscriptions!$A11,Discover!$B:$B,9) -> 7.99 | Q11: =SUMIFS(Discover!$F:$F,Discover!$K:$K,Subscriptions!$A11,Discover!$B:$B,10) -> 7.99 | R11: =SUMIFS(Discover!$F:$F,Discover!$K:$K,Subscriptions!$A11,Discover!$B:$B,11) -> 7.99 | S11: =SUMIFS(Discover!$F:$F,Discover!$K:$K,Subscriptions!$A11,Discover!$B:$B,12) -> 0 | T11: *Cancelled
A12: Disney | B12: 1 Month | C12: Yes | D12: {=AVERAGE(DAY(_xlfn.UNIQUE(_xlfn._xlws.FILTER(Discover!C:C, Discover!K:K = A12,0),1)))} -> 1 | E12: =SUMIFS(Discover!F:F,Discover!K:K,Subscriptions!A12) -> 69.99 | F12: =COUNTIFS(Discover!K:K,Subscriptions!A12,Discover!G:G,"APP") -> 1 | G12: =E12/F12 -> 69.99 | H12: =SUMIFS(Discover!$F:$F,Discover!$K:$K,Subscriptions!$A12,Discover!$B:$B,1) -> 0 | I12: =SUMIFS(Discover!$F:$F,Discover!$K:$K,Subscriptions!$A12,Discover!$B:$B,2) -> 0 | J12: =SUMIFS(Discover!$F:$F,Discover!$K:$K,Subscriptions!$A12,Discover!$B:$B,3) -> 69.99 | K12: =SUMIFS(Discover!$F:$F,Discover!$K:$K,Subscriptions!$A12,Discover!$B:$B,4) -> 0 | L12: =SUMIFS(Discover!$F:$F,Discover!$K:$K,Subscriptions!$A12,Discover!$B:$B,5) -> 0 | M12: =SUMIFS(Discover!$F:$F,Discover!$K:$K,Subscriptions!$A12,Discover!$B:$B,6) -> 0 | N12: =SUMIFS(Discover!$F:$F,Discover!$K:$K,Subscriptions!$A12,Discover!$B:$B,7) -> 0 | O12: =SUMIFS(Discover!$F:$F,Discover!$K:$K,Subscriptions!$A12,Discover!$B:$B,8) -> 0 | P12: =SUMIFS(Discover!$F:$F,Discover!$K:$K,Subscriptions!$A12,Discover!$B:$B,9) -> 0 | Q12: =SUMIFS(Discover!$F:$F,Discover!$K:$K,Subscriptions!$A12,Discover!$B:$B,10) -> 0 | R12: =SUMIFS(Discover!$F:$F,Discover!$K:$K,Subscriptions!$A12,Discover!$B:$B,11) -> 0 | S12: =SUMIFS(Discover!$F:$F,Discover!$K:$K,Subscriptions!$A12,Discover!$B:$B,12) -> 0
A13: Family Fitness | B13: Monthly | C13: No | D13: {=AVERAGE(DAY(_xlfn.UNIQUE(_xlfn._xlws.FILTER(Discover!C:C, Discover!K:K = A13,0),1)))} -> 6.2 | E13: =SUMIFS(Discover!F:F,Discover!K:K,Subscriptions!A13) -> 418.8 | F13: =COUNTIFS(Discover!K:K,Subscriptions!A13,Discover!G:G,"APP") -> 5 | G13: =E13/F13 -> 83.76 | H13: =SUMIFS(Discover!$F:$F,Discover!$K:$K,Subscriptions!$A13,Discover!$B:$B,1) -> 0 | I13: =SUMIFS(Discover!$F:$F,Discover!$K:$K,Subscriptions!$A13,Discover!$B:$B,2) -> 0 | J13: =SUMIFS(Discover!$F:$F,Discover!$K:$K,Subscriptions!$A13,Discover!$B:$B,3) -> 0 | K13: =SUMIFS(Discover!$F:$F,Discover!$K:$K,Subscriptions!$A13,Discover!$B:$B,4) -> 84.95 | L13: =SUMIFS(Discover!$F:$F,Discover!$K:$K,Subscriptions!$A13,Discover!$B:$B,5) -> 94.95 | M13: =SUMIFS(Discover!$F:$F,Discover!$K:$K,Subscriptions!$A13,Discover!$B:$B,6) -> 143.95 | N13: =SUMIFS(Discover!$F:$F,Discover!$K:$K,Subscriptions!$A13,Discover!$B:$B,7) -> 0 | O13: =SUMIFS(Discover!$F:$F,Discover!$K:$K,Subscriptions!$A13,Discover!$B:$B,8) -> 94.95 | P13: =SUMIFS(Discover!$F:$F,Discover!$K:$K,Subscriptions!$A13,Discover!$B:$B,9) -> 0 | Q13: =SUMIFS(Discover!$F:$F,Discover!$K:$K,Subscriptions!$A13,Discover!$B:$B,10) -> 0 | R13: =SUMIFS(Discover!$F:$F,Discover!$K:$K,Subscriptions!$A13,Discover!$B:$B,11) -> 0 | S13: =SUMIFS(Discover!$F:$F,Discover!$K:$K,Subscriptions!$A13,Discover!$B:$B,12) -> 0
A14: Final Fantasy | B14: Monthly | C14: No | D14: {=AVERAGE(DAY(_xlfn.UNIQUE(_xlfn._xlws.FILTER(Discover!C:C, Discover!K:K = A14,0),1)))} -> 9.5 | E14: =SUMIFS(Discover!F:F,Discover!K:K,Subscriptions!A14) -> 155.88 | F14: =COUNTIFS(Discover!K:K,Subscriptions!A14,Discover!G:G,"APP") -> 2 | G14: =E14/F14 -> 77.94 | H14: =SUMIFS(Discover!$F:$F,Discover!$K:$K,Subscriptions!$A14,Discover!$B:$B,1) -> 0 | I14: =SUMIFS(Discover!$F:$F,Discover!$K:$K,Subscriptions!$A14,Discover!$B:$B,2) -> 0 | J14: =SUMIFS(Discover!$F:$F,Discover!$K:$K,Subscriptions!$A14,Discover!$B:$B,3) -> 0 | K14: =SUMIFS(Discover!$F:$F,Discover!$K:$K,Subscriptions!$A14,Discover!$B:$B,4) -> 0 | L14: =SUMIFS(Discover!$F:$F,Discover!$K:$K,Subscriptions!$A14,Discover!$B:$B,5) -> 77.94 | M14: =SUMIFS(Discover!$F:$F,Discover!$K:$K,Subscriptions!$A14,Discover!$B:$B,6) -> 77.94 | N14: =SUMIFS(Discover!$F:$F,Discover!$K:$K,Subscriptions!$A14,Discover!$B:$B,7) -> 0 | O14: =SUMIFS(Discover!$F:$F,Discover!$K:$K,Subscriptions!$A14,Discover!$B:$B,8) -> 0 | P14: =SUMIFS(Discover!$F:$F,Discover!$K:$K,Subscriptions!$A14,Discover!$B:$B,9) -> 0 | Q14: =SUMIFS(Discover!$F:$F,Discover!$K:$K,Subscriptions!$A14,Discover!$B:$B,10) -> 0 | R14: =SUMIFS(Discover!$F:$F,Discover!$K:$K,Subscriptions!$A14,Discover!$B:$B,11) -> 0 | S14: =SUMIFS(Discover!$F:$F,Discover!$K:$K,Subscriptions!$A14,Discover!$B:$B,12) -> 0
A15: Finimize | E15: =SUMIFS(Discover!F:F,Discover!K:K,Subscriptions!A15) -> 79.99 | F15: =COUNTIFS(Discover!K:K,Subscriptions!A15,Discover!G:G,"APP") -> 1 | G15: =E15/F15 -> 79.99 | H15: =SUMIFS(Discover!$F:$F,Discover!$K:$K,Subscriptions!$A15,Discover!$B:$B,1) -> 0 | I15: =SUMIFS(Discover!$F:$F,Discover!$K:$K,Subscriptions!$A15,Discover!$B:$B,2) -> 0 | J15: =SUMIFS(Discover!$F:$F,Discover!$K:$K,Subscriptions!$A15,Discover!$B:$B,3) -> 79.99 | K15: =SUMIFS(Discover!$F:$F,Discover!$K:$K,Subscriptions!$A15,Discover!$B:$B,4) -> 0 | L15: =SUMIFS(Discover!$F:$F,Discover!$K:$K,Subscriptions!$A15,Discover!$B:$B,5) -> 0 | M15: =SUMIFS(Discover!$F:$F,Discover!$K:$K,Subscriptions!$A15,Discover!$B:$B,6) -> 0 | N15: =SUMIFS(Discover!$F:$F,Discover!$K:$K,Subscriptions!$A15,Discover!$B:$B,7) -> 0 | O15: =SUMIFS(Discover!$F:$F,Discover!$K:$K,Subscriptions!$A15,Discover!$B:$B,8) -> 0 | P15: =SUMIFS(Discover!$F:$F,Discover!$K:$K,Subscriptions!$A15,Discover!$B:$B,9) -> 0 | Q15: =SUMIFS(Discover!$F:$F,Discover!$K:$K,Subscriptions!$A15,Discover!$B:$B,10) -> 0 | R15: =SUMIFS(Discover!$F:$F,Discover!$K:$K,Subscriptions!$A15,Discover!$B:$B,11) -> 0 | S15: =SUMIFS(Discover!$F:$F,Discover!$K:$K,Subscriptions!$A15,Discover!$B:$B,12) -> 0
A16: Funimation | B16: Monthly | C16: No | D16: {=AVERAGE(DAY(_xlfn.UNIQUE(_xlfn._xlws.FILTER(Discover!C:C, Discover!K:K = A16,0),1)))} -> 18 | E16: =SUMIFS(Discover!F:F,Discover!K:K,Subscriptions!A16) -> 8.47 | F16: =COUNTIFS(Discover!K:K,Subscriptions!A16,Discover!G:G,"APP") -> 1 | G16: =E16/F16 -> 8.47 | H16: =SUMIFS(Discover!$F:$F,Discover!$K:$K,Subscriptions!$A16,Discover!$B:$B,1) -> 0 | I16: =SUMIFS(Discover!$F:$F,Discover!$K:$K,Subscriptions!$A16,Discover!$B:$B,2) -> 0 | J16: =SUMIFS(Discover!$F:$F,Discover!$K:$K,Subscriptions!$A16,Discover!$B:$B,3) -> 0 | K16: =SUMIFS(Discover!$F:$F,Discover!$K:$K,Subscriptions!$A16,Discover!$B:$B,4) -> 0 | L16: =SUMIFS(Discover!$F:$F,Discover!$K:$K,Subscriptions!$A16,Discover!$B:$B,5) -> 0 | M16: =SUMIFS(Discover!$F:$F,Discover!$K:$K,Subscriptions!$A16,Discover!$B:$B,6) -> 0 | N16: =SUMIFS(Discover!$F:$F,Discover!$K:$K,Subscriptions!$A16,Discover!$B:$B,7) -> 0 | O16: =SUMIFS(Discover!$F:$F,Discover!$K:$K,Subscriptions!$A16,Discover!$B:$B,8) -> 8.47 | P16: =SUMIFS(Discover!$F:$F,Discover!$K:$K,Subscriptions!$A16,Discover!$B:$B,9) -> 0 | Q16: =SUMIFS(Discover!$F:$F,Discover!$K:$K,Subscriptions!$A16,Discover!$B:$B,10) -> 0 | R16: =SUMIFS(Discover!$F:$F,Discover!$K:$K,Subscriptions!$A16,Discover!$B:$B,11) -> 0 | S16: =SUMIFS(Discover!$F:$F,Discover!$K:$K,Subscriptions!$A16,Discover!$B:$B,12) -> 0
A17: GuitarTuna | B17: Monthly | C17: No | D17: {=AVERAGE(DAY(_xlfn.UNIQUE(_xlfn._xlws.FILTER(Discover!C:C, Discover!K:K = A17,0),1)))} -> 25 | E17: =SUMIFS(Discover!F:F,Discover!K:K,Subscriptions!A17) -> 5.29 | F17: =COUNTIFS(Discover!K:K,Subscriptions!A17,Discover!G:G,"APP") -> 1 | G17: =E17/F17 -> 5.29 | H17: =SUMIFS(Discover!$F:$F,Discover!$K:$K,Subscriptions!$A17,Discover!$B:$B,1) -> 0 | I17: =SUMIFS(Discover!$F:$F,Discover!$K:$K,Subscriptions!$A17,Discover!$B:$B,2) -> 0 | J17: =SUMIFS(Discover!$F:$F,Discover!$K:$K,Subscriptions!$A17,Discover!$B:$B,3) -> 0 | K17: =SUMIFS(Discover!$F:$F,Discover!$K:$K,Subscriptions!$A17,Discover!$B:$B,4) -> 0 | L17: =SUMIFS(Discover!$F:$F,Discover!$K:$K,Subscriptions!$A17,Discover!$B:$B,5) -> 5.29 | M17: =SUMIFS(Discover!$F:$F,Discover!$K:$K,Subscriptions!$A17,Discover!$B:$B,6) -> 0 | N17: =SUMIFS(Discover!$F:$F,Discover!$K:$K,Subscriptions!$A17,Discover!$B:$B,7) -> 0 | O17: =SUMIFS(Discover!$F:$F,Discover!$K:$K,Subscriptions!$A17,Discover!$B:$B,8) -> 0 | P17: =SUMIFS(Discover!$F:$F,Discover!$K:$K,Subscriptions!$A17,Discover!$B:$B,9) -> 0 | Q17: =SUMIFS(Discover!$F:$F,Discover!$K:$K,Subscriptions!$A17,Discover!$B:$B,10) -> 0 | R17: =SUMIFS(Discover!$F:$F,Discover!$K:$K,Subscriptions!$A17,Discover!$B:$B,11) -> 0 | S17: =SUMIFS(Discover!$F:$F,Discover!$K:$K,Subscriptions!$A17,Discover!$B:$B,12) -> 0
A18: HBO | B18: Monthly | C18: No | D18: {=AVERAGE(DAY(_xlfn.UNIQUE(_xlfn._xlws.FILTER(Discover!C:C, Discover!K:K = A18,0),1)))} -> 12 | E18: =SUMIFS(Discover!F:F,Discover!K:K,Subscriptions!A18) -> 187.89 | F18: =COUNTIFS(Discover!K:K,Subscriptions!A18,Discover!G:G,"APP") -> 12 | G18: =E18/F18 -> 15.6575 | H18: =SUMIFS(Discover!$F:$F,Discover!$K:$K,Subscriptions!$A18,Discover!$B:$B,1) -> 14.99 | I18: =SUMIFS(Discover!$F:$F,Discover!$K:$K,Subscriptions!$A18,Discover!$B:$B,2) -> 14.99 | J18: =SUMIFS(Discover!$F:$F,Discover!$K:$K,Subscriptions!$A18,Discover!$B:$B,3) -> 14.99 | K18: =SUMIFS(Discover!$F:$F,Discover!$K:$K,Subscriptions!$A18,Discover!$B:$B,4) -> 15.89 | L18: =SUMIFS(Discover!$F:$F,Discover!$K:$K,Subscriptions!$A18,Discover!$B:$B,5) -> 15.89 | M18: =SUMIFS(Discover!$F:$F,Discover!$K:$K,Subscriptions!$A18,Discover!$B:$B,6) -> 15.89 | N18: =SUMIFS(Discover!$F:$F,Discover!$K:$K,Subscriptions!$A18,Discover!$B:$B,7) -> 15.89 | O18: =SUMIFS(Discover!$F:$F,Discover!$K:$K,Subscriptions!$A18,Discover!$B:$B,8) -> 16.01 | P18: =SUMIFS(Discover!$F:$F,Discover!$K:$K,Subscriptions!$A18,Discover!$B:$B,9) -> 15.68 | Q18: =SUMIFS(Discover!$F:$F,Discover!$K:$K,Subscriptions!$A18,Discover!$B:$B,10) -> 15.89 | R18: =SUMIFS(Discover!$F:$F,Discover!$K:$K,Subscriptions!$A18,Discover!$B:$B,11) -> 15.89 | S18: =SUMIFS(Discover!$F:$F,Discover!$K:$K,Subscriptions!$A18,Discover!$B:$B,12) -> 15.89
A19: Hulu | B19: Annual | C19: Yes | D19: {=AVERAGE(DAY(_xlfn.UNIQUE(_xlfn._xlws.FILTER(Discover!C:C, Discover!K:K = A19,0),1)))} -> 3 | E19: =SUMIFS(Discover!F:F,Discover!K:K,Subscriptions!A19) -> 68.33 | F19: =COUNTIFS(Discover!K:K,Subscriptions!A19,Discover!G:G,"APP") -> 8 | G19: =E19/F19 -> 8.54125 | H19: =SUMIFS(Discover!$F:$F,Discover!$K:$K,Subscriptions!$A19,Discover!$B:$B,1) -> 0 | I19: =SUMIFS(Discover!$F:$F,Discover!$K:$K,Subscriptions!$A19,Discover!$B:$B,2) -> 0 | J19: =SUMIFS(Discover!$F:$F,Discover!$K:$K,Subscriptions!$A19,Discover!$B:$B,3) -> 0 | K19: =SUMIFS(Discover!$F:$F,Discover!$K:$K,Subscriptions!$A19,Discover!$B:$B,4) -> 0.99 | L19: =SUMIFS(Discover!$F:$F,Discover!$K:$K,Subscriptions!$A19,Discover!$B:$B,5) -> 5.99 | M19: =SUMIFS(Discover!$F:$F,Discover!$K:$K,Subscriptions!$A19,Discover!$B:$B,6) -> 0.4 | N19: =SUMIFS(Discover!$F:$F,Discover!$K:$K,Subscriptions!$A19,Discover!$B:$B,7) -> 11.99 | O19: =SUMIFS(Discover!$F:$F,Discover!$K:$K,Subscriptions!$A19,Discover!$B:$B,8) -> 11.99 | P19: =SUMIFS(Discover!$F:$F,Discover!$K:$K,Subscriptions!$A19,Discover!$B:$B,9) -> 11.99 | Q19: =SUMIFS(Discover!$F:$F,Discover!$K:$K,Subscriptions!$A19,Discover!$B:$B,10) -> 11.99 | R19: =SUMIFS(Discover!$F:$F,Discover!$K:$K,Subscriptions!$A19,Discover!$B:$B,11) -> 12.99 | S19: =SUMIFS(Discover!$F:$F,Discover!$K:$K,Subscriptions!$A19,Discover!$B:$B,12) -> 0
