Workbook

Sheet Data
A1: {=_xlfn._xlws.PY(0,1,Combined_Accounts[#All])} -> #VALUE!
A4: Column1 | B4: ORIG_INDEX | C4: Trans_Date | D4: Description | E4: Amount | F4: Category | G4: Short_Desc | H4: Reoccurring_Flag | I4: Category_2 | J4: Date | K4: Year | L4: Sort_Date | M4: CumAmount | N4: Counter | O4: Account | P4: Last_balance
A5: 0 | B5: 0 | C5: 44927 | D5: Balance | E5: 616.53 | G5: Balance | H5: No | I5: Balance | J5: 44927 | K5: 2023 | L5: 44927 | M5: 616.53 | N5: 1 | O5: wells_fargo_checking | P5: =IF(J5<>J6, 1, 0) -> 1 | R5: =R6+Combined_Accounts[[#This Row],[Amount]] -> 1549.47 | T5: 616.53
A6: 1 | B6: 1 | C6: 45293 | D6: PURCHASE AUTHORIZED ON 01/01 A&A GAS BURLINGAME CA P584001656812755 CARD 1081 | E6: -47.14 | G6: gas | H6: No | I6: Utilities | J6: 45292 | K6: 2024 | L6: 45293 | M6: 569.39 | N6: 1 | O6: wells_fargo_checking | P6: =IF(J6<>J7, 1, 0) -> 0 | R6: =R7+Combined_Accounts[[#This Row],[Amount]] -> 932.94 | T6: =T5+Combined_Accounts[[#This Row],[Amount]] -> 569.39
A7: 2 | B7: 2 | C7: 45293 | D7: PURCHASE AUTHORIZED ON 12/30 REDWOOD CITY PARKI REDWOOD CITY CA S303364838418587 CARD 1081 | E7: -0.5 | G7: parking | H7: No | I7: Transportation | J7: 45292 | K7: 2024 | L7: 45293 | M7: 568.89 | N7: 1 | O7: wells_fargo_checking | P7: =IF(J7<>J8, 1, 0) -> 0 | R7: =R8+Combined_Accounts[[#This Row],[Amount]] -> 980.08 | T7: =T6+Combined_Accounts[[#This Row],[Amount]] -> 568.89
A8: 3 | B8: 3 | C8: 45302 | D8: PURCHASE AUTHORIZED ON 01/11 ARCO#00524MEHRZ MILL VALLEY CA P000000381980594 CARD 1081 | E8: -33.17 | G8: gas | H8: No | I8: Utilities | J8: 45292 | K8: 2024 | L8: 45302 | M8: 535.72 | N8: 2 | O8: wells_fargo_checking | P8: =IF(J8<>J9, 1, 0) -> 0 | R8: =R9+Combined_Accounts[[#This Row],[Amount]] -> 980.58 | T8: =T7+Combined_Accounts[[#This Row],[Amount]] -> 535.72
A9: 4 | B9: 4 | C9: 45302 | D9: PURCHASE AUTHORIZED ON 01/11 ARCO#00524MEHRZ MILL VALLEY CA P000000181526744 CARD 1081 | E9: -12.06 | G9: gas | H9: No | I9: Utilities | J9: 45292 | K9: 2024 | L9: 45302 | M9: 523.66 | N9: 3 | O9: wells_fargo_checking | P9: =IF(J9<>J10, 1, 0) -> 0 | R9: =R10+Combined_Accounts[[#This Row],[Amount]] -> 1013.75 | T9: =T8+Combined_Accounts[[#This Row],[Amount]] -> 523.66
A10: 5 | B10: 5 | C10: 45302 | D10: Nationwide PAYROLL 01 HRP0009988056 Sean Lewis | E10: 502.15 | G10: income | H10: No | I10: Income | J10: 45292 | K10: 2024 | L10: 45302 | M10: 1025.81 | N10: 1 | O10: wells_fargo_checking | P10: =IF(J10<>J11, 1, 0) -> 0 | R10: 1025.81 | T10: =T9+Combined_Accounts[[#This Row],[Amount]] -> 1025.81
A11: 6 | B11: 6 | C11: 45307 | D11: DEPT EDUCATION STUDENT LN 240112 6PN51D9CCK1 SEAN LEWIS | E11: -426.16 | G11: student_loan | H11: Yes | I11: Government | J11: 45292 | K11: 2024 | L11: 45307 | M11: 599.65 | N11: 1 | O11: wells_fargo_checking | P11: =IF(J11<>J12, 1, 0) -> 0 | T11: =T10+Combined_Accounts[[#This Row],[Amount]] -> 599.65
A12: 7 | B12: 7 | C12: 45307 | D12: ZELLE FROM LEWIS JUSTINA ON 01/13 REF # PP0RVXHPT7 CARE CREDIT PAYMENT | E12: 180 | G12: family | H12: No | I12: People | J12: 45292 | K12: 2024 | L12: 45307 | M12: 779.65 | N12: 1 | O12: wells_fargo_checking | P12: =IF(J12<>J13, 1, 0) -> 0 | T12: =T11+Combined_Accounts[[#This Row],[Amount]] -> 779.65
A13: 8 | B13: 8 | C13: 45308 | D13: ZELLE TO LEWIS DORRY ON 01/17 REF #PP0RW6NBQX GIFT NO RETURN | E13: -100 | G13: family | H13: No | I13: People | J13: 45292 | K13: 2024 | L13: 45308 | M13: 679.65 | N13: 2 | O13: wells_fargo_checking | P13: =IF(J13<>J14, 1, 0) -> 0 | T13: =T12+Combined_Accounts[[#This Row],[Amount]] -> 679.65
A14: 9 | B14: 9 | C14: 45308 | D14: STUBHUB CONS PAYMENTS 240117 000000017167884 9016004299-SEAN LEWIS | E14: 123.48 | G14: refunds | H14: No | I14: Income | J14: 45292 | K14: 2024 | L14: 45308 | M14: 803.13 | N14: 1 | O14: wells_fargo_checking | P14: =IF(J14<>J15, 1, 0) -> 0 | T14: =T13+Combined_Accounts[[#This Row],[Amount]] -> 803.13
A15: 10 | B15: 10 | C15: 45309 | D15: T-MOBILE PCS SVC 240117 1121101 DON LEWIS | E15: -111.63 | G15: Don | H15: No | I15: People | J15: 45292 | K15: 2024 | L15: 45309 | M15: 691.5 | N15: 1 | O15: wells_fargo_checking | P15: =IF(J15<>J16, 1, 0) -> 0 | T15: =T14+Combined_Accounts[[#This Row],[Amount]] -> 691.5
A16: 11 | B16: 11 | C16: 45314 | D16: ZELLE TO LEWIS JAYELIN ON 01/23 REF #PP0RWMP6F2 FOR LUNCH | E16: -30 | G16: family | H16: No | I16: People | J16: 45292 | K16: 2024 | L16: 45314 | M16: 661.5 | N16: 3 | O16: wells_fargo_checking | P16: =IF(J16<>J17, 1, 0) -> 0 | T16: =T15+Combined_Accounts[[#This Row],[Amount]] -> 661.5
A17: 12 | B17: 12 | C17: 45314 | D17: VENMO CASHOUT 240123 1032084728310 SEAN LEWIS | E17: 318.83 | G17: venmo | H17: No | I17: People | J17: 45292 | K17: 2024 | L17: 45314 | M17: 980.33 | N17: 1 | O17: wells_fargo_checking | P17: =IF(J17<>J18, 1, 0) -> 0 | T17: =T16+Combined_Accounts[[#This Row],[Amount]] -> 980.33
A18: 13 | B18: 13 | C18: 45315 | D18: Synchrony Bank CC PYMT JAN 23 524306003390321 SEAN LEWIS | E18: -417.29 | G18: care_credit | H18: Yes | I18: Medical | J18: 45292 | K18: 2024 | L18: 45315 | M18: 563.04 | N18: 1 | O18: wells_fargo_checking | P18: =IF(J18<>J19, 1, 0) -> 0 | T18: =T17+Combined_Accounts[[#This Row],[Amount]] -> 563.04
A19: 14 | B19: 14 | C19: 45315 | D19: ZELLE FROM LEWIS JAYELIN ON 01/24 REF # PP0RWQ7TRW PAYING BACK SUIT 200 OUT OF 700 | E19: 200 | G19: family | H19: No | I19: People | J19: 45292 | K19: 2024 | L19: 45315 | M19: 763.04 | N19: 4 | O19: wells_fargo_checking | P19: =IF(J19<>J20, 1, 0) -> 0 | T19: =T18+Combined_Accounts[[#This Row],[Amount]] -> 763.04
A20: 15 | B20: 15 | C20: 45316 | D20: SoFi Bank TRANSFER SD1300 SLewis Sean Lewis:66864:1064 | E20: -500 | G20: misc | H20: No | I20: Misc | J20: 45292 | K20: 2024 | L20: 45316 | M20: 263.04 | N20: 1 | O20: wells_fargo_checking | P20: =IF(J20<>J21, 1, 0) -> 0 | T20: =T19+Combined_Accounts[[#This Row],[Amount]] -> 263.04
A21: 16 | B21: 16 | C21: 45316 | D21: PURCHASE AUTHORIZED ON 01/24 West Town Bank T 8332572512 IL S384025071228723 CARD 1081 | E21: -30.86 | G21: restaurants | H21: No | I21: Personal_Spending | J21: 45292 | K21: 2024 | L21: 45316 | M21: 232.18 | N21: 1 | O21: wells_fargo_checking | P21: =IF(J21<>J22, 1, 0) -> 0 | T21: =T20+Combined_Accounts[[#This Row],[Amount]] -> 232.18
A22: 17 | B22: 17 | C22: 45316 | D22: Nationwide PAYROLL 01 HRP0010014543 Sean Lewis | E22: 502.15 | G22: income | H22: No | I22: Income | J22: 45292 | K22: 2024 | L22: 45316 | M22: 734.33 | N22: 2 | O22: wells_fargo_checking | P22: =IF(J22<>J23, 1, 0) -> 1 | T22: =T21+Combined_Accounts[[#This Row],[Amount]] -> 734.33
... A53: 48 | B53: 48 | C53: 45387 | D53: ZELLE TO LEWIS DORRY ON 04/05 REF #PP0S4Q22SG HOPE THIS HELPS | E53: -200 | G53: family | H53: No | I53: People | J53: 45383 | K53: 2024 | L53: 45387 | M53: 183.6 | N53: 8 | O53: wells_fargo_checking | P53: =IF(J53<>J54, 1, 0) -> 0 | T53: =T52+Combined_Accounts[[#This Row],[Amount]] -> 183.6
A54: 49 | B54: 49 | C54: 45391 | D54: ATM WITHDRAWAL AUTHORIZED ON 04/09 100 E 4th Ave San Mateo CA 0007489 ATM ID 0520C CARD 1081 | E54: -200 | G54: ATM | H54: No | I54: Personal_Spending | J54: 45383 | K54: 2024 | L54: 45391 | M54: -16.4 | N54: 3 | O54: wells_fargo_checking | P54: =IF(J54<>J55, 1, 0) -> 0
A55: 50 | B55: 50 | C55: 45391 | D55: ZELLE FROM LEWIS DORRY ON 04/08 REF # PP0S4ZN6KM | E55: 200 | G55: family | H55: No | I55: People | J55: 45383 | K55: 2024 | L55: 45391 | M55: 183.6 | N55: 9 | O55: wells_fargo_checking | P55: =IF(J55<>J56, 1, 0) -> 0
A56: 51 | B56: 51 | C56: 45392 | D56: ATM CASH DEPOSIT ON 04/10 100 E 4th Ave San Mateo CA 0007790 ATM ID 0520C CARD 1081 | E56: 32 | G56: ATM | H56: No | I56: Personal_Spending | J56: 45383 | K56: 2024 | L56: 45392 | M56: 215.6 | N56: 4 | O56: wells_fargo_checking | P56: =IF(J56<>J57, 1, 0) -> 0
A57: 52 | B57: 52 | C57: 45392 | D57: ATM CASH DEPOSIT ON 04/10 100 E 4th Ave San Mateo CA 0007789 ATM ID 0520C CARD 1081 | E57: 269 | G57: ATM | H57: No | I57: Personal_Spending | J57: 45383 | K57: 2024 | L57: 45392 | M57: 484.6 | N57: 5 | O57: wells_fargo_checking | P57: =IF(J57<>J58, 1, 0) -> 0
A58: 53 | B58: 53 | C58: 45397 | D58: VENMO PAYMENT 240415 1033792256663 SEAN LEWIS | E58: -20 | G58: venmo | H58: No | I58: People | J58: 45383 | K58: 2024 | L58: 45397 | M58: 464.6 | N58: 5 | O58: wells_fargo_checking | P58: =IF(J58<>J59, 1, 0) -> 0
A59: 54 | B59: 54 | C59: 45397 | D59: L A FITNESS 9492558100 041524 49343747 I783466887 | E59: -220 | G59: la_fitness | H59: Yes | I59: Personal_Spending | J59: 45383 | K59: 2024 | L59: 45397 | M59: 244.6 | N59: 2 | O59: wells_fargo_checking | P59: =IF(J59<>J60, 1, 0) -> 0
A60: 55 | B60: 55 | C60: 45397 | D60: PURCHASE AUTHORIZED ON 04/12 OANH LE DDS SAN MATEO CA S464103813791194 CARD 1081 | E60: -44 | G60: dentist | H60: No | I60: Medical | J60: 45383 | K60: 2024 | L60: 45397 | M60: 200.6 | N60: 2 | O60: wells_fargo_checking | P60: =IF(J60<>J61, 1, 0) -> 0
A61: 56 | B61: 56 | C61: 45400 | D61: T-MOBILE PCS SVC 240417 9053559 DON LEWIS | E61: -65.83 | G61: Don | H61: No | I61: People | J61: 45383 | K61: 2024 | L61: 45400 | M61: 134.77 | N61: 4 | O61: wells_fargo_checking | P61: =IF(J61<>J62, 1, 0) -> 0
A62: 57 | B62: 57 | C62: 45400 | D62: Nationwide PAYROLL 01 HRP0010244110 Sean Lewis | E62: 527.56 | G62: income | H62: No | I62: Income | J62: 45383 | K62: 2024 | L62: 45400 | M62: 662.33 | N62: 8 | O62: wells_fargo_checking | P62: =IF(J62<>J63, 1, 0) -> 0
A63: 58 | B63: 58 | C63: 45400 | D63: ZELLE FROM KAI FENG PAN ON 04/17 REF # BACAIP4JOFOT FOR INVISALIGN | E63: 3000 | G63: Vincent | H63: No | I63: People | J63: 45383 | K63: 2024 | L63: 45400 | M63: 3662.33 | N63: 1 | O63: wells_fargo_checking | P63: =IF(J63<>J64, 1, 0) -> 0
A64: 59 | B64: 59 | C64: 45401 | D64: Synchrony Bank CC PYMT Apr 19 524306003390321 SEAN LEWIS | E64: -3000 | G64: care_credit | H64: Yes | I64: Medical | J64: 45383 | K64: 2024 | L64: 45401 | M64: 662.33 | N64: 4 | O64: wells_fargo_checking | P64: =IF(J64<>J65, 1, 0) -> 0
A65: 60 | B65: 60 | C65: 45404 | D65: NON-WELLS FARGO ATM TRANSACTION FEE | E65: -5 | G65: ATM | H65: No | I65: Personal_Spending | J65: 45383 | K65: 2024 | L65: 45404 | M65: 657.33 | N65: 6 | O65: wells_fargo_checking | P65: =IF(J65<>J66, 1, 0) -> 0
... A377: 372 | B377: 372 | C377: 45593 | D377: PURCHASE AUTHORIZED ON 10/26 ARCO#04495SINO SAN MATEO CA P000000172446007 CARD 1081 | E377: -43.98 | G377: gas | H377: No | I377: Utilities | J377: 45566 | K377: 2024 | L377: 45593 | M377: 473.36 | N377: 15 | O377: wells_fargo_checking | P377: =IF(J377<>J378, 1, 0) -> 0
A378: 373 | B378: 373 | C378: 45593 | D378: PURCHASE AUTHORIZED ON 10/25 STADIUM GARAGE BERKELEY CA S584300071995368 CARD 1081 | E378: -30 | G378: starting_balance | H378: No | J378: 45566 | K378: 2024 | L378: 45593 | M378: 443.36 | N378: 1 | O378: wells_fargo_checking | P378: =IF(J378<>J379, 1, 0) -> 0
A379: 374 | B379: 374 | C379: 45596 | D379: Nationwide PAYROLL 01 HRP0010768329 Sean Lewis | E379: 527.56 | G379: income | H379: No | I379: Utilities | J379: 45566 | K379: 2024 | L379: 45596 | M379: 970.92 | N379: 16 | O379: wells_fargo_checking | P379: =IF(J379<>J380, 1, 0) -> 1
A380: 375 | B380: 375 | C380: 45597 | D380: PURCHASE AUTHORIZED ON 11/01 76 ORINDA ORINDA CA P000000177866673 CARD 1081 | E380: -47.24 | G380: gas | H380: No | I380: Utilities | J380: 45597 | K380: 2024 | L380: 45597 | M380: 923.68 | N380: 17 | O380: wells_fargo_checking | P380: =IF(J380<>J381, 1, 0) -> 0
A381: 376 | B381: 376 | C381: 45600 | D381: MONEY TRANSFER AUTHORIZED ON 11/01 CASH APP*CAIRO DAN Oakland CA S304306763501389 CARD 1081 | E381: -150 | G381: gas | H381: No | I381: Utilities | J381: 45597 | K381: 2024 | L381: 45600 | M381: 773.68 | N381: 18 | O381: wells_fargo_checking | P381: =IF(J381<>J382, 1, 0) -> 0
A382: 377 | B382: 377 | C382: 45600 | D382: ZELLE FROM JONATHAN W ABADA ON 11/03 REF # JPM99AQLEFH6 FANTASY | E382: 69 | G382: venmo | H382: No | I382: People | J382: 45597 | K382: 2024 | L382: 45600 | M382: 842.68 | N382: 13 | O382: wells_fargo_checking | P382: =IF(J382<>J383, 1, 0) -> 0
A383: 378 | B383: 378 | C383: 45604 | D383: PURCHASE AUTHORIZED ON 11/08 A&A GAS BURLINGAME CA P584313515259674 CARD 1081 | E383: -37.45 | G383: gas | H383: No | I383: Utilities | J383: 45597 | K383: 2024 | L383: 45604 | M383: 805.23 | N383: 19 | O383: wells_fargo_checking | P383: =IF(J383<>J384, 1, 0) -> 0
...

Sheet Reoccurring
A1: Reoccurring_Flag | B1: Yes
A3: Sum of Amount | B3: Column Labels
A4: Row Labels | B4: 45292 | C4: 45323 | D4: 45352 | E4: 45383 | F4: 45413 | G4: 45444 | H4: 45474 | I4: 45505 | J4: 45536 | K4: 45566 | L4: 45597 | M4: 45627 | N4: Grand Total
A5: adobe | B5: 29.99 | C5: 29.99 | D5: 29.99 | E5: 29.99 | F5: 29.99 | G5: 29.99 | H5: 29.99 | I5: 29.99 | J5: 29.99 | K5: 29.99 | L5: 29.99 | M5: 59.99 | N5: 389.88
A6: apple_care | B6: 9.99 | C6: 9.99 | D6: 9.99 | E6: 9.99 | N6: 39.96
A7: breaking_points | B7: 10 | C7: 10 | D7: 10 | E7: 10 | F7: 10 | G7: 10 | H7: 10 | I7: 10 | J7: 10 | K7: 10 | L7: 10 | M7: 10 | N7: 120
A8: care_credit | B8: -417.29 | C8: -237.29 | D8: -458.96 | E8: -3000 | F8: -458.96 | J8: -460 | N8: -5032.5
A9: cell_phone | C9: -366.21 | D9: 91.98 | L9: 820.34 | M9: 238.98 | N9: 785.09
A10: chatgpt | B10: 20 | C10: 20 | D10: 20 | E10: 20 | F10: 20 | G10: 20 | H10: 20 | I10: 20 | J10: 20 | K10: 20 | L10: 20 | M10: 20 | N10: 240
A11: do_the_bay | B11: 5 | C11: 0 | N11: 5
A12: google_colab | D12: 10.59 | N12: 10.59
A13: gym | B13: 269.5 | C13: 220 | K13: 49.5 | L13: 49.5 | N13: 588.5
A14: hbo | B14: 15.89 | N14: 15.89
A15: interest | B15: 0.04 | C15: 0.21 | D15: 0.17 | E15: 0.12 | F15: 0.18 | G15: 0.21 | H15: 0.33 | I15: 0.37 | J15: 0.65 | K15: 0.53 | L15: 0.62 | M15: 0.68 | N15: 4.11
A16: la_fitness | D16: -220 | E16: -220 | F16: -220 | G16: -220 | H16: 440 | N16: -440
A17: laptop | B17: -155 | C17: -155 | D17: -155 | E17: -155 | F17: -155 | G17: -634.69 | N17: -1409.69
A18: lickd | B18: 15 | N18: 15
A19: onepass | B19: 273.6 | C19: 273.6 | D19: 273.6 | E19: 273.6 | F19: 273.6 | G19: 273.6 | H19: 273.6 | I19: 273.6 | J19: 273.6 | K19: 273.6 | L19: 273.6 | M19: 273.6 | N19: 3283.2
A20: political_cause | B20: 5 | C20: 5 | D20: 5 | E20: 5 | F20: 5 | G20: 5 | H20: 5 | I20: 5 | J20: 5 | K20: 5 | L20: 5 | M20: 5 | N20: 60
A21: real_python | B21: 29.99 | C21: 29.99 | N21: 59.98
A22: rent | C22: -2450.61 | N22: -2450.61
A23: spotify | B23: 5.99 | C23: 5.99 | D23: 5.99 | E23: 5.99 | F23: 5.99 | G23: 5.99 | H23: 5.99 | I23: 5.99 | J23: 5.99 | K23: 5.99 | L23: 5.99 | M23: 11.99 | N23: 77.88
A24: state_farm | B24: 90.83 | C24: 90.54 | D24: 90.54 | E24: 90.54 | F24: 90.54 | G24: 90.54 | H24: 90.54 | I24: 108.56 | J24: 108.56 | N24: 851.19
A25: student_loan | B25: -426.16 | C25: -442.73 | D25: -442.73 | E25: -442.73 | F25: -442.73 | G25: -442.73 | H25: -442.73 | I25: -442.73 | J25: -442.73 | K25: -442.73 | L25: -442.73 | M25: -442.73 | N25: -5296.19
A26: vincent_debt | B26: -1803.4 | C26: -3606.8 | D26: -3277.12 | N26: -8687.32
A27: microsoft365 | E27: 69.99 | N27: 69.99
A28: nba_league_pass | F28: 24.37 | G28: 24.37 | H28: 24.37 | K28: 20 | L28: 50 | M28: 25 | N28: 168.11
A29: google_one | I29: 2.11 | J29: 2.11 | K29: 2.11 | L29: 2.11 | M29: 2.11 | N29: 10.55
A30: physical_therapy | K30: 30 | N30: 30
A31: Grand Total | B31: -2021.03 | C31: -6563.33 | D31: -4005.96 | E31: -3302.51 | F31: -817.02 | G31: -837.72 | H31: 457.09 | I31: 12.89 | J31: -446.83 | K31: 3.99 | L31: 824.42 | M31: 204.62 | N31: -16491.39

Sheet Summary
B2: Income | C2: 45292 | D2: =EOMONTH(C2,0)+1 -> 45323 | E2: =EOMONTH(D2,0)+1 -> 45352 | F2: =EOMONTH(E2,0)+1 -> 45383 | G2: =EOMONTH(F2,0)+1 -> 45413 | H2: =EOMONTH(G2,0)+1 -> 45444 | I2: =EOMONTH(H2,0)+1 -> 45474 | J2: =EOMONTH(I2,0)+1 -> 45505 | K2: =EOMONTH(J2,0)+1 -> 45536 | ... N2: =EOMONTH(M2,0)+1 -> 45627
B3: income | C3: =SUMIFS(Combined_Accounts[Amount],Combined_Accounts[Date],C$2,Combined_Accounts[Short_Desc],$B3) -> 6695.36 | D3: =SUMIFS(Combined_Accounts[Amount],Combined_Accounts[Date],D$2,Combined_Accounts[Short_Desc],$B3) -> 9108.05 | E3: =SUMIFS(Combined_Accounts[Amount],Combined_Accounts[Date],E$2,Combined_Accounts[Short_Desc],$B3) -> 8398.56 | F3: =SUMIFS(Combined_Accounts[Amount],Combined_Accounts[Date],F$2,Combined_Accounts[Short_Desc],$B3) -> 11304.56 | G3: =SUMIFS(Combined_Accounts[Amount],Combined_Accounts[Date],G$2,Combined_Accounts[Short_Desc],$B3) -> 7561.64 | H3: =SUMIFS(Combined_Accounts[Amount],Combined_Accounts[Date],H$2,Combined_Accounts[Short_Desc],$B3) -> 7966.08 | I3: =SUMIFS(Combined_Accounts[Amount],Combined_Accounts[Date],I$2,Combined_Accounts[Short_Desc],$B3) -> 7034.08 | J3: =SUMIFS(Combined_Accounts[Amount],Combined_Accounts[Date],J$2,Combined_Accounts[Short_Desc],$B3) -> 7034.08 | ... N3: =SUMIFS(Combined_Accounts[Amount],Combined_Accounts[Date],N$2,Combined_Accounts[Short_Desc],$B3) -> 7034.08
B4: savings | C4: =SUMIFS(Combined_Accounts[Amount],Combined_Accounts[Date],C$2,Combined_Accounts[Category_2],$B4) -> 5691.06 | D4: =SUMIFS(Combined_Accounts[Amount],Combined_Accounts[Date],D$2,Combined_Accounts[Category_2],$B4) -> 7753.09 | E4: =SUMIFS(Combined_Accounts[Amount],Combined_Accounts[Date],E$2,Combined_Accounts[Category_2],$B4) -> 7138.78 | F4: =SUMIFS(Combined_Accounts[Amount],Combined_Accounts[Date],F$2,Combined_Accounts[Category_2],$B4) -> 10249.44 | G4: =SUMIFS(Combined_Accounts[Amount],Combined_Accounts[Date],G$2,Combined_Accounts[Category_2],$B4) -> 5978.96 | H4: =SUMIFS(Combined_Accounts[Amount],Combined_Accounts[Date],H$2,Combined_Accounts[Category_2],$B4) -> 6771.17 | I4: =SUMIFS(Combined_Accounts[Amount],Combined_Accounts[Date],I$2,Combined_Accounts[Category_2],$B4) -> 5978.96 | J4: =SUMIFS(Combined_Accounts[Amount],Combined_Accounts[Date],J$2,Combined_Accounts[Category_2],$B4) -> 5978.96 | ... N4: =SUMIFS(Combined_Accounts[Amount],Combined_Accounts[Date],N$2,Combined_Accounts[Category_2],$B4) -> 5978.96
B5: checking | C5: =C3-C4 -> 1004.3 | D5: =D3-D4 -> 1354.96 | E5: =E3-E4 -> 1259.78 | F5: =F3-F4 -> 1055.12 | G5: =G3-G4 -> 1582.68 | H5: =H3-H4 -> 1194.91 | I5: =I3-I4 -> 1055.12 | J5: =J3-J4 -> 1055.12 | ... N5: =N3-N4 -> 1055.12
B6: don | F6: 400 | G6: 400 | H6: 400 | I6: 400 | J6: 400 | K6: 400 | L6: 400 | M6: 400 | N6: 400
B7: insurance reimbursement
B8: Total | C8: =SUM(C6:C7)+C3 -> 6695.36 | D8: =SUM(D6:D7)+D3 -> 9108.05 | E8: =SUM(E6:E7)+E3 -> 8398.56 | F8: =SUM(F6:F7)+F3 -> 11704.56 | G8: =SUM(G6:G7)+G3 -> 7961.64 | H8: =SUM(H6:H7)+H3 -> 8366.08 | I8: =SUM(I6:I7)+I3 -> 7434.08 | J8: =SUM(J6:J7)+J3 -> 7434.08 | ... N8: =SUM(N6:N7)+N3 -> 7434.08
B10: Fixed Expenses | C10: 45292 | D10: =EOMONTH(C10,0)+1 -> 45323 | E10: =EOMONTH(D10,0)+1 -> 45352 | F10: =EOMONTH(E10,0)+1 -> 45383 | G10: =EOMONTH(F10,0)+1 -> 45413 | H10: =EOMONTH(G10,0)+1 -> 45444 | I10: =EOMONTH(H10,0)+1 -> 45474 | J10: =EOMONTH(I10,0)+1 -> 45505 | K10: =EOMONTH(J10,0)+1 -> 45536 | ... N10: =EOMONTH(M10,0)+1 -> 45627
B11: rent | C11: =SUMIFS(Combined_Accounts[Amount],Combined_Accounts[Date],C$2,Combined_Accounts[Short_Desc],$B11,Combined_Accounts[Account],"discover") + SUMIFS(Combined_Accounts[Amount],Combined_Accounts[Date],C$2,Combined_Accounts[Short_Desc],$B11,Combined_Accounts[Account],"<>" & "discover")*-1 -> 0 | D11: =SUMIFS(Combined_Accounts[Amount],Combined_Accounts[Date],D$2,Combined_Accounts[Short_Desc],$B11,Combined_Accounts[Account],"discover") + SUMIFS(Combined_Accounts[Amount],Combined_Accounts[Date],D$2,Combined_Accounts[Short_Desc],$B11,Combined_Accounts[Account],"<>" & "discover")*-1 -> 2450.61 | E11: =SUMIFS(Combined_Accounts[Amount],Combined_Accounts[Date],E$2,Combined_Accounts[Short_Desc],$B11,Combined_Accounts[Account],"discover") + SUMIFS(Combined_Accounts[Amount],Combined_Accounts[Date],E$2,Combined_Accounts[Short_Desc],$B11,Combined_Accounts[Account],"<>" & "discover")*-1 -> 0 | F11: =SUMIFS(Combined_Accounts[Amount],Combined_Accounts[Date],F$2,Combined_Accounts[Short_Desc],$B11,Combined_Accounts[Account],"discover") + SUMIFS(Combined_Accounts[Amount],Combined_Accounts[Date],F$2,Combined_Accounts[Short_Desc],$B11,Combined_Accounts[Account],"<>" & "discover")*-1 -> 0 | G11: =SUMIFS(Combined_Accounts[Amount],Combined_Accounts[Date],G$2,Combined_Accounts[Short_Desc],$B11,Combined_Accounts[Account],"discover") + SUMIFS(Combined_Accounts[Amount],Combined_Accounts[Date],G$2,Combined_Accounts[Short_Desc],$B11,Combined_Accounts[Account],"<>" & "discover")*-1 -> 0 | H11: =SUMIFS(Combined_Accounts[Amount],Combined_Accounts[Date],H$2,Combined_Accounts[Short_Desc],$B11,Combined_Accounts[Account],"discover") + SUMIFS(Combined_Accounts[Amount],Combined_Accounts[Date],H$2,Combined_Accounts[Short_Desc],$B11,Combined_Accounts[Account],"<>" & "discover")*-1 -> 0 | I11: =SUMIFS(Combined_Accounts[Amount],Combined_Accounts[Date],I$2,Combined_Accounts[Short_Desc],$B11,Combined_Accounts[Account],"discover") + SUMIFS(Combined_Accounts[Amount],Combined_Accounts[Date],I$2,Combined_Accounts[Short_Desc],$B11,Combined_Accounts[Account],"<>" & "discover")*-1 -> 0 | J11: =SUMIFS(Combined_Accounts[Amount],Combined_Accounts[Date],J$2,Combined_Accounts[Short_Desc],$B11,Combined_Accounts[Account],"discover") + SUMIFS(Combined_Accounts[Amount],Combined_Accounts[Date],J$2,Combined_Accounts[Short_Desc],$B11,Combined_Accounts[Account],"<>" & "discover")*-1 -> 0 | K11: 1633.74 | L11: 1633.74 | M11: 1633.74 | N11: 1633.74
B12: vincent_debt | C12: =SUMIFS(Combined_Accounts[Amount],Combined_Accounts[Date],C$2,Combined_Accounts[Short_Desc],$B12,Combined_Accounts[Account],"discover") + SUMIFS(Combined_Accounts[Amount],Combined_Accounts[Date],C$2,Combined_Accounts[Short_Desc],$B12,Combined_Accounts[Account],"<>" & "discover")*-1 -> 1803.4 | D12: =SUMIFS(Combined_Accounts[Amount],Combined_Accounts[Date],D$2,Combined_Accounts[Short_Desc],$B12,Combined_Accounts[Account],"discover") + SUMIFS(Combined_Accounts[Amount],Combined_Accounts[Date],D$2,Combined_Accounts[Short_Desc],$B12,Combined_Accounts[Account],"<>" & "discover")*-1 -> 3606.8 | E12: =SUMIFS(Combined_Accounts[Amount],Combined_Accounts[Date],E$2,Combined_Accounts[Short_Desc],$B12)*-1 -> 3277.12 | F12: =SUMIFS(Combined_Accounts[Amount],Combined_Accounts[Date],F$2,Combined_Accounts[Short_Desc],$B12)*-1 -> 0 | G12: =SUMIFS(Combined_Accounts[Amount],Combined_Accounts[Date],G$2,Combined_Accounts[Short_Desc],$B12)*-1 -> 0 | H12: =SUMIFS(Combined_Accounts[Amount],Combined_Accounts[Date],H$2,Combined_Accounts[Short_Desc],$B12)*-1 -> 0 | I12: =SUMIFS(Combined_Accounts[Amount],Combined_Accounts[Date],I$2,Combined_Accounts[Short_Desc],$B12)*-1 -> 0 | J12: =SUMIFS(Combined_Accounts[Amount],Combined_Accounts[Date],J$2,Combined_Accounts[Short_Desc],$B12)*-1 -> 0 | K12: =SUMIFS(Combined_Accounts[Amount],Combined_Accounts[Date],K$2,Combined_Accounts[Short_Desc],$B12)*-1 -> 0 | L12: =SUMIFS(Combined_Accounts[Amount],Combined_Accounts[Date],L$2,Combined_Accounts[Short_Desc],$B12)*-1 -> 0 | ... N12: =SUMIFS(Combined_Accounts[Amount],Combined_Accounts[Date],N$2,Combined_Accounts[Short_Desc],$B12)*-1 -> 0
B13: laptop | C13: =SUMIFS(Combined_Accounts[Amount],Combined_Accounts[Date],C$2,Combined_Accounts[Short_Desc],$B13,Combined_Accounts[Account],"discover") + SUMIFS(Combined_Accounts[Amount],Combined_Accounts[Date],C$2,Combined_Accounts[Short_Desc],$B13,Combined_Accounts[Account],"<>" & "discover")*-1 -> 155 | D13: =SUMIFS(Combined_Accounts[Amount],Combined_Accounts[Date],D$2,Combined_Accounts[Short_Desc],$B13,Combined_Accounts[Account],"discover") + SUMIFS(Combined_Accounts[Amount],Combined_Accounts[Date],D$2,Combined_Accounts[Short_Desc],$B13,Combined_Accounts[Account],"<>" & "discover")*-1 -> 155 | E13: =SUMIFS(Combined_Accounts[Amount],Combined_Accounts[Date],E$2,Combined_Accounts[Short_Desc],$B13,Combined_Accounts[Account],"discover") + SUMIFS(Combined_Accounts[Amount],Combined_Accounts[Date],E$2,Combined_Accounts[Short_Desc],$B13,Combined_Accounts[Account],"<>" & "discover")*-1 -> 155 | F13: =SUMIFS(Combined_Accounts[Amount],Combined_Accounts[Date],F$2,Combined_Accounts[Short_Desc],$B13,Combined_Accounts[Account],"discover") + SUMIFS(Combined_Accounts[Amount],Combined_Accounts[Date],F$2,Combined_Accounts[Short_Desc],$B13,Combined_Accounts[Account],"<>" & "discover")*-1 -> 155 | G13: =SUMIFS(Combined_Accounts[Amount],Combined_Accounts[Date],G$2,Combined_Accounts[Short_Desc],$B13,Combined_Accounts[Account],"discover") + SUMIFS(Combined_Accounts[Amount],Combined_Accounts[Date],G$2,Combined_Accounts[Short_Desc],$B13,Combined_Accounts[Account],"<>" & "discover")*-1 -> 155 | H13: =SUMIFS(Combined_Accounts[Amount],Combined_Accounts[Date],H$2,Combined_Accounts[Short_Desc],$B13,Combined_Accounts[Account],"discover") + SUMIFS(Combined_Accounts[Amount],Combined_Accounts[Date],H$2,Combined_Accounts[Short_Desc],$B13,Combined_Accounts[Account],"<>" & "discover")*-1 -> 634.69 | I13: =SUMIFS(Combined_Accounts[Amount],Combined_Accounts[Date],I$2,Combined_Accounts[Short_Desc],$B13,Combined_Accounts[Account],"discover") + SUMIFS(Combined_Accounts[Amount],Combined_Accounts[Date],I$2,Combined_Accounts[Short_Desc],$B13,Combined_Accounts[Account],"<>" & "discover")*-1 -> 0 | J13: =SUMIFS(Combined_Accounts[Amount],Combined_Accounts[Date],J$2,Combined_Accounts[Short_Desc],$B13,Combined_Accounts[Account],"discover") + SUMIFS(Combined_Accounts[Amount],Combined_Accounts[Date],J$2,Combined_Accounts[Short_Desc],$B13,Combined_Accounts[Account],"<>" & "discover")*-1 -> 0 | ... N13: =SUMIFS(Combined_Accounts[Amount],Combined_Accounts[Date],N$2,Combined_Accounts[Short_Desc],$B13,Combined_Accounts[Account],"discover") + SUMIFS(Combined_Accounts[Amount],Combined_Accounts[Date],N$2,Combined_Accounts[Short_Desc],$B13,Combined_Accounts[Account],"<>" & "discover")*-1 -> 0
B14: care_credit | C14: =SUMIFS(Combined_Accounts[Amount],Combined_Accounts[Date],C$2,Combined_Accounts[Short_Desc],$B14,Combined_Accounts[Account],"discover") + SUMIFS(Combined_Accounts[Amount],Combined_Accounts[Date],C$2,Combined_Accounts[Short_Desc],$B14,Combined_Accounts[Account],"<>" & "discover")*-1 -> 417.29 | D14: =SUMIFS(Combined_Accounts[Amount],Combined_Accounts[Date],D$2,Combined_Accounts[Short_Desc],$B14,Combined_Accounts[Account],"discover") + SUMIFS(Combined_Accounts[Amount],Combined_Accounts[Date],D$2,Combined_Accounts[Short_Desc],$B14,Combined_Accounts[Account],"<>" & "discover")*-1 -> 237.29 | E14: =SUMIFS(Combined_Accounts[Amount],Combined_Accounts[Date],E$2,Combined_Accounts[Short_Desc],$B14,Combined_Accounts[Account],"discover") + SUMIFS(Combined_Accounts[Amount],Combined_Accounts[Date],E$2,Combined_Accounts[Short_Desc],$B14,Combined_Accounts[Account],"<>" & "discover")*-1 -> 458.96 | F14: =SUMIFS(Combined_Accounts[Amount],Combined_Accounts[Date],F$2,Combined_Accounts[Short_Desc],$B14,Combined_Accounts[Account],"discover") + SUMIFS(Combined_Accounts[Amount],Combined_Accounts[Date],F$2,Combined_Accounts[Short_Desc],$B14,Combined_Accounts[Account],"<>" & "discover")*-1 -> 3000 | G14: =SUMIFS(Combined_Accounts[Amount],Combined_Accounts[Date],G$2,Combined_Accounts[Short_Desc],$B14,Combined_Accounts[Account],"discover") + SUMIFS(Combined_Accounts[Amount],Combined_Accounts[Date],G$2,Combined_Accounts[Short_Desc],$B14,Combined_Accounts[Account],"<>" & "discover")*-1 -> 458.96 | H14: =SUMIFS(Combined_Accounts[Amount],Combined_Accounts[Date],H$2,Combined_Accounts[Short_Desc],$B14,Combined_Accounts[Account],"discover") + SUMIFS(Combined_Accounts[Amount],Combined_Accounts[Date],H$2,Combined_Accounts[Short_Desc],$B14,Combined_Accounts[Account],"<>" & "discover")*-1 -> 460 | I14: =SUMIFS(Combined_Accounts[Amount],Combined_Accounts[Date],I$2,Combined_Accounts[Short_Desc],$B14,Combined_Accounts[Account],"discover") + SUMIFS(Combined_Accounts[Amount],Combined_Accounts[Date],I$2,Combined_Accounts[Short_Desc],$B14,Combined_Accounts[Account],"<>" & "discover")*-1 -> 460 | J14: =SUMIFS(Combined_Accounts[Amount],Combined_Accounts[Date],J$2,Combined_Accounts[Short_Desc],$B14,Combined_Accounts[Account],"discover") + SUMIFS(Combined_Accounts[Amount],Combined_Accounts[Date],J$2,Combined_Accounts[Short_Desc],$B14,Combined_Accounts[Account],"<>" & "discover")*-1 -> 460 | K14: 460 | L14: 460 | M14: 460 | N14: 460
B15: onepass | C15: =SUMIFS(Combined_Accounts[Amount],Combined_Accounts[Date],C$2,Combined_Accounts[Short_Desc],$B15,Combined_Accounts[Account],"discover") + SUMIFS(Combined_Accounts[Amount],Combined_Accounts[Date],C$2,Combined_Accounts[Short_Desc],$B15,Combined_Accounts[Account],"<>" & "discover")*-1 -> 273.6 | D15: =SUMIFS(Combined_Accounts[Amount],Combined_Accounts[Date],D$2,Combined_Accounts[Short_Desc],$B15,Combined_Accounts[Account],"discover") + SUMIFS(Combined_Accounts[Amount],Combined_Accounts[Date],D$2,Combined_Accounts[Short_Desc],$B15,Combined_Accounts[Account],"<>" & "discover")*-1 -> 273.6 | E15: =SUMIFS(Combined_Accounts[Amount],Combined_Accounts[Date],E$2,Combined_Accounts[Short_Desc],$B15,Combined_Accounts[Account],"discover") + SUMIFS(Combined_Accounts[Amount],Combined_Accounts[Date],E$2,Combined_Accounts[Short_Desc],$B15,Combined_Accounts[Account],"<>" & "discover")*-1 -> 273.6 | F15: =SUMIFS(Combined_Accounts[Amount],Combined_Accounts[Date],F$2,Combined_Accounts[Short_Desc],$B15,Combined_Accounts[Account],"discover") + SUMIFS(Combined_Accounts[Amount],Combined_Accounts[Date],F$2,Combined_Accounts[Short_Desc],$B15,Combined_Accounts[Account],"<>" & "discover")*-1 -> 273.6 | G15: =SUMIFS(Combined_Accounts[Amount],Combined_Accounts[Date],G$2,Combined_Accounts[Short_Desc],$B15,Combined_Accounts[Account],"discover") + SUMIFS(Combined_Accounts[Amount],Combined_Accounts[Date],G$2,Combined_Accounts[Short_Desc],$B15,Combined_Accounts[Account],"<>" & "discover")*-1 -> 273.6 | H15: =SUMIFS(Combined_Accounts[Amount],Combined_Accounts[Date],H$2,Combined_Accounts[Short_Desc],$B15,Combined_Accounts[Account],"discover") + SUMIFS(Combined_Accounts[Amount],Combined_Accounts[Date],H$2,Combined_Accounts[Short_Desc],$B15,Combined_Accounts[Account],"<>" & "discover")*-1 -> 273.6 | I15: =SUMIFS(Combined_Accounts[Amount],Combined_Accounts[Date],I$2,Combined_Accounts[Short_Desc],$B15,Combined_Accounts[Account],"discover") + SUMIFS(Combined_Accounts[Amount],Combined_Accounts[Date],I$2,Combined_Accounts[Short_Desc],$B15,Combined_Accounts[Account],"<>" & "discover")*-1 -> 273.6 | J15: =SUMIFS(Combined_Accounts[Amount],Combined_Accounts[Date],J$2,Combined_Accounts[Short_Desc],$B15,Combined_Accounts[Account],"discover") + SUMIFS(Combined_Accounts[Amount],Combined_Accounts[Date],J$2,Combined_Accounts[Short_Desc],$B15,Combined_Accounts[Account],"<>" & "discover")*-1 -> 273.6 | ... N15: =SUMIFS(Combined_Accounts[Amount],Combined_Accounts[Date],N$2,Combined_Accounts[Short_Desc],$B15,Combined_Accounts[Account],"discover") + SUMIFS(Combined_Accounts[Amount],Combined_Accounts[Date],N$2,Combined_Accounts[Short_Desc],$B15,Combined_Accounts[Account],"<>" & "discover")*-1 -> 273.6
B16: state_farm | C16: =SUMIFS(Combined_Accounts[Amount],Combined_Accounts[Date],C$2,Combined_Accounts[Short_Desc],$B16,Combined_Accounts[Account],"discover") + SUMIFS(Combined_Accounts[Amount],Combined_Accounts[Date],C$2,Combined_Accounts[Short_Desc],$B16,Combined_Accounts[Account],"<>" & "discover")*-1 -> 90.83 | D16: =SUMIFS(Combined_Accounts[Amount],Combined_Accounts[Date],D$2,Combined_Accounts[Short_Desc],$B16,Combined_Accounts[Account],"discover") + SUMIFS(Combined_Accounts[Amount],Combined_Accounts[Date],D$2,Combined_Accounts[Short_Desc],$B16,Combined_Accounts[Account],"<>" & "discover")*-1 -> 90.54 | E16: =SUMIFS(Combined_Accounts[Amount],Combined_Accounts[Date],E$2,Combined_Accounts[Short_Desc],$B16,Combined_Accounts[Account],"discover") + SUMIFS(Combined_Accounts[Amount],Combined_Accounts[Date],E$2,Combined_Accounts[Short_Desc],$B16,Combined_Accounts[Account],"<>" & "discover")*-1 -> 90.54 | F16: =SUMIFS(Combined_Accounts[Amount],Combined_Accounts[Date],F$2,Combined_Accounts[Short_Desc],$B16,Combined_Accounts[Account],"discover") + SUMIFS(Combined_Accounts[Amount],Combined_Accounts[Date],F$2,Combined_Accounts[Short_Desc],$B16,Combined_Accounts[Account],"<>" & "discover")*-1 -> 90.54 | G16: =SUMIFS(Combined_Accounts[Amount],Combined_Accounts[Date],G$2,Combined_Accounts[Short_Desc],$B16,Combined_Accounts[Account],"discover") + SUMIFS(Combined_Accounts[Amount],Combined_Accounts[Date],G$2,Combined_Accounts[Short_Desc],$B16,Combined_Accounts[Account],"<>" & "discover")*-1 -> 90.54 | H16: =SUMIFS(Combined_Accounts[Amount],Combined_Accounts[Date],H$2,Combined_Accounts[Short_Desc],$B16,Combined_Accounts[Account],"discover") + SUMIFS(Combined_Accounts[Amount],Combined_Accounts[Date],H$2,Combined_Accounts[Short_Desc],$B16,Combined_Accounts[Account],"<>" & "discover")*-1 -> 90.54 | I16: =SUMIFS(Combined_Accounts[Amount],Combined_Accounts[Date],I$2,Combined_Accounts[Short_Desc],$B16,Combined_Accounts[Account],"discover") + SUMIFS(Combined_Accounts[Amount],Combined_Accounts[Date],I$2,Combined_Accounts[Short_Desc],$B16,Combined_Accounts[Account],"<>" & "discover")*-1 -> 90.54 | J16: =SUMIFS(Combined_Accounts[Amount],Combined_Accounts[Date],J$2,Combined_Accounts[Short_Desc],$B16,Combined_Accounts[Account],"discover") + SUMIFS(Combined_Accounts[Amount],Combined_Accounts[Date],J$2,Combined_Accounts[Short_Desc],$B16,Combined_Accounts[Account],"<>" & "discover")*-1 -> 108.56 | K16: 108.56 | L16: 108.56 | M16: 108.56 | N16: 108.56
B17: cell_phone | C17: =SUMIFS(Combined_Accounts[Amount],Combined_Accounts[Date],C$2,Combined_Accounts[Short_Desc],$B17,Combined_Accounts[Account],"discover") + SUMIFS(Combined_Accounts[Amount],Combined_Accounts[Date],C$2,Combined_Accounts[Short_Desc],$B17,Combined_Accounts[Account],"<>" & "discover")*-1 -> 0 | D17: =SUMIFS(Combined_Accounts[Amount],Combined_Accounts[Date],D$2,Combined_Accounts[Short_Desc],$B17,Combined_Accounts[Account],"discover") + SUMIFS(Combined_Accounts[Amount],Combined_Accounts[Date],D$2,Combined_Accounts[Short_Desc],$B17,Combined_Accounts[Account],"<>" & "discover")*-1 -> 366.21 | E17: =SUMIFS(Combined_Accounts[Amount],Combined_Accounts[Date],E$2,Combined_Accounts[Short_Desc],$B17,Combined_Accounts[Account],"discover") + SUMIFS(Combined_Accounts[Amount],Combined_Accounts[Date],E$2,Combined_Accounts[Short_Desc],$B17,Combined_Accounts[Account],"<>" & "discover")*-1 -> 91.98 | F17: =SUMIFS(Combined_Accounts[Amount],Combined_Accounts[Date],F$2,Combined_Accounts[Short_Desc],$B17,Combined_Accounts[Account],"discover") + SUMIFS(Combined_Accounts[Amount],Combined_Accounts[Date],F$2,Combined_Accounts[Short_Desc],$B17,Combined_Accounts[Account],"<>" & "discover")*-1 -> 0 | G17: =SUMIFS(Combined_Accounts[Amount],Combined_Accounts[Date],G$2,Combined_Accounts[Short_Desc],$B17,Combined_Accounts[Account],"discover") + SUMIFS(Combined_Accounts[Amount],Combined_Accounts[Date],G$2,Combined_Accounts[Short_Desc],$B17,Combined_Accounts[Account],"<>" & "discover")*-1 -> 0 | H17: =SUMIFS(Combined_Accounts[Amount],Combined_Accounts[Date],H$2,Combined_Accounts[Short_Desc],$B17,Combined_Accounts[Account],"discover") + SUMIFS(Combined_Accounts[Amount],Combined_Accounts[Date],H$2,Combined_Accounts[Short_Desc],$B17,Combined_Accounts[Account],"<>" & "discover")*-1 -> 0 | I17: =SUMIFS(Combined_Accounts[Amount],Combined_Accounts[Date],I$2,Combined_Accounts[Short_Desc],$B17,Combined_Accounts[Account],"discover") + SUMIFS(Combined_Accounts[Amount],Combined_Accounts[Date],I$2,Combined_Accounts[Short_Desc],$B17,Combined_Accounts[Account],"<>" & "discover")*-1 -> 0 | J17: =SUMIFS(Combined_Accounts[Amount],Combined_Accounts[Date],J$2,Combined_Accounts[Short_Desc],$B17,Combined_Accounts[Account],"discover") + SUMIFS(Combined_Accounts[Amount],Combined_Accounts[Date],J$2,Combined_Accounts[Short_Desc],$B17,Combined_Accounts[Account],"<>" & "discover")*-1 -> 0 | K17: 65.83 | L17: 65.83 | M17: 65.83 | N17: 65.83
B18: student_loan | C18: =SUMIFS(Combined_Accounts[Amount],Combined_Accounts[Date],C$2,Combined_Accounts[Short_Desc],$B18,Combined_Accounts[Account],"discover") + SUMIFS(Combined_Accounts[Amount],Combined_Accounts[Date],C$2,Combined_Accounts[Short_Desc],$B18,Combined_Accounts[Account],"<>" & "discover")*-1 -> 426.16 | D18: =SUMIFS(Combined_Accounts[Amount],Combined_Accounts[Date],D$2,Combined_Accounts[Short_Desc],$B18,Combined_Accounts[Account],"discover") + SUMIFS(Combined_Accounts[Amount],Combined_Accounts[Date],D$2,Combined_Accounts[Short_Desc],$B18,Combined_Accounts[Account],"<>" & "discover")*-1 -> 442.73 | E18: =SUMIFS(Combined_Accounts[Amount],Combined_Accounts[Date],E$2,Combined_Accounts[Short_Desc],$B18,Combined_Accounts[Account],"discover") + SUMIFS(Combined_Accounts[Amount],Combined_Accounts[Date],E$2,Combined_Accounts[Short_Desc],$B18,Combined_Accounts[Account],"<>" & "discover")*-1 -> 442.73 | F18: =SUMIFS(Combined_Accounts[Amount],Combined_Accounts[Date],F$2,Combined_Accounts[Short_Desc],$B18,Combined_Accounts[Account],"discover") + SUMIFS(Combined_Accounts[Amount],Combined_Accounts[Date],F$2,Combined_Accounts[Short_Desc],$B18,Combined_Accounts[Account],"<>" & "discover")*-1 -> 442.73 | G18: =SUMIFS(Combined_Accounts[Amount],Combined_Accounts[Date],G$2,Combined_Accounts[Short_Desc],$B18,Combined_Accounts[Account],"discover") + SUMIFS(Combined_Accounts[Amount],Combined_Accounts[Date],G$2,Combined_Accounts[Short_Desc],$B18,Combined_Accounts[Account],"<>" & "discover")*-1 -> 442.73 | H18: =SUMIFS(Combined_Accounts[Amount],Combined_Accounts[Date],H$2,Combined_Accounts[Short_Desc],$B18,Combined_Accounts[Account],"discover") + SUMIFS(Combined_Accounts[Amount],Combined_Accounts[Date],H$2,Combined_Accounts[Short_Desc],$B18,Combined_Accounts[Account],"<>" & "discover")*-1 -> 442.73 | I18: =SUMIFS(Combined_Accounts[Amount],Combined_Accounts[Date],I$2,Combined_Accounts[Short_Desc],$B18,Combined_Accounts[Account],"discover") + SUMIFS(Combined_Accounts[Amount],Combined_Accounts[Date],I$2,Combined_Accounts[Short_Desc],$B18,Combined_Accounts[Account],"<>" & "discover")*-1 -> 442.73 | J18: =SUMIFS(Combined_Accounts[Amount],Combined_Accounts[Date],J$2,Combined_Accounts[Short_Desc],$B18,Combined_Accounts[Account],"discover") + SUMIFS(Combined_Accounts[Amount],Combined_Accounts[Date],J$2,Combined_Accounts[Short_Desc],$B18,Combined_Accounts[Account],"<>" & "discover")*-1 -> 442.73 | K18: 442.73 | L18: 442.73 | M18: 442.73 | N18: 442.73 | O18: =SUM(C18:N18) -> 5296.19 | P18: ='Loan Schedule'!B5-Summary!O18 -> 15473.5
B19: adobe | C19: =SUMIFS(Combined_Accounts[Amount],Combined_Accounts[Date],C$2,Combined_Accounts[Short_Desc],$B19,Combined_Accounts[Account],"discover") + SUMIFS(Combined_Accounts[Amount],Combined_Accounts[Date],C$2,Combined_Accounts[Short_Desc],$B19,Combined_Accounts[Account],"<>" & "discover")*-1 -> 29.99 | D19: =SUMIFS(Combined_Accounts[Amount],Combined_Accounts[Date],D$2,Combined_Accounts[Short_Desc],$B19,Combined_Accounts[Account],"discover") + SUMIFS(Combined_Accounts[Amount],Combined_Accounts[Date],D$2,Combined_Accounts[Short_Desc],$B19,Combined_Accounts[Account],"<>" & "discover")*-1 -> 29.99 | E19: =SUMIFS(Combined_Accounts[Amount],Combined_Accounts[Date],E$2,Combined_Accounts[Short_Desc],$B19,Combined_Accounts[Account],"discover") + SUMIFS(Combined_Accounts[Amount],Combined_Accounts[Date],E$2,Combined_Accounts[Short_Desc],$B19,Combined_Accounts[Account],"<>" & "discover")*-1 -> 29.99 | F19: =SUMIFS(Combined_Accounts[Amount],Combined_Accounts[Date],F$2,Combined_Accounts[Short_Desc],$B19,Combined_Accounts[Account],"discover") + SUMIFS(Combined_Accounts[Amount],Combined_Accounts[Date],F$2,Combined_Accounts[Short_Desc],$B19,Combined_Accounts[Account],"<>" & "discover")*-1 -> 29.99 | G19: =SUMIFS(Combined_Accounts[Amount],Combined_Accounts[Date],G$2,Combined_Accounts[Short_Desc],$B19,Combined_Accounts[Account],"discover") + SUMIFS(Combined_Accounts[Amount],Combined_Accounts[Date],G$2,Combined_Accounts[Short_Desc],$B19,Combined_Accounts[Account],"<>" & "discover")*-1 -> 29.99 | H19: =SUMIFS(Combined_Accounts[Amount],Combined_Accounts[Date],H$2,Combined_Accounts[Short_Desc],$B19,Combined_Accounts[Account],"discover") + SUMIFS(Combined_Accounts[Amount],Combined_Accounts[Date],H$2,Combined_Accounts[Short_Desc],$B19,Combined_Accounts[Account],"<>" & "discover")*-1 -> 29.99 | I19: =SUMIFS(Combined_Accounts[Amount],Combined_Accounts[Date],I$2,Combined_Accounts[Short_Desc],$B19,Combined_Accounts[Account],"discover") + SUMIFS(Combined_Accounts[Amount],Combined_Accounts[Date],I$2,Combined_Accounts[Short_Desc],$B19,Combined_Accounts[Account],"<>" & "discover")*-1 -> 29.99 | J19: =SUMIFS(Combined_Accounts[Amount],Combined_Accounts[Date],J$2,Combined_Accounts[Short_Desc],$B19,Combined_Accounts[Account],"discover") + SUMIFS(Combined_Accounts[Amount],Combined_Accounts[Date],J$2,Combined_Accounts[Short_Desc],$B19,Combined_Accounts[Account],"<>" & "discover")*-1 -> 29.99 | K19: 29.99 | L19: 29.99 | M19: 29.99 | N19: 29.99
B20: apple_care | C20: =SUMIFS(Combined_Accounts[Amount],Combined_Accounts[Date],C$2,Combined_Accounts[Short_Desc],$B20,Combined_Accounts[Account],"discover") + SUMIFS(Combined_Accounts[Amount],Combined_Accounts[Date],C$2,Combined_Accounts[Short_Desc],$B20,Combined_Accounts[Account],"<>" & "discover")*-1 -> 9.99 | D20: =SUMIFS(Combined_Accounts[Amount],Combined_Accounts[Date],D$2,Combined_Accounts[Short_Desc],$B20,Combined_Accounts[Account],"discover") + SUMIFS(Combined_Accounts[Amount],Combined_Accounts[Date],D$2,Combined_Accounts[Short_Desc],$B20,Combined_Accounts[Account],"<>" & "discover")*-1 -> 9.99 | E20: =SUMIFS(Combined_Accounts[Amount],Combined_Accounts[Date],E$2,Combined_Accounts[Short_Desc],$B20,Combined_Accounts[Account],"discover") + SUMIFS(Combined_Accounts[Amount],Combined_Accounts[Date],E$2,Combined_Accounts[Short_Desc],$B20,Combined_Accounts[Account],"<>" & "discover")*-1 -> 9.99 | F20: =SUMIFS(Combined_Accounts[Amount],Combined_Accounts[Date],F$2,Combined_Accounts[Short_Desc],$B20,Combined_Accounts[Account],"discover") + SUMIFS(Combined_Accounts[Amount],Combined_Accounts[Date],F$2,Combined_Accounts[Short_Desc],$B20,Combined_Accounts[Account],"<>" & "discover")*-1 -> 9.99 | G20: =SUMIFS(Combined_Accounts[Amount],Combined_Accounts[Date],G$2,Combined_Accounts[Short_Desc],$B20,Combined_Accounts[Account],"discover") + SUMIFS(Combined_Accounts[Amount],Combined_Accounts[Date],G$2,Combined_Accounts[Short_Desc],$B20,Combined_Accounts[Account],"<>" & "discover")*-1 -> 0 | H20: =SUMIFS(Combined_Accounts[Amount],Combined_Accounts[Date],H$2,Combined_Accounts[Short_Desc],$B20,Combined_Accounts[Account],"discover") + SUMIFS(Combined_Accounts[Amount],Combined_Accounts[Date],H$2,Combined_Accounts[Short_Desc],$B20,Combined_Accounts[Account],"<>" & "discover")*-1 -> 0 | I20: =SUMIFS(Combined_Accounts[Amount],Combined_Accounts[Date],I$2,Combined_Accounts[Short_Desc],$B20,Combined_Accounts[Account],"discover") + SUMIFS(Combined_Accounts[Amount],Combined_Accounts[Date],I$2,Combined_Accounts[Short_Desc],$B20,Combined_Accounts[Account],"<>" & "discover")*-1 -> 0 | J20: =SUMIFS(Combined_Accounts[Amount],Combined_Accounts[Date],J$2,Combined_Accounts[Short_Desc],$B20,Combined_Accounts[Account],"discover") + SUMIFS(Combined_Accounts[Amount],Combined_Accounts[Date],J$2,Combined_Accounts[Short_Desc],$B20,Combined_Accounts[Account],"<>" & "discover")*-1 -> 0 | ... N20: =SUMIFS(Combined_Accounts[Amount],Combined_Accounts[Date],N$2,Combined_Accounts[Short_Desc],$B20,Combined_Accounts[Account],"discover") + SUMIFS(Combined_Accounts[Amount],Combined_Accounts[Date],N$2,Combined_Accounts[Short_Desc],$B20,Combined_Accounts[Account],"<>" & "discover")*-1 -> 0
B21: breaking_points | C21: =SUMIFS(Combined_Accounts[Amount],Combined_Accounts[Date],C$2,Combined_Accounts[Short_Desc],$B21,Combined_Accounts[Account],"discover") + SUMIFS(Combined_Accounts[Amount],Combined_Accounts[Date],C$2,Combined_Accounts[Short_Desc],$B21,Combined_Accounts[Account],"<>" & "discover")*-1 -> 10 | D21: =SUMIFS(Combined_Accounts[Amount],Combined_Accounts[Date],D$2,Combined_Accounts[Short_Desc],$B21,Combined_Accounts[Account],"discover") + SUMIFS(Combined_Accounts[Amount],Combined_Accounts[Date],D$2,Combined_Accounts[Short_Desc],$B21,Combined_Accounts[Account],"<>" & "discover")*-1 -> 10 | E21: =SUMIFS(Combined_Accounts[Amount],Combined_Accounts[Date],E$2,Combined_Accounts[Short_Desc],$B21,Combined_Accounts[Account],"discover") + SUMIFS(Combined_Accounts[Amount],Combined_Accounts[Date],E$2,Combined_Accounts[Short_Desc],$B21,Combined_Accounts[Account],"<>" & "discover")*-1 -> 10 | F21: =SUMIFS(Combined_Accounts[Amount],Combined_Accounts[Date],F$2,Combined_Accounts[Short_Desc],$B21,Combined_Accounts[Account],"discover") + SUMIFS(Combined_Accounts[Amount],Combined_Accounts[Date],F$2,Combined_Accounts[Short_Desc],$B21,Combined_Accounts[Account],"<>" & "discover")*-1 -> 10 | G21: =SUMIFS(Combined_Accounts[Amount],Combined_Accounts[Date],G$2,Combined_Accounts[Short_Desc],$B21,Combined_Accounts[Account],"discover") + SUMIFS(Combined_Accounts[Amount],Combined_Accounts[Date],G$2,Combined_Accounts[Short_Desc],$B21,Combined_Accounts[Account],"<>" & "discover")*-1 -> 10 | H21: =SUMIFS(Combined_Accounts[Amount],Combined_Accounts[Date],H$2,Combined_Accounts[Short_Desc],$B21,Combined_Accounts[Account],"discover") + SUMIFS(Combined_Accounts[Amount],Combined_Accounts[Date],H$2,Combined_Accounts[Short_Desc],$B21,Combined_Accounts[Account],"<>" & "discover")*-1 -> 10 | I21: =SUMIFS(Combined_Accounts[Amount],Combined_Accounts[Date],I$2,Combined_Accounts[Short_Desc],$B21,Combined_Accounts[Account],"discover") + SUMIFS(Combined_Accounts[Amount],Combined_Accounts[Date],I$2,Combined_Accounts[Short_Desc],$B21,Combined_Accounts[Account],"<>" & "discover")*-1 -> 10 | J21: =SUMIFS(Combined_Accounts[Amount],Combined_Accounts[Date],J$2,Combined_Accounts[Short_Desc],$B21,Combined_Accounts[Account],"discover") + SUMIFS(Combined_Accounts[Amount],Combined_Accounts[Date],J$2,Combined_Accounts[Short_Desc],$B21,Combined_Accounts[Account],"<>" & "discover")*-1 -> 10 | ... N21: =SUMIFS(Combined_Accounts[Amount],Combined_Accounts[Date],N$2,Combined_Accounts[Short_Desc],$B21,Combined_Accounts[Account],"discover") + SUMIFS(Combined_Accounts[Amount],Combined_Accounts[Date],N$2,Combined_Accounts[Short_Desc],$B21,Combined_Accounts[Account],"<>" & "discover")*-1 -> 10
B22: spotify | C22: =SUMIFS(Combined_Accounts[Amount],Combined_Accounts[Date],C$2,Combined_Accounts[Short_Desc],$B22,Combined_Accounts[Account],"discover") + SUMIFS(Combined_Accounts[Amount],Combined_Accounts[Date],C$2,Combined_Accounts[Short_Desc],$B22,Combined_Accounts[Account],"<>" & "discover")*-1 -> 5.99 | D22: =SUMIFS(Combined_Accounts[Amount],Combined_Accounts[Date],D$2,Combined_Accounts[Short_Desc],$B22,Combined_Accounts[Account],"discover") + SUMIFS(Combined_Accounts[Amount],Combined_Accounts[Date],D$2,Combined_Accounts[Short_Desc],$B22,Combined_Accounts[Account],"<>" & "discover")*-1 -> 5.99 | E22: =SUMIFS(Combined_Accounts[Amount],Combined_Accounts[Date],E$2,Combined_Accounts[Short_Desc],$B22,Combined_Accounts[Account],"discover") + SUMIFS(Combined_Accounts[Amount],Combined_Accounts[Date],E$2,Combined_Accounts[Short_Desc],$B22,Combined_Accounts[Account],"<>" & "discover")*-1 -> 5.99 | F22: =SUMIFS(Combined_Accounts[Amount],Combined_Accounts[Date],F$2,Combined_Accounts[Short_Desc],$B22,Combined_Accounts[Account],"discover") + SUMIFS(Combined_Accounts[Amount],Combined_Accounts[Date],F$2,Combined_Accounts[Short_Desc],$B22,Combined_Accounts[Account],"<>" & "discover")*-1 -> 5.99 | G22: =SUMIFS(Combined_Accounts[Amount],Combined_Accounts[Date],G$2,Combined_Accounts[Short_Desc],$B22,Combined_Accounts[Account],"discover") + SUMIFS(Combined_Accounts[Amount],Combined_Accounts[Date],G$2,Combined_Accounts[Short_Desc],$B22,Combined_Accounts[Account],"<>" & "discover")*-1 -> 5.99 | H22: =SUMIFS(Combined_Accounts[Amount],Combined_Accounts[Date],H$2,Combined_Accounts[Short_Desc],$B22,Combined_Accounts[Account],"discover") + SUMIFS(Combined_Accounts[Amount],Combined_Accounts[Date],H$2,Combined_Accounts[Short_Desc],$B22,Combined_Accounts[Account],"<>" & "discover")*-1 -> 5.99 | I22: =SUMIFS(Combined_Accounts[Amount],Combined_Accounts[Date],I$2,Combined_Accounts[Short_Desc],$B22,Combined_Accounts[Account],"discover") + SUMIFS(Combined_Accounts[Amount],Combined_Accounts[Date],I$2,Combined_Accounts[Short_Desc],$B22,Combined_Accounts[Account],"<>" & "discover")*-1 -> 5.99 | J22: =SUMIFS(Combined_Accounts[Amount],Combined_Accounts[Date],J$2,Combined_Accounts[Short_Desc],$B22,Combined_Accounts[Account],"discover") + SUMIFS(Combined_Accounts[Amount],Combined_Accounts[Date],J$2,Combined_Accounts[Short_Desc],$B22,Combined_Accounts[Account],"<>" & "discover")*-1 -> 5.99 | ... N22: =SUMIFS(Combined_Accounts[Amount],Combined_Accounts[Date],N$2,Combined_Accounts[Short_Desc],$B22,Combined_Accounts[Account],"discover") + SUMIFS(Combined_Accounts[Amount],Combined_Accounts[Date],N$2,Combined_Accounts[Short_Desc],$B22,Combined_Accounts[Account],"<>" & "discover")*-1 -> 11.99
B23: onlyfans | C23: =SUMIFS(Combined_Accounts[Amount],Combined_Accounts[Date],C$2,Combined_Accounts[Short_Desc],$B23,Combined_Accounts[Account],"discover") + SUMIFS(Combined_Accounts[Amount],Combined_Accounts[Date],C$2,Combined_Accounts[Short_Desc],$B23,Combined_Accounts[Account],"<>" & "discover")*-1 -> 63.31 | D23: =SUMIFS(Combined_Accounts[Amount],Combined_Accounts[Date],D$2,Combined_Accounts[Short_Desc],$B23,Combined_Accounts[Account],"discover") + SUMIFS(Combined_Accounts[Amount],Combined_Accounts[Date],D$2,Combined_Accounts[Short_Desc],$B23,Combined_Accounts[Account],"<>" & "discover")*-1 -> 29.98 | E23: =SUMIFS(Combined_Accounts[Amount],Combined_Accounts[Date],E$2,Combined_Accounts[Short_Desc],$B23,Combined_Accounts[Account],"discover") + SUMIFS(Combined_Accounts[Amount],Combined_Accounts[Date],E$2,Combined_Accounts[Short_Desc],$B23,Combined_Accounts[Account],"<>" & "discover")*-1 -> 142.37 | F23: =SUMIFS(Combined_Accounts[Amount],Combined_Accounts[Date],F$2,Combined_Accounts[Short_Desc],$B23,Combined_Accounts[Account],"discover") + SUMIFS(Combined_Accounts[Amount],Combined_Accounts[Date],F$2,Combined_Accounts[Short_Desc],$B23,Combined_Accounts[Account],"<>" & "discover")*-1 -> 158.02 | G23: =SUMIFS(Combined_Accounts[Amount],Combined_Accounts[Date],G$2,Combined_Accounts[Short_Desc],$B23,Combined_Accounts[Account],"discover") + SUMIFS(Combined_Accounts[Amount],Combined_Accounts[Date],G$2,Combined_Accounts[Short_Desc],$B23,Combined_Accounts[Account],"<>" & "discover")*-1 -> 102.51 | H23: =SUMIFS(Combined_Accounts[Amount],Combined_Accounts[Date],H$2,Combined_Accounts[Short_Desc],$B23,Combined_Accounts[Account],"discover") + SUMIFS(Combined_Accounts[Amount],Combined_Accounts[Date],H$2,Combined_Accounts[Short_Desc],$B23,Combined_Accounts[Account],"<>" & "discover")*-1 -> 46.37 | I23: =SUMIFS(Combined_Accounts[Amount],Combined_Accounts[Date],I$2,Combined_Accounts[Short_Desc],$B23,Combined_Accounts[Account],"discover") + SUMIFS(Combined_Accounts[Amount],Combined_Accounts[Date],I$2,Combined_Accounts[Short_Desc],$B23,Combined_Accounts[Account],"<>" & "discover")*-1 -> 47.99 | J23: =SUMIFS(Combined_Accounts[Amount],Combined_Accounts[Date],J$2,Combined_Accounts[Short_Desc],$B23,Combined_Accounts[Account],"discover") + SUMIFS(Combined_Accounts[Amount],Combined_Accounts[Date],J$2,Combined_Accounts[Short_Desc],$B23,Combined_Accounts[Account],"<>" & "discover")*-1 -> 98.99 | ... N23: =SUMIFS(Combined_Accounts[Amount],Combined_Accounts[Date],N$2,Combined_Accounts[Short_Desc],$B23,Combined_Accounts[Account],"discover") + SUMIFS(Combined_Accounts[Amount],Combined_Accounts[Date],N$2,Combined_Accounts[Short_Desc],$B23,Combined_Accounts[Account],"<>" & "discover")*-1 -> 83.65
B24: Other | C24: {=SUMPRODUCT( --(Data!$J:$J = Summary!C$10), --IF(ISNUMBER(MATCH(Data!$G:$G, $B$11:$B$23, 0)),0,1), --IF(ISNUMBER(MATCH(Data!$G:$G, Categories!$A:$A, 0)),0,1), --IF(ISNUMBER(MATCH(Data!$G:$G, Categories!$E:$E, 0)),0,1), --IF(ISNUMBER(MATCH(Data!$G:$G, Categories!$G:$G, 0)),0,1), --IF(ISNUMBER(MATCH(Data!$G:$G, Categories!$C:$C, 0)),1,0), --IF(ISNUMBER(MATCH(Data!$O:$O, {"wells_fargo_checking","sofi_savings","sofi_checking"}, 0)),-1,1), IFERROR(Data!$E:$E, 0) )} -> 1361.26 | D24: {=SUMPRODUCT( --(Data!$J:$J = Summary!D$10), --IF(ISNUMBER(MATCH(Data!$G:$G, $B$11:$B$23, 0)),0,1), --IF(ISNUMBER(MATCH(Data!$G:$G, Categories!$A:$A, 0)),0,1), --IF(ISNUMBER(MATCH(Data!$G:$G, Categories!$E:$E, 0)),0,1), --IF(ISNUMBER(MATCH(Data!$G:$G, Categories!$G:$G, 0)),0,1), --IF(ISNUMBER(MATCH(Data!$G:$G, Categories!$C:$C, 0)),1,0), --IF(ISNUMBER(MATCH(Data!$O:$O, {"wells_fargo_checking","sofi_savings","sofi_checking"}, 0)),-1,1), IFERROR(Data!$E:$E, 0) )} -> 482.95 | E24: {=SUMPRODUCT( --(Data!$J:$J = Summary!E$10), --IF(ISNUMBER(MATCH(Data!$G:$G, $B$11:$B$23, 0)),0,1), --IF(ISNUMBER(MATCH(Data!$G:$G, Categories!$A:$A, 0)),0,1), --IF(ISNUMBER(MATCH(Data!$G:$G, Categories!$E:$E, 0)),0,1), --IF(ISNUMBER(MATCH(Data!$G:$G, Categories!$G:$G, 0)),0,1), --IF(ISNUMBER(MATCH(Data!$G:$G, Categories!$C:$C, 0)),1,0), --IF(ISNUMBER(MATCH(Data!$O:$O, {"wells_fargo_checking","sofi_savings","sofi_checking"}, 0)),-1,1), IFERROR(Data!$E:$E, 0) )} -> 344.69 | F24: {=SUMPRODUCT( --(Data!$J:$J = Summary!F$10), --IF(ISNUMBER(MATCH(Data!$G:$G, $B$11:$B$23, 0)),0,1), --IF(ISNUMBER(MATCH(Data!$G:$G, Categories!$A:$A, 0)),0,1), --IF(ISNUMBER(MATCH(Data!$G:$G, Categories!$E:$E, 0)),0,1), --IF(ISNUMBER(MATCH(Data!$G:$G, Categories!$G:$G, 0)),0,1), --IF(ISNUMBER(MATCH(Data!$G:$G, Categories!$C:$C, 0)),1,0), --IF(ISNUMBER(MATCH(Data!$O:$O, {"wells_fargo_checking","sofi_savings","sofi_checking"}, 0)),-1,1), IFERROR(Data!$E:$E, 0) )} -> 460.63 | G24: {=SUMPRODUCT( --(Data!$J:$J = Summary!G$10), --IF(ISNUMBER(MATCH(Data!$G:$G, $B$11:$B$23, 0)),0,1), --IF(ISNUMBER(MATCH(Data!$G:$G, Categories!$A:$A, 0)),0,1), --IF(ISNUMBER(MATCH(Data!$G:$G, Categories!$E:$E, 0)),0,1), --IF(ISNUMBER(MATCH(Data!$G:$G, Categories!$G:$G, 0)),0,1), --IF(ISNUMBER(MATCH(Data!$G:$G, Categories!$C:$C, 0)),1,0), --IF(ISNUMBER(MATCH(Data!$O:$O, {"wells_fargo_checking","sofi_savings","sofi_checking"}, 0)),-1,1), IFERROR(Data!$E:$E, 0) )} -> 317.41 | H24: {=SUMPRODUCT( --(Data!$J:$J = Summary!H$10), --IF(ISNUMBER(MATCH(Data!$G:$G, $B$11:$B$23, 0)),0,1), --IF(ISNUMBER(MATCH(Data!$G:$G, Categories!$A:$A, 0)),0,1), --IF(ISNUMBER(MATCH(Data!$G:$G, Categories!$E:$E, 0)),0,1), --IF(ISNUMBER(MATCH(Data!$G:$G, Categories!$G:$G, 0)),0,1), --IF(ISNUMBER(MATCH(Data!$G:$G, Categories!$C:$C, 0)),1,0), --IF(ISNUMBER(MATCH(Data!$O:$O, {"wells_fargo_checking","sofi_savings","sofi_checking"}, 0)),-1,1), IFERROR(Data!$E:$E, 0) )} -> 297.37 | I24: {=SUMPRODUCT( --(Data!$J:$J = Summary!I$10), --IF(ISNUMBER(MATCH(Data!$G:$G, $B$11:$B$23, 0)),0,1), --IF(ISNUMBER(MATCH(Data!$G:$G, Categories!$A:$A, 0)),0,1), --IF(ISNUMBER(MATCH(Data!$G:$G, Categories!$E:$E, 0)),0,1), --IF(ISNUMBER(MATCH(Data!$G:$G, Categories!$G:$G, 0)),0,1), --IF(ISNUMBER(MATCH(Data!$G:$G, Categories!$C:$C, 0)),1,0), --IF(ISNUMBER(MATCH(Data!$O:$O, {"wells_fargo_checking","sofi_savings","sofi_checking"}, 0)),-1,1), IFERROR(Data!$E:$E, 0) )} -> 150.25 | J24: {=SUMPRODUCT( --(Data!$J:$J = Summary!J$10), --IF(ISNUMBER(MATCH(Data!$G:$G, $B$11:$B$23, 0)),0,1), --IF(ISNUMBER(MATCH(Data!$G:$G, Categories!$A:$A, 0)),0,1), --IF(ISNUMBER(MATCH(Data!$G:$G, Categories!$E:$E, 0)),0,1), --IF(ISNUMBER(MATCH(Data!$G:$G, Categories!$G:$G, 0)),0,1), --IF(ISNUMBER(MATCH(Data!$G:$G, Categories!$C:$C, 0)),1,0), --IF(ISNUMBER(MATCH(Data!$O:$O, {"wells_fargo_checking","sofi_savings","sofi_checking"}, 0)),-1,1), IFERROR(Data!$E:$E, 0) )} -> 2091.5 | ... N24: {=SUMPRODUCT( --(Data!$J:$J = Summary!N$10), --IF(ISNUMBER(MATCH(Data!$G:$G, $B$11:$B$23, 0)),0,1), --IF(ISNUMBER(MATCH(Data!$G:$G, Categories!$A:$A, 0)),0,1), --IF(ISNUMBER(MATCH(Data!$G:$G, Categories!$E:$E, 0)),0,1), --IF(ISNUMBER(MATCH(Data!$G:$G, Categories!$G:$G, 0)),0,1), --IF(ISNUMBER(MATCH(Data!$G:$G, Categories!$C:$C, 0)),1,0), --IF(ISNUMBER(MATCH(Data!$O:$O, {"wells_fargo_checking","sofi_savings","sofi_checking"}, 0)),-1,1), IFERROR(Data!$E:$E, 0) )} -> 271.41
B25: Total | C25: =SUM(C11:C24) -> 4646.82 | D25: =SUM(D11:D24) -> 8191.68 | E25: =SUM(E11:E24) -> 5332.96 | F25: =SUM(F11:F24) -> 4636.49 | G25: =SUM(G11:G24) -> 1886.73 | H25: =SUM(H11:H24) -> 2291.28 | I25: =SUM(I11:I24) -> 1511.09 | J25: =SUM(J11:J24) -> 3521.36 | ... N25: =SUM(N11:N24) -> 3391.5
B27: Variable Expenses | C27: 45292 | D27: =EOMONTH(C27,0)+1 -> 45323 | E27: =EOMONTH(D27,0)+1 -> 45352 | F27: =EOMONTH(E27,0)+1 -> 45383 | G27: =EOMONTH(F27,0)+1 -> 45413 | H27: =EOMONTH(G27,0)+1 -> 45444 | I27: =EOMONTH(H27,0)+1 -> 45474 | J27: =EOMONTH(I27,0)+1 -> 45505 | K27: =EOMONTH(J27,0)+1 -> 45536 | ... N27: =EOMONTH(M27,0)+1 -> 45627
B28: family | C28: =SUMIFS(Combined_Accounts[Amount],Combined_Accounts[Date],C$2,Combined_Accounts[Short_Desc],$B28, Combined_Accounts[Account],"discover") +SUMIFS(Combined_Accounts[Amount],Combined_Accounts[Date],C$2,Combined_Accounts[Short_Desc],$B28)*-1 -> -250 | D28: =SUMIFS(Combined_Accounts[Amount],Combined_Accounts[Date],D$2,Combined_Accounts[Short_Desc],$B28, Combined_Accounts[Account],"discover") +SUMIFS(Combined_Accounts[Amount],Combined_Accounts[Date],D$2,Combined_Accounts[Short_Desc],$B28)*-1 -> -50 | E28: =SUMIFS(Combined_Accounts[Amount],Combined_Accounts[Date],E$2,Combined_Accounts[Short_Desc],$B28, Combined_Accounts[Account],"discover") +SUMIFS(Combined_Accounts[Amount],Combined_Accounts[Date],E$2,Combined_Accounts[Short_Desc],$B28)*-1 -> 0 | F28: =SUMIFS(Combined_Accounts[Amount],Combined_Accounts[Date],F$2,Combined_Accounts[Short_Desc],$B28, Combined_Accounts[Account],"discover") +SUMIFS(Combined_Accounts[Amount],Combined_Accounts[Date],F$2,Combined_Accounts[Short_Desc],$B28)*-1 -> 2600 | G28: =SUMIFS(Combined_Accounts[Amount],Combined_Accounts[Date],G$2,Combined_Accounts[Short_Desc],$B28, Combined_Accounts[Account],"discover") +SUMIFS(Combined_Accounts[Amount],Combined_Accounts[Date],G$2,Combined_Accounts[Short_Desc],$B28)*-1 -> -200 | H28: =SUMIFS(Combined_Accounts[Amount],Combined_Accounts[Date],H$2,Combined_Accounts[Short_Desc],$B28, Combined_Accounts[Account],"discover") +SUMIFS(Combined_Accounts[Amount],Combined_Accounts[Date],H$2,Combined_Accounts[Short_Desc],$B28)*-1 -> 0 | I28: =SUMIFS(Combined_Accounts[Amount],Combined_Accounts[Date],I$2,Combined_Accounts[Short_Desc],$B28, Combined_Accounts[Account],"discover") +SUMIFS(Combined_Accounts[Amount],Combined_Accounts[Date],I$2,Combined_Accounts[Short_Desc],$B28)*-1 -> 0 | J28: =SUMIFS(Combined_Accounts[Amount],Combined_Accounts[Date],J$2,Combined_Accounts[Short_Desc],$B28, Combined_Accounts[Account],"discover") +SUMIFS(Combined_Accounts[Amount],Combined_Accounts[Date],J$2,Combined_Accounts[Short_Desc],$B28)*-1 -> 50 | ... N28: =SUMIFS(Combined_Accounts[Amount],Combined_Accounts[Date],N$2,Combined_Accounts[Short_Desc],$B28, Combined_Accounts[Account],"discover") +SUMIFS(Combined_Accounts[Amount],Combined_Accounts[Date],N$2,Combined_Accounts[Short_Desc],$B28)*-1 -> 0 | O28: =SUM(C28:N28) -> 2640
