Workbook

Sheet June Plan
A1: Sean Account Start | B1: 919.69 | C1: =750 -> 750
A2: Vincent Principal | B2: 18404.81 | C2: =SUM(Vincent!$D:$D) -> 14427.18 | D2: 16 | E2: =C2/D2 -> 901.69875 | F2: =SUM(J19:AI19) -> 9016.9875
A3: Lasik | C3: =Care_Credit!D26 -> 5695 | D3: 24 | E3: =C3/D3 -> 237.29167
A4: Student Loan | C4: 22430.56 | D4: =C4/E4 -> 64.62276 | E4: 347.1 | J4: 2732.7
C5: 5765.25 | D5: 0.034 | J5: 482.24
C6: 4868.38 | D6: 0.034 | J6: =SUM(J4:J5) -> 3214.94
C7: 11796.93 | D7: 0.0541
M8: Milestone 1 | Y8: Milestone 2
A10: Pay Date | B10: 45090 | C10: =B10+14 -> 45104 | D10: =C10+14 -> 45118 | E10: =D10+14 -> 45132 | F10: =E10+14 -> 45146 | G10: =F10+14 -> 45160 | H10: =G10+14 -> 45174 | I10: =H10+14 -> 45188 | J10: =I10+14 -> 45202 | ... AI10: =AH10+14 -> 45552
A11: Sofi | B11: 2258.37 | C11: =B11 -> 2258.37 | D11: =C11 -> 2258.37 | E11: =D11 -> 2258.37 | F11: =E11 -> 2258.37 | G11: =F11 -> 2258.37 | H11: =G11 -> 2258.37 | I11: 2732.7 | J11: 2732.7 | K11: 2732.7 | L11: 2732.7 | M11: 2732.7 | N11: 2732.7 | O11: 2732.7 | P11: 2732.7 | Q11: 2732.7 | R11: 2732.7 | S11: 2732.7 | T11: 2732.7 | U11: 2732.7 | V11: 2732.7 | W11: 2732.7 | X11: 2732.7 | Y11: 2732.7 | Z11: 2732.7 | AA11: 2732.7 | AB11: 2732.7 | AC11: 2732.7 | AD11: 2732.7 | AE11: 2732.7 | AF11: 2732.7 | AG11: 2732.7 | AH11: 2732.7 | AI11: 2732.7
A12: Wells Fargo | B12: 398.53 | C12: 398.53 | D12: 398.53 | E12: 398.53 | F12: 398.53 | G12: 398.53 | H12: 398.53 | I12: 482.24 | J12: 482.24 | K12: 482.24 | L12: 482.24 | M12: 482.24 | N12: 482.24 | O12: 482.24 | P12: 482.24 | Q12: 482.24 | R12: 482.24 | S12: 482.24 | T12: 482.24 | U12: 482.24 | V12: 482.24 | W12: 482.24 | X12: 482.24 | Y12: 482.24 | Z12: 482.24 | AA12: 482.24 | AB12: 482.24 | AC12: 482.24 | AD12: 482.24 | AE12: 482.24 | AF12: 482.24 | AG12: 482.24 | AH12: 482.24 | AI12: 482.24
B13: 2656.9 | C13: 2656.9 | D13: 2656.9 | E13: 2656.9 | F13: 2656.91 | G13: 2656.89 | H13: 2656.91 | I13: =SUM(I11:I12) -> 3214.94 | J13: =SUM(J11:J12) -> 3214.94 | K13: =SUM(K11:K12) -> 3214.94 | L13: =SUM(L11:L12) -> 3214.94 | M13: =SUM(M11:M12) -> 3214.94 | N13: =SUM(N11:N12) -> 3214.94 | O13: =SUM(O11:O12) -> 3214.94 | P13: =SUM(P11:P12) -> 3214.94 | ... AI13: =SUM(AI11:AI12) -> 3214.94
A15: Prev balance | B15: =B1 -> 919.69 | C15: =B32 -> 319.41722 | D15: =C32 -> 2068.8944 | E15: =D32 -> 1195.9957 | F15: =E32 -> 2701.1969 | G15: =F32 -> 2068.8082 | H15: =G32 -> 2804.1994 | I15: =H32 -> 1770.0807 | J15: =I32 -> 3681.6003 | ... AI15: =AH32 -> 35775.873
B17: TRUE | C17: TRUE | D17: TRUE | E17: TRUE | F17: TRUE | G17: TRUE | H17: TRUE | I17: TRUE | J17: TRUE | K17: TRUE | L17: TRUE | M17: TRUE | N17: TRUE | O17: TRUE | P17: TRUE | Q17: TRUE | R17: TRUE | S17: FALSE
B18: =EOMONTH(B10,-1)+1 -> 45078 | D18: =EOMONTH(D10,-1)+1 -> 45108 | F18: =EOMONTH(F10,-1)+1 -> 45139 | H18: =EOMONTH(H10,-1)+1 -> 45170 | J18: =EOMONTH(J10,-1)+1 -> 45200 | M18: =EOMONTH(M10,-1)+1 -> 45231 | O18: =EOMONTH(O10,-1)+1 -> 45261 | Q18: =EOMONTH(Q10,-1)+1 -> 45292 | S18: =EOMONTH(S10,-1)+1 -> 45323 | U18: =EOMONTH(U10,-1)+1 -> 45352 | W18: =EOMONTH(W10,-1)+1 -> 45383 | Z18: =EOMONTH(Z10,-1)+1 -> 45413 | AB18: =EOMONTH(AB10,-1)+1 -> 45444 | AD18: =EOMONTH(AD10,-1)+1 -> 45474 | AF18: =EOMONTH(AF10,-1)+1 -> 45505 | AH18: =EOMONTH(AH10,-1)+1 -> 45536
A19: Vincent Payment | B19: 907.42278 | C19: 907.42278 | D19: =$E$2 -> 901.69875 | E19: =$E$2 -> 901.69875 | F19: =$E$2 -> 901.69875 | G19: =$E$2 -> 901.69875 | H19: =$E$2 -> 901.69875 | I19: =$E$2 -> 901.69875 | J19: =$E$2 -> 901.69875 | K19: =$E$2 -> 901.69875 | ... S19: =$E$2 -> 901.69875 | T19: 0 | U19: 0 | V19: 0 | W19: 0 | X19: 0 | Y19: 0 | Z19: 0 | AA19: 0 | AB19: 0 | AC19: 0 | AD19: 0 | AE19: 0 | AF19: 0 | AG19: 0 | AH19: 0 | AI19: 0
A20: Lasik Payment | D20: 428 | E20: 250 | H20: 237.29 | I20: =$E$3 -> 237.29167 | J20: =$E$3 -> 237.29167 | K20: =$E$3 -> 237.29167 | L20: =$E$3 -> 237.29167 | M20: =$E$3 -> 237.29167 | N20: =$E$3 -> 237.29167 | O20: =$E$3 -> 237.29167 | P20: =$E$3 -> 237.29167 | ... AA20: =$E$3 -> 237.29167 | AB20: 0 | AC20: 0 | AD20: 0 | AE20: 0 | AF20: 0 | AG20: 0 | AH20: 0 | AI20: 0
A21: Student Loan Payment | J21: 347.1 | M21: 347.1 | O21: 347.1 | Q21: 347.1 | S21: 347.1 | U21: =$E$4 -> 347.1 | W21: =$E$4 -> 347.1 | Z21: =$E$4 -> 347.1 | AB21: =$E$4 -> 347.1 | AD21: =$E$4 -> 347.1 | AF21: =$E$4 -> 347.1 | AH21: =$E$4 -> 347.1
A22: Best Buy Payment | J22: 153.81 | L22: 153.81 | N22: 153.81 | P22: 153.81 | R22: 153.81 | T22: 153.81 | V22: 153.81 | X22: 153.81 | Z22: 153.81 | AB22: 153.81 | AD22: 153.81 | AF22: 153.81
A23: American Express Payment
A24: Slinger Payment | H24: 164.44 | I24: 164.43 | J24: 164.43 | K24: 164.44
A25: Stutter Health
A26: One Pass | B26: 125.1 | D26: 125.1 | F26: 125.1 | H26: 125.1 | J26: 125.1 | M26: 125.1 | O26: 125.1 | Q26: 125.1 | S26: 125.1 | U26: 125.1 | W26: 125.1 | Z26: 125.1 | AB26: 125.1 | AD26: 125.1 | AF26: 125.1 | AH26: 125.1
A27: Rent | B27: 625 | D27: 625 | F27: 812.5 | H27: 812.5 | J27: 812.5 | M27: 812.5 | O27: 812.5 | Q27: 812.5 | S27: 812.5 | U27: 812.5 | W27: 812.5 | Z27: 812.5 | AB27: 812.5 | AD27: 812.5 | AF27: 812.5 | AH27: 812.5
A28: Bills (Fixed Expense) | B28: =Summary!J45 -> 849.65 | D28: 700 | F28: 700 | H28: 700 | J28: 700 | M28: 700 | O28: 700 | Q28: 700 | S28: 700 | U28: 700 | W28: 700 | Z28: 700 | AB28: 700 | AD28: 700 | AF28: 700 | AH28: 700
A29: Spending Estimate | B29: =$C$1 -> 750 | D29: =$C$1 -> 750 | F29: =$C$1 -> 750 | H29: =$C$1 -> 750 | J29: =$C$1 -> 750 | M29: =$C$1 -> 750 | O29: =$C$1 -> 750 | Q29: =$C$1 -> 750 | S29: =$C$1 -> 750 | U29: =$C$1 -> 750 | W29: =$C$1 -> 750 | Z29: =$C$1 -> 750 | AB29: =$C$1 -> 750 | AD29: =$C$1 -> 750 | AF29: =$C$1 -> 750 | AH29: =$C$1 -> 750
A30: Car Repair | G30: 1019.8
A32: Cash Flow | B32: =B13+B15-SUM(B19:B29) -> 319.41722 | C32: =C13+C15-SUM(C19:C29) -> 2068.8944 | D32: =D13+D15-SUM(D19:D29) -> 1195.9957 | E32: =E13+E15-SUM(E19:E29) -> 2701.1969 | F32: =F13+F15-SUM(F19:F29) -> 2068.8082 | G32: =G13+G15-SUM(G19:G30) -> 2804.1994 | H32: =H13+H15-SUM(H19:H29) -> 1770.0807 | I32: =I13+I15-SUM(I19:I29) -> 3681.6003 | J32: =J13+J15-SUM(J19:J29) -> 2704.6099 | K32: =K13+K15-SUM(K19:K29) -> 4616.1194 | L32: =L13+L15-SUM(L19:L29) -> 6538.259 | M32: =M13+M15-SUM(M19:M29) -> 5879.5086 | N32: =N13+N15-SUM(N19:N29) -> 7801.6482 | O32: =O13+O15-SUM(O19:O29) -> 7142.8978 | ... AI32: =AI13+AI15-SUM(AI19:AI29) -> 38990.813
A33: Vincent Debt Princpal | D33: =C2-D19 -> 13525.481 | E33: =D33-E19 -> 12623.782 | F33: =E33-F19 -> 11722.084 | G33: =F33-G19 -> 10820.385 | H33: =G33-H19 -> 9918.6863 | I33: =H33-I19 -> 9016.9875 | J33: =I33-J19 -> 8115.2888 | K33: =J33-K19 -> 7213.59 | L33: =K33-L19 -> 6311.8913 | ... AI33: =AH33-AI19 -> 3.4106051e-12
A34: LASIK Debt Principal | D34: =C3-D20 -> 5267 | E34: =D34-E20 -> 5017 | F34: =E34-F20 -> 5017 | G34: =F34-G20 -> 5017 | H34: =G34-H20 -> 4779.71 | I34: =H34-I20 -> 4542.4183 | J34: =I34-J20 -> 4305.1267 | K34: =J34-K20 -> 4067.835 | L34: =K34-L20 -> 3830.5433 | ... AI34: =AH34-AI20 -> 271.16833
A35: Student Loan Principal | D35: =C4-D21 -> 22430.56 | E35: =D35-E21 -> 22430.56 | F35: =E35-F21 -> 22430.56 | G35: =F35-G21 -> 22430.56 | H35: =G35-H21 -> 22430.56 | I35: =H35-I21 -> 22430.56 | J35: =I35-J21 -> 22083.46 | K35: =J35-K21 -> 22083.46 | L35: =K35-L21 -> 22083.46 | ... AI35: =AH35-AI21 -> 18265.36

Sheet Student Loan Amort
C1: AA | D1: AC | E1: AE | F1: Total
B2: Estimated Years | C2: 6
B3: Annual Interest Rate | C3: 0.034 | D3: 0.034 | E3: 0.0541
B4: Monthly Interest Rate | C4: =C3/12 -> 0.0028333333 | D4: =D3/12 -> 0.0028333333 | E4: =E3/12 -> 0.0045083333
B5: Principal | C5: 5765.25 | D5: 4868.38 | E5: 11796.93 | F5: =SUM(C5:E5) -> 22430.56
B6: Payment | C6: =PMT(C3/12,$C$2*12,-C5) -> 88.630846 | D6: =PMT(D3/12,$C$2*12,-D5) -> 74.843006 | E6: =PMT(E3/12,$C$2*12,-E5) -> 192.24046 | F6: =SUM(C6:E6) -> 355.71431
C8: AA Payment | D8: AA Principal | E8: AA Interest | F8: AA Balance | G8: AC Payment | H8: AC Principal | I8: AC Interest | J8: AC Balance | K8: AE Payment | L8: AE Principal | M8: AE Interest | N8: AE Balance | O8: Principal | P8: Interest | Q8: Total Interest | R8: Total Balance
A9: {=_xlfn.SEQUENCE(C2*12)} -> 1 | B9: 45200 | C9: =$C$6 -> 88.630846 | D9: =C6-E9 -> 72.295971 | E9: =C4*C5 -> 16.334875 | F9: =C5-D9 -> 5692.954 | G9: =$D$6 -> 74.843006 | H9: =D6-I9 -> 61.049262 | I9: =D4*D5 -> 13.793743 | J9: =D5-H9 -> 4807.3307 | K9: =$E$6 -> 192.24046 | L9: =E6-M9 -> 139.05597 | M9: =E4*E5 -> 53.184493 | N9: =E5-L9 -> 11657.874 | O9: =SUM(D9,H9,L9) -> 272.4012 | P9: =SUM(E9,I9,M9) -> 83.313111 | Q9: =P9 -> 83.313111 | R9: =SUM(F9,J9,N9) -> 22158.159
A10: 2 | B10: =EOMONTH(B9,0)+1 -> 45231 | C10: =$C$6 -> 88.630846 | D10: =C10-E10 -> 72.50081 | E10: =$C$4*F9 -> 16.130036 | F10: =F9-D10 -> 5620.4532 | G10: =$D$6 -> 74.843006 | H10: =G10-I10 -> 61.222235 | I10: =$D$4*J9 -> 13.62077 | J10: =J9-H10 -> 4746.1085 | K10: =$E$6 -> 192.24046 | L10: =K10-M10 -> 139.68288 | M10: =$E$4*N9 -> 52.557582 | N10: =N9-L10 -> 11518.191 | O10: =SUM(D10,H10,L10) -> 273.40592 | P10: =SUM(E10,I10,M10) -> 82.308389 | Q10: =P10+Q9 -> 165.6215 | R10: =SUM(F10,J10,N10) -> 21884.753
A11: 3 | B11: =EOMONTH(B10,0)+1 -> 45261 | C11: =$C$6 -> 88.630846 | D11: =C11-E11 -> 72.706228 | E11: =$C$4*F10 -> 15.924617 | F11: =F10-D11 -> 5547.747 | G11: =$D$6 -> 74.843006 | H11: =G11-I11 -> 61.395698 | I11: =$D$4*J10 -> 13.447307 | J11: =J10-H11 -> 4684.7128 | K11: =$E$6 -> 192.24046 | L11: =K11-M11 -> 140.31262 | M11: =$E$4*N10 -> 51.927845 | N11: =N10-L11 -> 11377.879 | O11: =SUM(D11,H11,L11) -> 274.41454 | P11: =SUM(E11,I11,M11) -> 81.29977 | Q11: =P11+Q10 -> 246.92127 | R11: =SUM(F11,J11,N11) -> 21610.338
A12: 4 | B12: =EOMONTH(B11,0)+1 -> 45292 | C12: =$C$6 -> 88.630846 | D12: =C12-E12 -> 72.912229 | E12: =$C$4*F11 -> 15.718616 | F12: =F11-D12 -> 5474.8348 | G12: =$D$6 -> 74.843006 | H12: =G12-I12 -> 61.569653 | I12: =$D$4*J11 -> 13.273353 | J12: =J11-H12 -> 4623.1432 | K12: =$E$6 -> 192.24046 | L12: =K12-M12 -> 140.94519 | M12: =$E$4*N11 -> 51.295269 | N12: =N11-L12 -> 11236.933 | O12: =SUM(D12,H12,L12) -> 275.42707 | P12: =SUM(E12,I12,M12) -> 80.287238 | Q12: =P12+Q11 -> 327.20851 | R12: =SUM(F12,J12,N12) -> 21334.911
A13: 5 | B13: =EOMONTH(B12,0)+1 -> 45323 | C13: =$C$6 -> 88.630846 | D13: =C13-E13 -> 73.118814 | E13: =$C$4*F12 -> 15.512032 | F13: =F12-D13 -> 5401.7159 | G13: =$D$6 -> 74.843006 | H13: =G13-I13 -> 61.7441 | I13: =$D$4*J12 -> 13.098906 | J13: =J12-H13 -> 4561.3991 | K13: =$E$6 -> 192.24046 | L13: =K13-M13 -> 141.58062 | M13: =$E$4*N12 -> 50.659841 | N13: =N12-L13 -> 11095.353 | O13: =SUM(D13,H13,L13) -> 276.44353 | P13: =SUM(E13,I13,M13) -> 79.270779 | Q13: =P13+Q12 -> 406.47929 | R13: =SUM(F13,J13,N13) -> 21058.468
A14: 6 | B14: =EOMONTH(B13,0)+1 -> 45352 | C14: =$C$6 -> 88.630846 | D14: =C14-E14 -> 73.325984 | E14: =$C$4*F13 -> 15.304862 | F14: =F13-D14 -> 5328.39 | G14: =$D$6 -> 74.843006 | H14: =G14-I14 -> 61.919042 | I14: =$D$4*J13 -> 12.923964 | J14: =J13-H14 -> 4499.48 | K14: =$E$6 -> 192.24046 | L14: =K14-M14 -> 142.21891 | M14: =$E$4*N13 -> 50.021549 | N14: =N13-L14 -> 10953.134 | O14: =SUM(D14,H14,L14) -> 277.46394 | P14: =SUM(E14,I14,M14) -> 78.250374 | Q14: =P14+Q13 -> 484.72966 | R14: =SUM(F14,J14,N14) -> 20781.004
A15: 7 | B15: =EOMONTH(B14,0)+1 -> 45383 | C15: =$C$6 -> 88.630846 | D15: =C15-E15 -> 73.533741 | E15: =$C$4*F14 -> 15.097105 | F15: =F14-D15 -> 5254.8562 | G15: =$D$6 -> 74.843006 | H15: =G15-I15 -> 62.094479 | I15: =$D$4*J14 -> 12.748527 | J15: =J14-H15 -> 4437.3855 | K15: =$E$6 -> 192.24046 | L15: =K15-M15 -> 142.86008 | M15: =$E$4*N14 -> 49.380378 | N15: =N14-L15 -> 10810.274 | O15: =SUM(D15,H15,L15) -> 278.4883 | P15: =SUM(E15,I15,M15) -> 77.22601 | Q15: =P15+Q14 -> 561.95567 | R15: =SUM(F15,J15,N15) -> 20502.515
A16: 8 | B16: =EOMONTH(B15,0)+1 -> 45413 | C16: =$C$6 -> 88.630846 | D16: =C16-E16 -> 73.742087 | E16: =$C$4*F15 -> 14.888759 | F16: =F15-D16 -> 5181.1141 | G16: =$D$6 -> 74.843006 | H16: =G16-I16 -> 62.270413 | I16: =$D$4*J15 -> 12.572592 | J16: =J15-H16 -> 4375.1151 | K16: =$E$6 -> 192.24046 | L16: =K16-M16 -> 143.50414 | M16: =$E$4*N15 -> 48.736317 | N16: =N15-L16 -> 10666.77 | O16: =SUM(D16,H16,L16) -> 279.51664 | P16: =SUM(E16,I16,M16) -> 76.197669 | Q16: =P16+Q15 -> 638.15334 | R16: =SUM(F16,J16,N16) -> 20222.999
A17: 9 | B17: =EOMONTH(B16,0)+1 -> 45444 | C17: =$C$6 -> 88.630846 | D17: =C17-E17 -> 73.951023 | E17: =$C$4*F16 -> 14.679823 | F17: =F16-D17 -> 5107.1631 | G17: =$D$6 -> 74.843006 | H17: =G17-I17 -> 62.446846 | I17: =$D$4*J16 -> 12.39616 | J17: =J16-H17 -> 4312.6683 | K17: =$E$6 -> 192.24046 | L17: =K17-M17 -> 144.15111 | M17: =$E$4*N16 -> 48.089353 | N17: =N16-L17 -> 10522.618 | O17: =SUM(D17,H17,L17) -> 280.54898 | P17: =SUM(E17,I17,M17) -> 75.165336 | Q17: =P17+Q16 -> 713.31868 | R17: =SUM(F17,J17,N17) -> 19942.45
A18: 10 | B18: =EOMONTH(B17,0)+1 -> 45474 | C18: =$C$6 -> 88.630846 | D18: =C18-E18 -> 74.16055 | E18: =$C$4*F17 -> 14.470295 | F18: =F17-D18 -> 5033.0026 | G18: =$D$6 -> 74.843006 | H18: =G18-I18 -> 62.623779 | I18: =$D$4*J17 -> 12.219227 | J18: =J17-H18 -> 4250.0445 | K18: =$E$6 -> 192.24046 | L18: =K18-M18 -> 144.80099 | M18: =$E$4*N17 -> 47.439472 | N18: =N17-L18 -> 10377.817 | O18: =SUM(D18,H18,L18) -> 281.58532 | P18: =SUM(E18,I18,M18) -> 74.128994 | Q18: =P18+Q17 -> 787.44767 | R18: =SUM(F18,J18,N18) -> 19660.865
A19: 11 | B19: =EOMONTH(B18,0)+1 -> 45505 | C19: =$C$6 -> 88.630846 | D19: =C19-E19 -> 74.370672 | E19: =$C$4*F18 -> 14.260174 | F19: =F18-D19 -> 4958.6319 | G19: =$D$6 -> 74.843006 | H19: =G19-I19 -> 62.801213 | I19: =$D$4*J18 -> 12.041793 | J19: =J18-H19 -> 4187.2433 | K19: =$E$6 -> 192.24046 | L19: =K19-M19 -> 145.4538 | M19: =$E$4*N18 -> 46.786661 | N19: =N18-L19 -> 10232.364 | O19: =SUM(D19,H19,L19) -> 282.62568 | P19: =SUM(E19,I19,M19) -> 73.088627 | Q19: =P19+Q18 -> 860.5363 | R19: =SUM(F19,J19,N19) -> 19378.239
A20: 12 | B20: =EOMONTH(B19,0)+1 -> 45536 | C20: =$C$6 -> 88.630846 | D20: =C20-E20 -> 74.581389 | E20: =$C$4*F19 -> 14.049457 | F20: =F19-D20 -> 4884.0505 | G20: =$D$6 -> 74.843006 | H20: =G20-I20 -> 62.97915 | I20: =$D$4*J19 -> 11.863856 | J20: =J19-H20 -> 4124.2641 | K20: =$E$6 -> 192.24046 | L20: =K20-M20 -> 146.10955 | M20: =$E$4*N19 -> 46.130906 | N20: =N19-L20 -> 10086.254 | O20: =SUM(D20,H20,L20) -> 283.67009 | P20: =SUM(E20,I20,M20) -> 72.044219 | Q20: =P20+Q19 -> 932.58052 | R20: =SUM(F20,J20,N20) -> 19094.569
A21: 13 | B21: =EOMONTH(B20,0)+1 -> 45566 | C21: =$C$6 -> 88.630846 | D21: =C21-E21 -> 74.792703 | E21: =$C$4*F20 -> 13.838143 | F21: =F20-D21 -> 4809.2578 | G21: =$D$6 -> 74.843006 | H21: =G21-I21 -> 63.15759 | I21: =$D$4*J20 -> 11.685415 | J21: =J20-H21 -> 4061.1065 | K21: =$E$6 -> 192.24046 | L21: =K21-M21 -> 146.76826 | M21: =$E$4*N20 -> 45.472196 | N21: =N20-L21 -> 9939.4859 | O21: =SUM(D21,H21,L21) -> 284.71856 | P21: =SUM(E21,I21,M21) -> 70.995754 | Q21: =P21+Q20 -> 1003.5763 | R21: =SUM(F21,J21,N21) -> 18809.85
... A80: 72 | B80: =EOMONTH(B79,0)+1 -> 47362 | C80: =$C$6 -> 88.630846 | D80: =C80-E80 -> 88.380435 | E80: =$C$4*F79 -> 0.25041123 | F80: =F79-D80 -> 2.6005864e-12 | G80: =$D$6 -> 74.843006 | H80: =G80-I80 -> 74.631549 | I80: =$D$4*J79 -> 0.21145606 | J80: =J79-H80 -> 2.9700686e-12 | K80: =$E$6 -> 192.24046 | L80: =K80-M80 -> 191.37767 | M80: =$E$4*N79 -> 0.86279431 | N80: =N79-L80 -> -1.9326762e-12 | O80: =SUM(D80,H80,L80) -> 354.38965 | P80: =SUM(E80,I80,M80) -> 1.3246616 | Q80: =P80+Q79 -> 3180.8705 | R80: =SUM(F80,J80,N80) -> 3.6379788e-12

Sheet Lasik
B2: 5535.28
A3: 45090
A4: =EOMONTH(A3,0)+10 -> 45117 | B4: =$B$2/20 -> 276.764 | C4: =B2-B4 -> 5258.516 | D4: 1
A5: =EOMONTH(A4,0)+10 -> 45148 | B5: =$B$2/20 -> 276.764 | C5: =C4-B5 -> 4981.752 | D5: 1
A6: =EOMONTH(A5,0)+10 -> 45179 | B6: =$B$2/20 -> 276.764 | C6: =C5-B6 -> 4704.988 | D6: 1
A7: =EOMONTH(A6,0)+10 -> 45209 | B7: =$B$2/20 -> 276.764 | C7: =C6-B7 -> 4428.224 | D7: 1
A8: =EOMONTH(A7,0)+10 -> 45240 | B8: =$B$2/20 -> 276.764 | C8: =C7-B8 -> 4151.46 | D8: 1
A9: =EOMONTH(A8,0)+10 -> 45270 | B9: =$B$2/20 -> 276.764 | C9: =C8-B9 -> 3874.696 | D9: 1
A10: =EOMONTH(A9,0)+10 -> 45301 | B10: =$B$2/20 -> 276.764 | C10: =C9-B10 -> 3597.932 | D10: 1
A11: =EOMONTH(A10,0)+10 -> 45332 | B11: =$B$2/20 -> 276.764 | C11: =C10-B11 -> 3321.168 | D11: 1
A12: =EOMONTH(A11,0)+10 -> 45361 | B12: =$B$2/20 -> 276.764 | C12: =C11-B12 -> 3044.404 | D12: 1
A13: =EOMONTH(A12,0)+10 -> 45392 | B13: =$B$2/20 -> 276.764 | C13: =C12-B13 -> 2767.64
A14: =EOMONTH(A13,0)+10 -> 45422 | B14: =$B$2/20 -> 276.764 | C14: =C13-B14 -> 2490.876
A15: =EOMONTH(A14,0)+10 -> 45453 | B15: =$B$2/20 -> 276.764 | C15: =C14-B15 -> 2214.112
A16: =EOMONTH(A15,0)+10 -> 45483 | B16: =$B$2/20 -> 276.764 | C16: =C15-B16 -> 1937.348
A17: =EOMONTH(A16,0)+10 -> 45514 | B17: =$B$2/20 -> 276.764 | C17: =C16-B17 -> 1660.584
A18: =EOMONTH(A17,0)+10 -> 45545 | B18: =$B$2/20 -> 276.764 | C18: =C17-B18 -> 1383.82
A19: =EOMONTH(A18,0)+10 -> 45575 | B19: =$B$2/20 -> 276.764 | C19: =C18-B19 -> 1107.056
A20: =EOMONTH(A19,0)+10 -> 45606 | B20: =$B$2/20 -> 276.764 | C20: =C19-B20 -> 830.292
A21: =EOMONTH(A20,0)+10 -> 45636 | B21: =$B$2/20 -> 276.764 | C21: =C20-B21 -> 553.528
A22: =EOMONTH(A21,0)+10 -> 45667 | B22: =$B$2/20 -> 276.764 | C22: =C21-B22 -> 276.764
A23: =EOMONTH(A22,0)+10 -> 45698 | B23: =$B$2/20 -> 276.764 | C23: =C22-B23 -> -2.2737368e-12
A24: =EOMONTH(A23,0)+10 -> 45726 | B24: =$B$2/20 -> 276.764 | C24: =C23-B24 -> -276.764
... A28: =EOMONTH(A27,0)+10 -> 45848 | B28: =$B$2/20 -> 276.764 | C28: =C27-B28 -> -1383.82

Sheet Wells Fargo
A1: Month | B1: Trans Date | C1: Debit_Amount | D1: Column1 | E1: Column2 | F1: Column22 | G1: Description | H1: Column3 | I1: Column4 | N1: {=_xlfn.UNIQUE('Discover Data'!J2:J361)} -> Balance
A2: =MONTH(wf_table[[#This Row],[Trans Date]]) -> 1 | B2: 44927 | C2: =D3-C3 -> 406.52 | E2: =IF(wf_table[[#This Row],[Debit_Amount]]<0,"debit","-") -> - | G2: Balance | N2: Recreation_Entertainment
A3: =MONTH(wf_table[[#This Row],[Trans Date]]) -> 1 | B3: 44929 | C3: -80 | D3: 326.52 | E3: =IF(wf_table[[#This Row],[Debit_Amount]]<0,"debit","-") -> debit | G3: PURCHASE AUTHORIZED ON 01/01 CASH APP*ANUSH ROH 8774174551 CA S383001689612697 CARD 6659 | N3: Food
A4: =MONTH(wf_table[[#This Row],[Trans Date]]) -> 1 | B4: 44936 | C4: -200 | D4: =D3+wf_table[[#This Row],[Debit_Amount]] -> 126.52 | E4: =IF(wf_table[[#This Row],[Debit_Amount]]<0,"debit","-") -> debit | G4: ZELLE TO LEWIS SHEVON ON 01/10 REF #RP0QXXRHQF EARLY INVESTMENT | N4: Personal_Spending
A5: =MONTH(wf_table[[#This Row],[Trans Date]]) -> 1 | B5: 44936 | C5: -50 | D5: =D4+wf_table[[#This Row],[Debit_Amount]] -> 76.52 | E5: =IF(wf_table[[#This Row],[Debit_Amount]]<0,"debit","-") -> debit | G5: PURCHASE AUTHORIZED ON 01/09 CASH APP*CYANFACE 8774174551 CA S463009600364898 CARD 6659 | N5: Medical
A6: =MONTH(wf_table[[#This Row],[Trans Date]]) -> 1 | B6: 44937 | C6: -182 | D6: =D5+wf_table[[#This Row],[Debit_Amount]] -> -105.48 | E6: =IF(wf_table[[#This Row],[Debit_Amount]]<0,"debit","-") -> debit | G6: VENMO PAYMENT 230111 1024637239631 SEAN LEWIS | N6: Payment_and_Interest
A7: =MONTH(wf_table[[#This Row],[Trans Date]]) -> 1 | B7: 44937 | C7: -24.14 | D7: =D6+wf_table[[#This Row],[Debit_Amount]] -> -129.62 | E7: =IF(wf_table[[#This Row],[Debit_Amount]]<0,"debit","-") -> debit | G7: VENMO PAYMENT 230111 1024637259890 SEAN LEWIS | N7: Transportation
A8: =MONTH(wf_table[[#This Row],[Trans Date]]) -> 1 | B8: 44938 | C8: 541.16 | D8: =D7+wf_table[[#This Row],[Debit_Amount]] -> 411.54 | E8: =IF(wf_table[[#This Row],[Debit_Amount]]<0,"debit","-") -> - | F8: deposit | G8: Nationwide PAYROLL 01 HRP0008984397 Sean Lewis | N8: Misc
A9: =MONTH(wf_table[[#This Row],[Trans Date]]) -> 1 | B9: 44939 | C9: -200 | D9: =D8+wf_table[[#This Row],[Debit_Amount]] -> 211.54 | E9: =IF(wf_table[[#This Row],[Debit_Amount]]<0,"debit","-") -> debit | G9: TRANSFER TO LEWIS SHARON ON 01/13 REF #PP0QY4HH2S TAX PT2 | N9: Insurance
A10: =MONTH(wf_table[[#This Row],[Trans Date]]) -> 1 | B10: 44939 | C10: -500 | D10: =D9+wf_table[[#This Row],[Debit_Amount]] -> -288.46 | E10: =IF(wf_table[[#This Row],[Debit_Amount]]<0,"debit","-") -> debit | G10: TRANSFER TO LEWIS SHARON ON 01/13 REF #PP0QY4CRFP FOR TAXES | N10: Utilities
A11: =MONTH(wf_table[[#This Row],[Trans Date]]) -> 1 | B11: 44939 | C11: 400 | D11: =D10+wf_table[[#This Row],[Debit_Amount]] -> 111.54 | E11: =IF(wf_table[[#This Row],[Debit_Amount]]<0,"debit","-") -> - | G11: ATM CASH DEPOSIT ON 01/13 1435 Burlingame Ave Burlingame CA 0000637 ATM ID 0165J CARD 6659 | N11: Housing
A12: =MONTH(wf_table[[#This Row],[Trans Date]]) -> 1 | B12: 44939 | C12: 106 | D12: =D11+wf_table[[#This Row],[Debit_Amount]] -> 217.54 | E12: =IF(wf_table[[#This Row],[Debit_Amount]]<0,"debit","-") -> - | G12: MONEY TRANSFER AUTHORIZED ON 01/13 FROM Sean Lewis VA S463013513474302 CARD 6659 | N12: People
A13: =MONTH(wf_table[[#This Row],[Trans Date]]) -> 1 | B13: 44943 | C13: -25.48 | D13: =D12+wf_table[[#This Row],[Debit_Amount]] -> 192.06 | E13: =IF(wf_table[[#This Row],[Debit_Amount]]<0,"debit","-") -> debit | G13: PLANET FIT CLUB FEES 2301306620293 623-439-5550 | N13: Government
A14: =MONTH(wf_table[[#This Row],[Trans Date]]) -> 1 | B14: 44949 | C14: -25 | D14: =D13+wf_table[[#This Row],[Debit_Amount]] -> 167.06 | E14: =IF(wf_table[[#This Row],[Debit_Amount]]<0,"debit","-") -> debit | G14: VENMO PAYMENT 230121 1024827296273 SEAN LEWIS
A15: =MONTH(wf_table[[#This Row],[Trans Date]]) -> 1 | B15: 44949 | C15: -65.61 | D15: =D14+wf_table[[#This Row],[Debit_Amount]] -> 101.45 | E15: =IF(wf_table[[#This Row],[Debit_Amount]]<0,"debit","-") -> debit | G15: PURCHASE AUTHORIZED ON 01/20 STREET FOOD CAFE SAN MATEO CA S303021134090263 CARD 6659
A16: =MONTH(wf_table[[#This Row],[Trans Date]]) -> 1 | B16: 44952 | C16: -100 | D16: =D15+wf_table[[#This Row],[Debit_Amount]] -> 1.45 | E16: =IF(wf_table[[#This Row],[Debit_Amount]]<0,"debit","-") -> debit | G16: ZELLE TO LEWIS SHEVON ON 01/26 REF #RP0QYXPP3Q FOR GAS
A17: =MONTH(wf_table[[#This Row],[Trans Date]]) -> 1 | B17: 44952 | C17: 477.52 | D17: =D16+wf_table[[#This Row],[Debit_Amount]] -> 478.97 | E17: =IF(wf_table[[#This Row],[Debit_Amount]]<0,"debit","-") -> - | F17: deposit | G17: Nationwide PAYROLL 01 HRP0009017504 Sean Lewis
A18: =MONTH(wf_table[[#This Row],[Trans Date]]) -> 1 | B18: 44952 | C18: 75 | D18: =D17+wf_table[[#This Row],[Debit_Amount]] -> 553.97 | E18: =IF(wf_table[[#This Row],[Debit_Amount]]<0,"debit","-") -> - | G18: Square Inc * Cash App 230126 T3EC2YGP8SHTR06 Sean Lewis
A19: =MONTH(wf_table[[#This Row],[Trans Date]]) -> 2 | B19: 44958 | C19: -158 | D19: =D18+wf_table[[#This Row],[Debit_Amount]] -> 395.97 | E19: =IF(wf_table[[#This Row],[Debit_Amount]]<0,"debit","-") -> debit | G19: VENMO PAYMENT 230201 1025016489585 SEAN LEWIS
A20: =MONTH(wf_table[[#This Row],[Trans Date]]) -> 2 | B20: 44963 | C20: -53.01 | D20: =D19+wf_table[[#This Row],[Debit_Amount]] -> 342.96 | E20: =IF(wf_table[[#This Row],[Debit_Amount]]<0,"debit","-") -> debit | G20: PURCHASE AUTHORIZED ON 02/03 CHEVRON/CSI-092600/1556 FOSTER CITY CA P383035071538454 CARD 1081
A21: =MONTH(wf_table[[#This Row],[Trans Date]]) -> 2 | B21: 44965 | C21: -500 | D21: =D20+wf_table[[#This Row],[Debit_Amount]] -> -157.04 | E21: - | G21: SoFi Bank TRANSFER SD1300 SLewis Sean Lewis:66513:690
A22: =MONTH(wf_table[[#This Row],[Trans Date]]) -> 2 | B22: 44965 | C22: 87 | D22: =D21+wf_table[[#This Row],[Debit_Amount]] -> -70.04 | E22: =IF(wf_table[[#This Row],[Debit_Amount]]<0,"debit","-") -> - | G22: VENMO CASHOUT 230207 1025155149107 SEAN LEWIS
A23: =MONTH(wf_table[[#This Row],[Trans Date]]) -> 2 | B23: 44966 | C23: 267.17 | D23: =D22+wf_table[[#This Row],[Debit_Amount]] -> 197.13 | E23: =IF(wf_table[[#This Row],[Debit_Amount]]<0,"debit","-") -> - | F23: deposit | G23: Nationwide PAYROLL 01 HRP0009061376 Sean Lewis
A24: =MONTH(wf_table[[#This Row],[Trans Date]]) -> 2 | B24: 44967 | C24: -21.21 | D24: =D23+wf_table[[#This Row],[Debit_Amount]] -> 175.92 | E24: =IF(wf_table[[#This Row],[Debit_Amount]]<0,"debit","-") -> debit | G24: VENMO PAYMENT 230210 1025196796049 SEAN LEWIS
A25: =MONTH(wf_table[[#This Row],[Trans Date]]) -> 2 | B25: 44970 | C25: -43.39 | D25: =D24+wf_table[[#This Row],[Debit_Amount]] -> 132.53 | E25: =IF(wf_table[[#This Row],[Debit_Amount]]<0,"debit","-") -> debit | G25: VENMO PAYMENT 230213 1025255412913 SEAN LEWIS
A26: =MONTH(wf_table[[#This Row],[Trans Date]]) -> 2 | B26: 44970 | C26: -17.5 | D26: =D25+wf_table[[#This Row],[Debit_Amount]] -> 115.03 | E26: =IF(wf_table[[#This Row],[Debit_Amount]]<0,"debit","-") -> debit | G26: VENMO PAYMENT 230211 1025215575532 SEAN LEWIS
A27: =MONTH(wf_table[[#This Row],[Trans Date]]) -> 2 | B27: 44971 | C27: 200 | D27: =D26+wf_table[[#This Row],[Debit_Amount]] -> 315.03 | E27: =IF(wf_table[[#This Row],[Debit_Amount]]<0,"debit","-") -> - | G27: ATM CASH DEPOSIT ON 02/13 632 Eastern Blvd Essex MD 0008972 ATM ID 0282M CARD 1081
A28: =MONTH(wf_table[[#This Row],[Trans Date]]) -> 2 | B28: 44974 | C28: -25.48 | D28: =D27+wf_table[[#This Row],[Debit_Amount]] -> 289.55 | E28: =IF(wf_table[[#This Row],[Debit_Amount]]<0,"debit","-") -> debit | G28: PLANET FIT CLUB FEES 2304706550250 623-439-5550
A29: =MONTH(wf_table[[#This Row],[Trans Date]]) -> 2 | B29: 44974 | C29: 136 | D29: =D28+wf_table[[#This Row],[Debit_Amount]] -> 425.55 | E29: =IF(wf_table[[#This Row],[Debit_Amount]]<0,"debit","-") -> - | G29: HEALTHEQUITY INC HealthEqui 16 Feb 22317048 Sean Lewis (22317048)
A30: =MONTH(wf_table[[#This Row],[Trans Date]]) -> 2 | B30: 44978 | C30: -194.5 | D30: =D29+wf_table[[#This Row],[Debit_Amount]] -> 231.05 | E30: =IF(wf_table[[#This Row],[Debit_Amount]]<0,"debit","-") -> debit | G30: VENMO PAYMENT 230218 1025351910082 SEAN LEWIS
A31: =MONTH(wf_table[[#This Row],[Trans Date]]) -> 2 | B31: 44978 | C31: -265 | D31: =D30+wf_table[[#This Row],[Debit_Amount]] -> -33.95 | E31: =IF(wf_table[[#This Row],[Debit_Amount]]<0,"debit","-") -> debit | G31: ZELLE TO LEWIS SHARON ON 02/20 REF #PP0R2LTMPW BDAY PARTY EXCEPT DON SEAN
A32: =MONTH(wf_table[[#This Row],[Trans Date]]) -> 2 | B32: 44978 | C32: -2.5 | D32: =D31+wf_table[[#This Row],[Debit_Amount]] -> -36.45 | E32: =IF(wf_table[[#This Row],[Debit_Amount]]<0,"debit","-") -> debit | G32: NON-WELLS FARGO ATM TRANSACTION FEE
A33: =MONTH(wf_table[[#This Row],[Trans Date]]) -> 2 | B33: 44978 | C33: -23 | D33: =D32+wf_table[[#This Row],[Debit_Amount]] -> -59.45 | E33: =IF(wf_table[[#This Row],[Debit_Amount]]<0,"debit","-") -> debit | G33: NON-WF ATM WITHDRAWAL AUTHORIZED ON 02/18 M&T 5980 KINGSTOWN ALEXANDR1A VA 463049709972404 ATM ID SA1847 CARD 1081
A34: =MONTH(wf_table[[#This Row],[Trans Date]]) -> 2 | B34: 44978 | C34: 100 | D34: =D33+wf_table[[#This Row],[Debit_Amount]] -> 40.55 | E34: =IF(wf_table[[#This Row],[Debit_Amount]]<0,"debit","-") -> - | G34: SoFi Bank TRANSFER SD1700 SLewis Sean Lewis:66526:32382
A35: =MONTH(wf_table[[#This Row],[Trans Date]]) -> 2 | B35: 44979 | C35: -650 | D35: =D34+wf_table[[#This Row],[Debit_Amount]] -> -609.45 | E35: =IF(wf_table[[#This Row],[Debit_Amount]]<0,"debit","-") -> debit | G35: ZELLE TO LEWIS SHEVON ON 02/22 REF #RP0R2Q2L33 MARCH SUB
... A45: =MONTH(wf_table[[#This Row],[Trans Date]]) -> 3 | B45: 44993 | C45: -2 | D45: =D44+wf_table[[#This Row],[Debit_Amount]] -> 303.11 | E45: =IF(wf_table[[#This Row],[Debit_Amount]]<0,"debit","-") -> debit | G45: VENMO PAYMENT 230308 1025696123572 SEAN LEWIS
A46: =MONTH(wf_table[[#This Row],[Trans Date]]) -> 3 | B46: 44994 | C46: 290.51 | D46: =D45+wf_table[[#This Row],[Debit_Amount]] -> 593.62 | E46: =IF(wf_table[[#This Row],[Debit_Amount]]<0,"debit","-") -> - | F46: deposit | G46: Nationwide PAYROLL 01 HRP0009139641 Sean Lewis
A47: =MONTH(wf_table[[#This Row],[Trans Date]]) -> 3 | B47: 44994 | C47: 165.84 | D47: =D46+wf_table[[#This Row],[Debit_Amount]] -> 759.46 | E47: =IF(wf_table[[#This Row],[Debit_Amount]]<0,"debit","-") -> - | G47: Cash App * Cash App 230309 T36VMBW9GF2GB15 Sean Lewis
A48: =MONTH(wf_table[[#This Row],[Trans Date]]) -> 3 | B48: 44995 | C48: -500 | D48: =D47+wf_table[[#This Row],[Debit_Amount]] -> 259.46 | E48: - | G48: SoFi Bank TRANSFER SD1300 SLewis Sean Lewis:66543:1977
A49: =MONTH(wf_table[[#This Row],[Trans Date]]) -> 3 | B49: 44995 | C49: -180.41 | D49: =D48+wf_table[[#This Row],[Debit_Amount]] -> 79.05 | E49: =IF(wf_table[[#This Row],[Debit_Amount]]<0,"debit","-") -> debit | G49: BEST BUY PAYMENT 230309 631006869237022 SEAN LEWIS
...

Sheet SOFI_CHECKING
A1: Month | B1: Transaction Date | C1: Description | D1: Type | E1: Amount | F1: Column1 | G1: Short_Desc | H1: Category_2
A2: =MONTH(sofiC_table[[#This Row],[Transaction Date]]) -> 1 | B2: 44927 | C2: Balance | E2: =F3-E3 -> 60.34
A3: =MONTH(sofiC_table[[#This Row],[Transaction Date]]) -> 1 | B3: 44928 | C3: OAKLAND PARKMOBILE PAY | D3: Debit Card | E3: -4.25 | F3: 56.09 | G3: parking | H3: transportation
A4: =MONTH(sofiC_table[[#This Row],[Transaction Date]]) -> 1 | B4: 44931 | C4: From Savings - 3552 | D4: Deposit | E4: 750 | F4: 806.09
A5: =MONTH(sofiC_table[[#This Row],[Transaction Date]]) -> 1 | B5: 44932 | C5: VENMO | D5: Direct Payment | E5: -750 | F5: 56.09
A6: =MONTH(sofiC_table[[#This Row],[Transaction Date]]) -> 1 | B6: 44939 | C6: 1435 Burlingame Ave | D6: ATM | E6: -403 | F6: 253.09
A7: =MONTH(sofiC_table[[#This Row],[Transaction Date]]) -> 1 | B7: 44939 | C7: From Savings - 3552 | D7: Deposit | E7: 600 | F7: 656.09
A8: =MONTH(sofiC_table[[#This Row],[Transaction Date]]) -> 1 | B8: 44941 | C8: To Emergency Fund Vault | D8: Withdrawal | E8: -253.09 | F8: 0
A9: =MONTH(sofiC_table[[#This Row],[Transaction Date]]) -> 1 | B9: 44951 | C9: From Savings - 3552 | D9: Deposit | E9: 100 | F9: 150
A10: =MONTH(sofiC_table[[#This Row],[Transaction Date]]) -> 1 | B10: 44951 | C10: From Savings - 3552 | D10: Deposit | E10: 50 | F10: 50
A11: =MONTH(sofiC_table[[#This Row],[Transaction Date]]) -> 1 | B11: 44953 | C11: Roundup *CITY OF SM PARKPAYBYPH | D11: Roundup | E11: -0.4 | F11: 144.2
A12: =MONTH(sofiC_table[[#This Row],[Transaction Date]]) -> 1 | B12: 44953 | C12: Roundup *PENINSULA JEWISH COMMU | D12: Roundup | E12: -0.2 | F12: 144.6
A13: =MONTH(sofiC_table[[#This Row],[Transaction Date]]) -> 1 | B13: 44953 | C13: CITY OF SM PARKPAYBYPH | D13: Debit Card | E13: -0.4 | F13: 144.8
A14: =MONTH(sofiC_table[[#This Row],[Transaction Date]]) -> 1 | B14: 44953 | C14: PENINSULA JEWISH COMMU | D14: Debit Card | E14: -4.8 | F14: 145.2
A15: =MONTH(sofiC_table[[#This Row],[Transaction Date]]) -> 1 | B15: 44954 | C15: CITY OF BURLINGAME-PAR | D15: Debit Card | E15: -1 | F15: 143.2
A16: =MONTH(sofiC_table[[#This Row],[Transaction Date]]) -> 1 | B16: 44956 | C16: CASH APP*CYANFACE | D16: Debit Card | E16: -50 | F16: 93.2 | G16: jayelin | H16: people
A17: =MONTH(sofiC_table[[#This Row],[Transaction Date]]) -> 1 | B17: 44957 | C17: Interest earned | D17: Interest Earned | E17: 0.19 | F17: 93.39
A18: =MONTH(sofiC_table[[#This Row],[Transaction Date]]) -> 2 | B18: 44961 | C18: PENINSULA JEWISH COMMU | D18: Debit Card | E18: -73 | F18: 20.39 | G18: gym
A19: =MONTH(sofiC_table[[#This Row],[Transaction Date]]) -> 2 | B19: 44962 | C19: From Savings - 3552 | D19: Deposit | E19: 50 | F19: 120.39
A20: =MONTH(sofiC_table[[#This Row],[Transaction Date]]) -> 2 | B20: 44962 | C20: From Savings - 3552 | D20: Deposit | E20: 50 | F20: 70.39
A21: =MONTH(sofiC_table[[#This Row],[Transaction Date]]) -> 2 | B21: 44964 | C21: CASH APP*CYANFACE | D21: Debit Card | E21: -55 | F21: 65.39 | G21: jayelin | H21: people
A22: =MONTH(sofiC_table[[#This Row],[Transaction Date]]) -> 2 | B22: 44967 | C22: CASH APP*KAIYA | D22: Debit Card | E22: -20 | F22: 25.39
A23: =MONTH(sofiC_table[[#This Row],[Transaction Date]]) -> 2 | B23: 44967 | C23: CASH APP*ROBIN JOSEPH | D23: Debit Card | E23: -20 | F23: 45.39
A24: =MONTH(sofiC_table[[#This Row],[Transaction Date]]) -> 2 | B24: 44978 | C24: CVS STORE #09940 | D24: ATM | E24: -100 | F24: 25.39
A25: =MONTH(sofiC_table[[#This Row],[Transaction Date]]) -> 2 | B25: 44978 | C25: From Savings - 3552 | D25: Deposit | E25: 100 | F25: 125.39
A26: =MONTH(sofiC_table[[#This Row],[Transaction Date]]) -> 2 | B26: 44985 | C26: Interest earned | D26: Interest Earned | E26: 0.08 | F26: 25.47
A27: =MONTH(sofiC_table[[#This Row],[Transaction Date]]) -> 3 | B27: 44986 | C27: From Savings - 3552 | D27: Deposit | E27: 150 | F27: 175.47
A28: =MONTH(sofiC_table[[#This Row],[Transaction Date]]) -> 3 | B28: 44989 | C28: PENINSULA JEWISH COMMU | D28: Debit Card | E28: -146 | F28: 29.47 | G28: gym
A29: =MONTH(sofiC_table[[#This Row],[Transaction Date]]) -> 3 | B29: 44995 | C29: From Savings - 3552 | D29: Deposit | E29: 800 | F29: 829.47
A30: =MONTH(sofiC_table[[#This Row],[Transaction Date]]) -> 3 | B30: 44998 | C30: VENMO | D30: Direct Payment | E30: -772.3 | F30: 57.17
A31: =MONTH(sofiC_table[[#This Row],[Transaction Date]]) -> 3 | B31: 45002 | C31: From Savings - 3552 | D31: Deposit | E31: 141.6 | F31: 198.77
A32: =MONTH(sofiC_table[[#This Row],[Transaction Date]]) -> 3 | B32: 45005 | C32: CASH APP*CYANFACE | D32: Debit Card | E32: -15 | F32: 42.17 | G32: jayelin | H32: people
A33: =MONTH(sofiC_table[[#This Row],[Transaction Date]]) -> 3 | B33: 45005 | C33: VENMO | D33: Direct Payment | E33: -141.6 | F33: 57.17
A34: =MONTH(sofiC_table[[#This Row],[Transaction Date]]) -> 3 | B34: 45016 | C34: Interest earned | D34: Interest Earned | E34: 0.27 | F34: 42.44
A35: =MONTH(sofiC_table[[#This Row],[Transaction Date]]) -> 4 | B35: 45024 | C35: TCB*MTA METER MTA PBP | D35: Debit Card | E35: -3.5 | F35: 38.94
A36: =MONTH(sofiC_table[[#This Row],[Transaction Date]]) -> 4 | B36: 45026 | C36: Mobile Check Deposit | D36: Check Deposit | E36: 217.6 | F36: 256.54
A37: =MONTH(sofiC_table[[#This Row],[Transaction Date]]) -> 4 | B37: 45027 | C37: BEST BUY | D37: Direct Payment | E37: -153.1 | F37: 103.44
A38: =MONTH(sofiC_table[[#This Row],[Transaction Date]]) -> 4 | B38: 45032 | C38: To Savings - 3552 | D38: Withdrawal | E38: -100 | F38: 3.44
A39: =MONTH(sofiC_table[[#This Row],[Transaction Date]]) -> 4 | B39: 45036 | C39: CITY OF SM PARKPAYBYPH | D39: Debit Card | E39: -0.1 | F39: 2.61
A40: =MONTH(sofiC_table[[#This Row],[Transaction Date]]) -> 4 | B40: 45036 | C40: CITY OF SM PARKPAYBYPH | D40: Debit Card | E40: -0.63 | F40: 2.71
...

Sheet SOFI_SAVINGS
A1: Month | B1: Transaction Date | C1: Description | D1: Type | E1: Amount | F1: Cumulative | G1: incremental | H1: Short_Desc | I1: Category_2
A2: =MONTH(sofiS_table[[#This Row],[Transaction Date]]) -> 1 | B2: 44927 | C2: Balance | E2: =F3-E3 -> 1148.39 | G2: =IFERROR(sofiS_table[[#This Row],[Cumulative]]-F1,0) -> 0
A3: =MONTH(sofiS_table[[#This Row],[Transaction Date]]) -> 1 | B3: 44931 | C3: To Checking - 8930 | D3: Withdrawal | E3: -750 | F3: 398.39 | G3: =IFERROR(sofiS_table[[#This Row],[Cumulative]]-F1,0) -> 0
A4: =MONTH(sofiS_table[[#This Row],[Transaction Date]]) -> 1 | B4: 44936 | C4: Nationwide | D4: Direct Deposit | E4: 3066.58 | F4: 3464.97 | G4: =IFERROR(sofiS_table[[#This Row],[Cumulative]]-F3,0) -> 3066.58
A5: =MONTH(sofiS_table[[#This Row],[Transaction Date]]) -> 1 | B5: 44938 | C5: DISCOVER | D5: Direct Payment | E5: -552.53 | F5: 2912.44 | G5: =IFERROR(sofiS_table[[#This Row],[Cumulative]]-F4,0) -> -552.53
A6: =MONTH(sofiS_table[[#This Row],[Transaction Date]]) -> 1 | B6: 44939 | C6: To Checking - 8930 | D6: Withdrawal | E6: -600 | F6: 2312.44 | G6: =IFERROR(sofiS_table[[#This Row],[Cumulative]]-F5,0) -> -600
A7: =MONTH(sofiS_table[[#This Row],[Transaction Date]]) -> 1 | B7: 44941 | C7: From Emergency Fund Vault | D7: Deposit | E7: 253.09 | F7: 2565.53 | G7: =IFERROR(sofiS_table[[#This Row],[Cumulative]]-F6,0) -> 253.09
A8: =MONTH(sofiS_table[[#This Row],[Transaction Date]]) -> 1 | B8: 44943 | C8: BOARD OF REGENTS | D8: Direct Payment | E8: -932 | F8: 1633.53 | G8: =IFERROR(sofiS_table[[#This Row],[Cumulative]]-F7,0) -> -932
A9: =MONTH(sofiS_table[[#This Row],[Transaction Date]]) -> 1 | B9: 44949 | C9: DISCOVER | D9: Direct Payment | E9: -1000 | F9: 633.53 | G9: =IFERROR(sofiS_table[[#This Row],[Cumulative]]-F8,0) -> -1000
A10: =MONTH(sofiS_table[[#This Row],[Transaction Date]]) -> 1 | B10: 44950 | C10: Nationwide | D10: Direct Deposit | E10: 2705.92 | F10: 3339.45 | G10: =IFERROR(sofiS_table[[#This Row],[Cumulative]]-F9,0) -> 2705.92
A11: =MONTH(sofiS_table[[#This Row],[Transaction Date]]) -> 1 | B11: 44951 | C11: SoFi Rewards Redemption | D11: Other | E11: 4.1 | F11: 3193.55 | G11: =IFERROR(sofiS_table[[#This Row],[Cumulative]]-F10,0) -> -145.9
A12: =MONTH(sofiS_table[[#This Row],[Transaction Date]]) -> 1 | B12: 44951 | C12: To Checking - 8930 | D12: Withdrawal | E12: -100 | F12: 3189.45 | G12: =IFERROR(sofiS_table[[#This Row],[Cumulative]]-F11,0) -> -4.1
A13: =MONTH(sofiS_table[[#This Row],[Transaction Date]]) -> 1 | B13: 44951 | C13: To Checking - 8930 | D13: Withdrawal | E13: -50 | F13: 3289.45 | G13: =IFERROR(sofiS_table[[#This Row],[Cumulative]]-F12,0) -> 100
A14: =MONTH(sofiS_table[[#This Row],[Transaction Date]]) -> 1 | B14: 44952 | C14: DISCOVER | D14: Direct Payment | E14: -2071.58 | F14: 1121.97 | G14: =IFERROR(sofiS_table[[#This Row],[Cumulative]]-F13,0) -> -2167.48
A15: =MONTH(sofiS_table[[#This Row],[Transaction Date]]) -> 1 | B15: 44957 | C15: Interest earned | D15: Interest Earned | E15: 5.02 | F15: 1126.99 | G15: =IFERROR(sofiS_table[[#This Row],[Cumulative]]-F14,0) -> 5.02
... A74: =MONTH(sofiS_table[[#This Row],[Transaction Date]]) -> 7 | B74: 45113 | C74: HEALTHEQUITY INC | D74: Deposit | E74: 499.64 | F74: 764.66 | G74: =IFERROR(sofiS_table[[#This Row],[Cumulative]]-F73,0) -> 321.64
A75: =MONTH(sofiS_table[[#This Row],[Transaction Date]]) -> 7 | B75: 45114 | C75: Instamed | E75: -599.64 | F75: =F74+sofiS_table[[#This Row],[Amount]] -> 165.02 | G75: =IFERROR(sofiS_table[[#This Row],[Cumulative]]-F74,0) -> -599.64
A76: =MONTH(sofiS_table[[#This Row],[Transaction Date]]) -> 7 | B76: 45118 | C76: Nationwide | D76: Direct Deposit | E76: 2258.37 | F76: =F75+sofiS_table[[#This Row],[Amount]] -> 2423.39 | G76: =IFERROR(sofiS_table[[#This Row],[Cumulative]]-F75,0) -> 2258.37
A77: =MONTH(sofiS_table[[#This Row],[Transaction Date]]) -> 7 | B77: 45119 | C77: To Checking - 8930 | E77: -2 | F77: =F76+sofiS_table[[#This Row],[Amount]] -> 2421.39 | G77: =IFERROR(sofiS_table[[#This Row],[Cumulative]]-F76,0) -> -2
A78: =MONTH(sofiS_table[[#This Row],[Transaction Date]]) -> 7 | B78: 45120 | C78: Discover | E78: -2118.23 | F78: =F77+sofiS_table[[#This Row],[Amount]] -> 303.16 | G78: =IFERROR(sofiS_table[[#This Row],[Cumulative]]-F77,0) -> -2118.23
A79: =MONTH(sofiS_table[[#This Row],[Transaction Date]]) -> 7 | B79: 45132 | C79: To Checking - 8930 | E79: -1803.4 | F79: =F78+sofiS_table[[#This Row],[Amount]] -> -1500.24 | G79: =IFERROR(sofiS_table[[#This Row],[Cumulative]]-F78,0) -> -1803.4
A80: =MONTH(sofiS_table[[#This Row],[Transaction Date]]) -> 7 | B80: 45132 | C80: Nationwide | D80: Direct Deposit | E80: 2258.37 | F80: =F79+sofiS_table[[#This Row],[Amount]] -> 758.13 | G80: =IFERROR(sofiS_table[[#This Row],[Cumulative]]-F79,0) -> 2258.37
A81: =MONTH(sofiS_table[[#This Row],[Transaction Date]]) -> 7 | B81: 45132 | C81: Healthequity Inc | E81: 100 | F81: =F80+sofiS_table[[#This Row],[Amount]] -> 858.13 | G81: =IFERROR(sofiS_table[[#This Row],[Cumulative]]-F80,0) -> 100
A82: =MONTH(sofiS_table[[#This Row],[Transaction Date]]) -> 7 | B82: 45133 | C82: To Checking - 8930 | E82: -200 | F82: =F81+sofiS_table[[#This Row],[Amount]] -> 658.13 | G82: =IFERROR(sofiS_table[[#This Row],[Cumulative]]-F81,0) -> -200
A83: =MONTH(sofiS_table[[#This Row],[Transaction Date]]) -> 7 | B83: 45134 | C83: Discover | E83: -500 | F83: =F82+sofiS_table[[#This Row],[Amount]] -> 158.13 | G83: =IFERROR(sofiS_table[[#This Row],[Cumulative]]-F82,0) -> -500
A84: =MONTH(sofiS_table[[#This Row],[Transaction Date]]) -> 7 | B84: 45138 | C84: Interest earned | E84: 1.28 | F84: =F83+sofiS_table[[#This Row],[Amount]] -> 159.41 | G84: =IFERROR(sofiS_table[[#This Row],[Cumulative]]-F83,0) -> 1.28
A85: =MONTH(sofiS_table[[#This Row],[Transaction Date]]) -> 7 | B85: 45138 | C85: Wells Fargo Bank Na | E85: -50 | F85: =F84+sofiS_table[[#This Row],[Amount]] -> 109.41 | G85: =IFERROR(sofiS_table[[#This Row],[Cumulative]]-F84,0) -> -50
A86: =MONTH(sofiS_table[[#This Row],[Transaction Date]]) -> 8 | B86: 45142 | C86: To Checking - 8930 | E86: -5 | F86: =F85+sofiS_table[[#This Row],[Amount]] -> 104.41 | G86: =IFERROR(sofiS_table[[#This Row],[Cumulative]]-F85,0) -> -5
A87: =MONTH(sofiS_table[[#This Row],[Transaction Date]]) -> 8 | B87: 45144 | C87: Cash App | E87: 100 | F87: =F86+sofiS_table[[#This Row],[Amount]] -> 204.41 | G87: =IFERROR(sofiS_table[[#This Row],[Cumulative]]-F86,0) -> 100
A88: =MONTH(sofiS_table[[#This Row],[Transaction Date]]) -> 8 | B88: 45146 | C88: To Emergency Fund Vault | E88: -901.7 | F88: =F87+sofiS_table[[#This Row],[Amount]] -> -697.29 | G88: =IFERROR(sofiS_table[[#This Row],[Cumulative]]-F87,0) -> -901.7
A89: =MONTH(sofiS_table[[#This Row],[Transaction Date]]) -> 8 | B89: 45146 | C89: Nationwide | D89: Direct Deposit | E89: 2258.37 | F89: =F88+sofiS_table[[#This Row],[Amount]] -> 1561.08 | G89: =IFERROR(sofiS_table[[#This Row],[Cumulative]]-F88,0) -> 2258.37
A90: =MONTH(sofiS_table[[#This Row],[Transaction Date]]) -> 8 | B90: 45148 | C90: Discover | E90: -1027.93 | F90: =F89+sofiS_table[[#This Row],[Amount]] -> 533.15 | G90: =IFERROR(sofiS_table[[#This Row],[Cumulative]]-F89,0) -> -1027.93
A91: =MONTH(sofiS_table[[#This Row],[Transaction Date]]) -> 8 | B91: 45160 | C91: Nationwide | D91: Direct Deposit | E91: 3050.56 | F91: =F90+sofiS_table[[#This Row],[Amount]] -> 3583.71 | G91: =IFERROR(sofiS_table[[#This Row],[Cumulative]]-F90,0) -> 3050.56
A92: =MONTH(sofiS_table[[#This Row],[Transaction Date]]) -> 8 | B92: 45162 | C92: To Checking - 8930 | E92: -932 | F92: =F91+sofiS_table[[#This Row],[Amount]] -> 2651.71 | G92: =IFERROR(sofiS_table[[#This Row],[Cumulative]]-F91,0) -> -932
A93: =MONTH(sofiS_table[[#This Row],[Transaction Date]]) -> 8 | B93: 45163 | C93: To Checking - 8930 | E93: -816.87 | F93: =F92+sofiS_table[[#This Row],[Amount]] -> 1834.84 | G93: =IFERROR(sofiS_table[[#This Row],[Cumulative]]-F92,0) -> -816.87
A94: =MONTH(sofiS_table[[#This Row],[Transaction Date]]) -> 8 | B94: 45163 | C94: Discover | E94: -2000 | F94: =F93+sofiS_table[[#This Row],[Amount]] -> -165.16 | G94: =IFERROR(sofiS_table[[#This Row],[Cumulative]]-F93,0) -> -2000
A95: =MONTH(sofiS_table[[#This Row],[Transaction Date]]) -> 8 | B95: 45163 | C95: From Emergency Fund Vault | E95: 902.3 | F95: =F94+sofiS_table[[#This Row],[Amount]] -> 737.14 | G95: =IFERROR(sofiS_table[[#This Row],[Cumulative]]-F94,0) -> 902.3
A96: =MONTH(sofiS_table[[#This Row],[Transaction Date]]) -> 8 | B96: 45166 | C96: To Checking - 8930 | E96: -793.5 | F96: =F95+sofiS_table[[#This Row],[Amount]] -> -56.36 | G96: =IFERROR(sofiS_table[[#This Row],[Cumulative]]-F95,0) -> -793.5
A97: =MONTH(sofiS_table[[#This Row],[Transaction Date]]) -> 8 | B97: 45166 | C97: Wells Fargo Bank Na | E97: 300 | F97: =F96+sofiS_table[[#This Row],[Amount]] -> 243.64 | G97: =IFERROR(sofiS_table[[#This Row],[Cumulative]]-F96,0) -> 300
A98: =MONTH(sofiS_table[[#This Row],[Transaction Date]]) -> 8 | B98: 45169 | C98: Interest earned | E98: 2.45 | F98: =F97+sofiS_table[[#This Row],[Amount]] -> 246.09 | G98: =IFERROR(sofiS_table[[#This Row],[Cumulative]]-F97,0) -> 2.45
...

Sheet HSA
A1: Column1 | B1: Date | C1: Transaction | D1: Amount | E1: HSA Cash Balance
A2: =(MONTH(B2))+0 -> 1 | B2: 44938 | C2: Employer Contribution (Tax year: 2023) (Tax year: 2023) | D2: 250 | E2: 500.71
A3: =(MONTH(B3))+0 -> 1 | B3: 44938 | C3: Employee Contribution (Tax year: 2023) (Tax year: 2023) | D3: 118.85 | E3: 250.71
A4: =(MONTH(B4))+0 -> 1 | B4: 44938 | C4: Balance Forward | D4: 131.86 | E4: 131.86 | F4: 0
A5: =(MONTH(B5))+0 -> 1 | B5: 44945 | C5: A Plus Dental Center - Sa, San Mateo, CA (Card Transaction ID: 0it8ihn) | D5: -234.4 | E5: 526.31
A6: =(MONTH(B6))+0 -> 1 | B6: 44945 | C6: Employer Contribution (Tax year: 2023) (Tax year: 2023) | D6: 260 | E6: 760.71
A7: =(MONTH(B7))+0 -> 1 | B7: 44952 | C7: Employee Contribution (Tax year: 2023) (Tax year: 2023) | D7: 118.85 | E7: 764.01
A8: =(MONTH(B8))+0 -> 1 | B8: 44952 | C8: Employer Contribution (Tax year: 2023) (Tax year: 2023) | D8: 118.85 | E8: 645.16
A9: =(MONTH(B9))+0 -> 1 | B9: 44957 | C9: Interest for Jan-23 | D9: 0.04 | E9: 764.05
A10: =(MONTH(B10))+0 -> 2 | B10: 44973 | C10: Arman Kirakosian Dpm (Claim ID:22317048-0006) | D10: -103.02 | E10: 447.88
A11: =(MONTH(B11))+0 -> 2 | B11: 44974 | C11: Wells Fargo (Claim ID:22317048-0005) | D11: -136 | E11: 311.88
A12: =(MONTH(B12))+0 -> 2 | B12: 44980 | C12: Sq *ayurbliss Physical, San Mateo, CA (Card Transaction ID: vp35vwm) | D12: -68 | E12: 375.03
A13: =(MONTH(B13))+0 -> 2 | B13: 44980 | C13: Employee Contribution (Tax year: 2023) (Tax year: 2023) | D13: 118.85 | E13: 443.03
A14: =(MONTH(B14))+0 -> 2 | B14: 44980 | C14: Employer Contribution (Tax year: 2023) (Tax year: 2023) | D14: 12.3 | E14: 324.18
A15: =(MONTH(B15))+0 -> 2 | B15: 44981 | C15: Sq *ayurbliss Physical Th, San Mateo, CA (Card Transaction ID: nt9xxgb) | D15: -68 | E15: 307.03
A16: =(MONTH(B16))+0 -> 2 | B16: 44985 | C16: Interest for Feb-23 | D16: 0.04 | E16: 307.07
... A49: =(MONTH(B49))+0 -> 6 | B49: 45092 | C49: Employee Contribution (Tax year: 2023) (Tax year: 2023) | D49: 118.85 | E49: 686.34
A50: =(MONTH(B50))+0 -> 6 | B50: 6/29/2023 | C50: Employee Contribution (Tax year: 2023) (Tax year: 2023) | D50: 118.85 | E50: 605.19
A51: =(MONTH(B51))+0 -> 6 | B51: 6/30/2023 | C51: Interest for Jun-23 | D51: 0.04 | E51: 605.23
A52: =(MONTH(B52))+0 -> 7 | B52: 7/6/2023 | C52: SOFI (Claim ID:22317048-0008) | D52: -499.64 | E52: 105.59
A53: =(MONTH(B53))+0 -> 7 | B53: 45120 | C53: Employee Contribution (tax year: 2023) | D53: 118.85 | E53: =E52+hsa_table[[#This Row],[Amount]] -> 224.44
A54: =(MONTH(B54))+0 -> 7 | B54: 45133 | C54: Sofi (claim ID:x-0008) Eft to Sofi | D54: -100 | E54: =E53+hsa_table[[#This Row],[Amount]] -> 124.44
A55: =(MONTH(B55))+0 -> 7 | B55: 45134 | C55: Employee Contribution (tax year: 2023) | D55: 118.85 | E55: =E54+hsa_table[[#This Row],[Amount]] -> 243.29
A56: =(MONTH(B56))+0 -> 7 | B56: 45138 | C56: Interest for Jul-23 | D56: 0.02 | E56: =E55+hsa_table[[#This Row],[Amount]] -> 243.31
A57: =(MONTH(B57))+0 -> 8 | B57: 45148 | C57: Employee Contribution (tax year: 2023) | D57: 118.85 | E57: =E56+hsa_table[[#This Row],[Amount]] -> 362.16
A58: =(MONTH(B58))+0 -> 8 | B58: 45154 | C58: Suttr Hlth Pcr Mho Hosp, x-x-1633, CA (card Transaction Id: iqbxey8) | D58: -199.72 | E58: =E57+hsa_table[[#This Row],[Amount]] -> 162.44
A59: =(MONTH(B59))+0 -> 8 | B59: 45162 | C59: Employee Contribution (tax year: 2023) | D59: 118.85 | E59: =E58+hsa_table[[#This Row],[Amount]] -> 281.29
A60: =(MONTH(B60))+0 -> 8 | B60: 45169 | C60: Interest for Aug-23 | D60: 0.02 | E60: =E59+hsa_table[[#This Row],[Amount]] -> 281.31
A61: =(MONTH(B61))+0 -> 9 | B61: 45175 | C61: North Peninsula Podiatry, San Bruno, CA (card Transaction Id: 3t62tix) | D61: -210 | E61: =E60+hsa_table[[#This Row],[Amount]] -> 71.31
A62: =(MONTH(B62))+0 -> 9 | B62: 45176 | C62: Employee Contribution (tax year: 2023) | D62: 118.85 | E62: =E61+hsa_table[[#This Row],[Amount]] -> 190.16
A63: =(MONTH(B63))+0 -> 9 | B63: 45190 | C63: Employee Contribution (tax year: 2023) | D63: 118.85 | E63: =E62+hsa_table[[#This Row],[Amount]] -> 309.01

Sheet Fidelity
A1: Month | B1: Date | C1: Investment | D1: Transaction Type | E1: Amount | F1: Shares/Unit
A2: =MONTH(sofiS_table8910[[#This Row],[Date]]) -> 1 | B2: 44927 | C2: 2055 FUND | D2: Balance Forward | E2: 12785.41 | F2: 0
A3: =MONTH(sofiS_table8910[[#This Row],[Date]]) -> 1 | B3: 44939 | C3: 2055 FUND | D3: Contributions | E3: 672.31 | F3: 61.736 | H3: 0
A4: =MONTH(sofiS_table8910[[#This Row],[Date]]) -> 1 | B4: 44953 | C4: 2055 FUND | D4: Contributions | E4: 1244.42 | F4: 112.414
A5: =MONTH(sofiS_table8910[[#This Row],[Date]]) -> 2 | B5: 44967 | C5: 2055 FUND | D5: Contributions | E5: 743.08 | F5: 67.308
A6: =MONTH(sofiS_table8910[[#This Row],[Date]]) -> 2 | B6: 44981 | C6: 2055 FUND | D6: Contributions | E6: 743.08 | F6: 68.868
A7: =MONTH(sofiS_table8910[[#This Row],[Date]]) -> 2 | B7: 44984 | C7: 2055 FUND | D7: RECORDKEEPING FEE | E7: -4.02 | F7: -0.371
A8: =MONTH(sofiS_table8910[[#This Row],[Date]]) -> 2 | B8: 44984 | C8: 2055 FUND | D8: Change in Market Value | E8: 0.1 | F8: 0
A9: =MONTH(sofiS_table8910[[#This Row],[Date]]) -> 3 | B9: 44995 | C9: 2055 FUND | D9: Contributions | E9: 880 | F9: 83.019
A10: =MONTH(sofiS_table8910[[#This Row],[Date]]) -> 3 | B10: 45009 | C10: 2055 FUND | D10: Contributions | E10: 160 | F10: 15.009
A11: =MONTH(sofiS_table8910[[#This Row],[Date]]) -> 4 | B11: 45026 | C11: 2055 FUND | D11: Contributions | E11: 160 | F11: 14.585
A12: =MONTH(sofiS_table8910[[#This Row],[Date]]) -> 4 | B12: 45037 | C12: 2055 FUND | D12: Contributions | E12: 160 | F12: 14.401
A13: =MONTH(sofiS_table8910[[#This Row],[Date]]) -> 5 | B13: 45051 | C13: 2055 FUND | D13: Contributions | E13: 160 | F13: 14.409
A14: =MONTH(sofiS_table8910[[#This Row],[Date]]) -> 5 | B14: 45057 | C14: 2055 FUND | D14: RECORDKEEPING FEE | E14: -2.51 | F14: -0.227
A15: =MONTH(sofiS_table8910[[#This Row],[Date]]) -> 5 | B15: 45057 | C15: 2055 FUND | D15: Change in Market Value | E15: 0.11 | F15: 0
... A18: =MONTH(sofiS_table8910[[#This Row],[Date]]) -> 6 | B18: 45095 | C18: 2055 FUND | D18: Change in Market Value | E18: 1860.16 | F18: 11.57
A19: =MONTH(sofiS_table8910[[#This Row],[Date]]) -> 7 | B19: 45121 | C19: 2055 FUND | D19: Contributions | E19: 0.02
A20: =MONTH(sofiS_table8910[[#This Row],[Date]]) -> 7 | B20: 45135 | C20: 2055 FUND | D20: Contributions | E20: 0.04
A21: =MONTH(sofiS_table8910[[#This Row],[Date]]) -> 8 | B21: 45147 | C21: 2055 FUND | D21: RECORDKEEPING FEE | E21: -4.24
A22: =MONTH(sofiS_table8910[[#This Row],[Date]]) -> 8 | B22: 45163 | C22: 2055 FUND | D22: Contributions | E22: 0.06
A23: =MONTH(sofiS_table8910[[#This Row],[Date]]) -> 9 | B23: 45191 | C23: 2055 FUND | D23: Contributions | E23: 0.03

Sheet Discover Data
B1: Month | C1: Trans. date | D1: Post date | E1: Description | F1: Amount | G1: Category | H1: Short_Desc | I1: Reoccurring_Flag | J1: Category_2 | K1: Date | L1: Year | M1: Sort_Date | N1: CumAmount | O1: Counter | S1: 44927 | T1: 44958 | U1: 44986 | V1: 45017 | W1: 45047 | X1: 45078 | Y1: 45108 | Z1: 08/2023 | AA1: 09/2023 | AB1: 10/2023 | AC1: 11/2023 | AD1: 12/2023
A2: 0 | B2: =MONTH(dis_table[[#This Row],[Date]]) -> 1 | C2: 44927 | D2: 44927 | E2: Balance | F2: 577.5 | G2: Balance | H2: Balance | I2: No | J2: Balance | K2: 44927 | L2: 2023 | M2: 44927 | N2: 577.5 | O2: 1 | R2: Automotive | S2: =SUMIFS(dis_table[Amount],dis_table[Category],$R2,dis_table[Date],S$1) -> 16.4 | T2: =SUMIFS(dis_table[Amount],dis_table[Category],$R2,dis_table[Date],T$1) -> 279.89 | U2: =SUMIFS(dis_table[Amount],dis_table[Category],$R2,dis_table[Date],U$1) -> 106.56 | V2: =SUMIFS(dis_table[Amount],dis_table[Category],$R2,dis_table[Date],V$1) -> 0 | W2: =SUMIFS(dis_table[Amount],dis_table[Category],$R2,dis_table[Date],W$1) -> 0 | X2: =SUMIFS(dis_table[Amount],dis_table[Category],$R2,dis_table[Date],X$1) -> 0 | Y2: =SUMIFS(dis_table[Amount],dis_table[Category],$R2,dis_table[Date],Y$1) -> 0 | Z2: =SUMIFS(dis_table[Amount],dis_table[Category],$R2,dis_table[Date],Z$1) -> 0 | ... AD2: =SUMIFS(dis_table[Amount],dis_table[Category],$R2,dis_table[Date],AD$1) -> 151.04
A3: 1 | B3: =MONTH(dis_table[[#This Row],[Date]]) -> 1 | C3: 44927 | D3: 44927 | E3: SPOTIFY P1FEF894B5 8777781161 NY | F3: 4.99 | G3: Merchandise | H3: spotify | I3: Yes | J3: Recreation_Entertainment | K3: 44927 | L3: 2023 | M3: 44927 | N3: 582.49 | O3: 1 | R3: Education | S3: =SUMIFS(dis_table[Amount],dis_table[Category],$R3,dis_table[Date],S$1) -> 49 | T3: =SUMIFS(dis_table[Amount],dis_table[Category],$R3,dis_table[Date],T$1) -> 98 | U3: =SUMIFS(dis_table[Amount],dis_table[Category],$R3,dis_table[Date],U$1) -> 448 | V3: =SUMIFS(dis_table[Amount],dis_table[Category],$R3,dis_table[Date],V$1) -> 0 | W3: =SUMIFS(dis_table[Amount],dis_table[Category],$R3,dis_table[Date],W$1) -> 1057.49 | X3: =SUMIFS(dis_table[Amount],dis_table[Category],$R3,dis_table[Date],X$1) -> 19.99 | Y3: =SUMIFS(dis_table[Amount],dis_table[Category],$R3,dis_table[Date],Y$1) -> 7.99 | Z3: =SUMIFS(dis_table[Amount],dis_table[Category],$R3,dis_table[Date],Z$1) -> 49 | ... AD3: =SUMIFS(dis_table[Amount],dis_table[Category],$R3,dis_table[Date],AD$1) -> 0
A4: 2 | B4: =MONTH(dis_table[[#This Row],[Date]]) -> 1 | C4: 44927 | D4: 44929 | E4: NETFLIX.COM NETFLIX.COM CAITEM TRANSFERRED FROM PREV ACCOUNT | F4: 10.59 | G4: Merchandise | H4: netflix | I4: Yes | J4: Recreation_Entertainment | K4: 44927 | L4: 2023 | M4: 44927 | N4: 593.08 | O4: 1 | Q4: 0 | R4: Gasoline | S4: =SUMIFS(dis_table[Amount],dis_table[Category],$R4,dis_table[Date],S$1) -> 132.49 | T4: =SUMIFS(dis_table[Amount],dis_table[Category],$R4,dis_table[Date],T$1) -> 15.5 | U4: =SUMIFS(dis_table[Amount],dis_table[Category],$R4,dis_table[Date],U$1) -> 99.56 | V4: =SUMIFS(dis_table[Amount],dis_table[Category],$R4,dis_table[Date],V$1) -> 148.38 | W4: =SUMIFS(dis_table[Amount],dis_table[Category],$R4,dis_table[Date],W$1) -> 161.57 | X4: =SUMIFS(dis_table[Amount],dis_table[Category],$R4,dis_table[Date],X$1) -> 0 | Y4: =SUMIFS(dis_table[Amount],dis_table[Category],$R4,dis_table[Date],Y$1) -> 0 | Z4: =SUMIFS(dis_table[Amount],dis_table[Category],$R4,dis_table[Date],Z$1) -> 2100.1 | ... AD4: =SUMIFS(dis_table[Amount],dis_table[Category],$R4,dis_table[Date],AD$1) -> 50.16
A5: 3 | B5: =MONTH(dis_table[[#This Row],[Date]]) -> 1 | C5: 44927 | D5: 44929 | E5: SAFEWAY #1547 BURLINGAME CA | F5: 34.46 | G5: Supermarkets | H5: groceries | I5: No | J5: Food | K5: 44927 | L5: 2023 | M5: 44927 | N5: 627.54 | O5: 1 | R5: Government Services | S5: =SUMIFS(dis_table[Amount],dis_table[Category],$R5,dis_table[Date],S$1) -> 260.36 | T5: =SUMIFS(dis_table[Amount],dis_table[Category],$R5,dis_table[Date],T$1) -> 0 | U5: =SUMIFS(dis_table[Amount],dis_table[Category],$R5,dis_table[Date],U$1) -> 17.1 | V5: =SUMIFS(dis_table[Amount],dis_table[Category],$R5,dis_table[Date],V$1) -> 16.94 | W5: =SUMIFS(dis_table[Amount],dis_table[Category],$R5,dis_table[Date],W$1) -> 80.75 | X5: =SUMIFS(dis_table[Amount],dis_table[Category],$R5,dis_table[Date],X$1) -> 46.33 | Y5: =SUMIFS(dis_table[Amount],dis_table[Category],$R5,dis_table[Date],Y$1) -> 0 | Z5: =SUMIFS(dis_table[Amount],dis_table[Category],$R5,dis_table[Date],Z$1) -> 0 | ... AD5: =SUMIFS(dis_table[Amount],dis_table[Category],$R5,dis_table[Date],AD$1) -> 0
A6: 4 | B6: =MONTH(dis_table[[#This Row],[Date]]) -> 1 | C6: 44928 | D6: 44929 | E6: KRYSTAL AND SAAGAR 2025317527 DCITEM TRANSFERRED FROM PREV ACCOUNT | F6: 10 | G6: Merchandise | H6: breaking_points | I6: Yes | J6: Recreation_Entertainment | K6: 44927 | L6: 2023 | M6: 44928 | N6: 637.54 | O6: 1 | R6: Home Improvement | S6: =SUMIFS(dis_table[Amount],dis_table[Category],$R6,dis_table[Date],S$1) -> 0 | T6: =SUMIFS(dis_table[Amount],dis_table[Category],$R6,dis_table[Date],T$1) -> 0 | U6: =SUMIFS(dis_table[Amount],dis_table[Category],$R6,dis_table[Date],U$1) -> 0 | V6: =SUMIFS(dis_table[Amount],dis_table[Category],$R6,dis_table[Date],V$1) -> 23.91 | W6: =SUMIFS(dis_table[Amount],dis_table[Category],$R6,dis_table[Date],W$1) -> 0 | X6: =SUMIFS(dis_table[Amount],dis_table[Category],$R6,dis_table[Date],X$1) -> 0 | Y6: =SUMIFS(dis_table[Amount],dis_table[Category],$R6,dis_table[Date],Y$1) -> 0 | Z6: =SUMIFS(dis_table[Amount],dis_table[Category],$R6,dis_table[Date],Z$1) -> 0 | ... AD6: =SUMIFS(dis_table[Amount],dis_table[Category],$R6,dis_table[Date],AD$1) -> 0
A7: 5 | B7: =MONTH(dis_table[[#This Row],[Date]]) -> 1 | C7: 44928 | D7: 44929 | E7: OBSIDIAN.MD 2262203323 CAN | F7: 10 | G7: Merchandise | H7: obsidian | I7: Yes | J7: Personal_Spending | K7: 44927 | L7: 2023 | M7: 44928 | N7: 647.54 | O7: 1 | R7: Interest | S7: =SUMIFS(dis_table[Amount],dis_table[Category],$R7,dis_table[Date],S$1) -> 0 | T7: =SUMIFS(dis_table[Amount],dis_table[Category],$R7,dis_table[Date],T$1) -> 0 | U7: =SUMIFS(dis_table[Amount],dis_table[Category],$R7,dis_table[Date],U$1) -> 0 | V7: =SUMIFS(dis_table[Amount],dis_table[Category],$R7,dis_table[Date],V$1) -> 0 | W7: =SUMIFS(dis_table[Amount],dis_table[Category],$R7,dis_table[Date],W$1) -> 0 | X7: =SUMIFS(dis_table[Amount],dis_table[Category],$R7,dis_table[Date],X$1) -> 0 | Y7: =SUMIFS(dis_table[Amount],dis_table[Category],$R7,dis_table[Date],Y$1) -> 0 | Z7: =SUMIFS(dis_table[Amount],dis_table[Category],$R7,dis_table[Date],Z$1) -> 0 | ... AD7: =SUMIFS(dis_table[Amount],dis_table[Category],$R7,dis_table[Date],AD$1) -> 0
A8: 6 | B8: =MONTH(dis_table[[#This Row],[Date]]) -> 1 | C8: 44929 | D8: 44929 | E8: A PLUS DENTAL CENTER - S SAN MATEO CA | F8: 549.6 | G8: Medical Services | H8: dental | I8: No | J8: Medical | K8: 44927 | L8: 2023 | M8: 44929 | N8: 1197.14 | O8: 1 | R8: Medical Services | S8: =SUMIFS(dis_table[Amount],dis_table[Category],$R8,dis_table[Date],S$1) -> 656.1 | T8: =SUMIFS(dis_table[Amount],dis_table[Category],$R8,dis_table[Date],T$1) -> 299.32 | U8: =SUMIFS(dis_table[Amount],dis_table[Category],$R8,dis_table[Date],U$1) -> 1174.21 | V8: =SUMIFS(dis_table[Amount],dis_table[Category],$R8,dis_table[Date],V$1) -> 66.53 | W8: =SUMIFS(dis_table[Amount],dis_table[Category],$R8,dis_table[Date],W$1) -> 178.08 | X8: =SUMIFS(dis_table[Amount],dis_table[Category],$R8,dis_table[Date],X$1) -> 0 | Y8: =SUMIFS(dis_table[Amount],dis_table[Category],$R8,dis_table[Date],Y$1) -> 266.7 | Z8: =SUMIFS(dis_table[Amount],dis_table[Category],$R8,dis_table[Date],Z$1) -> 0 | ... AD8: =SUMIFS(dis_table[Amount],dis_table[Category],$R8,dis_table[Date],AD$1) -> 40.65
A9: 7 | B9: =MONTH(dis_table[[#This Row],[Date]]) -> 1 | C9: 44929 | D9: 44929 | E9: AMAZON.COM*7H1T34W33 AMZN.COM/BILLWA7CGLY7QDYF3 | F9: 42.12 | G9: Merchandise | H9: everything_store | I9: No | J9: Personal_Spending | K9: 44927 | L9: 2023 | M9: 44929 | N9: 1239.26 | O9: 1 | R9: Merchandise | S9: =SUMIFS(dis_table[Amount],dis_table[Category],$R9,dis_table[Date],S$1) -> 654.74 | T9: =SUMIFS(dis_table[Amount],dis_table[Category],$R9,dis_table[Date],T$1) -> 1246.36 | U9: =SUMIFS(dis_table[Amount],dis_table[Category],$R9,dis_table[Date],U$1) -> 1452.31 | V9: =SUMIFS(dis_table[Amount],dis_table[Category],$R9,dis_table[Date],V$1) -> 2083.87 | W9: =SUMIFS(dis_table[Amount],dis_table[Category],$R9,dis_table[Date],W$1) -> 2565.32 | X9: =SUMIFS(dis_table[Amount],dis_table[Category],$R9,dis_table[Date],X$1) -> 741.64 | Y9: =SUMIFS(dis_table[Amount],dis_table[Category],$R9,dis_table[Date],Y$1) -> 849.87 | Z9: =SUMIFS(dis_table[Amount],dis_table[Category],$R9,dis_table[Date],Z$1) -> 1024.45 | ... AD9: =SUMIFS(dis_table[Amount],dis_table[Category],$R9,dis_table[Date],AD$1) -> 1094.63
A10: 8 | B10: =MONTH(dis_table[[#This Row],[Date]]) -> 1 | C10: 44929 | D10: 44929 | E10: AUTOMATIC STATEMENT CREDIT | F10: -41.41 | G10: Awards and Rebate Credits | H10: credits | I10: No | J10: Payment_and_Interest | K10: 44927 | L10: 2023 | M10: 44929 | N10: 1197.85 | O10: 1 | R10: Restaurants | S10: =SUMIFS(dis_table[Amount],dis_table[Category],$R10,dis_table[Date],S$1) -> 318.3 | T10: =SUMIFS(dis_table[Amount],dis_table[Category],$R10,dis_table[Date],T$1) -> 657.48 | U10: =SUMIFS(dis_table[Amount],dis_table[Category],$R10,dis_table[Date],U$1) -> 482.18 | V10: =SUMIFS(dis_table[Amount],dis_table[Category],$R10,dis_table[Date],V$1) -> 270.53 | W10: =SUMIFS(dis_table[Amount],dis_table[Category],$R10,dis_table[Date],W$1) -> 556.46 | X10: =SUMIFS(dis_table[Amount],dis_table[Category],$R10,dis_table[Date],X$1) -> 41.37 | Y10: =SUMIFS(dis_table[Amount],dis_table[Category],$R10,dis_table[Date],Y$1) -> 62.19 | Z10: =SUMIFS(dis_table[Amount],dis_table[Category],$R10,dis_table[Date],Z$1) -> 337.29 | ... AD10: =SUMIFS(dis_table[Amount],dis_table[Category],$R10,dis_table[Date],AD$1) -> 543.97
